Workbook
Name Inverter_Capacity: #REF!
Name Inverter_Supplier: #REF!
Name Project_Size: 'Finance - Revenue'!Projectsize
Name Project_Size: Projectsize
Name Projectsize: #REF!
Name Projectsize: #REF!
Name Security_Serv: #REF!
Name Security_Serv: #REF!
Name SSS: #REF!
Name SSS: #REF!
Name USD_ZAR: #REF!

Sheet Certificate - Financial Close
B2: Emergent Energy – Financial Close Completion Certificate | H2: FINANCIAL CLOSE CERTIFICATE
B4: Project Name: | C4: ='Project Plan'!E2 -> SuperSpar Despatch Ph2
B5: COO: | C5: Johannes Potgieter
B6: Programme Manager: | C6: Roedolph Venter
B7: HoPD: | C7: Natasha Watkins-Baker
B9: Date of Phase Completion:
B10: Phase Deliverables Checklist: (Y/N)
B11: Product Agreement
B12: EPC Agreement
B13: O&M Agreeement
B14: Cost Proposal
B15: Deposit Received
B16: Risks / Notes
B18: Acknowledgement and Acceptance:
B19: Role | C19: Name | D19: Signature | E19: Date

Sheet Certificate - Planning
B2: Emergent Energy – Planning Phase Completion Certificate | H2: PLANNING CERTIFICATE
B4: Project Name: | C4: ='Project Plan'!E2 -> SuperSpar Despatch Ph2
B5: Client Representative:
B6: Programme Manager: | C6: Roedolph Venter
B7: Project Manager: | C7: ='Project Plan'!E5 -> Lloyd Brown
B8: Project Engineer:
B10: Date of Phase Completion:
B11: Phase Deliverables Checklist: (Y/N)
B12: Project Introduction Presentation
B13: Project Brief
B14: Engineering Pack
B15: BOQ
B16: PO – Material & Equipment
B17: PO - Contractors
B18: HSE – NOC
B19: HSE – EE File
B20: HSE – Contractor File
... B24: Acknowledgement and Acceptance:
B25: Role | C25: Name | D25: Signature | E25: Date

Sheet Change Register
F1: Change Register
B3: ID | C3: Description | D3: Supporting Image (If Applicable) | E3: Impact | F3: Proposed Date | G3: Proposed By | H3: Status | I3: Approved By | J3: Approved Date | K3: Results / Comments
B4: DEC001
B5: DEC002
B6: DEC003
B7: DEC004
B8: DEC005
B9: DEC006
B10: DEC007
B11: DEC008
B12: DEC009
B13: DEC010
B14: DEC011
B15: DEC012
... B33: DEC030

Sheet BOQ
B2: Item | C2: Supplier | D2: Description | E2: Quantity | F2: Comments
B3: PV Module | C3: Menlo | D3: Jinko610W - JKM610N072HL4M-BDV | E3: 257
B4: DC Cable Red & Black | C4: Menlo | D4: Enco | E4: 6000
B5: Inverters | C5: Menlo | D5: 1 x Huawei 100KTL - 1 x Huawei 50KTL | E5: 2
B6: Mounting Structure
B7: Current Transformers (Production)
B8: Current Transformers (Consumption)
B9: Solar Production Meter (Techistter)
B10: Grid Consumption Meter
B11: Wi-Fi Router & Sim
B12: Switch
B13: Back Up Battery
B14: PVDB
B23: Supplier List
B24: Accuenergy
B25: Krannich
... B30: Techsitter

Sheet Compliance
B2: HSE
B4: Description | C4: Status | D4: Approved By | E4: Date | F4: Results / Comments
B5: NOC | F5: In Progress
B6: 7.1 Agreement | F6: In Progress
B7: 13.2 Agreement | F7: In Progress
B8: EE File | F8: In Progress
B9: Subbie File | F9: Awaiting
B16: SSEG
B18: Description | C18: Status | D18: Approved By | E18: Date | F18: Results / Comments
B19: SSEG Application
B20: PTI
B21: Commissioning Approval

Sheet Project Plan
N1: =TODAY() -> 46064 | O1: =TODAY() -> 46064
C2: PROJECT PLAN | E2: SuperSpar Despatch Ph2 | I2: Net Work Days | K2: =NETWORKDAYS(I18,K39,Data!C3:C60) -> 10 | N2: 0 | O2: 1
C3: PROJECT SIZE (kWp) | E3: 157 | I3: Total Weeks | K3: =K2/5 -> 2
C4: PROJECT DEVELOPER | E4: Gordon Upton | I4: kW/Week Installation Rate | K4: =E3/K3 -> 78.5
C5: PROJECT MANAGERS | E5: Lloyd Brown
C6: CONTRACT VALUE | E6: 1364882.4
C7: Phase: | E7: QA
B8: No. | C8: HIGH LEVEL PROGRAMME | E8: Planned Start | F8: Duration | G8: Planned End | I8: Actual Start | J8: Duration | K8: Actual End | M8: Status | N8: Expected Status | O8: Comment
F9: =G39-E19 -> 23 | J9: =K39-I19 -> 11 | M9: =AVERAGE(M11,M18,M21,M28,M35,M39,M48,M44) -> 0.69910714 | N9: =AVERAGE(N11,N18,N21,N28,N35,N39,N48,N44) -> 0.91110156 | S9: =TODAY() -> 46064 | T9: =TODAY() -> 46064
S10: 1 | T10: 0
B11: 1 | C11: Project Initiation | E11: =MIN(E12:E17) -> 45986 | F11: =G11-E11 -> 64 | G11: =MAX(G12:G17) -> 46050 | I11: =MIN(I12:I17) -> 45986 | J11: =K11-I11 -> 64 | K11: =MAX(K12:K17) -> 46050 | M11: =(J12*M12+J13*M13+J14*M14+J15*M15+J16*M16)/SUM(J12:J16) -> 1 | N11: =(K12*N12+K13*N13+K14*N14+K15*N15+K16*N16)/SUM(K12:K16) -> 1
B12: 1.1 | C12: Project Charter Handover | E12: 45986 | F12: 1 | G12: =WORKDAY.INTL(E12,F12,1,Data!$C$3:$C$60) -> 45987 | I12: 45986 | J12: 1 | K12: =WORKDAY.INTL(I12,J12,1,Data!$C$3:$C$60) -> 45987 | M12: 1 | N12: =_xlfn.LET( _xlpm.s,VALUE($I12), _xlpm.e,VALUE($K12), IF(OR(_xlpm.s="",_xlpm.e=""),"", IF(_xlpm.e<=_xlpm.s, IF(TODAY()>=_xlpm.e,1,0), MAX(0,MIN(1,(TODAY()-_xlpm.s)/(_xlpm.e-_xlpm.s))))) ) -> 1 | S12: Milestone | T12: Start Date | U12: Duration | V12: End Date
B13: 1.2 | C13: HSE Readiness and Signoff | E13: =WORKDAY.INTL(G12,0,1,Data!$C$3:$C$60)+7 -> 45994 | F13: 15 | G13: =WORKDAY.INTL(E13,F13,1,Data!$C$3:$C$60) -> 46050 | I13: =WORKDAY.INTL(K12,0,1,Data!$C$3:$C$60)+7 -> 45994 | J13: 15 | K13: =WORKDAY.INTL(I13,J13,1,Data!$C$3:$C$60) -> 46050 | M13: 1 | N13: =_xlfn.LET( _xlpm.s,VALUE($I13), _xlpm.e,VALUE($K13), IF(OR(_xlpm.s="",_xlpm.e=""),"", IF(_xlpm.e<=_xlpm.s, IF(TODAY()>=_xlpm.e,1,0), MAX(0,MIN(1,(TODAY()-_xlpm.s)/(_xlpm.e-_xlpm.s))))) ) -> 1 | S13: =C11 -> Project Initiation | T13: =I11 -> 45986 | U13: =J11 -> 64 | V13: =K11 -> 46050
B14: 1.3 | C14: Project Introduction | E14: =WORKDAY.INTL(G12,0,1,Data!$C$3:$C$60)+21 -> 46008 | F14: 1 | G14: =WORKDAY.INTL(E14,F14,1,Data!$C$3:$C$60) -> 46041 | I14: =WORKDAY.INTL(K12,0,1,Data!$C$3:$C$60)+21 -> 46008 | J14: 1 | K14: =WORKDAY.INTL(I14,J14,1,Data!$C$3:$C$60) -> 46041 | M14: 1 | N14: =_xlfn.LET( _xlpm.s,VALUE($I14), _xlpm.e,VALUE($K14), IF(OR(_xlpm.s="",_xlpm.e=""),"", IF(_xlpm.e<=_xlpm.s, IF(TODAY()>=_xlpm.e,1,0), MAX(0,MIN(1,(TODAY()-_xlpm.s)/(_xlpm.e-_xlpm.s))))) ) -> 1 | S14: =C18 -> Site Establishment | T14: =I18 -> 46048 | U14: =J18 -> 1 | V14: =K18 -> 46049
B15: 1.4 | C15: Installer Kick Off | E15: =WORKDAY.INTL(E13,0,1,Data!$C$3:$C$60)+14 -> 46008 | F15: 1 | G15: =WORKDAY.INTL(E15,F15,1,Data!$C$3:$C$60) -> 46041 | I15: =WORKDAY.INTL(I13,0,1,Data!$C$3:$C$60)+14 -> 46008 | J15: 1 | K15: =WORKDAY.INTL(I15,J15,1,Data!$C$3:$C$60) -> 46041 | M15: 1 | N15: =_xlfn.LET( _xlpm.s,VALUE($I15), _xlpm.e,VALUE($K15), IF(OR(_xlpm.s="",_xlpm.e=""),"", IF(_xlpm.e<=_xlpm.s, IF(TODAY()>=_xlpm.e,1,0), MAX(0,MIN(1,(TODAY()-_xlpm.s)/(_xlpm.e-_xlpm.s))))) ) -> 1 | S15: =C21 -> AC Installation | T15: =I21 -> 45994 | U15: =J21 -> 58 | V15: =K21 -> 46052
B16: 1.5 | C16: Project Review | E16: =WORKDAY.INTL(E15,0,1,Data!$C$3:$C$60)-4 -> 46004 | F16: 1 | G16: =WORKDAY.INTL(E16,F16,1,Data!$C$3:$C$60) -> 46041 | I16: =WORKDAY.INTL(I15,0,1,Data!$C$3:$C$60)-4 -> 46004 | J16: 1 | K16: =WORKDAY.INTL(I16,J16,1,Data!$C$3:$C$60) -> 46041 | M16: 1 | N16: =_xlfn.LET( _xlpm.s,VALUE($I16), _xlpm.e,VALUE($K16), IF(OR(_xlpm.s="",_xlpm.e=""),"", IF(_xlpm.e<=_xlpm.s, IF(TODAY()>=_xlpm.e,1,0), MAX(0,MIN(1,(TODAY()-_xlpm.s)/(_xlpm.e-_xlpm.s))))) ) -> 1 | S16: =C28 -> DC Works | T16: =I28 -> 46001 | U16: =J28 -> 47 | V16: =K28 -> 46048
S17: =C35 -> Module installation | T17: =I35 -> 46001 | U17: =J35 -> 50 | V17: =K35 -> 46051
B18: 2 | C18: Site Establishment | E18: =MIN(E19:E20) -> 46048 | F18: =G18-E18 -> 1 | G18: =MAX(G19:G20) -> 46049 | I18: =MIN(I19:I20) -> 46048 | J18: =K18-I18 -> 1 | K18: =MAX(K19:K20) -> 46049 | M18: =(J19*M19)/J18 -> 1 | N18: =(K19*N19)/K18 -> 1 | S18: =C39 -> Commissioning | T18: =I39 -> 46051 | U18: =J39 -> 8 | V18: =K39 -> 46059
B19: 2.1 | C19: Solar Contractor Establishment | E19: =WORKDAY.INTL(G16,0,1,Data!$C$3:$C$60)+7 -> 46048 | F19: 1 | G19: =E19+F19 -> 46049 | I19: =WORKDAY.INTL(K16,0,1,Data!$C$3:$C$60)+7 -> 46048 | J19: 1 | K19: =I19+J19 -> 46049 | M19: 1 | N19: =_xlfn.LET( _xlpm.s,VALUE($I19), _xlpm.e,VALUE($K19), IF(OR(_xlpm.s="",_xlpm.e=""),"", IF(_xlpm.e<=_xlpm.s, IF(TODAY()>=_xlpm.e,1,0), MAX(0,MIN(1,(TODAY()-_xlpm.s)/(_xlpm.e-_xlpm.s))))) ) -> 1 | S19: =C44 -> QA Inspections | T19: =I44 -> 46058 | U19: =J44 -> 8 | V19: =K44 -> 46066
S20: =C48 -> Project Closure | T20: =I48 -> 46063 | U20: =J48 -> 16 | V20: =K48 -> 46079
B21: 3 | C21: AC Installation | E21: =MIN(E22:E27) -> 45994 | F21: =G21-E21 -> 68 | G21: =MAX(G22:G27) -> 46062 | I21: =MIN(I22:I27) -> 45994 | J21: =K21-I21 -> 58 | K21: =MAX(K22:K27) -> 46052 | M21: =(J22*M22+J23*M23+J24*M24+J25*M25+J26*M26)/SUM(J22:J26) -> 1 | N21: =(J22*N22+J23*N23+J24*N24+J25*N25+J26*N26)/SUM(J22:J26) -> 1
B22: 3.1 | C22: Inverters delivered | E22: 46001 | F22: 1 | G22: =WORKDAY.INTL(E22,F22,1,Data!$C$3:$C$60) -> 46002 | I22: 46001 | J22: 1 | K22: =WORKDAY.INTL(I22,J22,1,Data!$C$3:$C$60) -> 46002 | M22: 1 | N22: =_xlfn.LET( _xlpm.s,VALUE($I22), _xlpm.e,VALUE($K22), IF(OR(_xlpm.s="",_xlpm.e=""),"", IF(_xlpm.e<=_xlpm.s, IF(TODAY()>=_xlpm.e,1,0), MAX(0,MIN(1,(TODAY()-_xlpm.s)/(_xlpm.e-_xlpm.s))))) ) -> 1
B23: 3.2 | C23: Inverters Mounted | E23: 46050 | F23: 1 | G23: =WORKDAY.INTL(E23,F23,1,Data!$C$3:$C$60) -> 46051 | I23: 46050 | J23: 1 | K23: =WORKDAY.INTL(I23,J23,1,Data!$C$3:$C$60) -> 46051 | M23: 1 | N23: =_xlfn.LET( _xlpm.s,VALUE($I23), _xlpm.e,VALUE($K23), IF(OR(_xlpm.s="",_xlpm.e=""),"", IF(_xlpm.e<=_xlpm.s, IF(TODAY()>=_xlpm.e,1,0), MAX(0,MIN(1,(TODAY()-_xlpm.s)/(_xlpm.e-_xlpm.s))))) ) -> 1
B24: 3.3 | C24: Solar DB Lead Time | E24: =WORKDAY.INTL(E14,0,1,Data!$C$3:$C$60)-14 -> 45994 | F24: 20 | G24: =WORKDAY.INTL(E24,F24,1,Data!$C$3:$C$60) -> 46057 | I24: =WORKDAY.INTL(I14,0,1,Data!$C$3:$C$60)-14 -> 45994 | J24: 15 | K24: =WORKDAY.INTL(I24,J24,1,Data!$C$3:$C$60) -> 46050 | M24: 1 | N24: =_xlfn.LET( _xlpm.s,VALUE($I24), _xlpm.e,VALUE($K24), IF(OR(_xlpm.s="",_xlpm.e=""),"", IF(_xlpm.e<=_xlpm.s, IF(TODAY()>=_xlpm.e,1,0), MAX(0,MIN(1,(TODAY()-_xlpm.s)/(_xlpm.e-_xlpm.s))))) ) -> 1
B25: 3.4 | C25: AC Works | E25: =WORKDAY.INTL(G24,0,1,Data!$C$3:$C$60) -> 46057 | F25: 3 | G25: =WORKDAY.INTL(E25,F25,1,Data!$C$3:$C$60) -> 46062 | I25: 46041 | J25: 4 | K25: =WORKDAY.INTL(I25,J25,1,Data!$C$3:$C$60) -> 46045 | M25: 1 | N25: =_xlfn.LET( _xlpm.s,VALUE($I25), _xlpm.e,VALUE($K25), IF(OR(_xlpm.s="",_xlpm.e=""),"", IF(_xlpm.e<=_xlpm.s, IF(TODAY()>=_xlpm.e,1,0), MAX(0,MIN(1,(TODAY()-_xlpm.s)/(_xlpm.e-_xlpm.s))))) ) -> 1
B26: 3.5 | C26: AC Tie-In | E26: =WORKDAY.INTL(E25,0,1,Data!$C$3:$C$60) -> 46057 | F26: 1 | G26: =WORKDAY.INTL(E26,F26,1,Data!$C$3:$C$60) -> 46058 | I26: 46051 | J26: 1 | K26: =WORKDAY.INTL(I26,J26,1,Data!$C$3:$C$60) -> 46052 | M26: 1 | N26: =_xlfn.LET( _xlpm.s,VALUE($I26), _xlpm.e,VALUE($K26), IF(OR(_xlpm.s="",_xlpm.e=""),"", IF(_xlpm.e<=_xlpm.s, IF(TODAY()>=_xlpm.e,1,0), MAX(0,MIN(1,(TODAY()-_xlpm.s)/(_xlpm.e-_xlpm.s))))) ) -> 1
B28: 4 | C28: DC Works | E28: =MIN(E30:E34) -> 46001 | F28: =G28-E28 -> 51 | G28: =MAX(G30:G34) -> 46052 | I28: =MIN(I30:I34) -> 46001 | J28: =K28-I28 -> 47 | K28: =MAX(K30:K34) -> 46048 | M28: =(J30*M30+J31*M31+J33*M33)/SUM(J30,J31,J33) -> 1 | N28: =(J30*N30+J31*N31+J33*N33)/SUM(J30,J31,J33) -> 1
B30: 4.1 | C30: Mounting Structure delivered | E30: 46001 | F30: 1 | G30: =WORKDAY.INTL(E30,F30,1,Data!$C$3:$C$60) -> 46002 | I30: 46001 | J30: 1 | K30: =WORKDAY.INTL(I30,J30,1,Data!$C$3:$C$60) -> 46002 | M30: 1 | N30: =_xlfn.LET( _xlpm.s,VALUE($I30), _xlpm.e,VALUE($K30), IF(OR(_xlpm.s="",_xlpm.e=""),"", IF(_xlpm.e<=_xlpm.s, IF(TODAY()>=_xlpm.e,1,0), MAX(0,MIN(1,(TODAY()-_xlpm.s)/(_xlpm.e-_xlpm.s))))) ) -> 1
B31: 4.2 | C31: Mounting Structure installation | E31: =WORKDAY.INTL(G30,0,1,Data!$C$3:$C$60) -> 46002 | F31: 2 | G31: =E31+F31 -> 46004 | I31: =WORKDAY.INTL(K30,0,1,Data!$C$3:$C$60) -> 46002 | J31: 2 | K31: =I31+J31 -> 46004 | M31: 1 | N31: =_xlfn.LET( _xlpm.s,VALUE($I31), _xlpm.e,VALUE($K31), IF(OR(_xlpm.s="",_xlpm.e=""),"", IF(_xlpm.e<=_xlpm.s, IF(TODAY()>=_xlpm.e,1,0), MAX(0,MIN(1,(TODAY()-_xlpm.s)/(_xlpm.e-_xlpm.s))))) ) -> 1
B32: 4.3 | C32: DC Cable delivered | E32: =E30 -> 46001 | F32: 1 | G32: =WORKDAY.INTL(E32,F32,1,Data!$C$3:$C$60) -> 46002 | I32: =I30 -> 46001 | J32: 1 | K32: =WORKDAY.INTL(I32,J32,1,Data!$C$3:$C$60) -> 46002 | M32: 1 | N32: =_xlfn.LET( _xlpm.s,VALUE($I32), _xlpm.e,VALUE($K32), IF(OR(_xlpm.s="",_xlpm.e=""),"", IF(_xlpm.e<=_xlpm.s, IF(TODAY()>=_xlpm.e,1,0), MAX(0,MIN(1,(TODAY()-_xlpm.s)/(_xlpm.e-_xlpm.s))))) ) -> 1
B33: 4.4 | C33: DC Stringing | E33: =WORKDAY.INTL(G37,0,1,Data!$C$3:$C$60)-3 -> 46048 | F33: 4 | G33: =WORKDAY.INTL(E33,F33,1,Data!$C$3:$C$60) -> 46052 | I33: 46042 | J33: 4 | K33: =WORKDAY.INTL(I33,J33,1,Data!$C$3:$C$60) -> 46048 | M33: 1 | N33: =_xlfn.LET( _xlpm.s,VALUE($I33), _xlpm.e,VALUE($K33), IF(OR(_xlpm.s="",_xlpm.e=""),"", IF(_xlpm.e<=_xlpm.s, IF(TODAY()>=_xlpm.e,1,0), MAX(0,MIN(1,(TODAY()-_xlpm.s)/(_xlpm.e-_xlpm.s))))) ) -> 1
B35: 5 | C35: Module installation | E35: =MIN(E36:E38) -> 46001 | F35: =G35-E35 -> 50 | G35: =MAX(G36:G38) -> 46051 | I35: =MIN(I36:I38) -> 46001 | J35: =K35-I35 -> 50 | K35: =MAX(K36:K38) -> 46051 | M35: =(J36*M36+J37*M37)/SUM(J36:J37) -> 1 | N35: =(K36*N36+K37*N37)/SUM(K36:K37) -> 1
B36: 5.1 | C36: Module delivery | E36: 46001 | F36: 1 | G36: =WORKDAY.INTL(E36,F36,1,Data!$C$3:$C$60) -> 46002 | I36: 46001 | J36: 1 | K36: =WORKDAY.INTL(I36,J36,1,Data!$C$3:$C$60) -> 46002 | M36: 1 | N36: =_xlfn.LET( _xlpm.s,VALUE($I36), _xlpm.e,VALUE($K36), IF(OR(_xlpm.s="",_xlpm.e=""),"", IF(_xlpm.e<=_xlpm.s, IF(TODAY()>=_xlpm.e,1,0), MAX(0,MIN(1,(TODAY()-_xlpm.s)/(_xlpm.e-_xlpm.s))))) ) -> 1
B37: 5.2 | C37: Module mounting | E37: =G31 -> 46004 | F37: 9 | G37: =WORKDAY.INTL(E37,F37,1,Data!$C$3:$C$60) -> 46051 | I37: =K31 -> 46004 | J37: 9 | K37: =WORKDAY.INTL(I37,J37,1,Data!$C$3:$C$60) -> 46051 | M37: 1 | N37: =_xlfn.LET( _xlpm.s,VALUE($I37), _xlpm.e,VALUE($K37), IF(OR(_xlpm.s="",_xlpm.e=""),"", IF(_xlpm.e<=_xlpm.s, IF(TODAY()>=_xlpm.e,1,0), MAX(0,MIN(1,(TODAY()-_xlpm.s)/(_xlpm.e-_xlpm.s))))) ) -> 1
B39: 6 | C39: Commissioning | E39: =MIN(E40:E43) -> 46062 | F39: =G39-E39 -> 9 | G39: =MAX(G40:G43) -> 46071 | I39: =MIN(I40:I43) -> 46051 | J39: =K39-I39 -> 8 | K39: =MAX(K40:K43) -> 46059 | M39: =(J40*M40+J41*M41+J42*M42)/SUM(J40:J42) -> 0.59285714 | N39: =(K40*N40+K41*N41)/SUM(K40:K41) -> 1
B40: 6.1 | C40: Commissioning | E40: =WORKDAY.INTL(MAX(G21,G28,G35),0,1,Data!$C$3:$C$60) -> 46062 | F40: 1 | G40: =WORKDAY.INTL(E40,F40,1,Data!$C$3:$C$60) -> 46063 | I40: 46051 | J40: 1 | K40: =WORKDAY.INTL(I40,J40,1,Data!$C$3:$C$60) -> 46052 | M40: 1 | N40: =_xlfn.LET( _xlpm.s,VALUE($I40), _xlpm.e,VALUE($K40), IF(OR(_xlpm.s="",_xlpm.e=""),"", IF(_xlpm.e<=_xlpm.s, IF(TODAY()>=_xlpm.e,1,0), MAX(0,MIN(1,(TODAY()-_xlpm.s)/(_xlpm.e-_xlpm.s))))) ) -> 1
B41: 6.2 | C41: Practical Completion | E41: =WORKDAY.INTL(G40,0,1,Data!$C$3:$C$60) -> 46063 | F41: 1 | G41: =WORKDAY.INTL(E41,F41,1,Data!$C$3:$C$60) -> 46064 | I41: 46051 | J41: 1 | K41: =WORKDAY.INTL(I41,J41,1,Data!$C$3:$C$60) -> 46052 | M41: 1 | N41: =_xlfn.LET( _xlpm.s,VALUE($I41), _xlpm.e,VALUE($K41), IF(OR(_xlpm.s="",_xlpm.e=""),"", IF(_xlpm.e<=_xlpm.s, IF(TODAY()>=_xlpm.e,1,0), MAX(0,MIN(1,(TODAY()-_xlpm.s)/(_xlpm.e-_xlpm.s))))) ) -> 1
B42: 6.3 | C42: System Performance Monitoring | E42: =WORKDAY.INTL(G41,0,1,Data!$C$3:$C$60) -> 46064 | F42: 5 | G42: =WORKDAY.INTL(E42,F42,1,Data!$C$3:$C$60) -> 46071 | I42: =WORKDAY.INTL(K41,0,1,Data!$C$3:$C$60) -> 46052 | J42: 5 | K42: =WORKDAY.INTL(I42,J42,1,Data!$C$3:$C$60) -> 46059 | M42: 0.43 | N42: =_xlfn.LET( _xlpm.s,VALUE($I42), _xlpm.e,VALUE($K42), IF(OR(_xlpm.s="",_xlpm.e=""),"", IF(_xlpm.e<=_xlpm.s, IF(TODAY()>=_xlpm.e,1,0), MAX(0,MIN(1,(TODAY()-_xlpm.s)/(_xlpm.e-_xlpm.s))))) ) -> 1
B44: 7 | C44: QA Inspections | E44: =MIN(E45:E47) -> 46064 | F44: =G44-E44 -> 8 | G44: =MAX(G45:G47) -> 46072 | I44: =MIN(I45:I47) -> 46058 | J44: =K44-I44 -> 8 | K44: =MAX(K45:K47) -> 46066 | M44: =(J45*M45+J46*M46)/SUM(J45:J46) -> 0 | N44: =(K45*N45)/SUM(K45) -> 1
B45: 7.1 | C45: Red-Team Inspection | E45: =WORKDAY.INTL(E42,0,1,Data!$C$3:$C$60) -> 46064 | F45: 3 | G45: =WORKDAY.INTL(E45,F45,1,Data!$C$3:$C$60) -> 46069 | I45: 46058 | J45: 3 | K45: =WORKDAY.INTL(I45,J45,1,Data!$C$3:$C$60) -> 46063 | M45: 0 | N45: =_xlfn.LET( _xlpm.s,VALUE($I45), _xlpm.e,VALUE($K45), IF(OR(_xlpm.s="",_xlpm.e=""),"", IF(_xlpm.e<=_xlpm.s, IF(TODAY()>=_xlpm.e,1,0), MAX(0,MIN(1,(TODAY()-_xlpm.s)/(_xlpm.e-_xlpm.s))))) ) -> 1
...

Sheet Revenue Tracking
B2: HIGH LEVEL PROJECT REVENUE TRACKING | U2: 2026 Budget Revenue | V2: 2026 Budget COS | W2: 2026 Actual Revenue | X2: 2026 Actual COS
D3: COSTED | F3: ACTUAL | L3: FINANCIAL REVIEW | N3: TIMELINE REVIEW | U3: =D4 -> 1364882.4 | V3: =D5 -> 1114901.6 | W3: =SUMIFS('Expenditure Breakdown'!$U:$U, 'Expenditure Breakdown'!$T:$T, ">"&DATE(2025,8,31), 'Expenditure Breakdown'!$T:$T, "<="&DATE(2026,8,31), 'Expenditure Breakdown'!$S:$S, "<>") -> 1038243.5 | X3: =SUMIFS('Expenditure Breakdown'!$Q:$Q, 'Expenditure Breakdown'!$T:$T, ">"&DATE(2025,8,31), 'Expenditure Breakdown'!$T:$T, "<="&DATE(2026,8,31), 'Expenditure Breakdown'!$S:$S, "<>") -> 684555.7
B4: 1 | C4: Planned Revenue | D4: ='Project Plan'!E6 -> 1364882.4 | F4: =F21 -> 1364882.4 | L4: 1364882.4 | N4: Start Date
B5: 2 | C5: Planned Expenditure | D5: =+'Expenditure Tracking'!F5 -> 1114901.6 | F5: =+'Expenditure Tracking'!H5 -> 948906.4 | G5: VO PM LIMIT | H5: CURRENT VO Total | L5: 979941.98 | N5: 46001
B6: 3 | C6: Planned Profit | D6: =+D4-D5 -> 249980.81 | F6: =+F4-F5 -> 415975.98 | G6: =D6*0.05 -> 12499.04 | H6: =SUMIF('Expenditure Breakdown'!N:N,"*VO*",'Expenditure Breakdown'!Q:Q) -> 33897 | L6: 384940.4 | N6: End Date - PC
B7: 4 | C7: Planned Margin | D7: =+D6/D4 -> 0.1831519 | F7: =+F6/F4 -> 0.30477057 | L7: 0.28203192 | N7: 46071
B10: CONTRACT
B12: No. | C12: PAYMENT MILESTONE | E12: % | F12: VALUE | H12: PLANNED PAYMENT DATE | L12: INVOICE NUMBER | N12: INVOICE RAISED DATE | P12: PAYMENT RECEIVED DATE | R12: MILESTONE NOTES & COMMENTS | S12: MILESTONE DOCUMENTS RECEIVED
B13: 1 | C13: Signature of this Proposal, receipt of solar panels on site. | E13: 0.4 | F13: =$D$4*E13 -> 545952.95 | H13: 45975 | L13: 004809 | N13: 45880 | P13: 45974 | S13: TRUE | AP13: ='Change Register'!$Q$14+ 7 -> 7
B14: 2 | C14: Receipt of inverters of site | E14: 0.4 | F14: =$D$4*E14 -> 545952.95 | H14: ='Project Plan'!G22+7 -> 46009 | L14: 004902 | N14: 46006 | P14: 46069 | R14: Delivery note has been submitted for payment, Bank is waiting on Client to submit paperwork | S14: FALSE
B15: 3 | C15: All provisional test successful finalised, and documentation provided. | E15: 0.2 | F15: =$D$4*E15 -> 272976.48 | H15: ='Project Plan'!G50+7 -> 46086 | P15: ='Project Plan'!K50+7 -> 46080 | S15: FALSE
B16: 4 | C16: - | E16: 0 | F16: =$D$4*E16 -> 0 | S16: FALSE
B17: 5 | C17: - | E17: 0 | F17: =$D$4*E17 -> 0 | S17: FALSE
B18: 6 | C18: - | E18: 0 | F18: =$D$4*E18 -> 0 | S18: FALSE
B19: 7 | C19: - | E19: 0 | F19: =$D$4*E19 -> 0 | S19: FALSE
E21: =SUM(E13:E19) -> 1 | F21: =SUM(F13:F19) -> 1364882.4
B23: KEY: | C23: contains an error (in result or a check has failed)
C24: Red Font - IF TEXT : content not yet confirmed
C25: Red Font - IF NUMBER: Negative value
C26: Anything in yellow is a concern or risk for noting or action
C27: confirmed
C28: [ADD INITIALS: comment for noting in square brackets, use colour or red to draw attention if important]
C29: [RT: When adding rows into sheet, ensure you insert between first and last row of each category]
C30: end of sheet - do not insert information below/beyond this
B40: No. | C40: PAYMENT MILESTONE | E40: % | F40: VALUE
B41: 1 | C41: Deposit - Project commencement | E41: 0.35 | F41: =$F$47*E41 -> 477708.83
B42: 2 | C42: Delivery of Panels | E42: 0.3 | F42: =$F$47*E42 -> 409464.71
B43: 3 | C43: Delivery of Inverters | E43: 0.2 | F43: =$F$47*E43 -> 272976.48
B44: 4 | C44: Practical Completion | E44: 0.1 | F44: =$F$47*E44 -> 136488.24
B45: 5 | C45: Handover | E45: 0.05 | F45: =$F$47*E45 -> 68244.119
C46: Total | E46: =SUM(E41:E45) -> 1 | F46: =SUM(F41:F45) -> 1364882.4
E47: =SUM(E41:E45) -> 1 | F47: =F21 -> 1364882.4

Sheet Expenditure Tracking
B2: HIGH LEVEL PROJECT EXPENDITURE TRACKING
F4: COSTED | H4: ACTUAL | J4: Difference from Costed
B5: EXPENDITURE | F5: =SUM(F9:F23) -> 1114901.6 | H5: =SUM(H9:H23) -> 948906.4 | J5: =SUM(J9:J23) -> 165995.18
B7: No. | D7: Item | F7: Costed Expenditure | H7: Actual Expenditure | J7: Saving / Overrun | L7: Comments on variations from planned expenditure
B9: ='Expenditure Breakdown'!L6 -> 1 | D9: ='Expenditure Breakdown'!M6 -> 1. Panels | F9: ='Expenditure Breakdown'!I6 -> 388678.39 | H9: ='Expenditure Breakdown'!X6 -> 306891 | J9: =F9-H9 -> 81787.388
B10: ='Expenditure Breakdown'!L13 -> 2 | D10: ='Expenditure Breakdown'!M13 -> 2. Inverters | F10: ='Expenditure Breakdown'!I13 -> 120000 | H10: ='Expenditure Breakdown'!X13 -> 112476.43 | J10: =F10-H10 -> 7523.57
B11: ='Expenditure Breakdown'!L21 -> 3 | D11: ='Expenditure Breakdown'!M21 -> 3. Mounting Structures | F11: ='Expenditure Breakdown'!I21 -> 70821 | H11: ='Expenditure Breakdown'!X21 -> 27727.27 | J11: =F11-H11 -> 43093.73
B12: ='Expenditure Breakdown'!L31 -> 4 | D12: ='Expenditure Breakdown'!M31 -> 4. DC Equipment | F12: ='Expenditure Breakdown'!I31 -> 151607.8 | H12: ='Expenditure Breakdown'!X31 -> 96009.97 | J12: =F12-H12 -> 55597.83
B13: ='Expenditure Breakdown'!L47 -> 5 | D13: ='Expenditure Breakdown'!M47 -> 5. Monitoring | F13: ='Expenditure Breakdown'!I47 -> 0 | H13: ='Expenditure Breakdown'!X47 -> 11530.85 | J13: =F13-H13 -> -11530.85
B14: ='Expenditure Breakdown'!L55 -> 6 | D14: ='Expenditure Breakdown'!M55 -> 6. AC Equipment | F14: ='Expenditure Breakdown'!I55 -> 139985.95 | H14: ='Expenditure Breakdown'!X55 -> 144028 | J14: =F14-H14 -> -4042.0522
B15: ='Expenditure Breakdown'!L73 -> 7 | D15: ='Expenditure Breakdown'!M73 -> 7.BESS | F15: ='Expenditure Breakdown'!I73 -> 0 | H15: ='Expenditure Breakdown'!X73 -> 0 | J15: =F15-H15 -> 0
B16: ='Expenditure Breakdown'!L82 -> 8 | D16: ='Expenditure Breakdown'!M82 -> 8. Product Add On | F16: ='Expenditure Breakdown'!I82 -> 34428 | H16: ='Expenditure Breakdown'!X82 -> 36548 | J16: =F16-H16 -> -2120
B17: ='Expenditure Breakdown'!L92 -> 9 | D17: ='Expenditure Breakdown'!M92 -> 9. AC & DC installation | F17: ='Expenditure Breakdown'!I92 -> 125130 | H17: ='Expenditure Breakdown'!X92 -> 135346.8 | J17: =F17-H17 -> -10216.8
B18: ='Expenditure Breakdown'!L105 -> 10 | D18: ='Expenditure Breakdown'!M105 -> 10. Site Logistics | F18: ='Expenditure Breakdown'!I105 -> 39318.667 | H18: ='Expenditure Breakdown'!X105 -> 22311.8 | J18: =F18-H18 -> 17006.867
B19: ='Expenditure Breakdown'!L121 -> 11 | D19: ='Expenditure Breakdown'!M121 -> 11. Due Dilligence | F19: ='Expenditure Breakdown'!I121 -> 29000 | H19: ='Expenditure Breakdown'!X121 -> 18577.5 | J19: =F19-H19 -> 10422.5
B20: ='Expenditure Breakdown'!L127 -> 12 | D20: ='Expenditure Breakdown'!M127 -> 12. BDP Commission | F20: ='Expenditure Breakdown'!I127 -> 0 | H20: ='Expenditure Breakdown'!X127 -> 0 | J20: =F20-H20 -> 0
B21: ='Expenditure Breakdown'!L130 -> 13 | D21: ='Expenditure Breakdown'!M131 -> 13. Engineering | F21: ='Expenditure Breakdown'!I130 -> 13306.773 | H21: ='Expenditure Breakdown'!X130 -> 0 | J21: =F21-H21 -> 13306.773
B22: ='Expenditure Breakdown'!L137 -> 14 | D22: ='Expenditure Breakdown'!M137 -> 14. General Expenses | F22: ='Expenditure Breakdown'!I137 -> 2625 | H22: ='Expenditure Breakdown'!X137 -> 3111.78 | J22: =F22-H22 -> -486.78
B23: ='Expenditure Breakdown'!L150 -> 15 | D23: ='Expenditure Breakdown'!M150 -> 15. Service Add On | F23: ='Expenditure Breakdown'!I150 -> 0 | H23: ='Expenditure Breakdown'!X150 -> 34347 | J23: =F23-H23 -> -34347
D25: check: | F25: ='Expenditure Breakdown'!I2-'Expenditure Tracking'!F5 -> 0 | G25: =#REF!-G5 -> #REF! | H25: ='Expenditure Breakdown'!X2-H5 -> 0

Sheet Expenditure Breakdown
B2: COSTED EXPENDITURE BREAKDOWN | I2: =SUM(I6:I162) -> 1114901.6 | J2: =SUM(J6:J162) -> 1364882.4 | L2: ACTUAL EXPENDITURE BREAKDOWN | R2: FINANCE ONLY | X2: =SUM(X6:X162) -> 948906.4
B4: No. | C4: Product / Service | D4: Description of Work | E4: QTY | F4: Rate / Unit | G4: Budget Total | H4: FORECASTED PAYMENT DATE | I4: Total COS | J4: =IF(J2-'Revenue Tracking'!D4>=0, "Total Revenue", "ERROR on REV" ) -> ERROR on REV | L4: No. | M4: Product/ Service | N4: Description of Work | O4: QTY | P4: Rate / Unit | Q4: Actual Total | R4: PO NUMBER | S4: INVOICE NUMBER | T4: INVOICE RAISED DATE | U4: REVENUE RECOGNITION AMOUNT | V4: CHECK | W4: FINANCE PAYMENT DATE | X4: Total COS
B6: 1 | C6: Panels | D6: Panels Budget | G6: =D163 -> 388678.39 | H6: ='Project Plan'!E36+60 -> 46061 | I6: =SUM(G6:G11) -> 388678.39 | J6: =F163 -> 485847.99 | L6: 1 | M6: 1. Panels | N6: Jinko 610W - JKM610N-72HL4M-BDV | O6: 258 | P6: 1189.5 | Q6: =O6*P6 -> 306891 | S6: MSA Energy - INV0003484 | T6: 46022 | U6: 485847.99 | V6: =J6-SUM(U6:U11) -> 0 | W6: 46057 | X6: =SUM(Q6:Q11) -> 306891
B7: 1 | D7: Delivery Budget | L7: 1 | M7: 1. Panels | T7: =IF(W7>1,EOMONTH(W7,0),"") | U7: 0
B8: 1 | L8: 1 | M8: 1. Panels | T8: =IF(W8>1,EOMONTH(W8,0),"") | U8: 0
B9: 1 | L9: 1 | M9: 1. Panels | T9: =IF(W9>1,EOMONTH(W9,0),"") | U9: 0
B10: 1 | L10: 1 | M10: 1. Panels | T10: =IF(W10>1,EOMONTH(W10,0),"") | U10: 0
B11: 1 | L11: 1 | M11: 1. Panels | T11: =IF(W11>1,EOMONTH(W11,0),"") | U11: 0 | Y11: BUDGET | Z11: Installer Allocation
T12: =IF(W12>1,EOMONTH(W12,0),"") | Y12: AC Equipment | Z12: =G55 -> 139985.95
B13: 2 | C13: Inverters | D13: Inverter Budget | G13: =D164 -> 120000 | H13: ='Project Plan'!E22+60 -> 46061 | I13: =SUM(G13:G19) -> 120000 | J13: =F164 -> 150000 | L13: 2 | M13: 2. Inverters | N13: Huawei 100KTL | O13: 1 | P13: 68870.35 | Q13: =O13*P13 -> 68870.35 | S13: =S6 -> MSA Energy - INV0003484 | T13: =T6 -> 46022 | U13: 91846.376 | V13: =J13-SUM(U13:U19) -> 0 | W13: =W6 -> 46057 | X13: =SUM(Q13:Q19) -> 112476.43 | Y13: DC Equipment | Z13: =G32 -> 100395.8
B14: 2 | L14: 2 | M14: 2. Inverters | N14: Huawei 50KTL | O14: 1 | P14: 43606.08 | Q14: =O14*P14 -> 43606.08 | S14: =S6 -> MSA Energy - INV0003484 | T14: =T6 -> 46022 | U14: 58153.624 | W14: =W13 -> 46057 | Y14: AC Labour | Z14: =G92 -> 39345
B15: 2 | L15: 2 | M15: 2. Inverters | T15: =IF(W15>1,EOMONTH(W15,0),"") | U15: 0 | Y15: DC Labour | Z15: =G93 -> 85785
B16: 2 | L16: 2 | M16: 2. Inverters | T16: =IF(W16>1,EOMONTH(W16,0),"") | U16: 0 | Y16: Offloading | Z16: =G105 -> 8500
B17: 2 | L17: 2 | M17: 2. Inverters | T17: =IF(W17>1,EOMONTH(W17,0),"") | U17: 0 | Y17: Scaffolding | Z17: =G106 -> 12818.667
B18: 2 | L18: 2 | M18: 2. Inverters | T18: =IF(W18>1,EOMONTH(W18,0),"") | U18: 0 | Y18: Storage | Z18: =G108 -> 0
B19: 2 | L19: 2 | M19: 2. Inverters | T19: =IF(W19>1,EOMONTH(W19,0),"") | U19: 0 | Y19: Telehandler | Z19: 0
T20: =IF(W20>1,EOMONTH(W20,0),"")
B21: 3 | C21: Mounting Structures | D21: Structure Budget | G21: =D165 -> 70821 | H21: ='Project Plan'!E30+30 -> 46031 | I21: =SUM(G21:G29) -> 70821 | J21: =F165 -> 88526.25 | L21: 3 | M21: 3. Mounting Structures | N21: Clamp fit Pro - From stock refer to stocksheet | O21: 600 | P21: 26.47 | Q21: =O21*P21 -> 15882 | S21: Allocated from PE Storetoom | T21: 46053 | U21: 61736.99 | V21: =J21-SUM(U21:U29) -> -0.0041899532 | W21: 46053 | X21: =SUM(Q21:Q29) -> 27727.27 | Y21: Other | Z21: 0
B22: 3 | L22: 3 | M22: 3. Mounting Structures | N22: Mid Clamps - From stock - refer to stocksheet | O22: 201 | P22: 12.31 | Q22: =O22*P22 -> 2474.31 | S22: Allocated from PE Storetoom | T22: 46053 | U22: 7899.854 | W22: 46053 | Y22: Total | Z22: =SUM(Z12:Z21) -> 386830.41
L23: 3 | M23: 3. Mounting Structures | N23: Mid Clamps - From stock - refer to stocksheet | O23: 184 | P23: 14.19 | Q23: =O23*P23 -> 2610.96 | S23: Allocated from PE Storeroom | T23: 46053 | U23: 8336.1434 | W23: 46053
L24: 3 | M24: 3. Mounting Structures | N24: End Clamps - From stock - refer to stocksheet | O24: 100 | P24: 12.68 | Q24: =O24*P24 -> 1268 | S24: Allocated from PE Storetoom | T24: 46053 | U24: 4048.4074 | W24: 46053
L25: 3 | M25: 3. Mounting Structures
B26: 3 | L26: 3 | M26: 3. Mounting Structures | N26: Balance of Equipment | Q26: 5492 | R26: PO4526-SSDPH2-20251208 - RV Approved | S26: Schletter - INV2520 | T26: 46022 | U26: 6504.8589 | W26: 46021 | Y26: Less 15% | Z26: =+Z22*0.85 -> 328805.85
B27: 3 | L27: 3 | M27: 3. Mounting Structures | T27: =IF(W27>1,EOMONTH(W27,0),"") | U27: =(Q27/$X$21*$J$21) -> 0 | Y27: R/Wp | Z27: =Z26/'Project Plan'!$E$3/1000 -> 2.0943048
B28: 3 | L28: 3 | M28: 3. Mounting Structures | T28: =IF(W28>1,EOMONTH(W28,0),"") | U28: =(Q28/$X$21*$J$21) -> 0
B29: 3 | L29: 3 | M29: 3. Mounting Structures | T29: =IF(W29>1,EOMONTH(W29,0),"") | U29: =(Q29/$X$21*$J$21) -> 0 | Y29: ACTUAL | Z29: Installer Price
T30: =IF(W30>1,EOMONTH(W30,0),"") | Y30: =Y12 -> AC Equipment | Z30: 62952
B31: 4 | C31: DC Equipment | D31: DC Cable Budget | E31: 3658 | G31: 51212 | H31: ='Project Plan'!E32+60 -> 46061 | I31: =SUM(G31:G45) -> 151607.8 | J31: =F166 -> 189509.75 | L31: 4 | M31: 4. DC Equipment | N31: DC Cable - from Standard Bank GQ | O31: 2000 | P31: 14 | Q31: =O31*P31 -> 28000 | S31: Allocated from Std Bank GQ | T31: 46053 | U31: 55267.937 | V31: =J31-SUM(U31:U45) -> 0.0045400532 | W31: 46053 | X31: =SUM(Q31:Q45) -> 96009.97 | Y31: =Y13 -> DC Equipment | Z31: 39345
B32: 4 | D32: DC Equipment Budget | G32: =D166-G31 -> 100395.8 | H32: ='Project Plan'!G28 -> 46052 | L32: 4 | M32: 4. DC Equipment | O32: 2000 | P32: 14 | Q32: =O32*P32 -> 28000 | S32: Allocated from Std Bank GQ | T32: 46053 | U32: 55267.937 | W32: 46053 | Y32: =Y14 -> AC Labour | Z32: 40918.8
B33: 4 | L33: 4 | M33: 4. DC Equipment | N33: Courier | Q33: 664.97 | S33: DSV Inv:180161978 | T33: 46053 | U33: 969.91429 | W33: 46079 | Y33: =Y15 -> DC Labour | Z33: 94428
B34: 4 | L34: 4 | M34: 4. DC Equipment | T34: =IF(W34>1,EOMONTH(W34,0),"") | U34: =(Q34/$X$31*$J$31) -> 0 | Y34: Lifting & Logistics | Z34: 17311.8
B35: 4 | L35: 4 | M35: 4. DC Equipment | N35: Project Kick Off | O35: =Z31 -> 39345 | P35: 0.1 | Q35: =$O$35*P35 -> 3934.5 | R35: PO4523-SSDPH2-20251208 - RV Approved | S35: =S93 -> BDL Solar- IN000763 | T35: =T93 -> 46022 | U35: 7903.1863 | W35: =W93 -> 46003 | Y35: HSE | Z35: 5000
B36: 4 | L36: 4 | M36: 4. DC Equipment | N36: Site Establishment | P36: 0.15 | Q36: =$O$35*P36 -> 5901.75 | S36: =S62 -> BDL Solar- IN000764 | T36: =T94 -> 46022 | U36: 11854.779 | W36: =W94 -> 46003 | Y36: Geda | Z36: 0
B37: 4 | L37: 4 | M37: 4. DC Equipment | N37: AC Installation Complete | P37: 0.2 | Q37: =$O$35*P37 -> 7869 | T37: =T95 -> 46081 | U37: =(Q37/$X$31*$J$31) -> 15532.264 | W37: =W95 -> 46066 | Y37: Logistics | Z37: 0
B38: 4 | L38: 4 | M38: 4. DC Equipment | N38: DC Installation Complete | P38: 0.25 | Q38: =$O$35*P38 -> 9836.25 | T38: =T96 -> 46081 | U38: =(Q38/$X$31*$J$31) -> 19415.33 | W38: =W96 -> 46062 | Y38: HSE | Z38: 0
B39: 4 | L39: 4 | M39: 4. DC Equipment | N39: Commissioning Complete | P39: 0.1 | Q39: =$O$35*P39 -> 3934.5 | T39: =T97 -> 46081 | U39: =(Q39/$X$31*$J$31) -> 7766.1321 | W39: =W97 -> 46069 | Y39: Other | Z39: 0
B40: 4 | L40: 4 | M40: 4. DC Equipment | N40: Site De-establisment | P40: 0.1 | Q40: =$O$35*P40 -> 3934.5 | T40: =T98 -> 46081 | U40: =(Q40/$X$31*$J$31) -> 7766.1321 | W40: =W98 -> 46076 | Y40: Other | Z40: 0
B41: 4 | L41: 4 | M41: 4. DC Equipment | N41: Handover Document Complete | P41: 0.05 | Q41: =$O$35*P41 -> 1967.25 | T41: =T99 -> 46112 | U41: =(Q41/$X$31*$J$31) -> 3883.0661 | W41: =W99 -> 46083 | Y41: Total | Z41: =SUM(Z30:Z40) -> 259955.6
B42: 4 | L42: 4 | M42: 4. DC Equipment | N42: End of Defects Period | P42: 0.05 | Q42: =$O$35*P42 -> 1967.25 | T42: =T100 -> 46142 | U42: =(Q42/$X$31*$J$31) -> 3883.0661 | W42: =W100 -> 46113 | Y42: R/Wp | Z42: =Z41/'Project Plan'!$E$3/1000 -> 1.6557682
B43: 4 | L43: 4 | M43: 4. DC Equipment | T43: =IF(W43>1,EOMONTH(W43,0),"") | U43: =(Q43/$X$31*$J$31) -> 0
...

Sheet Cashflow
D1: [RT: Double Check the first date is always a MONDAY] | F1: 45971 | G1: =F1+7 -> 45978 | H1: =G1+7 -> 45985 | I1: =H1+7 -> 45992 | J1: =I1+7 -> 45999 | K1: =J1+7 -> 46006 | L1: =K1+7 -> 46013 | M1: =L1+7 -> 46020 | N1: =M1+7 -> 46027 | ... KF1: =KE1+7 -> 47973
A2: PLANNED | C2: CHECK | D2: CHECK
B3: Planned Revenue | C3: ='Revenue Tracking'!D4 -> 1364882.4 | D3: =SUM(F3:KF3) -> 1364882.4 | F3: =SUMIFS('Revenue Tracking'!$F$13:$F$19, 'Revenue Tracking'!$H$13:$H$19, ">="&F1,'Revenue Tracking'!$H$13:$H$19, "<"&G1) -> 545952.95 | G3: =SUMIFS('Revenue Tracking'!$F$13:$F$19, 'Revenue Tracking'!$H$13:$H$19, ">="&G1,'Revenue Tracking'!$H$13:$H$19, "<"&H1) -> 0 | H3: =SUMIFS('Revenue Tracking'!$F$13:$F$19, 'Revenue Tracking'!$H$13:$H$19, ">="&H1,'Revenue Tracking'!$H$13:$H$19, "<"&I1) -> 0 | I3: =SUMIFS('Revenue Tracking'!$F$13:$F$19, 'Revenue Tracking'!$H$13:$H$19, ">="&I1,'Revenue Tracking'!$H$13:$H$19, "<"&J1) -> 0 | J3: =SUMIFS('Revenue Tracking'!$F$13:$F$19, 'Revenue Tracking'!$H$13:$H$19, ">="&J1,'Revenue Tracking'!$H$13:$H$19, "<"&K1) -> 0 | K3: =SUMIFS('Revenue Tracking'!$F$13:$F$19, 'Revenue Tracking'!$H$13:$H$19, ">="&K1,'Revenue Tracking'!$H$13:$H$19, "<"&L1) -> 545952.95 | L3: =SUMIFS('Revenue Tracking'!$F$13:$F$19, 'Revenue Tracking'!$H$13:$H$19, ">="&L1,'Revenue Tracking'!$H$13:$H$19, "<"&M1) -> 0 | M3: =SUMIFS('Revenue Tracking'!$F$13:$F$19, 'Revenue Tracking'!$H$13:$H$19, ">="&M1,'Revenue Tracking'!$H$13:$H$19, "<"&N1) -> 0 | ... KE3: =SUMIFS('Revenue Tracking'!$F$13:$F$19, 'Revenue Tracking'!$H$13:$H$19, ">="&KE1,'Revenue Tracking'!$H$13:$H$19, "<"&KF1) -> 0 | KF3: =SUMIFS('Revenue Tracking'!$F$13:$F$19, 'Revenue Tracking'!$H$13:$H$19, ">="&KF1,'Revenue Tracking'!$H$13:$H$19, "<"&#REF!) -> 0
B4: Planned Revenue - Cumulative | F4: =F3 -> 545952.95 | G4: =F4+G3 -> 545952.95 | H4: =G4+H3 -> 545952.95 | I4: =H4+I3 -> 545952.95 | J4: =I4+J3 -> 545952.95 | K4: =J4+K3 -> 1091905.9 | L4: =K4+L3 -> 1091905.9 | M4: =L4+M3 -> 1091905.9 | N4: =M4+N3 -> 1091905.9 | ... KF4: =KE4+KF3 -> 1364882.4
B5: Planned Expenditure | C5: ='Revenue Tracking'!D5 -> 1114901.6 | D5: =SUM(F5:KF5) -> 1114901.6 | F5: =SUMIFS('Expenditure Breakdown'!$G$6:$G$169, 'Expenditure Breakdown'!$H$6:$H$169, ">="&F1,'Expenditure Breakdown'!$H$6:$H$169, "<"&G1) -> 0 | G5: =SUMIFS('Expenditure Breakdown'!$G$6:$G$169, 'Expenditure Breakdown'!$H$6:$H$169, ">="&G1,'Expenditure Breakdown'!$H$6:$H$169, "<"&H1) -> 0 | H5: =SUMIFS('Expenditure Breakdown'!$G$6:$G$169, 'Expenditure Breakdown'!$H$6:$H$169, ">="&H1,'Expenditure Breakdown'!$H$6:$H$169, "<"&I1) -> 0 | I5: =SUMIFS('Expenditure Breakdown'!$G$6:$G$169, 'Expenditure Breakdown'!$H$6:$H$169, ">="&I1,'Expenditure Breakdown'!$H$6:$H$169, "<"&J1) -> 0 | J5: =SUMIFS('Expenditure Breakdown'!$G$6:$G$169, 'Expenditure Breakdown'!$H$6:$H$169, ">="&J1,'Expenditure Breakdown'!$H$6:$H$169, "<"&K1) -> 0 | K5: =SUMIFS('Expenditure Breakdown'!$G$6:$G$169, 'Expenditure Breakdown'!$H$6:$H$169, ">="&K1,'Expenditure Breakdown'!$H$6:$H$169, "<"&L1) -> 0 | L5: =SUMIFS('Expenditure Breakdown'!$G$6:$G$169, 'Expenditure Breakdown'!$H$6:$H$169, ">="&L1,'Expenditure Breakdown'!$H$6:$H$169, "<"&M1) -> 0 | M5: =SUMIFS('Expenditure Breakdown'!$G$6:$G$169, 'Expenditure Breakdown'!$H$6:$H$169, ">="&M1,'Expenditure Breakdown'!$H$6:$H$169, "<"&N1) -> 0 | ... KE5: =SUMIFS('Expenditure Breakdown'!$G$6:$G$169, 'Expenditure Breakdown'!$H$6:$H$169, ">="&KE1,'Expenditure Breakdown'!$H$6:$H$169, "<"&KF1) -> 0 | KF5: =SUMIFS('Expenditure Breakdown'!$G$6:$G$169, 'Expenditure Breakdown'!$H$6:$H$169, ">="&KF1,'Expenditure Breakdown'!$H$6:$H$169, "<"&#REF!) -> 0
B6: Planned Expenditure - Cumulative | F6: =F5 -> 0 | G6: =F6+G5 -> 0 | H6: =G6+H5 -> 0 | I6: =H6+I5 -> 0 | J6: =I6+J5 -> 0 | K6: =J6+K5 -> 0 | L6: =K6+L5 -> 0 | M6: =L6+M5 -> 0 | N6: =M6+N5 -> 70821 | ... KF6: =KE6+KF5 -> 1114901.6
B7: PLANNED CashFlow | F7: =F4-F6 -> 545952.95 | G7: =G4-G6 -> 545952.95 | H7: =H4-H6 -> 545952.95 | I7: =I4-I6 -> 545952.95 | J7: =J4-J6 -> 545952.95 | K7: =K4-K6 -> 1091905.9 | L7: =L4-L6 -> 1091905.9 | M7: =M4-M6 -> 1091905.9 | ... KF7: =KF4-KF6 -> 249980.81
A8: ACTUAL | C8: CHECK | D8: CHECK
B9: Actual + Planned Revenue | C9: ='Revenue Tracking'!F4 -> 1364882.4 | D9: =SUM(F9:KF9) -> 1364882.4 | F9: =SUMIFS('Revenue Tracking'!$F$13:$F$19, 'Revenue Tracking'!$P$13:$P$19, ">="&F1,'Revenue Tracking'!$P$13:$P$19, "<"&G1) -> 545952.95 | G9: =SUMIFS('Revenue Tracking'!$F$13:$F$19, 'Revenue Tracking'!$P$13:$P$19, ">="&G1,'Revenue Tracking'!$P$13:$P$19, "<"&H1) -> 0 | H9: =SUMIFS('Revenue Tracking'!$F$13:$F$19, 'Revenue Tracking'!$P$13:$P$19, ">="&H1,'Revenue Tracking'!$P$13:$P$19, "<"&I1) -> 0 | I9: =SUMIFS('Revenue Tracking'!$F$13:$F$19, 'Revenue Tracking'!$P$13:$P$19, ">="&I1,'Revenue Tracking'!$P$13:$P$19, "<"&J1) -> 0 | J9: =SUMIFS('Revenue Tracking'!$F$13:$F$19, 'Revenue Tracking'!$P$13:$P$19, ">="&J1,'Revenue Tracking'!$P$13:$P$19, "<"&K1) -> 0 | K9: =SUMIFS('Revenue Tracking'!$F$13:$F$19, 'Revenue Tracking'!$P$13:$P$19, ">="&K1,'Revenue Tracking'!$P$13:$P$19, "<"&L1) -> 0 | L9: =SUMIFS('Revenue Tracking'!$F$13:$F$19, 'Revenue Tracking'!$P$13:$P$19, ">="&L1,'Revenue Tracking'!$P$13:$P$19, "<"&M1) -> 0 | M9: =SUMIFS('Revenue Tracking'!$F$13:$F$19, 'Revenue Tracking'!$P$13:$P$19, ">="&M1,'Revenue Tracking'!$P$13:$P$19, "<"&N1) -> 0 | ... KE9: =SUMIFS('Revenue Tracking'!$F$13:$F$19, 'Revenue Tracking'!$P$13:$P$19, ">="&KE1,'Revenue Tracking'!$P$13:$P$19, "<"&KF1) -> 0 | KF9: =SUMIFS('Revenue Tracking'!$F$13:$F$19, 'Revenue Tracking'!$P$13:$P$19, ">="&KF1,'Revenue Tracking'!$P$13:$P$19, "<"&#REF!) -> 0
B10: Actual + Planned Revenue - Cumulative | F10: =F9 -> 545952.95 | G10: =F10+G9 -> 545952.95 | H10: =G10+H9 -> 545952.95 | I10: =H10+I9 -> 545952.95 | J10: =I10+J9 -> 545952.95 | K10: =J10+K9 -> 545952.95 | L10: =K10+L9 -> 545952.95 | M10: =L10+M9 -> 545952.95 | N10: =M10+N9 -> 545952.95 | ... KF10: =KE10+KF9 -> 1364882.4
B11: Actual + Planned Expenditure | C11: ='Revenue Tracking'!F5 -> 948906.4 | D11: =SUM(F11:KF11) -> 948456.4 | F11: =SUMIFS('Expenditure Breakdown'!$Q$6:$Q$169, 'Expenditure Breakdown'!$W$6:$W$169, ">="&F1,'Expenditure Breakdown'!$W$6:$W$169, "<"&G1) -> 0 | G11: =SUMIFS('Expenditure Breakdown'!$Q$6:$Q$169, 'Expenditure Breakdown'!$W$6:$W$169, ">="&G1,'Expenditure Breakdown'!$W$6:$W$169, "<"&H1) -> 0 | H11: =SUMIFS('Expenditure Breakdown'!$Q$6:$Q$169, 'Expenditure Breakdown'!$W$6:$W$169, ">="&H1,'Expenditure Breakdown'!$W$6:$W$169, "<"&I1) -> 0 | I11: =SUMIFS('Expenditure Breakdown'!$Q$6:$Q$169, 'Expenditure Breakdown'!$W$6:$W$169, ">="&I1,'Expenditure Breakdown'!$W$6:$W$169, "<"&J1) -> 428.4 | J11: =SUMIFS('Expenditure Breakdown'!$Q$6:$Q$169, 'Expenditure Breakdown'!$W$6:$W$169, ">="&J1,'Expenditure Breakdown'!$W$6:$W$169, "<"&K1) -> 64988.9 | K11: =SUMIFS('Expenditure Breakdown'!$Q$6:$Q$169, 'Expenditure Breakdown'!$W$6:$W$169, ">="&K1,'Expenditure Breakdown'!$W$6:$W$169, "<"&L1) -> 0 | L11: =SUMIFS('Expenditure Breakdown'!$Q$6:$Q$169, 'Expenditure Breakdown'!$W$6:$W$169, ">="&L1,'Expenditure Breakdown'!$W$6:$W$169, "<"&M1) -> 0 | M11: =SUMIFS('Expenditure Breakdown'!$Q$6:$Q$169, 'Expenditure Breakdown'!$W$6:$W$169, ">="&M1,'Expenditure Breakdown'!$W$6:$W$169, "<"&N1) -> 5492 | ... KE11: =SUMIFS('Expenditure Breakdown'!$Q$6:$Q$169, 'Expenditure Breakdown'!$W$6:$W$169, ">="&KE1,'Expenditure Breakdown'!$W$6:$W$169, "<"&KF1) -> 0 | KF11: =SUMIFS('Expenditure Breakdown'!$Q$6:$Q$169, 'Expenditure Breakdown'!$W$6:$W$169, ">="&KF1,'Expenditure Breakdown'!$W$6:$W$169, "<"&#REF!) -> 0
B12: Actual + Planned Expenditure - Cumulative | F12: =F11 -> 0 | G12: =F12+G11 -> 0 | H12: =G12+H11 -> 0 | I12: =H12+I11 -> 428.4 | J12: =I12+J11 -> 65417.3 | K12: =J12+K11 -> 65417.3 | L12: =K12+L11 -> 65417.3 | M12: =L12+M11 -> 70909.3 | N12: =M12+N11 -> 71366.26 | ... KF12: =KE12+KF11 -> 948456.4
B14: ACTUAL CashFlow | F14: =F10-F12 -> 545952.95 | G14: =G10-G12 -> 545952.95 | H14: =H10-H12 -> 545952.95 | I14: =I10-I12 -> 545524.55 | J14: =J10-J12 -> 480535.65 | K14: =K10-K12 -> 480535.65 | L14: =L10-L12 -> 480535.65 | M14: =M10-M12 -> 475043.65 | ... KF14: =KF10-KF12 -> 416425.98
C16: CHECK | D16: CHECK
B17: Revenue Recognition | C17: =C3-D17 -> 0.0049043938 | D17: =SUM(F17:KF17) -> 1364882.4 | F17: =SUMIFS('Expenditure Breakdown'!$U$6:$U$169, 'Expenditure Breakdown'!$T$6:$T$169, ">="&F1,'Expenditure Breakdown'!$T$6:$T$169, "<"&G1) -> 0 | G17: =SUMIFS('Expenditure Breakdown'!$U$6:$U$169, 'Expenditure Breakdown'!$T$6:$T$169, ">="&G1,'Expenditure Breakdown'!$T$6:$T$169, "<"&H1) -> 0 | H17: =SUMIFS('Expenditure Breakdown'!$U$6:$U$169, 'Expenditure Breakdown'!$T$6:$T$169, ">="&H1,'Expenditure Breakdown'!$T$6:$T$169, "<"&I1) -> 521.24398 | I17: =SUMIFS('Expenditure Breakdown'!$U$6:$U$169, 'Expenditure Breakdown'!$T$6:$T$169, ">="&I1,'Expenditure Breakdown'!$T$6:$T$169, "<"&J1) -> 0 | J17: =SUMIFS('Expenditure Breakdown'!$U$6:$U$169, 'Expenditure Breakdown'!$T$6:$T$169, ">="&J1,'Expenditure Breakdown'!$T$6:$T$169, "<"&K1) -> 0 | K17: =SUMIFS('Expenditure Breakdown'!$U$6:$U$169, 'Expenditure Breakdown'!$T$6:$T$169, ">="&K1,'Expenditure Breakdown'!$T$6:$T$169, "<"&L1) -> 0 | L17: =SUMIFS('Expenditure Breakdown'!$U$6:$U$169, 'Expenditure Breakdown'!$T$6:$T$169, ">="&L1,'Expenditure Breakdown'!$T$6:$T$169, "<"&M1) -> 0 | M17: =SUMIFS('Expenditure Breakdown'!$U$6:$U$169, 'Expenditure Breakdown'!$T$6:$T$169, ">="&M1,'Expenditure Breakdown'!$T$6:$T$169, "<"&N1) -> 727517.81 | ... KE17: =SUMIFS('Expenditure Breakdown'!$U$6:$U$169, 'Expenditure Breakdown'!$T$6:$T$169, ">="&KE1,'Expenditure Breakdown'!$T$6:$T$169, "<"&KF1) -> 0 | KF17: =SUMIFS('Expenditure Breakdown'!$U$6:$U$169, 'Expenditure Breakdown'!$T$6:$T$169, ">="&KF1,'Expenditure Breakdown'!$T$6:$T$169, "<"&#REF!) -> 0
B18: Revenue Recognition Cumulative | C18: =D17-D18 -> 0 | D18: =MAX(F18:KF18) -> 1364882.4 | F18: =F17 -> 0 | G18: =F18+G17 -> 0 | H18: =G18+H17 -> 521.24398 | I18: =H18+I17 -> 521.24398 | J18: =I18+J17 -> 521.24398 | K18: =J18+K17 -> 521.24398 | L18: =K18+L17 -> 521.24398 | M18: =L18+M17 -> 728039.05 | N18: =M18+N17 -> 728039.05 | ... KF18: =KE18+KF17 -> 1364882.4

Sheet Finance - Revenue
A3: Sum of REVENUE RECOGNITION AMOUNT | B3: Column Labels
A4: Row Labels | B4: (blank) | C4: 45991 | D4: 46022 | F4: 46053 | G4: 46081 | H4: 46112 | I4: 46142 | J4: Grand Total
A5: (blank)
A6: 1. Panels | D6: 485847.99 | E6: 0 | J6: 485847.99
A7: 2. Inverters | D7: 150000 | E7: 0 | J7: 150000
A8: 3. Mounting Structures | D8: 6504.8589 | E8: 0 | F8: 82021.395 | J8: 88526.254
A9: 4. DC Equipment | D9: 19757.966 | E9: 0 | F9: 111505.79 | G9: 50479.859 | H9: 3883.0661 | I9: 3883.0661 | J9: 189509.75
A10: 5. Monitoring
A11: 6. AC Equipment | D11: 19120.404 | E11: 0 | F11: 98500.818 | G11: 49713.051 | H11: 3824.0808 | I11: 3824.0808 | J11: 174982.43
A12: 8. Product Add On | B12: 0 | E12: 0 | G12: 43035 | J12: 43035
A13: 9. AC & DC installation | D13: 34758.333 | E13: 0 | G13: 90371.667 | H13: 6951.6667 | I13: 6951.6667 | J13: 139033.33
A14: 10. Site Logistics | D14: 10921.852 | E14: 0 | G14: 28396.815 | H14: 2184.3704 | I14: 2184.3704 | J14: 43687.407
A15: 11. Due Dilligence | B15: 0 | E15: 0 | G15: 32222.222 | J15: 32222.222
A16: 13. Engineering | E16: 0 | F16: 15121.332 | J16: 15121.332
A17: 14. General Expenses | B17: 0 | C17: 521.24398 | D17: 606.40805 | E17: 0 | F17: 558.80583 | G17: 615.10213 | H17: 615.10213 | J17: 2916.6621
A18: 15. Service Add On
A19: 12. BDP Commission
A20: 7.BESS
A21: Grand Total | B21: 0 | C21: 521.24398 | D21: 727517.81 | E21: 0 | F21: 307708.14 | G21: 294833.72 | H21: 17458.286 | I21: 16843.184 | J21: 1364882.4

Sheet Finance - COS
A3: Sum of Actual Total | B3: Column Labels
A4: Row Labels | B4: (blank) | C4: 45991 | D4: 46022 | F4: 46053 | G4: 46081 | H4: 46112 | I4: 46142 | J4: Grand Total
A5: (blank)
A6: 1. Panels | D6: 306891 | J6: 306891
A7: 2. Inverters | D7: 112476.43 | J7: 112476.43
A8: 3. Mounting Structures | D8: 5492 | F8: 22235.27 | J8: 27727.27
A9: 4. DC Equipment | D9: 9836.25 | F9: 56664.97 | G9: 25574.25 | H9: 1967.25 | I9: 1967.25 | J9: 96009.97
A10: 5. Monitoring | F10: 361.85 | G10: 11169 | J10: 11530.85
A11: 6. AC Equipment | D11: 15738 | F11: 81076 | G11: 40918.8 | H11: 3147.6 | I11: 3147.6 | J11: 144028
A12: 8. Product Add On | G12: 36548 | J12: 36548
A13: 9. AC & DC installation | D13: 33836.7 | G13: 87975.42 | H13: 6767.34 | I13: 6767.34 | J13: 135346.8
A14: 10. Site Logistics | D14: 5577.95 | G14: 14502.67 | H14: 1115.59 | I14: 1115.59 | J14: 22311.8
A15: 11. Due Dilligence | B15: 0 | G15: 18577.5 | J15: 18577.5
A16: 13. Engineering | F16: 0 | J16: 0
A17: 14. General Expenses | C17: 428.4 | D17: 456.96 | F17: 913.92 | G17: 656.25 | H17: 656.25 | J17: 3111.78
A18: 15. Service Add On | C18: 450 | G18: 33897 | J18: 34347
A19: 12. BDP Commission | E19: 0 | J19: 0
A20: 7.BESS
A21: Grand Total | B21: 0 | C21: 878.4 | D21: 490305.29 | E21: 0 | F21: 161252.01 | G21: 269818.89 | H21: 13654.03 | I21: 12997.78 | J21: 948906.4

Sheet Data
C2: Public holidays | F2: Drop down list
C3: 45658 | D3: New Years Day | F3: Approved
C4: 45737 | D4: Human Rights day | F4: Pending
C5: 45765 | D5: Good Friday | F5: Declined
C6: 45768 | D6: Family Day | F6: Abanded
C7: 45774 | D7: Freedom Day
C8: 45765 | D8: Freedom DayObserved
C9: 45778 | D9: Workers day
C10: 45824 | D10: Youth Day Holiday
C11: 45878 | D11: Womens Day
C12: 45924 | D12: Heritage Day
C13: 46007 | D13: Day of Reconciliation | H13: Manual dates
C14: 46016 | D14: Christmas Day
C15: 46017 | D15: Day of Goodwill
C16: 46006 | D16: Builders Break
C17: 46007 | D17: Builders Break
C18: 46008 | D18: Builders Break
C19: 46009 | D19: Builders Break
C20: 46010 | D20: Builders Break
C21: 46011 | D21: Builders Break
C22: 46012 | D22: Builders Break
C23: 46013 | D23: Builders Break
C24: 46014 | D24: Builders Break
C25: 46015 | D25: Builders Break
... C60: 46382 | D60: Day of Goodwill
