Workbook
Name Inverter_Capacity: #REF!
Name Inverter_Supplier: #REF!
Name Project_Size: Compliance!Projectsize
Name Project_Size: 'Finance - Revenue'!Projectsize
Name Project_Size: Projectsize
Name Projectsize: #REF!
Name Projectsize: #REF!
Name Projectsize: 'Project Margins'!$K$5
Name Security_Serv: #REF!
Name Security_Serv: #REF!
Name SSS: #REF!
Name SSS: #REF!
Name USD_ZAR: #REF!

Sheet Sheet1
A1: PROJECT PLAN
A2: # | B2: Project Milestone | C2: Planned Start Date | D2: Duration (Work Days) | E2: Planned End Date | F2: Actual Start Date | H2: Actual End Date | J2: Comments | L2: =C3 -> 43831 | M2: =L2+3 -> 43834 | N2: =M2+7 -> 43841 | O2: =N2+7 -> 43848 | P2: =O2+7 -> 43855 | Q2: =P2+6 -> 43861 | R2: =Q2+1 -> 43862 | S2: =R2+7 -> 43869 | T2: =S2+7 -> 43876 | U2: =T2+7 -> 43883 | V2: =U2+6 -> 43889 | W2: =V2+7 -> 43896 | X2: =W2+7 -> 43903 | Y2: =X2+7 -> 43910 | Z2: =Y2+7 -> 43917 | AA2: =Z2+3 -> 43920 | AB2: =AA2+4 -> 43924 | AC2: =AB2+7 -> 43931 | AD2: =AC2+7 -> 43938 | AE2: =AD2+7 -> 43945 | AF2: =AE2+6 -> 43951 | AG2: =AF2+2 -> 43953 | AH2: =AG2+7 -> 43960 | AI2: =AH2+7 -> 43967 | AJ2: =AI2+7 -> 43974 | AK2: =AJ2+7 -> 43981 | AL2: =AK2+1 -> 43982 | AM2: =AL2+6 -> 43988 | AN2: =AM2+7 -> 43995 | AO2: =AN2+7 -> 44002 | AP2: =AO2+7 -> 44009 | AQ2: =AP2+3 -> 44012 | AR2: =AQ2+4 -> 44016 | AS2: =AR2+7 -> 44023 | AT2: =AS2+7 -> 44030 | AU2: =AT2+7 -> 44037 | AV2: =AU2+6 -> 44043 | AW2: =AV2+1 -> 44044 | AX2: =AW2+7 -> 44051 | AY2: =AX2+7 -> 44058 | AZ2: =AY2+7 -> 44065 | BA2: =AZ2+7 -> 44072 | BB2: =BA2+2 -> 44074 | BC2: =BB2+5 -> 44079 | BD2: =BC2+7 -> 44086 | BE2: =BD2+7 -> 44093 | BF2: =BE2+7 -> 44100 | BG2: =BF2+4 -> 44104
A3: 1 | B3: Contract Signature | C3: 43831 | D3: 1 | E3: 43832 | F3: 43831 | G3: 1 | H3: 43832 | L3: =IF(AND($F3<(L$2+7),$F3>L$2),1, IF(AND($H3<L$2+7,$H3>L$2),3, IF(AND($F3<=L$2, $H3>=L$2), 2, "" ))) -> 3 | M3: =IF(AND($F3<(M$2+7),$F3>M$2),1, IF(AND($H3<M$2+7,$H3>M$2),3, IF(AND($F3<=M$2, $H3>=M$2), 2, "" ))) | N3: =IF(AND($F3<(N$2+7),$F3>N$2),1, IF(AND($H3<N$2+7,$H3>N$2),3, IF(AND($F3<=N$2, $H3>=N$2), 2, "" ))) | O3: =IF(AND($F3<(O$2+7),$F3>O$2),1, IF(AND($H3<O$2+7,$H3>O$2),3, IF(AND($F3<=O$2, $H3>=O$2), 2, "" ))) | P3: =IF(AND($F3<(P$2+7),$F3>P$2),1, IF(AND($H3<P$2+7,$H3>P$2),3, IF(AND($F3<=P$2, $H3>=P$2), 2, "" ))) | Q3: =IF(AND($F3<(Q$2+7),$F3>Q$2),1, IF(AND($H3<Q$2+7,$H3>Q$2),3, IF(AND($F3<=Q$2, $H3>=Q$2), 2, "" ))) | R3: =IF(AND($F3<(R$2+7),$F3>R$2),1, IF(AND($H3<R$2+7,$H3>R$2),3, IF(AND($F3<=R$2, $H3>=R$2), 2, "" ))) | S3: =IF(AND($F3<(S$2+7),$F3>S$2),1, IF(AND($H3<S$2+7,$H3>S$2),3, IF(AND($F3<=S$2, $H3>=S$2), 2, "" ))) | ... AQ3: =IF(AND($F3<(AQ$2+7),$F3>AQ$2),1, IF(AND($H3<AQ$2+7,$H3>AQ$2),3, IF(AND($F3<=AQ$2, $H3>=AQ$2), 2, "" )))
A4: A | B4: PAYMENT MILESTONE 1: DEPOSIT | C4: 43832 | D4: 1 | E4: 43833 | F4: 43832 | G4: 1 | H4: 43833 | L4: =IF(AND($F4<(L$2+7),$F4>L$2),1, IF(AND($H4<L$2+7,$H4>L$2),3, IF(AND($F4<=L$2, $H4>=L$2), 2, "" ))) -> 1 | M4: =IF(AND($F4<(M$2+7),$F4>M$2),1, IF(AND($H4<M$2+7,$H4>M$2),3, IF(AND($F4<=M$2, $H4>=M$2), 2, "" ))) | N4: =IF(AND($F4<(N$2+7),$F4>N$2),1, IF(AND($H4<N$2+7,$H4>N$2),3, IF(AND($F4<=N$2, $H4>=N$2), 2, "" ))) | O4: =IF(AND($F4<(O$2+7),$F4>O$2),1, IF(AND($H4<O$2+7,$H4>O$2),3, IF(AND($F4<=O$2, $H4>=O$2), 2, "" ))) | P4: =IF(AND($F4<(P$2+7),$F4>P$2),1, IF(AND($H4<P$2+7,$H4>P$2),3, IF(AND($F4<=P$2, $H4>=P$2), 2, "" ))) | Q4: =IF(AND($F4<(Q$2+7),$F4>Q$2),1, IF(AND($H4<Q$2+7,$H4>Q$2),3, IF(AND($F4<=Q$2, $H4>=Q$2), 2, "" ))) | R4: =IF(AND($F4<(R$2+7),$F4>R$2),1, IF(AND($H4<R$2+7,$H4>R$2),3, IF(AND($F4<=R$2, $H4>=R$2), 2, "" ))) | S4: =IF(AND($F4<(S$2+7),$F4>S$2),1, IF(AND($H4<S$2+7,$H4>S$2),3, IF(AND($F4<=S$2, $H4>=S$2), 2, "" ))) | ... AQ4: =IF(AND($F4<(AQ$2+7),$F4>AQ$2),1, IF(AND($H4<AQ$2+7,$H4>AQ$2),3, IF(AND($F4<=AQ$2, $H4>=AQ$2), 2, "" )))
A5: 2 | B5: Structural and Electrical Due Diligences | C5: 43833 | D5: 5 | E5: 43840 | F5: 43833 | G5: 5 | H5: 43840 | L5: =IF(AND($F5<(L$2+7),$F5>L$2),1, IF(AND($H5<L$2+7,$H5>L$2),3, IF(AND($F5<=L$2, $H5>=L$2), 2, "" ))) -> 1 | M5: =IF(AND($F5<(M$2+7),$F5>M$2),1, IF(AND($H5<M$2+7,$H5>M$2),3, IF(AND($F5<=M$2, $H5>=M$2), 2, "" ))) -> 3 | N5: =IF(AND($F5<(N$2+7),$F5>N$2),1, IF(AND($H5<N$2+7,$H5>N$2),3, IF(AND($F5<=N$2, $H5>=N$2), 2, "" ))) | O5: =IF(AND($F5<(O$2+7),$F5>O$2),1, IF(AND($H5<O$2+7,$H5>O$2),3, IF(AND($F5<=O$2, $H5>=O$2), 2, "" ))) | P5: =IF(AND($F5<(P$2+7),$F5>P$2),1, IF(AND($H5<P$2+7,$H5>P$2),3, IF(AND($F5<=P$2, $H5>=P$2), 2, "" ))) | Q5: =IF(AND($F5<(Q$2+7),$F5>Q$2),1, IF(AND($H5<Q$2+7,$H5>Q$2),3, IF(AND($F5<=Q$2, $H5>=Q$2), 2, "" ))) | R5: =IF(AND($F5<(R$2+7),$F5>R$2),1, IF(AND($H5<R$2+7,$H5>R$2),3, IF(AND($F5<=R$2, $H5>=R$2), 2, "" ))) | S5: =IF(AND($F5<(S$2+7),$F5>S$2),1, IF(AND($H5<S$2+7,$H5>S$2),3, IF(AND($F5<=S$2, $H5>=S$2), 2, "" ))) | ... AQ5: =IF(AND($F5<(AQ$2+7),$F5>AQ$2),1, IF(AND($H5<AQ$2+7,$H5>AQ$2),3, IF(AND($F5<=AQ$2, $H5>=AQ$2), 2, "" )))
A6: 3 | B6: Design Confirmation | C6: 43841 | D6: 2 | E6: 43844 | F6: 43841 | G6: 2 | H6: 43844 | L6: =IF(AND($F6<(L$2+7),$F6>L$2),1, IF(AND($H6<L$2+7,$H6>L$2),3, IF(AND($F6<=L$2, $H6>=L$2), 2, "" ))) | M6: =IF(AND($F6<(M$2+7),$F6>M$2),1, IF(AND($H6<M$2+7,$H6>M$2),3, IF(AND($F6<=M$2, $H6>=M$2), 2, "" ))) | N6: =IF(AND($F6<(N$2+7),$F6>N$2),1, IF(AND($H6<N$2+7,$H6>N$2),3, IF(AND($F6<=N$2, $H6>=N$2), 2, "" ))) -> 3 | O6: =IF(AND($F6<(O$2+7),$F6>O$2),1, IF(AND($H6<O$2+7,$H6>O$2),3, IF(AND($F6<=O$2, $H6>=O$2), 2, "" ))) | P6: =IF(AND($F6<(P$2+7),$F6>P$2),1, IF(AND($H6<P$2+7,$H6>P$2),3, IF(AND($F6<=P$2, $H6>=P$2), 2, "" ))) | Q6: =IF(AND($F6<(Q$2+7),$F6>Q$2),1, IF(AND($H6<Q$2+7,$H6>Q$2),3, IF(AND($F6<=Q$2, $H6>=Q$2), 2, "" ))) | R6: =IF(AND($F6<(R$2+7),$F6>R$2),1, IF(AND($H6<R$2+7,$H6>R$2),3, IF(AND($F6<=R$2, $H6>=R$2), 2, "" ))) | S6: =IF(AND($F6<(S$2+7),$F6>S$2),1, IF(AND($H6<S$2+7,$H6>S$2),3, IF(AND($F6<=S$2, $H6>=S$2), 2, "" ))) | ... AQ6: =IF(AND($F6<(AQ$2+7),$F6>AQ$2),1, IF(AND($H6<AQ$2+7,$H6>AQ$2),3, IF(AND($F6<=AQ$2, $H6>=AQ$2), 2, "" )))
A7: 4 | B7: Equipment Procurement | C7: 43833 | E7: 43949 | F7: 43833 | H7: 43949 | L7: =IF(AND($F7<(L$2+7),$F7>L$2),1, IF(AND($H7<L$2+7,$H7>L$2),3, IF(AND($F7<=L$2, $H7>=L$2), 2, "" ))) -> 1 | M7: =IF(AND($F7<(M$2+7),$F7>M$2),1, IF(AND($H7<M$2+7,$H7>M$2),3, IF(AND($F7<=M$2, $H7>=M$2), 2, "" ))) -> 2 | N7: =IF(AND($F7<(N$2+7),$F7>N$2),1, IF(AND($H7<N$2+7,$H7>N$2),3, IF(AND($F7<=N$2, $H7>=N$2), 2, "" ))) -> 2 | O7: =IF(AND($F7<(O$2+7),$F7>O$2),1, IF(AND($H7<O$2+7,$H7>O$2),3, IF(AND($F7<=O$2, $H7>=O$2), 2, "" ))) -> 2 | P7: =IF(AND($F7<(P$2+7),$F7>P$2),1, IF(AND($H7<P$2+7,$H7>P$2),3, IF(AND($F7<=P$2, $H7>=P$2), 2, "" ))) -> 2 | Q7: =IF(AND($F7<(Q$2+7),$F7>Q$2),1, IF(AND($H7<Q$2+7,$H7>Q$2),3, IF(AND($F7<=Q$2, $H7>=Q$2), 2, "" ))) -> 2 | R7: =IF(AND($F7<(R$2+7),$F7>R$2),1, IF(AND($H7<R$2+7,$H7>R$2),3, IF(AND($F7<=R$2, $H7>=R$2), 2, "" ))) -> 2 | S7: =IF(AND($F7<(S$2+7),$F7>S$2),1, IF(AND($H7<S$2+7,$H7>S$2),3, IF(AND($F7<=S$2, $H7>=S$2), 2, "" ))) -> 2 | ... AQ7: =IF(AND($F7<(AQ$2+7),$F7>AQ$2),1, IF(AND($H7<AQ$2+7,$H7>AQ$2),3, IF(AND($F7<=AQ$2, $H7>=AQ$2), 2, "" )))
B8: Panel Procurement | C8: 43833 | D8: 5 | E8: 43840 | F8: 43833 | G8: 5 | H8: 43840 | L8: =IF(AND($F8<(L$2+7),$F8>L$2),1, IF(AND($H8<L$2+7,$H8>L$2),3, IF(AND($F8<=L$2, $H8>=L$2), 2, "" ))) -> 1 | M8: =IF(AND($F8<(M$2+7),$F8>M$2),1, IF(AND($H8<M$2+7,$H8>M$2),3, IF(AND($F8<=M$2, $H8>=M$2), 2, "" ))) -> 3 | N8: =IF(AND($F8<(N$2+7),$F8>N$2),1, IF(AND($H8<N$2+7,$H8>N$2),3, IF(AND($F8<=N$2, $H8>=N$2), 2, "" ))) | O8: =IF(AND($F8<(O$2+7),$F8>O$2),1, IF(AND($H8<O$2+7,$H8>O$2),3, IF(AND($F8<=O$2, $H8>=O$2), 2, "" ))) | P8: =IF(AND($F8<(P$2+7),$F8>P$2),1, IF(AND($H8<P$2+7,$H8>P$2),3, IF(AND($F8<=P$2, $H8>=P$2), 2, "" ))) | Q8: =IF(AND($F8<(Q$2+7),$F8>Q$2),1, IF(AND($H8<Q$2+7,$H8>Q$2),3, IF(AND($F8<=Q$2, $H8>=Q$2), 2, "" ))) | R8: =IF(AND($F8<(R$2+7),$F8>R$2),1, IF(AND($H8<R$2+7,$H8>R$2),3, IF(AND($F8<=R$2, $H8>=R$2), 2, "" ))) | S8: =IF(AND($F8<(S$2+7),$F8>S$2),1, IF(AND($H8<S$2+7,$H8>S$2),3, IF(AND($F8<=S$2, $H8>=S$2), 2, "" ))) | ... AQ8: =IF(AND($F8<(AQ$2+7),$F8>AQ$2),1, IF(AND($H8<AQ$2+7,$H8>AQ$2),3, IF(AND($F8<=AQ$2, $H8>=AQ$2), 2, "" )))
B9: Inverter Procurement | C9: 43941 | D9: 5 | E9: 43949 | F9: 43941 | G9: 5 | H9: 43949 | L9: =IF(AND($F9<(L$2+7),$F9>L$2),1, IF(AND($H9<L$2+7,$H9>L$2),3, IF(AND($F9<=L$2, $H9>=L$2), 2, "" ))) | M9: =IF(AND($F9<(M$2+7),$F9>M$2),1, IF(AND($H9<M$2+7,$H9>M$2),3, IF(AND($F9<=M$2, $H9>=M$2), 2, "" ))) | N9: =IF(AND($F9<(N$2+7),$F9>N$2),1, IF(AND($H9<N$2+7,$H9>N$2),3, IF(AND($F9<=N$2, $H9>=N$2), 2, "" ))) | O9: =IF(AND($F9<(O$2+7),$F9>O$2),1, IF(AND($H9<O$2+7,$H9>O$2),3, IF(AND($F9<=O$2, $H9>=O$2), 2, "" ))) | P9: =IF(AND($F9<(P$2+7),$F9>P$2),1, IF(AND($H9<P$2+7,$H9>P$2),3, IF(AND($F9<=P$2, $H9>=P$2), 2, "" ))) | Q9: =IF(AND($F9<(Q$2+7),$F9>Q$2),1, IF(AND($H9<Q$2+7,$H9>Q$2),3, IF(AND($F9<=Q$2, $H9>=Q$2), 2, "" ))) | R9: =IF(AND($F9<(R$2+7),$F9>R$2),1, IF(AND($H9<R$2+7,$H9>R$2),3, IF(AND($F9<=R$2, $H9>=R$2), 2, "" ))) | S9: =IF(AND($F9<(S$2+7),$F9>S$2),1, IF(AND($H9<S$2+7,$H9>S$2),3, IF(AND($F9<=S$2, $H9>=S$2), 2, "" ))) | ... AQ9: =IF(AND($F9<(AQ$2+7),$F9>AQ$2),1, IF(AND($H9<AQ$2+7,$H9>AQ$2),3, IF(AND($F9<=AQ$2, $H9>=AQ$2), 2, "" )))
B10: Mounting Structure Procurement | C10: 43941 | D10: 5 | E10: 43949 | F10: 43941 | G10: 5 | H10: 43949 | L10: =IF(AND($F10<(L$2+7),$F10>L$2),1, IF(AND($H10<L$2+7,$H10>L$2),3, IF(AND($F10<=L$2, $H10>=L$2), 2, "" ))) | M10: =IF(AND($F10<(M$2+7),$F10>M$2),1, IF(AND($H10<M$2+7,$H10>M$2),3, IF(AND($F10<=M$2, $H10>=M$2), 2, "" ))) | N10: =IF(AND($F10<(N$2+7),$F10>N$2),1, IF(AND($H10<N$2+7,$H10>N$2),3, IF(AND($F10<=N$2, $H10>=N$2), 2, "" ))) | O10: =IF(AND($F10<(O$2+7),$F10>O$2),1, IF(AND($H10<O$2+7,$H10>O$2),3, IF(AND($F10<=O$2, $H10>=O$2), 2, "" ))) | P10: =IF(AND($F10<(P$2+7),$F10>P$2),1, IF(AND($H10<P$2+7,$H10>P$2),3, IF(AND($F10<=P$2, $H10>=P$2), 2, "" ))) | Q10: =IF(AND($F10<(Q$2+7),$F10>Q$2),1, IF(AND($H10<Q$2+7,$H10>Q$2),3, IF(AND($F10<=Q$2, $H10>=Q$2), 2, "" ))) | R10: =IF(AND($F10<(R$2+7),$F10>R$2),1, IF(AND($H10<R$2+7,$H10>R$2),3, IF(AND($F10<=R$2, $H10>=R$2), 2, "" ))) | S10: =IF(AND($F10<(S$2+7),$F10>S$2),1, IF(AND($H10<S$2+7,$H10>S$2),3, IF(AND($F10<=S$2, $H10>=S$2), 2, "" ))) | ... AQ10: =IF(AND($F10<(AQ$2+7),$F10>AQ$2),1, IF(AND($H10<AQ$2+7,$H10>AQ$2),3, IF(AND($F10<=AQ$2, $H10>=AQ$2), 2, "" )))
B11: BOS Procurement | C11: 43941 | D11: 5 | E11: 43949 | F11: 43941 | G11: 5 | H11: 43949 | L11: =IF(AND($F11<(L$2+7),$F11>L$2),1, IF(AND($H11<L$2+7,$H11>L$2),3, IF(AND($F11<=L$2, $H11>=L$2), 2, "" ))) | M11: =IF(AND($F11<(M$2+7),$F11>M$2),1, IF(AND($H11<M$2+7,$H11>M$2),3, IF(AND($F11<=M$2, $H11>=M$2), 2, "" ))) | N11: =IF(AND($F11<(N$2+7),$F11>N$2),1, IF(AND($H11<N$2+7,$H11>N$2),3, IF(AND($F11<=N$2, $H11>=N$2), 2, "" ))) | O11: =IF(AND($F11<(O$2+7),$F11>O$2),1, IF(AND($H11<O$2+7,$H11>O$2),3, IF(AND($F11<=O$2, $H11>=O$2), 2, "" ))) | P11: =IF(AND($F11<(P$2+7),$F11>P$2),1, IF(AND($H11<P$2+7,$H11>P$2),3, IF(AND($F11<=P$2, $H11>=P$2), 2, "" ))) | Q11: =IF(AND($F11<(Q$2+7),$F11>Q$2),1, IF(AND($H11<Q$2+7,$H11>Q$2),3, IF(AND($F11<=Q$2, $H11>=Q$2), 2, "" ))) | R11: =IF(AND($F11<(R$2+7),$F11>R$2),1, IF(AND($H11<R$2+7,$H11>R$2),3, IF(AND($F11<=R$2, $H11>=R$2), 2, "" ))) | S11: =IF(AND($F11<(S$2+7),$F11>S$2),1, IF(AND($H11<S$2+7,$H11>S$2),3, IF(AND($F11<=S$2, $H11>=S$2), 2, "" ))) | ... AQ11: =IF(AND($F11<(AQ$2+7),$F11>AQ$2),1, IF(AND($H11<AQ$2+7,$H11>AQ$2),3, IF(AND($F11<=AQ$2, $H11>=AQ$2), 2, "" )))
A12: 5 | B12: Internal Project Kick off | C12: 43936 | D12: 5 | E12: 43943 | F12: 43936 | G12: 5 | H12: 43943
A13: 6 | B13: Client Project Kick-off | C13: 43963 | D13: 5 | E13: 43970 | F13: 43963 | G13: 5 | H13: 43970 | L13: =IF(AND($F13<(L$2+7),$F13>L$2),1, IF(AND($H13<L$2+7,$H13>L$2),3, IF(AND($F13<=L$2, $H13>=L$2), 2, "" ))) | M13: =IF(AND($F13<(M$2+7),$F13>M$2),1, IF(AND($H13<M$2+7,$H13>M$2),3, IF(AND($F13<=M$2, $H13>=M$2), 2, "" ))) | N13: =IF(AND($F13<(N$2+7),$F13>N$2),1, IF(AND($H13<N$2+7,$H13>N$2),3, IF(AND($F13<=N$2, $H13>=N$2), 2, "" ))) | O13: =IF(AND($F13<(O$2+7),$F13>O$2),1, IF(AND($H13<O$2+7,$H13>O$2),3, IF(AND($F13<=O$2, $H13>=O$2), 2, "" ))) | P13: =IF(AND($F13<(P$2+7),$F13>P$2),1, IF(AND($H13<P$2+7,$H13>P$2),3, IF(AND($F13<=P$2, $H13>=P$2), 2, "" ))) | Q13: =IF(AND($F13<(Q$2+7),$F13>Q$2),1, IF(AND($H13<Q$2+7,$H13>Q$2),3, IF(AND($F13<=Q$2, $H13>=Q$2), 2, "" ))) | R13: =IF(AND($F13<(R$2+7),$F13>R$2),1, IF(AND($H13<R$2+7,$H13>R$2),3, IF(AND($F13<=R$2, $H13>=R$2), 2, "" ))) | S13: =IF(AND($F13<(S$2+7),$F13>S$2),1, IF(AND($H13<S$2+7,$H13>S$2),3, IF(AND($F13<=S$2, $H13>=S$2), 2, "" ))) | ... AQ13: =IF(AND($F13<(AQ$2+7),$F13>AQ$2),1, IF(AND($H13<AQ$2+7,$H13>AQ$2),3, IF(AND($F13<=AQ$2, $H13>=AQ$2), 2, "" )))
A14: 7 | B14: Equipment Delivery | C14: 43983 | D14: 9 | E14: 43994 | F14: 43983 | G14: 9 | H14: 43994 | L14: =IF(AND($F14<(L$2+7),$F14>L$2),1, IF(AND($H14<L$2+7,$H14>L$2),3, IF(AND($F14<=L$2, $H14>=L$2), 2, "" ))) | M14: =IF(AND($F14<(M$2+7),$F14>M$2),1, IF(AND($H14<M$2+7,$H14>M$2),3, IF(AND($F14<=M$2, $H14>=M$2), 2, "" ))) | N14: =IF(AND($F14<(N$2+7),$F14>N$2),1, IF(AND($H14<N$2+7,$H14>N$2),3, IF(AND($F14<=N$2, $H14>=N$2), 2, "" ))) | O14: =IF(AND($F14<(O$2+7),$F14>O$2),1, IF(AND($H14<O$2+7,$H14>O$2),3, IF(AND($F14<=O$2, $H14>=O$2), 2, "" ))) | P14: =IF(AND($F14<(P$2+7),$F14>P$2),1, IF(AND($H14<P$2+7,$H14>P$2),3, IF(AND($F14<=P$2, $H14>=P$2), 2, "" ))) | Q14: =IF(AND($F14<(Q$2+7),$F14>Q$2),1, IF(AND($H14<Q$2+7,$H14>Q$2),3, IF(AND($F14<=Q$2, $H14>=Q$2), 2, "" ))) | R14: =IF(AND($F14<(R$2+7),$F14>R$2),1, IF(AND($H14<R$2+7,$H14>R$2),3, IF(AND($F14<=R$2, $H14>=R$2), 2, "" ))) | S14: =IF(AND($F14<(S$2+7),$F14>S$2),1, IF(AND($H14<S$2+7,$H14>S$2),3, IF(AND($F14<=S$2, $H14>=S$2), 2, "" ))) | ... AQ14: =IF(AND($F14<(AQ$2+7),$F14>AQ$2),1, IF(AND($H14<AQ$2+7,$H14>AQ$2),3, IF(AND($F14<=AQ$2, $H14>=AQ$2), 2, "" )))
B15: Mounting Structure Delivery | C15: 43983 | D15: 2 | E15: 43985 | F15: 43983 | G15: 2 | H15: 43985
B16: Panel Delivery | C16: 43990 | D16: 2 | E16: 43992 | F16: 43990 | G16: 2 | H16: 43992 | L16: =IF(AND($F16<(L$2+7),$F16>L$2),1, IF(AND($H16<L$2+7,$H16>L$2),3, IF(AND($F16<=L$2, $H16>=L$2), 2, "" ))) | M16: =IF(AND($F16<(M$2+7),$F16>M$2),1, IF(AND($H16<M$2+7,$H16>M$2),3, IF(AND($F16<=M$2, $H16>=M$2), 2, "" ))) | N16: =IF(AND($F16<(N$2+7),$F16>N$2),1, IF(AND($H16<N$2+7,$H16>N$2),3, IF(AND($F16<=N$2, $H16>=N$2), 2, "" ))) | O16: =IF(AND($F16<(O$2+7),$F16>O$2),1, IF(AND($H16<O$2+7,$H16>O$2),3, IF(AND($F16<=O$2, $H16>=O$2), 2, "" ))) | P16: =IF(AND($F16<(P$2+7),$F16>P$2),1, IF(AND($H16<P$2+7,$H16>P$2),3, IF(AND($F16<=P$2, $H16>=P$2), 2, "" ))) | Q16: =IF(AND($F16<(Q$2+7),$F16>Q$2),1, IF(AND($H16<Q$2+7,$H16>Q$2),3, IF(AND($F16<=Q$2, $H16>=Q$2), 2, "" ))) | R16: =IF(AND($F16<(R$2+7),$F16>R$2),1, IF(AND($H16<R$2+7,$H16>R$2),3, IF(AND($F16<=R$2, $H16>=R$2), 2, "" ))) | S16: =IF(AND($F16<(S$2+7),$F16>S$2),1, IF(AND($H16<S$2+7,$H16>S$2),3, IF(AND($F16<=S$2, $H16>=S$2), 2, "" ))) | ... AQ16: =IF(AND($F16<(AQ$2+7),$F16>AQ$2),1, IF(AND($H16<AQ$2+7,$H16>AQ$2),3, IF(AND($F16<=AQ$2, $H16>=AQ$2), 2, "" )))
B17: Generator Delivery | C17: 43983 | D17: 2 | E17: 43985 | F17: 43983 | G17: 2 | H17: 43985
A18: B | B18: PAYMENT MILESTONE 2: DELIVERY OF PV PANELS | C18: 43992 | D18: 2 | E18: 43994 | F18: 43992 | G18: 2 | H18: 43994
B19: Inverter Delivery | C19: 43983 | D19: 2 | E19: 43985 | F19: 43983 | G19: 2 | H19: 43985 | L19: =IF(AND($F19<(L$2+7),$F19>L$2),1, IF(AND($H19<L$2+7,$H19>L$2),3, IF(AND($F19<=L$2, $H19>=L$2), 2, "" ))) | M19: =IF(AND($F19<(M$2+7),$F19>M$2),1, IF(AND($H19<M$2+7,$H19>M$2),3, IF(AND($F19<=M$2, $H19>=M$2), 2, "" ))) | N19: =IF(AND($F19<(N$2+7),$F19>N$2),1, IF(AND($H19<N$2+7,$H19>N$2),3, IF(AND($F19<=N$2, $H19>=N$2), 2, "" ))) | O19: =IF(AND($F19<(O$2+7),$F19>O$2),1, IF(AND($H19<O$2+7,$H19>O$2),3, IF(AND($F19<=O$2, $H19>=O$2), 2, "" ))) | P19: =IF(AND($F19<(P$2+7),$F19>P$2),1, IF(AND($H19<P$2+7,$H19>P$2),3, IF(AND($F19<=P$2, $H19>=P$2), 2, "" ))) | Q19: =IF(AND($F19<(Q$2+7),$F19>Q$2),1, IF(AND($H19<Q$2+7,$H19>Q$2),3, IF(AND($F19<=Q$2, $H19>=Q$2), 2, "" ))) | R19: =IF(AND($F19<(R$2+7),$F19>R$2),1, IF(AND($H19<R$2+7,$H19>R$2),3, IF(AND($F19<=R$2, $H19>=R$2), 2, "" ))) | S19: =IF(AND($F19<(S$2+7),$F19>S$2),1, IF(AND($H19<S$2+7,$H19>S$2),3, IF(AND($F19<=S$2, $H19>=S$2), 2, "" ))) | ... AQ19: =IF(AND($F19<(AQ$2+7),$F19>AQ$2),1, IF(AND($H19<AQ$2+7,$H19>AQ$2),3, IF(AND($F19<=AQ$2, $H19>=AQ$2), 2, "" )))
B20: BOS Delivery | C20: 43983 | D20: 1 | E20: 43984 | F20: 43983 | G20: 1 | H20: 43984 | L20: =IF(AND($F20<(L$2+7),$F20>L$2),1, IF(AND($H20<L$2+7,$H20>L$2),3, IF(AND($F20<=L$2, $H20>=L$2), 2, "" ))) | M20: =IF(AND($F20<(M$2+7),$F20>M$2),1, IF(AND($H20<M$2+7,$H20>M$2),3, IF(AND($F20<=M$2, $H20>=M$2), 2, "" ))) | N20: =IF(AND($F20<(N$2+7),$F20>N$2),1, IF(AND($H20<N$2+7,$H20>N$2),3, IF(AND($F20<=N$2, $H20>=N$2), 2, "" ))) | O20: =IF(AND($F20<(O$2+7),$F20>O$2),1, IF(AND($H20<O$2+7,$H20>O$2),3, IF(AND($F20<=O$2, $H20>=O$2), 2, "" ))) | P20: =IF(AND($F20<(P$2+7),$F20>P$2),1, IF(AND($H20<P$2+7,$H20>P$2),3, IF(AND($F20<=P$2, $H20>=P$2), 2, "" ))) | Q20: =IF(AND($F20<(Q$2+7),$F20>Q$2),1, IF(AND($H20<Q$2+7,$H20>Q$2),3, IF(AND($F20<=Q$2, $H20>=Q$2), 2, "" ))) | R20: =IF(AND($F20<(R$2+7),$F20>R$2),1, IF(AND($H20<R$2+7,$H20>R$2),3, IF(AND($F20<=R$2, $H20>=R$2), 2, "" ))) | S20: =IF(AND($F20<(S$2+7),$F20>S$2),1, IF(AND($H20<S$2+7,$H20>S$2),3, IF(AND($F20<=S$2, $H20>=S$2), 2, "" ))) | ... AQ20: =IF(AND($F20<(AQ$2+7),$F20>AQ$2),1, IF(AND($H20<AQ$2+7,$H20>AQ$2),3, IF(AND($F20<=AQ$2, $H20>=AQ$2), 2, "" )))
A21: C | B21: PAYMENT MILESTONE 3: DELIVERY OF INVERTERS AND BOS | C21: 43985 | D21: 2 | E21: 43987 | F21: 43985 | G21: 2 | H21: 43987
A22: 8 | B22: Installation | C22: 43990 | D22: 22 | E22: 44012 | F22: 43990 | G22: 22 | H22: 44012 | L22: =IF(AND($F22<(L$2+7),$F22>L$2),1, IF(AND($H22<L$2+7,$H22>L$2),3, IF(AND($F22<=L$2, $H22>=L$2), 2, "" ))) | M22: =IF(AND($F22<(M$2+7),$F22>M$2),1, IF(AND($H22<M$2+7,$H22>M$2),3, IF(AND($F22<=M$2, $H22>=M$2), 2, "" ))) | N22: =IF(AND($F22<(N$2+7),$F22>N$2),1, IF(AND($H22<N$2+7,$H22>N$2),3, IF(AND($F22<=N$2, $H22>=N$2), 2, "" ))) | O22: =IF(AND($F22<(O$2+7),$F22>O$2),1, IF(AND($H22<O$2+7,$H22>O$2),3, IF(AND($F22<=O$2, $H22>=O$2), 2, "" ))) | P22: =IF(AND($F22<(P$2+7),$F22>P$2),1, IF(AND($H22<P$2+7,$H22>P$2),3, IF(AND($F22<=P$2, $H22>=P$2), 2, "" ))) | Q22: =IF(AND($F22<(Q$2+7),$F22>Q$2),1, IF(AND($H22<Q$2+7,$H22>Q$2),3, IF(AND($F22<=Q$2, $H22>=Q$2), 2, "" ))) | R22: =IF(AND($F22<(R$2+7),$F22>R$2),1, IF(AND($H22<R$2+7,$H22>R$2),3, IF(AND($F22<=R$2, $H22>=R$2), 2, "" ))) | S22: =IF(AND($F22<(S$2+7),$F22>S$2),1, IF(AND($H22<S$2+7,$H22>S$2),3, IF(AND($F22<=S$2, $H22>=S$2), 2, "" ))) | ... AQ22: =IF(AND($F22<(AQ$2+7),$F22>AQ$2),1, IF(AND($H22<AQ$2+7,$H22>AQ$2),3, IF(AND($F22<=AQ$2, $H22>=AQ$2), 2, "" ))) -> 2
B23: Site Establishment | C23: 43990 | D23: 1 | E23: 43991 | F23: 43990 | G23: 1 | H23: 43991 | J23: Installation placed on hold due to Covid-19 case | L23: =IF(AND($F23<(L$2+7),$F23>L$2),1, IF(AND($H23<L$2+7,$H23>L$2),3, IF(AND($F23<=L$2, $H23>=L$2), 2, "" ))) | M23: =IF(AND($F23<(M$2+7),$F23>M$2),1, IF(AND($H23<M$2+7,$H23>M$2),3, IF(AND($F23<=M$2, $H23>=M$2), 2, "" ))) | N23: =IF(AND($F23<(N$2+7),$F23>N$2),1, IF(AND($H23<N$2+7,$H23>N$2),3, IF(AND($F23<=N$2, $H23>=N$2), 2, "" ))) | O23: =IF(AND($F23<(O$2+7),$F23>O$2),1, IF(AND($H23<O$2+7,$H23>O$2),3, IF(AND($F23<=O$2, $H23>=O$2), 2, "" ))) | P23: =IF(AND($F23<(P$2+7),$F23>P$2),1, IF(AND($H23<P$2+7,$H23>P$2),3, IF(AND($F23<=P$2, $H23>=P$2), 2, "" ))) | Q23: =IF(AND($F23<(Q$2+7),$F23>Q$2),1, IF(AND($H23<Q$2+7,$H23>Q$2),3, IF(AND($F23<=Q$2, $H23>=Q$2), 2, "" ))) | R23: =IF(AND($F23<(R$2+7),$F23>R$2),1, IF(AND($H23<R$2+7,$H23>R$2),3, IF(AND($F23<=R$2, $H23>=R$2), 2, "" ))) | S23: =IF(AND($F23<(S$2+7),$F23>S$2),1, IF(AND($H23<S$2+7,$H23>S$2),3, IF(AND($F23<=S$2, $H23>=S$2), 2, "" ))) | ... AQ23: =IF(AND($F23<(AQ$2+7),$F23>AQ$2),1, IF(AND($H23<AQ$2+7,$H23>AQ$2),3, IF(AND($F23<=AQ$2, $H23>=AQ$2), 2, "" )))
A24: 9 | B24: DC Works | C24: 43991 | D24: 16 | E24: 44012 | F24: 43991 | G24: 16 | H24: 44012 | L24: =IF(AND($F24<(L$2+7),$F24>L$2),1, IF(AND($H24<L$2+7,$H24>L$2),3, IF(AND($F24<=L$2, $H24>=L$2), 2, "" ))) | M24: =IF(AND($F24<(M$2+7),$F24>M$2),1, IF(AND($H24<M$2+7,$H24>M$2),3, IF(AND($F24<=M$2, $H24>=M$2), 2, "" ))) | N24: =IF(AND($F24<(N$2+7),$F24>N$2),1, IF(AND($H24<N$2+7,$H24>N$2),3, IF(AND($F24<=N$2, $H24>=N$2), 2, "" ))) | O24: =IF(AND($F24<(O$2+7),$F24>O$2),1, IF(AND($H24<O$2+7,$H24>O$2),3, IF(AND($F24<=O$2, $H24>=O$2), 2, "" ))) | P24: =IF(AND($F24<(P$2+7),$F24>P$2),1, IF(AND($H24<P$2+7,$H24>P$2),3, IF(AND($F24<=P$2, $H24>=P$2), 2, "" ))) | Q24: =IF(AND($F24<(Q$2+7),$F24>Q$2),1, IF(AND($H24<Q$2+7,$H24>Q$2),3, IF(AND($F24<=Q$2, $H24>=Q$2), 2, "" ))) | R24: =IF(AND($F24<(R$2+7),$F24>R$2),1, IF(AND($H24<R$2+7,$H24>R$2),3, IF(AND($F24<=R$2, $H24>=R$2), 2, "" ))) | S24: =IF(AND($F24<(S$2+7),$F24>S$2),1, IF(AND($H24<S$2+7,$H24>S$2),3, IF(AND($F24<=S$2, $H24>=S$2), 2, "" ))) | ... AQ24: =IF(AND($F24<(AQ$2+7),$F24>AQ$2),1, IF(AND($H24<AQ$2+7,$H24>AQ$2),3, IF(AND($F24<=AQ$2, $H24>=AQ$2), 2, "" ))) -> 2
B25: Mounting structure Installation | C25: 43991 | D25: 4 | E25: 43997 | F25: 43991 | G25: 4 | H25: 43997 | L25: =IF(AND($F25<(L$2+7),$F25>L$2),1, IF(AND($H25<L$2+7,$H25>L$2),3, IF(AND($F25<=L$2, $H25>=L$2), 2, "" ))) | M25: =IF(AND($F25<(M$2+7),$F25>M$2),1, IF(AND($H25<M$2+7,$H25>M$2),3, IF(AND($F25<=M$2, $H25>=M$2), 2, "" ))) | N25: =IF(AND($F25<(N$2+7),$F25>N$2),1, IF(AND($H25<N$2+7,$H25>N$2),3, IF(AND($F25<=N$2, $H25>=N$2), 2, "" ))) | O25: =IF(AND($F25<(O$2+7),$F25>O$2),1, IF(AND($H25<O$2+7,$H25>O$2),3, IF(AND($F25<=O$2, $H25>=O$2), 2, "" ))) | P25: =IF(AND($F25<(P$2+7),$F25>P$2),1, IF(AND($H25<P$2+7,$H25>P$2),3, IF(AND($F25<=P$2, $H25>=P$2), 2, "" ))) | Q25: =IF(AND($F25<(Q$2+7),$F25>Q$2),1, IF(AND($H25<Q$2+7,$H25>Q$2),3, IF(AND($F25<=Q$2, $H25>=Q$2), 2, "" ))) | R25: =IF(AND($F25<(R$2+7),$F25>R$2),1, IF(AND($H25<R$2+7,$H25>R$2),3, IF(AND($F25<=R$2, $H25>=R$2), 2, "" ))) | S25: =IF(AND($F25<(S$2+7),$F25>S$2),1, IF(AND($H25<S$2+7,$H25>S$2),3, IF(AND($F25<=S$2, $H25>=S$2), 2, "" ))) | ... AQ25: =IF(AND($F25<(AQ$2+7),$F25>AQ$2),1, IF(AND($H25<AQ$2+7,$H25>AQ$2),3, IF(AND($F25<=AQ$2, $H25>=AQ$2), 2, "" )))
B26: Cable tray Installation | C26: 43997 | D26: 3 | E26: 44004 | F26: 43997 | G26: 3 | H26: 44004 | L26: =IF(AND($F26<(L$2+7),$F26>L$2),1, IF(AND($H26<L$2+7,$H26>L$2),3, IF(AND($F26<=L$2, $H26>=L$2), 2, "" ))) | M26: =IF(AND($F26<(M$2+7),$F26>M$2),1, IF(AND($H26<M$2+7,$H26>M$2),3, IF(AND($F26<=M$2, $H26>=M$2), 2, "" ))) | N26: =IF(AND($F26<(N$2+7),$F26>N$2),1, IF(AND($H26<N$2+7,$H26>N$2),3, IF(AND($F26<=N$2, $H26>=N$2), 2, "" ))) | O26: =IF(AND($F26<(O$2+7),$F26>O$2),1, IF(AND($H26<O$2+7,$H26>O$2),3, IF(AND($F26<=O$2, $H26>=O$2), 2, "" ))) | P26: =IF(AND($F26<(P$2+7),$F26>P$2),1, IF(AND($H26<P$2+7,$H26>P$2),3, IF(AND($F26<=P$2, $H26>=P$2), 2, "" ))) | Q26: =IF(AND($F26<(Q$2+7),$F26>Q$2),1, IF(AND($H26<Q$2+7,$H26>Q$2),3, IF(AND($F26<=Q$2, $H26>=Q$2), 2, "" ))) | R26: =IF(AND($F26<(R$2+7),$F26>R$2),1, IF(AND($H26<R$2+7,$H26>R$2),3, IF(AND($F26<=R$2, $H26>=R$2), 2, "" ))) | S26: =IF(AND($F26<(S$2+7),$F26>S$2),1, IF(AND($H26<S$2+7,$H26>S$2),3, IF(AND($F26<=S$2, $H26>=S$2), 2, "" ))) | ... AQ26: =IF(AND($F26<(AQ$2+7),$F26>AQ$2),1, IF(AND($H26<AQ$2+7,$H26>AQ$2),3, IF(AND($F26<=AQ$2, $H26>=AQ$2), 2, "" )))
B27: DC Cable Installation | C27: 44004 | D27: 2 | E27: 44006 | F27: 44004 | G27: 2 | H27: 44006 | L27: =IF(AND($F27<(L$2+7),$F27>L$2),1, IF(AND($H27<L$2+7,$H27>L$2),3, IF(AND($F27<=L$2, $H27>=L$2), 2, "" ))) | M27: =IF(AND($F27<(M$2+7),$F27>M$2),1, IF(AND($H27<M$2+7,$H27>M$2),3, IF(AND($F27<=M$2, $H27>=M$2), 2, "" ))) | N27: =IF(AND($F27<(N$2+7),$F27>N$2),1, IF(AND($H27<N$2+7,$H27>N$2),3, IF(AND($F27<=N$2, $H27>=N$2), 2, "" ))) | O27: =IF(AND($F27<(O$2+7),$F27>O$2),1, IF(AND($H27<O$2+7,$H27>O$2),3, IF(AND($F27<=O$2, $H27>=O$2), 2, "" ))) | P27: =IF(AND($F27<(P$2+7),$F27>P$2),1, IF(AND($H27<P$2+7,$H27>P$2),3, IF(AND($F27<=P$2, $H27>=P$2), 2, "" ))) | Q27: =IF(AND($F27<(Q$2+7),$F27>Q$2),1, IF(AND($H27<Q$2+7,$H27>Q$2),3, IF(AND($F27<=Q$2, $H27>=Q$2), 2, "" ))) | R27: =IF(AND($F27<(R$2+7),$F27>R$2),1, IF(AND($H27<R$2+7,$H27>R$2),3, IF(AND($F27<=R$2, $H27>=R$2), 2, "" ))) | S27: =IF(AND($F27<(S$2+7),$F27>S$2),1, IF(AND($H27<S$2+7,$H27>S$2),3, IF(AND($F27<=S$2, $H27>=S$2), 2, "" ))) | ... AQ27: =IF(AND($F27<(AQ$2+7),$F27>AQ$2),1, IF(AND($H27<AQ$2+7,$H27>AQ$2),3, IF(AND($F27<=AQ$2, $H27>=AQ$2), 2, "" )))
B28: Module Installation | C28: 44006 | D28: 4 | E28: 44012 | F28: 44006 | G28: 4 | H28: 44012 | L28: =IF(AND($F28<(L$2+7),$F28>L$2),1, IF(AND($H28<L$2+7,$H28>L$2),3, IF(AND($F28<=L$2, $H28>=L$2), 2, "" ))) | M28: =IF(AND($F28<(M$2+7),$F28>M$2),1, IF(AND($H28<M$2+7,$H28>M$2),3, IF(AND($F28<=M$2, $H28>=M$2), 2, "" ))) | N28: =IF(AND($F28<(N$2+7),$F28>N$2),1, IF(AND($H28<N$2+7,$H28>N$2),3, IF(AND($F28<=N$2, $H28>=N$2), 2, "" ))) | O28: =IF(AND($F28<(O$2+7),$F28>O$2),1, IF(AND($H28<O$2+7,$H28>O$2),3, IF(AND($F28<=O$2, $H28>=O$2), 2, "" ))) | P28: =IF(AND($F28<(P$2+7),$F28>P$2),1, IF(AND($H28<P$2+7,$H28>P$2),3, IF(AND($F28<=P$2, $H28>=P$2), 2, "" ))) | Q28: =IF(AND($F28<(Q$2+7),$F28>Q$2),1, IF(AND($H28<Q$2+7,$H28>Q$2),3, IF(AND($F28<=Q$2, $H28>=Q$2), 2, "" ))) | R28: =IF(AND($F28<(R$2+7),$F28>R$2),1, IF(AND($H28<R$2+7,$H28>R$2),3, IF(AND($F28<=R$2, $H28>=R$2), 2, "" ))) | S28: =IF(AND($F28<(S$2+7),$F28>S$2),1, IF(AND($H28<S$2+7,$H28>S$2),3, IF(AND($F28<=S$2, $H28>=S$2), 2, "" ))) | ... AQ28: =IF(AND($F28<(AQ$2+7),$F28>AQ$2),1, IF(AND($H28<AQ$2+7,$H28>AQ$2),3, IF(AND($F28<=AQ$2, $H28>=AQ$2), 2, "" ))) -> 2
B29: Earth Cable Installation | C29: 44004 | D29: 1 | E29: 44005 | F29: 44004 | G29: 1 | H29: 44005 | L29: =IF(AND($F29<(L$2+7),$F29>L$2),1, IF(AND($H29<L$2+7,$H29>L$2),3, IF(AND($F29<=L$2, $H29>=L$2), 2, "" ))) | M29: =IF(AND($F29<(M$2+7),$F29>M$2),1, IF(AND($H29<M$2+7,$H29>M$2),3, IF(AND($F29<=M$2, $H29>=M$2), 2, "" ))) | N29: =IF(AND($F29<(N$2+7),$F29>N$2),1, IF(AND($H29<N$2+7,$H29>N$2),3, IF(AND($F29<=N$2, $H29>=N$2), 2, "" ))) | O29: =IF(AND($F29<(O$2+7),$F29>O$2),1, IF(AND($H29<O$2+7,$H29>O$2),3, IF(AND($F29<=O$2, $H29>=O$2), 2, "" ))) | P29: =IF(AND($F29<(P$2+7),$F29>P$2),1, IF(AND($H29<P$2+7,$H29>P$2),3, IF(AND($F29<=P$2, $H29>=P$2), 2, "" ))) | Q29: =IF(AND($F29<(Q$2+7),$F29>Q$2),1, IF(AND($H29<Q$2+7,$H29>Q$2),3, IF(AND($F29<=Q$2, $H29>=Q$2), 2, "" ))) | R29: =IF(AND($F29<(R$2+7),$F29>R$2),1, IF(AND($H29<R$2+7,$H29>R$2),3, IF(AND($F29<=R$2, $H29>=R$2), 2, "" ))) | S29: =IF(AND($F29<(S$2+7),$F29>S$2),1, IF(AND($H29<S$2+7,$H29>S$2),3, IF(AND($F29<=S$2, $H29>=S$2), 2, "" ))) | ... AQ29: =IF(AND($F29<(AQ$2+7),$F29>AQ$2),1, IF(AND($H29<AQ$2+7,$H29>AQ$2),3, IF(AND($F29<=AQ$2, $H29>=AQ$2), 2, "" )))
A30: 10 | B30: AC Works | C30: 43991 | D30: 8 | E30: 44000 | F30: 43991 | G30: 8 | H30: 44000
B31: Inverters Installation | C31: 43991 | D31: 2 | E31: 43993 | F31: 43991 | G31: 2 | H31: 43993 | L31: =IF(AND($F31<(L$2+7),$F31>L$2),1, IF(AND($H31<L$2+7,$H31>L$2),3, IF(AND($F31<=L$2, $H31>=L$2), 2, "" ))) | M31: =IF(AND($F31<(M$2+7),$F31>M$2),1, IF(AND($H31<M$2+7,$H31>M$2),3, IF(AND($F31<=M$2, $H31>=M$2), 2, "" ))) | N31: =IF(AND($F31<(N$2+7),$F31>N$2),1, IF(AND($H31<N$2+7,$H31>N$2),3, IF(AND($F31<=N$2, $H31>=N$2), 2, "" ))) | O31: =IF(AND($F31<(O$2+7),$F31>O$2),1, IF(AND($H31<O$2+7,$H31>O$2),3, IF(AND($F31<=O$2, $H31>=O$2), 2, "" ))) | P31: =IF(AND($F31<(P$2+7),$F31>P$2),1, IF(AND($H31<P$2+7,$H31>P$2),3, IF(AND($F31<=P$2, $H31>=P$2), 2, "" ))) | Q31: =IF(AND($F31<(Q$2+7),$F31>Q$2),1, IF(AND($H31<Q$2+7,$H31>Q$2),3, IF(AND($F31<=Q$2, $H31>=Q$2), 2, "" ))) | R31: =IF(AND($F31<(R$2+7),$F31>R$2),1, IF(AND($H31<R$2+7,$H31>R$2),3, IF(AND($F31<=R$2, $H31>=R$2), 2, "" ))) | S31: =IF(AND($F31<(S$2+7),$F31>S$2),1, IF(AND($H31<S$2+7,$H31>S$2),3, IF(AND($F31<=S$2, $H31>=S$2), 2, "" ))) | ... AQ31: =IF(AND($F31<(AQ$2+7),$F31>AQ$2),1, IF(AND($H31<AQ$2+7,$H31>AQ$2),3, IF(AND($F31<=AQ$2, $H31>=AQ$2), 2, "" )))
B32: AC BOS Installation | C32: 43993 | D32: 3 | E32: 44000 | F32: 43993 | G32: 3 | H32: 44000 | L32: =IF(AND($F32<(L$2+7),$F32>L$2),1, IF(AND($H32<L$2+7,$H32>L$2),3, IF(AND($F32<=L$2, $H32>=L$2), 2, "" ))) | M32: =IF(AND($F32<(M$2+7),$F32>M$2),1, IF(AND($H32<M$2+7,$H32>M$2),3, IF(AND($F32<=M$2, $H32>=M$2), 2, "" ))) | N32: =IF(AND($F32<(N$2+7),$F32>N$2),1, IF(AND($H32<N$2+7,$H32>N$2),3, IF(AND($F32<=N$2, $H32>=N$2), 2, "" ))) | O32: =IF(AND($F32<(O$2+7),$F32>O$2),1, IF(AND($H32<O$2+7,$H32>O$2),3, IF(AND($F32<=O$2, $H32>=O$2), 2, "" ))) | P32: =IF(AND($F32<(P$2+7),$F32>P$2),1, IF(AND($H32<P$2+7,$H32>P$2),3, IF(AND($F32<=P$2, $H32>=P$2), 2, "" ))) | Q32: =IF(AND($F32<(Q$2+7),$F32>Q$2),1, IF(AND($H32<Q$2+7,$H32>Q$2),3, IF(AND($F32<=Q$2, $H32>=Q$2), 2, "" ))) | R32: =IF(AND($F32<(R$2+7),$F32>R$2),1, IF(AND($H32<R$2+7,$H32>R$2),3, IF(AND($F32<=R$2, $H32>=R$2), 2, "" ))) | S32: =IF(AND($F32<(S$2+7),$F32>S$2),1, IF(AND($H32<S$2+7,$H32>S$2),3, IF(AND($F32<=S$2, $H32>=S$2), 2, "" ))) | ... AQ32: =IF(AND($F32<(AQ$2+7),$F32>AQ$2),1, IF(AND($H32<AQ$2+7,$H32>AQ$2),3, IF(AND($F32<=AQ$2, $H32>=AQ$2), 2, "" )))
B33: AC Cable/Tie-In | C33: 43992 | D33: 3 | E33: 43997 | F33: 43992 | G33: 3 | H33: 43997 | L33: =IF(AND($F33<(L$2+7),$F33>L$2),1, IF(AND($H33<L$2+7,$H33>L$2),3, IF(AND($F33<=L$2, $H33>=L$2), 2, "" ))) | M33: =IF(AND($F33<(M$2+7),$F33>M$2),1, IF(AND($H33<M$2+7,$H33>M$2),3, IF(AND($F33<=M$2, $H33>=M$2), 2, "" ))) | N33: =IF(AND($F33<(N$2+7),$F33>N$2),1, IF(AND($H33<N$2+7,$H33>N$2),3, IF(AND($F33<=N$2, $H33>=N$2), 2, "" ))) | O33: =IF(AND($F33<(O$2+7),$F33>O$2),1, IF(AND($H33<O$2+7,$H33>O$2),3, IF(AND($F33<=O$2, $H33>=O$2), 2, "" ))) | P33: =IF(AND($F33<(P$2+7),$F33>P$2),1, IF(AND($H33<P$2+7,$H33>P$2),3, IF(AND($F33<=P$2, $H33>=P$2), 2, "" ))) | Q33: =IF(AND($F33<(Q$2+7),$F33>Q$2),1, IF(AND($H33<Q$2+7,$H33>Q$2),3, IF(AND($F33<=Q$2, $H33>=Q$2), 2, "" ))) | R33: =IF(AND($F33<(R$2+7),$F33>R$2),1, IF(AND($H33<R$2+7,$H33>R$2),3, IF(AND($F33<=R$2, $H33>=R$2), 2, "" ))) | S33: =IF(AND($F33<(S$2+7),$F33>S$2),1, IF(AND($H33<S$2+7,$H33>S$2),3, IF(AND($F33<=S$2, $H33>=S$2), 2, "" ))) | ... AQ33: =IF(AND($F33<(AQ$2+7),$F33>AQ$2),1, IF(AND($H33<AQ$2+7,$H33>AQ$2),3, IF(AND($F33<=AQ$2, $H33>=AQ$2), 2, "" )))
B34: Monitoring Platform Installation | C34: 43997 | D34: 1 | E34: 44000 | F34: 43997 | G34: 1 | H34: 44000
A35: 11 | B35: Completion | C35: 44000 | D35: 14 | E35: 44014 | F35: 44000 | G35: 14 | H35: 44014 | L35: =IF(AND($F35<(L$2+7),$F35>L$2),1, IF(AND($H35<L$2+7,$H35>L$2),3, IF(AND($F35<=L$2, $H35>=L$2), 2, "" ))) | M35: =IF(AND($F35<(M$2+7),$F35>M$2),1, IF(AND($H35<M$2+7,$H35>M$2),3, IF(AND($F35<=M$2, $H35>=M$2), 2, "" ))) | N35: =IF(AND($F35<(N$2+7),$F35>N$2),1, IF(AND($H35<N$2+7,$H35>N$2),3, IF(AND($F35<=N$2, $H35>=N$2), 2, "" ))) | O35: =IF(AND($F35<(O$2+7),$F35>O$2),1, IF(AND($H35<O$2+7,$H35>O$2),3, IF(AND($F35<=O$2, $H35>=O$2), 2, "" ))) | P35: =IF(AND($F35<(P$2+7),$F35>P$2),1, IF(AND($H35<P$2+7,$H35>P$2),3, IF(AND($F35<=P$2, $H35>=P$2), 2, "" ))) | Q35: =IF(AND($F35<(Q$2+7),$F35>Q$2),1, IF(AND($H35<Q$2+7,$H35>Q$2),3, IF(AND($F35<=Q$2, $H35>=Q$2), 2, "" ))) | R35: =IF(AND($F35<(R$2+7),$F35>R$2),1, IF(AND($H35<R$2+7,$H35>R$2),3, IF(AND($F35<=R$2, $H35>=R$2), 2, "" ))) | S35: =IF(AND($F35<(S$2+7),$F35>S$2),1, IF(AND($H35<S$2+7,$H35>S$2),3, IF(AND($F35<=S$2, $H35>=S$2), 2, "" ))) | ... AQ35: =IF(AND($F35<(AQ$2+7),$F35>AQ$2),1, IF(AND($H35<AQ$2+7,$H35>AQ$2),3, IF(AND($F35<=AQ$2, $H35>=AQ$2), 2, "" ))) -> 3
B36: DC Works | C36: 44012 | D36: 2 | E36: 44014 | F36: 44012 | G36: 2 | H36: 44014 | L36: =IF(AND($F36<(L$2+7),$F36>L$2),1, IF(AND($H36<L$2+7,$H36>L$2),3, IF(AND($F36<=L$2, $H36>=L$2), 2, "" ))) | M36: =IF(AND($F36<(M$2+7),$F36>M$2),1, IF(AND($H36<M$2+7,$H36>M$2),3, IF(AND($F36<=M$2, $H36>=M$2), 2, "" ))) | N36: =IF(AND($F36<(N$2+7),$F36>N$2),1, IF(AND($H36<N$2+7,$H36>N$2),3, IF(AND($F36<=N$2, $H36>=N$2), 2, "" ))) | O36: =IF(AND($F36<(O$2+7),$F36>O$2),1, IF(AND($H36<O$2+7,$H36>O$2),3, IF(AND($F36<=O$2, $H36>=O$2), 2, "" ))) | P36: =IF(AND($F36<(P$2+7),$F36>P$2),1, IF(AND($H36<P$2+7,$H36>P$2),3, IF(AND($F36<=P$2, $H36>=P$2), 2, "" ))) | Q36: =IF(AND($F36<(Q$2+7),$F36>Q$2),1, IF(AND($H36<Q$2+7,$H36>Q$2),3, IF(AND($F36<=Q$2, $H36>=Q$2), 2, "" ))) | R36: =IF(AND($F36<(R$2+7),$F36>R$2),1, IF(AND($H36<R$2+7,$H36>R$2),3, IF(AND($F36<=R$2, $H36>=R$2), 2, "" ))) | S36: =IF(AND($F36<(S$2+7),$F36>S$2),1, IF(AND($H36<S$2+7,$H36>S$2),3, IF(AND($F36<=S$2, $H36>=S$2), 2, "" ))) | ... AQ36: =IF(AND($F36<(AQ$2+7),$F36>AQ$2),1, IF(AND($H36<AQ$2+7,$H36>AQ$2),3, IF(AND($F36<=AQ$2, $H36>=AQ$2), 2, "" ))) -> 3
B37: AC Works | C37: 44000 | D37: 2 | E37: 44004 | F37: 44000 | G37: 2 | H37: 44004 | L37: =IF(AND($F37<(L$2+7),$F37>L$2),1, IF(AND($H37<L$2+7,$H37>L$2),3, IF(AND($F37<=L$2, $H37>=L$2), 2, "" ))) | M37: =IF(AND($F37<(M$2+7),$F37>M$2),1, IF(AND($H37<M$2+7,$H37>M$2),3, IF(AND($F37<=M$2, $H37>=M$2), 2, "" ))) | N37: =IF(AND($F37<(N$2+7),$F37>N$2),1, IF(AND($H37<N$2+7,$H37>N$2),3, IF(AND($F37<=N$2, $H37>=N$2), 2, "" ))) | O37: =IF(AND($F37<(O$2+7),$F37>O$2),1, IF(AND($H37<O$2+7,$H37>O$2),3, IF(AND($F37<=O$2, $H37>=O$2), 2, "" ))) | P37: =IF(AND($F37<(P$2+7),$F37>P$2),1, IF(AND($H37<P$2+7,$H37>P$2),3, IF(AND($F37<=P$2, $H37>=P$2), 2, "" ))) | Q37: =IF(AND($F37<(Q$2+7),$F37>Q$2),1, IF(AND($H37<Q$2+7,$H37>Q$2),3, IF(AND($F37<=Q$2, $H37>=Q$2), 2, "" ))) | R37: =IF(AND($F37<(R$2+7),$F37>R$2),1, IF(AND($H37<R$2+7,$H37>R$2),3, IF(AND($F37<=R$2, $H37>=R$2), 2, "" ))) | S37: =IF(AND($F37<(S$2+7),$F37>S$2),1, IF(AND($H37<S$2+7,$H37>S$2),3, IF(AND($F37<=S$2, $H37>=S$2), 2, "" ))) | ... AQ37: =IF(AND($F37<(AQ$2+7),$F37>AQ$2),1, IF(AND($H37<AQ$2+7,$H37>AQ$2),3, IF(AND($F37<=AQ$2, $H37>=AQ$2), 2, "" )))
A38: D | B38: PAYMENT MILESTONE 4: PRACTICAL COMPLETION | C38: 44012 | D38: 1 | E38: 44013 | F38: 44012 | G38: 1 | H38: 44013 | L38: =IF(AND($F38<(L$2+7),$F38>L$2),1, IF(AND($H38<L$2+7,$H38>L$2),3, IF(AND($F38<=L$2, $H38>=L$2), 2, "" ))) | M38: =IF(AND($F38<(M$2+7),$F38>M$2),1, IF(AND($H38<M$2+7,$H38>M$2),3, IF(AND($F38<=M$2, $H38>=M$2), 2, "" ))) | N38: =IF(AND($F38<(N$2+7),$F38>N$2),1, IF(AND($H38<N$2+7,$H38>N$2),3, IF(AND($F38<=N$2, $H38>=N$2), 2, "" ))) | O38: =IF(AND($F38<(O$2+7),$F38>O$2),1, IF(AND($H38<O$2+7,$H38>O$2),3, IF(AND($F38<=O$2, $H38>=O$2), 2, "" ))) | P38: =IF(AND($F38<(P$2+7),$F38>P$2),1, IF(AND($H38<P$2+7,$H38>P$2),3, IF(AND($F38<=P$2, $H38>=P$2), 2, "" ))) | Q38: =IF(AND($F38<(Q$2+7),$F38>Q$2),1, IF(AND($H38<Q$2+7,$H38>Q$2),3, IF(AND($F38<=Q$2, $H38>=Q$2), 2, "" ))) | R38: =IF(AND($F38<(R$2+7),$F38>R$2),1, IF(AND($H38<R$2+7,$H38>R$2),3, IF(AND($F38<=R$2, $H38>=R$2), 2, "" ))) | S38: =IF(AND($F38<(S$2+7),$F38>S$2),1, IF(AND($H38<S$2+7,$H38>S$2),3, IF(AND($F38<=S$2, $H38>=S$2), 2, "" ))) | ... AQ38: =IF(AND($F38<(AQ$2+7),$F38>AQ$2),1, IF(AND($H38<AQ$2+7,$H38>AQ$2),3, IF(AND($F38<=AQ$2, $H38>=AQ$2), 2, "" ))) -> 3
A39: 12 | B39: Commissioning | C39: 43997 | D39: 22 | E39: 44019 | F39: 43997 | G39: 22 | H39: 44019 | L39: =IF(AND($F39<(L$2+7),$F39>L$2),1, IF(AND($H39<L$2+7,$H39>L$2),3, IF(AND($F39<=L$2, $H39>=L$2), 2, "" ))) | M39: =IF(AND($F39<(M$2+7),$F39>M$2),1, IF(AND($H39<M$2+7,$H39>M$2),3, IF(AND($F39<=M$2, $H39>=M$2), 2, "" ))) | N39: =IF(AND($F39<(N$2+7),$F39>N$2),1, IF(AND($H39<N$2+7,$H39>N$2),3, IF(AND($F39<=N$2, $H39>=N$2), 2, "" ))) | O39: =IF(AND($F39<(O$2+7),$F39>O$2),1, IF(AND($H39<O$2+7,$H39>O$2),3, IF(AND($F39<=O$2, $H39>=O$2), 2, "" ))) | P39: =IF(AND($F39<(P$2+7),$F39>P$2),1, IF(AND($H39<P$2+7,$H39>P$2),3, IF(AND($F39<=P$2, $H39>=P$2), 2, "" ))) | Q39: =IF(AND($F39<(Q$2+7),$F39>Q$2),1, IF(AND($H39<Q$2+7,$H39>Q$2),3, IF(AND($F39<=Q$2, $H39>=Q$2), 2, "" ))) | R39: =IF(AND($F39<(R$2+7),$F39>R$2),1, IF(AND($H39<R$2+7,$H39>R$2),3, IF(AND($F39<=R$2, $H39>=R$2), 2, "" ))) | S39: =IF(AND($F39<(S$2+7),$F39>S$2),1, IF(AND($H39<S$2+7,$H39>S$2),3, IF(AND($F39<=S$2, $H39>=S$2), 2, "" ))) | ... AQ39: =IF(AND($F39<(AQ$2+7),$F39>AQ$2),1, IF(AND($H39<AQ$2+7,$H39>AQ$2),3, IF(AND($F39<=AQ$2, $H39>=AQ$2), 2, "" ))) -> 2
B40: Snag List | C40: 44014 | D40: 3 | E40: 44019 | F40: 44014 | G40: 3 | H40: 44019
...

Sheet Compliance
B2: HSE
B4: Description | C4: Status | D4: Approved By | E4: Date | F4: Results / Comments
B5: NOC
B6: 7.1 Agreement
B7: 13.2 Agreement
B8: EE File
B9: Subbie File
B16: SSEG
B18: Description | C18: Status | D18: Approved By | E18: Date | F18: Results / Comments
B19: SSEG Application
B20: PTI
B21: Commissioning Approval

Sheet Revenue Tracking
B2: HIGH LEVEL PROJECT REVENUE TRACKING
D3: PLANNED | F3: ACTUAL | L3: FINANCIAL REVIEW | N3: TIMELINE REVIEW | R3: Allocated in 2024 | S3: Budgeted | T3: Acutal
B4: 1 | C4: Planned Revenue | D4: ='Project Plan'!E6 -> 2462259 | F4: =F21 -> 2505210.5 | L4: 2462259 | N4: Start Date | P4: Sales | R4: =GETPIVOTDATA("REVENUE RECOGNITION AMOUNT",'Finance - Revenue'!$A$3,"INVOICE RAISED DATE",DATE(2024,7,31))+GETPIVOTDATA("REVENUE RECOGNITION AMOUNT",'Finance - Revenue'!$A$3,"INVOICE RAISED DATE",DATE(2024,8,31)) -> 848045.34 | S4: 1614213.7 | T4: =F4-R4 -> 1657165.1
B5: 2 | C5: Planned Expenditure | D5: =+'Expenditure Tracking'!F5 -> 2105194.2 | F5: =+'Expenditure Tracking'!J5 -> 2103862.1 | L5: 2040967.7 | N5: 45560 | P5: COS | R5: =GETPIVOTDATA("Actual Total ",'Finance - COS'!$A$3,"INVOICE RAISED DATE",DATE(2024,7,31))+GETPIVOTDATA("Actual Total ",'Finance - COS'!$A$3,"INVOICE RAISED DATE",DATE(2024,8,31)) -> 730147.42 | S5: 1301474.2 | T5: =F5-R5 -> 1373714.7
B6: 3 | C6: Planned Profit | D6: =+D4-D5 -> 357064.85 | F6: =+F4-F5 -> 401348.36 | L6: 421291.35 | N6: End Date - PC | P6: GP | R6: =R4-R5 -> 117897.92 | S6: =S4-S5 -> 312739.45 | T6: =T4-T5 -> 283450.44
B7: 4 | C7: Planned Margin | D7: =+D6/D4 -> 0.14501515 | F7: =+F6/F4 -> 0.16020545 | L7: 0.17109952 | N7: 45600
B10: CONTRACT
B12: No. | C12: PAYMENT MILESTONE | E12: % | F12: VALUE | H12: PLANNED PAYMENT DATE | L12: INVOICE NUMBER | N12: INVOICE RAISED DATE | P12: PAYMENT RECEIVED DATE | R12: MILESTONE NOTES & COMMENTS
B13: 1 | C13: Acceptance and Initial Deposit | E13: 0.35 | F13: =$D$4*E13 -> 861790.65 | H13: 45491 | L13: 004471 | N13: 45488 | P13: 45490
B14: 2 | C14: Delivery of Inverters | E14: 0.25 | F14: =$D$4*E14 -> 615564.75 | H14: ='Project Plan'!E22+7 -> 45567 | L14: 004555 | N14: 45567 | P14: =N14+7 -> 45574
B15: 3 | C15: Delivery of Panels | E15: 0.25 | F15: =$D$4*E15 -> 615564.75 | H15: ='Project Plan'!E35+7 -> 45583 | L15: 004576 | N15: 45586 | P15: =N15+38 -> 45624
B16: 4 | C16: Practical Completion | E16: 0.1 | F16: =$D$4*E16 -> 246225.9 | H16: ='Project Plan'!E39+7 -> 45616 | L16: 004608 | N16: 45610 | P16: =N16+14 -> 45624
B17: 5 | C17: Handover | E17: 0.05 | F17: =$D$4*E17 -> 123112.95 | H17: ='Project Plan'!E50+7 -> 45642 | L17: 004693 | N17: 45714 | P17: 45946
B18: 6 | C18: VO - Walkways | E18: 0 | F18: ='Expenditure Breakdown'!R68+'Expenditure Breakdown'!R69+'Expenditure Breakdown'!R70+'Expenditure Breakdown'!R72 -> 52281.12 | H18: =H17 -> 45642 | L18: 004693 | N18: 45714 | P18: 45946
B19: 7 | C19: Credit Note - Walkways | E19: 0 | F19: -9329.65 | L19: 004931 | N19: 46045 | P19: 46081
E21: =SUM(E13:E19) -> 1 | F21: =SUM(F13:F19) -> 2505210.5
B23: KEY: | C23: contains an error (in result or a check has failed)
C24: Red Font - IF TEXT : content not yet confirmed
C25: Red Font - IF NUMBER: Negative value
C26: Anything in yellow is a concern or risk for noting or action
C27: confirmed
C28: [ADD INITIALS: comment for noting in square brackets, use colour or red to draw attention if important]
C29: [RT: When adding rows into sheet, ensure you insert between first and last row of each category]
C30: end of sheet - do not insert information below/beyond this
B40: No. | C40: PAYMENT MILESTONE | E40: % | F40: VALUE
B41: 1 | C41: Deposit - Project commencement | E41: 0.35 | F41: =$F$47*E41 -> 876823.67
B42: 2 | C42: Delivery of Panels | E42: 0.3 | F42: =$F$47*E42 -> 751563.14
B43: 3 | C43: Delivery of Inverters | E43: 0.2 | F43: =$F$47*E43 -> 501042.09
B44: 4 | C44: Practical Completion | E44: 0.1 | F44: =$F$47*E44 -> 250521.05
B45: 5 | C45: Handover | E45: 0.05 | F45: =$F$47*E45 -> 125260.52
C46: Total | E46: =SUM(E41:E45) -> 1 | F46: =SUM(F41:F45) -> 2505210.5
E47: =SUM(E41:E45) -> 1 | F47: =F21 -> 2505210.5

Sheet Project Plan
N1: 45943 | O1: 45943
C2: PROJECT PLAN | E2: SA Metal - 22 Christiaan | N2: 0 | O2: 1
C3: PROJECT SIZE (kWp) | E3: 250
C4: BUSINESS DEVELOPER | E4: Peet
C5: PROJECT MANAGER | E5: Lloyd
C6: CONTRACT VALUE | E6: 2462259
C7: Phase: | E7: Compliance Handover
B8: No. | C8: HIGH LEVEL PROGRAMME | E8: Planned Start | F8: Duration (days) | G8: Planned End | I8: Actual Start | J8: Duration (days) | K8: Actual End | M8: Status | O8: Comment
F9: 55 | J9: 55 | M9: 1 | N9: 1
B11: 1 | C11: Project Initiation | E11: 45518 | F11: 37 | G11: 45555 | I11: 45518 | J11: 37 | K11: 45555 | M11: 1 | N11: 1
B12: 1.1 | C12: BD Handover | E12: 45518 | F12: 1 | G12: 45519 | I12: 45518 | J12: 1 | K12: 45519 | M12: 1 | N12: 1
B13: 1.2 | C13: Project Introduction | E13: 45540 | F13: 1 | G13: 45541 | I13: 45540 | J13: 1 | K13: 45541 | M13: 1 | N13: 1
B14: 1.3 | C14: HSE | E14: 45540 | F14: 15 | G14: 45555 | I14: 45540 | J14: 15 | K14: 45555 | M14: 1 | N14: 1
B15: 1.4 | C15: Installer Kick Off | E15: 45548 | F15: 1 | G15: 45551 | I15: 45548 | J15: 1 | K15: 45551 | M15: 1 | N15: 1
B16: 1.5 | C16: Project Review | E16: 45547 | F16: 1 | G16: 45548 | I16: 45547 | J16: 1 | K16: 45548 | M16: 1 | N16: 1
B18: 2 | C18: Site Establishment | E18: 45560 | F18: 1 | G18: 45561 | I18: 45560 | J18: 1 | K18: 45561 | M18: 1 | N18: 1
B19: 2.1 | C19: Installer on site & Roof Assessment | E19: 45560 | F19: 1 | G19: 45561 | I19: 45560 | J19: 1 | K19: 45561 | M19: 1 | N19: 1 | S19: 88 | T19: Net working Days
B21: 3 | C21: AC Installation | E21: 45562 | F21: 35 | G21: 45597 | I21: 45562 | J21: 35 | K21: 45597 | M21: 1 | N21: 1 | S21: 17.6 | T21: Net Working Weeks
B22: 3.1 | C22: Inverters delivered | E22: 45560 | F22: 1 | G22: 45561 | I22: 45565 | J22: 1 | K22: 45566 | M22: 1 | N22: 1 | S22: 14.204545 | T22: kW/Week Installationn Speed
B23: 3.2 | C23: Inverters Mounted | E23: 45561 | F23: 1 | G23: 45562 | I23: 45566 | J23: 1 | K23: 45567 | M23: 1 | N23: 1
B24: 3.3 | C24: Solar DB lead time | E24: 45560 | F24: 30 | G24: 45602 | I24: 45560 | J24: 30 | K24: 45602 | M24: 1 | N24: 1
B25: 3.4 | C25: AC Works | E25: 45561 | F25: 10 | G25: 45575 | I25: 45566 | J25: 10 | K25: 45580 | M25: 1 | N25: 1
B26: 3.5 | C26: AC Tie - in | E26: 45569 | F26: 1 | G26: 45572 | I26: 45574 | J26: 1 | K26: 45575 | M26: 1 | N26: 1
B28: 4 | C28: DC Works | E28: 45560 | F28: 37 | G28: 45597 | I28: 45560 | J28: 37 | K28: 45597 | M28: 1 | N28: 1
B29: 4.1 | C29: Mounting Structure delivered | E29: 45560 | F29: 1 | G29: 45561 | I29: 45560 | J29: 1 | K29: 45561 | M29: 1 | N29: 1
B30: 4.2 | C30: Mounting Structure installation | E30: 45560 | F30: 8 | G30: 45572 | I30: 45560 | J30: 8 | K30: 45572 | M30: 1 | N30: 1
B31: 4.3 | C31: DC Cable delivered | E31: 45560 | F31: 1 | G31: 45561 | I31: 45560 | J31: 1 | K31: 45561 | M31: 1 | N31: 1
B32: 4.3 | C32: DC Stringing | E32: 45597 | F32: 5 | G32: 45604 | I32: 45597 | J32: 5 | K32: 45604 | M32: 1 | N32: 1
B34: 5 | C34: Module installation | E34: 45576 | F34: 33 | G34: 45609 | I34: 45576 | J34: 33 | K34: 45609 | M34: 1 | N34: 1
B35: 5.1 | C35: Module delivery | E35: 45576 | F35: 1 | G35: 45579 | I35: 45576 | J35: 1 | K35: 45579 | M35: 1 | N35: 1
B36: 5.2 | C36: Module mounting | E36: 45576 | F36: 15 | G36: 45597 | I36: 45576 | J36: 15 | K36: 45597 | M36: 1 | N36: 1
B38: 6 | C38: Commissioning | E38: 45604 | F38: 5 | G38: 45609 | I38: 45604 | J38: 5 | K38: 45609 | M38: 1 | N38: 1
B39: 6.1 | C39: Commissioning | E39: 45609 | F39: 1 | G39: 45610 | I39: 45609 | J39: 1 | K39: 45610 | M39: 1 | N39: 1
B40: 6.2 | C40: Practical Completion | E40: 45609 | F40: 4 | G40: 45615 | I40: 45609 | J40: 4 | K40: 45615 | M40: 1 | N40: 1
B42: 7 | C42: QA Inspections | E42: 45609 | F42: 28 | G42: 45637 | I42: 45609 | J42: 28 | K42: 45637 | M42: 1 | N42: 1
B43: 7.1 | C43: Red-Team Inspection | E43: 45615 | F43: 3 | G43: 45618 | I43: 45632 | J43: 3 | K43: 45637 | M43: 1 | N43: 1
B45: 8 | C45: Project Closure | E45: 45634 | F45: 52 | G45: 45686 | I45: 45634 | J45: 52 | K45: 45686 | M45: 1 | N45: 1
B46: 8.1 | C46: Equipment serial numbers | E46: 45618 | F46: 1 | G46: 45621 | I46: 45637 | J46: 1 | K46: 45638 | M46: 1 | N46: 1
B47: 8.2 | C47: Snags completion | E47: 45621 | F47: 5 | G47: 45628 | I47: 45638 | J47: 28 | K47: 45681 | M47: 1 | N47: 1
B48: 8.3 | C48: System Performance Monitoring | E48: 45628 | F48: 5 | G48: 45635 | I48: 45646 | J48: 10 | K48: 45664 | M48: 1 | N48: 1
...

Sheet Data
C2: Public holidays | F2: Drop down list
C3: 45292 | D3: New Years Day | F3: Approved
C4: 45372 | D4: Human Rights day | F4: Pending
C5: 45380 | D5: Good Friday | F5: Declined
C6: 45383 | D6: Family Day | F6: Abanded
C7: 45413 | D7: Workers day
C8: 45460 | D8: Youth Day Holiday
C9: 45513 | D9: Womens Day
C10: 45559 | D10: Heritage Day
C11: 45642 | D11: Day of Reconciliation
C12: 45651 | D12: Christmas Day
C13: 45652 | D13: Day of Goodwill | H13: Manual dates

Sheet Expenditure Tracking
B2: HIGH LEVEL PROJECT EXPENDITURE TRACKING
F4: COSTED | H4: PLANNED | J4: ACTUAL | L4: Difference from costed | N4: Difference from planned
B5: EXPENDITURE | F5: =SUM(F9:F23) -> 2105194.2 | H5: =SUM(H9:H23) -> 2040967.7 | J5: =SUM(J9:J23) -> 2103862.1 | L5: =SUM(L9:L23) -> 1332.043 | N5: =SUM(N9:N23) -> -62894.452
B7: No. | D7: Item | F7: Costed Expenditure | H7: Planned Expenditure | J7: Actual Expenditure | L7: Saving / Overrun | N7: Saving / Overrun | P7: Comments on variations from planned expenditure
B9: ='Expenditure Breakdown'!B6 -> 1 | D9: ='Expenditure Breakdown'!C6 -> Panels | F9: ='Expenditure Breakdown'!J6 -> 690973.73 | H9: 736862.5 | J9: ='Expenditure Breakdown'!X6 -> 647765.5 | L9: =F9-J9 -> 43208.233 | N9: =H9-J9 -> 89097
B10: ='Expenditure Breakdown'!B13 -> 2 | D10: ='Expenditure Breakdown'!C13 -> Inverters | F10: =+'Expenditure Breakdown'!J13 -> 157796 | H10: 151514 | J10: =+'Expenditure Breakdown'!X13 -> 138845.23 | L10: =F10-J10 -> 18950.77 | N10: =H10-J10 -> 12668.77
B11: ='Expenditure Breakdown'!B18 -> 3 | D11: ='Expenditure Breakdown'!C18 -> Mounting Structures | F11: =+'Expenditure Breakdown'!J18 -> 99864 | H11: 58349.4 | J11: =+'Expenditure Breakdown'!X18 -> 169924.22 | L11: =F11-J11 -> -70060.22 | N11: =H11-J11 -> -111574.82
B12: ='Expenditure Breakdown'!B26 -> 4 | D12: ='Expenditure Breakdown'!C26 -> DC Equipment | F12: =+'Expenditure Breakdown'!J26 -> 237064.3 | H12: 242250 | J12: =+'Expenditure Breakdown'!X26 -> 242250 | L12: =F12-J12 -> -5185.7 | N12: =H12-J12 -> 0
B13: ='Expenditure Breakdown'!B37 -> 5 | D13: ='Expenditure Breakdown'!C37 -> Monitoring | F13: =+'Expenditure Breakdown'!J37 -> 49000 | H13: 80720.5 | J13: =+'Expenditure Breakdown'!X37 -> 71452.01 | L13: =F13-J13 -> -22452.01 | N13: =H13-J13 -> 9268.49
B14: ='Expenditure Breakdown'!B44 -> 6 | D14: ='Expenditure Breakdown'!C44 -> AC Equipment | F14: =+'Expenditure Breakdown'!J44 -> 304429.82 | H14: 212432 | J14: =+'Expenditure Breakdown'!X44 -> 212863.6 | L14: =F14-J14 -> 91566.22 | N14: =H14-J14 -> -431.6
B15: ='Expenditure Breakdown'!B59 -> 7 | D15: ='Expenditure Breakdown'!C59 -> Battery Systems | F15: =+'Expenditure Breakdown'!J59 -> 0 | H15: 0 | J15: ='Expenditure Breakdown'!X59 -> 0 | L15: =F15-J15 -> 0 | N15: =H15-J15 -> 0
B16: ='Expenditure Breakdown'!B68 -> 8 | D16: ='Expenditure Breakdown'!C68 -> Product Add On | F16: ='Expenditure Breakdown'!J68 -> 0 | H16: 0 | J16: ='Expenditure Breakdown'!X68 -> 158729.52 | L16: =F16-J16 -> -158729.52 | N16: =H16-J16 -> -158729.52
B17: ='Expenditure Breakdown'!M77 -> 9 | D17: ='Expenditure Breakdown'!C77 -> AC & DC Installation | F17: =+'Expenditure Breakdown'!J77 -> 208050 | H17: 175013.8 | J17: =+'Expenditure Breakdown'!X77 -> 175013.8 | L17: =F17-J17 -> 33036.2 | N17: =H17-J17 -> 0
B18: ='Expenditure Breakdown'!B86 -> 10 | D18: ='Expenditure Breakdown'!C86 -> Site Logistics | F18: =+'Expenditure Breakdown'!J86 -> 38356.3 | H18: 122767 | J18: =+'Expenditure Breakdown'!X86 -> 107767 | L18: =F18-J18 -> -69410.7 | N18: =H18-J18 -> 15000
B19: ='Expenditure Breakdown'!B101 -> 11 | D19: ='Expenditure Breakdown'!C101 -> Due Dilligence | F19: ='Expenditure Breakdown'!J101 -> 89000 | H19: 23020 | J19: ='Expenditure Breakdown'!X101 -> 14174.76 | L19: =F19-J19 -> 74825.24 | N19: =H19-J19 -> 8845.24
B20: ='Expenditure Breakdown'!B109 -> 12 | D20: ='Expenditure Breakdown'!C109 -> BDP Commission | F20: ='Expenditure Breakdown'!G107 -> 63011.44 | H20: 63043.34 | J20: ='Expenditure Breakdown'!X107 -> 63043.34 | L20: =F20-J20 -> -31.9 | N20: =H20-J20 -> 0
B21: ='Expenditure Breakdown'!B111 -> 13 | D21: ='Expenditure Breakdown'!C111 -> Engineering | F21: =+'Expenditure Breakdown'!J111 -> 163448.56 | H21: 170795.12 | J21: =+'Expenditure Breakdown'!X111 -> 62400 | L21: =F21-J21 -> 101048.56 | N21: =H21-J21 -> 108395.12 | P21: RV: Matriarch defects percentage 1.25%
B22: ='Expenditure Breakdown'!B119 -> 14 | D22: ='Expenditure Breakdown'!C119 -> General Expenses | F22: =+'Expenditure Breakdown'!J119 -> 4200 | H22: 4200 | J22: =+'Expenditure Breakdown'!X119 -> 7385.64 | L22: =F22-J22 -> -3185.64 | N22: =H22-J22 -> -3185.64
B23: ='Expenditure Breakdown'!B128 -> 15 | D23: ='Expenditure Breakdown'!C128 -> Service Add On | F23: =+'Expenditure Breakdown'!J128 -> 0 | H23: 0 | J23: =+'Expenditure Breakdown'!X128 -> 32247.49 | L23: =F23-J23 -> -32247.49 | N23: =H23-J23 -> -32247.49
D25: check: | F25: ='Expenditure Breakdown'!J2-'Expenditure Tracking'!F5 -> 0 | G25: ='Expenditure Breakdown'!#REF!-G5 -> #REF! | H25: ='Expenditure Breakdown'!X2-J5 -> 0 | I25: ='Expenditure Breakdown'!#REF!-I5 -> #REF! | J25: ='Expenditure Breakdown'!X2-J5 -> 0
A27: Copy amounts in column H and paste as values at Project review.

Sheet Expenditure Breakdown
B2: COSTED EXPENDITURE BREAKDOWN | J2: =SUM(J6:J132) -> 2105194.2 | K2: =SUM(K6:K132) -> 2506224.1 | M2: ACTUAL EXPENDITURE BREAKDOWN | S2: FINANCE ONLY | X2: =SUM(X6:X132) -> 2103862.1
B4: No. | C4: Product / Service | D4: Description of Work | E4: QTY | F4: Rate / Unit | G4: Budget Total | H4: Project Related date | J4: Total COS | K4: =IF(K2-'Revenue Tracking'!D4>=0, "Total Revenue", "ERROR on REV" ) -> Total Revenue | M4: No. | N4: Product/ Service | O4: Description of Work | P4: QTY | Q4: Rate / Unit | R4: Actual Total | S4: INVOICE NUMBER | T4: INVOICE RAISED DATE | U4: REVENUE RECOGNITION AMOUNT | V4: CHECK | W4: FINANCE PAYMENT DATE | X4: Total COS | Y4: PO NUMBER | Z4: COMMENTS
B6: 1 | C6: Panels | D6: Longi 570W - Costing Sheet | E6: 438 | F6: 1531.9035 | G6: =E6*F6 -> 670973.73 | H6: ='Project Plan'!E35+60 -> 45636 | J6: =SUM(G6:G11) -> 690973.73 | K6: 842650.89 | M6: 1 | N6: 1. Panels | O6: Canadian Solar 555W - Deposit - Herholdts | P6: 450 | Q6: 1415.25 | R6: =P6*Q6*0.5 -> 318431.25 | S6: Herholdts Inv: INV875402 | T6: 45504 | U6: 396426.72 | V6: =K6-SUM(U6:U11) -> -0.00044532667 | W6: 45562 | X6: =SUM(R6:R11) -> 647765.5 | Y6: PO3244-SAM-20240719 - RV Approved | AA6: 19
B7: 1 | D7: Jinko Solar 575W | M7: 1 | N7: 1. Panels | R7: =P6*Q6*0.5 -> 318431.25 | S7: Herholdts Inv: INV875402 | T7: 45504 | U7: 396426.72 | W7: 45596 | AA7: BUDGET | AB7: Installer Allocation
B8: 1 | M8: 1 | N8: 1. Panels | O8: Storage handling Fee | R8: 1300 | S8: Supply Chain: Inv SCO04502 | T8: 45596 | U8: 1691.1153 | W8: 45625 | AA8: AC Equipment | AB8: =C51 -> 304429.82
B9: 1 | D9: Delivery | G9: 20000 | H9: =H6 -> 45636 | M9: 1 | N9: 1. Panels | O9: Delivery | R9: 8550 | S9: Supply Chain: Inv SCO04533 | T9: 45596 | U9: 11122.335 | W9: 45625 | AA9: DC Equipment | AB9: =SUM(G28:G35) -> 116936.3
B10: 1 | M10: 1 | N10: 1. Panels | O10: Storage | R10: 1053 | S10: Supply Chain: Inv SCO04502 | T10: =T9 -> 45596 | U10: 1369.8034 | W10: 45625 | AA10: AC Labour | AB10: =C79 -> 145635
B11: 1 | M11: 1 | N11: 1. Panels | O11: Delivery and storage budget | T11: 45626 | U11: 35614.21 | AA11: DC Labour | AB11: =C78 -> 62415
AA12: Offloading | AB12: =G96 -> 8500
B13: 2 | C13: Inverters | D13: Huawei 100KTL | E13: 2 | F13: 78898 | G13: =E13*F13 -> 157796 | H13: ='Project Plan'!E22+30 -> 45590 | J13: =SUM(G13:G16) -> 157796 | K13: 192434.15 | M13: 2 | N13: 2. Inverters | O13: Huawei 100KTL | P13: 2 | Q13: 68870 | R13: =P13*Q13 -> 137740 | S13: Kathea Inv518635 | T13: 45565 | U13: 190902.34 | V13: =K13-SUM(U13:U16) -> 0 | W13: =T13+30 -> 45595 | X13: =SUM(R13:R16) -> 138845.23 | Z13: MI: Kathea quote | AA13: Telehandler | AB13: =G86 -> 0
B14: 2 | M14: 2 | N14: 2. Inverters | U14: =(R14/$X$13*$K$13) -> 0 | AA14: Storage | AB14: =G97 -> 0
B15: 2 | M15: 2 | N15: 2. Inverters | O15: Delivery | R15: 1105.23 | S15: Kathea Inv518635 | T15: 45565 | U15: 1531.8063 | W15: =W13 -> 45595 | AA15: =D99 -> Scaffolding | AB15: =G99 -> 29856.3
B16: 2 | M16: 2 | N16: 2. Inverters | U16: =(R16/$X$13*$K$13) -> 0 | AA16: Other | AB16: 0
AA17: Total | AB17: =SUM(AB8:AB16) -> 667772.42
B18: 3 | C18: Mounting Structures | D18: KlipLok Roof | E18: ='Project Plan'!E3*1000 -> 250000 | F18: 0.45 | G18: 99864 | H18: ='Project Plan'!E19+30 -> 45590 | J18: =SUM(G18:G24) -> 99864 | K18: 121785.37 | M18: 3 | N18: 3. Mounting Structures | O18: MS | P18: 1 | Q18: 56499.4 | R18: =P18*Q18 -> 56499.4 | S18: Schletter Inv0891 | T18: 45565 | U18: 117065.68 | V18: =K18-SUM(U18:U24) -> 0 | W18: 45558 | X18: =SUM(R18:R24) -> 169924.22 | Y18: PO3364-SAM22-20240918 - RV Approved | AA18: Less 15% | AB18: =+AB17*0.85 -> 567606.56 | AF18: 62178.86
B19: 3 | M19: 3 | N19: 3. Mounting Structures | R19: -56499.4 | S19: Schletter Inv0891 | T19: 45657 | U19: 0 | W19: 45657 | AA19: R/Wp | AB19: =+AB18/'Project Plan'!$E$3/1000 -> 2.2704262
M20: 3 | N20: 3. Mounting Structures | R20: 44229.04 | S20: Schletter Inv0891 | T20: 45657 | W20: 45657
B21: 3 | M21: 3 | N21: 3. Mounting Structures | O21: Delivery | R21: 1850 | S21: Schletter Inv0893 | T21: 45565 | U21: 3833.1648 | W21: =W18 -> 45558
M22: 3 | N22: 3. Mounting Structures | O22: Seam Clamps | R22: 155413 | S22: Schletter Inv: INV1051 | T22: 45626 | U22: 0 | W22: 45645
M23: 3 | N23: 3. Mounting Structures | O23: Seam Clamp Returned | R23: -31995.68 | S23: Schletter Credit: CRN0160 | T23: 45626 | W23: 45645
B24: 3 | M24: 3 | N24: 3. Mounting Structures | R24: 427.86 | S24: DSV Inv: 180099596 | T24: 45596 | U24: 886.51779 | W24: 45625 | AA24: ACTUAL - Cosmic Sun | AB24: Installer Price | AE24: ACTUAL - Thula Moya | AF24: Installer Price | AH24: ACTUAL - CornerStone | AI24: Installer Price
T25: =IF(W25>1,EOMONTH(W25,-1),"") | AA25: AC Equipment | AB25: 79400 | AE25: AC Equipment | AF25: 146732 | AH25: AC Equipment | AI25: =55724.24+6662.03 -> 62386.27 | AJ25: *Removed 6 Comms Metering R25976,34
B26: 4 | C26: DC Equipment | D26: DC Cable | E26: 6133 | F26: 16 | G26: =E26*F26 -> 98128 | H26: ='Project Plan'!E31+30 -> 45590 | J26: =SUM(G26:G35) -> 237064.3 | K26: 289102.8 | M26: 4 | N26: 4. DC Equipment | O26: DC Cable | P26: 8000 | Q26: 13.5 | R26: =P26*Q26 -> 108000 | S26: Herholdts Inv: INV922149 | T26: 45596 | U26: 128887.94 | V26: =K26-SUM(U26:U35) -> 0 | W26: 45596 | X26: =SUM(R26:R35) -> 242250 | Y26: PO3315-MUL-20240823 - RV Approved | Z26: MI: Herholdts quote | AA26: DC Equipment | AB26: 84262.4 | AE26: DC Equipment | AF26: 134250 | AH26: DC Equipment | AI26: 145954.74
B27: 4 | D27: DC Surge Arrestor | E27: 4 | F27: 5500 | G27: =E27*F27 -> 22000 | H27: =H28 -> 45606 | M27: 4 | N27: 4. DC Equipment | O27: Delivery | R27: 0 | U27: =(R27/$X$26*$K$26) -> 0 | AA27: AC Labour | AB27: 62500 | AE27: AC Labour | AF27: 62504 | AH27: AC Labour | AI27: 15154.29
B28: 4 | D28: DC Cable Tray | E28: 220 | F28: 152 | G28: =E28*F28 -> 33440 | H28: ='Project Plan'!E34+30 -> 45606 | M28: 4 | N28: 4. DC Equipment | O28: Project Kick Off | P28: =AF26 -> 134250 | Q28: 0.1 | R28: =$P$28*Q28 -> 13425 | S28: Thula Moya Inv04436 | T28: =T77 -> 45565 | U28: 16021.487 | W28: =W77 -> 45560 | Y28: PO3367-SAM22-20240924 - RV Approved | AA28: DC Labour | AB28: 149000 | AC28: =SUM(AB27:AB28)/250000 -> 0.846 | AE28: DC Labour | AF28: 112509.8 | AG28: =SUM(AF27:AF28)/250000 -> 0.7000552 | AH28: DC Labour | AI28: 191994.01 | AJ28: =SUM(AI27:AI28)/250000 -> 0.8285932
B29: 4 | D29: Earth Cable | E29: =E26 -> 6133 | F29: 13.5 | G29: =E29*F29 -> 82795.5 | H29: =H18 -> 45590 | M29: 4 | N29: 4. DC Equipment | O29: Site Establishment | Q29: 0.15 | R29: =$P$28*Q29 -> 20137.5 | S29: Thula Moya Inv04439 | T29: =T78 -> 45565 | U29: 24032.23 | W29: =W78 -> 45575 | AA29: Offloading | AB29: 8500 | AE29: Site Logistics | AF29: 47669 | AH29: Site Logistics | AI29: =76775.4+15381.6 -> 92157
B30: 4 | D30: Earth clamp | E30: 43.8 | F30: 16 | G30: =E30*F30 -> 700.8 | H30: ='Project Plan'!E35 -> 45576 | M30: 4 | N30: 4. DC Equipment | O30: AC Installation Complete | Q30: 0.2 | R30: =$P$28*Q30 -> 26850 | S30: Thula Moya IN04473 | T30: =T79 -> 45596 | U30: 32042.973 | W30: =W79 -> 45596 | AA30: Roof Access | AB30: 15000 | AE30: Sundries | AF30: 14986 | AH30: HSE | AI30: 7027.8
B31: 4 | M31: 4 | N31: 4. DC Equipment | O31: DC Installation Complete | Q31: 0.25 | R31: =$P$28*Q31 -> 33562.5 | S31: Thula Moya IN04474 | T31: =T80 -> 45596 | U31: 40053.717 | W31: =W80 -> 45596 | AA31: Container | AB31: 8500 | AE31: Accomodation | AF31: 45112 | AH31: COC | AI31: 3978
B32: 4 | M32: 4 | N32: 4. DC Equipment | O32: Commissioning Complete | Q32: 0.1 | R32: =$P$28*Q32 -> 13425 | S32: Thula Moya IN04475 | T32: 45596 | U32: 16021.487 | W32: =W81 -> 45610 | AA32: HSE | AB32: 4500 | AE32: Scaffolding | AF32: 0 | AH32: Travel | AI32: 17801.55
B33: 4 | M33: 4 | N33: 4. DC Equipment | O33: Site De-establisment | Q33: 0.1 | R33: =$P$28*Q33 -> 13425 | S33: Thula Moya IN04476 | T33: 45596 | U33: 16021.487 | W33: =W82 -> 45631 | AA33: Other | AB33: 0 | AE33: Other | AF33: 0 | AH33: Other | AI33: 0
B34: 4 | M34: 4 | N34: 4. DC Equipment | O34: Handover Document Complete | Q34: 0.05 | R34: =$P$28*Q34 -> 6712.5 | S34: =S83 -> Thula Moya IN04598 | T34: =T83 -> 45688 | U34: 8010.7434 | W34: =W83 -> 45701 | AA34: Other | AB34: 0 | AE34: Other | AF34: 0 | AH34: Other | AI34: 0
B35: 4 | M35: 4 | N35: 4. DC Equipment | O35: End of Defects Period | Q35: 0.05 | R35: =$P$28*Q35 -> 6712.5 | S35: =S84 -> Thula Moya IN04599 | T35: =T84 -> 45688 | U35: 8010.7434 | W35: =W84 -> 45722 | AA35: Other | AB35: 0 | AE35: Other | AF35: 0 | AH35: Other | AI35: 0
T36: =IF(W36>1,EOMONTH(W36,-1),"") | AA36: Total | AB36: =SUM(AB25:AB35) -> 411662.4 | AE36: Total | AF36: =SUM(AF25:AF35) -> 563762.8 | AH36: Total | AI36: =SUM(AI25:AI35) -> 536453.66
B37: 5 | C37: Monitoring | D37: Smartlogger 3000 | E37: 1 | F37: 26000 | G37: =F37*E37 -> 26000 | H37: =H13 -> 45590 | J37: =SUM(G37:G42) -> 49000 | K37: 59756.098 | M37: 5 | N37: 5. Monitoring | O37: Smartlogger 3000 | P37: 1 | Q37: 8000 | R37: =Q37*P37 -> 8000 | S37: Solarworld SASIV-24-00517 | T37: 45535 | U37: 5922.2723 | V37: =K37-SUM(U37:U42) -> 0.00081832578 | W37: =T37+30 -> 45565 | X37: =SUM(R37:R42) -> 71452.01 | Z37: MI: Kathea quote | AA37: R/Wp | AB37: =+AB36/'Project Plan'!$E$3/1000 -> 1.6466496 | AE37: R/Wp | AF37: =+AF36/'Project Plan'!$E$3/1000 -> 2.2550512 | AH37: R/Wp | AI37: =+AI36/'Project Plan'!$E$3/1000 -> 2.1458146
B38: 5 | D38: Comms DB | G38: 8000 | H38: =H37 -> 45590 | M38: 5 | N38: 5. Monitoring | O38: CTs | R38: 13970.5 | S38: AccuEnergy ASAI-003743 | T38: 45535 | U38: 10342.138 | W38: =T38+30 -> 45565
B39: 5 | D39: Revenue Grade Meter | E39: 1 | F39: 15000 | G39: =F39*E39 -> 15000 | H39: ='Project Plan'!G51 -> 45618 | M39: 5 | N39: 5. Monitoring | O39: Revenue Grade Meter | P39: 1 | Q39: 11169 | R39: =Q39*P39 -> 11169 | S39: MATRIARCH - INV-3278 | T39: 45626 | U39: 11797.237 | W39: 45626
B40: 5 | M40: 5 | N40: 5. Monitoring | O40: SCADA | R40: 35750 | S40: Rubicon INVWCRE-0060133 | T40: 45535 | U40: 26465.154 | W40: 45562
B41: 5 | M41: 5 | N41: 5. Monitoring | O41: Frontline Comms Equipment | R41: =12812.55/5 -> 2562.51 | S41: Frontline Electrical: INV697940 | T41: 45596 | U41: 5229.2951 | W41: 45575 | Y41: PO3387-SAM-20241007 - RV Approved | Z41: PO split across the portfolio
B42: 5 | M42: 5 | N42: 5. Monitoring | T42: =IF(W42>1,EOMONTH(W42,-1),"") | U42: =(R42/$X$37*$K$37) -> 0
T43: =IF(W43>1,EOMONTH(W43,-1),"")
...

Sheet Cashflow
