Workbook
Name Inverter_Capacity: #REF!
Name Inverter_Supplier: #REF!
Name Project_Size: 'Finance - Revenue'!Projectsize
Name Project_Size: Projectsize
Name Projectsize: #REF!
Name Projectsize: #REF!
Name Security_Serv: #REF!
Name Security_Serv: #REF!
Name SSS: #REF!
Name SSS: #REF!
Name USD_ZAR: #REF!

Sheet Certificate - Financial Close
B2: Emergent Energy – Financial Close Completion Certificate | H2: FINANCIAL CLOSE CERTIFICATE
B4: Project Name: | C4: ='Project Plan'!E2 -> 25 Superior Road
B5: COO: | C5: Johannes Potgieter
B6: Programme Manager: | C6: Roedolph Venter
B7: HoPD: | C7: Natasha Watkins-Baker
B9: Date of Phase Completion:
B10: Phase Deliverables Checklist: (Y/N)
B11: Product Agreement
B12: EPC Agreement
B13: O&M Agreeement
B14: Cost Proposal
B15: Deposit Received
B16: Risks / Notes
B18: Acknowledgement and Acceptance:
B19: Role | C19: Name | D19: Signature | E19: Date

Sheet Certificate - Planning
B2: Emergent Energy – Planning Phase Completion Certificate | H2: PLANNING CERTIFICATE
B4: Project Name: | C4: ='Project Plan'!E2 -> 25 Superior Road
B5: Client Representative:
B6: Programme Manager: | C6: Roedolph Venter
B7: Project Manager: | C7: ='Project Plan'!E5 -> JT Moorosi
B8: Project Engineer:
B10: Date of Phase Completion:
B11: Phase Deliverables Checklist: (Y/N)
B12: Project Introduction Presentation
B13: Project Brief
B14: Engineering Pack
B15: BOQ
B16: PO – Material & Equipment
B17: PO - Contractors
B18: HSE – NOC
B19: HSE – EE File
B20: HSE – Contractor File
... B24: Acknowledgement and Acceptance:
B25: Role | C25: Name | D25: Signature | E25: Date

Sheet Change Register
F1: Change Register
B3: ID | C3: Description | D3: Supporting Image (If Applicable) | E3: Impact | F3: Proposed Date | G3: Proposed By | H3: Status | I3: Approved By | J3: Approved Date | K3: Results / Comments
B4: DEC001
B5: DEC002
B6: DEC003
B7: DEC004
B8: DEC005
B9: DEC006
B10: DEC007
B11: DEC008
B12: DEC009
B13: DEC010
B14: DEC011
B15: DEC012
... B33: DEC030

Sheet BOQ
B2: Item | C2: Supplier | D2: Description | E2: Quantity | F2: Comments
B3: PV Module
B4: DC Cable Red & Black
B5: Inverters
B6: Mounting Structure
B7: Current Transformers (Production)
B8: Current Transformers (Consumption)
B9: Solar Production Meter (Techistter)
B10: Grid Consumption Meter
B11: Wi-Fi Router & Sim
B12: Switch
B13: Back Up Battery
B14: PVDB
... B30: Techsitter

Sheet Compliance
B2: HSE
B4: Description | C4: Status | D4: Approved By | E4: Date | F4: Results / Comments
B5: NOC | F5: In progress
B6: 7.1 Agreement | F6: In progress
B7: 13.2 Agreement | F7: In progress
B8: EE File | F8: In progress
B9: Subbie File | F9: Not appointed yet
B16: SSEG
B18: Description | C18: Status | D18: Approved By | E18: Date | F18: Results / Comments
B19: SSEG Application
B20: PTI
B21: Commissioning Approval

Sheet Project Plan
N1: =TODAY() -> 46055 | O1: =TODAY() -> 46055
C2: PROJECT PLAN | E2: 25 Superior Road | I2: Net Work Days | K2: =NETWORKDAYS(I19,K40,Data!C3:C60) -> 23 | N2: 0 | O2: 1
C3: PROJECT SIZE (kWp) | E3: 120 | I3: Total Weeks | K3: =K2/5 -> 4.6
C4: PROJECT DEVELOPER | E4: Megan Moore | I4: kW/Week Installation Rate | K4: =E3/K3 -> 26.086957
C5: PROJECT MANAGERS | E5: JT Moorosi
C6: CONTRACT VALUE | E6: 2899774.7
C7: Phase: | E7: Financial Close
B8: No. | C8: HIGH LEVEL PROGRAMME | E8: Planned Start | F8: Duration | G8: Planned End | I8: Actual Start | J8: Duration | K8: Actual End | M8: Status | N8: Expected Status | O8: Comment
F9: =G40-E20 -> 35 | J9: =K40-I20 -> 34 | M9: =AVERAGE(M11,M19,M22,M29,M36,M40,M49,M45) -> 0 | N9: =AVERAGE(N11,N19,N22,N29,N36,N40,N49,N45) -> 0.070080036 | S9: =TODAY() -> 46055 | T9: =TODAY() -> 46055
S10: 1 | T10: 0
B11: 1 | C11: Project Initiation | E11: =MIN(E12:E18) -> 46038 | F11: =G11-E11 -> 25 | G11: =MAX(G12:G18) -> 46063 | I11: =MIN(I12:I18) -> 46038 | J11: =K11-I11 -> 42 | K11: =MAX(K12:K18) -> 46080 | M11: =(J12*M12+J14*M14+J15*M15+J16*M16+J17*M17)/SUM(J12:J17) -> 0 | N11: =(K12*N12+K14*N14+K15*N15+K16*N16+K17*N17)/SUM(K12:K17) -> 0.44436122
B12: 1.1 | C12: Project Charter Handover | E12: 46038 | F12: 1 | G12: =WORKDAY.INTL(E12,F12,1,Data!$C$3:$C$60) -> 46041 | I12: 46038 | J12: 1 | K12: =WORKDAY.INTL(I12,J12,1,Data!$C$3:$C$60) -> 46041 | M12: 0 | N12: =_xlfn.LET( _xlpm.s,VALUE($I12), _xlpm.e,VALUE($K12), IF(OR(_xlpm.s="",_xlpm.e=""),"", IF(_xlpm.e<=_xlpm.s, IF(TODAY()>=_xlpm.e,1,0), MAX(0,MIN(1,(TODAY()-_xlpm.s)/(_xlpm.e-_xlpm.s))))) ) -> 1 | S12: Milestone | T12: Start Date | U12: Duration | V12: End Date
C13: Contracts | I13: =I12 -> 46038 | J13: 30 | K13: =WORKDAY.INTL(I13,J13,1,Data!$C$3:$C$60) -> 46080
B14: 1.2 | C14: HSE Readiness and Signoff | E14: =G12 -> 46041 | F14: 15 | G14: =WORKDAY.INTL(E14,F14,1,Data!$C$3:$C$60) -> 46062 | I14: =K12 -> 46041 | J14: 15 | K14: =WORKDAY.INTL(I14,J14,1,Data!$C$3:$C$60) -> 46062 | M14: 0 | N14: =_xlfn.LET( _xlpm.s,VALUE($I14), _xlpm.e,VALUE($K14), IF(OR(_xlpm.s="",_xlpm.e=""),"", IF(_xlpm.e<=_xlpm.s, IF(TODAY()>=_xlpm.e,1,0), MAX(0,MIN(1,(TODAY()-_xlpm.s)/(_xlpm.e-_xlpm.s))))) ) -> 0.66666667 | S14: =C11 -> Project Initiation | T14: =I11 -> 46038 | U14: =J11 -> 42 | V14: =K11 -> 46080
B15: 1.3 | C15: Project Introduction | E15: =WORKDAY.INTL(G14,0,1,Data!$C$3:$C$60) -> 46062 | F15: 1 | G15: =WORKDAY.INTL(E15,F15,1,Data!$C$3:$C$60) -> 46063 | I15: =WORKDAY.INTL(K14,0,1,Data!$C$3:$C$60) -> 46062 | J15: 1 | K15: =WORKDAY.INTL(I15,J15,1,Data!$C$3:$C$60) -> 46063 | M15: 0 | N15: =_xlfn.LET( _xlpm.s,VALUE($I15), _xlpm.e,VALUE($K15), IF(OR(_xlpm.s="",_xlpm.e=""),"", IF(_xlpm.e<=_xlpm.s, IF(TODAY()>=_xlpm.e,1,0), MAX(0,MIN(1,(TODAY()-_xlpm.s)/(_xlpm.e-_xlpm.s))))) ) -> 0 | S15: =C19 -> Site Establishment | T15: =I19 -> 46087 | U15: =J19 -> 1 | V15: =K19 -> 46088
B16: 1.4 | C16: Installer Kick Off | E16: =WORKDAY.INTL(E14,0,1,Data!$C$3:$C$60)+14 -> 46055 | F16: 1 | G16: =WORKDAY.INTL(E16,F16,1,Data!$C$3:$C$60) -> 46056 | I16: =WORKDAY.INTL(I14,0,1,Data!$C$3:$C$60)+14 -> 46055 | J16: 1 | K16: =WORKDAY.INTL(I16,J16,1,Data!$C$3:$C$60) -> 46056 | M16: 0 | N16: =_xlfn.LET( _xlpm.s,VALUE($I16), _xlpm.e,VALUE($K16), IF(OR(_xlpm.s="",_xlpm.e=""),"", IF(_xlpm.e<=_xlpm.s, IF(TODAY()>=_xlpm.e,1,0), MAX(0,MIN(1,(TODAY()-_xlpm.s)/(_xlpm.e-_xlpm.s))))) ) -> 0 | S16: =C22 -> AC Installation | T16: =I22 -> 46048 | U16: =J22 -> 60 | V16: =K22 -> 46108
B17: 1.5 | C17: Project Review | E17: =WORKDAY.INTL(E16,0,1,Data!$C$3:$C$60)-4 -> 46051 | F17: 1 | G17: =WORKDAY.INTL(E17,F17,1,Data!$C$3:$C$60) -> 46052 | I17: =WORKDAY.INTL(I16,0,1,Data!$C$3:$C$60)-4 -> 46051 | J17: 1 | K17: =WORKDAY.INTL(I17,J17,1,Data!$C$3:$C$60) -> 46052 | M17: 0 | N17: =_xlfn.LET( _xlpm.s,VALUE($I17), _xlpm.e,VALUE($K17), IF(OR(_xlpm.s="",_xlpm.e=""),"", IF(_xlpm.e<=_xlpm.s, IF(TODAY()>=_xlpm.e,1,0), MAX(0,MIN(1,(TODAY()-_xlpm.s)/(_xlpm.e-_xlpm.s))))) ) -> 1 | S17: =C29 -> DC Works | T17: =I29 -> 46087 | U17: =J29 -> 20 | V17: =K29 -> 46107
S18: =C36 -> Module installation | T18: =I36 -> 46087 | U18: =J36 -> 19 | V18: =K36 -> 46106
B19: 2 | C19: Site Establishment | E19: =MIN(E20:E21) -> 46086 | F19: =G19-E19 -> 1 | G19: =MAX(G20:G21) -> 46087 | I19: =MIN(I20:I21) -> 46087 | J19: =K19-I19 -> 1 | K19: =MAX(K20:K21) -> 46088 | M19: =(J20*M20)/J19 -> 0 | N19: =(K20*N20)/K19 -> 0 | S19: =C40 -> Commissioning | T19: =I40 -> 46108 | U19: =J40 -> 13 | V19: =K40 -> 46121
B20: 2.1 | C20: Solar Contractor Establishment | E20: 46086 | F20: 1 | G20: =E20+F20 -> 46087 | I20: =K11+7 -> 46087 | J20: 1 | K20: =I20+J20 -> 46088 | M20: 0 | N20: =_xlfn.LET( _xlpm.s,VALUE($I20), _xlpm.e,VALUE($K20), IF(OR(_xlpm.s="",_xlpm.e=""),"", IF(_xlpm.e<=_xlpm.s, IF(TODAY()>=_xlpm.e,1,0), MAX(0,MIN(1,(TODAY()-_xlpm.s)/(_xlpm.e-_xlpm.s))))) ) -> 0 | S20: =C45 -> QA Inspections | T20: =I45 -> 46112 | U20: =J45 -> 10 | V20: =K45 -> 46122
S21: =C49 -> Project Closure | T21: =I49 -> 46119 | U21: =J49 -> 16 | V21: =K49 -> 46135
B22: 3 | C22: AC Installation | E22: =MIN(E23:E28) -> 46048 | F22: =G22-E22 -> 60 | G22: =MAX(G23:G28) -> 46108 | I22: =MIN(I23:I28) -> 46048 | J22: =K22-I22 -> 60 | K22: =MAX(K23:K28) -> 46108 | M22: =(J23*M23+J24*M24+J25*M25+J26*M26+J27*M27)/SUM(J23:J27) -> 0 | N22: =(J23*N23+J24*N24+J25*N25+J26*N26+J27*N27)/SUM(J23:J27) -> 0.11627907
B23: 3.1 | C23: Inverters delivered | E23: =WORKDAY.INTL(G20,0,1,Data!$C$3:$C$60) -> 46087 | F23: 1 | G23: =WORKDAY.INTL(E23,F23,1,Data!$C$3:$C$60) -> 46090 | I23: =WORKDAY.INTL(K20,0,1,Data!$C$3:$C$60) -> 46088 | J23: 1 | K23: =WORKDAY.INTL(I23,J23,1,Data!$C$3:$C$60) -> 46090 | M23: 0 | N23: =_xlfn.LET( _xlpm.s,VALUE($I23), _xlpm.e,VALUE($K23), IF(OR(_xlpm.s="",_xlpm.e=""),"", IF(_xlpm.e<=_xlpm.s, IF(TODAY()>=_xlpm.e,1,0), MAX(0,MIN(1,(TODAY()-_xlpm.s)/(_xlpm.e-_xlpm.s))))) ) -> 0
B24: 3.2 | C24: Inverters Mounted | E24: =WORKDAY.INTL(G23,0,1,Data!$C$3:$C$60) -> 46090 | F24: 1 | G24: =WORKDAY.INTL(E24,F24,1,Data!$C$3:$C$60) -> 46091 | I24: =WORKDAY.INTL(K23,0,1,Data!$C$3:$C$60) -> 46090 | J24: 1 | K24: =WORKDAY.INTL(I24,J24,1,Data!$C$3:$C$60) -> 46091 | M24: 0 | N24: =_xlfn.LET( _xlpm.s,VALUE($I24), _xlpm.e,VALUE($K24), IF(OR(_xlpm.s="",_xlpm.e=""),"", IF(_xlpm.e<=_xlpm.s, IF(TODAY()>=_xlpm.e,1,0), MAX(0,MIN(1,(TODAY()-_xlpm.s)/(_xlpm.e-_xlpm.s))))) ) -> 0
B25: 3.3 | C25: Solar DB Lead Time | E25: =WORKDAY.INTL(E15,0,1,Data!$C$3:$C$60)-14 -> 46048 | F25: 25 | G25: =WORKDAY.INTL(E25,F25,1,Data!$C$3:$C$60) -> 46083 | I25: =WORKDAY.INTL(I15,0,1,Data!$C$3:$C$60)-14 -> 46048 | J25: 25 | K25: =WORKDAY.INTL(I25,J25,1,Data!$C$3:$C$60) -> 46083 | M25: 0 | N25: =_xlfn.LET( _xlpm.s,VALUE($I25), _xlpm.e,VALUE($K25), IF(OR(_xlpm.s="",_xlpm.e=""),"", IF(_xlpm.e<=_xlpm.s, IF(TODAY()>=_xlpm.e,1,0), MAX(0,MIN(1,(TODAY()-_xlpm.s)/(_xlpm.e-_xlpm.s))))) ) -> 0.2
B26: 3.4 | C26: AC Works | E26: =E23 -> 46087 | F26: 15 | G26: =WORKDAY.INTL(E26,F26,1,Data!$C$3:$C$60) -> 46108 | I26: =I23 -> 46088 | J26: 15 | K26: =WORKDAY.INTL(I26,J26,1,Data!$C$3:$C$60) -> 46108 | M26: 0 | N26: =_xlfn.LET( _xlpm.s,VALUE($I26), _xlpm.e,VALUE($K26), IF(OR(_xlpm.s="",_xlpm.e=""),"", IF(_xlpm.e<=_xlpm.s, IF(TODAY()>=_xlpm.e,1,0), MAX(0,MIN(1,(TODAY()-_xlpm.s)/(_xlpm.e-_xlpm.s))))) ) -> 0
B27: 3.5 | C27: AC Tie-In | E27: =WORKDAY.INTL(E26,0,1,Data!$C$3:$C$60) -> 46087 | F27: 1 | G27: =WORKDAY.INTL(E27,F27,1,Data!$C$3:$C$60) -> 46090 | I27: =WORKDAY.INTL(I26,0,1,Data!$C$3:$C$60) -> 46088 | J27: 1 | K27: =WORKDAY.INTL(I27,J27,1,Data!$C$3:$C$60) -> 46090 | M27: 0 | N27: =_xlfn.LET( _xlpm.s,VALUE($I27), _xlpm.e,VALUE($K27), IF(OR(_xlpm.s="",_xlpm.e=""),"", IF(_xlpm.e<=_xlpm.s, IF(TODAY()>=_xlpm.e,1,0), MAX(0,MIN(1,(TODAY()-_xlpm.s)/(_xlpm.e-_xlpm.s))))) ) -> 0
B29: 4 | C29: DC Works | E29: =MIN(E31:E35) -> 46086 | F29: =G29-E29 -> 21 | G29: =MAX(G31:G35) -> 46107 | I29: =MIN(I31:I35) -> 46087 | J29: =K29-I29 -> 20 | K29: =MAX(K31:K35) -> 46107 | M29: =(J31*M31+J32*M32+J34*M34)/SUM(J31:J34) -> 0 | N29: =(K31*N31+K32*N32+K34*N34)/SUM(K31:K34) -> 0
B31: 4.1 | C31: Mounting Structure delivered | E31: =E20 -> 46086 | F31: 1 | G31: =WORKDAY.INTL(E31,F31,1,Data!$C$3:$C$60) -> 46087 | I31: =I20 -> 46087 | J31: 1 | K31: =WORKDAY.INTL(I31,J31,1,Data!$C$3:$C$60) -> 46090 | M31: 0 | N31: =_xlfn.LET( _xlpm.s,VALUE($I31), _xlpm.e,VALUE($K31), IF(OR(_xlpm.s="",_xlpm.e=""),"", IF(_xlpm.e<=_xlpm.s, IF(TODAY()>=_xlpm.e,1,0), MAX(0,MIN(1,(TODAY()-_xlpm.s)/(_xlpm.e-_xlpm.s))))) ) -> 0
B32: 4.2 | C32: Mounting Structure installation | E32: =WORKDAY.INTL(G31,0,1,Data!$C$3:$C$60) -> 46087 | F32: 3 | G32: =WORKDAY.INTL(E32,F32,1,Data!$C$3:$C$60) -> 46092 | I32: =WORKDAY.INTL(K31,0,1,Data!$C$3:$C$60) -> 46090 | J32: 3 | K32: =WORKDAY.INTL(I32,J32,1,Data!$C$3:$C$60) -> 46093 | M32: 0 | N32: =_xlfn.LET( _xlpm.s,VALUE($I32), _xlpm.e,VALUE($K32), IF(OR(_xlpm.s="",_xlpm.e=""),"", IF(_xlpm.e<=_xlpm.s, IF(TODAY()>=_xlpm.e,1,0), MAX(0,MIN(1,(TODAY()-_xlpm.s)/(_xlpm.e-_xlpm.s))))) ) -> 0
B33: 4.3 | C33: DC Cable delivered | E33: =E31 -> 46086 | F33: 1 | G33: =WORKDAY.INTL(E33,F33,1,Data!$C$3:$C$60) -> 46087 | I33: =I31 -> 46087 | J33: 1 | K33: =WORKDAY.INTL(I33,J33,1,Data!$C$3:$C$60) -> 46090 | M33: 0 | N33: =_xlfn.LET( _xlpm.s,VALUE($I33), _xlpm.e,VALUE($K33), IF(OR(_xlpm.s="",_xlpm.e=""),"", IF(_xlpm.e<=_xlpm.s, IF(TODAY()>=_xlpm.e,1,0), MAX(0,MIN(1,(TODAY()-_xlpm.s)/(_xlpm.e-_xlpm.s))))) ) -> 0
B34: 4.4 | C34: DC Stringing | E34: =WORKDAY.INTL(G38,0,1,Data!$C$3:$C$60)-3 -> 46102 | F34: 4 | G34: =WORKDAY.INTL(E34,F34,1,Data!$C$3:$C$60) -> 46107 | I34: =WORKDAY.INTL(K38,0,1,Data!$C$3:$C$60)-3 -> 46103 | J34: 4 | K34: =WORKDAY.INTL(I34,J34,1,Data!$C$3:$C$60) -> 46107 | M34: 0 | N34: =_xlfn.LET( _xlpm.s,VALUE($I34), _xlpm.e,VALUE($K34), IF(OR(_xlpm.s="",_xlpm.e=""),"", IF(_xlpm.e<=_xlpm.s, IF(TODAY()>=_xlpm.e,1,0), MAX(0,MIN(1,(TODAY()-_xlpm.s)/(_xlpm.e-_xlpm.s))))) ) -> 0
B36: 5 | C36: Module installation | E36: =MIN(E37:E39) -> 46086 | F36: =G36-E36 -> 19 | G36: =MAX(G37:G39) -> 46105 | I36: =MIN(I37:I39) -> 46087 | J36: =K36-I36 -> 19 | K36: =MAX(K37:K39) -> 46106 | M36: =(J37*M37+J38*M38)/SUM(J37:J38) -> 0 | N36: =(K37*N37+K38*N38)/SUM(K37:K38) -> 0
B37: 5.1 | C37: Module delivery | E37: =WORKDAY.INTL(E20,0,1,Data!$C$3:$C$60) -> 46086 | F37: 1 | G37: =WORKDAY.INTL(E37,F37,1,Data!$C$3:$C$60) -> 46087 | I37: =WORKDAY.INTL(I20,0,1,Data!$C$3:$C$60) -> 46087 | J37: 1 | K37: =WORKDAY.INTL(I37,J37,1,Data!$C$3:$C$60) -> 46090 | M37: 0 | N37: =_xlfn.LET( _xlpm.s,VALUE($I37), _xlpm.e,VALUE($K37), IF(OR(_xlpm.s="",_xlpm.e=""),"", IF(_xlpm.e<=_xlpm.s, IF(TODAY()>=_xlpm.e,1,0), MAX(0,MIN(1,(TODAY()-_xlpm.s)/(_xlpm.e-_xlpm.s))))) ) -> 0
B38: 5.2 | C38: Module mounting | E38: =G32 -> 46092 | F38: 9 | G38: =WORKDAY.INTL(E38,F38,1,Data!$C$3:$C$60) -> 46105 | I38: =K32 -> 46093 | J38: 9 | K38: =WORKDAY.INTL(I38,J38,1,Data!$C$3:$C$60) -> 46106 | M38: 0 | N38: =_xlfn.LET( _xlpm.s,VALUE($I38), _xlpm.e,VALUE($K38), IF(OR(_xlpm.s="",_xlpm.e=""),"", IF(_xlpm.e<=_xlpm.s, IF(TODAY()>=_xlpm.e,1,0), MAX(0,MIN(1,(TODAY()-_xlpm.s)/(_xlpm.e-_xlpm.s))))) ) -> 0
B40: 6 | C40: Commissioning | E40: =MIN(E41:E44) -> 46108 | F40: =G40-E40 -> 13 | G40: =MAX(G41:G44) -> 46121 | I40: =MIN(I41:I44) -> 46108 | J40: =K40-I40 -> 13 | K40: =MAX(K41:K44) -> 46121 | M40: =(J41*M41+J42*M42+J43*M43)/SUM(J41:J43) -> 0 | N40: =(K41*N41+K42*N42)/SUM(K41:K42) -> 0
B41: 6.1 | C41: Commissioning | E41: =WORKDAY.INTL(MAX(G22,G29,G36),0,1,Data!$C$3:$C$60) -> 46108 | F41: 1 | G41: =WORKDAY.INTL(E41,F41,1,Data!$C$3:$C$60) -> 46111 | I41: =WORKDAY.INTL(MAX(K22,K29,K36),0,1,Data!$C$3:$C$60) -> 46108 | J41: 1 | K41: =WORKDAY.INTL(I41,J41,1,Data!$C$3:$C$60) -> 46111 | M41: 0 | N41: =_xlfn.LET( _xlpm.s,VALUE($I41), _xlpm.e,VALUE($K41), IF(OR(_xlpm.s="",_xlpm.e=""),"", IF(_xlpm.e<=_xlpm.s, IF(TODAY()>=_xlpm.e,1,0), MAX(0,MIN(1,(TODAY()-_xlpm.s)/(_xlpm.e-_xlpm.s))))) ) -> 0
B42: 6.2 | C42: Practical Completion | E42: =WORKDAY.INTL(G41,0,1,Data!$C$3:$C$60) -> 46111 | F42: 1 | G42: =WORKDAY.INTL(E42,F42,1,Data!$C$3:$C$60) -> 46112 | I42: =WORKDAY.INTL(K41,0,1,Data!$C$3:$C$60) -> 46111 | J42: 1 | K42: =WORKDAY.INTL(I42,J42,1,Data!$C$3:$C$60) -> 46112 | M42: 0 | N42: =_xlfn.LET( _xlpm.s,VALUE($I42), _xlpm.e,VALUE($K42), IF(OR(_xlpm.s="",_xlpm.e=""),"", IF(_xlpm.e<=_xlpm.s, IF(TODAY()>=_xlpm.e,1,0), MAX(0,MIN(1,(TODAY()-_xlpm.s)/(_xlpm.e-_xlpm.s))))) ) -> 0
B43: 6.3 | C43: System Performance Monitoring | E43: =WORKDAY.INTL(G42,0,1,Data!$C$3:$C$60) -> 46112 | F43: 5 | G43: =WORKDAY.INTL(E43,F43,1,Data!$C$3:$C$60) -> 46121 | I43: =WORKDAY.INTL(K42,0,1,Data!$C$3:$C$60) -> 46112 | J43: 5 | K43: =WORKDAY.INTL(I43,J43,1,Data!$C$3:$C$60) -> 46121 | M43: 0 | N43: =_xlfn.LET( _xlpm.s,VALUE($I43), _xlpm.e,VALUE($K43), IF(OR(_xlpm.s="",_xlpm.e=""),"", IF(_xlpm.e<=_xlpm.s, IF(TODAY()>=_xlpm.e,1,0), MAX(0,MIN(1,(TODAY()-_xlpm.s)/(_xlpm.e-_xlpm.s))))) ) -> 0
B45: 7 | C45: QA Inspections | E45: =MIN(E46:E48) -> 46112 | F45: =G45-E45 -> 10 | G45: =MAX(G46:G48) -> 46122 | I45: =MIN(I46:I48) -> 46112 | J45: =K45-I45 -> 10 | K45: =MAX(K46:K48) -> 46122 | M45: =(J46*M46+J47*M47)/SUM(J46:J47) -> 0 | N45: =(K46*N46)/SUM(K46) -> 0
...

Sheet Revenue Tracking
B2: HIGH LEVEL PROJECT REVENUE TRACKING | U2: 2026 Budget Revenue | V2: 2026 Budget COS | W2: 2026 Actual Revenue | X2: 2026 Actual COS
D3: COSTED | F3: ACTUAL | L3: FINANCIAL REVIEW | N3: TIMELINE REVIEW | U3: =SUMIFS('Expenditure Breakdown'!$U:$U, 'Expenditure Breakdown'!$T:$T, ">"&DATE(2025,8,31), 'Expenditure Breakdown'!$T:$T, "<="&DATE(2026,8,31)) -> 2899774.7 | V3: =SUMIFS('Expenditure Breakdown'!$Q:$Q, 'Expenditure Breakdown'!$T:$T, ">"&DATE(2025,8,31), 'Expenditure Breakdown'!$T:$T, "<="&DATE(2026,8,31)) -> 2564437.3 | W3: =SUMIFS('Expenditure Breakdown'!$U:$U, 'Expenditure Breakdown'!$T:$T, ">"&DATE(2025,8,31), 'Expenditure Breakdown'!$T:$T, "<="&DATE(2026,8,31), 'Expenditure Breakdown'!$S:$S, "<>") -> 0 | X3: =SUMIFS('Expenditure Breakdown'!$Q:$Q, 'Expenditure Breakdown'!$T:$T, ">"&DATE(2025,8,31), 'Expenditure Breakdown'!$T:$T, "<="&DATE(2026,8,31), 'Expenditure Breakdown'!$S:$S, "<>") -> 0
B4: 1 | C4: Planned Revenue | D4: ='Project Plan'!E6 -> 2899774.7 | F4: =F21 -> 2899774.7 | N4: Start Date
B5: 2 | C5: Planned Expenditure | D5: =+'Expenditure Tracking'!F5 -> 2528912.6 | F5: =+'Expenditure Tracking'!H5 -> 2564437.3 | H5: VO vs Costed Margin
B6: 3 | C6: Planned Profit | D6: =+D4-D5 -> 370862.08 | F6: =+F4-F5 -> 335337.38 | H6: =D6*0.5 -> 185431.04 | N6: End Date - PC
B7: 4 | C7: Planned Margin | D7: =+D6/D4 -> 0.12789342 | F7: =+F6/F4 -> 0.11564257 | H7: =SUMIF('Expenditure Breakdown'!N:N,"*VO*",'Expenditure Breakdown'!Q:Q) -> 0
B10: CONTRACT
B12: No. | C12: PAYMENT MILESTONE | E12: % | F12: VALUE | H12: PLANNED PAYMENT DATE | L12: INVOICE NUMBER | N12: INVOICE RAISED DATE | P12: PAYMENT RECEIVED DATE | R12: MILESTONE NOTES & COMMENTS | S12: MILESTONE DOCUMENTS RECEIVED
B13: 1 | C13: Acceptance and Initial Deposit | E13: 0.5 | F13: =$D$4*E13 -> 1449887.3 | H13: 46083 | P13: 46083 | S13: FALSE | AP13: ='Change Register'!$Q$14+ 7 -> 7
B14: 2 | C14: Delivery of Panels | E14: 0.25 | F14: =$D$4*E14 -> 724943.66 | H14: ='Project Plan'!G37+7 -> 46094 | P14: ='Project Plan'!K37+7 -> 46097 | S14: FALSE
B15: 3 | C15: Delivery of Inverters | E15: 0.1 | F15: =$D$4*E15 -> 289977.47 | H15: ='Project Plan'!G23+7 -> 46097 | P15: ='Project Plan'!K23+7 -> 46097 | S15: FALSE
B16: 4 | C16: Practical Completion | E16: 0.1 | F16: =$D$4*E16 -> 289977.47 | H16: ='Project Plan'!G40+7 -> 46128 | P16: ='Project Plan'!K40+7 -> 46128 | S16: FALSE
B17: 5 | C17: Handover | E17: 0.05 | F17: =$D$4*E17 -> 144988.73 | H17: ='Project Plan'!G51+365 -> 46494 | P17: ='Project Plan'!K51+365 -> 46494 | S17: FALSE
B18: 6 | C18: - | E18: 0 | F18: =$D$4*E18 -> 0 | S18: FALSE
B19: 7 | C19: - | E19: 0 | F19: =$D$4*E19 -> 0 | S19: FALSE
E21: =SUM(E13:E19) -> 1 | F21: =SUM(F13:F19) -> 2899774.7
B23: KEY: | C23: contains an error (in result or a check has failed)
C24: Red Font - IF TEXT : content not yet confirmed
C25: Red Font - IF NUMBER: Negative value
C26: Anything in yellow is a concern or risk for noting or action
C27: confirmed
C28: [ADD INITIALS: comment for noting in square brackets, use colour or red to draw attention if important]
C29: [RT: When adding rows into sheet, ensure you insert between first and last row of each category]
C30: end of sheet - do not insert information below/beyond this
B40: No. | C40: PAYMENT MILESTONE | E40: % | F40: VALUE
B41: 1 | C41: Deposit - Project commencement | E41: 0.35 | F41: =$F$47*E41 -> 1014921.1
B42: 2 | C42: Delivery of Panels | E42: 0.3 | F42: =$F$47*E42 -> 869932.4
B43: 3 | C43: Delivery of Inverters | E43: 0.2 | F43: =$F$47*E43 -> 579954.93
B44: 4 | C44: Practical Completion | E44: 0.1 | F44: =$F$47*E44 -> 289977.47
B45: 5 | C45: Handover | E45: 0.05 | F45: =$F$47*E45 -> 144988.73
C46: Total | E46: =SUM(E41:E45) -> 1 | F46: =SUM(F41:F45) -> 2899774.7
E47: =SUM(E41:E45) -> 1 | F47: =F21 -> 2899774.7

Sheet Expenditure Tracking
B2: HIGH LEVEL PROJECT EXPENDITURE TRACKING
F4: COSTED | H4: ACTUAL | J4: Difference from Costed
B5: EXPENDITURE | F5: =SUM(F9:F23) -> 2528912.6 | H5: =SUM(H9:H23) -> 2564437.3 | J5: =SUM(J9:J23) -> -35524.703
B7: No. | D7: Item | F7: Costed Expenditure | H7: Actual Expenditure | J7: Saving / Overrun | L7: Comments on variations from planned expenditure
B9: ='Expenditure Breakdown'!L6 -> 1 | D9: ='Expenditure Breakdown'!M6 -> 1. Panels | F9: ='Expenditure Breakdown'!I6 -> 263738 | H9: ='Expenditure Breakdown'!X6 -> 258000 | J9: =F9-H9 -> 5738.005
B10: ='Expenditure Breakdown'!L13 -> 2 | D10: ='Expenditure Breakdown'!M13 -> 2. Inverters | F10: ='Expenditure Breakdown'!I13 -> 0 | H10: ='Expenditure Breakdown'!X13 -> 0 | J10: =F10-H10 -> 0
B11: ='Expenditure Breakdown'!L21 -> 3 | D11: ='Expenditure Breakdown'!M21 -> 3. Mounting Structures | F11: ='Expenditure Breakdown'!I21 -> 53802 | H11: ='Expenditure Breakdown'!X21 -> 53802 | J11: =F11-H11 -> 0
B12: ='Expenditure Breakdown'!L28 -> 4 | D12: ='Expenditure Breakdown'!M28 -> 4. DC Equipment | F12: ='Expenditure Breakdown'!I28 -> 125191.1 | H12: ='Expenditure Breakdown'!X28 -> 115032.93 | J12: =F12-H12 -> 10158.165
B13: ='Expenditure Breakdown'!L44 -> 5 | D13: ='Expenditure Breakdown'!M44 -> 5. Monitoring | F13: ='Expenditure Breakdown'!I44 -> 0 | H13: ='Expenditure Breakdown'!X44 -> 49000 | J13: =F13-H13 -> -49000
B14: ='Expenditure Breakdown'!L52 -> 6 | D14: ='Expenditure Breakdown'!M52 -> 6. AC Equipment | F14: ='Expenditure Breakdown'!I52 -> 0 | H14: ='Expenditure Breakdown'!X52 -> 0 | J14: =F14-H14 -> 0
B15: ='Expenditure Breakdown'!L70 -> 7 | D15: ='Expenditure Breakdown'!M70 -> 7.BESS | F15: ='Expenditure Breakdown'!I70 -> 1211692.6 | H15: ='Expenditure Breakdown'!X70 -> 1211692.6 | J15: =F15-H15 -> 0
B16: ='Expenditure Breakdown'!L79 -> 8 | D16: ='Expenditure Breakdown'!M79 -> 8. Product Add On | F16: ='Expenditure Breakdown'!I79 -> 693148.4 | H16: ='Expenditure Breakdown'!X79 -> 693148.4 | J16: =F16-H16 -> 0
B17: ='Expenditure Breakdown'!L89 -> 9 | D17: ='Expenditure Breakdown'!M89 -> 9. AC & DC installation | F17: ='Expenditure Breakdown'!I89 -> 95060 | H17: ='Expenditure Breakdown'!X89 -> 80801 | J17: =F17-H17 -> 14259
B18: ='Expenditure Breakdown'!L102 -> 10 | D18: ='Expenditure Breakdown'!M102 -> 10. Site Logistics | F18: ='Expenditure Breakdown'!I102 -> 32715.467 | H18: ='Expenditure Breakdown'!X102 -> 29788.147 | J18: =F18-H18 -> 2927.32
B19: ='Expenditure Breakdown'!L118 -> 11 | D19: ='Expenditure Breakdown'!M118 -> 11. Due Dilligence | F19: ='Expenditure Breakdown'!I118 -> 29000 | H19: ='Expenditure Breakdown'!X118 -> 35000 | J19: =F19-H19 -> -6000
B20: ='Expenditure Breakdown'!L124 -> 12 | D20: ='Expenditure Breakdown'!M124 -> 12. BDP Commission | F20: ='Expenditure Breakdown'!I124 -> 0 | H20: ='Expenditure Breakdown'!X124 -> 0 | J20: =F20-H20 -> 0
B21: ='Expenditure Breakdown'!L127 -> 13 | D21: ='Expenditure Breakdown'!M128 -> 13. Engineering | F21: ='Expenditure Breakdown'!I127 -> 22639.99 | H21: ='Expenditure Breakdown'!X127 -> 36247.183 | J21: =F21-H21 -> -13607.193
B22: ='Expenditure Breakdown'!L134 -> 14 | D22: ='Expenditure Breakdown'!M134 -> 14. General Expenses | F22: ='Expenditure Breakdown'!I134 -> 1925 | H22: ='Expenditure Breakdown'!X134 -> 1925 | J22: =F22-H22 -> 0
B23: ='Expenditure Breakdown'!L147 -> 15 | D23: ='Expenditure Breakdown'!M147 -> 15. Service Add On | F23: ='Expenditure Breakdown'!I147 -> 0 | H23: ='Expenditure Breakdown'!X147 -> 0 | J23: =F23-H23 -> 0
D25: check: | F25: ='Expenditure Breakdown'!I2-'Expenditure Tracking'!F5 -> 0 | G25: =#REF!-G5 -> #REF! | H25: ='Expenditure Breakdown'!X2-H5 -> 0

Sheet Expenditure Breakdown
B2: COSTED EXPENDITURE BREAKDOWN | I2: =SUM(I6:I159) -> 2528912.6 | J2: =SUM(J6:J159) -> 2899774.7 | L2: ACTUAL EXPENDITURE BREAKDOWN | R2: FINANCE ONLY | X2: =SUM(X6:X159) -> 2564437.3
B4: No. | C4: Product / Service | D4: Description of Work | E4: QTY | F4: Rate / Unit | G4: Budget Total | H4: FORECASTED PAYMENT DATE | I4: Total COS | J4: =IF(J2-'Revenue Tracking'!D4>=0, "Total Revenue", "ERROR on REV" ) -> Total Revenue | L4: No. | M4: Product/ Service | N4: Description of Work | O4: QTY | P4: Rate / Unit | Q4: Actual Total | R4: PO NUMBER | S4: INVOICE NUMBER | T4: INVOICE RAISED DATE | U4: REVENUE RECOGNITION AMOUNT | V4: CHECK | W4: FINANCE PAYMENT DATE | X4: Total COS
B6: 1 | C6: Panels | D6: Panels Budget | G6: =D160 -> 263738 | H6: ='Project Plan'!E37+60 -> 46146 | I6: =SUM(G6:G11) -> 263738 | J6: =F160 -> 306672.1 | L6: 1 | M6: 1. Panels | N6: Panel Size - TBC - 610W as placeholder | O6: ='Project Plan'!$E$3*1000/610 -> 196.72131 | P6: =2.15*610 -> 1311.5 | Q6: =O6*P6 -> 258000 | T6: =IF(W6>1,EOMONTH(W6,0),"") -> 46173 | U6: =(Q6/$X$6*$J$6) -> 306672.1 | V6: =J6-SUM(U6:U11) -> 0 | W6: ='Project Plan'!K37+60 -> 46150 | X6: =SUM(Q6:Q11) -> 258000
B7: 1 | D7: Delivery Budget | L7: 1 | M7: 1. Panels | T7: =IF(W7>1,EOMONTH(W7,0),"") | U7: =(Q7/$X$6*$J$6) -> 0
B8: 1 | L8: 1 | M8: 1. Panels | T8: =IF(W8>1,EOMONTH(W8,0),"") | U8: =(Q8/$X$6*$J$6) -> 0
B9: 1 | L9: 1 | M9: 1. Panels | N9: Ziegler - Longi 610W | T9: =IF(W9>1,EOMONTH(W9,0),"") | U9: =(Q9/$X$6*$J$6) -> 0
B10: 1 | L10: 1 | M10: 1. Panels | T10: =IF(W10>1,EOMONTH(W10,0),"") | U10: =(Q10/$X$6*$J$6) -> 0
B11: 1 | L11: 1 | M11: 1. Panels | T11: =IF(W11>1,EOMONTH(W11,0),"") | U11: =(Q11/$X$6*$J$6) -> 0 | Y11: BUDGET | Z11: Installer Allocation
T12: =IF(W12>1,EOMONTH(W12,0),"") | Y12: AC Equipment | Z12: =G52 -> 0 | AA12: Includes the PVDB price, see price below in actual excluding DB price. This is what the contractor can quote us for.
B13: 2 | C13: Inverters | D13: Inverter Budget | G13: =D161 -> 0 | H13: ='Project Plan'!E23+60 -> 46147 | I13: =SUM(G13:G19) -> 0 | J13: =F161 -> 0 | L13: 2 | M13: 2. Inverters | V13: =J13-SUM(U13:U19) -> 0 | X13: =SUM(Q13:Q19) -> 0 | Y13: DC Equipment | Z13: =G29 -> 85921.1
B14: 2 | L14: 2 | M14: 2. Inverters | Y14: AC Labour | Z14: =G89 -> 29890
B15: 2 | L15: 2 | M15: 2. Inverters | T15: =IF(W15>1,EOMONTH(W15,0),"") | Y15: DC Labour | Z15: =G90 -> 65170
B16: 2 | L16: 2 | M16: 2. Inverters | T16: =IF(W16>1,EOMONTH(W16,0),"") | Y16: Offloading | Z16: =G102 -> 8500
B17: 2 | L17: 2 | M17: 2. Inverters | T17: =IF(W17>1,EOMONTH(W17,0),"") | Y17: Scaffolding | Z17: =G103 -> 11015.467
B18: 2 | L18: 2 | M18: 2. Inverters | T18: =IF(W18>1,EOMONTH(W18,0),"") | Y18: Storage | Z18: =G105 -> 0
B19: 2 | L19: 2 | M19: 2. Inverters | T19: =IF(W19>1,EOMONTH(W19,0),"") | Y19: Telehandler | Z19: 0
T20: =IF(W20>1,EOMONTH(W20,0),"") | Y20: Trenching | Z20: 0
B21: 3 | C21: Mounting Structures | D21: Structure Budget | G21: =D162 -> 53802 | H21: ='Project Plan'!E31+30 -> 46116 | I21: =SUM(G21:G26) -> 53802 | J21: =F162 -> 62560.465 | L21: 3 | M21: 3. Mounting Structures | N21: Schletter Structure | Q21: 53802 | T21: =IF(W21>1,EOMONTH(W21,0),"") -> 46142 | U21: =(Q21/$X$21*$J$21) -> 62560.465 | V21: =J21-SUM(U21:U26) -> 0 | W21: 46142 | X21: =SUM(Q21:Q26) -> 53802 | Y21: Other | Z21: 0
B22: 3 | L22: 3 | M22: 3. Mounting Structures | T22: =IF(W22>1,EOMONTH(W22,0),"") | U22: =(Q22/$X$21*$J$21) -> 0 | Y22: Total | Z22: =SUM(Z12:Z21) -> 200496.57
B23: 3 | L23: 3 | M23: 3. Mounting Structures | T23: =IF(W23>1,EOMONTH(W23,0),"") | U23: =(Q23/$X$21*$J$21) -> 0 | Y23: Less 15% | Z23: =+Z22*0.85 -> 170422.08
B24: 3 | L24: 3 | M24: 3. Mounting Structures | T24: =IF(W24>1,EOMONTH(W24,0),"") | U24: =(Q24/$X$21*$J$21) -> 0 | Y24: R/Wp | Z24: =Z23/'Project Plan'!$E$3/1000 -> 1.420184
B25: 3 | L25: 3 | M25: 3. Mounting Structures | T25: =IF(W25>1,EOMONTH(W25,0),"") | U25: =(Q25/$X$21*$J$21) -> 0
B26: 3 | L26: 3 | M26: 3. Mounting Structures | T26: =IF(W26>1,EOMONTH(W26,0),"") | U26: =(Q26/$X$21*$J$21) -> 0 | Y26: ACTUAL | Z26: Installer Price
T27: =IF(W27>1,EOMONTH(W27,0),"") | Y27: =Y12 -> AC Equipment | Z27: 0
B28: 4 | C28: DC Equipment | D28: DC Cable Budget | E28: 2805 | G28: 39270 | H28: ='Project Plan'!E33+60 -> 46146 | I28: =SUM(G28:G42) -> 125191.1 | J28: =F163 -> 145571.05 | L28: 4 | M28: 4. DC Equipment | N28: DC Cable | O28: 3000 | P28: 14 | Q28: =O28*P28 -> 42000 | T28: =T6 -> 46173 | U28: =(Q28/$X$28*$J$28) -> 53149.856 | V28: =J28-SUM(U28:U42) -> 0 | W28: =W6 -> 46150 | X28: =SUM(Q28:Q42) -> 115032.93 | Y28: =Y13 -> DC Equipment | Z28: =Z13*0.85 -> 73032.935
B29: 4 | D29: DC Equipment Budget | G29: =D163-G28 -> 85921.1 | H29: ='Project Plan'!G29 -> 46107 | L29: 4 | M29: 4. DC Equipment | T29: =IF(W29>1,EOMONTH(W29,0),"") | U29: =(Q29/$X$28*$J$28) -> 0 | Y29: =Y14 -> AC Labour | Z29: =Z14*0.85 -> 25406.5
B30: 4 | L30: 4 | M30: 4. DC Equipment | T30: =IF(W30>1,EOMONTH(W30,0),"") | U30: =(Q30/$X$28*$J$28) -> 0 | Y30: =Y15 -> DC Labour | Z30: =Z15*0.85 -> 55394.5
B31: 4 | L31: 4 | M31: 4. DC Equipment | T31: =IF(W31>1,EOMONTH(W31,0),"") | U31: =(Q31/$X$28*$J$28) -> 0 | Y31: Lifelines | Z31: =Z16*0.85 -> 7225
B32: 4 | L32: 4 | M32: 4. DC Equipment | N32: Project Kick Off | O32: =Z28 -> 73032.935 | P32: 0.1 | Q32: =$O$32*P32 -> 7303.2935 | T32: =T90 -> 46081 | U32: =(Q32/$X$28*$J$28) -> 9242.119 | W32: =W90 -> 46080 | Y32: Forklift | Z32: =Z17*0.85 -> 9363.1467
B33: 4 | L33: 4 | M33: 4. DC Equipment | N33: Site Establishment | P33: 0.15 | Q33: =$O$32*P33 -> 10954.94 | T33: =T91 -> 46112 | U33: =(Q33/$X$28*$J$28) -> 13863.179 | W33: =W91 -> 46087 | Y33: Geda | Z33: =Z18*0.85 -> 0
B34: 4 | L34: 4 | M34: 4. DC Equipment | N34: AC Installation Complete | P34: 0.2 | Q34: =$O$32*P34 -> 14606.587 | T34: =T92 -> 46142 | U34: =(Q34/$X$28*$J$28) -> 18484.238 | W34: =W92 -> 46115 | Y34: Logistics | Z34: 0
B35: 4 | L35: 4 | M35: 4. DC Equipment | N35: DC Installation Complete | P35: 0.25 | Q35: =$O$32*P35 -> 18258.234 | T35: =T93 -> 46142 | U35: =(Q35/$X$28*$J$28) -> 23105.298 | W35: =W93 -> 46114 | Y35: Trenching | Z35: 0
B36: 4 | L36: 4 | M36: 4. DC Equipment | N36: Commissioning Complete | P36: 0.1 | Q36: =$O$32*P36 -> 7303.2935 | T36: =T94 -> 46142 | U36: =(Q36/$X$28*$J$28) -> 9242.119 | W36: =W94 -> 46128 | Y36: Other | Z36: 0
B37: 4 | L37: 4 | M37: 4. DC Equipment | N37: Site De-establisment | P37: 0.1 | Q37: =$O$32*P37 -> 7303.2935 | T37: =T95 -> 46142 | U37: =(Q37/$X$28*$J$28) -> 9242.119 | W37: =W95 -> 46129 | Y37: Other | Z37: 0
B38: 4 | L38: 4 | M38: 4. DC Equipment | N38: Handover Document Complete | P38: 0.05 | Q38: =$O$32*P38 -> 3651.6467 | T38: =T96 -> 46142 | U38: =(Q38/$X$28*$J$28) -> 4621.0595 | W38: =W96 -> 46129 | Y38: Total | Z38: =SUM(Z27:Z37) -> 170422.08
B39: 4 | L39: 4 | M39: 4. DC Equipment | N39: End of Defects Period | P39: 0.05 | Q39: =$O$32*P39 -> 3651.6467 | T39: =T97 -> 46173 | U39: =(Q39/$X$28*$J$28) -> 4621.0595 | W39: =W97 -> 46152 | Y39: R/Wp | Z39: =Z38/'Project Plan'!$E$3/1000 -> 1.420184
B40: 4 | L40: 4 | M40: 4. DC Equipment | T40: =IF(W40>1,EOMONTH(W40,0),"") | U40: =(Q40/$X$28*$J$28) -> 0
B41: 4 | L41: 4 | M41: 4. DC Equipment | T41: =IF(W41>1,EOMONTH(W41,0),"") | U41: =(Q41/$X$28*$J$28) -> 0
B42: 4 | L42: 4 | M42: 4. DC Equipment | T42: =IF(W42>1,EOMONTH(W42,0),"") | U42: =(Q42/$X$28*$J$28) -> 0
T43: =IF(W43>1,EOMONTH(W43,0),"")
...

Sheet Cashflow
D1: [RT: Double Check the first date is always a MONDAY] | F1: 45964 | G1: =F1+7 -> 45971 | H1: =G1+7 -> 45978 | I1: =H1+7 -> 45985 | J1: =I1+7 -> 45992 | K1: =J1+7 -> 45999 | L1: =K1+7 -> 46006 | M1: =L1+7 -> 46013 | N1: =M1+7 -> 46020 | ... KE1: =KD1+7 -> 47959
A2: PLANNED | C2: CHECK | D2: CHECK
B3: Planned Revenue | C3: ='Revenue Tracking'!D4 -> 2899774.7 | D3: =SUM(F3:KE3) -> 2899774.7 | F3: =SUMIFS('Revenue Tracking'!$F$13:$F$19, 'Revenue Tracking'!$H$13:$H$19, ">="&F1,'Revenue Tracking'!$H$13:$H$19, "<"&G1) -> 0 | G3: =SUMIFS('Revenue Tracking'!$F$13:$F$19, 'Revenue Tracking'!$H$13:$H$19, ">="&G1,'Revenue Tracking'!$H$13:$H$19, "<"&H1) -> 0 | H3: =SUMIFS('Revenue Tracking'!$F$13:$F$19, 'Revenue Tracking'!$H$13:$H$19, ">="&H1,'Revenue Tracking'!$H$13:$H$19, "<"&I1) -> 0 | I3: =SUMIFS('Revenue Tracking'!$F$13:$F$19, 'Revenue Tracking'!$H$13:$H$19, ">="&I1,'Revenue Tracking'!$H$13:$H$19, "<"&J1) -> 0 | J3: =SUMIFS('Revenue Tracking'!$F$13:$F$19, 'Revenue Tracking'!$H$13:$H$19, ">="&J1,'Revenue Tracking'!$H$13:$H$19, "<"&K1) -> 0 | K3: =SUMIFS('Revenue Tracking'!$F$13:$F$19, 'Revenue Tracking'!$H$13:$H$19, ">="&K1,'Revenue Tracking'!$H$13:$H$19, "<"&L1) -> 0 | L3: =SUMIFS('Revenue Tracking'!$F$13:$F$19, 'Revenue Tracking'!$H$13:$H$19, ">="&L1,'Revenue Tracking'!$H$13:$H$19, "<"&M1) -> 0 | M3: =SUMIFS('Revenue Tracking'!$F$13:$F$19, 'Revenue Tracking'!$H$13:$H$19, ">="&M1,'Revenue Tracking'!$H$13:$H$19, "<"&N1) -> 0 | ... KD3: =SUMIFS('Revenue Tracking'!$F$13:$F$19, 'Revenue Tracking'!$H$13:$H$19, ">="&KD1,'Revenue Tracking'!$H$13:$H$19, "<"&KE1) -> 0 | KE3: =SUMIFS('Revenue Tracking'!$F$13:$F$19, 'Revenue Tracking'!$H$13:$H$19, ">="&KE1,'Revenue Tracking'!$H$13:$H$19, "<"&#REF!) -> 0
B4: Planned Revenue - Cumulative | F4: =F3 -> 0 | G4: =F4+G3 -> 0 | H4: =G4+H3 -> 0 | I4: =H4+I3 -> 0 | J4: =I4+J3 -> 0 | K4: =J4+K3 -> 0 | L4: =K4+L3 -> 0 | M4: =L4+M3 -> 0 | N4: =M4+N3 -> 0 | ... KE4: =KD4+KE3 -> 2899774.7
B5: Planned Expenditure | C5: ='Revenue Tracking'!D5 -> 2528912.6 | D5: =SUM(F5:KE5) -> 2577912.6 | F5: =SUMIFS('Expenditure Breakdown'!$G$6:$G$166, 'Expenditure Breakdown'!$H$6:$H$166, ">="&F1,'Expenditure Breakdown'!$H$6:$H$166, "<"&G1) -> 0 | G5: =SUMIFS('Expenditure Breakdown'!$G$6:$G$166, 'Expenditure Breakdown'!$H$6:$H$166, ">="&G1,'Expenditure Breakdown'!$H$6:$H$166, "<"&H1) -> 0 | H5: =SUMIFS('Expenditure Breakdown'!$G$6:$G$166, 'Expenditure Breakdown'!$H$6:$H$166, ">="&H1,'Expenditure Breakdown'!$H$6:$H$166, "<"&I1) -> 0 | I5: =SUMIFS('Expenditure Breakdown'!$G$6:$G$166, 'Expenditure Breakdown'!$H$6:$H$166, ">="&I1,'Expenditure Breakdown'!$H$6:$H$166, "<"&J1) -> 0 | J5: =SUMIFS('Expenditure Breakdown'!$G$6:$G$166, 'Expenditure Breakdown'!$H$6:$H$166, ">="&J1,'Expenditure Breakdown'!$H$6:$H$166, "<"&K1) -> 0 | K5: =SUMIFS('Expenditure Breakdown'!$G$6:$G$166, 'Expenditure Breakdown'!$H$6:$H$166, ">="&K1,'Expenditure Breakdown'!$H$6:$H$166, "<"&L1) -> 0 | L5: =SUMIFS('Expenditure Breakdown'!$G$6:$G$166, 'Expenditure Breakdown'!$H$6:$H$166, ">="&L1,'Expenditure Breakdown'!$H$6:$H$166, "<"&M1) -> 0 | M5: =SUMIFS('Expenditure Breakdown'!$G$6:$G$166, 'Expenditure Breakdown'!$H$6:$H$166, ">="&M1,'Expenditure Breakdown'!$H$6:$H$166, "<"&N1) -> 0 | ... KD5: =SUMIFS('Expenditure Breakdown'!$G$6:$G$166, 'Expenditure Breakdown'!$H$6:$H$166, ">="&KD1,'Expenditure Breakdown'!$H$6:$H$166, "<"&KE1) -> 0 | KE5: =SUMIFS('Expenditure Breakdown'!$G$6:$G$166, 'Expenditure Breakdown'!$H$6:$H$166, ">="&KE1,'Expenditure Breakdown'!$H$6:$H$166, "<"&#REF!) -> 0
B6: Planned Expenditure - Cumulative | F6: =F5 -> 0 | G6: =F6+G5 -> 0 | H6: =G6+H5 -> 0 | I6: =H6+I5 -> 0 | J6: =I6+J5 -> 0 | K6: =J6+K5 -> 0 | L6: =K6+L5 -> 0 | M6: =L6+M5 -> 0 | N6: =M6+N5 -> 0 | ... KE6: =KD6+KE5 -> 2577912.6
B7: PLANNED CashFlow | F7: =F4-F6 -> 0 | G7: =G4-G6 -> 0 | H7: =H4-H6 -> 0 | I7: =I4-I6 -> 0 | J7: =J4-J6 -> 0 | K7: =K4-K6 -> 0 | L7: =L4-L6 -> 0 | M7: =M4-M6 -> 0 | ... KE7: =KE4-KE6 -> 321862.08
A8: ACTUAL | C8: CHECK | D8: CHECK
B9: Actual + Planned Revenue | C9: ='Revenue Tracking'!F4 -> 2899774.7 | D9: =SUM(F9:KE9) -> 2899774.7 | F9: =SUMIFS('Revenue Tracking'!$F$13:$F$19, 'Revenue Tracking'!$P$13:$P$19, ">="&F1,'Revenue Tracking'!$P$13:$P$19, "<"&G1) -> 0 | G9: =SUMIFS('Revenue Tracking'!$F$13:$F$19, 'Revenue Tracking'!$P$13:$P$19, ">="&G1,'Revenue Tracking'!$P$13:$P$19, "<"&H1) -> 0 | H9: =SUMIFS('Revenue Tracking'!$F$13:$F$19, 'Revenue Tracking'!$P$13:$P$19, ">="&H1,'Revenue Tracking'!$P$13:$P$19, "<"&I1) -> 0 | I9: =SUMIFS('Revenue Tracking'!$F$13:$F$19, 'Revenue Tracking'!$P$13:$P$19, ">="&I1,'Revenue Tracking'!$P$13:$P$19, "<"&J1) -> 0 | J9: =SUMIFS('Revenue Tracking'!$F$13:$F$19, 'Revenue Tracking'!$P$13:$P$19, ">="&J1,'Revenue Tracking'!$P$13:$P$19, "<"&K1) -> 0 | K9: =SUMIFS('Revenue Tracking'!$F$13:$F$19, 'Revenue Tracking'!$P$13:$P$19, ">="&K1,'Revenue Tracking'!$P$13:$P$19, "<"&L1) -> 0 | L9: =SUMIFS('Revenue Tracking'!$F$13:$F$19, 'Revenue Tracking'!$P$13:$P$19, ">="&L1,'Revenue Tracking'!$P$13:$P$19, "<"&M1) -> 0 | M9: =SUMIFS('Revenue Tracking'!$F$13:$F$19, 'Revenue Tracking'!$P$13:$P$19, ">="&M1,'Revenue Tracking'!$P$13:$P$19, "<"&N1) -> 0 | ... KD9: =SUMIFS('Revenue Tracking'!$F$13:$F$19, 'Revenue Tracking'!$P$13:$P$19, ">="&KD1,'Revenue Tracking'!$P$13:$P$19, "<"&KE1) -> 0 | KE9: =SUMIFS('Revenue Tracking'!$F$13:$F$19, 'Revenue Tracking'!$P$13:$P$19, ">="&KE1,'Revenue Tracking'!$P$13:$P$19, "<"&#REF!) -> 0
B10: Actual + Planned Revenue - Cumulative | F10: =F9 -> 0 | G10: =F10+G9 -> 0 | H10: =G10+H9 -> 0 | I10: =H10+I9 -> 0 | J10: =I10+J9 -> 0 | K10: =J10+K9 -> 0 | L10: =K10+L9 -> 0 | M10: =L10+M9 -> 0 | N10: =M10+N9 -> 0 | ... KE10: =KD10+KE9 -> 2899774.7
B11: Actual + Planned Expenditure | C11: ='Revenue Tracking'!F5 -> 2564437.3 | D11: =SUM(F11:KE11) -> 2564437.3 | F11: =SUMIFS('Expenditure Breakdown'!$Q$6:$Q$166, 'Expenditure Breakdown'!$W$6:$W$166, ">="&F1,'Expenditure Breakdown'!$W$6:$W$166, "<"&G1) -> 0 | G11: =SUMIFS('Expenditure Breakdown'!$Q$6:$Q$166, 'Expenditure Breakdown'!$W$6:$W$166, ">="&G1,'Expenditure Breakdown'!$W$6:$W$166, "<"&H1) -> 0 | H11: =SUMIFS('Expenditure Breakdown'!$Q$6:$Q$166, 'Expenditure Breakdown'!$W$6:$W$166, ">="&H1,'Expenditure Breakdown'!$W$6:$W$166, "<"&I1) -> 0 | I11: =SUMIFS('Expenditure Breakdown'!$Q$6:$Q$166, 'Expenditure Breakdown'!$W$6:$W$166, ">="&I1,'Expenditure Breakdown'!$W$6:$W$166, "<"&J1) -> 0 | J11: =SUMIFS('Expenditure Breakdown'!$Q$6:$Q$166, 'Expenditure Breakdown'!$W$6:$W$166, ">="&J1,'Expenditure Breakdown'!$W$6:$W$166, "<"&K1) -> 0 | K11: =SUMIFS('Expenditure Breakdown'!$Q$6:$Q$166, 'Expenditure Breakdown'!$W$6:$W$166, ">="&K1,'Expenditure Breakdown'!$W$6:$W$166, "<"&L1) -> 0 | L11: =SUMIFS('Expenditure Breakdown'!$Q$6:$Q$166, 'Expenditure Breakdown'!$W$6:$W$166, ">="&L1,'Expenditure Breakdown'!$W$6:$W$166, "<"&M1) -> 0 | M11: =SUMIFS('Expenditure Breakdown'!$Q$6:$Q$166, 'Expenditure Breakdown'!$W$6:$W$166, ">="&M1,'Expenditure Breakdown'!$W$6:$W$166, "<"&N1) -> 0 | ... KD11: =SUMIFS('Expenditure Breakdown'!$Q$6:$Q$166, 'Expenditure Breakdown'!$W$6:$W$166, ">="&KD1,'Expenditure Breakdown'!$W$6:$W$166, "<"&KE1) -> 0 | KE11: =SUMIFS('Expenditure Breakdown'!$Q$6:$Q$166, 'Expenditure Breakdown'!$W$6:$W$166, ">="&KE1,'Expenditure Breakdown'!$W$6:$W$166, "<"&#REF!) -> 0
B12: Actual + Planned Expenditure - Cumulative | F12: =F11 -> 0 | G12: =F12+G11 -> 0 | H12: =G12+H11 -> 0 | I12: =H12+I11 -> 0 | J12: =I12+J11 -> 0 | K12: =J12+K11 -> 0 | L12: =K12+L11 -> 0 | M12: =L12+M11 -> 0 | N12: =M12+N11 -> 0 | ... KE12: =KD12+KE11 -> 2564437.3
B14: ACTUAL CashFlow | F14: =F10-F12 -> 0 | G14: =G10-G12 -> 0 | H14: =H10-H12 -> 0 | I14: =I10-I12 -> 0 | J14: =J10-J12 -> 0 | K14: =K10-K12 -> 0 | L14: =L10-L12 -> 0 | M14: =M10-M12 -> 0 | ... KE14: =KE10-KE12 -> 335337.38
C16: CHECK | D16: CHECK
B17: Revenue Recognition | C17: =C3-D17 -> 0 | D17: =SUM(F17:KE17) -> 2899774.7 | F17: =SUMIFS('Expenditure Breakdown'!$U$6:$U$166, 'Expenditure Breakdown'!$T$6:$T$166, ">="&F1,'Expenditure Breakdown'!$T$6:$T$166, "<"&G1) -> 0 | G17: =SUMIFS('Expenditure Breakdown'!$U$6:$U$166, 'Expenditure Breakdown'!$T$6:$T$166, ">="&G1,'Expenditure Breakdown'!$T$6:$T$166, "<"&H1) -> 0 | H17: =SUMIFS('Expenditure Breakdown'!$U$6:$U$166, 'Expenditure Breakdown'!$T$6:$T$166, ">="&H1,'Expenditure Breakdown'!$T$6:$T$166, "<"&I1) -> 0 | I17: =SUMIFS('Expenditure Breakdown'!$U$6:$U$166, 'Expenditure Breakdown'!$T$6:$T$166, ">="&I1,'Expenditure Breakdown'!$T$6:$T$166, "<"&J1) -> 0 | J17: =SUMIFS('Expenditure Breakdown'!$U$6:$U$166, 'Expenditure Breakdown'!$T$6:$T$166, ">="&J1,'Expenditure Breakdown'!$T$6:$T$166, "<"&K1) -> 0 | K17: =SUMIFS('Expenditure Breakdown'!$U$6:$U$166, 'Expenditure Breakdown'!$T$6:$T$166, ">="&K1,'Expenditure Breakdown'!$T$6:$T$166, "<"&L1) -> 0 | L17: =SUMIFS('Expenditure Breakdown'!$U$6:$U$166, 'Expenditure Breakdown'!$T$6:$T$166, ">="&L1,'Expenditure Breakdown'!$T$6:$T$166, "<"&M1) -> 0 | M17: =SUMIFS('Expenditure Breakdown'!$U$6:$U$166, 'Expenditure Breakdown'!$T$6:$T$166, ">="&M1,'Expenditure Breakdown'!$T$6:$T$166, "<"&N1) -> 0 | ... KD17: =SUMIFS('Expenditure Breakdown'!$U$6:$U$166, 'Expenditure Breakdown'!$T$6:$T$166, ">="&KD1,'Expenditure Breakdown'!$T$6:$T$166, "<"&KE1) -> 0 | KE17: =SUMIFS('Expenditure Breakdown'!$U$6:$U$166, 'Expenditure Breakdown'!$T$6:$T$166, ">="&KE1,'Expenditure Breakdown'!$T$6:$T$166, "<"&#REF!) -> 0
B18: Revenue Recognition Cumulative | C18: =D17-D18 -> 0 | D18: =MAX(F18:KE18) -> 2899774.7 | F18: =F17 -> 0 | G18: =F18+G17 -> 0 | H18: =G18+H17 -> 0 | I18: =H18+I17 -> 0 | J18: =I18+J17 -> 0 | K18: =J18+K17 -> 0 | L18: =K18+L17 -> 0 | M18: =L18+M17 -> 0 | N18: =M18+N17 -> 0 | ... KE18: =KD18+KE17 -> 2899774.7

Sheet Finance - Revenue
A3: Sum of REVENUE RECOGNITION AMOUNT | B3: Column Labels
A4: Row Labels | B4: (blank) | D4: 46053 | E4: 46173 | F4: 46142 | G4: 46081 | H4: 46112 | I4: Grand Total
A5: (blank)
A6: 1. Panels | C6: 0 | E6: 306672.1 | I6: 306672.1
A7: 2. Inverters
A8: 3. Mounting Structures | C8: 0 | F8: 62560.465 | I8: 62560.465
A9: 4. DC Equipment | C9: 0 | E9: 57770.916 | F9: 64694.833 | G9: 9242.119 | H9: 13863.179 | I9: 145571.05
A10: 5. Monitoring | C10: 0 | H10: 0 | I10: 0
A11: 6. AC Equipment
A12: 8. Product Add On | B12: 0 | C12: 0 | F12: 805986.51 | I12: 805986.51
A13: 9. AC & DC installation | C13: 0 | E13: 5281.1111 | F13: 73935.556 | G13: 10562.222 | H13: 15843.333 | I13: 105622.22
A14: 10. Site Logistics | C14: 0 | E14: 1012.127 | F14: 30277.757 | G14: 2024.2539 | H14: 3036.3809 | I14: 36350.519
A15: 11. Due Dilligence | C15: 0 | F15: 32222.222 | I15: 32222.222
A16: 13. Engineering | C16: 0 | F16: 25727.261 | I16: 25727.261
A17: 14. General Expenses | C17: 0 | D17: 534.72222 | F17: 534.72222 | G17: 534.72222 | H17: 534.72222 | I17: 2138.8889
A18: 15. Service Add On
A19: 12. BDP Commission
A20: 7.BESS | C20: 0 | F20: 1376923.4 | I20: 1376923.4
A21: Grand Total | B21: 0 | C21: 0 | D21: 534.72222 | E21: 370736.25 | F21: 2472862.7 | G21: 22363.317 | H21: 33277.615 | I21: 2899774.7

Sheet Finance - COS
A3: Sum of Actual Total | B3: Column Labels
A4: Row Labels | B4: (blank) | D4: 46053 | E4: 46173 | F4: 46142 | G4: 46081 | H4: 46112 | I4: Grand Total
A5: (blank)
A6: 1. Panels | E6: 258000 | I6: 258000
A7: 2. Inverters
A8: 3. Mounting Structures | F8: 53802 | I8: 53802
A9: 4. DC Equipment | E9: 45651.647 | F9: 51123.054 | G9: 7303.2935 | H9: 10954.94 | I9: 115032.93
A10: 5. Monitoring | H10: 49000 | I10: 49000
A11: 6. AC Equipment | E11: 0 | F11: 0 | G11: 0 | H11: 0 | I11: 0
A12: 8. Product Add On | F12: 693148.4 | I12: 693148.4
A13: 9. AC & DC installation | E13: 4040.05 | F13: 56560.7 | G13: 8080.1 | H13: 12120.15 | I13: 80801
A14: 10. Site Logistics | E14: 829.40733 | F14: 24811.703 | G14: 1658.8147 | H14: 2488.222 | I14: 29788.147
A15: 11. Due Dilligence | C15: 0 | F15: 35000 | I15: 35000
A16: 13. Engineering | F16: 36247.183 | I16: 36247.183
A17: 14. General Expenses | D17: 481.25 | F17: 481.25 | G17: 481.25 | H17: 481.25 | I17: 1925
A18: 15. Service Add On
A19: 12. BDP Commission | C19: 0 | I19: 0
A20: 7.BESS | F20: 1211692.6 | I20: 1211692.6
A21: Grand Total | C21: 0 | D21: 481.25 | E21: 308521.1 | F21: 2162866.9 | G21: 17523.458 | H21: 75044.562 | I21: 2564437.3

Sheet Data
C2: Public holidays | F2: Drop down list
C3: 45658 | D3: New Years Day | F3: Approved
C4: 45737 | D4: Human Rights day | F4: Pending
C5: 45765 | D5: Good Friday | F5: Declined
C6: 45768 | D6: Family Day | F6: Abanded
C7: 45774 | D7: Freedom Day
C8: 45765 | D8: Freedom DayObserved
C9: 45778 | D9: Workers day
C10: 45824 | D10: Youth Day Holiday
C11: 45878 | D11: Womens Day
C12: 45924 | D12: Heritage Day
C13: 46007 | D13: Day of Reconciliation | H13: Manual dates
C14: 46016 | D14: Christmas Day
C15: 46017 | D15: Day of Goodwill
C16: 46006 | D16: Builders Break
C17: 46007 | D17: Builders Break
C18: 46008 | D18: Builders Break
C19: 46009 | D19: Builders Break
C20: 46010 | D20: Builders Break
C21: 46011 | D21: Builders Break
C22: 46012 | D22: Builders Break
C23: 46013 | D23: Builders Break
C24: 46014 | D24: Builders Break
C25: 46015 | D25: Builders Break
... C60: 46382 | D60: Day of Goodwill
