Workbook

Sheet Voc & Isc Test Result
A2: A1 Commissioning - IV Curve Testing | L2: Atterbury Boulevard
L4: Tested By: | M4: Date:
A5: I - V CURVE IN STRINGS | H5: Inspection 1 Accept / Reject | I5: Inspection 2 Accept / Reject | L5: Cornelius Rheeders, Jaco Snyman | M5: 44336
A6: 1 | B6: Test carried out during a cloudless interval with irradiance above 600W/m2
A7: =A6+1 -> 2 | B7: Test carried out before connecting the inverters to the loads
A8: =A7+1 -> 3 | B8: Fuses removed prior to connection of the I-V tracer in the case that the PV Facility is connected to the electrical network
A9: =A8+1 -> 4 | B9: Polarity of the strings measured and checked
A10: =A9+1 -> 5 | B10: Measure and record the temperature measured on the backsheet of the PV module (Tm ) for thermographic camera or through the average of the temperature cell sensors
A11: =A10+1 -> 6 | B11: Measure and record the Irradiance on the plane of the PV modules when performing the I-V curve
A12: =A11+1 -> 7 | B12: Measure and record the open circuit voltage Voc across each string through the I-V tracer
A13: =A12+1 -> 8 | B13: Measure and record the short circuit current (Isc ) of the string through the I-V tracer
A14: Notes:
A15: Only String 1 - 6 was tested by Cornelius and Jaco Snyman, the rest of the strings will be tested by Jaco and his team.
A17: CALCULATIONS
A19: Tc: temperature of the cell of the PV module will be calculated theoretically using the formula:
A21: Tc | B21: Temperature of the cell of the PV module (°C)
A22: Tm | B22: Temperature measured on the backsheet of the PV module (°C)
A23: G | B23: Irradiance on the plane of the PV modules (W/m2)
A24: Gstc | B24: Irradiance in STC (1000W/m2)
A25: ∆T | B25: Temperature differences between PV cell and the PV backsheet, considered as 3 °C (as per IEC 61724, table A-1)
A27: INVERTER 1 | D27: G | E27: Gstc | F27: Tm | H27: ∆T | I27: Tc
A28: MPPT 1 | B28: INPUT 1 | D28: ='Raw Data_Mod Tests'!E2 -> 900 | E28: 1000 | F28: ='Raw Data_Mod Tests'!F2 -> 45 | H28: 3 | I28: =F28+((D28/E28)*H28) -> 47.7
B29: INPUT 2 | D29: ='Raw Data_Mod Tests'!E3 -> 703 | E29: 1000 | F29: ='Raw Data_Mod Tests'!F3 -> 33 | H29: 3 | I29: =F29+((D29/E29)*H29) -> 35.109
A30: MPPT 2 | B30: INPUT 1 | D30: ='Raw Data_Mod Tests'!E4 -> 703 | E30: 1000 | F30: ='Raw Data_Mod Tests'!F4 -> 33 | H30: 3 | I30: =F30+((D30/E30)*H30) -> 35.109
B31: INPUT 2 | D31: ='Raw Data_Mod Tests'!E5 -> 0 | E31: 1000 | F31: ='Raw Data_Mod Tests'!F5 -> 0 | H31: 3 | I31: =F31+((D31/E31)*H31) -> 0
A32: MPPT 3 | B32: INPUT 1 | D32: ='Raw Data_Mod Tests'!E6 -> 692 | E32: 1000 | F32: ='Raw Data_Mod Tests'!F6 -> 36 | H32: 3 | I32: =F32+((D32/E32)*H32) -> 38.076
B33: INPUT 2 | D33: ='Raw Data_Mod Tests'!E7 -> 695 | E33: 1000 | F33: ='Raw Data_Mod Tests'!F7 -> 35 | H33: 3 | I33: =F33+((D33/E33)*H33) -> 37.085
A34: MPPT 4 | B34: INPUT 1 | D34: ='Raw Data_Mod Tests'!E8 -> 698 | E34: 1000 | F34: ='Raw Data_Mod Tests'!F8 -> 35 | H34: 3 | I34: =F34+((D34/E34)*H34) -> 37.094
B35: INPUT 2 | D35: ='Raw Data_Mod Tests'!E9 -> 0 | E35: 1000 | F35: ='Raw Data_Mod Tests'!F9 -> 0 | H35: 3 | I35: =F35+((D35/E35)*H35) -> 0
A36: MPPT 5 | B36: INPUT 1 | D36: ='Raw Data_Mod Tests'!E10 -> 550 | E36: 1000 | F36: ='Raw Data_Mod Tests'!F10 -> 34 | H36: 3 | I36: =F36+((D36/E36)*H36) -> 35.65
B37: INPUT 2 | D37: ='Raw Data_Mod Tests'!E11 -> 0 | E37: 1000 | F37: ='Raw Data_Mod Tests'!F11 -> 0 | H37: 3 | I37: =F37+((D37/E37)*H37) -> 0
A38: MPPT 6 | B38: INPUT 1 | D38: ='Raw Data_Mod Tests'!E12 -> 550 | E38: 1000 | F38: ='Raw Data_Mod Tests'!F12 -> 34 | H38: 3 | I38: =F38+((D38/E38)*H38) -> 35.65
B39: INPUT 2 | D39: ='Raw Data_Mod Tests'!E13 -> 0 | E39: 1000 | F39: ='Raw Data_Mod Tests'!F13 -> 0 | H39: 3 | I39: =F39+((D39/E39)*H39) -> 0
A40: MPPT 7 | B40: INPUT 1 | D40: ='Raw Data_Mod Tests'!E14 -> 550 | E40: 1000 | F40: ='Raw Data_Mod Tests'!F14 -> 34 | H40: 3 | I40: =F40+((D40/E40)*H40) -> 35.65
B41: INPUT 2 | D41: ='Raw Data_Mod Tests'!E15 -> 0 | E41: 1000 | F41: ='Raw Data_Mod Tests'!F15 -> 0 | H41: 3 | I41: =F41+((D41/E41)*H41) -> 0
A42: MPPT 8 | B42: INPUT 1 | D42: ='Raw Data_Mod Tests'!E16 -> 552 | E42: 1000 | F42: ='Raw Data_Mod Tests'!F16 -> 33 | H42: 3 | I42: =F42+((D42/E42)*H42) -> 34.656
B43: INPUT 2 | D43: ='Raw Data_Mod Tests'!E17 -> 0 | E43: 1000 | F43: ='Raw Data_Mod Tests'!F17 -> 0 | H43: 3 | I43: =F43+((D43/E43)*H43) -> 0
A44: MPPT 9 | B44: INPUT 1 | D44: ='Raw Data_Mod Tests'!E18 -> 552 | E44: 1000 | F44: ='Raw Data_Mod Tests'!F18 -> 36 | H44: 3 | I44: =F44+((D44/E44)*H44) -> 37.656
B45: INPUT 2 | D45: ='Raw Data_Mod Tests'!E19 -> 552 | E45: 1000 | F45: ='Raw Data_Mod Tests'!F19 -> 36 | H45: 3 | I45: =F45+((D45/E45)*H45) -> 37.656
A46: MPPT 10 | B46: INPUT 1 | D46: ='Raw Data_Mod Tests'!E20 -> 713 | E46: 1000 | F46: ='Raw Data_Mod Tests'!F20 -> 36 | H46: 3 | I46: =F46+((D46/E46)*H46) -> 38.139
...

Sheet Raw Data_Mod Tests
A1: Inverter | B1: MPPT | C1: String | D1: Tc | E1: G | F1: Tm | G1: Voc Measure | H1: Isc Measure | I1: Voc stc Check | J1: Column1 | K1: N | L1: Gstc | M1: ΔT | N1: Voc theo | O1: Nmod | P1: Voc stc | Q1: Ic | R1: δ Voc | S1: Tc | T1: Isc stc | U1: δIsc | V1: Isc theo | Z1: Tc | AA1: Temperature of the cell of the PV module (°C)
A2: 1 | B2: 1 | C2: 1 | D2: =Table3[[#This Row],[Tm]]+Table3[[#This Row],[ΔT]]*(Table3[[#This Row],[G]]/Table3[[#This Row],[Gstc]]) -> 47.7 | E2: 900 | F2: 45 | G2: 649 | H2: 5.45 | K2: 14 | L2: =IF(K2>0,1000,0) -> 1000 | M2: =IF(L2>0,3,0) -> 3 | O2: =K2 -> 14 | P2: ='Voc & Isc Test Result'!L174 -> 0.94222259 | Q2: ='Voc & Isc Test Result'!L321 -> 0.42555766 | R2: -0.0023 | T2: 14.07 | U2: 0.0005 | Z2: Tm | AA2: Temperature measured on the backsheet of the PV module (°C)
C3: 2 | D3: =Table3[[#This Row],[Tm]]+Table3[[#This Row],[ΔT]]*(Table3[[#This Row],[G]]/Table3[[#This Row],[Gstc]]) -> 35.109 | E3: 703 | F3: 33 | G3: 735 | H3: 5.94 | K3: 16 | L3: =IF(K3>0,1000,0) -> 1000 | M3: =IF(L3>0,3,0) -> 3 | O3: =K3 -> 16 | P3: ='Voc & Isc Test Result'!L175 -> 1.0179871 | Q3: ='Voc & Isc Test Result'!L322 -> 0.59751307 | Z3: G | AA3: Irradiance on the plane of the PV modules (W/m2)
B4: 2 | C4: 3 | D4: =Table3[[#This Row],[Tm]]+Table3[[#This Row],[ΔT]]*(Table3[[#This Row],[G]]/Table3[[#This Row],[Gstc]]) -> 35.109 | E4: 703 | F4: 33 | G4: 834 | H4: 6.48 | K4: 18 | L4: =IF(K4>0,1000,0) -> 1000 | M4: =IF(L4>0,3,0) -> 3 | O4: =K4 -> 18 | P4: ='Voc & Isc Test Result'!L176 -> 1.0267589 | Q4: ='Voc & Isc Test Result'!L323 -> 0.65183244 | Z4: Gstc | AA4: Irradiance in STC (1000W/m2)
D5: =Table3[[#This Row],[Tm]]+Table3[[#This Row],[ΔT]]*(Table3[[#This Row],[G]]/Table3[[#This Row],[Gstc]]) -> #DIV/0! | L5: =IF(K5>0,1000,0) -> 0 | M5: =IF(L5>0,3,0) -> 0 | O5: =K5 -> 0 | P5: ='Voc & Isc Test Result'!L177 | Q5: ='Voc & Isc Test Result'!L324 | Z5: ∆T | AA5: Temperature differences between PV cell and the PV backsheet, considered as 3 °C (as per IEC 61724, table A-1)
B6: 3 | C6: 4 | D6: =Table3[[#This Row],[Tm]]+Table3[[#This Row],[ΔT]]*(Table3[[#This Row],[G]]/Table3[[#This Row],[Gstc]]) -> 38.076 | E6: 692 | F6: 36 | G6: 776 | H6: 7.62 | K6: 17 | L6: =IF(K6>0,1000,0) -> 1000 | M6: =IF(L6>0,3,0) -> 3 | O6: =K6 -> 17 | P6: ='Voc & Isc Test Result'!L178 -> 1.0186678 | Q6: ='Voc & Isc Test Result'!L325 -> 0.77754334 | Z6: Voc theo | AA6: Theoratical open circuit voltage (V)
C7: 5 | D7: =Table3[[#This Row],[Tm]]+Table3[[#This Row],[ΔT]]*(Table3[[#This Row],[G]]/Table3[[#This Row],[Gstc]]) -> 37.085 | E7: 695 | F7: 35 | G7: 774 | H7: 7.68 | K7: 17 | L7: =IF(K7>0,1000,0) -> 1000 | M7: =IF(L7>0,3,0) -> 3 | O7: =K7 -> 17 | P7: ='Voc & Isc Test Result'!L179 -> 1.0136603 | Q7: ='Voc & Isc Test Result'!L326 -> 0.7806673 | Z7: Nmod | AA7: Number of the modules which compose each tested string
B8: 4 | C8: 6 | D8: =Table3[[#This Row],[Tm]]+Table3[[#This Row],[ΔT]]*(Table3[[#This Row],[G]]/Table3[[#This Row],[Gstc]]) -> 37.094 | E8: 698 | F8: 35 | G8: 778 | H8: 7.64 | K8: 17 | L8: =IF(K8>0,1000,0) -> 1000 | M8: =IF(L8>0,3,0) -> 3 | O8: =K8 -> 17 | P8: ='Voc & Isc Test Result'!L180 -> 1.0189205 | Q8: ='Voc & Isc Test Result'!L327 -> 0.77326004 | Z8: Voc stc | AA8: Rated PV module open circuit voltage at standard conditions (STC) (V)
D9: =Table3[[#This Row],[Tm]]+Table3[[#This Row],[ΔT]]*(Table3[[#This Row],[G]]/Table3[[#This Row],[Gstc]]) -> #DIV/0! | L9: =IF(K9>0,1000,0) -> 0 | M9: =IF(L9>0,3,0) -> 0 | O9: =K9 -> 0 | P9: ='Voc & Isc Test Result'!L181 | Q9: ='Voc & Isc Test Result'!L328 | Z9: δ Voc | AA9: PV module manufacturer's rated temperature coefficient of Voc (% / ° C)
B10: 5 | C10: 7 | D10: =Table3[[#This Row],[Tm]]+Table3[[#This Row],[ΔT]]*(Table3[[#This Row],[G]]/Table3[[#This Row],[Gstc]]) -> 35.65 | E10: 550 | F10: 34 | G10: 775 | H10: 7.58 | K10: 17 | L10: =IF(K10>0,1000,0) -> 1000 | M10: =IF(L10>0,3,0) -> 3 | O10: =K10 -> 17 | P10: ='Voc & Isc Test Result'!L182 -> 1.0115359 | Q10: ='Voc & Isc Test Result'!L329 -> 0.97432969 | Z10: Tc | AA10: Temperature of the cell of the PV module (°C)
D11: =Table3[[#This Row],[Tm]]+Table3[[#This Row],[ΔT]]*(Table3[[#This Row],[G]]/Table3[[#This Row],[Gstc]]) -> #DIV/0! | L11: =IF(K11>0,1000,0) -> 0 | M11: =IF(L11>0,3,0) -> 0 | O11: =K11 -> 0 | P11: ='Voc & Isc Test Result'!L183 | Q11: ='Voc & Isc Test Result'!L330 | Z11: N | AA11: Number of strings which compose each test
B12: 6 | C12: 8 | D12: =Table3[[#This Row],[Tm]]+Table3[[#This Row],[ΔT]]*(Table3[[#This Row],[G]]/Table3[[#This Row],[Gstc]]) -> 35.65 | E12: 550 | F12: 34 | G12: 777 | H12: 7.57 | K12: 17 | L12: =IF(K12>0,1000,0) -> 1000 | M12: =IF(L12>0,3,0) -> 3 | O12: =K12 -> 17 | P12: ='Voc & Isc Test Result'!L184 -> 1.0141463 | Q12: ='Voc & Isc Test Result'!L331 -> 0.97304429 | Z12: Isc stc | AA12: Rated PV module short circuit curent at standard conditions indicated in the photovoltaic panel data sheet (STC) (A)
D13: =Table3[[#This Row],[Tm]]+Table3[[#This Row],[ΔT]]*(Table3[[#This Row],[G]]/Table3[[#This Row],[Gstc]]) -> #DIV/0! | L13: =IF(K13>0,1000,0) -> 0 | M13: =IF(L13>0,3,0) -> 0 | O13: =K13 -> 0 | P13: ='Voc & Isc Test Result'!L185 | Q13: ='Voc & Isc Test Result'!L332 | Z13: G | AA13: Irradiance on the plane of the PV modules (W/m2)
B14: 7 | C14: 9 | D14: =Table3[[#This Row],[Tm]]+Table3[[#This Row],[ΔT]]*(Table3[[#This Row],[G]]/Table3[[#This Row],[Gstc]]) -> 35.65 | E14: 550 | F14: 34 | G14: 866 | H14: 7.63 | K14: 19 | L14: =IF(K14>0,1000,0) -> 1000 | M14: =IF(L14>0,3,0) -> 3 | O14: =K14 -> 19 | P14: ='Voc & Isc Test Result'!L186 -> 1.0113298 | Q14: ='Voc & Isc Test Result'!L333 -> 0.98075667
D15: =Table3[[#This Row],[Tm]]+Table3[[#This Row],[ΔT]]*(Table3[[#This Row],[G]]/Table3[[#This Row],[Gstc]]) -> #DIV/0! | L15: =IF(K15>0,1000,0) -> 0 | M15: =IF(L15>0,3,0) -> 0 | O15: =K15 -> 0 | P15: ='Voc & Isc Test Result'!L187 | Q15: ='Voc & Isc Test Result'!L334
B16: 8 | C16: 10 | D16: =Table3[[#This Row],[Tm]]+Table3[[#This Row],[ΔT]]*(Table3[[#This Row],[G]]/Table3[[#This Row],[Gstc]]) -> 34.656 | E16: 552 | F16: 33 | G16: 868 | H16: 7.61 | K16: 19 | L16: =IF(K16>0,1000,0) -> 1000 | M16: =IF(L16>0,3,0) -> 3 | O16: =K16 -> 19 | P16: ='Voc & Isc Test Result'!L188 -> 1.0112954 | Q16: ='Voc & Isc Test Result'!L335 -> 0.97512379
D17: =Table3[[#This Row],[Tm]]+Table3[[#This Row],[ΔT]]*(Table3[[#This Row],[G]]/Table3[[#This Row],[Gstc]]) -> #DIV/0! | L17: =IF(K17>0,1000,0) -> 0 | M17: =IF(L17>0,3,0) -> 0 | O17: =K17 -> 0 | P17: ='Voc & Isc Test Result'!L189 | Q17: ='Voc & Isc Test Result'!L336
B18: 9 | C18: 11 | D18: =Table3[[#This Row],[Tm]]+Table3[[#This Row],[ΔT]]*(Table3[[#This Row],[G]]/Table3[[#This Row],[Gstc]]) -> 37.656 | E18: 552 | F18: 36 | G18: 729 | H18: 7.65 | K18: 16 | L18: =IF(K18>0,1000,0) -> 1000 | M18: =IF(L18>0,3,0) -> 3 | O18: =K18 -> 16 | P18: ='Voc & Isc Test Result'!L190 -> 1.0157691 | Q18: ='Voc & Isc Test Result'!L337 -> 0.97878815
C19: 12 | D19: =Table3[[#This Row],[Tm]]+Table3[[#This Row],[ΔT]]*(Table3[[#This Row],[G]]/Table3[[#This Row],[Gstc]]) -> 37.656 | E19: 552 | F19: 36 | G19: 732 | H19: 7.59 | K19: 16 | L19: =IF(K19>0,1000,0) -> 1000 | M19: =IF(L19>0,3,0) -> 3 | O19: =K19 -> 16 | P19: ='Voc & Isc Test Result'!L191 -> 1.0199492 | Q19: ='Voc & Isc Test Result'!L338 -> 0.97111138
B20: 10 | C20: 13 | D20: =Table3[[#This Row],[Tm]]+Table3[[#This Row],[ΔT]]*(Table3[[#This Row],[G]]/Table3[[#This Row],[Gstc]]) -> 38.139 | E20: 713 | F20: 36 | G20: 736 | H20: 7.55 | K20: 16 | L20: =IF(K20>0,1000,0) -> 1000 | M20: =IF(L20>0,3,0) -> 3 | O20: =K20 -> 16 | P20: ='Voc & Isc Test Result'!L192 -> 1.0266975 | Q20: ='Voc & Isc Test Result'!L339 -> 0.74768653
D21: =Table3[[#This Row],[Tm]]+Table3[[#This Row],[ΔT]]*(Table3[[#This Row],[G]]/Table3[[#This Row],[Gstc]]) -> #DIV/0! | L21: =IF(K21>0,1000,0) -> 0 | M21: =IF(L21>0,3,0) -> 0 | O21: =K21 -> 0 | P21: ='Voc & Isc Test Result'!L193 | Q21: ='Voc & Isc Test Result'!L340
A22: 2 | B22: 1 | C22: 14 | D22: =Table3[[#This Row],[Tm]]+Table3[[#This Row],[ΔT]]*(Table3[[#This Row],[G]]/Table3[[#This Row],[Gstc]]) -> 32.136 | E22: 712 | F22: 30 | G22: 818 | H22: 6.17 | K22: 18 | L22: =IF(K22>0,1000,0) -> 1000 | M22: =IF(L22>0,3,0) -> 3 | O22: =K22 -> 18 | P22: ='Voc & Isc Test Result'!L196 -> 1.0000598 | Q22: ='Voc & Isc Test Result'!L344 -> 0.61371151 | Z22: Gstc | AA22: Irradiance in STC conditions (1000 W/m2)
C23: 15 | D23: =Table3[[#This Row],[Tm]]+Table3[[#This Row],[ΔT]]*(Table3[[#This Row],[G]]/Table3[[#This Row],[Gstc]]) -> 32.136 | E23: 712 | F23: 30 | G23: 817 | H23: 6.1 | K23: 18 | L23: =IF(K23>0,1000,0) -> 1000 | M23: =IF(L23>0,3,0) -> 3 | O23: =K23 -> 18 | P23: ='Voc & Isc Test Result'!L197 -> 0.9988372 | Q23: ='Voc & Isc Test Result'!L345 -> 0.60674882 | Z23: δIsc | AA23: PV module manufacturer's rated temperature coefficient of Isc (% / °C)
B24: 2 | C24: 16 | D24: =Table3[[#This Row],[Tm]]+Table3[[#This Row],[ΔT]]*(Table3[[#This Row],[G]]/Table3[[#This Row],[Gstc]]) -> 32.136 | E24: 712 | F24: 30 | G24: 814 | H24: 6.14 | K24: 18 | L24: =IF(K24>0,1000,0) -> 1000 | M24: =IF(L24>0,3,0) -> 3 | O24: =K24 -> 18 | P24: ='Voc & Isc Test Result'!L198 -> 0.9951695 | Q24: ='Voc & Isc Test Result'!L346 -> 0.6107275 | Z24: Tc | AA24: Temperature of the cell of the PV module (°C)
C25: 17 | D25: =Table3[[#This Row],[Tm]]+Table3[[#This Row],[ΔT]]*(Table3[[#This Row],[G]]/Table3[[#This Row],[Gstc]]) -> 34.115 | E25: 705 | F25: 32 | G25: 822 | H25: 6.11 | K25: 18 | L25: =IF(K25>0,1000,0) -> 1000 | M25: =IF(L25>0,3,0) -> 3 | O25: =K25 -> 18 | P25: ='Voc & Isc Test Result'!L199 -> 1.0096222 | Q25: ='Voc & Isc Test Result'!L347 -> 0.61317324 | Z25: Isc theo | AA25: Theoratical short circuit current (A)
B26: 3 | C26: 18 | D26: =Table3[[#This Row],[Tm]]+Table3[[#This Row],[ΔT]]*(Table3[[#This Row],[G]]/Table3[[#This Row],[Gstc]]) -> 34.106 | E26: 702 | F26: 32 | G26: 822 | H26: 6.32 | K26: 18 | L26: =IF(K26>0,1000,0) -> 1000 | M26: =IF(L26>0,3,0) -> 3 | O26: =K26 -> 18 | P26: ='Voc & Isc Test Result'!L200 -> 1.0096009 | Q26: ='Voc & Isc Test Result'!L348 -> 0.63696125
C27: 19 | D27: =Table3[[#This Row],[Tm]]+Table3[[#This Row],[ΔT]]*(Table3[[#This Row],[G]]/Table3[[#This Row],[Gstc]]) -> 34.106 | E27: 702 | F27: 32 | G27: 824 | H27: 6.42 | K27: 18 | L27: =IF(K27>0,1000,0) -> 1000 | M27: =IF(L27>0,3,0) -> 3 | O27: =K27 -> 18 | P27: ='Voc & Isc Test Result'!L201 -> 1.0120573 | Q27: ='Voc & Isc Test Result'!L349
B28: 4 | C28: 20 | D28: =Table3[[#This Row],[Tm]]+Table3[[#This Row],[ΔT]]*(Table3[[#This Row],[G]]/Table3[[#This Row],[Gstc]]) -> 34.106 | E28: 702 | F28: 32 | G28: 824 | H28: 6.17 | K28: 18 | L28: =IF(K28>0,1000,0) -> 1000 | M28: =IF(L28>0,3,0) -> 3 | O28: =K28 -> 18 | P28: ='Voc & Isc Test Result'!L202 -> 1.0120573 | Q28: ='Voc & Isc Test Result'!L350 -> 0.6218435
D29: =Table3[[#This Row],[Tm]]+Table3[[#This Row],[ΔT]]*(Table3[[#This Row],[G]]/Table3[[#This Row],[Gstc]]) -> #DIV/0! | L29: =IF(K29>0,1000,0) -> 0 | M29: =IF(L29>0,3,0) -> 0 | O29: =K29 -> 0 | P29: ='Voc & Isc Test Result'!L203 | Q29: ='Voc & Isc Test Result'!L351
B30: 5 | C30: 21 | D30: =Table3[[#This Row],[Tm]]+Table3[[#This Row],[ΔT]]*(Table3[[#This Row],[G]]/Table3[[#This Row],[Gstc]]) -> 2.106 | E30: 702 | G30: 785 | H30: 7.45 | K30: 17 | L30: =IF(K30>0,1000,0) -> 1000 | M30: =IF(L30>0,3,0) -> 3 | O30: =K30 -> 17 | P30: ='Voc & Isc Test Result'!L204 -> 0.94949396 | Q30: ='Voc & Isc Test Result'!L352 -> 0.763001
C31: 22 | D31: =Table3[[#This Row],[Tm]]+Table3[[#This Row],[ΔT]]*(Table3[[#This Row],[G]]/Table3[[#This Row],[Gstc]]) -> 2.106 | E31: 702 | G31: 777 | H31: 7.49 | K31: 17 | L31: =IF(K31>0,1000,0) -> 1000 | M31: =IF(L31>0,3,0) -> 3 | O31: =K31 -> 17 | P31: ='Voc & Isc Test Result'!L205 -> 0.93981759 | Q31: ='Voc & Isc Test Result'!L353 -> 0.76709765
B32: 6 | C32: 23 | D32: =Table3[[#This Row],[Tm]]+Table3[[#This Row],[ΔT]]*(Table3[[#This Row],[G]]/Table3[[#This Row],[Gstc]]) -> 2.106 | E32: 702 | K32: 17 | L32: =IF(K32>0,1000,0) -> 1000 | M32: =IF(L32>0,3,0) -> 3 | O32: =K32 -> 17 | P32: ='Voc & Isc Test Result'!L206 -> 0 | Q32: ='Voc & Isc Test Result'!L354 -> 0
C33: 24 | D33: =Table3[[#This Row],[Tm]]+Table3[[#This Row],[ΔT]]*(Table3[[#This Row],[G]]/Table3[[#This Row],[Gstc]]) -> 31.737 | E33: 579 | F33: 30 | G33: 778 | H33: 7.39 | K33: 17 | L33: =IF(K33>0,1000,0) -> 1000 | M33: =IF(L33>0,3,0) -> 3 | O33: =K33 -> 17 | P33: ='Voc & Isc Test Result'!L207 -> 1.0061687 | Q33: ='Voc & Isc Test Result'!L355 -> 0.90408927
B34: 7 | C34: 25 | D34: =Table3[[#This Row],[Tm]]+Table3[[#This Row],[ΔT]]*(Table3[[#This Row],[G]]/Table3[[#This Row],[Gstc]]) -> 31.737 | E34: 579 | F34: 30 | G34: 774 | H34: 7.35 | K34: 17 | L34: =IF(K34>0,1000,0) -> 1000 | M34: =IF(L34>0,3,0) -> 3 | O34: =K34 -> 17 | P34: ='Voc & Isc Test Result'!L208 -> 1.0009956 | Q34: ='Voc & Isc Test Result'!L356 -> 0.89919569
D35: =Table3[[#This Row],[Tm]]+Table3[[#This Row],[ΔT]]*(Table3[[#This Row],[G]]/Table3[[#This Row],[Gstc]]) -> #DIV/0! | L35: =IF(K35>0,1000,0) -> 0 | M35: =IF(L35>0,3,0) -> 0 | O35: =K35 -> 0 | P35: ='Voc & Isc Test Result'!L209 | Q35: ='Voc & Isc Test Result'!L357
B36: 8 | C36: 26 | D36: =Table3[[#This Row],[Tm]]+Table3[[#This Row],[ΔT]]*(Table3[[#This Row],[G]]/Table3[[#This Row],[Gstc]]) -> 31.737 | E36: 579 | F36: 30 | G36: 777 | H36: 7.27 | K36: 17 | L36: =IF(K36>0,1000,0) -> 1000 | M36: =IF(L36>0,3,0) -> 3 | O36: =K36 -> 17 | P36: ='Voc & Isc Test Result'!L210 -> 1.0048755 | Q36: ='Voc & Isc Test Result'!L358 -> 0.88940852
D37: =Table3[[#This Row],[Tm]]+Table3[[#This Row],[ΔT]]*(Table3[[#This Row],[G]]/Table3[[#This Row],[Gstc]]) -> #DIV/0! | L37: =IF(K37>0,1000,0) -> 0 | M37: =IF(L37>0,3,0) -> 0 | O37: =K37 -> 0 | P37: ='Voc & Isc Test Result'!L211 | Q37: ='Voc & Isc Test Result'!L359
B38: 9 | C38: 27 | D38: =Table3[[#This Row],[Tm]]+Table3[[#This Row],[ΔT]]*(Table3[[#This Row],[G]]/Table3[[#This Row],[Gstc]]) -> 31.737 | E38: 579 | F38: 30 | G38: 775 | H38: 7.29 | K38: 17 | L38: =IF(K38>0,1000,0) -> 1000 | M38: =IF(L38>0,3,0) -> 3 | O38: =K38 -> 17 | P38: ='Voc & Isc Test Result'!L212 -> 1.0022889 | Q38: ='Voc & Isc Test Result'!L360 -> 0.89185531
D39: =Table3[[#This Row],[Tm]]+Table3[[#This Row],[ΔT]]*(Table3[[#This Row],[G]]/Table3[[#This Row],[Gstc]]) -> #DIV/0! | L39: =IF(K39>0,1000,0) -> 0 | M39: =IF(L39>0,3,0) -> 0 | O39: =K39 -> 0 | P39: ='Voc & Isc Test Result'!L213 | Q39: ='Voc & Isc Test Result'!L361
B40: 10 | C40: 28 | D40: =Table3[[#This Row],[Tm]]+Table3[[#This Row],[ΔT]]*(Table3[[#This Row],[G]]/Table3[[#This Row],[Gstc]]) -> 31.737 | E40: 579 | F40: 30 | G40: 864 | H40: 7.23 | K40: 19 | L40: =IF(K40>0,1000,0) -> 1000 | M40: =IF(L40>0,3,0) -> 3 | O40: =K40 -> 19 | P40: ='Voc & Isc Test Result'!L214 -> 0.99977042 | Q40: ='Voc & Isc Test Result'!L362 -> 0.88451494
...

Sheet Sheet4
A1: Inverter | B1: MPPT | C1: String | D1: Tc | E1: G | F1: Tm
A2: 1 | B2: 1 | C2: 1 | D2: =Table3[[#This Row],[Tm]]+Table3[[#This Row],[ΔT]]*(Table3[[#This Row],[G]]/Table3[[#This Row],[Gstc]]) -> 47.7 | E2: 703 | F2: 33
C3: 2 | D3: =Table3[[#This Row],[Tm]]+Table3[[#This Row],[ΔT]]*(Table3[[#This Row],[G]]/Table3[[#This Row],[Gstc]]) -> 35.109 | E3: 703 | F3: 33
B4: 2 | C4: 3 | D4: =Table3[[#This Row],[Tm]]+Table3[[#This Row],[ΔT]]*(Table3[[#This Row],[G]]/Table3[[#This Row],[Gstc]]) -> 35.109 | E4: 703 | F4: 33
B6: 3 | C6: 4 | D6: =Table3[[#This Row],[Tm]]+Table3[[#This Row],[ΔT]]*(Table3[[#This Row],[G]]/Table3[[#This Row],[Gstc]]) -> 38.076 | E6: 692 | F6: 36
C7: 5 | D7: =Table3[[#This Row],[Tm]]+Table3[[#This Row],[ΔT]]*(Table3[[#This Row],[G]]/Table3[[#This Row],[Gstc]]) -> 37.085 | E7: 695 | F7: 35
B8: 4 | C8: 6 | D8: =Table3[[#This Row],[Tm]]+Table3[[#This Row],[ΔT]]*(Table3[[#This Row],[G]]/Table3[[#This Row],[Gstc]]) -> 37.094 | E8: 698 | F8: 35
B10: 5 | C10: 7 | D10: =Table3[[#This Row],[Tm]]+Table3[[#This Row],[ΔT]]*(Table3[[#This Row],[G]]/Table3[[#This Row],[Gstc]]) -> 35.65 | E10: 550 | F10: 34
B12: 6 | C12: 8 | D12: =Table3[[#This Row],[Tm]]+Table3[[#This Row],[ΔT]]*(Table3[[#This Row],[G]]/Table3[[#This Row],[Gstc]]) -> 35.65 | E12: 550 | F12: 34
B14: 7 | C14: 9 | D14: =Table3[[#This Row],[Tm]]+Table3[[#This Row],[ΔT]]*(Table3[[#This Row],[G]]/Table3[[#This Row],[Gstc]]) -> 35.65 | E14: 550 | F14: 34
B16: 8 | C16: 10 | D16: =Table3[[#This Row],[Tm]]+Table3[[#This Row],[ΔT]]*(Table3[[#This Row],[G]]/Table3[[#This Row],[Gstc]]) -> 34.656 | E16: 552 | F16: 33
B18: 9 | C18: 11 | D18: =Table3[[#This Row],[Tm]]+Table3[[#This Row],[ΔT]]*(Table3[[#This Row],[G]]/Table3[[#This Row],[Gstc]]) -> 37.656 | E18: 552 | F18: 36
C19: 12 | D19: =Table3[[#This Row],[Tm]]+Table3[[#This Row],[ΔT]]*(Table3[[#This Row],[G]]/Table3[[#This Row],[Gstc]]) -> 37.656 | E19: 552 | F19: 36
B20: 10 | C20: 13 | D20: =Table3[[#This Row],[Tm]]+Table3[[#This Row],[ΔT]]*(Table3[[#This Row],[G]]/Table3[[#This Row],[Gstc]]) -> 38.139 | E20: 713 | F20: 36
A22: 2 | B22: 1 | C22: 14 | D22: =Table3[[#This Row],[Tm]]+Table3[[#This Row],[ΔT]]*(Table3[[#This Row],[G]]/Table3[[#This Row],[Gstc]]) -> 32.136 | E22: 712 | F22: 30
C23: 15 | D23: =Table3[[#This Row],[Tm]]+Table3[[#This Row],[ΔT]]*(Table3[[#This Row],[G]]/Table3[[#This Row],[Gstc]]) -> 32.136 | E23: 712 | F23: 30
B24: 2 | C24: 16 | D24: =Table3[[#This Row],[Tm]]+Table3[[#This Row],[ΔT]]*(Table3[[#This Row],[G]]/Table3[[#This Row],[Gstc]]) -> 32.136 | E24: 712 | F24: 30
C25: 17 | D25: =Table3[[#This Row],[Tm]]+Table3[[#This Row],[ΔT]]*(Table3[[#This Row],[G]]/Table3[[#This Row],[Gstc]]) -> 34.115 | E25: 705 | F25: 32
B26: 3 | C26: 18 | D26: =Table3[[#This Row],[Tm]]+Table3[[#This Row],[ΔT]]*(Table3[[#This Row],[G]]/Table3[[#This Row],[Gstc]]) -> 34.106 | E26: 702 | F26: 32
C27: 19 | D27: =Table3[[#This Row],[Tm]]+Table3[[#This Row],[ΔT]]*(Table3[[#This Row],[G]]/Table3[[#This Row],[Gstc]]) -> 34.106 | E27: 702 | F27: 32
B28: 4 | C28: 20 | D28: =Table3[[#This Row],[Tm]]+Table3[[#This Row],[ΔT]]*(Table3[[#This Row],[G]]/Table3[[#This Row],[Gstc]]) -> 34.106 | E28: 702 | F28: 32
B30: 5 | C30: 21 | D30: =Table3[[#This Row],[Tm]]+Table3[[#This Row],[ΔT]]*(Table3[[#This Row],[G]]/Table3[[#This Row],[Gstc]]) -> 2.106 | E30: 702
C31: 22 | D31: =Table3[[#This Row],[Tm]]+Table3[[#This Row],[ΔT]]*(Table3[[#This Row],[G]]/Table3[[#This Row],[Gstc]]) -> 2.106 | E31: 702
B32: 6 | C32: 23 | D32: =Table3[[#This Row],[Tm]]+Table3[[#This Row],[ΔT]]*(Table3[[#This Row],[G]]/Table3[[#This Row],[Gstc]]) -> 2.106 | E32: 702
C33: 24 | D33: =Table3[[#This Row],[Tm]]+Table3[[#This Row],[ΔT]]*(Table3[[#This Row],[G]]/Table3[[#This Row],[Gstc]]) -> 31.737
B34: 7 | C34: 25 | D34: =Table3[[#This Row],[Tm]]+Table3[[#This Row],[ΔT]]*(Table3[[#This Row],[G]]/Table3[[#This Row],[Gstc]]) -> 31.737
B36: 8 | C36: 26 | D36: =Table3[[#This Row],[Tm]]+Table3[[#This Row],[ΔT]]*(Table3[[#This Row],[G]]/Table3[[#This Row],[Gstc]]) -> 31.737 | E36: 579 | F36: 30
B38: 9 | C38: 27 | D38: =Table3[[#This Row],[Tm]]+Table3[[#This Row],[ΔT]]*(Table3[[#This Row],[G]]/Table3[[#This Row],[Gstc]]) -> 31.737 | E38: 579 | F38: 30
B40: 10 | C40: 28 | D40: =Table3[[#This Row],[Tm]]+Table3[[#This Row],[ΔT]]*(Table3[[#This Row],[G]]/Table3[[#This Row],[Gstc]]) -> 31.737 | E40: 579 | F40: 30
A42: 3 | B42: 1 | C42: 29 | D42: =Table3[[#This Row],[Tm]]+Table3[[#This Row],[ΔT]]*(Table3[[#This Row],[G]]/Table3[[#This Row],[Gstc]]) -> 32.07
B44: 2 | C44: 30 | D44: =Table3[[#This Row],[Tm]]+Table3[[#This Row],[ΔT]]*(Table3[[#This Row],[G]]/Table3[[#This Row],[Gstc]]) -> 1.833
B46: 3 | C46: 31 | D46: =Table3[[#This Row],[Tm]]+Table3[[#This Row],[ΔT]]*(Table3[[#This Row],[G]]/Table3[[#This Row],[Gstc]]) -> 1.833
B48: 4 | C48: 32 | D48: =Table3[[#This Row],[Tm]]+Table3[[#This Row],[ΔT]]*(Table3[[#This Row],[G]]/Table3[[#This Row],[Gstc]]) -> 1.833
B50: 5 | C50: 33 | D50: =Table3[[#This Row],[Tm]]+Table3[[#This Row],[ΔT]]*(Table3[[#This Row],[G]]/Table3[[#This Row],[Gstc]]) -> 34.815 | E50: 605 | F50: 33
C51: 34 | D51: =Table3[[#This Row],[Tm]]+Table3[[#This Row],[ΔT]]*(Table3[[#This Row],[G]]/Table3[[#This Row],[Gstc]]) -> 34.815 | E51: 605 | F51: 33
B52: 6 | C52: 35 | D52: =Table3[[#This Row],[Tm]]+Table3[[#This Row],[ΔT]]*(Table3[[#This Row],[G]]/Table3[[#This Row],[Gstc]]) -> 34.815 | E52: 605 | F52: 33
C53: 36 | D53: =Table3[[#This Row],[Tm]]+Table3[[#This Row],[ΔT]]*(Table3[[#This Row],[G]]/Table3[[#This Row],[Gstc]]) -> 30.728 | E53: 576 | F53: 29
B54: 7 | C54: 37 | D54: =Table3[[#This Row],[Tm]]+Table3[[#This Row],[ΔT]]*(Table3[[#This Row],[G]]/Table3[[#This Row],[Gstc]]) -> 30.728 | E54: 576 | F54: 29
C55: 38 | D55: =Table3[[#This Row],[Tm]]+Table3[[#This Row],[ΔT]]*(Table3[[#This Row],[G]]/Table3[[#This Row],[Gstc]]) -> 30.728 | E55: 576 | F55: 29
B56: 8 | C56: 39 | D56: =Table3[[#This Row],[Tm]]+Table3[[#This Row],[ΔT]]*(Table3[[#This Row],[G]]/Table3[[#This Row],[Gstc]]) -> 30.728 | E56: 576 | F56: 29
...

Sheet Sheet2
C7: G -Irradiance | D7: I -Current
C8: 702 | D8: 7.49
C9: 605 | D9: 7.17
C10: 753 | D10: 8.77
C11: 605 | D11: 7.14
C12: 576 | D12: 7.04
I14: 580
I15: 0.19
I16: =I14*I15 -> 110.2

Sheet Sheet1
C5: Strings
B6: Inv 1 | C6: 13
B7: Inv 2 | C7: 15
B8: Inv 3 | C8: 13
B9: Inv 4 | C9: 15
B10: Inv 5 | C10: 15
B11: Inv 6 | C11: 13
B12: Total | C12: =SUM(C6:C11) -> 84

Sheet Sheet3
B1: Inverter | C1: MPPT | D1: String | E1: No. of modules | F1: Orientation | G1: Tilt angle
B2: 1 | C2: 1 | D2: 1 | E2: 16 | F2: 270 | G2: 5
D3: 2 | E3: 16 | F3: 270 | G3: 5
C4: 2 | D4: 3 | E4: 18 | F4: 270 | G4: 5
C6: 3 | D6: 4 | E6: 17 | F6: 310 | G6: 5
D7: 5 | E7: 17 | F7: 310 | G7: 5
C8: 4 | D8: 6 | E8: 17 | F8: 310 | G8: 5
C10: 5 | D10: 7 | E10: 17 | F10: 310 | G10: 5
C12: 6 | D12: 8 | E12: 17 | F12: 310 | G12: 5
C14: 7 | D14: 9 | E14: 19 | F14: 310 | G14: 5
C16: 8 | D16: 10 | E16: 19 | F16: 310 | G16: 5
C18: 9 | D18: 11 | E18: 16 | F18: 310 | G18: 5
D19: 12 | E19: 16 | F19: 310 | G19: 5
C20: 10 | D20: 13 | E20: 16 | F20: 310 | G20: 5
B22: 2 | C22: 1 | D22: 14 | E22: 18 | F22: 130 | G22: 5
D23: 15 | E23: 18 | F23: 130 | G23: 5
C24: 2 | D24: 16 | E24: 18 | F24: 130 | G24: 5
D25: 17 | E25: 18 | F25: 130 | G25: 5
C26: 3 | D26: 18 | E26: 18 | F26: 130 | G26: 5
D27: 19 | E27: 18 | F27: 130 | G27: 5
C28: 4 | D28: 20 | E28: 18 | F28: 130 | G28: 5
C30: 5 | D30: 21 | E30: 17 | F30: 310 | G30: 5
D31: 22 | E31: 17 | F31: 310 | G31: 5
C32: 6 | D32: 23 | E32: 17 | F32: 310 | G32: 5
D33: 24 | E33: 17 | F33: 310 | G33: 5
C34: 7 | D34: 25 | E34: 17 | F34: 310 | G34: 5
C36: 8 | D36: 26 | E36: 17 | F36: 310 | G36: 5
C38: 9 | D38: 27 | E38: 17 | F38: 310 | G38: 5
C40: 10 | D40: 28 | E40: 19 | F40: 310 | G40: 5
B42: 3 | C42: 1 | D42: 29 | E42: 20 | F42: 130 | G42: 5
C44: 2 | D44: 30 | E44: 20 | F44: 130 | G44: 5
C46: 3 | D46: 31 | E46: 20 | F46: 130 | G46: 5
C48: 4 | D48: 32 | E48: 20 | F48: 130 | G48: 5
C50: 5 | D50: 33 | E50: 18 | F50: 310 | G50: 5
D51: 34 | E51: 18 | F51: 310 | G51: 5
C52: 6 | D52: 35 | E52: 18 | F52: 310 | G52: 5
D53: 36 | E53: 18 | F53: 310 | G53: 5
C54: 7 | D54: 37 | E54: 18 | F54: 310 | G54: 5
D55: 38 | E55: 18 | F55: 310 | G55: 5
C56: 8 | D56: 39 | E56: 18 | F56: 310 | G56: 5
...
