Workbook

Sheet Voc & Isc Test Result
A2: A1 Commissioning - IV Curve Testing | L2: Site Name
L4: Tested By: | M4: Date:
A5: I - V CURVE IN STRINGS | H5: Inspection 1 Accept / Reject | I5: Inspection 2 Accept / Reject | L5: Your Name Here | M5: The Date
A6: 1 | B6: Test carried out during a cloudless interval with irradiance above 600W/m2
A7: =A6+1 -> 2 | B7: Test carried out before connecting the inverters to the loads
A8: =A7+1 -> 3 | B8: Fuses removed prior to connection of the I-V tracer in the case that the PV Facility is connected to the electrical network
A9: =A8+1 -> 4 | B9: Polarity of the strings measured and checked
A10: =A9+1 -> 5 | B10: Measure and record the temperature measured on the backsheet of the PV module (Tm ) for thermographic camera or through the average of the temperature cell sensors
A11: =A10+1 -> 6 | B11: Measure and record the Irradiance on the plane of the PV modules when performing the I-V curve
A12: =A11+1 -> 7 | B12: Measure and record the open circuit voltage Voc across each string through the I-V tracer
A13: =A12+1 -> 8 | B13: Measure and record the short circuit current (Isc ) of the string through the I-V tracer
A14: Notes:
A17: CALCULATIONS
A19: Tc: temperature of the cell of the PV module will be calculated theoretically using the formula:
A21: Tc | B21: Temperature of the cell of the PV module (°C)
A22: Tm | B22: Temperature measured on the backsheet of the PV module (°C)
A23: G | B23: Irradiance on the plane of the PV modules (W/m2)
A24: Gstc | B24: Irradiance in STC (1000W/m2)
A25: ∆T | B25: Temperature differences between PV cell and the PV backsheet, considered as 3 °C (as per IEC 61724, table A-1)
A27: INVERTER 1 | D27: G | E27: Gstc | F27: Tm | H27: ∆T | I27: Tc
A28: MPPT 1 | B28: INPUT 1 | D28: ='Raw Data_Mod Tests'!E2 -> 0 | E28: 1000 | F28: ='Raw Data_Mod Tests'!F2 -> 0 | H28: 3 | I28: =F28+((D28/E28)*H28) -> 0
B29: INPUT 2 | D29: ='Raw Data_Mod Tests'!E3 -> 0 | E29: 1000 | F29: ='Raw Data_Mod Tests'!F3 -> 0 | H29: 3 | I29: =F29+((D29/E29)*H29) -> 0
A30: MPPT 2 | B30: INPUT 1 | D30: ='Raw Data_Mod Tests'!E4 -> 0 | E30: 1000 | F30: ='Raw Data_Mod Tests'!F4 -> 0 | H30: 3 | I30: =F30+((D30/E30)*H30) -> 0
B31: INPUT 2 | D31: ='Raw Data_Mod Tests'!E5 -> 0 | E31: 1000 | F31: ='Raw Data_Mod Tests'!F5 -> 0 | H31: 3 | I31: =F31+((D31/E31)*H31) -> 0
A32: MPPT 3 | B32: INPUT 1 | D32: ='Raw Data_Mod Tests'!E6 -> 0 | E32: 1000 | F32: ='Raw Data_Mod Tests'!F6 -> 0 | H32: 3 | I32: =F32+((D32/E32)*H32) -> 0
B33: INPUT 2 | D33: ='Raw Data_Mod Tests'!E7 -> 0 | E33: 1000 | F33: ='Raw Data_Mod Tests'!F7 -> 0 | H33: 3 | I33: =F33+((D33/E33)*H33) -> 0
A34: MPPT 4 | B34: INPUT 1 | D34: ='Raw Data_Mod Tests'!E8 -> 0 | E34: 1000 | F34: ='Raw Data_Mod Tests'!F8 -> 0 | H34: 3 | I34: =F34+((D34/E34)*H34) -> 0
B35: INPUT 2 | D35: ='Raw Data_Mod Tests'!E9 -> 0 | E35: 1000 | F35: ='Raw Data_Mod Tests'!F9 -> 0 | H35: 3 | I35: =F35+((D35/E35)*H35) -> 0
A36: MPPT 5 | B36: INPUT 1 | D36: ='Raw Data_Mod Tests'!E10 -> 0 | E36: 1000 | F36: ='Raw Data_Mod Tests'!F10 -> 0 | H36: 3 | I36: =F36+((D36/E36)*H36) -> 0
B37: INPUT 2 | D37: ='Raw Data_Mod Tests'!E11 -> 0 | E37: 1000 | F37: ='Raw Data_Mod Tests'!F11 -> 0 | H37: 3 | I37: =F37+((D37/E37)*H37) -> 0
A38: MPPT 6 | B38: INPUT 1 | D38: ='Raw Data_Mod Tests'!E12 -> 0 | E38: 1000 | F38: ='Raw Data_Mod Tests'!F12 -> 0 | H38: 3 | I38: =F38+((D38/E38)*H38) -> 0
B39: INPUT 2 | D39: ='Raw Data_Mod Tests'!E13 -> 0 | E39: 1000 | F39: ='Raw Data_Mod Tests'!F13 -> 0 | H39: 3 | I39: =F39+((D39/E39)*H39) -> 0
A42: INVERTER 2 | D42: G | E42: Gstc | F42: Tm | H42: ∆T | I42: Tc
A43: MPPT 1 | B43: INPUT 1 | D43: ='Raw Data_Mod Tests'!E14 -> 0 | E43: 1000 | F43: ='Raw Data_Mod Tests'!F14 -> 0 | H43: 3 | I43: =F43+((D43/E43)*H43) -> 0
B44: INPUT 2 | D44: ='Raw Data_Mod Tests'!E15 -> 0 | E44: 1000 | F44: ='Raw Data_Mod Tests'!F15 -> 0 | H44: 3 | I44: =F44+((D44/E44)*H44) -> 0
A45: MPPT 2 | B45: INPUT 1 | D45: ='Raw Data_Mod Tests'!E16 -> 0 | E45: 1000 | F45: ='Raw Data_Mod Tests'!F16 -> 0 | H45: 3 | I45: =F45+((D45/E45)*H45) -> 0
B46: INPUT 2 | D46: ='Raw Data_Mod Tests'!E17 -> 0 | E46: 1000 | F46: ='Raw Data_Mod Tests'!F17 -> 0 | H46: 3 | I46: =F46+((D46/E46)*H46) -> 0
A47: MPPT 3 | B47: INPUT 1 | D47: ='Raw Data_Mod Tests'!E18 -> 0 | E47: 1000 | F47: ='Raw Data_Mod Tests'!F18 -> 0 | H47: 3 | I47: =F47+((D47/E47)*H47) -> 0
B48: INPUT 2 | D48: ='Raw Data_Mod Tests'!E19 -> 0 | E48: 1000 | F48: ='Raw Data_Mod Tests'!F19 -> 0 | H48: 3 | I48: =F48+((D48/E48)*H48) -> 0
A49: MPPT 4 | B49: INPUT 1 | D49: ='Raw Data_Mod Tests'!E20 -> 0 | E49: 1000 | F49: ='Raw Data_Mod Tests'!F20 -> 0 | H49: 3 | I49: =F49+((D49/E49)*H49) -> 0
...

Sheet Raw Data_Mod Tests
A1: Inverter | B1: MPPT | C1: String | D1: Tc | E1: G | F1: Tm | G1: Voc Measure | H1: Isc Measure | I1: Voc stc Check | J1: N | K1: Gstc | L1: ΔT | M1: Voc theo | N1: Nmod | O1: Voc stc | P1: δ Voc | Q1: Tc | R1: Isc stc | S1: δIsc | T1: Isc theo | X1: Tc | Y1: Temperature of the cell of the PV module (°C)
A2: 1 | B2: 1 | C2: 1 | K2: =IF(J2>0,1000,0) -> 0 | L2: =IF(K2>0,3,0) -> 0 | N2: =J2 -> 0 | O2: 48.9 | P2: -0.0027 | R2: 11.46 | S2: 0.00048 | X2: Tm | Y2: Temperature measured on the backsheet of the PV module (°C)
C3: 2 | K3: =IF(J3>0,1000,0) -> 0 | L3: =IF(K3>0,3,0) -> 0 | N3: =J3 -> 0 | X3: G | Y3: Irradiance on the plane of the PV modules (W/m2)
B4: 2 | C4: 1 | K4: =IF(J4>0,1000,0) -> 0 | L4: =IF(K4>0,3,0) -> 0 | N4: =J4 -> 0 | X4: Gstc | Y4: Irradiance in STC (1000W/m2)
C5: 2 | K5: =IF(J5>0,1000,0) -> 0 | L5: =IF(K5>0,3,0) -> 0 | N5: =J5 -> 0 | X5: ∆T | Y5: Temperature differences between PV cell and the PV backsheet, considered as 3 °C (as per IEC 61724, table A-1)
B6: 3 | C6: 1 | K6: =IF(J6>0,1000,0) -> 0 | L6: =IF(K6>0,3,0) -> 0 | N6: =J6 -> 0 | X6: Voc theo | Y6: Theoratical open circuit voltage (V)
C7: 2 | K7: =IF(J7>0,1000,0) -> 0 | L7: =IF(K7>0,3,0) -> 0 | N7: =J7 -> 0 | X7: Nmod | Y7: Number of the modules which compose each tested string
B8: 4 | C8: 1 | K8: =IF(J8>0,1000,0) -> 0 | L8: =IF(K8>0,3,0) -> 0 | N8: =J8 -> 0 | X8: Voc stc | Y8: Rated PV module open circuit voltage at standard conditions (STC) (V)
C9: 2 | K9: =IF(J9>0,1000,0) -> 0 | L9: =IF(K9>0,3,0) -> 0 | N9: =J9 -> 0 | X9: δ Voc | Y9: PV module manufacturer's rated temperature coefficient of Voc (% / ° C)
B10: 5 | C10: 1 | K10: =IF(J10>0,1000,0) -> 0 | L10: =IF(K10>0,3,0) -> 0 | N10: =J10 -> 0 | X10: Tc | Y10: Temperature of the cell of the PV module (°C)
C11: 2 | K11: =IF(J11>0,1000,0) -> 0 | L11: =IF(K11>0,3,0) -> 0 | N11: =J11 -> 0 | X11: N | Y11: Number of strings which compose each test
B12: 6 | C12: 1 | K12: =IF(J12>0,1000,0) -> 0 | L12: =IF(K12>0,3,0) -> 0 | N12: =J12 -> 0 | X12: Isc stc | Y12: Rated PV module short circuit curent at standard conditions indicated in the photovoltaic panel data sheet (STC) (A)
C13: 2 | K13: =IF(J13>0,1000,0) -> 0 | L13: =IF(K13>0,3,0) -> 0 | N13: =J13 -> 0 | X13: G | Y13: Irradiance on the plane of the PV modules (W/m2)
A14: 2 | B14: 1 | C14: 1 | K14: =IF(J14>0,1000,0) -> 0 | L14: =IF(K14>0,3,0) -> 0 | N14: =J14 -> 0 | X14: Gstc | Y14: Irradiance in STC conditions (1000 W/m2)
C15: 2 | K15: =IF(J15>0,1000,0) -> 0 | L15: =IF(K15>0,3,0) -> 0 | N15: =J15 -> 0 | X15: δIsc | Y15: PV module manufacturer's rated temperature coefficient of Isc (% / °C)
B16: 2 | C16: 1 | K16: =IF(J16>0,1000,0) -> 0 | L16: =IF(K16>0,3,0) -> 0 | N16: =J16 -> 0 | X16: Tc | Y16: Temperature of the cell of the PV module (°C)
C17: 2 | K17: =IF(J17>0,1000,0) -> 0 | L17: =IF(K17>0,3,0) -> 0 | N17: =J17 -> 0 | X17: Isc theo | Y17: Theoratical short circuit current (A)
B18: 3 | C18: 1 | K18: =IF(J18>0,1000,0) -> 0 | L18: =IF(K18>0,3,0) -> 0 | N18: =J18 -> 0
C19: 2 | K19: =IF(J19>0,1000,0) -> 0 | L19: =IF(K19>0,3,0) -> 0 | N19: =J19 -> 0 | X19: Module at
B20: 4 | C20: 1 | K20: =IF(J20>0,1000,0) -> 0 | L20: =IF(K20>0,3,0) -> 0 | N20: =J20 -> 0
C21: 2 | K21: =IF(J21>0,1000,0) -> 0 | L21: =IF(K21>0,3,0) -> 0 | N21: =J21 -> 0
B22: 5 | C22: 1 | K22: =IF(J22>0,1000,0) -> 0 | L22: =IF(K22>0,3,0) -> 0 | N22: =J22 -> 0
C23: 2 | K23: =IF(J23>0,1000,0) -> 0 | L23: =IF(K23>0,3,0) -> 0 | N23: =J23 -> 0
B24: 6 | C24: 1 | K24: =IF(J24>0,1000,0) -> 0 | L24: =IF(K24>0,3,0) -> 0 | N24: =J24 -> 0
C25: 2 | K25: =IF(J25>0,1000,0) -> 0 | L25: =IF(K25>0,3,0) -> 0 | N25: =J25 -> 0
A26: 3 | B26: 1 | C26: 1 | K26: =IF(J26>0,1000,0) -> 0 | L26: =IF(K26>0,3,0) -> 0 | N26: =J26 -> 0
C27: 2 | K27: =IF(J27>0,1000,0) -> 0 | L27: =IF(K27>0,3,0) -> 0 | N27: =J27 -> 0
B28: 2 | C28: 1 | K28: =IF(J28>0,1000,0) -> 0 | L28: =IF(K28>0,3,0) -> 0 | N28: =J28 -> 0
C29: 2 | K29: =IF(J29>0,1000,0) -> 0 | L29: =IF(K29>0,3,0) -> 0 | N29: =J29 -> 0
B30: 3 | C30: 1 | K30: =IF(J30>0,1000,0) -> 0 | L30: =IF(K30>0,3,0) -> 0 | N30: =J30 -> 0
C31: 2 | K31: =IF(J31>0,1000,0) -> 0 | L31: =IF(K31>0,3,0) -> 0 | N31: =J31 -> 0
B32: 4 | C32: 1 | K32: =IF(J32>0,1000,0) -> 0 | L32: =IF(K32>0,3,0) -> 0 | N32: =J32 -> 0
C33: 2 | K33: =IF(J33>0,1000,0) -> 0 | L33: =IF(K33>0,3,0) -> 0 | N33: =J33 -> 0
B34: 5 | C34: 1 | K34: =IF(J34>0,1000,0) -> 0 | L34: =IF(K34>0,3,0) -> 0 | N34: =J34 -> 0
C35: 2 | K35: =IF(J35>0,1000,0) -> 0 | L35: =IF(K35>0,3,0) -> 0 | N35: =J35 -> 0
B36: 6 | C36: 1 | K36: =IF(J36>0,1000,0) -> 0 | L36: =IF(K36>0,3,0) -> 0 | N36: =J36 -> 0
C37: 2 | K37: =IF(J37>0,1000,0) -> 0 | L37: =IF(K37>0,3,0) -> 0 | N37: =J37 -> 0
A38: 4 | B38: 1 | C38: 1 | K38: =IF(J38>0,1000,0) -> 0 | L38: =IF(K38>0,3,0) -> 0 | N38: =J38 -> 0
C39: 2 | K39: =IF(J39>0,1000,0) -> 0 | L39: =IF(K39>0,3,0) -> 0 | N39: =J39 -> 0
B40: 2 | C40: 1 | K40: =IF(J40>0,1000,0) -> 0 | L40: =IF(K40>0,3,0) -> 0 | N40: =J40 -> 0
...
