Workbook
Name Inverter_Capacity: #REF!
Name Inverter_Supplier: #REF!
Name Project_Size: 'Finance - Revenue'!Projectsize
Name Project_Size: Projectsize
Name Projectsize: #REF!
Name Projectsize: #REF!
Name Security_Serv: #REF!
Name Security_Serv: #REF!
Name SSS: #REF!
Name SSS: #REF!
Name USD_ZAR: #REF!

Sheet Certificate - Financial Close
B2: Emergent Energy – Financial Close Completion Certificate | H2: FINANCIAL CLOSE CERTIFICATE
B4: Project Name: | C4: ='Project Plan'!E2 -> Shoprite Mini_Bredarsdorp
B5: COO: | C5: Johannes Potgieter
B6: Programme Manager: | C6: Roedolph Venter
B7: HoPD: | C7: Natasha Watkins-Baker
B9: Date of Phase Completion: | F9: {=_xlfn.LET(_xlpm.w,$B$10:$B$54,_xlpm.r,$M$10:$M$54,_xlpm.v,IF(ISNUMBER(_xlpm.r),_xlpm.r,IFERROR(VALUE(SUBSTITUTE(_xlpm.r,"%",""))/100,0)),_xlpm.g,IFERROR(VALUE(LEFT(_xlpm.w,1)),0),_xlpm.bdOnly,(SUMPRODUCT((_xlpm.w="1.1")*(_xlpm.v>0))>0)*(SUMPRODUCT((_xlpm.w<>"1.1")*(_xlpm.v>0))=0),_xlpm.anyConstr,SUMPRODUCT((_xlpm.g>=2)*(_xlpm.g<=6)*(_xlpm.v>0))>0,_xlpm.anyQA,SUMPRODUCT((_xlpm.g=7)*(_xlpm.v>0))>0,_xlpm.anyHO,SUMPRODUCT((_xlpm.g=8)*(_xlpm.v>0))>0,_xlpm.anyPlan,SUMPRODUCT((_xlpm.g=1)*(_xlpm.v>0))>0,IF(_xlpm.bdOnly,"1. Financial Close",IF(_xlpm.anyConstr,"3. Construction",IF(_xlpm.anyQA,"4. QA",IF(_xlpm.anyHO,"5. Handover",IF(_xlpm.anyPlan,"2. Planning","1. Financial Close"))))))} -> 1. Financial Close | G9: {=_xlfn.LET(_xlpm.w,$B$10:$B$54,_xlpm.r,$N$10:$N$54,_xlpm.v,IF(ISNUMBER(_xlpm.r),_xlpm.r,IFERROR(VALUE(SUBSTITUTE(_xlpm.r,"%",""))/100,0)),_xlpm.g,IFERROR(VALUE(LEFT(_xlpm.w,1)),0),_xlpm.bdOnly,(SUMPRODUCT((_xlpm.w="1.1")*(_xlpm.v>0))>0)*(SUMPRODUCT((_xlpm.w<>"1.1")*(_xlpm.v>0))=0),_xlpm.anyConstr,SUMPRODUCT((_xlpm.g>=2)*(_xlpm.g<=6)*(_xlpm.v>0))>0,_xlpm.anyQA,SUMPRODUCT((_xlpm.g=7)*(_xlpm.v>0))>0,_xlpm.anyHO,SUMPRODUCT((_xlpm.g=8)*(_xlpm.v>0))>0,_xlpm.anyPlan,SUMPRODUCT((_xlpm.g=1)*(_xlpm.v>0))>0,IF(_xlpm.bdOnly,"1. Financial Close",IF(_xlpm.anyConstr,"3. Construction",IF(_xlpm.anyQA,"4. QA",IF(_xlpm.anyHO,"5. Handover",IF(_xlpm.anyPlan,"2. Planning","1. Financial Close"))))))} -> 1. Financial Close
B10: Phase Deliverables Checklist: (Y/N)
B11: Product Agreement
B12: EPC Agreement
B13: O&M Agreeement
B14: Cost Proposal
B15: Deposit Received
B16: Risks / Notes
B18: Acknowledgement and Acceptance:
B19: Role | C19: Name | D19: Signature | E19: Date

Sheet Certificate - Planning
B2: Emergent Energy – Planning Phase Completion Certificate | H2: PLANNING CERTIFICATE
B4: Project Name: | C4: ='Project Plan'!E2 -> Shoprite Mini_Bredarsdorp
B5: Client Representative:
B6: Programme Manager: | C6: Roedolph Venter
B7: Project Manager: | C7: ='Project Plan'!E5 -> Peet Verreynne
B8: Project Engineer:
B10: Date of Phase Completion:
B11: Phase Deliverables Checklist: (Y/N)
B12: Project Introduction Presentation
B13: Project Brief
B14: Engineering Pack
B15: BOQ
B16: PO – Material & Equipment
B17: PO - Contractors
B18: HSE – NOC
B19: HSE – EE File
B20: HSE – Contractor File
... B24: Acknowledgement and Acceptance:
B25: Role | C25: Name | D25: Signature | E25: Date

Sheet Change Register
F1: Change Register
B3: ID | C3: Description | D3: Supporting Image (If Applicable) | E3: Impact | F3: Proposed Date | G3: Proposed By | H3: Status | I3: Approved By | J3: Approved Date | K3: Results / Comments
B4: DEC001
B5: DEC002
B6: DEC003
B7: DEC004
B8: DEC005
B9: DEC006
B10: DEC007
B11: DEC008
B12: DEC009
B13: DEC010
B14: DEC011
B15: DEC012
... B33: DEC030

Sheet BOQ
B2: Item | C2: Supplier | D2: Description | E2: Quantity | F2: Comments
B3: PV Module
B4: DC Cable Red & Black
B5: Inverters
B6: Mounting Structure
B7: Current Transformers (Production)
B8: Current Transformers (Consumption)
B9: Solar Production Meter (Techistter)
B10: Grid Consumption Meter
B11: Wi-Fi Router & Sim
B12: Switch
B13: Back Up Battery
B14: PVDB
... B30: Techsitter

Sheet Compliance
B2: HSE
B4: Description | C4: Status | D4: Approved By | E4: Date | F4: Results / Comments
B5: NOC
B6: 7.1 Agreement
B7: 13.2 Agreement
B8: EE File
B9: Subbie File
B16: SSEG
B18: Description | C18: Status | D18: Approved By | E18: Date | F18: Results / Comments
B19: SSEG Application
B20: PTI
B21: Commissioning Approval

Sheet Project Plan
N1: =TODAY() -> 46062 | O1: =TODAY() -> 46062
C2: PROJECT PLAN | E2: Shoprite Mini_Bredarsdorp | I2: Net Work Days | K2: =NETWORKDAYS(I18,K39,Data!C3:C60) -> 21 | N2: 0 | O2: 1
C3: PROJECT SIZE (kWp) | E3: 250 | I3: Total Weeks | K3: =K2/5 -> 4.2
C4: PROJECT DEVELOPER | E4: Peet Verreynne | I4: kW/Week Installation Rate | K4: =E3/K3 -> 59.52381
C5: PROJECT MANAGERS | E5: Peet Verreynne
C6: CONTRACT VALUE | E6: 2077436.3
C7: Phase: | E7: Compliance Handover
B8: No. | C8: HIGH LEVEL PROGRAMME | E8: Planned Start | F8: Duration | G8: Planned End | I8: Actual Start | J8: Duration | K8: Actual End | M8: Status | N8: Expected Status | O8: Comment
F9: =G39-E19 -> 21 | J9: =K39-I19 -> 28 | M9: =AVERAGE(M11,M18,M21,M28,M35,M39,M48,M44) -> 1 | N9: =AVERAGE(N11,N18,N21,N28,N35,N39,N48,N44) -> 0.99996959 | S9: =TODAY() -> 46062 | T9: =TODAY() -> 46062
S10: 1 | T10: 0
B11: 1 | C11: Project Initiation | E11: =MIN(E12:E17) -> 45931 | F11: =G11-E11 -> 30 | G11: =MAX(G12:G17) -> 45961 | I11: =MIN(I12:I17) -> 45931 | J11: =K11-I11 -> 30 | K11: =MAX(K12:K17) -> 45961 | M11: =(J12*M12+J13*M13+J14*M14+J15*M15+J16*M16)/SUM(J12:J16) -> 1 | N11: =(K12*N12+K13*N13+K14*N14+K15*N15+K16*N16)/SUM(K12:K16) -> 1
B12: 1.1 | C12: Project Charter Handover | E12: 45931 | F12: 1 | G12: =WORKDAY.INTL(E12,F12,1,Data!$C$3:$C$60) -> 45932 | I12: 45931 | J12: 1 | K12: =WORKDAY.INTL(I12,J12,1,Data!$C$3:$C$60) -> 45932 | M12: 1 | N12: =_xlfn.LET( _xlpm.s,VALUE($I12), _xlpm.e,VALUE($K12), IF(OR(_xlpm.s="",_xlpm.e=""),"", IF(_xlpm.e<=_xlpm.s, IF(TODAY()>=_xlpm.e,1,0), MAX(0,MIN(1,(TODAY()-_xlpm.s)/(_xlpm.e-_xlpm.s))))) ) -> 1 | S12: Milestone | T12: Start Date | U12: Duration | V12: End Date
B13: 1.2 | C13: HSE Readiness and Signoff | E13: =WORKDAY.INTL(G12,0,1,Data!$C$3:$C$60) -> 45932 | F13: 15 | G13: =WORKDAY.INTL(E13,F13,1,Data!$C$3:$C$60) -> 45953 | I13: =WORKDAY.INTL(K12,0,1,Data!$C$3:$C$60) -> 45932 | J13: 15 | K13: =WORKDAY.INTL(I13,J13,1,Data!$C$3:$C$60) -> 45953 | M13: 1 | N13: =_xlfn.LET( _xlpm.s,VALUE($I13), _xlpm.e,VALUE($K13), IF(OR(_xlpm.s="",_xlpm.e=""),"", IF(_xlpm.e<=_xlpm.s, IF(TODAY()>=_xlpm.e,1,0), MAX(0,MIN(1,(TODAY()-_xlpm.s)/(_xlpm.e-_xlpm.s))))) ) -> 1 | S13: =C11 -> Project Initiation | T13: =I11 -> 45931 | U13: =J11 -> 30 | V13: =K11 -> 45961
B14: 1.3 | C14: Project Introduction | E14: =WORKDAY.INTL(G12,0,1,Data!$C$3:$C$60)+14 -> 45946 | F14: 1 | G14: =WORKDAY.INTL(E14,F14,1,Data!$C$3:$C$60) -> 45947 | I14: =WORKDAY.INTL(K12,0,1,Data!$C$3:$C$60)+14 -> 45946 | J14: 1 | K14: =WORKDAY.INTL(I14,J14,1,Data!$C$3:$C$60) -> 45947 | M14: 1 | N14: =_xlfn.LET( _xlpm.s,VALUE($I14), _xlpm.e,VALUE($K14), IF(OR(_xlpm.s="",_xlpm.e=""),"", IF(_xlpm.e<=_xlpm.s, IF(TODAY()>=_xlpm.e,1,0), MAX(0,MIN(1,(TODAY()-_xlpm.s)/(_xlpm.e-_xlpm.s))))) ) -> 1 | S14: =C18 -> Site Establishment | T14: =I18 -> 45967 | U14: =J18 -> 1 | V14: =K18 -> 45968
B15: 1.4 | C15: Installer Kick Off | E15: =WORKDAY.INTL(E14,0,1,Data!$C$3:$C$60)+14 -> 45960 | F15: 1 | G15: =WORKDAY.INTL(E15,F15,1,Data!$C$3:$C$60) -> 45961 | I15: =WORKDAY.INTL(I14,0,1,Data!$C$3:$C$60)+14 -> 45960 | J15: 1 | K15: =WORKDAY.INTL(I15,J15,1,Data!$C$3:$C$60) -> 45961 | M15: 1 | N15: =_xlfn.LET( _xlpm.s,VALUE($I15), _xlpm.e,VALUE($K15), IF(OR(_xlpm.s="",_xlpm.e=""),"", IF(_xlpm.e<=_xlpm.s, IF(TODAY()>=_xlpm.e,1,0), MAX(0,MIN(1,(TODAY()-_xlpm.s)/(_xlpm.e-_xlpm.s))))) ) -> 1 | S15: =C21 -> AC Installation | T15: =I21 -> 45925 | U15: =J21 -> 62 | V15: =K21 -> 45987
B16: 1.5 | C16: Project Review | E16: =WORKDAY.INTL(E15,0,1,Data!$C$3:$C$60) -> 45960 | F16: 1 | G16: =WORKDAY.INTL(E16,F16,1,Data!$C$3:$C$60) -> 45961 | I16: =WORKDAY.INTL(I15,0,1,Data!$C$3:$C$60) -> 45960 | J16: 1 | K16: =WORKDAY.INTL(I16,J16,1,Data!$C$3:$C$60) -> 45961 | M16: 1 | N16: =_xlfn.LET( _xlpm.s,VALUE($I16), _xlpm.e,VALUE($K16), IF(OR(_xlpm.s="",_xlpm.e=""),"", IF(_xlpm.e<=_xlpm.s, IF(TODAY()>=_xlpm.e,1,0), MAX(0,MIN(1,(TODAY()-_xlpm.s)/(_xlpm.e-_xlpm.s))))) ) -> 1 | S16: =C28 -> DC Works | T16: =I28 -> 45967 | U16: =J28 -> 21 | V16: =K28 -> 45988
S17: =C35 -> Module installation | T17: =I35 -> 45974 | U17: =J35 -> 11 | V17: =K35 -> 45985
B18: 2 | C18: Site Establishment | E18: =MIN(E19:E20) -> 45968 | F18: =G18-E18 -> 1 | G18: =MAX(G19:G20) -> 45969 | I18: =MIN(I19:I20) -> 45967 | J18: =K18-I18 -> 1 | K18: =MAX(K19:K20) -> 45968 | M18: =(J19*M19)/J18 -> 1 | N18: =(K19*N19)/K18 -> 1 | S18: =C39 -> Commissioning | T18: =I39 -> 45988 | U18: =J39 -> 7 | V18: =K39 -> 45995
B19: 2.1 | C19: Solar Contractor Establishment | E19: =WORKDAY.INTL(G16,0,1,Data!$C$3:$C$60)+7 -> 45968 | F19: 1 | G19: =E19+F19 -> 45969 | I19: 45967 | J19: 1 | K19: =I19+J19 -> 45968 | M19: 1 | N19: =_xlfn.LET( _xlpm.s,VALUE($I19), _xlpm.e,VALUE($K19), IF(OR(_xlpm.s="",_xlpm.e=""),"", IF(_xlpm.e<=_xlpm.s, IF(TODAY()>=_xlpm.e,1,0), MAX(0,MIN(1,(TODAY()-_xlpm.s)/(_xlpm.e-_xlpm.s))))) ) -> 1 | S19: =C44 -> QA Inspections | T19: =I44 -> 45988 | U19: =J44 -> 4 | V19: =K44 -> 45992
S20: =C48 -> Project Closure | T20: =I48 -> 45989 | U20: =J48 -> 62 | V20: =K48 -> 46051
B21: 3 | C21: AC Installation | E21: =MIN(E22:E27) -> 45925 | F21: =G21-E21 -> 49 | G21: =MAX(G22:G27) -> 45974 | I21: =MIN(I22:I27) -> 45925 | J21: =K21-I21 -> 62 | K21: =MAX(K22:K27) -> 45987 | M21: =(J22*M22+J23*M23+J24*M24+J25*M25+J26*M26)/SUM(J22:J26) -> 1 | N21: =(J22*N22+J23*N23+J24*N24+J25*N25+J26*N26)/SUM(J22:J26) -> 1
B22: 3.1 | C22: Inverters delivered | E22: =WORKDAY.INTL(G19,0,1,Data!$C$3:$C$60) -> 45969 | F22: 1 | G22: =WORKDAY.INTL(E22,F22,1,Data!$C$3:$C$60) -> 45971 | I22: 45973 | J22: 1 | K22: =WORKDAY.INTL(I22,J22,1,Data!$C$3:$C$60) -> 45974 | M22: 1 | N22: =_xlfn.LET( _xlpm.s,VALUE($I22), _xlpm.e,VALUE($K22), IF(OR(_xlpm.s="",_xlpm.e=""),"", IF(_xlpm.e<=_xlpm.s, IF(TODAY()>=_xlpm.e,1,0), MAX(0,MIN(1,(TODAY()-_xlpm.s)/(_xlpm.e-_xlpm.s))))) ) -> 1
B23: 3.2 | C23: Inverters Mounted | E23: =WORKDAY.INTL(G22,0,1,Data!$C$3:$C$60) -> 45971 | F23: 2 | G23: =WORKDAY.INTL(E23,F23,1,Data!$C$3:$C$60) -> 45973 | I23: 45973 | J23: 1 | K23: =WORKDAY.INTL(I23,J23,1,Data!$C$3:$C$60) -> 45974 | M23: 1 | N23: =_xlfn.LET( _xlpm.s,VALUE($I23), _xlpm.e,VALUE($K23), IF(OR(_xlpm.s="",_xlpm.e=""),"", IF(_xlpm.e<=_xlpm.s, IF(TODAY()>=_xlpm.e,1,0), MAX(0,MIN(1,(TODAY()-_xlpm.s)/(_xlpm.e-_xlpm.s))))) ) -> 1
B24: 3.3 | C24: Solar DB Lead Time | E24: =WORKDAY.INTL(E14,0,1,Data!$C$3:$C$60)-21 -> 45925 | F24: 30 | G24: =WORKDAY.INTL(E24,F24,1,Data!$C$3:$C$60) -> 45967 | I24: =WORKDAY.INTL(I14,0,1,Data!$C$3:$C$60)-21 -> 45925 | J24: 36 | K24: =WORKDAY.INTL(I24,J24,1,Data!$C$3:$C$60) -> 45975 | M24: 1 | N24: =_xlfn.LET( _xlpm.s,VALUE($I24), _xlpm.e,VALUE($K24), IF(OR(_xlpm.s="",_xlpm.e=""),"", IF(_xlpm.e<=_xlpm.s, IF(TODAY()>=_xlpm.e,1,0), MAX(0,MIN(1,(TODAY()-_xlpm.s)/(_xlpm.e-_xlpm.s))))) ) -> 1
B25: 3.4 | C25: AC Works | E25: =WORKDAY.INTL(G24,0,1,Data!$C$3:$C$60) -> 45967 | F25: 5 | G25: =WORKDAY.INTL(E25,F25,1,Data!$C$3:$C$60) -> 45974 | I25: 45978 | J25: 6 | K25: =WORKDAY.INTL(I25,J25,1,Data!$C$3:$C$60) -> 45986 | M25: 1 | N25: =_xlfn.LET( _xlpm.s,VALUE($I25), _xlpm.e,VALUE($K25), IF(OR(_xlpm.s="",_xlpm.e=""),"", IF(_xlpm.e<=_xlpm.s, IF(TODAY()>=_xlpm.e,1,0), MAX(0,MIN(1,(TODAY()-_xlpm.s)/(_xlpm.e-_xlpm.s))))) ) -> 1
B26: 3.5 | C26: AC Tie-In | E26: =WORKDAY.INTL(E25,0,1,Data!$C$3:$C$60) -> 45967 | F26: 1 | G26: =WORKDAY.INTL(E26,F26,1,Data!$C$3:$C$60) -> 45968 | I26: =K25 -> 45986 | J26: 1 | K26: =WORKDAY.INTL(I26,J26,1,Data!$C$3:$C$60) -> 45987 | M26: 1 | N26: =_xlfn.LET( _xlpm.s,VALUE($I26), _xlpm.e,VALUE($K26), IF(OR(_xlpm.s="",_xlpm.e=""),"", IF(_xlpm.e<=_xlpm.s, IF(TODAY()>=_xlpm.e,1,0), MAX(0,MIN(1,(TODAY()-_xlpm.s)/(_xlpm.e-_xlpm.s))))) ) -> 1
B28: 4 | C28: DC Works | E28: =MIN(E30:E34) -> 45968 | F28: =G28-E28 -> 12 | G28: =MAX(G30:G34) -> 45980 | I28: =MIN(I30:I34) -> 45967 | J28: =K28-I28 -> 21 | K28: =MAX(K30:K34) -> 45988 | M28: =(J30*M30+J31*M31+J33*M33+J32*M32)/SUM(J30:J33) -> 1 | N28: =(K30*N30+K31*N31+K33*N33+K32*N32)/SUM(K30:K33) -> 1
B30: 4.1 | C30: Mounting Structure delivered | E30: =E19 -> 45968 | F30: 1 | G30: =WORKDAY.INTL(E30,F30,1,Data!$C$3:$C$60) -> 45971 | I30: =I19 -> 45967 | J30: 1 | K30: =WORKDAY.INTL(I30,J30,1,Data!$C$3:$C$60) -> 45968 | M30: 1 | N30: =_xlfn.LET( _xlpm.s,VALUE($I30), _xlpm.e,VALUE($K30), IF(OR(_xlpm.s="",_xlpm.e=""),"", IF(_xlpm.e<=_xlpm.s, IF(TODAY()>=_xlpm.e,1,0), MAX(0,MIN(1,(TODAY()-_xlpm.s)/(_xlpm.e-_xlpm.s))))) ) -> 1
B31: 4.2 | C31: Mounting Structure installation | E31: =WORKDAY.INTL(G30,0,1,Data!$C$3:$C$60) -> 45971 | F31: 3 | G31: =WORKDAY.INTL(E31,F31,1,Data!$C$3:$C$60) -> 45974 | I31: =WORKDAY.INTL(K30,0,1,Data!$C$3:$C$60) -> 45968 | J31: 4 | K31: =WORKDAY.INTL(I31,J31,1,Data!$C$3:$C$60) -> 45974 | M31: 1 | N31: =_xlfn.LET( _xlpm.s,VALUE($I31), _xlpm.e,VALUE($K31), IF(OR(_xlpm.s="",_xlpm.e=""),"", IF(_xlpm.e<=_xlpm.s, IF(TODAY()>=_xlpm.e,1,0), MAX(0,MIN(1,(TODAY()-_xlpm.s)/(_xlpm.e-_xlpm.s))))) ) -> 1
B32: 4.3 | C32: DC Cable delivered | E32: =E30 -> 45968 | F32: 1 | G32: =WORKDAY.INTL(E32,F32,1,Data!$C$3:$C$60) -> 45971 | I32: =I30 -> 45967 | J32: 1 | K32: =WORKDAY.INTL(I32,J32,1,Data!$C$3:$C$60) -> 45968 | M32: 1 | N32: =_xlfn.LET( _xlpm.s,VALUE($I32), _xlpm.e,VALUE($K32), IF(OR(_xlpm.s="",_xlpm.e=""),"", IF(_xlpm.e<=_xlpm.s, IF(TODAY()>=_xlpm.e,1,0), MAX(0,MIN(1,(TODAY()-_xlpm.s)/(_xlpm.e-_xlpm.s))))) ) -> 1
B33: 4.4 | C33: DC Stringing | E33: =WORKDAY.INTL(G37,0,1,Data!$C$3:$C$60)-3 -> 45977 | F33: 3 | G33: =WORKDAY.INTL(E33,F33,1,Data!$C$3:$C$60) -> 45980 | I33: =WORKDAY.INTL(K37,0,1,Data!$C$3:$C$60)-3 -> 45982 | J33: 4 | K33: =WORKDAY.INTL(I33,J33,1,Data!$C$3:$C$60) -> 45988 | M33: 1 | N33: =_xlfn.LET( _xlpm.s,VALUE($I33), _xlpm.e,VALUE($K33), IF(OR(_xlpm.s="",_xlpm.e=""),"", IF(_xlpm.e<=_xlpm.s, IF(TODAY()>=_xlpm.e,1,0), MAX(0,MIN(1,(TODAY()-_xlpm.s)/(_xlpm.e-_xlpm.s))))) ) -> 1
B35: 5 | C35: Module installation | E35: =MIN(E36:E38) -> 45968 | F35: =G35-E35 -> 12 | G35: =MAX(G36:G38) -> 45980 | I35: =MIN(I36:I38) -> 45974 | J35: =K35-I35 -> 11 | K35: =MAX(K36:K38) -> 45985 | M35: =(J36*M36+J37*M37)/SUM(J36:J37) -> 1 | N35: =(K36*N36+K37*N37)/SUM(K36:K37) -> 1
B36: 5.1 | C36: Module delivery | E36: =WORKDAY.INTL(E19,0,1,Data!$C$3:$C$60) -> 45968 | F36: 1 | G36: =WORKDAY.INTL(E36,F36,1,Data!$C$3:$C$60) -> 45971 | I36: 45974 | J36: 2 | K36: =WORKDAY.INTL(I36,J36,1,Data!$C$3:$C$60) -> 45978 | M36: 1 | N36: =_xlfn.LET( _xlpm.s,VALUE($I36), _xlpm.e,VALUE($K36), IF(OR(_xlpm.s="",_xlpm.e=""),"", IF(_xlpm.e<=_xlpm.s, IF(TODAY()>=_xlpm.e,1,0), MAX(0,MIN(1,(TODAY()-_xlpm.s)/(_xlpm.e-_xlpm.s))))) ) -> 1
B37: 5.2 | C37: Module mounting | E37: =G31 -> 45974 | F37: 4 | G37: =WORKDAY.INTL(E37,F37,1,Data!$C$3:$C$60) -> 45980 | I37: =K31 -> 45974 | J37: 7 | K37: =WORKDAY.INTL(I37,J37,1,Data!$C$3:$C$60) -> 45985 | M37: 1 | N37: =_xlfn.LET( _xlpm.s,VALUE($I37), _xlpm.e,VALUE($K37), IF(OR(_xlpm.s="",_xlpm.e=""),"", IF(_xlpm.e<=_xlpm.s, IF(TODAY()>=_xlpm.e,1,0), MAX(0,MIN(1,(TODAY()-_xlpm.s)/(_xlpm.e-_xlpm.s))))) ) -> 1
B39: 6 | C39: Commissioning | E39: =MIN(E40:E43) -> 45980 | F39: =G39-E39 -> 9 | G39: =MAX(G40:G43) -> 45989 | I39: =MIN(I40:I43) -> 45988 | J39: =K39-I39 -> 7 | K39: =MAX(K40:K43) -> 45995 | M39: =(J40*M40+J41*M41+J42*M42)/SUM(J40:J42) -> 1 | N39: =(K40*N40+K41*N41)/SUM(K40:K41) -> 1
B40: 6.1 | C40: Commissioning | E40: =WORKDAY.INTL(MAX(G21,G28,G35),0,1,Data!$C$3:$C$60) -> 45980 | F40: 1 | G40: =WORKDAY.INTL(E40,F40,1,Data!$C$3:$C$60) -> 45981 | I40: =WORKDAY.INTL(MAX(K21,K28,K35),0,1,Data!$C$3:$C$60) -> 45988 | J40: 1 | K40: =WORKDAY.INTL(I40,J40,1,Data!$C$3:$C$60) -> 45989 | M40: 1 | N40: =_xlfn.LET( _xlpm.s,VALUE($I40), _xlpm.e,VALUE($K40), IF(OR(_xlpm.s="",_xlpm.e=""),"", IF(_xlpm.e<=_xlpm.s, IF(TODAY()>=_xlpm.e,1,0), MAX(0,MIN(1,(TODAY()-_xlpm.s)/(_xlpm.e-_xlpm.s))))) ) -> 1
B41: 6.2 | C41: Practical Completion | E41: =WORKDAY.INTL(G40,0,1,Data!$C$3:$C$60) -> 45981 | F41: 1 | G41: =WORKDAY.INTL(E41,F41,1,Data!$C$3:$C$60) -> 45982 | I41: =WORKDAY.INTL(K40,0,1,Data!$C$3:$C$60) -> 45989 | J41: 1 | K41: =WORKDAY.INTL(I41,J41,1,Data!$C$3:$C$60) -> 45992 | M41: 1 | N41: =_xlfn.LET( _xlpm.s,VALUE($I41), _xlpm.e,VALUE($K41), IF(OR(_xlpm.s="",_xlpm.e=""),"", IF(_xlpm.e<=_xlpm.s, IF(TODAY()>=_xlpm.e,1,0), MAX(0,MIN(1,(TODAY()-_xlpm.s)/(_xlpm.e-_xlpm.s))))) ) -> 1
B42: 6.3 | C42: System Performance Monitoring | E42: =WORKDAY.INTL(G41,0,1,Data!$C$3:$C$60) -> 45982 | F42: 5 | G42: =WORKDAY.INTL(E42,F42,1,Data!$C$3:$C$60) -> 45989 | I42: =WORKDAY.INTL(K41,0,1,Data!$C$3:$C$60) -> 45992 | J42: 3 | K42: =WORKDAY.INTL(I42,J42,1,Data!$C$3:$C$60) -> 45995 | M42: 1 | N42: =_xlfn.LET( _xlpm.s,VALUE($I42), _xlpm.e,VALUE($K42), IF(OR(_xlpm.s="",_xlpm.e=""),"", IF(_xlpm.e<=_xlpm.s, IF(TODAY()>=_xlpm.e,1,0), MAX(0,MIN(1,(TODAY()-_xlpm.s)/(_xlpm.e-_xlpm.s))))) ) -> 1
B44: 7 | C44: QA Inspections | E44: =MIN(E45:E47) -> 45980 | F44: =G44-E44 -> 6 | G44: =MAX(G45:G47) -> 45986 | I44: =MIN(I45:I47) -> 45988 | J44: =K44-I44 -> 4 | K44: =MAX(K45:K47) -> 45992 | M44: =(J45*M45+J46*M46)/SUM(J45:J46) -> 1 | N44: =(K45*N45)/SUM(K45) -> 1
B45: 7.1 | C45: Red-Team Inspection | E45: =WORKDAY.INTL(E40,0,1,Data!$C$3:$C$60) -> 45980 | F45: 2 | G45: =WORKDAY.INTL(E45,F45,1,Data!$C$3:$C$60) -> 45982 | I45: =WORKDAY.INTL(I40,0,1,Data!$C$3:$C$60) -> 45988 | J45: 1 | K45: =WORKDAY.INTL(I45,J45,1,Data!$C$3:$C$60) -> 45989 | M45: 1 | N45: =_xlfn.LET( _xlpm.s,VALUE($I45), _xlpm.e,VALUE($K45), IF(OR(_xlpm.s="",_xlpm.e=""),"", IF(_xlpm.e<=_xlpm.s, IF(TODAY()>=_xlpm.e,1,0), MAX(0,MIN(1,(TODAY()-_xlpm.s)/(_xlpm.e-_xlpm.s))))) ) -> 1
...

Sheet Revenue Tracking
B2: HIGH LEVEL PROJECT REVENUE TRACKING
D3: COSTED | F3: ACTUAL | L3: FINANCIAL REVIEW | N3: TIMELINE REVIEW | T3: 2025 Actual Revenue | U3: 2025 Actual COS | V3: 2026 Budget Revenue | W3: 2026 Budget COS | X3: 2026 Actual Revenue | Y3: 2026 Actual COS
B4: 1 | C4: Planned Revenue | D4: ='Project Plan'!E6 -> 2077436.3 | F4: =F21 -> 2077436.3 | N4: Start Date | T4: =SUMIFS('Expenditure Breakdown'!$U:$U, 'Expenditure Breakdown'!$T:$T, ">"&DATE(2024,8,31), 'Expenditure Breakdown'!$T:$T, "<="&DATE(2025,8,31), 'Expenditure Breakdown'!$S:$S, "<>") -> 0 | U4: =SUMIFS('Expenditure Breakdown'!$Q:$Q, 'Expenditure Breakdown'!$T:$T, ">"&DATE(2024,8,31), 'Expenditure Breakdown'!$T:$T, "<="&DATE(2025,8,31), 'Expenditure Breakdown'!$S:$S, "<>") -> 0 | V4: =SUMIFS('Expenditure Breakdown'!$U:$U, 'Expenditure Breakdown'!$T:$T, ">"&DATE(2025,8,31), 'Expenditure Breakdown'!$T:$T, "<="&DATE(2026,8,31)) -> 2064651.7 | W4: =SUMIFS('Expenditure Breakdown'!$Q:$Q, 'Expenditure Breakdown'!$T:$T, ">"&DATE(2025,8,31), 'Expenditure Breakdown'!$T:$T, "<="&DATE(2026,8,31)) -> 1502144.2 | X4: =SUMIFS('Expenditure Breakdown'!$U:$U, 'Expenditure Breakdown'!$T:$T, ">"&DATE(2025,8,31), 'Expenditure Breakdown'!$T:$T, "<="&DATE(2026,8,31), 'Expenditure Breakdown'!$S:$S, "<>") -> 2063554.3 | Y4: =SUMIFS('Expenditure Breakdown'!$Q:$Q, 'Expenditure Breakdown'!$T:$T, ">"&DATE(2025,8,31), 'Expenditure Breakdown'!$T:$T, "<="&DATE(2026,8,31), 'Expenditure Breakdown'!$S:$S, "<>") -> 1501050.4
B5: 2 | C5: Planned Expenditure | D5: =+'Expenditure Tracking'!F5 -> 1702430.3 | F5: =+'Expenditure Tracking'!H5 -> 1502144.2
B6: 3 | C6: Planned Profit | D6: =+D4-D5 -> 375005.96 | F6: =+F4-F5 -> 575292.1 | N6: End Date - PC
B7: 4 | C7: Planned Margin | D7: =+D6/D4 -> 0.18051382 | F7: =+F6/F4 -> 0.27692406
B10: CONTRACT
B12: No. | C12: PAYMENT MILESTONE | E12: % | F12: VALUE | H12: PLANNED PAYMENT DATE | L12: INVOICE NUMBER | N12: INVOICE RAISED DATE | P12: PAYMENT RECEIVED DATE | R12: MILESTONE NOTES & COMMENTS
B13: 1 | C13: Acceptance and Initial Deposit | E13: 0.5 | F13: =$D$4*E13 -> 1038718.1 | H13: 45908 | L13: 004873 | N13: 45961 | P13: 45971 | AO13: ='Change Register'!$Q$14+ 7 -> 7
B14: 2 | C14: Delivery of Panels | E14: 0.25 | F14: =$D$4*E14 -> 519359.07 | H14: ='Project Plan'!E36+7 -> 45975 | L14: 004873 | N14: 45961 | P14: 45975
B15: 3 | C15: Delivery of Inverters | E15: 0.1 | F15: =$D$4*E15 -> 207743.63 | H15: ='Project Plan'!E22+7 -> 45976 | L15: 004873 | N15: 45961 | P15: 45975
B16: 4 | C16: Practical Completion | E16: 0.1 | F16: =$D$4*E16 -> 207743.63 | H16: ='Project Plan'!G39+7 -> 45996 | L16: 004873 | N16: 45961 | P16: ='Project Plan'!K39+7 -> 46002
B17: 5 | C17: Handover | E17: 0.05 | F17: =$D$4*E17 -> 103871.81 | H17: ='Project Plan'!E50+7 -> 46000 | L17: 004873 | N17: 45961 | P17: 46002
B18: 6 | C18: - | E18: 0 | F18: =$D$4*E18 -> 0
B19: 7 | C19: - | E19: 0 | F19: =$D$4*E19 -> 0
E21: =SUM(E13:E19) -> 1 | F21: =SUM(F13:F19) -> 2077436.3
B23: KEY: | C23: contains an error (in result or a check has failed)
C24: Red Font - IF TEXT : content not yet confirmed
C25: Red Font - IF NUMBER: Negative value
C26: Anything in yellow is a concern or risk for noting or action
C27: confirmed
C28: [ADD INITIALS: comment for noting in square brackets, use colour or red to draw attention if important]
C29: [RT: When adding rows into sheet, ensure you insert between first and last row of each category]
C30: end of sheet - do not insert information below/beyond this
B40: No. | C40: PAYMENT MILESTONE | E40: % | F40: VALUE
B41: 1 | C41: Deposit - Project commencement | E41: 0.35 | F41: =$F$47*E41 -> 727102.7
B42: 2 | C42: Delivery of Panels | E42: 0.3 | F42: =$F$47*E42 -> 623230.88
B43: 3 | C43: Delivery of Inverters | E43: 0.2 | F43: =$F$47*E43 -> 415487.26
B44: 4 | C44: Practical Completion | E44: 0.1 | F44: =$F$47*E44 -> 207743.63
B45: 5 | C45: Handover | E45: 0.05 | F45: =$F$47*E45 -> 103871.81
C46: Total | E46: =SUM(E41:E45) -> 1 | F46: =SUM(F41:F45) -> 2077436.3
E47: =SUM(E41:E45) -> 1 | F47: =F21 -> 2077436.3

Sheet Expenditure Tracking
B2: HIGH LEVEL PROJECT EXPENDITURE TRACKING
F4: COSTED | H4: ACTUAL | J4: Difference from Costed
B5: EXPENDITURE | F5: =SUM(F9:F23) -> 1702430.3 | H5: =SUM(H9:H23) -> 1502144.2 | J5: =SUM(J9:J23) -> 200286.14
B7: No. | D7: Item | F7: Costed Expenditure | H7: Actual Expenditure | J7: Saving / Overrun | L7: Comments on variations from planned expenditure
B9: ='Expenditure Breakdown'!L6 -> 1 | D9: ='Expenditure Breakdown'!M6 -> 1. Panels | F9: ='Expenditure Breakdown'!I6 -> 556966.5 | H9: ='Expenditure Breakdown'!X6 -> 506043.6 | J9: =F9-H9 -> 50922.9
B10: ='Expenditure Breakdown'!L13 -> 2 | D10: ='Expenditure Breakdown'!M13 -> 2. Inverters | F10: ='Expenditure Breakdown'!I13 -> 140000 | H10: ='Expenditure Breakdown'!X13 -> 137740.7 | J10: =F10-H10 -> 2259.3
B11: ='Expenditure Breakdown'!L21 -> 3 | D11: ='Expenditure Breakdown'!M21 -> 3. Mounting Structures | F11: ='Expenditure Breakdown'!I21 -> 112716 | H11: ='Expenditure Breakdown'!X21 -> 78119 | J11: =F11-H11 -> 34597
B12: ='Expenditure Breakdown'!L29 -> 4 | D12: ='Expenditure Breakdown'!M29 -> 4. DC Equipment | F12: ='Expenditure Breakdown'!I29 -> 207033.9 | H12: ='Expenditure Breakdown'!X29 -> 93178.37 | J12: =F12-H12 -> 113855.53
B13: ='Expenditure Breakdown'!L46 -> 5 | D13: ='Expenditure Breakdown'!M46 -> 5. Monitoring | F13: ='Expenditure Breakdown'!I46 -> 49000 | H13: ='Expenditure Breakdown'!X46 -> 59038.01 | J13: =F13-H13 -> -10038.01
B14: ='Expenditure Breakdown'!L56 -> 6 | D14: ='Expenditure Breakdown'!M56 -> 6. AC Equipment | F14: ='Expenditure Breakdown'!I56 -> 268570.82 | H14: ='Expenditure Breakdown'!X56 -> 121280.62 | J14: =F14-H14 -> 147290.2
B15: ='Expenditure Breakdown'!L75 -> 7 | D15: ='Expenditure Breakdown'!M75 -> 7.BESS | F15: ='Expenditure Breakdown'!I75 -> 0 | H15: ='Expenditure Breakdown'!X75 -> 0 | J15: =F15-H15 -> 0
B16: ='Expenditure Breakdown'!L84 -> 8 | D16: ='Expenditure Breakdown'!M84 -> 8. Product Add On | F16: ='Expenditure Breakdown'!I84 -> 0 | H16: ='Expenditure Breakdown'!X84 -> 26057.31 | J16: =F16-H16 -> -26057.31
B17: ='Expenditure Breakdown'!L94 -> 9 | D17: ='Expenditure Breakdown'!M94 -> 9. AC & DC installation | F17: ='Expenditure Breakdown'!I94 -> 196950 | H17: ='Expenditure Breakdown'!X94 -> 311148.25 | J17: =F17-H17 -> -114198.25
B18: ='Expenditure Breakdown'!L108 -> 10 | D18: ='Expenditure Breakdown'!M108 -> 10. Site Logistics | F18: ='Expenditure Breakdown'!I108 -> 56854.45 | H18: ='Expenditure Breakdown'!X108 -> 109850.74 | J18: =F18-H18 -> -52996.29
B19: ='Expenditure Breakdown'!L125 -> 11 | D19: ='Expenditure Breakdown'!M125 -> 11. Due Dilligence | F19: ='Expenditure Breakdown'!I125 -> 89000 | H19: ='Expenditure Breakdown'!X125 -> 21375 | J19: =F19-H19 -> 67625
B20: ='Expenditure Breakdown'!L131 -> 12 | D20: ='Expenditure Breakdown'!M131 -> 12. BDP Commission | F20: ='Expenditure Breakdown'!I131 -> 0 | H20: ='Expenditure Breakdown'!X131 -> 0 | J20: =F20-H20 -> 0
B21: ='Expenditure Breakdown'!L134 -> 13 | D21: ='Expenditure Breakdown'!M135 -> 13. Engineering | F21: ='Expenditure Breakdown'!I134 -> 20963.65 | H21: ='Expenditure Breakdown'!X134 -> 25967.954 | J21: =F21-H21 -> -5004.3035
B22: ='Expenditure Breakdown'!L141 -> 14 | D22: ='Expenditure Breakdown'!M141 -> 14. General Expenses | F22: ='Expenditure Breakdown'!I141 -> 4375 | H22: ='Expenditure Breakdown'!X141 -> 4844.63 | J22: =F22-H22 -> -469.63
B23: ='Expenditure Breakdown'!L154 -> 15 | D23: ='Expenditure Breakdown'!M154 -> 15. Service Add On | F23: ='Expenditure Breakdown'!I154 -> 0 | H23: ='Expenditure Breakdown'!X154 -> 7500 | J23: =F23-H23 -> -7500
D25: check: | F25: ='Expenditure Breakdown'!I2-'Expenditure Tracking'!F5 -> 0 | G25: =#REF!-G5 -> #REF! | H25: ='Expenditure Breakdown'!X2-H5 -> 0

Sheet Expenditure Breakdown
B2: COSTED EXPENDITURE BREAKDOWN | I2: =SUM(I6:I166) -> 1702430.3 | J2: =SUM(J6:J166) -> 2077436 | L2: ACTUAL EXPENDITURE BREAKDOWN | R2: FINANCE ONLY | X2: =SUM(X6:X166) -> 1502144.2
B4: No. | C4: Product / Service | D4: Description of Work | E4: QTY | F4: Rate / Unit | G4: Budget Total | H4: FORECASTED PAYMENT DATE | I4: Total COS | J4: =IF(J2-'Revenue Tracking'!D4>=0, "Total Revenue", "ERROR on REV" ) -> ERROR on REV | L4: No. | M4: Product/ Service | N4: Description of Work | O4: QTY | P4: Rate / Unit | Q4: Actual Total | R4: PO NUMBER | S4: INVOICE NUMBER | T4: INVOICE RAISED DATE | U4: REVENUE RECOGNITION AMOUNT | V4: CHECK | W4: FINANCE PAYMENT DATE | X4: Total COS
B6: 1 | C6: Panels | D6: Panels Budget | G6: =D167 -> 556966.5 | H6: ='Project Plan'!E36+60 -> 46028 | I6: =SUM(G6:G11) -> 556966.5 | J6: =F167 -> 696208 | L6: 1 | M6: 1. Panels | N6: JA Solar 600W (Menlo) | O6: 360 | P6: 1200 | Q6: =O6*P6 -> 432000 | S6: Menlo - INV0003417 | T6: 45991 | U6: 594339.81 | V6: =J6-SUM(U6:U11) -> 0 | W6: 46037 | X6: =SUM(Q6:Q11) -> 506043.6
B7: 1 | D7: Delivery Budget | L7: 1 | M7: 1. Panels | N7: JA Solar 600W (Menlo) | O7: 57 | P7: 1200 | Q7: =O7*P7 -> 68400 | S7: Menlo - INV0003407 | T7: 45991 | U7: 94103.803 | W7: 46037
B8: 1 | L8: 1 | M8: 1. Panels | N8: QC4 Connectors | Q8: 3143.6 | S8: MSA Energy INV0003456 | T8: 45991 | U8: 4324.9227 | W8: 46045
B9: 1 | L9: 1 | M9: 1. Panels | T9: =IF(W9>1,EOMONTH(W9,0),"") | U9: 0
B10: 1 | L10: 1 | M10: 1. Panels | N10: Module transport | Q10: 2500 | S10: MSA Energy INV0003436 | T10: 45991 | U10: 3439.4665 | W10: 46045
B11: 1 | L11: 1 | M11: 1. Panels | T11: =IF(W11>1,EOMONTH(W11,0),"") | U11: =(Q11/$X$6*$J$6) -> 0 | Y11: BUDGET | Z11: Installer Allocation
T12: =IF(W12>1,EOMONTH(W12,0),"") | Y12: AC Equipment | Z12: =G56 -> 268570.82
B13: 2 | C13: Inverters | D13: Inverter Budget | G13: =D168 -> 140000 | H13: ='Project Plan'!E22+60 -> 46029 | I13: =SUM(G13:G19) -> 140000 | J13: =F168 -> 175000 | L13: 2 | M13: 2. Inverters | N13: Huawei 100KTL Menlo | O13: 2 | P13: 68870.35 | Q13: =O13*P13 -> 137740.7 | S13: Menlo - INV0003407 | T13: 45991 | U13: 175000 | V13: =J13-SUM(U13:U19) -> 0 | W13: 46050 | X13: =SUM(Q13:Q19) -> 137740.7 | Y13: DC Equipment | Z13: =G30 -> 127723.9
B14: 2 | L14: 2 | M14: 2. Inverters | T14: =IF(W14>1,EOMONTH(W14,0),"") | U14: =(Q14/$X$13*$J$13) -> 0 | Y14: AC Labour | Z14: =G94 -> 62620
B15: 2 | L15: 2 | M15: 2. Inverters | T15: =IF(W15>1,EOMONTH(W15,0),"") | U15: =(Q15/$X$13*$J$13) -> 0 | Y15: DC Labour | Z15: =G95 -> 134330
B16: 2 | L16: 2 | M16: 2. Inverters | T16: =IF(W16>1,EOMONTH(W16,0),"") | U16: =(Q16/$X$13*$J$13) -> 0 | Y16: Offloading | Z16: =G108 -> 8500
B17: 2 | L17: 2 | M17: 2. Inverters | T17: =IF(W17>1,EOMONTH(W17,0),"") | U17: =(Q17/$X$13*$J$13) -> 0 | Y17: Scaffolding | Z17: =G109 -> 17326.67
B18: 2 | L18: 2 | M18: 2. Inverters | T18: =IF(W18>1,EOMONTH(W18,0),"") | U18: =(Q18/$X$13*$J$13) -> 0 | Y18: Storage | Z18: =G111 -> 1027.78
B19: 2 | L19: 2 | M19: 2. Inverters | T19: =IF(W19>1,EOMONTH(W19,0),"") | U19: =(Q19/$X$13*$J$13) -> 0 | Y19: Telehandler | Z19: 0
T20: =IF(W20>1,EOMONTH(W20,0),"")
B21: 3 | C21: Mounting Structures | D21: Structure Budget | G21: =D169 -> 112716 | H21: ='Project Plan'!E30+30 -> 45998 | I21: =SUM(G21:G27) -> 112716 | J21: =F169 -> 140895 | L21: 3 | M21: 3. Mounting Structures | N21: Schletter Structure | V21: =J21-SUM(U21:U27) -> 12784.223 | X21: =SUM(Q21:Q27) -> 78119 | Y21: Other | Z21: 0
B22: 3 | L22: 3 | M22: 3. Mounting Structures | N22: Schletter Structure | Q22: 76171 | R22: PO4423-RRB-20251030 - RV Approved | S22: Schletter - INV2381 | T22: 45991 | U22: 124985.3 | W22: 46021 | Y22: Total | Z22: =SUM(Z12:Z21) -> 620099.17
B23: 3 | L23: 3 | M23: 3. Mounting Structures | T23: =IF(W23>1,EOMONTH(W23,0),"") | U23: =(Q23/$X$21*$J$21) -> 0 | Y23: Less 15% | Z23: =+Z22*0.85 -> 527084.29
B24: 3 | L24: 3 | M24: 3. Mounting Structures | N24: Additional nuts and bolts | Q24: 1948 | R24: PO4455-RRB-20251110 - RV Approved | S24: Schletter - INV2403 | T24: 45991 | U24: 3125.4736 | W24: =T24+30 -> 46021 | Y24: R/Wp | Z24: =Z23/'Project Plan'!$E$3/1000 -> 2.1083372
B25: 3 | L25: 3 | M25: 3. Mounting Structures | T25: =IF(W25>1,EOMONTH(W25,0),"") | U25: =(Q25/$X$21*$J$21) -> 0
B26: 3 | L26: 3 | M26: 3. Mounting Structures | U26: =(Q26/$X$21*$J$21) -> 0 | Y26: Jasolar | AC26: Revised
B27: 3 | L27: 3 | M27: 3. Mounting Structures | T27: =IF(W27>1,EOMONTH(W27,0),"") | U27: =(Q27/$X$21*$J$21) -> 0 | Y27: ACTUAL | Z27: Installer Price | AC27: ACTUAL | AD27: Installer Price
T28: =IF(W28>1,EOMONTH(W28,0),"") | Y28: =Y12 -> AC Equipment | Z28: 41164.9 | AC28: AC Equipment | AD28: 41164.9
B29: 4 | C29: DC Equipment | D29: DC Cable Budget | E29: =G29/14*1.15 -> 6514.75 | G29: 79310 | H29: ='Project Plan'!E32+60 -> 46028 | I29: =SUM(G29:G44) -> 207033.9 | J29: =F170 -> 258792 | L29: 4 | M29: 4. DC Equipment | N29: DC Cable | O29: 6000 | P29: 13.65 | Q29: =O29*P29 -> 81900 | S29: Menlo - INV0003407 | T29: 45991 | U29: 143405.59 | V29: =J29-SUM(U29:U44) -> 0.072109651 | W29: 46037 | X29: =SUM(Q29:Q44) -> 93178.37 | Y29: =Y13 -> DC Equipment | Z29: 42673.4 | AC29: DC Equipment | AD29: 42673.4
B30: 4 | D30: DC Equipment Budget | G30: =D170-G29 -> 127723.9 | H30: ='Project Plan'!G28 -> 45980 | L30: 4 | M30: 4. DC Equipment | N30: DC Cable - Black | O30: -1000 | P30: 13.65 | Q30: =O30*P30 -> -13650 | S30: Alllocated to Cpt Storeroom | T30: 46022 | U30: 0 | W30: 46022 | Y30: =Y14 -> AC Labour | Z30: 44112.61 | AA30: =Z30/'Project Plan'!$E$3/1000 -> 0.17645044 | AC30: AC Labour | AD30: 44112.61
B31: 4 | L31: 4 | M31: 4. DC Equipment | N31: DC Cable - Red | O31: -1300 | P31: 13.65 | Q31: =O31*P31 -> -17745 | S31: Alllocated to Cpt Storeroom | T31: 46022 | U31: 0 | W31: 46022 | Y31: =Y15 -> DC Labour | Z31: 267035.64 | AA31: =Z31/'Project Plan'!$E$3/1000 -> 1.0681426 | AC31: DC Labour | AD31: 267035.64
B32: 4 | L32: 4 | M32: 4. DC Equipment | T32: =IF(W32>1,EOMONTH(W32,0),"") | U32: =(Q32/$X$29*$J$29) -> 0 | Y32: Offloading | Z32: 11410 | AC32: Offloading | AD32: 11410
B33: 4 | L33: 4 | M33: 4. DC Equipment | N33: Project Kick Off | O33: =Z29 -> 42673.4 | P33: 0.1 | Q33: =$O$33*P33 -> 4267.34 | R33: PO4381-RRB-20251017 - RV Approved | S33: JA Electrical: Inv 1110 | T33: 45961 | U33: 8718.1165 | W33: =W95 -> 45967 | Y33: Geda/scaffholding | Z33: 23642.5 | AC33: Geda/scaffholding | AD33: 23642.5
B34: 4 | L34: 4 | M34: 4. DC Equipment | N34: Site Establishment | P34: 0.15 | Q34: =$O$33*P34 -> 6401.01 | S34: JA Electrical: Inv 1120 | T34: 45991 | U34: 17778.049 | W34: =W96 -> 45989 | Y34: Geda | AC34: Geda
B35: 4 | L35: 4 | M35: 4. DC Equipment | N35: AC Installation Complete | P35: 0.2 | Q35: =$O$33*P35 -> 8534.68 | S35: JA Electrical: Inv 1123 | T35: =T97 -> 45991 | U35: 23704.066 | W35: =W97 -> 45989 | Y35: Storage | Z35: 35837.75 | AC35: Storage | AD35: 35837.75
B36: 4 | L36: 4 | M36: 4. DC Equipment | N36: DC Installation Complete - Partial | P36: 0.2 | Q36: =$O$33*P36 -> 8534.68 | S36: JA Electrical: Inv 1123 | T36: =T98 -> 45991 | U36: 23704.066 | W36: =W98 -> 45989 | Y36: P&G's | Z36: 14117.5 | AC36: P&G's | AD36: =10637.5+3480 -> 14117.5
L37: 4 | M37: 4. DC Equipment | N37: DC Installation Complete - Partial | P37: 0.05 | Q37: 2133.64 | S37: JA Electrical: Inv 1152 | T37: =T99 -> 46053 | U37: =(Q37/$X$29*$J$29) -> 5925.935 | W37: =W99 -> 46053
B38: 4 | L38: 4 | M38: 4. DC Equipment | N38: Commissioning Complete | P38: 0.1 | Q38: =$O$33*P38 -> 4267.34 | S38: JA Electrical: Inv 1152 | T38: =T100 -> 46053 | U38: =(Q38/$X$29*$J$29) -> 11852.037 | W38: =W100 -> 46058 | Y38: Shuffle Boards | Z38: 17693 | AC38: Shuffle Boards | AD38: 17693
B39: 4 | L39: 4 | M39: 4. DC Equipment | N39: Site De-establisment | P39: 0.1 | Q39: =$O$33*P39 -> 4267.34 | S39: JA Electrical: Inv 1152 | T39: =T101 -> 46053 | U39: =(Q39/$X$29*$J$29) -> 11852.037 | W39: =W101 -> 46065 | Y39: Other | Z39: 0 | AC39: Other
B40: 4 | L40: 4 | M40: 4. DC Equipment | N40: Handover Document Complete | P40: 0.05 | Q40: =$O$33*P40 -> 2133.67 | S40: JA Electrical Inv 1153 | T40: =T102 -> 46053 | U40: =(Q40/$X$29*$J$29) -> 5926.0183 | W40: =W102 -> 46065 | Y40: Total | Z40: =SUM(Z28:Z39) -> 497687.3 | AC40: Total | AD40: =SUM(AD28:AD39) -> 497687.3
B41: 4 | L41: 4 | M41: 4. DC Equipment | N41: End of Defects Period | P41: 0.05 | Q41: =$O$33*P41 -> 2133.67 | S41: JA Electrical Inv 1153 | T41: =T103 -> 46053 | U41: =(Q41/$X$29*$J$29) -> 5926.0183 | W41: =W103 -> 46095 | Y41: R/Wp | Z41: =Z40/'Project Plan'!$E$3/1000 -> 1.9907492 | AC41: R/Wp | AD41: =AD40/'Project Plan'!E3/1000 -> 1.9907492
B42: 4 | L42: 4 | M42: 4. DC Equipment | T42: =IF(W42>1,EOMONTH(W42,0),"") | U42: =(Q42/$X$29*$J$29) -> 0
B43: 4 | L43: 4 | M43: 4. DC Equipment | T43: =IF(W43>1,EOMONTH(W43,0),"") | U43: =(Q43/$X$29*$J$29) -> 0
...

Sheet Cashflow
D1: [RT: Double Check the first date is always a MONDAY] | F1: 45901 | G1: =F1+7 -> 45908 | H1: =G1+7 -> 45915 | I1: =H1+7 -> 45922 | J1: =I1+7 -> 45929 | K1: =J1+7 -> 45936 | L1: =K1+7 -> 45943 | M1: =L1+7 -> 45950 | N1: =M1+7 -> 45957 | ... KF1: =KE1+7 -> 47903
A2: PLANNED | C2: CHECK | D2: CHECK
B3: Planned Revenue | C3: ='Revenue Tracking'!D4 -> 2077436.3 | D3: =SUM(F3:KF3) -> 2077436.3 | F3: =SUMIFS('Revenue Tracking'!$F$13:$F$19, 'Revenue Tracking'!$H$13:$H$19, ">="&F1,'Revenue Tracking'!$H$13:$H$19, "<"&G1) -> 0 | G3: =SUMIFS('Revenue Tracking'!$F$13:$F$19, 'Revenue Tracking'!$H$13:$H$19, ">="&G1,'Revenue Tracking'!$H$13:$H$19, "<"&H1) -> 1038718.1 | H3: =SUMIFS('Revenue Tracking'!$F$13:$F$19, 'Revenue Tracking'!$H$13:$H$19, ">="&H1,'Revenue Tracking'!$H$13:$H$19, "<"&I1) -> 0 | I3: =SUMIFS('Revenue Tracking'!$F$13:$F$19, 'Revenue Tracking'!$H$13:$H$19, ">="&I1,'Revenue Tracking'!$H$13:$H$19, "<"&J1) -> 0 | J3: =SUMIFS('Revenue Tracking'!$F$13:$F$19, 'Revenue Tracking'!$H$13:$H$19, ">="&J1,'Revenue Tracking'!$H$13:$H$19, "<"&K1) -> 0 | K3: =SUMIFS('Revenue Tracking'!$F$13:$F$19, 'Revenue Tracking'!$H$13:$H$19, ">="&K1,'Revenue Tracking'!$H$13:$H$19, "<"&L1) -> 0 | L3: =SUMIFS('Revenue Tracking'!$F$13:$F$19, 'Revenue Tracking'!$H$13:$H$19, ">="&L1,'Revenue Tracking'!$H$13:$H$19, "<"&M1) -> 0 | M3: =SUMIFS('Revenue Tracking'!$F$13:$F$19, 'Revenue Tracking'!$H$13:$H$19, ">="&M1,'Revenue Tracking'!$H$13:$H$19, "<"&N1) -> 0 | ... KE3: =SUMIFS('Revenue Tracking'!$F$13:$F$19, 'Revenue Tracking'!$H$13:$H$19, ">="&KE1,'Revenue Tracking'!$H$13:$H$19, "<"&KF1) -> 0 | KF3: =SUMIFS('Revenue Tracking'!$F$13:$F$19, 'Revenue Tracking'!$H$13:$H$19, ">="&KF1,'Revenue Tracking'!$H$13:$H$19, "<"&#REF!) -> 0
B4: Planned Revenue - Cumulative | F4: =F3 -> 0 | G4: =F4+G3 -> 1038718.1 | H4: =G4+H3 -> 1038718.1 | I4: =H4+I3 -> 1038718.1 | J4: =I4+J3 -> 1038718.1 | K4: =J4+K3 -> 1038718.1 | L4: =K4+L3 -> 1038718.1 | M4: =L4+M3 -> 1038718.1 | N4: =M4+N3 -> 1038718.1 | ... KF4: =KE4+KF3 -> 2077436.3
B5: Planned Expenditure | C5: ='Revenue Tracking'!D5 -> 1702430.3 | D5: =SUM(F5:KF5) -> 1702430.3 | F5: =SUMIFS('Expenditure Breakdown'!$G$6:$G$173, 'Expenditure Breakdown'!$H$6:$H$173, ">="&F1,'Expenditure Breakdown'!$H$6:$H$173, "<"&G1) -> 0 | G5: =SUMIFS('Expenditure Breakdown'!$G$6:$G$173, 'Expenditure Breakdown'!$H$6:$H$173, ">="&G1,'Expenditure Breakdown'!$H$6:$H$173, "<"&H1) -> 0 | H5: =SUMIFS('Expenditure Breakdown'!$G$6:$G$173, 'Expenditure Breakdown'!$H$6:$H$173, ">="&H1,'Expenditure Breakdown'!$H$6:$H$173, "<"&I1) -> 0 | I5: =SUMIFS('Expenditure Breakdown'!$G$6:$G$173, 'Expenditure Breakdown'!$H$6:$H$173, ">="&I1,'Expenditure Breakdown'!$H$6:$H$173, "<"&J1) -> 0 | J5: =SUMIFS('Expenditure Breakdown'!$G$6:$G$173, 'Expenditure Breakdown'!$H$6:$H$173, ">="&J1,'Expenditure Breakdown'!$H$6:$H$173, "<"&K1) -> 0 | K5: =SUMIFS('Expenditure Breakdown'!$G$6:$G$173, 'Expenditure Breakdown'!$H$6:$H$173, ">="&K1,'Expenditure Breakdown'!$H$6:$H$173, "<"&L1) -> 0 | L5: =SUMIFS('Expenditure Breakdown'!$G$6:$G$173, 'Expenditure Breakdown'!$H$6:$H$173, ">="&L1,'Expenditure Breakdown'!$H$6:$H$173, "<"&M1) -> 0 | M5: =SUMIFS('Expenditure Breakdown'!$G$6:$G$173, 'Expenditure Breakdown'!$H$6:$H$173, ">="&M1,'Expenditure Breakdown'!$H$6:$H$173, "<"&N1) -> 0 | ... KE5: =SUMIFS('Expenditure Breakdown'!$G$6:$G$173, 'Expenditure Breakdown'!$H$6:$H$173, ">="&KE1,'Expenditure Breakdown'!$H$6:$H$173, "<"&KF1) -> 0 | KF5: =SUMIFS('Expenditure Breakdown'!$G$6:$G$173, 'Expenditure Breakdown'!$H$6:$H$173, ">="&KF1,'Expenditure Breakdown'!$H$6:$H$173, "<"&#REF!) -> 0
B6: Planned Expenditure - Cumulative | F6: =F5 -> 0 | G6: =F6+G5 -> 0 | H6: =G6+H5 -> 0 | I6: =H6+I5 -> 0 | J6: =I6+J5 -> 0 | K6: =J6+K5 -> 0 | L6: =K6+L5 -> 0 | M6: =L6+M5 -> 0 | N6: =M6+N5 -> 0 | ... KF6: =KE6+KF5 -> 1702430.3
B7: PLANNED CashFlow | F7: =F4-F6 -> 0 | G7: =G4-G6 -> 1038718.1 | H7: =H4-H6 -> 1038718.1 | I7: =I4-I6 -> 1038718.1 | J7: =J4-J6 -> 1038718.1 | K7: =K4-K6 -> 1038718.1 | L7: =L4-L6 -> 1038718.1 | M7: =M4-M6 -> 1038718.1 | ... KF7: =KF4-KF6 -> 375005.96
A8: ACTUAL | C8: CHECK | D8: CHECK
B9: Actual + Planned Revenue | C9: ='Revenue Tracking'!F4 -> 2077436.3 | D9: =SUM(F9:KF9) -> 2077436.3 | F9: =SUMIFS('Revenue Tracking'!$F$13:$F$19, 'Revenue Tracking'!$P$13:$P$19, ">="&F1,'Revenue Tracking'!$P$13:$P$19, "<"&G1) -> 0 | G9: =SUMIFS('Revenue Tracking'!$F$13:$F$19, 'Revenue Tracking'!$P$13:$P$19, ">="&G1,'Revenue Tracking'!$P$13:$P$19, "<"&H1) -> 0 | H9: =SUMIFS('Revenue Tracking'!$F$13:$F$19, 'Revenue Tracking'!$P$13:$P$19, ">="&H1,'Revenue Tracking'!$P$13:$P$19, "<"&I1) -> 0 | I9: =SUMIFS('Revenue Tracking'!$F$13:$F$19, 'Revenue Tracking'!$P$13:$P$19, ">="&I1,'Revenue Tracking'!$P$13:$P$19, "<"&J1) -> 0 | J9: =SUMIFS('Revenue Tracking'!$F$13:$F$19, 'Revenue Tracking'!$P$13:$P$19, ">="&J1,'Revenue Tracking'!$P$13:$P$19, "<"&K1) -> 0 | K9: =SUMIFS('Revenue Tracking'!$F$13:$F$19, 'Revenue Tracking'!$P$13:$P$19, ">="&K1,'Revenue Tracking'!$P$13:$P$19, "<"&L1) -> 0 | L9: =SUMIFS('Revenue Tracking'!$F$13:$F$19, 'Revenue Tracking'!$P$13:$P$19, ">="&L1,'Revenue Tracking'!$P$13:$P$19, "<"&M1) -> 0 | M9: =SUMIFS('Revenue Tracking'!$F$13:$F$19, 'Revenue Tracking'!$P$13:$P$19, ">="&M1,'Revenue Tracking'!$P$13:$P$19, "<"&N1) -> 0 | ... KE9: =SUMIFS('Revenue Tracking'!$F$13:$F$19, 'Revenue Tracking'!$P$13:$P$19, ">="&KE1,'Revenue Tracking'!$P$13:$P$19, "<"&KF1) -> 0 | KF9: =SUMIFS('Revenue Tracking'!$F$13:$F$19, 'Revenue Tracking'!$P$13:$P$19, ">="&KF1,'Revenue Tracking'!$P$13:$P$19, "<"&#REF!) -> 0
B10: Actual + Planned Revenue - Cumulative | F10: =F9 -> 0 | G10: =F10+G9 -> 0 | H10: =G10+H9 -> 0 | I10: =H10+I9 -> 0 | J10: =I10+J9 -> 0 | K10: =J10+K9 -> 0 | L10: =K10+L9 -> 0 | M10: =L10+M9 -> 0 | N10: =M10+N9 -> 0 | ... KF10: =KE10+KF9 -> 2077436.3
B11: Actual + Planned Expenditure | C11: ='Revenue Tracking'!F5 -> 1502144.2 | D11: =SUM(F11:KF11) -> 1446769.1 | F11: =SUMIFS('Expenditure Breakdown'!$Q$6:$Q$173, 'Expenditure Breakdown'!$W$6:$W$173, ">="&F1,'Expenditure Breakdown'!$W$6:$W$173, "<"&G1) -> 0 | G11: =SUMIFS('Expenditure Breakdown'!$Q$6:$Q$173, 'Expenditure Breakdown'!$W$6:$W$173, ">="&G1,'Expenditure Breakdown'!$W$6:$W$173, "<"&H1) -> 0 | H11: =SUMIFS('Expenditure Breakdown'!$Q$6:$Q$173, 'Expenditure Breakdown'!$W$6:$W$173, ">="&H1,'Expenditure Breakdown'!$W$6:$W$173, "<"&I1) -> 0 | I11: =SUMIFS('Expenditure Breakdown'!$Q$6:$Q$173, 'Expenditure Breakdown'!$W$6:$W$173, ">="&I1,'Expenditure Breakdown'!$W$6:$W$173, "<"&J1) -> 0 | J11: =SUMIFS('Expenditure Breakdown'!$Q$6:$Q$173, 'Expenditure Breakdown'!$W$6:$W$173, ">="&J1,'Expenditure Breakdown'!$W$6:$W$173, "<"&K1) -> 0 | K11: =SUMIFS('Expenditure Breakdown'!$Q$6:$Q$173, 'Expenditure Breakdown'!$W$6:$W$173, ">="&K1,'Expenditure Breakdown'!$W$6:$W$173, "<"&L1) -> 975 | L11: =SUMIFS('Expenditure Breakdown'!$Q$6:$Q$173, 'Expenditure Breakdown'!$W$6:$W$173, ">="&L1,'Expenditure Breakdown'!$W$6:$W$173, "<"&M1) -> 0 | M11: =SUMIFS('Expenditure Breakdown'!$Q$6:$Q$173, 'Expenditure Breakdown'!$W$6:$W$173, ">="&M1,'Expenditure Breakdown'!$W$6:$W$173, "<"&N1) -> 0 | ... KE11: =SUMIFS('Expenditure Breakdown'!$Q$6:$Q$173, 'Expenditure Breakdown'!$W$6:$W$173, ">="&KE1,'Expenditure Breakdown'!$W$6:$W$173, "<"&KF1) -> 0 | KF11: =SUMIFS('Expenditure Breakdown'!$Q$6:$Q$173, 'Expenditure Breakdown'!$W$6:$W$173, ">="&KF1,'Expenditure Breakdown'!$W$6:$W$173, "<"&#REF!) -> 0
B12: Actual + Planned Expenditure - Cumulative | F12: =F11 -> 0 | G12: =F12+G11 -> 0 | H12: =G12+H11 -> 0 | I12: =H12+I11 -> 0 | J12: =I12+J11 -> 0 | K12: =J12+K11 -> 975 | L12: =K12+L11 -> 975 | M12: =L12+M11 -> 975 | N12: =M12+N11 -> 975 | ... KF12: =KE12+KF11 -> 1446769.1
B14: ACTUAL CashFlow | F14: =F10-F12 -> 0 | G14: =G10-G12 -> 0 | H14: =H10-H12 -> 0 | I14: =I10-I12 -> 0 | J14: =J10-J12 -> 0 | K14: =K10-K12 -> -975 | L14: =L10-L12 -> -975 | M14: =M10-M12 -> -975 | ... KF14: =KF10-KF12 -> 630667.18
C16: CHECK | D16: CHECK
B17: Revenue Recognition | C17: =C3-D17 -> 12784.584 | D17: =SUM(F17:KF17) -> 2064651.7 | F17: =SUMIFS('Expenditure Breakdown'!$U$6:$U$173, 'Expenditure Breakdown'!$T$6:$T$173, ">="&F1,'Expenditure Breakdown'!$T$6:$T$173, "<"&G1) -> 0 | G17: =SUMIFS('Expenditure Breakdown'!$U$6:$U$173, 'Expenditure Breakdown'!$T$6:$T$173, ">="&G1,'Expenditure Breakdown'!$T$6:$T$173, "<"&H1) -> 0 | H17: =SUMIFS('Expenditure Breakdown'!$U$6:$U$173, 'Expenditure Breakdown'!$T$6:$T$173, ">="&H1,'Expenditure Breakdown'!$T$6:$T$173, "<"&I1) -> 0 | I17: =SUMIFS('Expenditure Breakdown'!$U$6:$U$173, 'Expenditure Breakdown'!$T$6:$T$173, ">="&I1,'Expenditure Breakdown'!$T$6:$T$173, "<"&J1) -> 0 | J17: =SUMIFS('Expenditure Breakdown'!$U$6:$U$173, 'Expenditure Breakdown'!$T$6:$T$173, ">="&J1,'Expenditure Breakdown'!$T$6:$T$173, "<"&K1) -> 0 | K17: =SUMIFS('Expenditure Breakdown'!$U$6:$U$173, 'Expenditure Breakdown'!$T$6:$T$173, ">="&K1,'Expenditure Breakdown'!$T$6:$T$173, "<"&L1) -> 0 | L17: =SUMIFS('Expenditure Breakdown'!$U$6:$U$173, 'Expenditure Breakdown'!$T$6:$T$173, ">="&L1,'Expenditure Breakdown'!$T$6:$T$173, "<"&M1) -> 0 | M17: =SUMIFS('Expenditure Breakdown'!$U$6:$U$173, 'Expenditure Breakdown'!$T$6:$T$173, ">="&M1,'Expenditure Breakdown'!$T$6:$T$173, "<"&N1) -> 0 | ... KE17: =SUMIFS('Expenditure Breakdown'!$U$6:$U$173, 'Expenditure Breakdown'!$T$6:$T$173, ">="&KE1,'Expenditure Breakdown'!$T$6:$T$173, "<"&KF1) -> 0 | KF17: =SUMIFS('Expenditure Breakdown'!$U$6:$U$173, 'Expenditure Breakdown'!$T$6:$T$173, ">="&KF1,'Expenditure Breakdown'!$T$6:$T$173, "<"&#REF!) -> 0
B18: Revenue Recognition Cumulative | C18: =D17-D18 -> 0 | D18: =MAX(F18:KF18) -> 2064651.7 | F18: =F17 -> 0 | G18: =F18+G17 -> 0 | H18: =G18+H17 -> 0 | I18: =H18+I17 -> 0 | J18: =I18+J17 -> 0 | K18: =J18+K17 -> 0 | L18: =K18+L17 -> 0 | M18: =L18+M17 -> 0 | N18: =M18+N17 -> 100416.31 | ... KF18: =KE18+KF17 -> 2064651.7

Sheet Finance - Revenue
A3: Sum of REVENUE RECOGNITION AMOUNT | B3: Column Labels
A4: Row Labels | B4: (blank) | C4: 45961 | D4: 45991 | E4: 46022 | G4: 46053 | H4: Grand Total
A5: (blank)
A6: 1. Panels | D6: 696208 | F6: 0 | H6: 696208
A7: 2. Inverters | D7: 175000 | F7: 0 | H7: 175000
A8: 3. Mounting Structures | B8: 0 | D8: 128110.78 | F8: 0 | G8: 12784.222 | H8: 140895
A9: 4. DC Equipment | C9: 8718.1165 | D9: 208591.77 | E9: 0 | F9: 0 | G9: 41482.115 | H9: 258792
A10: 5. Monitoring | C10: 52102.936 | D10: 9147.0598 | F10: 0 | H10: 61249.996
A11: 6. AC Equipment | C11: 11394.758 | D11: 284437.59 | F11: 0 | G11: 39881.653 | H11: 335714
A12: 8. Product Add On
A13: 9. AC & DC installation | B13: 0 | C13: 21883.4 | D13: 120358.7 | F13: 0 | G13: 76591.9 | H13: 218834
A14: 10. Site Logistics | C14: 6317.1 | D14: 32482.618 | E14: 3700.52 | F14: 0 | G14: 20670.757 | H14: 63170.996
A15: 11. Due Dilligence | B15: 0 | F15: 0 | G15: 98889 | H15: 98889
A16: 13. Engineering | B16: 0 | G16: 23822 | H16: 23822
A17: 14. General Expenses | C17: 0 | D17: 2291.9784 | E17: 1471.5798 | F17: 0 | G17: 1097.4458 | H17: 4861.0039
A18: 15. Service Add On
A19: 12. BDP Commission
A20: 7.BESS
A21: Grand Total | B21: 0 | C21: 100416.31 | D21: 1656628.5 | E21: 5172.0998 | F21: 0 | G21: 315219.09 | H21: 2077436

Sheet Finance - COS
A3: Sum of Actual Total | B3: Column Labels
A4: Row Labels | B4: (blank) | C4: 45961 | D4: 45991 | E4: 46022 | G4: 46053 | H4: Grand Total
A5: (blank)
A6: 1. Panels | D6: 506043.6 | H6: 506043.6
A7: 2. Inverters | D7: 137740.7 | H7: 137740.7
A8: 3. Mounting Structures | D8: 78119 | G8: 9696 | H8: 87815
A9: 4. DC Equipment | C9: 4267.34 | D9: 105370.37 | E9: -31395 | G9: 14935.69 | H9: 93178.4
A10: 5. Monitoring | C10: 48977.33 | D10: 8760.68 | E10: 1300 | H10: 59038.01
A11: 6. AC Equipment | C11: 4116.49 | D11: 102756.41 | G11: 14407.715 | H11: 121280.62
A12: 8. Product Add On | D12: 18231.22 | E12: 7826.09 | H12: 26057.31
A13: 9. AC & DC installation | C13: 31114.825 | D13: 171131.54 | G13: 108901.89 | H13: 311148.25
A14: 10. Site Logistics | C14: 10270.075 | D14: 56485.412 | E14: 7150 | G14: 35945.262 | H14: 109850.75
A15: 11. Due Dilligence | B15: 0 | G15: 21375 | H15: 21375
A16: 13. Engineering | G16: 25967.954 | H16: 25967.954
A17: 14. General Expenses | C17: 0 | D17: 1951.6 | E17: 1799.28 | G17: 1093.75 | H17: 4844.63
A18: 15. Service Add On | E18: 7500 | H18: 7500
A19: 12. BDP Commission | D19: 0 | H19: 0
A20: 7.BESS
A21: Grand Total | B21: 0 | C21: 98746.06 | D21: 1186590.5 | E21: -5819.63 | G21: 232323.26 | H21: 1511840.2

Sheet Data
C2: Public holidays | F2: Drop down list
C3: 45658 | D3: New Years Day | F3: Approved
C4: 45737 | D4: Human Rights day | F4: Pending
C5: 45765 | D5: Good Friday | F5: Declined
C6: 45768 | D6: Family Day | F6: Abanded
C7: 45774 | D7: Freedom Day
C8: 45765 | D8: Freedom DayObserved
C9: 45778 | D9: Workers day
C10: 45824 | D10: Youth Day Holiday
C11: 45878 | D11: Womens Day
C12: 45924 | D12: Heritage Day
C13: 46007 | D13: Day of Reconciliation | H13: Manual dates
C14: 46016 | D14: Christmas Day
C15: 46017 | D15: Day of Goodwill
C16: 46006 | D16: Builders Break
C17: 46007 | D17: Builders Break
C18: 46008 | D18: Builders Break
C19: 46009 | D19: Builders Break
C20: 46010 | D20: Builders Break
C21: 46011 | D21: Builders Break
C22: 46012 | D22: Builders Break
C23: 46013 | D23: Builders Break
C24: 46014 | D24: Builders Break
C25: 46015 | D25: Builders Break
... C60: 46382 | D60: Day of Goodwill
