Workbook
Name Inverter_Capacity: #REF!
Name Inverter_Supplier: #REF!
Name Project_Size: 'Finance - Revenue'!Projectsize
Name Project_Size: Projectsize
Name Projectsize: #REF!
Name Projectsize: #REF!
Name Security_Serv: #REF!
Name Security_Serv: #REF!
Name SSS: #REF!
Name SSS: #REF!
Name USD_ZAR: #REF!

Sheet Certificate - Financial Close
B2: Emergent Energy – Financial Close Completion Certificate | H2: FINANCIAL CLOSE CERTIFICATE
B4: Project Name: | C4: ='Project Plan'!E2 -> Mahikeng Builders Express
B5: COO: | C5: Johannes Potgieter
B6: Programme Manager: | C6: Roedolph Venter
B7: HoPD: | C7: Natasha Watkins-Baker
B9: Date of Phase Completion:
B10: Phase Deliverables Checklist: (Y/N)
B11: Product Agreement | C11: Y
B12: EPC Agreement | C12: Y
B13: O&M Agreeement | C13: NA
B14: Cost Proposal | C14: NA
B15: Deposit Received | C15: N
B16: Risks / Notes
B18: Acknowledgement and Acceptance:
B19: Role | C19: Name | D19: Signature | E19: Date
B20: COO | C20: Johannes | D20: JTP | E20: 45957

Sheet Certificate - Planning
B2: Emergent Energy – Planning Phase Completion Certificate | H2: PLANNING CERTIFICATE
B4: Project Name: | C4: ='Project Plan'!E2 -> Mahikeng Builders Express
B5: Client Representative:
B6: Programme Manager: | C6: Roedolph Venter
B7: Project Manager: | C7: Eon Van Rensberg
B8: Project Engineer:
B10: Date of Phase Completion:
B11: Phase Deliverables Checklist: (Y/N)
B12: Project Introduction Presentation
B13: Project Brief
B14: Engineering Pack
B15: BOQ
B16: PO – Material & Equipment
B17: PO - Contractors
B18: HSE – NOC
B19: HSE – EE File
B20: HSE – Contractor File
... B24: Acknowledgement and Acceptance:
B25: Role | C25: Name | D25: Signature | E25: Date

Sheet Change Register
F1: Change Register
B3: ID | C3: Description | D3: Supporting Image (If Applicable) | E3: Impact | F3: Proposed Date | G3: Proposed By | H3: Status | I3: Approved By | J3: Approved Date | K3: Results / Comments
B4: DEC001
B5: DEC002
B6: DEC003
B7: DEC004
B8: DEC005
B9: DEC006
B10: DEC007
B11: DEC008
B12: DEC009
B13: DEC010
B14: DEC011
B15: DEC012
... B33: DEC030

Sheet Compliance
B2: HSE
B4: Description | C4: Status | D4: Approved By | E4: Date | F4: Results / Comments
B5: NOC | C5: Approved | E5: 24/10/2025
B6: 7.1 Agreement | C6: Approved
B7: 13.2 Agreement | C7: Approved
B8: EE File | C8: Approved | E8: 27/10/2025
B9: Subbie File | C9: Approved
B16: SSEG
B18: Description | C18: Status | D18: Approved By | E18: Date | F18: Results / Comments
B19: SSEG Application | C19: Pending | E19: 45946 | F19: Awaiting SSEG-SLD from Engineering
B20: PTI
B21: Commissioning Approval
B22: NERSA Registration

Sheet Project Plan
N1: =TODAY() -> 46064 | O1: =TODAY() -> 46064
C2: PROJECT PLAN | E2: Mahikeng Builders Express | I2: Net Work Days | K2: =NETWORKDAYS(I19,K40,Data!C3:C60) -> 27 | N2: 0 | O2: 1
C3: PROJECT SIZE (kWp) | E3: 250 | I3: Total Weeks | K3: =K2/5 -> 5.4
C4: PROJECT DEVELOPER | E4: Kirsten Marwick | I4: kW/Week Installation Rate | K4: =E3/K3 -> 46.296296
C5: PROJECT MANAGERS | E5: Eon Van Rensburg
C6: CONTRACT VALUE | E6: 2581531
C7: Phase: | E7: Handover
B8: No. | C8: HIGH LEVEL PROGRAMME | E8: Planned Start | F8: Duration | G8: Planned End | I8: Actual Start | J8: Duration | K8: Actual End | M8: Status | N8: Expected Status | O8: Comment
J9: =K40-I20 -> 36 | M9: =AVERAGE(M11,M19,M22,M29,M36,M40,M50,M45) -> 0.91283508 | N9: =AVERAGE(N11,N19,N22,N29,N36,N40,N50,N45) -> 0.90619476 | S9: =TODAY() -> 46064 | T9: =TODAY() -> 46064
S10: 1 | T10: 0
B11: 1 | C11: Project Initiation | E11: =MIN(E12:E18) -> 45939 | F11: =G11-E11 -> 27 | G11: =MAX(G12:G18) -> 45966 | I11: =MIN(I12:I18) -> 45939 | J11: =K11-I11 -> 27 | K11: =MAX(K12:K18) -> 45966 | M11: 1 | N11: 1
B12: 1.1 | C12: Project Charter Handover | E12: 45939 | F12: 1 | G12: =WORKDAY.INTL(E12,F12,1,Data!$C$3:$C$60) -> 45940 | I12: 45939 | J12: 1 | K12: =WORKDAY.INTL(I12,J12,1,Data!$C$3:$C$60) -> 45940 | M12: 1 | N12: =_xlfn.LET( _xlpm.s,VALUE($I12), _xlpm.e,VALUE($K12), IF(OR(_xlpm.s="",_xlpm.e=""),"", IF(_xlpm.e<=_xlpm.s, IF(TODAY()>=_xlpm.e,1,0), MAX(0,MIN(1,(TODAY()-_xlpm.s)/(_xlpm.e-_xlpm.s))))) ) -> 1 | S12: Milestone | T12: Start Date | U12: Duration | V12: End Date
B13: 1.2 | C13: HSE Readiness and Signoff | E13: =WORKDAY.INTL(G12,0,1,Data!$C$3:$C$60) -> 45940 | F13: 18 | G13: =WORKDAY.INTL(E13,F13,1,Data!$C$3:$C$60) -> 45966 | I13: =WORKDAY.INTL(K12,0,1,Data!$C$3:$C$60) -> 45940 | J13: 18 | K13: =WORKDAY.INTL(I13,J13,1,Data!$C$3:$C$60) -> 45966 | M13: 1 | N13: =_xlfn.LET( _xlpm.s,VALUE($I13), _xlpm.e,VALUE($K13), IF(OR(_xlpm.s="",_xlpm.e=""),"", IF(_xlpm.e<=_xlpm.s, IF(TODAY()>=_xlpm.e,1,0), MAX(0,MIN(1,(TODAY()-_xlpm.s)/(_xlpm.e-_xlpm.s))))) ) -> 1 | O13: Greenway to only send file tomorrow | S13: =C11 -> Project Initiation | T13: =I11 -> 45939 | U13: =J11 -> 27 | V13: =K11 -> 45966
B14: 1.3 | C14: Project Introduction | E14: 45943 | F14: 1 | G14: =WORKDAY.INTL(E14,F14,1,Data!$C$3:$C$60) -> 45944 | I14: 45943 | J14: 1 | K14: =WORKDAY.INTL(I14,J14,1,Data!$C$3:$C$60) -> 45944 | M14: 1 | N14: =_xlfn.LET( _xlpm.s,VALUE($I14), _xlpm.e,VALUE($K14), IF(OR(_xlpm.s="",_xlpm.e=""),"", IF(_xlpm.e<=_xlpm.s, IF(TODAY()>=_xlpm.e,1,0), MAX(0,MIN(1,(TODAY()-_xlpm.s)/(_xlpm.e-_xlpm.s))))) ) -> 1 | S14: =C19 -> Site Establishment | T14: =I19 -> 45959 | U14: =J19 -> 1 | V14: =K19 -> 45960
B15: 1.4 | C15: Contract & Design Sign off | E15: =WORKDAY.INTL(E12,0,1,Data!$C$3:$C$60)+14 -> 45953 | F15: 1 | G15: =WORKDAY.INTL(E15,F15,1,Data!$C$3:$C$60) -> 45954 | I15: =WORKDAY.INTL(I12,0,1,Data!$C$3:$C$60)+14 -> 45953 | J15: 1 | K15: =WORKDAY.INTL(I15,J15,1,Data!$C$3:$C$60) -> 45954 | M15: 1 | N15: =_xlfn.LET( _xlpm.s,VALUE($I15), _xlpm.e,VALUE($K15), IF(OR(_xlpm.s="",_xlpm.e=""),"", IF(_xlpm.e<=_xlpm.s, IF(TODAY()>=_xlpm.e,1,0), MAX(0,MIN(1,(TODAY()-_xlpm.s)/(_xlpm.e-_xlpm.s))))) ) -> 1
B16: 1.5 | C16: Installer Kick Off | E16: 45951 | F16: 1 | G16: =WORKDAY.INTL(E16,F16,1,Data!$C$3:$C$60) -> 45952 | I16: 45951 | J16: 1 | K16: =WORKDAY.INTL(I16,J16,1,Data!$C$3:$C$60) -> 45952 | M16: 1 | N16: =_xlfn.LET( _xlpm.s,VALUE($I16), _xlpm.e,VALUE($K16), IF(OR(_xlpm.s="",_xlpm.e=""),"", IF(_xlpm.e<=_xlpm.s, IF(TODAY()>=_xlpm.e,1,0), MAX(0,MIN(1,(TODAY()-_xlpm.s)/(_xlpm.e-_xlpm.s))))) ) -> 1 | S16: =C22 -> AC Installation | T16: =I22 -> 45954 | U16: =J22 -> 34 | V16: =K22 -> 45988
B17: 1.6 | C17: Project Review | E17: =WORKDAY.INTL(E16,0,1,Data!$C$3:$C$60) -> 45951 | F17: 1 | G17: =WORKDAY.INTL(E17,F17,1,Data!$C$3:$C$60) -> 45952 | I17: =WORKDAY.INTL(I16,0,1,Data!$C$3:$C$60) -> 45951 | J17: 1 | K17: =WORKDAY.INTL(I17,J17,1,Data!$C$3:$C$60) -> 45952 | M17: 1 | N17: =_xlfn.LET( _xlpm.s,VALUE($I17), _xlpm.e,VALUE($K17), IF(OR(_xlpm.s="",_xlpm.e=""),"", IF(_xlpm.e<=_xlpm.s, IF(TODAY()>=_xlpm.e,1,0), MAX(0,MIN(1,(TODAY()-_xlpm.s)/(_xlpm.e-_xlpm.s))))) ) -> 1 | S17: =C29 -> DC Works | T17: =I29 -> 45960 | U17: =J29 -> 12 | V17: =K29 -> 45972
S18: =C36 -> Module installation | T18: =I36 -> 45960 | U18: =J36 -> 19 | V18: =K36 -> 45979
B19: 2 | C19: Site Establishment | E19: =MIN(E20:E21) -> 45957 | F19: =G19-E19 -> 1 | G19: =MAX(G20:G21) -> 45958 | I19: =MIN(I20:I21) -> 45959 | J19: =K19-I19 -> 1 | K19: =MAX(K20:K21) -> 45960 | M19: =(J20*M20)/J19 -> 1 | N19: =(K20*N20)/K19 -> 1 | S19: =C40 -> Commissioning (Practical Completion - JBCC) | T19: =I40 -> 45988 | U19: =J40 -> 7 | V19: =K40 -> 45995
B20: 2.1 | C20: Solar Contractor Establishment | E20: 45957 | F20: 1 | G20: =E20+F20 -> 45958 | I20: 45959 | J20: 1 | K20: =I20+J20 -> 45960 | M20: 1 | N20: =_xlfn.LET( _xlpm.s,VALUE($I20), _xlpm.e,VALUE($K20), IF(OR(_xlpm.s="",_xlpm.e=""),"", IF(_xlpm.e<=_xlpm.s, IF(TODAY()>=_xlpm.e,1,0), MAX(0,MIN(1,(TODAY()-_xlpm.s)/(_xlpm.e-_xlpm.s))))) ) -> 1 | S20: =C45 -> QA Inspections (Works Completion - JBCC) | T20: =I45 -> 45988 | U20: =J45 -> 76 | V20: =K45 -> 46064
S21: =C50 -> Project Closure (Final Completion - JBCC) | T21: =I50 -> 45989 | U21: =J50 -> 88 | V21: =K50 -> 46077
B22: 3 | C22: AC Installation | E22: =MIN(E23:E28) -> 45954 | F22: =G22-E22 -> 27 | G22: =MAX(G23:G28) -> 45981 | I22: =MIN(I23:I28) -> 45954 | J22: =K22-I22 -> 34 | K22: =MAX(K23:K28) -> 45988 | M22: =(J23*M23+J24*M24+J25*M25+J26*M26+J27*M27)/SUM(J23:J27) -> 1 | N22: =(J23*N23+J24*N24+J25*N25+J26*N26+J27*N27)/SUM(J23:J27) -> 1
B23: 3.1 | C23: Inverters delivered | E23: =WORKDAY.INTL(G20,0,1,Data!$C$3:$C$60) -> 45958 | F23: 1 | G23: =WORKDAY.INTL(E23,F23,1,Data!$C$3:$C$60) -> 45959 | I23: =WORKDAY.INTL(I20,0,1,Data!$C$3:$C$60)+1 -> 45960 | J23: 1 | K23: =WORKDAY.INTL(I23,J23,1,Data!$C$3:$C$60) -> 45961 | M23: 1 | N23: =_xlfn.LET( _xlpm.s,VALUE($I23), _xlpm.e,VALUE($K23), IF(OR(_xlpm.s="",_xlpm.e=""),"", IF(_xlpm.e<=_xlpm.s, IF(TODAY()>=_xlpm.e,1,0), MAX(0,MIN(1,(TODAY()-_xlpm.s)/(_xlpm.e-_xlpm.s))))) ) -> 1
B24: 3.2 | C24: Inverters Mounted | E24: =WORKDAY.INTL(G23,0,1,Data!$C$3:$C$60) -> 45959 | F24: 1 | G24: =WORKDAY.INTL(E24,F24,1,Data!$C$3:$C$60) -> 45960 | I24: 45979 | J24: 1 | K24: =WORKDAY.INTL(I24,J24,1,Data!$C$3:$C$60) -> 45980 | M24: 1 | N24: =_xlfn.LET( _xlpm.s,VALUE($I24), _xlpm.e,VALUE($K24), IF(OR(_xlpm.s="",_xlpm.e=""),"", IF(_xlpm.e<=_xlpm.s, IF(TODAY()>=_xlpm.e,1,0), MAX(0,MIN(1,(TODAY()-_xlpm.s)/(_xlpm.e-_xlpm.s))))) ) -> 1
B25: 3.3 | C25: Solar DB Lead Time | E25: 45954 | F25: 15 | G25: =WORKDAY.INTL(E25,F25,1,Data!$C$3:$C$60) -> 45975 | I25: 45954 | J25: 20 | K25: =WORKDAY.INTL(I25,J25,1,Data!$C$3:$C$60) -> 45982 | M25: 1 | N25: =_xlfn.LET( _xlpm.s,VALUE($I25), _xlpm.e,VALUE($K25), IF(OR(_xlpm.s="",_xlpm.e=""),"", IF(_xlpm.e<=_xlpm.s, IF(TODAY()>=_xlpm.e,1,0), MAX(0,MIN(1,(TODAY()-_xlpm.s)/(_xlpm.e-_xlpm.s))))) ) -> 1
B26: 3.4 | C26: AC Works | E26: =WORKDAY.INTL(G25,0,1,Data!$C$3:$C$60)-3 -> 45972 | F26: 7 | G26: =WORKDAY.INTL(E26,F26,1,Data!$C$3:$C$60) -> 45981 | I26: =WORKDAY.INTL(K25,0,1,Data!$C$3:$C$60)-3 -> 45979 | J26: 7 | K26: =WORKDAY.INTL(I26,J26,1,Data!$C$3:$C$60) -> 45988 | M26: 1 | N26: =_xlfn.LET( _xlpm.s,VALUE($I26), _xlpm.e,VALUE($K26), IF(OR(_xlpm.s="",_xlpm.e=""),"", IF(_xlpm.e<=_xlpm.s, IF(TODAY()>=_xlpm.e,1,0), MAX(0,MIN(1,(TODAY()-_xlpm.s)/(_xlpm.e-_xlpm.s))))) ) -> 1
B27: 3.5 | C27: AC Tie-In | E27: =WORKDAY.INTL(E26,0,1,Data!$C$3:$C$60) -> 45972 | F27: 1 | G27: =WORKDAY.INTL(E27,F27,1,Data!$C$3:$C$60) -> 45973 | I27: =WORKDAY.INTL(I26,0,1,Data!$C$3:$C$60) -> 45979 | J27: 1 | K27: =WORKDAY.INTL(I27,J27,1,Data!$C$3:$C$60) -> 45980 | M27: 1 | N27: =_xlfn.LET( _xlpm.s,VALUE($I27), _xlpm.e,VALUE($K27), IF(OR(_xlpm.s="",_xlpm.e=""),"", IF(_xlpm.e<=_xlpm.s, IF(TODAY()>=_xlpm.e,1,0), MAX(0,MIN(1,(TODAY()-_xlpm.s)/(_xlpm.e-_xlpm.s))))) ) -> 1
B29: 4 | C29: DC Works | E29: =MIN(E31:E35) -> 45957 | F29: =G29-E29 -> 28 | G29: =MAX(G31:G35) -> 45985 | I29: =MIN(I31:I35) -> 45960 | J29: =K29-I29 -> 12 | K29: =MAX(K31:K35) -> 45972 | M29: =(J31*M31+J32*M32+J34*M34)/SUM(J31:J34) -> 0.90909091 | N29: =(K31*N31+K32*N32+K34*N34)/SUM(K31:K34) -> 0.75002312
B31: 4.1 | C31: Mounting Structure delivered | E31: =E20 -> 45957 | F31: 1 | G31: =WORKDAY.INTL(E31,F31,1,Data!$C$3:$C$60) -> 45958 | I31: =I20+1 -> 45960 | J31: 1 | K31: =WORKDAY.INTL(I31,J31,1,Data!$C$3:$C$60) -> 45961 | M31: 1 | N31: =_xlfn.LET( _xlpm.s,VALUE($I31), _xlpm.e,VALUE($K31), IF(OR(_xlpm.s="",_xlpm.e=""),"", IF(_xlpm.e<=_xlpm.s, IF(TODAY()>=_xlpm.e,1,0), MAX(0,MIN(1,(TODAY()-_xlpm.s)/(_xlpm.e-_xlpm.s))))) ) -> 1
B32: 4.2 | C32: Mounting Structure installation | E32: =WORKDAY.INTL(G31,0,1,Data!$C$3:$C$60) -> 45958 | F32: 4 | G32: =WORKDAY.INTL(E32,F32,1,Data!$C$3:$C$60) -> 45964 | I32: =WORKDAY.INTL(K31,0,1,Data!$C$3:$C$60) -> 45961 | J32: 4 | K32: =WORKDAY.INTL(I32,J32,1,Data!$C$3:$C$60) -> 45967 | M32: 1 | N32: =_xlfn.LET( _xlpm.s,VALUE($I32), _xlpm.e,VALUE($K32), IF(OR(_xlpm.s="",_xlpm.e=""),"", IF(_xlpm.e<=_xlpm.s, IF(TODAY()>=_xlpm.e,1,0), MAX(0,MIN(1,(TODAY()-_xlpm.s)/(_xlpm.e-_xlpm.s))))) ) -> 1
B33: 4.3 | C33: DC Cable delivered | E33: =E31 -> 45957 | F33: 1 | G33: =WORKDAY.INTL(E33,F33,1,Data!$C$3:$C$60) -> 45958 | I33: =I31 -> 45960 | J33: 1 | K33: =WORKDAY.INTL(I33,J33,1,Data!$C$3:$C$60) -> 45961 | M33: 1 | N33: =_xlfn.LET( _xlpm.s,VALUE($I33), _xlpm.e,VALUE($K33), IF(OR(_xlpm.s="",_xlpm.e=""),"", IF(_xlpm.e<=_xlpm.s, IF(TODAY()>=_xlpm.e,1,0), MAX(0,MIN(1,(TODAY()-_xlpm.s)/(_xlpm.e-_xlpm.s))))) ) -> 1
B34: 4.4 | C34: DC Stringing | E34: =WORKDAY.INTL(E38,0,1,Data!$C$3:$C$60)-2 -> 45978 | F34: 5 | G34: =WORKDAY.INTL(E34,F34,1,Data!$C$3:$C$60) -> 45985 | I34: =WORKDAY.INTL(I38,0,1,Data!$C$3:$C$60)-2 -> 45965 | J34: 5 | K34: =WORKDAY.INTL(I34,J34,1,Data!$C$3:$C$60) -> 45972 | M34: 1 | N34: =_xlfn.LET( _xlpm.s,VALUE($I34), _xlpm.e,VALUE($K34), IF(OR(_xlpm.s="",_xlpm.e=""),"", IF(_xlpm.e<=_xlpm.s, IF(TODAY()>=_xlpm.e,1,0), MAX(0,MIN(1,(TODAY()-_xlpm.s)/(_xlpm.e-_xlpm.s))))) ) -> 1
B36: 5 | C36: Module installation | E36: =MIN(E37:E39) -> 45979 | F36: =G36-E36 -> 9 | G36: =MAX(G37:G39) -> 45988 | I36: =MIN(I37:I39) -> 45960 | J36: =K36-I36 -> 19 | K36: =MAX(K37:K39) -> 45979 | M36: =(J37*M37+J38*M38)/SUM(J37:J38) -> 1 | N36: =(K37*N37+K38*N38)/SUM(K37:K38) -> 1
B37: 5.1 | C37: Module delivery | E37: 45979 | F37: 1 | G37: =WORKDAY.INTL(E37,F37,1,Data!$C$3:$C$60) -> 45980 | I37: =I20+1 -> 45960 | J37: 1 | K37: =WORKDAY.INTL(I37,J37,1,Data!$C$3:$C$60) -> 45961 | M37: 1 | N37: =_xlfn.LET( _xlpm.s,VALUE($I37), _xlpm.e,VALUE($K37), IF(OR(_xlpm.s="",_xlpm.e=""),"", IF(_xlpm.e<=_xlpm.s, IF(TODAY()>=_xlpm.e,1,0), MAX(0,MIN(1,(TODAY()-_xlpm.s)/(_xlpm.e-_xlpm.s))))) ) -> 1
B38: 5.2 | C38: Module mounting | E38: =G37 -> 45980 | F38: 6 | G38: =WORKDAY.INTL(E38,F38,1,Data!$C$3:$C$60) -> 45988 | I38: =K32 -> 45967 | J38: 8 | K38: =WORKDAY.INTL(I38,J38,1,Data!$C$3:$C$60) -> 45979 | M38: 1 | N38: =_xlfn.LET( _xlpm.s,VALUE($I38), _xlpm.e,VALUE($K38), IF(OR(_xlpm.s="",_xlpm.e=""),"", IF(_xlpm.e<=_xlpm.s, IF(TODAY()>=_xlpm.e,1,0), MAX(0,MIN(1,(TODAY()-_xlpm.s)/(_xlpm.e-_xlpm.s))))) ) -> 1
B40: 6 | C40: Commissioning (Practical Completion - JBCC) | E40: =MIN(E41:E44) -> 45988 | F40: =G40-E40 -> 7 | G40: =MAX(G41:G44) -> 45995 | I40: =MIN(I41:I44) -> 45988 | J40: =K40-I40 -> 7 | K40: =MAX(K41:K44) -> 45995 | M40: =(J41*M41+J42*M42+J43*M43)/SUM(J41:J43) -> 1 | N40: =(K41*N41+K42*N42)/SUM(K41:K42) -> 1
B41: 6.1 | C41: Commissioning (Energy Flowing) | E41: =WORKDAY.INTL(MAX(G22,G29,G36),0,1,Data!$C$3:$C$60) -> 45988 | F41: 1 | G41: =WORKDAY.INTL(E41,F41,1,Data!$C$3:$C$60) -> 45989 | I41: =WORKDAY.INTL(MAX(K22,K29,K36),0,1,Data!$C$3:$C$60) -> 45988 | J41: 1 | K41: =WORKDAY.INTL(I41,J41,1,Data!$C$3:$C$60) -> 45989 | M41: 1 | N41: =_xlfn.LET( _xlpm.s,VALUE($I41), _xlpm.e,VALUE($K41), IF(OR(_xlpm.s="",_xlpm.e=""),"", IF(_xlpm.e<=_xlpm.s, IF(TODAY()>=_xlpm.e,1,0), MAX(0,MIN(1,(TODAY()-_xlpm.s)/(_xlpm.e-_xlpm.s))))) ) -> 1
B42: 6.2 | C42: Practical Completion Achieved | E42: =WORKDAY.INTL(E41,0,1,Data!$C$3:$C$60) -> 45988 | F42: 5 | G42: =WORKDAY.INTL(E42,F42,1,Data!$C$3:$C$60) -> 45995 | I42: =WORKDAY.INTL(I41,0,1,Data!$C$3:$C$60) -> 45988 | J42: 5 | K42: =WORKDAY.INTL(I42,J42,1,Data!$C$3:$C$60) -> 45995 | M42: 1 | N42: =_xlfn.LET( _xlpm.s,VALUE($I42), _xlpm.e,VALUE($K42), IF(OR(_xlpm.s="",_xlpm.e=""),"", IF(_xlpm.e<=_xlpm.s, IF(TODAY()>=_xlpm.e,1,0), MAX(0,MIN(1,(TODAY()-_xlpm.s)/(_xlpm.e-_xlpm.s))))) ) -> 1
B43: 6.3 | C43: System Performance Monitoring | E43: =WORKDAY.INTL(E42,0,1,Data!$C$3:$C$60) -> 45988 | F43: 5 | G43: =WORKDAY.INTL(E43,F43,1,Data!$C$3:$C$60) -> 45995 | I43: =WORKDAY.INTL(I42,0,1,Data!$C$3:$C$60) -> 45988 | J43: 5 | K43: =WORKDAY.INTL(I43,J43,1,Data!$C$3:$C$60) -> 45995 | M43: 1 | N43: =_xlfn.LET( _xlpm.s,VALUE($I43), _xlpm.e,VALUE($K43), IF(OR(_xlpm.s="",_xlpm.e=""),"", IF(_xlpm.e<=_xlpm.s, IF(TODAY()>=_xlpm.e,1,0), MAX(0,MIN(1,(TODAY()-_xlpm.s)/(_xlpm.e-_xlpm.s))))) ) -> 1
B45: 7 | C45: QA Inspections (Works Completion - JBCC) | E45: =MIN(E46:E49) -> 45988 | F45: =G45-E45 -> 8 | G45: =MAX(G46:G49) -> 45996 | I45: =MIN(I46:I49) -> 45988 | J45: =K45-I45 -> 76 | K45: =MAX(K46:K49) -> 46064 | M45: =(J46*M46+J47*M47)/SUM(J46:J47) -> 0.81666667 | N45: =(K46*N46)/SUM(K46) -> 1
...

Sheet BOQ
B2: Item | C2: Supplier | D2: Description | E2: Quantity | F2: PO Generated Y/N | G2: Comments
B3: PV Module | C3: Menlo | D3: Jinko 590W - JKM590N-72HL4-BDV | E3: 424
B4: DC Cable Red & Black | C4: Menlo | D4: Enco 6mm PV Cable | E4: 6000
B5: Inverters | C5: Menlo | D5: Huawei String inverter 50kW 3PH | E5: 4
B6: Mounting Structure | C6: Schletter | D6: Kliplock Mounting structures | F6: Yes | G6: PO4401-MBE-20251023
B7: Current Transformers (Production)
B8: Current Transformers (Consumption)
B9: Solar Production Meter (Techistter)
B10: Grid Consumption Meter
B11: Wi-Fi Router & Sim
B12: Switch
B13: Back Up Battery
B14: PVDB
B23: Supplier List
B24: Accuenergy
B25: Krannich
B26: Menlo
... B30: Techsitter

Sheet Revenue Tracking
B2: HIGH LEVEL PROJECT REVENUE TRACKING
D3: COSTED | F3: ACTUAL | L3: FINANCIAL REVIEW | N3: TIMELINE REVIEW | T3: 2025 Actual Revenue | U3: 2025 Actual COS | V3: 2026 Budget Revenue | W3: 2026 Budget COS | X3: 2026 Actual Revenue | Y3: 2026 Actual COS
B4: 1 | C4: Planned Revenue | D4: ='Project Plan'!E6 -> 2581531 | F4: =F29 -> 2820054.9 | L4: 2581531 | N4: Start Date | T4: =SUMIFS('Expenditure Breakdown'!$U:$U, 'Expenditure Breakdown'!$T:$T, ">"&DATE(2024,8,31), 'Expenditure Breakdown'!$T:$T, "<="&DATE(2025,8,31), 'Expenditure Breakdown'!$S:$S, "<>") -> 0 | U4: =SUMIFS('Expenditure Breakdown'!$Q:$Q, 'Expenditure Breakdown'!$T:$T, ">"&DATE(2024,8,31), 'Expenditure Breakdown'!$T:$T, "<="&DATE(2025,8,31), 'Expenditure Breakdown'!$S:$S, "<>") -> 0 | V4: =SUMIFS('Expenditure Breakdown'!$U:$U, 'Expenditure Breakdown'!$T:$T, ">"&DATE(2025,8,31), 'Expenditure Breakdown'!$T:$T, "<="&DATE(2026,8,31)) -> 2792654 | W4: =SUMIFS('Expenditure Breakdown'!$Q:$Q, 'Expenditure Breakdown'!$T:$T, ">"&DATE(2025,8,31), 'Expenditure Breakdown'!$T:$T, "<="&DATE(2026,8,31)) -> 2684846.7 | X4: =SUMIFS('Expenditure Breakdown'!$U:$U, 'Expenditure Breakdown'!$T:$T, ">"&DATE(2025,8,31), 'Expenditure Breakdown'!$T:$T, "<="&DATE(2026,8,31), 'Expenditure Breakdown'!$S:$S, "<>") -> 2727994.4 | Y4: =SUMIFS('Expenditure Breakdown'!$Q:$Q, 'Expenditure Breakdown'!$T:$T, ">"&DATE(2025,8,31), 'Expenditure Breakdown'!$T:$T, "<="&DATE(2026,8,31), 'Expenditure Breakdown'!$S:$S, "<>") -> 2580748.5
B5: 2 | C5: Planned Expenditure | D5: =+'Expenditure Tracking'!F5 -> 2278170.9 | F5: =+'Expenditure Tracking'!H5 -> 2684846.7 | L5: 2452512.1 | N5: 45959
B6: 3 | C6: Planned Profit | D6: =+D4-D5 -> 303360.15 | F6: =+F4-F5 -> 135208.24 | L6: 129018.87 | N6: End Date - PC
B7: 4 | C7: Planned Margin | D7: =+D6/D4 -> 0.11751172 | F7: =+F6/F4 -> 0.047945251 | L7: 0.049977658 | N7: 45989
B10: CONTRACT
B12: No. | C12: PAYMENT MILESTONE | E12: % | F12: VALUE | H12: PLANNED PAYMENT DATE | L12: INVOICE NUMBER | N12: INVOICE RAISED DATE | P12: PAYMENT RECEIVED DATE | R12: MILESTONE NOTES & COMMENTS
B13: 1 | C13: Signature of Contract | E13: 0.01 | F13: =$D$4*E13*0.9 -> 23233.779 | H13: ='Project Plan'!G15+7 -> 45961 | L13: 004874 | N13: 45961 | P13: 45964 | AO13: ='Change Register'!$Q$14+ 7 -> 7
B14: 2 | C14: Design Sign Off | E14: 0.015 | F14: =$D$4*E14*0.9 -> 34850.668 | H14: =H13 -> 45961 | L14: 004874 | N14: 45961 | P14: 45964
B15: 3 | C15: Site Establishment Completion | E15: 0.02 | F15: =$D$4*E15*0.9 -> 46467.558 | H15: ='Project Plan'!G19+7 -> 45965 | L15: 004874 | N15: 45961 | P15: 45964
B16: 4 | C16: Start of Rooftop Structure Installation | E16: 0.08 | F16: =$D$4*E16*0.9 -> 185870.23 | H16: ='Project Plan'!G32+7 -> 45971 | L16: 004874 | N16: 45961 | P16: 45964
B17: 5 | C17: Mounting Structure Delivery to Site | E17: 0.1 | F17: =$D$4*E17*0.9 -> 232337.79 | H17: ='Project Plan'!E31+7 -> 45964 | L17: 004876 | N17: 45971 | P17: 45975
B18: 6 | C18: Module Delivery to Site | E18: 0.325 | F18: =$D$4*E18*0.9 -> 755097.82 | H18: ='Project Plan'!E37+7 -> 45986 | L18: 004876 | N18: 45971 | P18: 45975
B19: 7 | C19: Inverter Delivery to Site | E19: 0.265 | F19: 615695.11 | H19: ='Project Plan'!E23+7 -> 45965 | L19: 004876 | N19: 45971 | P19: 45975
B20: 8 | C20: Practical Completion | E20: 0.135 | F20: =$D$4*E20 -> 348506.68 | H20: ='Project Plan'!G25+7 -> 45982 | L20: 004896 | N20: 46000 | P20: 46001
B21: 9 | C21: Works Completion & PV Output | E21: 0.05 | F21: =$D$4*E21 -> 129076.55 | H21: ='Project Plan'!G40+7 -> 46002 | P21: 46066
C22: Retention Claimable | E22: 0 | F22: =136618.21461111+11082.6948847238 -> 147700.91 | H22: ='Project Plan'!G41+7 -> 45996 | L22: 004896 | N22: 46000 | P22: 46001
B23: 10 | C23: Retention | E23: 0 | F23: 62693.86 | H23: ='Project Plan'!G50+90 -> 46091 | P23: =P21+90 -> 46156 | R23: Check contract regarding Retention Requirements - also check with PD
B24: 11 | C24: VO - Roof Remedial Work | E24: 0 | F24: ='Expenditure Breakdown'!O175 -> 23350 | H24: =H20 -> 45982 | L24: 004896 | N24: 46000 | P24: 46001
C25: VO - Walkways | E25: 0 | F25: 183223.96 | H25: =H19 -> 45965 | P25: =P21 -> 46066
C26: VO - Catladder Design, manufacture, supply & install | E26: 0 | F26: 26500 | H26: =H20 -> 45982 | L26: 004896 | N26: 46000 | P26: =P27 -> 46001
B27: 12 | C27: VO - Waterpoint | E27: 0 | F27: 5450 | H27: =H20 -> 45982 | L27: 004896 | N27: 46000 | P27: =P20 -> 46001
E29: =SUM(E13:E27) -> 1 | F29: =SUM(F13:F27) -> 2820054.9
B31: KEY: | C31: contains an error (in result or a check has failed)
C32: Red Font - IF TEXT : content not yet confirmed
C33: Red Font - IF NUMBER: Negative value
C34: Anything in yellow is a concern or risk for noting or action
C35: confirmed
C36: [ADD INITIALS: comment for noting in square brackets, use colour or red to draw attention if important]
C37: [RT: When adding rows into sheet, ensure you insert between first and last row of each category]
C38: end of sheet - do not insert information below/beyond this
B48: No. | C48: PAYMENT MILESTONE | E48: % | F48: VALUE
B49: 1 | C49: Deposit - Project commencement | E49: 0.35 | F49: =$F$55*E49 -> 987019.22
B50: 2 | C50: Delivery of Panels | E50: 0.3 | F50: =$F$55*E50 -> 846016.48
B51: 3 | C51: Delivery of Inverters | E51: 0.2 | F51: =$F$55*E51 -> 564010.98
B52: 4 | C52: Practical Completion | E52: 0.1 | F52: =$F$55*E52 -> 282005.49
B53: 5 | C53: Handover | E53: 0.05 | F53: =$F$55*E53 -> 141002.75
C54: Total | E54: =SUM(E49:E53) -> 1 | F54: =SUM(F49:F53) -> 2820054.9
E55: =SUM(E49:E53) -> 1 | F55: =F29 -> 2820054.9

Sheet Expenditure Tracking
B2: HIGH LEVEL PROJECT EXPENDITURE TRACKING
F4: COSTED | H4: ACTUAL | J4: Difference from Costed
B5: EXPENDITURE | F5: =SUM(F9:F23) -> 2278170.9 | H5: =SUM(H9:H23) -> 2684846.7 | J5: =SUM(J9:J23) -> -406675.83
B7: No. | D7: Item | F7: Costed Expenditure | H7: Actual Expenditure | J7: Saving / Overrun | L7: Comments on variations from planned expenditure
B9: ='Expenditure Breakdown'!L6 -> 1 | D9: ='Expenditure Breakdown'!M6 -> 1. Panels | F9: ='Expenditure Breakdown'!I6 -> 561360.21 | H9: ='Expenditure Breakdown'!X6 -> 487812 | J9: =F9-H9 -> 73548.21
B10: ='Expenditure Breakdown'!L13 -> 2 | D10: ='Expenditure Breakdown'!M13 -> 2. Inverters | F10: ='Expenditure Breakdown'!I13 -> 247000 | H10: ='Expenditure Breakdown'!X13 -> 174424.32 | J10: =F10-H10 -> 72575.68
B11: ='Expenditure Breakdown'!L21 -> 3 | D11: ='Expenditure Breakdown'!M21 -> 3. Mounting Structures | F11: ='Expenditure Breakdown'!I21 -> 100040 | H11: ='Expenditure Breakdown'!X21 -> 48031 | J11: =F11-H11 -> 52009
B12: ='Expenditure Breakdown'!L28 -> 4 | D12: ='Expenditure Breakdown'!M28 -> 4. DC Equipment | F12: ='Expenditure Breakdown'!I28 -> 161926 | H12: ='Expenditure Breakdown'!X28 -> 143126.92 | J12: =F12-H12 -> 18799.08
B13: ='Expenditure Breakdown'!L44 -> 5 | D13: ='Expenditure Breakdown'!M44 -> 5. Monitoring | F13: ='Expenditure Breakdown'!I44 -> 148000 | H13: ='Expenditure Breakdown'!X44 -> 105182.45 | J13: =F13-H13 -> 42817.55
B14: ='Expenditure Breakdown'!L53 -> 6 | D14: ='Expenditure Breakdown'!M53 -> 6. AC Equipment | F14: ='Expenditure Breakdown'!I53 -> 278660.6 | H14: ='Expenditure Breakdown'!X53 -> 389809.96 | J14: =F14-H14 -> -111149.36 | L14: Request line item breakdown of Q
B15: ='Expenditure Breakdown'!L71 -> 7 | D15: ='Expenditure Breakdown'!M71 -> 7.BESS | F15: ='Expenditure Breakdown'!I71 -> 0 | H15: ='Expenditure Breakdown'!X71 -> 0 | J15: =F15-H15 -> 0
B16: ='Expenditure Breakdown'!L80 -> 8 | D16: ='Expenditure Breakdown'!M80 -> 8. Product Add On | F16: ='Expenditure Breakdown'!I80 -> 469833.45 | H16: ='Expenditure Breakdown'!X80 -> 533564.02 | J16: =F16-H16 -> -63730.57
B17: ='Expenditure Breakdown'!L114 -> 9 | D17: ='Expenditure Breakdown'!M114 -> 9. AC & DC installation | F17: ='Expenditure Breakdown'!I114 -> 198850 | H17: ='Expenditure Breakdown'!X114 -> 361334 | J17: =F17-H17 -> -162484
B18: ='Expenditure Breakdown'!L127 -> 10 | D18: ='Expenditure Breakdown'!M127 -> 10. Site Logistics | F18: ='Expenditure Breakdown'!I127 -> 56854.45 | H18: ='Expenditure Breakdown'!X127 -> 176150.51 | J18: =F18-H18 -> -119296.06
B19: ='Expenditure Breakdown'!L143 -> 11 | D19: ='Expenditure Breakdown'!M143 -> 11. Due Dilligence | F19: ='Expenditure Breakdown'!I143 -> 29000 | H19: ='Expenditure Breakdown'!X143 -> 161123.5 | J19: =F19-H19 -> -132123.5
B20: ='Expenditure Breakdown'!L151 -> 12 | D20: ='Expenditure Breakdown'!M151 -> 12. BDP Commission | F20: ='Expenditure Breakdown'!I151 -> 0 | H20: ='Expenditure Breakdown'!X151 -> 0 | J20: =F20-H20 -> 0
B21: ='Expenditure Breakdown'!L154 -> 13 | D21: ='Expenditure Breakdown'!M155 -> 13. Engineering | F21: ='Expenditure Breakdown'!I154 -> 22271.14 | H21: ='Expenditure Breakdown'!X154 -> 32269.138 | J21: =F21-H21 -> -9997.9975
B22: ='Expenditure Breakdown'!L161 -> 14 | D22: ='Expenditure Breakdown'!M161 -> 14. General Expenses | F22: ='Expenditure Breakdown'!I161 -> 4375 | H22: ='Expenditure Breakdown'!X161 -> 33994.93 | J22: =F22-H22 -> -29619.93
B23: ='Expenditure Breakdown'!L174 -> 15 | D23: ='Expenditure Breakdown'!M174 -> 15. Service Add On | F23: ='Expenditure Breakdown'!I174 -> 0 | H23: ='Expenditure Breakdown'!X174 -> 38023.93 | J23: =F23-H23 -> -38023.93
D25: check: | F25: ='Expenditure Breakdown'!I2-'Expenditure Tracking'!F5 -> 0 | G25: =#REF!-G5 -> #REF! | H25: ='Expenditure Breakdown'!X2-H5 -> 0

Sheet Expenditure Breakdown
B2: COSTED EXPENDITURE BREAKDOWN | I2: =SUM(I6:I186) -> 2278170.9 | J2: =SUM(J6:J186) -> 2581529 | L2: ACTUAL EXPENDITURE BREAKDOWN | R2: FINANCE ONLY | X2: =SUM(X6:X186) -> 2684846.7
B4: No. | C4: Product / Service | D4: Description of Work | E4: QTY | F4: Rate / Unit | G4: Budget Total | H4: FORECASTED PAYMENT DATE | I4: Total COS | J4: =IF(J2-'Revenue Tracking'!D4>=0, "Total Revenue", "ERROR on REV" ) -> ERROR on REV | L4: No. | M4: Product/ Service | N4: Description of Work | O4: QTY | P4: Rate / Unit | Q4: Actual Total | R4: PO NUMBER | S4: INVOICE NUMBER | T4: INVOICE RAISED DATE | U4: REVENUE RECOGNITION AMOUNT | V4: CHECK | W4: FINANCE PAYMENT DATE | X4: Total COS
B6: 1 | C6: Panels | D6: Panels Budget | G6: =D187 -> 561360.21 | H6: ='Project Plan'!E37+60 -> 46039 | I6: =SUM(G6:G11) -> 561360.21 | J6: =F187 -> 637909 | L6: 1 | M6: 1. Panels | N6: Jinko 590W - Menlo | O6: 424 | P6: 1150.5 | Q6: =O6*P6 -> 487812 | S6: Menlo INV0003366 | T6: 45961 | U6: 637909 | V6: =J6-SUM(U6:U11) -> 0 | W6: 46019 | X6: =SUM(Q6:Q11) -> 487812
B7: 1 | D7: Delivery Budget | L7: 1 | M7: 1. Panels | P7: =P6/590 -> 1.95 | T7: =IF(W7>1,EOMONTH(W7,0),"") | U7: 0
B8: 1 | L8: 1 | M8: 1. Panels | T8: =IF(W8>1,EOMONTH(W8,0),"") | U8: 0
B9: 1 | L9: 1 | M9: 1. Panels | T9: =IF(W9>1,EOMONTH(W9,0),"") | U9: 0
B10: 1 | L10: 1 | M10: 1. Panels | T10: =IF(W10>1,EOMONTH(W10,0),"") | U10: 0
B11: 1 | L11: 1 | M11: 1. Panels | T11: =IF(W11>1,EOMONTH(W11,0),"") | U11: 0 | Y11: BUDGET | Z11: Installer Allocation
T12: =IF(W12>1,EOMONTH(W12,0),"") | Y12: AC Equipment | Z12: =G53 -> 278660.6
B13: 2 | C13: Inverters | D13: Inverter Budget | E13: 4 | G13: =D188 -> 247000 | H13: ='Project Plan'!E23+60 -> 46018 | I13: =SUM(G13:G19) -> 247000 | J13: =F188 -> 280682 | L13: 2 | M13: 2. Inverters | N13: Huawei 50KTL (Menlo) | O13: 4 | P13: 43606.08 | Q13: =O13*P13 -> 174424.32 | S13: Menlo INV0003366 | T13: 45961 | U13: 280682 | V13: =J13-SUM(U13:U19) -> 0 | W13: =W6 -> 46019 | X13: =SUM(Q13:Q19) -> 174424.32 | Y13: DC Equipment | Z13: =G29 -> 103406
B14: 2 | L14: 2 | M14: 2. Inverters | T14: =IF(W14>1,EOMONTH(W14,0),"") | U14: 0 | Y14: AC Labour | Z14: =G114 -> 62525 | AA14: =Z14/250000 -> 0.2501
B15: 2 | L15: 2 | M15: 2. Inverters | T15: =IF(W15>1,EOMONTH(W15,0),"") | U15: 0 | Y15: DC Labour | Z15: =G115 -> 136325 | AA15: =Z15/250000 -> 0.5453
B16: 2 | L16: 2 | M16: 2. Inverters | T16: =IF(W16>1,EOMONTH(W16,0),"") | U16: 0 | Y16: Offloading | Z16: =G127 -> 8500
B17: 2 | L17: 2 | M17: 2. Inverters | T17: =IF(W17>1,EOMONTH(W17,0),"") | U17: 0 | Y17: Scaffolding | Z17: =G128 -> 17326.67
B18: 2 | L18: 2 | M18: 2. Inverters | T18: =IF(W18>1,EOMONTH(W18,0),"") | U18: 0 | Y18: Storage | Z18: =G130 -> 1027.78
B19: 2 | L19: 2 | M19: 2. Inverters | T19: =IF(W19>1,EOMONTH(W19,0),"") | U19: 0 | Y19: Telehandler | Z19: 0
T20: =IF(W20>1,EOMONTH(W20,0),"")
B21: 3 | C21: Mounting Structures | D21: Structure Budget | G21: =D189 -> 100040 | H21: ='Project Plan'!E31+30 -> 45987 | I21: =SUM(G21:G26) -> 100040 | J21: =F189 -> 113682 | L21: 3 | M21: 3. Mounting Structures | N21: Schletter - Mounting Structure | Q21: =48031-Q22 -> 45051 | R21: PO4401-MBE-20251023 - RV Approved | S21: Schletter INV 2353 | T21: 45961 | U21: 106628.8 | V21: =J21-SUM(U21:U26) -> 0 | W21: 45989 | X21: =SUM(Q21:Q26) -> 48031 | Y21: Other | Z21: 0
B22: 3 | L22: 3 | M22: 3. Mounting Structures | N22: Delivery | Q22: 2980 | S22: Schletter INV 2353 | T22: =T21 -> 45961 | U22: 7053.2023 | W22: =W21 -> 45989 | Y22: Total | Z22: =SUM(Z12:Z21) -> 607771.05
B23: 3 | L23: 3 | M23: 3. Mounting Structures | T23: =IF(W23>1,EOMONTH(W23,0),"") | U23: 0 | Y23: Less 15% | Z23: =+Z22*0.85 -> 516605.39
B24: 3 | L24: 3 | M24: 3. Mounting Structures | T24: =IF(W24>1,EOMONTH(W24,0),"") | U24: 0 | Y24: R/Wp | Z24: =Z23/'Project Plan'!$E$3/1000 -> 2.0664216
B25: 3 | L25: 3 | M25: 3. Mounting Structures | T25: =IF(W25>1,EOMONTH(W25,0),"") | U25: 0
B26: 3 | L26: 3 | M26: 3. Mounting Structures | T26: =IF(W26>1,EOMONTH(W26,0),"") | U26: 0 | Y26: ACTUAL - Greenway Solar | Z26: Installer Price | AE26: Revised Cost
T27: =IF(W27>1,EOMONTH(W27,0),"") | Y27: =Y12 -> AC Equipment | Z27: 390053.47 | AA27: 200m AC cable | AF27: 389809.96
B28: 4 | C28: DC Equipment | D28: DC Cable Budget | E28: =G28/14*1.15 -> 4807 | G28: 58520 | H28: ='Project Plan'!E33+60 -> 46017 | I28: =SUM(G28:G42) -> 161926 | J28: =F190 -> 184007 | L28: 4 | M28: 4. DC Equipment | N28: DC Cable - Menlo | O28: 6000 | P28: 13.65 | Q28: =O28*P28 -> 81900 | S28: Menlo INV0003366 | T28: 45961 | U28: 76217.104 | V28: =J28-SUM(U28:U42) -> -0.0023061084 | W28: =W13 -> 46019 | X28: =SUM(Q28:Q42) -> 143126.92 | Y28: =Y13 -> DC Equipment | Z28: 115826.92 | AF28: =Z28 -> 115826.92
B29: 4 | D29: DC Equipment Budget | G29: =D190-G28 -> 103406 | H29: ='Project Plan'!G29 -> 45985 | L29: 4 | M29: 4. DC Equipment | N29: DC Cable -Red Move to stock JHB) | O29: -2000 | P29: 13.65 | Q29: =O29*P29 -> -27300 | S29: Allocated to Joburg Storeroom | T29: 46053 | U29: 0 | W29: 46053 | Y29: =Y14 -> AC Labour | Z29: 138972.23 | AA29: =Z29/250000 -> 0.55588892 | AB29: =0.3*250000 -> 75000 | AC29: "@0,30c/W | AD29: 36k of Walkway installation | AE29: 0,5/W | AF29: 109400.2 | AG29: 0,31/W for installation | AH29: 0,19/W for living out
B30: 4 | L30: 4 | M30: 4. DC Equipment | N30: DC Cable - BlackMove to stock JHB) | O30: -2000 | P30: 13.65 | Q30: =O30*P30 -> -27300 | S30: Allocated to Joburg Storeroom | T30: 46053 | U30: 0 | W30: 46053 | Y30: =Y15 -> DC Labour | Z30: 320601.87 | AA30: =Z30/250000 -> 1.2824075 | AB30: =1*250*1000 -> 250000 | AC30: "@1/W | AE30: 1,15/W | AF30: 251933.8 | AG30: 0,72/W for installation | AH30: 0,43/W for living out
B31: 4 | L31: 4 | M31: 4. DC Equipment | T31: =IF(W31>1,EOMONTH(W31,0),"") | U31: =(Q31/$X$28*$J$28) -> 0 | Y31: Roof Access | Z31: 16041.03 | AF31: 15879.25
B32: 4 | L32: 4 | M32: 4. DC Equipment | N32: Project Kick Off | O32: =AF28 -> 115826.92 | P32: 0.1 | Q32: =$O$32*P32 -> 11582.692 | R32: PO4415-MBE-20251028 - RV Approved | S32: =S59 -> The Greenway INV0001528 | T32: =T115 -> 45961 | U32: 10778.99 | W32: =W115 -> 45960 | Y32: Deliveries and Collections | Z32: 48180 | AA32: <----- | AB32: Doesn't include the forklift. Container delivery. AC & Equipment delivery | AD32: Total saving of R64 000 | AE32: 0.19 | AF32: 26180
B33: 4 | L33: 4 | M33: 4. DC Equipment | N33: Site Establishment | P33: 0.15 | Q33: =$O$32*P33 -> 17374.038 | S33: The Greenway INV0001529 | T33: 45961 | U33: 16168.484 | W33: =W116 -> 45967 | Y33: Offloading and Rigging | Z33: 59410 | AA33: <----- | AB33: Forklift hire and Operator | AE33: 0.11 | AF33: 28490
B34: 4 | L34: 4 | M34: 4. DC Equipment | N34: AC Installation Complete | P34: 0.2 | Q34: =$O$32*P34 -> 23165.384 | S34: The Greenway INV0001555 | T34: =T117 -> 46022 | U34: 21557.979 | W34: =W117 -> 46003 | Y34: P&G | Z34: 90051.25 | AB34: Greenway's time | AF34: 77601.25
B35: 4 | L35: 4 | M35: 4. DC Equipment | N35: DC Installation Complete | P35: 0.25 | Q35: =$O$32*P35 -> 28956.73 | S35: The Greenway INV0001556 | T35: =T118 -> 46022 | U35: 26947.474 | W35: =W118 -> 46003 | Y35: HSE | Z35: =Z20*0.85 -> 0
B36: 4 | L36: 4 | M36: 4. DC Equipment | N36: Commissioning Complete | P36: 0.1 | Q36: =$O$32*P36 -> 11582.692 | S36: The Greenway INV0001557 | T36: =T119 -> 46022 | U36: 10778.99 | W36: =W119 -> 46003 | Y36: Other | Z36: 0
B37: 4 | L37: 4 | M37: 4. DC Equipment | N37: Site De-establisment | P37: 0.1 | Q37: =$O$32*P37 -> 11582.692 | S37: =S120 -> The Greenway INV0001564 | T37: =T120 -> 46022 | U37: 10778.99 | W37: =W120 -> 46015 | Y37: Other | Z37: 0
B38: 4 | L38: 4 | M38: 4. DC Equipment | N38: Handover Document Complete | P38: 0.05 | Q38: =$O$32*P38 -> 5791.346 | S38: The Greenway - INV0001565 | T38: =T121 -> 46022 | U38: 5389.4948 | W38: 46051 | Y38: Total | Z38: =SUM(Z27:Z37) -> 1179136.8 | AB38: =SUM(Z31:Z37)+SUM(Z27:Z28)+SUM(AB29:AB30) -> 1044562.7 | AC38: =Z38-AB38 -> 134574.1 | AF38: =SUM(AF27:AF34) -> 1015121.4
B39: 4 | L39: 4 | M39: 4. DC Equipment | N39: End of Defects Period | P39: 0.05 | Q39: =$O$32*P39 -> 5791.346 | T39: =T122 -> 46081 | U39: =(Q39/$X$28*$J$28)-2055.98 -> 5389.4971 | W39: =W122 -> 46081 | Y39: R/Wp | Z39: =Z38/'Project Plan'!$E$3/1000 -> 4.7165471 | AB39: =AB38/'Project Plan'!$E$3/1000 -> 4.1782507 | AF39: =AF38/'Project Plan'!$E$3/1000 -> 4.0604855
B40: 4 | L40: 4 | M40: 4. DC Equipment | T40: =IF(W40>1,EOMONTH(W40,0),"") | U40: =(Q40/$X$28*$J$28) -> 0
B41: 4 | L41: 4 | M41: 4. DC Equipment | T41: =IF(W41>1,EOMONTH(W41,0),"") | U41: =(Q41/$X$28*$J$28) -> 0 | Z41: =Z38/'Project Plan'!K3 -> 218358.66 | AA41: =SUM(AA29:AA30)/6 -> 0.30638273
B42: 4 | L42: 4 | M42: 4. DC Equipment | T42: =IF(W42>1,EOMONTH(W42,0),"") | U42: =(Q42/$X$28*$J$28) -> 0 | Z42: =SUM(Z29:Z30)/'Project Plan'!K3 -> 85106.315
T43: =IF(W43>1,EOMONTH(W43,0),"")
...

Sheet Sheet1
A1: Scope | B1: Cost
A2: Walkways - 190m - Additional | B2: 159713.96
A3: Walkways - 190m - Additional Labour | B3: 23510
A4: Gravity Lifelines Equipment - Additional | B4: 304738.28
A5: Gravity Lifelines Labour - Additional | B5: 113035
A6: Sub-Total of Additional Scope | B6: =SUM(B2:B5) -> 600997.24
A8: Emergent Energy Contribution
A9: Walkways - 130m - Costed | B9: 97500
A10: Walkways - 130m - Labour Costed | B10: 14000
A11: Lifelines Equipment - Costed | B11: 60000
A12: Lifelines Labour - Costed | B12: 22000
A13: Sub-Total of EE contribution | B13: =SUM(B9:B12) -> 193500
A15: Sub-Total (Netting off EE Contribution) | B15: =B6-B13 -> 407497.24
A16: Vat | B16: =B15*15% -> 61124.586
A17: Total | B17: =B16+B15 -> 468621.83

Sheet Cashflow
D1: [RT: Double Check the first date is always a MONDAY] | F1: 45901 | G1: =F1+7 -> 45908 | H1: =G1+7 -> 45915 | I1: =H1+7 -> 45922 | J1: =I1+7 -> 45929 | K1: =J1+7 -> 45936 | L1: =K1+7 -> 45943 | M1: =L1+7 -> 45950 | N1: =M1+7 -> 45957 | ... KF1: =KE1+7 -> 47903
A2: PLANNED | C2: CHECK | D2: CHECK
B3: Planned Revenue | C3: ='Revenue Tracking'!D4 -> 2581531 | D3: =SUM(F3:KF3) -> 2820054.9 | F3: =SUMIFS('Revenue Tracking'!$F$13:$F$27, 'Revenue Tracking'!$H$13:$H$27, ">="&F1,'Revenue Tracking'!$H$13:$H$27, "<"&G1) -> 0 | G3: =SUMIFS('Revenue Tracking'!$F$13:$F$27, 'Revenue Tracking'!$H$13:$H$27, ">="&G1,'Revenue Tracking'!$H$13:$H$27, "<"&H1) -> 0 | H3: =SUMIFS('Revenue Tracking'!$F$13:$F$27, 'Revenue Tracking'!$H$13:$H$27, ">="&H1,'Revenue Tracking'!$H$13:$H$27, "<"&I1) -> 0 | I3: =SUMIFS('Revenue Tracking'!$F$13:$F$27, 'Revenue Tracking'!$H$13:$H$27, ">="&I1,'Revenue Tracking'!$H$13:$H$27, "<"&J1) -> 0 | J3: =SUMIFS('Revenue Tracking'!$F$13:$F$27, 'Revenue Tracking'!$H$13:$H$27, ">="&J1,'Revenue Tracking'!$H$13:$H$27, "<"&K1) -> 0 | K3: =SUMIFS('Revenue Tracking'!$F$13:$F$27, 'Revenue Tracking'!$H$13:$H$27, ">="&K1,'Revenue Tracking'!$H$13:$H$27, "<"&L1) -> 0 | L3: =SUMIFS('Revenue Tracking'!$F$13:$F$27, 'Revenue Tracking'!$H$13:$H$27, ">="&L1,'Revenue Tracking'!$H$13:$H$27, "<"&M1) -> 0 | M3: =SUMIFS('Revenue Tracking'!$F$13:$F$27, 'Revenue Tracking'!$H$13:$H$27, ">="&M1,'Revenue Tracking'!$H$13:$H$27, "<"&N1) -> 0 | ... KE3: =SUMIFS('Revenue Tracking'!$F$13:$F$27, 'Revenue Tracking'!$H$13:$H$27, ">="&KE1,'Revenue Tracking'!$H$13:$H$27, "<"&KF1) -> 0 | KF3: =SUMIFS('Revenue Tracking'!$F$13:$F$27, 'Revenue Tracking'!$H$13:$H$27, ">="&KF1,'Revenue Tracking'!$H$13:$H$27, "<"&#REF!) -> 0
B4: Planned Revenue - Cumulative | F4: =F3 -> 0 | G4: =F4+G3 -> 0 | H4: =G4+H3 -> 0 | I4: =H4+I3 -> 0 | J4: =I4+J3 -> 0 | K4: =J4+K3 -> 0 | L4: =K4+L3 -> 0 | M4: =L4+M3 -> 0 | N4: =M4+N3 -> 58084.448 | ... KF4: =KE4+KF3 -> 2820054.9
B5: Planned Expenditure | C5: ='Revenue Tracking'!D5 -> 2278170.9 | D5: =SUM(F5:KF5) -> 2278170.9 | F5: =SUMIFS('Expenditure Breakdown'!$G$6:$G$193, 'Expenditure Breakdown'!$H$6:$H$193, ">="&F1,'Expenditure Breakdown'!$H$6:$H$193, "<"&G1) -> 0 | G5: =SUMIFS('Expenditure Breakdown'!$G$6:$G$193, 'Expenditure Breakdown'!$H$6:$H$193, ">="&G1,'Expenditure Breakdown'!$H$6:$H$193, "<"&H1) -> 0 | H5: =SUMIFS('Expenditure Breakdown'!$G$6:$G$193, 'Expenditure Breakdown'!$H$6:$H$193, ">="&H1,'Expenditure Breakdown'!$H$6:$H$193, "<"&I1) -> 0 | I5: =SUMIFS('Expenditure Breakdown'!$G$6:$G$193, 'Expenditure Breakdown'!$H$6:$H$193, ">="&I1,'Expenditure Breakdown'!$H$6:$H$193, "<"&J1) -> 0 | J5: =SUMIFS('Expenditure Breakdown'!$G$6:$G$193, 'Expenditure Breakdown'!$H$6:$H$193, ">="&J1,'Expenditure Breakdown'!$H$6:$H$193, "<"&K1) -> 0 | K5: =SUMIFS('Expenditure Breakdown'!$G$6:$G$193, 'Expenditure Breakdown'!$H$6:$H$193, ">="&K1,'Expenditure Breakdown'!$H$6:$H$193, "<"&L1) -> 0 | L5: =SUMIFS('Expenditure Breakdown'!$G$6:$G$193, 'Expenditure Breakdown'!$H$6:$H$193, ">="&L1,'Expenditure Breakdown'!$H$6:$H$193, "<"&M1) -> 0 | M5: =SUMIFS('Expenditure Breakdown'!$G$6:$G$193, 'Expenditure Breakdown'!$H$6:$H$193, ">="&M1,'Expenditure Breakdown'!$H$6:$H$193, "<"&N1) -> 0 | ... KE5: =SUMIFS('Expenditure Breakdown'!$G$6:$G$193, 'Expenditure Breakdown'!$H$6:$H$193, ">="&KE1,'Expenditure Breakdown'!$H$6:$H$193, "<"&KF1) -> 0 | KF5: =SUMIFS('Expenditure Breakdown'!$G$6:$G$193, 'Expenditure Breakdown'!$H$6:$H$193, ">="&KF1,'Expenditure Breakdown'!$H$6:$H$193, "<"&#REF!) -> 0
B6: Planned Expenditure - Cumulative | F6: =F5 -> 0 | G6: =F6+G5 -> 0 | H6: =G6+H5 -> 0 | I6: =H6+I5 -> 0 | J6: =I6+J5 -> 0 | K6: =J6+K5 -> 0 | L6: =K6+L5 -> 0 | M6: =L6+M5 -> 0 | N6: =M6+N5 -> 0 | ... KF6: =KE6+KF5 -> 2278170.9
B7: PLANNED CashFlow | F7: =F4-F6 -> 0 | G7: =G4-G6 -> 0 | H7: =H4-H6 -> 0 | I7: =I4-I6 -> 0 | J7: =J4-J6 -> 0 | K7: =K4-K6 -> 0 | L7: =L4-L6 -> 0 | M7: =M4-M6 -> 0 | ... KF7: =KF4-KF6 -> 541884.07
A8: ACTUAL | C8: CHECK | D8: CHECK
B9: Actual + Planned Revenue | C9: ='Revenue Tracking'!F4 -> 2820054.9 | D9: =SUM(F9:KF9) -> 2820054.9 | F9: =SUMIFS('Revenue Tracking'!$F$13:$F$27, 'Revenue Tracking'!$P$13:$P$27, ">="&F1,'Revenue Tracking'!$P$13:$P$27, "<"&G1) -> 0 | G9: =SUMIFS('Revenue Tracking'!$F$13:$F$27, 'Revenue Tracking'!$P$13:$P$27, ">="&G1,'Revenue Tracking'!$P$13:$P$27, "<"&H1) -> 0 | H9: =SUMIFS('Revenue Tracking'!$F$13:$F$27, 'Revenue Tracking'!$P$13:$P$27, ">="&H1,'Revenue Tracking'!$P$13:$P$27, "<"&I1) -> 0 | I9: =SUMIFS('Revenue Tracking'!$F$13:$F$27, 'Revenue Tracking'!$P$13:$P$27, ">="&I1,'Revenue Tracking'!$P$13:$P$27, "<"&J1) -> 0 | J9: =SUMIFS('Revenue Tracking'!$F$13:$F$27, 'Revenue Tracking'!$P$13:$P$27, ">="&J1,'Revenue Tracking'!$P$13:$P$27, "<"&K1) -> 0 | K9: =SUMIFS('Revenue Tracking'!$F$13:$F$27, 'Revenue Tracking'!$P$13:$P$27, ">="&K1,'Revenue Tracking'!$P$13:$P$27, "<"&L1) -> 0 | L9: =SUMIFS('Revenue Tracking'!$F$13:$F$27, 'Revenue Tracking'!$P$13:$P$27, ">="&L1,'Revenue Tracking'!$P$13:$P$27, "<"&M1) -> 0 | M9: =SUMIFS('Revenue Tracking'!$F$13:$F$27, 'Revenue Tracking'!$P$13:$P$27, ">="&M1,'Revenue Tracking'!$P$13:$P$27, "<"&N1) -> 0 | ... KE9: =SUMIFS('Revenue Tracking'!$F$13:$F$27, 'Revenue Tracking'!$P$13:$P$27, ">="&KE1,'Revenue Tracking'!$P$13:$P$27, "<"&KF1) -> 0 | KF9: =SUMIFS('Revenue Tracking'!$F$13:$F$27, 'Revenue Tracking'!$P$13:$P$27, ">="&KF1,'Revenue Tracking'!$P$13:$P$27, "<"&#REF!) -> 0
B10: Actual + Planned Revenue - Cumulative | F10: =F9 -> 0 | G10: =F10+G9 -> 0 | H10: =G10+H9 -> 0 | I10: =H10+I9 -> 0 | J10: =I10+J9 -> 0 | K10: =J10+K9 -> 0 | L10: =K10+L9 -> 0 | M10: =L10+M9 -> 0 | N10: =M10+N9 -> 0 | ... KF10: =KE10+KF9 -> 2820054.9
B11: Actual + Planned Expenditure | C11: ='Revenue Tracking'!F5 -> 2684846.7 | D11: =SUM(F11:KF11) -> 2677596.7 | F11: =SUMIFS('Expenditure Breakdown'!$Q$6:$Q$193, 'Expenditure Breakdown'!$W$6:$W$193, ">="&F1,'Expenditure Breakdown'!$W$6:$W$193, "<"&G1) -> 0 | G11: =SUMIFS('Expenditure Breakdown'!$Q$6:$Q$193, 'Expenditure Breakdown'!$W$6:$W$193, ">="&G1,'Expenditure Breakdown'!$W$6:$W$193, "<"&H1) -> 0 | H11: =SUMIFS('Expenditure Breakdown'!$Q$6:$Q$193, 'Expenditure Breakdown'!$W$6:$W$193, ">="&H1,'Expenditure Breakdown'!$W$6:$W$193, "<"&I1) -> 0 | I11: =SUMIFS('Expenditure Breakdown'!$Q$6:$Q$193, 'Expenditure Breakdown'!$W$6:$W$193, ">="&I1,'Expenditure Breakdown'!$W$6:$W$193, "<"&J1) -> 0 | J11: =SUMIFS('Expenditure Breakdown'!$Q$6:$Q$193, 'Expenditure Breakdown'!$W$6:$W$193, ">="&J1,'Expenditure Breakdown'!$W$6:$W$193, "<"&K1) -> 0 | K11: =SUMIFS('Expenditure Breakdown'!$Q$6:$Q$193, 'Expenditure Breakdown'!$W$6:$W$193, ">="&K1,'Expenditure Breakdown'!$W$6:$W$193, "<"&L1) -> 0 | L11: =SUMIFS('Expenditure Breakdown'!$Q$6:$Q$193, 'Expenditure Breakdown'!$W$6:$W$193, ">="&L1,'Expenditure Breakdown'!$W$6:$W$193, "<"&M1) -> 0 | M11: =SUMIFS('Expenditure Breakdown'!$Q$6:$Q$193, 'Expenditure Breakdown'!$W$6:$W$193, ">="&M1,'Expenditure Breakdown'!$W$6:$W$193, "<"&N1) -> 6000 | ... KE11: =SUMIFS('Expenditure Breakdown'!$Q$6:$Q$193, 'Expenditure Breakdown'!$W$6:$W$193, ">="&KE1,'Expenditure Breakdown'!$W$6:$W$193, "<"&KF1) -> 0 | KF11: =SUMIFS('Expenditure Breakdown'!$Q$6:$Q$193, 'Expenditure Breakdown'!$W$6:$W$193, ">="&KF1,'Expenditure Breakdown'!$W$6:$W$193, "<"&#REF!) -> 0
B12: Actual + Planned Expenditure - Cumulative | F12: =F11 -> 0 | G12: =F12+G11 -> 0 | H12: =G12+H11 -> 0 | I12: =H12+I11 -> 0 | J12: =I12+J11 -> 0 | K12: =J12+K11 -> 0 | L12: =K12+L11 -> 0 | M12: =L12+M11 -> 6000 | N12: =M12+N11 -> 118885.64 | ... KF12: =KE12+KF11 -> 2677596.7
B14: ACTUAL CashFlow | F14: =F10-F12 -> 0 | G14: =G10-G12 -> 0 | H14: =H10-H12 -> 0 | I14: =I10-I12 -> 0 | J14: =J10-J12 -> 0 | K14: =K10-K12 -> 0 | L14: =L10-L12 -> 0 | M14: =M10-M12 -> -6000 | ... KF14: =KF10-KF12 -> 142458.24
C16: CHECK | D16: CHECK
B17: Revenue Recognition | C17: =C3-D17 -> -211122.98 | D17: =SUM(F17:KF17) -> 2792654 | F17: =SUMIFS('Expenditure Breakdown'!$U$6:$U$193, 'Expenditure Breakdown'!$T$6:$T$193, ">="&F1,'Expenditure Breakdown'!$T$6:$T$193, "<"&G1) -> 0 | G17: =SUMIFS('Expenditure Breakdown'!$U$6:$U$193, 'Expenditure Breakdown'!$T$6:$T$193, ">="&G1,'Expenditure Breakdown'!$T$6:$T$193, "<"&H1) -> 0 | H17: =SUMIFS('Expenditure Breakdown'!$U$6:$U$193, 'Expenditure Breakdown'!$T$6:$T$193, ">="&H1,'Expenditure Breakdown'!$T$6:$T$193, "<"&I1) -> 0 | I17: =SUMIFS('Expenditure Breakdown'!$U$6:$U$193, 'Expenditure Breakdown'!$T$6:$T$193, ">="&I1,'Expenditure Breakdown'!$T$6:$T$193, "<"&J1) -> 0 | J17: =SUMIFS('Expenditure Breakdown'!$U$6:$U$193, 'Expenditure Breakdown'!$T$6:$T$193, ">="&J1,'Expenditure Breakdown'!$T$6:$T$193, "<"&K1) -> 0 | K17: =SUMIFS('Expenditure Breakdown'!$U$6:$U$193, 'Expenditure Breakdown'!$T$6:$T$193, ">="&K1,'Expenditure Breakdown'!$T$6:$T$193, "<"&L1) -> 0 | L17: =SUMIFS('Expenditure Breakdown'!$U$6:$U$193, 'Expenditure Breakdown'!$T$6:$T$193, ">="&L1,'Expenditure Breakdown'!$T$6:$T$193, "<"&M1) -> 0 | M17: =SUMIFS('Expenditure Breakdown'!$U$6:$U$193, 'Expenditure Breakdown'!$T$6:$T$193, ">="&M1,'Expenditure Breakdown'!$T$6:$T$193, "<"&N1) -> 0 | ... KE17: =SUMIFS('Expenditure Breakdown'!$U$6:$U$193, 'Expenditure Breakdown'!$T$6:$T$193, ">="&KE1,'Expenditure Breakdown'!$T$6:$T$193, "<"&KF1) -> 0 | KF17: =SUMIFS('Expenditure Breakdown'!$U$6:$U$193, 'Expenditure Breakdown'!$T$6:$T$193, ">="&KF1,'Expenditure Breakdown'!$T$6:$T$193, "<"&#REF!) -> 0
B18: Revenue Recognition Cumulative | C18: =D17-D18 -> 0 | D18: =MAX(F18:KF18) -> 2792654 | F18: =F17 -> 0 | G18: =F18+G17 -> 0 | H18: =G18+H17 -> 0 | I18: =H18+I17 -> 0 | J18: =I18+J17 -> 0 | K18: =J18+K17 -> 0 | L18: =K18+L17 -> 0 | M18: =L18+M17 -> 0 | N18: =M18+N17 -> 1304579.4 | ... KF18: =KE18+KF17 -> 2792654

Sheet Finance - Revenue
A3: Sum of REVENUE RECOGNITION AMOUNT | B3: Column Labels
A4: Row Labels | B4: (blank) | C4: 45961 | D4: 45991 | E4: 46022 | G4: 46053 | H4: 46081 | I4: Grand Total
A5: (blank)
A6: 1. Panels | C6: 637909 | F6: 0 | I6: 637909
A7: 2. Inverters | C7: 280682 | F7: 0 | I7: 280682
A8: 3. Mounting Structures | C8: 113682 | F8: 0 | I8: 113682
A9: 4. DC Equipment | C9: 103164.58 | E9: 75452.927 | F9: 0 | G9: 0 | H9: 5389.4971 | I9: 184007
A10: 5. Monitoring | C10: 9890.213 | D10: 135150.33 | F10: 0 | G10: 23141.458 | I10: 168182
A11: 6. AC Equipment | B11: 0 | C11: 79165 | E11: 221662 | F11: 0 | H11: 15833 | I11: 316660
A12: 8. Product Add On | B12: 0 | D12: 512862.35 | E12: 91090.538 | F12: 0 | G12: 112435.42 | I12: 716388.31
A13: 9. AC & DC installation | B13: 0 | C13: 55236 | E13: 154660.8 | F13: 0 | H13: 11047.2 | I13: 220944
A14: 10. Site Logistics | C14: 13282.414 | E14: 47232.103 | F14: 0 | H14: 2656.4844 | I14: 63171.001
A15: 11. Due Dilligence | C15: 10031.395 | E15: 20828.379 | H15: 1362.2268 | I15: 32222.001
A16: 13. Engineering | B16: 0 | H16: 25308 | I16: 25308
A17: 14. General Expenses | C17: 1536.8081 | D17: 1455.2804 | E17: 1016.026 | F17: 0 | G17: 352.40905 | H17: 500.47169 | I17: 4860.9953
A18: 15. Service Add On | D18: 23350 | E18: 2725 | H18: 2725 | I18: 28800
A19: 12. BDP Commission
A20: 7.BESS
A21: Grand Total | B21: 0 | C21: 1304579.4 | D21: 672817.95 | E21: 614667.77 | F21: 0 | G21: 135929.29 | H21: 64821.88 | I21: 2792816.3

Sheet Finance - COS
A3: Sum of Actual Total | B3: Column Labels
A4: Row Labels | B4: (blank) | D4: 45961 | E4: 45991 | F4: 46022 | G4: 46053 | H4: 46081 | I4: Grand Total
A5: (blank)
A6: 1. Panels | D6: 487812 | I6: 487812
A7: 2. Inverters | D7: 174424.32 | I7: 174424.32
A8: 3. Mounting Structures | D8: 48031 | I8: 48031
A9: 4. DC Equipment | D9: 110856.73 | F9: 81078.844 | G9: -54600 | H9: 5791.346 | I9: 143126.92
A10: 5. Monitoring | D10: 8598.34 | E10: 85415.11 | G10: 11169 | I10: 105182.45
A11: 6. AC Equipment | B11: 0 | D11: 97452.49 | F11: 272866.97 | H11: 19490.498 | I11: 389809.96
A12: 8. Product Add On | B12: 0 | E12: 326377.64 | F12: 89988.38 | G12: 111075 | I12: 527441.02
A13: 9. AC & DC installation | D13: 90333.5 | F13: 252933.8 | H13: 18066.7 | I13: 361334
A14: 10. Site Logistics | D14: 37037.625 | F14: 131705.36 | H14: 7407.53 | I14: 176150.51
A15: 11. Due Dilligence | D15: 42573.5 | F15: 93350 | H15: 6000 | I15: 141923.5
A16: 13. Engineering | H16: 32269.138 | I16: 32269.138
A17: 14. General Expenses | D17: 8016.46 | E17: 10490.93 | F17: 8655.54 | G17: 3332 | H17: 3500 | I17: 33994.93
A18: 15. Service Add On | E18: 23350 | F18: 9223.93 | H18: 11573 | I18: 44146.93
A19: 12. BDP Commission | B19: 0 | I19: 0
A20: 7.BESS
A21: Grand Total | B21: 0 | D21: 1105136 | E21: 445633.68 | F21: 939802.82 | G21: 70976 | H21: 104098.21 | I21: 2665646.7

Sheet Data
C2: Public holidays | F2: Drop down list
C3: 45658 | D3: New Years Day | F3: Approved
C4: 45737 | D4: Human Rights day | F4: Pending
C5: 45765 | D5: Good Friday | F5: Declined
C6: 45768 | D6: Family Day | F6: Abanded
C7: 45774 | D7: Freedom Day
C8: 45765 | D8: Freedom DayObserved
C9: 45778 | D9: Workers day
C10: 45824 | D10: Youth Day Holiday
C11: 45878 | D11: Womens Day
C12: 45924 | D12: Heritage Day
C13: 46007 | D13: Day of Reconciliation | H13: Manual dates
C14: 46016 | D14: Christmas Day
C15: 46017 | D15: Day of Goodwill
C16: 46006 | D16: Builders Break
C17: 46007 | D17: Builders Break
C18: 46008 | D18: Builders Break
C19: 46009 | D19: Builders Break
C20: 46010 | D20: Builders Break
C21: 46011 | D21: Builders Break
C22: 46012 | D22: Builders Break
C23: 46013 | D23: Builders Break
C24: 46014 | D24: Builders Break
C25: 46015 | D25: Builders Break
... C60: 46382 | D60: Day of Goodwill
