Workbook
Name Inverter_Capacity: #REF!
Name Inverter_Supplier: #REF!
Name Project_Size: 'Finance - Revenue'!Projectsize
Name Project_Size: Projectsize
Name Projectsize: #REF!
Name Projectsize: #REF!
Name Security_Serv: #REF!
Name Security_Serv: #REF!
Name SSS: #REF!
Name SSS: #REF!
Name USD_ZAR: #REF!

Sheet Certificate - Financial Close
B2: Emergent Energy – Financial Close Completion Certificate | H2: FINANCIAL CLOSE CERTIFICATE
B4: Project Name: | C4: ='Project Plan'!E2 -> 7th Avenue Park
B5: COO: | C5: Johannes Potgieter
B6: Programme Manager: | C6: Roedolph Venter
B7: HoPD: | C7: Natasha Watkins-Baker
B9: Date of Phase Completion:
B10: Phase Deliverables Checklist: (Y/N)
B11: Product Agreement
B12: EPC Agreement
B13: O&M Agreeement
B14: Cost Proposal
B15: Deposit Received
B16: Risks / Notes
B18: Acknowledgement and Acceptance:
B19: Role | C19: Name | D19: Signature | E19: Date

Sheet Certificate - Planning
B2: Emergent Energy – Planning Phase Completion Certificate | H2: PLANNING CERTIFICATE
B4: Project Name: | C4: ='Project Plan'!E2 -> 7th Avenue Park
B5: Client Representative:
B6: Programme Manager: | C6: Roedolph Venter
B7: Project Manager: | C7: ='Project Plan'!E5 -> Justin Franke
B8: Project Engineer:
B10: Date of Phase Completion:
B11: Phase Deliverables Checklist: (Y/N)
B12: Project Introduction Presentation
B13: Project Brief
B14: Engineering Pack
B15: BOQ
B16: PO – Material & Equipment
B17: PO - Contractors
B18: HSE – NOC
B19: HSE – EE File
B20: HSE – Contractor File
... B24: Acknowledgement and Acceptance:
B25: Role | C25: Name | D25: Signature | E25: Date

Sheet Change Register
F1: Change Register
B3: ID | C3: Description | D3: Supporting Image (If Applicable) | E3: Impact | F3: Proposed Date | G3: Proposed By | H3: Status | I3: Approved By | J3: Approved Date | K3: Results / Comments
B4: DEC001
B5: DEC002
B6: DEC003
B7: DEC004
B8: DEC005
B9: DEC006
B10: DEC007
B11: DEC008
B12: DEC009
B13: DEC010
B14: DEC011
B15: DEC012
... B33: DEC030

Sheet BOQ
B2: Item | C2: Supplier | D2: Description | E2: Quantity | F2: Comments
B3: PV Module
B4: DC Cable Red & Black
B5: Inverters
B6: Mounting Structure
B7: Current Transformers (Production)
B8: Current Transformers (Consumption)
B9: Solar Production Meter (Techistter)
B10: Grid Consumption Meter
B11: Wi-Fi Router & Sim
B12: Switch
B13: Back Up Battery
B14: PVDB
... B30: Techsitter

Sheet Compliance
B2: HSE
B4: Description | C4: Status | D4: Approved By | E4: Date | F4: Results / Comments
B5: NOC | F5: In progress
B6: 7.1 Agreement | F6: In progress
B7: 13.2 Agreement | F7: In progress
B8: EE File | F8: In progress
B9: Subbie File | F9: Not appointed yet
B16: SSEG
B18: Description | C18: Status | D18: Approved By | E18: Date | F18: Results / Comments
B19: SSEG Application
B20: PTI
B21: Commissioning Approval

Sheet Project Plan
N1: =TODAY() -> 46052 | O1: =TODAY() -> 46052
C2: PROJECT PLAN | E2: 7th Avenue Park | I2: Net Work Days | K2: =NETWORKDAYS(I18,K39,Data!C3:C60) -> 22 | N2: 0 | O2: 1
C3: PROJECT SIZE (kWp) | E3: 178 | I3: Total Weeks | K3: =K2/5 -> 4.4
C4: PROJECT DEVELOPER | E4: Cole Bisset | I4: kW/Week Installation Rate | K4: =E3/K3 -> 40.454545
C5: PROJECT MANAGERS | E5: Justin Franke | I5: Proposed Contractor | K5: Photon Solar
C6: CONTRACT VALUE | E6: 1879275.4
C7: Phase: | E7: Planning
B8: No. | C8: HIGH LEVEL PROGRAMME | E8: Planned Start | F8: Duration | G8: Planned End | I8: Actual Start | J8: Duration | K8: Actual End | M8: Status | N8: Expected Status | O8: Comment
F9: =G39-E19 -> 29 | J9: =K39-I19 -> 29 | M9: =AVERAGE(M11,M18,M21,M28,M35,M39,M48,M44) -> 0.021875 | N9: =AVERAGE(N11,N18,N21,N28,N35,N39,N48,N44) -> 0.18836406 | S9: =TODAY() -> 46052 | T9: =TODAY() -> 46052
S10: 1 | T10: 0
B11: 1 | C11: Project Initiation | E11: =MIN(E12:E17) -> 45986 | F11: =G11-E11 -> 63 | G11: =MAX(G12:G17) -> 46049 | I11: =MIN(I12:I17) -> 45986 | J11: =K11-I11 -> 63 | K11: =MAX(K12:K17) -> 46049 | M11: =(J12*M12+J13*M13+J14*M14+J15*M15+J16*M16)/SUM(J12:J16) -> 0.175 | N11: =(K12*N12+K13*N13+K14*N14+K15*N15+K16*N16)/SUM(K12:K16) -> 1
B12: 1.1 | C12: Project Charter Handover | E12: 45986 | F12: 1 | G12: =WORKDAY.INTL(E12,F12,1,Data!$C$3:$C$60) -> 45987 | I12: 45986 | J12: 1 | K12: =WORKDAY.INTL(I12,J12,1,Data!$C$3:$C$60) -> 45987 | M12: 1 | N12: =_xlfn.LET( _xlpm.s,VALUE($I12), _xlpm.e,VALUE($K12), IF(OR(_xlpm.s="",_xlpm.e=""),"", IF(_xlpm.e<=_xlpm.s, IF(TODAY()>=_xlpm.e,1,0), MAX(0,MIN(1,(TODAY()-_xlpm.s)/(_xlpm.e-_xlpm.s))))) ) -> 1 | S12: Milestone | T12: Start Date | U12: Duration | V12: End Date
B13: 1.2 | C13: HSE Readiness and Signoff | E13: 46029 | F13: 10 | G13: =WORKDAY.INTL(E13,F13,1,Data!$C$3:$C$60) -> 46044 | I13: 46029 | J13: 10 | K13: =WORKDAY.INTL(I13,J13,1,Data!$C$3:$C$60) -> 46044 | M13: 0.1 | N13: =_xlfn.LET( _xlpm.s,VALUE($I13), _xlpm.e,VALUE($K13), IF(OR(_xlpm.s="",_xlpm.e=""),"", IF(_xlpm.e<=_xlpm.s, IF(TODAY()>=_xlpm.e,1,0), MAX(0,MIN(1,(TODAY()-_xlpm.s)/(_xlpm.e-_xlpm.s))))) ) -> 1 | S13: =C11 -> Project Initiation | T13: =I11 -> 45986 | U13: =J11 -> 63 | V13: =K11 -> 46049
B14: 1.3 | C14: Project Introduction | E14: =WORKDAY.INTL(G13,0,1,Data!$C$3:$C$60) -> 46044 | F14: 1 | G14: =WORKDAY.INTL(E14,F14,1,Data!$C$3:$C$60) -> 46045 | I14: =WORKDAY.INTL(K13,0,1,Data!$C$3:$C$60) -> 46044 | J14: 1 | K14: =WORKDAY.INTL(I14,J14,1,Data!$C$3:$C$60) -> 46045 | M14: 0.8 | N14: =_xlfn.LET( _xlpm.s,VALUE($I14), _xlpm.e,VALUE($K14), IF(OR(_xlpm.s="",_xlpm.e=""),"", IF(_xlpm.e<=_xlpm.s, IF(TODAY()>=_xlpm.e,1,0), MAX(0,MIN(1,(TODAY()-_xlpm.s)/(_xlpm.e-_xlpm.s))))) ) -> 1 | S14: =C18 -> Site Establishment | T14: =I18 -> 46062 | U14: =J18 -> 1 | V14: =K18 -> 46063
B15: 1.4 | C15: Installer Kick Off | E15: =WORKDAY.INTL(E13,0,1,Data!$C$3:$C$60)+14 -> 46043 | F15: 1 | G15: =WORKDAY.INTL(E15,F15,1,Data!$C$3:$C$60) -> 46044 | I15: =WORKDAY.INTL(I13,0,1,Data!$C$3:$C$60)+14 -> 46043 | J15: 1 | K15: =WORKDAY.INTL(I15,J15,1,Data!$C$3:$C$60) -> 46044 | M15: 0 | N15: =_xlfn.LET( _xlpm.s,VALUE($I15), _xlpm.e,VALUE($K15), IF(OR(_xlpm.s="",_xlpm.e=""),"", IF(_xlpm.e<=_xlpm.s, IF(TODAY()>=_xlpm.e,1,0), MAX(0,MIN(1,(TODAY()-_xlpm.s)/(_xlpm.e-_xlpm.s))))) ) -> 1 | S15: =C21 -> AC Installation | T15: =I21 -> 46030 | U15: =J21 -> 40 | V15: =K21 -> 46070
B16: 1.5 | C16: Project Review | E16: =WORKDAY.INTL(G13,0,1,Data!$C$3:$C$60) -> 46044 | F16: 3 | G16: =WORKDAY.INTL(E16,F16,1,Data!$C$3:$C$60) -> 46049 | I16: =WORKDAY.INTL(K13,0,1,Data!$C$3:$C$60) -> 46044 | J16: 3 | K16: =WORKDAY.INTL(I16,J16,1,Data!$C$3:$C$60) -> 46049 | M16: 0 | N16: =_xlfn.LET( _xlpm.s,VALUE($I16), _xlpm.e,VALUE($K16), IF(OR(_xlpm.s="",_xlpm.e=""),"", IF(_xlpm.e<=_xlpm.s, IF(TODAY()>=_xlpm.e,1,0), MAX(0,MIN(1,(TODAY()-_xlpm.s)/(_xlpm.e-_xlpm.s))))) ) -> 1 | S16: =C28 -> DC Works | T16: =I28 -> 46057 | U16: =J28 -> 23 | V16: =K28 -> 46080
S17: =C35 -> Module installation | T17: =I35 -> 46062 | U17: =J35 -> 17 | V17: =K35 -> 46079
B18: 2 | C18: Site Establishment | E18: =MIN(E19:E20) -> 46062 | F18: =G18-E18 -> 1 | G18: =MAX(G19:G20) -> 46063 | I18: =MIN(I19:I20) -> 46062 | J18: =K18-I18 -> 1 | K18: =MAX(K19:K20) -> 46063 | M18: =(J19*M19)/J18 -> 0 | N18: =(K19*N19)/K18 -> 0 | S18: =C39 -> Commissioning | T18: =I39 -> 46080 | U18: =J39 -> 11 | V18: =K39 -> 46091
B19: 2.1 | C19: Solar Contractor Establishment | E19: 46062 | F19: 1 | G19: =E19+F19 -> 46063 | I19: 46062 | J19: 1 | K19: =I19+J19 -> 46063 | M19: 0 | N19: =_xlfn.LET( _xlpm.s,VALUE($I19), _xlpm.e,VALUE($K19), IF(OR(_xlpm.s="",_xlpm.e=""),"", IF(_xlpm.e<=_xlpm.s, IF(TODAY()>=_xlpm.e,1,0), MAX(0,MIN(1,(TODAY()-_xlpm.s)/(_xlpm.e-_xlpm.s))))) ) -> 0 | S19: =C44 -> QA Inspections | T19: =I44 -> 46084 | U19: =J44 -> 8 | V19: =K44 -> 46092
S20: =C48 -> Project Closure | T20: =I48 -> 46087 | U20: =J48 -> 18 | V20: =K48 -> 46105
B21: 3 | C21: AC Installation | E21: =MIN(E22:E27) -> 46030 | F21: =G21-E21 -> 40 | G21: =MAX(G22:G27) -> 46070 | I21: =MIN(I22:I27) -> 46030 | J21: =K21-I21 -> 40 | K21: =MAX(K22:K27) -> 46070 | M21: =(J22*M22+J23*M23+J24*M24+J25*M25+J26*M26)/SUM(J22:J26) -> 0 | N21: =(J22*N22+J23*N23+J24*N24+J25*N25+J26*N26)/SUM(J22:J26) -> 0.50691244
B22: 3.1 | C22: Inverters delivered | E22: =WORKDAY.INTL(E19,0,1,Data!$C$3:$C$60) -> 46062 | F22: 1 | G22: =WORKDAY.INTL(E22,F22,1,Data!$C$3:$C$60) -> 46063 | I22: =WORKDAY.INTL(I19,0,1,Data!$C$3:$C$60) -> 46062 | J22: 1 | K22: =WORKDAY.INTL(I22,J22,1,Data!$C$3:$C$60) -> 46063 | M22: 0 | N22: =_xlfn.LET( _xlpm.s,VALUE($I22), _xlpm.e,VALUE($K22), IF(OR(_xlpm.s="",_xlpm.e=""),"", IF(_xlpm.e<=_xlpm.s, IF(TODAY()>=_xlpm.e,1,0), MAX(0,MIN(1,(TODAY()-_xlpm.s)/(_xlpm.e-_xlpm.s))))) ) -> 0
B23: 3.2 | C23: Inverters Mounted | E23: =WORKDAY.INTL(G22,0,1,Data!$C$3:$C$60) -> 46063 | F23: 1 | G23: =WORKDAY.INTL(E23,F23,1,Data!$C$3:$C$60) -> 46064 | I23: =WORKDAY.INTL(K22,0,1,Data!$C$3:$C$60) -> 46063 | J23: 1 | K23: =WORKDAY.INTL(I23,J23,1,Data!$C$3:$C$60) -> 46064 | M23: 0 | N23: =_xlfn.LET( _xlpm.s,VALUE($I23), _xlpm.e,VALUE($K23), IF(OR(_xlpm.s="",_xlpm.e=""),"", IF(_xlpm.e<=_xlpm.s, IF(TODAY()>=_xlpm.e,1,0), MAX(0,MIN(1,(TODAY()-_xlpm.s)/(_xlpm.e-_xlpm.s))))) ) -> 0
B24: 3.3 | C24: Solar DB Lead Time | E24: =WORKDAY.INTL(E14,0,1,Data!$C$3:$C$60)-14 -> 46030 | F24: 25 | G24: =WORKDAY.INTL(E24,F24,1,Data!$C$3:$C$60) -> 46065 | I24: =WORKDAY.INTL(I14,0,1,Data!$C$3:$C$60)-14 -> 46030 | J24: 25 | K24: =WORKDAY.INTL(I24,J24,1,Data!$C$3:$C$60) -> 46065 | M24: 0 | N24: =_xlfn.LET( _xlpm.s,VALUE($I24), _xlpm.e,VALUE($K24), IF(OR(_xlpm.s="",_xlpm.e=""),"", IF(_xlpm.e<=_xlpm.s, IF(TODAY()>=_xlpm.e,1,0), MAX(0,MIN(1,(TODAY()-_xlpm.s)/(_xlpm.e-_xlpm.s))))) ) -> 0.62857143
B25: 3.4 | C25: AC Works | E25: =WORKDAY.INTL(G24,0,1,Data!$C$3:$C$60) -> 46065 | F25: 3 | G25: =WORKDAY.INTL(E25,F25,1,Data!$C$3:$C$60) -> 46070 | I25: =WORKDAY.INTL(K24,0,1,Data!$C$3:$C$60) -> 46065 | J25: 3 | K25: =WORKDAY.INTL(I25,J25,1,Data!$C$3:$C$60) -> 46070 | M25: 0 | N25: =_xlfn.LET( _xlpm.s,VALUE($I25), _xlpm.e,VALUE($K25), IF(OR(_xlpm.s="",_xlpm.e=""),"", IF(_xlpm.e<=_xlpm.s, IF(TODAY()>=_xlpm.e,1,0), MAX(0,MIN(1,(TODAY()-_xlpm.s)/(_xlpm.e-_xlpm.s))))) ) -> 0
B26: 3.5 | C26: AC Tie-In | E26: =WORKDAY.INTL(E25,0,1,Data!$C$3:$C$60) -> 46065 | F26: 1 | G26: =WORKDAY.INTL(E26,F26,1,Data!$C$3:$C$60) -> 46066 | I26: =WORKDAY.INTL(I25,0,1,Data!$C$3:$C$60) -> 46065 | J26: 1 | K26: =WORKDAY.INTL(I26,J26,1,Data!$C$3:$C$60) -> 46066 | M26: 0 | N26: =_xlfn.LET( _xlpm.s,VALUE($I26), _xlpm.e,VALUE($K26), IF(OR(_xlpm.s="",_xlpm.e=""),"", IF(_xlpm.e<=_xlpm.s, IF(TODAY()>=_xlpm.e,1,0), MAX(0,MIN(1,(TODAY()-_xlpm.s)/(_xlpm.e-_xlpm.s))))) ) -> 0
B28: 4 | C28: DC Works | E28: =MIN(E30:E34) -> 46062 | F28: =G28-E28 -> 18 | G28: =MAX(G30:G34) -> 46080 | I28: =MIN(I30:I34) -> 46057 | J28: =K28-I28 -> 23 | K28: =MAX(K30:K34) -> 46080 | M28: =(J30*M30+J31*M31+J33*M33)/SUM(J30:J33) -> 0 | N28: =(K30*N30+K31*N31+K33*N33)/SUM(K30:K33) -> 0
B30: 4.1 | C30: Mounting Structure delivered | E30: =E19 -> 46062 | F30: 1 | G30: =WORKDAY.INTL(E30,F30,1,Data!$C$3:$C$60) -> 46063 | I30: =I19 -> 46062 | J30: 1 | K30: =WORKDAY.INTL(I30,J30,1,Data!$C$3:$C$60) -> 46063 | M30: 0 | N30: =_xlfn.LET( _xlpm.s,VALUE($I30), _xlpm.e,VALUE($K30), IF(OR(_xlpm.s="",_xlpm.e=""),"", IF(_xlpm.e<=_xlpm.s, IF(TODAY()>=_xlpm.e,1,0), MAX(0,MIN(1,(TODAY()-_xlpm.s)/(_xlpm.e-_xlpm.s))))) ) -> 0
B31: 4.2 | C31: Mounting Structure installation | E31: =WORKDAY.INTL(G30,0,1,Data!$C$3:$C$60) -> 46063 | F31: 3 | G31: =WORKDAY.INTL(E31,F31,1,Data!$C$3:$C$60) -> 46066 | I31: =WORKDAY.INTL(K30,0,1,Data!$C$3:$C$60) -> 46063 | J31: 3 | K31: =WORKDAY.INTL(I31,J31,1,Data!$C$3:$C$60) -> 46066 | M31: 0 | N31: =_xlfn.LET( _xlpm.s,VALUE($I31), _xlpm.e,VALUE($K31), IF(OR(_xlpm.s="",_xlpm.e=""),"", IF(_xlpm.e<=_xlpm.s, IF(TODAY()>=_xlpm.e,1,0), MAX(0,MIN(1,(TODAY()-_xlpm.s)/(_xlpm.e-_xlpm.s))))) ) -> 0
B32: 4.3 | C32: DC Cable delivered | E32: =E30 -> 46062 | F32: 1 | G32: =WORKDAY.INTL(E32,F32,1,Data!$C$3:$C$60) -> 46063 | I32: 46057 | J32: 1 | K32: =WORKDAY.INTL(I32,J32,1,Data!$C$3:$C$60) -> 46058 | M32: 0 | N32: =_xlfn.LET( _xlpm.s,VALUE($I32), _xlpm.e,VALUE($K32), IF(OR(_xlpm.s="",_xlpm.e=""),"", IF(_xlpm.e<=_xlpm.s, IF(TODAY()>=_xlpm.e,1,0), MAX(0,MIN(1,(TODAY()-_xlpm.s)/(_xlpm.e-_xlpm.s))))) ) -> 0
B33: 4.4 | C33: DC Stringing | E33: =WORKDAY.INTL(G37,0,1,Data!$C$3:$C$60)-3 -> 46076 | F33: 4 | G33: =WORKDAY.INTL(E33,F33,1,Data!$C$3:$C$60) -> 46080 | I33: =WORKDAY.INTL(K37,0,1,Data!$C$3:$C$60)-3 -> 46076 | J33: 4 | K33: =WORKDAY.INTL(I33,J33,1,Data!$C$3:$C$60) -> 46080 | M33: 0 | N33: =_xlfn.LET( _xlpm.s,VALUE($I33), _xlpm.e,VALUE($K33), IF(OR(_xlpm.s="",_xlpm.e=""),"", IF(_xlpm.e<=_xlpm.s, IF(TODAY()>=_xlpm.e,1,0), MAX(0,MIN(1,(TODAY()-_xlpm.s)/(_xlpm.e-_xlpm.s))))) ) -> 0
B35: 5 | C35: Module installation | E35: =MIN(E36:E38) -> 46062 | F35: =G35-E35 -> 17 | G35: =MAX(G36:G38) -> 46079 | I35: =MIN(I36:I38) -> 46062 | J35: =K35-I35 -> 17 | K35: =MAX(K36:K38) -> 46079 | M35: =(J36*M36+J37*M37)/SUM(J36:J37) -> 0 | N35: =(K36*N36+K37*N37)/SUM(K36:K37) -> 0
B36: 5.1 | C36: Module delivery | E36: =WORKDAY.INTL(E19,0,1,Data!$C$3:$C$60) -> 46062 | F36: 1 | G36: =WORKDAY.INTL(E36,F36,1,Data!$C$3:$C$60) -> 46063 | I36: =WORKDAY.INTL(I19,0,1,Data!$C$3:$C$60) -> 46062 | J36: 1 | K36: =WORKDAY.INTL(I36,J36,1,Data!$C$3:$C$60) -> 46063 | M36: 0 | N36: =_xlfn.LET( _xlpm.s,VALUE($I36), _xlpm.e,VALUE($K36), IF(OR(_xlpm.s="",_xlpm.e=""),"", IF(_xlpm.e<=_xlpm.s, IF(TODAY()>=_xlpm.e,1,0), MAX(0,MIN(1,(TODAY()-_xlpm.s)/(_xlpm.e-_xlpm.s))))) ) -> 0
B37: 5.2 | C37: Module mounting | E37: =G31 -> 46066 | F37: 9 | G37: =WORKDAY.INTL(E37,F37,1,Data!$C$3:$C$60) -> 46079 | I37: =K31 -> 46066 | J37: 9 | K37: =WORKDAY.INTL(I37,J37,1,Data!$C$3:$C$60) -> 46079 | M37: 0 | N37: =_xlfn.LET( _xlpm.s,VALUE($I37), _xlpm.e,VALUE($K37), IF(OR(_xlpm.s="",_xlpm.e=""),"", IF(_xlpm.e<=_xlpm.s, IF(TODAY()>=_xlpm.e,1,0), MAX(0,MIN(1,(TODAY()-_xlpm.s)/(_xlpm.e-_xlpm.s))))) ) -> 0
B39: 6 | C39: Commissioning | E39: =MIN(E40:E43) -> 46080 | F39: =G39-E39 -> 11 | G39: =MAX(G40:G43) -> 46091 | I39: =MIN(I40:I43) -> 46080 | J39: =K39-I39 -> 11 | K39: =MAX(K40:K43) -> 46091 | M39: =(J40*M40+J41*M41+J42*M42)/SUM(J40:J42) -> 0 | N39: =(K40*N40+K41*N41)/SUM(K40:K41) -> 0
B40: 6.1 | C40: Commissioning | E40: =WORKDAY.INTL(MAX(G21,G28,G35),0,1,Data!$C$3:$C$60) -> 46080 | F40: 1 | G40: =WORKDAY.INTL(E40,F40,1,Data!$C$3:$C$60) -> 46083 | I40: =WORKDAY.INTL(MAX(K21,K28,K35),0,1,Data!$C$3:$C$60) -> 46080 | J40: 1 | K40: =WORKDAY.INTL(I40,J40,1,Data!$C$3:$C$60) -> 46083 | M40: 0 | N40: =_xlfn.LET( _xlpm.s,VALUE($I40), _xlpm.e,VALUE($K40), IF(OR(_xlpm.s="",_xlpm.e=""),"", IF(_xlpm.e<=_xlpm.s, IF(TODAY()>=_xlpm.e,1,0), MAX(0,MIN(1,(TODAY()-_xlpm.s)/(_xlpm.e-_xlpm.s))))) ) -> 0
B41: 6.2 | C41: Practical Completion | E41: =WORKDAY.INTL(G40,0,1,Data!$C$3:$C$60) -> 46083 | F41: 1 | G41: =WORKDAY.INTL(E41,F41,1,Data!$C$3:$C$60) -> 46084 | I41: =WORKDAY.INTL(K40,0,1,Data!$C$3:$C$60) -> 46083 | J41: 1 | K41: =WORKDAY.INTL(I41,J41,1,Data!$C$3:$C$60) -> 46084 | M41: 0 | N41: =_xlfn.LET( _xlpm.s,VALUE($I41), _xlpm.e,VALUE($K41), IF(OR(_xlpm.s="",_xlpm.e=""),"", IF(_xlpm.e<=_xlpm.s, IF(TODAY()>=_xlpm.e,1,0), MAX(0,MIN(1,(TODAY()-_xlpm.s)/(_xlpm.e-_xlpm.s))))) ) -> 0
B42: 6.3 | C42: System Performance Monitoring | E42: =WORKDAY.INTL(G41,0,1,Data!$C$3:$C$60) -> 46084 | F42: 5 | G42: =WORKDAY.INTL(E42,F42,1,Data!$C$3:$C$60) -> 46091 | I42: =WORKDAY.INTL(K41,0,1,Data!$C$3:$C$60) -> 46084 | J42: 5 | K42: =WORKDAY.INTL(I42,J42,1,Data!$C$3:$C$60) -> 46091 | M42: 0 | N42: =_xlfn.LET( _xlpm.s,VALUE($I42), _xlpm.e,VALUE($K42), IF(OR(_xlpm.s="",_xlpm.e=""),"", IF(_xlpm.e<=_xlpm.s, IF(TODAY()>=_xlpm.e,1,0), MAX(0,MIN(1,(TODAY()-_xlpm.s)/(_xlpm.e-_xlpm.s))))) ) -> 0
B44: 7 | C44: QA Inspections | E44: =MIN(E45:E47) -> 46084 | F44: =G44-E44 -> 8 | G44: =MAX(G45:G47) -> 46092 | I44: =MIN(I45:I47) -> 46084 | J44: =K44-I44 -> 8 | K44: =MAX(K45:K47) -> 46092 | M44: =(J45*M45+J46*M46)/SUM(J45:J46) -> 0 | N44: =(K45*N45)/SUM(K45) -> 0
B45: 7.1 | C45: Red-Team Inspection | E45: =WORKDAY.INTL(E42,0,1,Data!$C$3:$C$60) -> 46084 | F45: 3 | G45: =WORKDAY.INTL(E45,F45,1,Data!$C$3:$C$60) -> 46087 | I45: =WORKDAY.INTL(I42,0,1,Data!$C$3:$C$60) -> 46084 | J45: 3 | K45: =WORKDAY.INTL(I45,J45,1,Data!$C$3:$C$60) -> 46087 | M45: 0 | N45: =_xlfn.LET( _xlpm.s,VALUE($I45), _xlpm.e,VALUE($K45), IF(OR(_xlpm.s="",_xlpm.e=""),"", IF(_xlpm.e<=_xlpm.s, IF(TODAY()>=_xlpm.e,1,0), MAX(0,MIN(1,(TODAY()-_xlpm.s)/(_xlpm.e-_xlpm.s))))) ) -> 0
...

Sheet Revenue Tracking
B2: HIGH LEVEL PROJECT REVENUE TRACKING | U2: 2026 Budget Revenue | V2: 2026 Budget COS | W2: 2026 Actual Revenue | X2: 2026 Actual COS
D3: COSTED | F3: ACTUAL | L3: FINANCIAL REVIEW | N3: TIMELINE REVIEW | U3: =D4 -> 1879275.4 | V3: =D5 -> 1533654.4 | W3: =SUMIFS('Expenditure Breakdown'!$U:$U, 'Expenditure Breakdown'!$T:$T, ">"&DATE(2025,8,31), 'Expenditure Breakdown'!$T:$T, "<="&DATE(2026,8,31), 'Expenditure Breakdown'!$S:$S, "<>") -> 975787.82 | X3: =SUMIFS('Expenditure Breakdown'!$Q:$Q, 'Expenditure Breakdown'!$T:$T, ">"&DATE(2025,8,31), 'Expenditure Breakdown'!$T:$T, "<="&DATE(2026,8,31), 'Expenditure Breakdown'!$S:$S, "<>") -> 661634.27
B4: 1 | C4: Planned Revenue | D4: ='Project Plan'!E6 -> 1879275.4 | F4: =F22 -> 1879275.4 | N4: Start Date
B5: 2 | C5: Planned Expenditure | D5: =+'Expenditure Tracking'!F5 -> 1533654.4 | F5: =+'Expenditure Tracking'!H5 -> 1370745.5 | G5: VO PM LIMIT | H5: CURRENT VO Total
B6: 3 | C6: Planned Profit | D6: =+D4-D5 -> 345620.99 | F6: =+F4-F5 -> 508529.88 | G6: =D6*0.05 -> 17281.05 | H6: =SUMIF('Expenditure Breakdown'!N:N,"*VO*",'Expenditure Breakdown'!Q:Q) -> 0 | N6: End Date - PC
B7: 4 | C7: Planned Margin | D7: =+D6/D4 -> 0.18391184 | F7: =+F6/F4 -> 0.27059891
B10: CONTRACT
B12: No. | C12: PAYMENT MILESTONE | E12: % | F12: VALUE | H12: PLANNED PAYMENT DATE | L12: INVOICE NUMBER | N12: INVOICE RAISED DATE | P12: PAYMENT RECEIVED DATE | R12: MILESTONE NOTES & COMMENTS | S12: MILESTONE DOCUMENTS RECEIVED
B13: 1 | C13: Acceptance and Initial Deposit | E13: 0.25 | F13: =1000/1.15 -> 869.56522 | H13: 46003 | L13: 004882 | N13: 45989 | P13: 45999 | S13: FALSE | AP13: ='Change Register'!$Q$14+ 7 -> 7
B14: 1 | C14: Acceptance and Initial Deposit | F14: =469818.848799029-F13 -> 468949.28 | H14: 46003 | L14: 004882 | N14: 45989 | P14: 46034 | S14: FALSE
B15: 2 | C15: Delivery of Panels | E15: 0.5 | F15: =$D$4*E15 -> 939637.7 | H15: ='Project Plan'!G36+7 -> 46070 | P15: ='Project Plan'!K36+7 -> 46070 | S15: FALSE
B16: 3 | C16: Delivery of Inverters | E16: 0.1 | F16: =$D$4*E16 -> 187927.54 | H16: ='Project Plan'!G22+7 -> 46070 | P16: ='Project Plan'!K22+7 -> 46070 | S16: FALSE
B17: 4 | C17: Practical Completion | E17: 0.1 | F17: =$D$4*E17 -> 187927.54 | H17: ='Project Plan'!G39+7 -> 46098 | P17: ='Project Plan'!K39+7 -> 46098 | S17: FALSE
B18: 5 | C18: Handover | E18: 0.05 | F18: =$D$4*E18 -> 93963.77 | H18: ='Project Plan'!G50+7 -> 46106 | P18: ='Project Plan'!K50+7 -> 46106 | S18: FALSE
B19: 6 | C19: - | E19: 0 | F19: =$D$4*E19 -> 0 | S19: FALSE
B20: 7 | C20: - | E20: 0 | F20: =$D$4*E20 -> 0
E22: =SUM(E13:E20) -> 1 | F22: =SUM(F13:F20) -> 1879275.4
B24: KEY: | C24: contains an error (in result or a check has failed)
C25: Red Font - IF TEXT : content not yet confirmed
C26: Red Font - IF NUMBER: Negative value
C27: Anything in yellow is a concern or risk for noting or action
C28: confirmed
C29: [ADD INITIALS: comment for noting in square brackets, use colour or red to draw attention if important]
C30: [RT: When adding rows into sheet, ensure you insert between first and last row of each category]
C31: end of sheet - do not insert information below/beyond this
B41: No. | C41: PAYMENT MILESTONE | E41: % | F41: VALUE
B42: 1 | C42: Deposit - Project commencement | E42: 0.35 | F42: =$F$48*E42 -> 657746.39
B43: 2 | C43: Delivery of Panels | E43: 0.3 | F43: =$F$48*E43 -> 563782.62
B44: 3 | C44: Delivery of Inverters | E44: 0.2 | F44: =$F$48*E44 -> 375855.08
B45: 4 | C45: Practical Completion | E45: 0.1 | F45: =$F$48*E45 -> 187927.54
B46: 5 | C46: Handover | E46: 0.05 | F46: =$F$48*E46 -> 93963.77
C47: Total | E47: =SUM(E42:E46) -> 1 | F47: =SUM(F42:F46) -> 1879275.4
E48: =SUM(E42:E46) -> 1 | F48: =F22 -> 1879275.4

Sheet Expenditure Tracking
B2: HIGH LEVEL PROJECT EXPENDITURE TRACKING
F4: COSTED | H4: ACTUAL | J4: Difference from Costed
B5: EXPENDITURE | F5: =SUM(F9:F23) -> 1533654.4 | H5: =SUM(H9:H23) -> 1370745.5 | J5: =SUM(J9:J23) -> 162908.89
B7: No. | D7: Item | F7: Costed Expenditure | H7: Actual Expenditure | J7: Saving / Overrun | L7: Comments on variations from planned expenditure
B9: ='Expenditure Breakdown'!L6 -> 1 | D9: ='Expenditure Breakdown'!M6 -> 1. Panels | F9: ='Expenditure Breakdown'!I6 -> 461648.54 | H9: ='Expenditure Breakdown'!X6 -> 357460 | J9: =F9-H9 -> 104188.54
B10: ='Expenditure Breakdown'!L13 -> 2 | D10: ='Expenditure Breakdown'!M13 -> 2. Inverters | F10: ='Expenditure Breakdown'!I13 -> 140000 | H10: ='Expenditure Breakdown'!X13 -> 137740 | J10: =F10-H10 -> 2260
B11: ='Expenditure Breakdown'!L21 -> 3 | D11: ='Expenditure Breakdown'!M21 -> 3. Mounting Structures | F11: ='Expenditure Breakdown'!I21 -> 151074 | H11: ='Expenditure Breakdown'!X21 -> 161359.47 | J11: =F11-H11 -> -10285.47
B12: ='Expenditure Breakdown'!L28 -> 4 | D12: ='Expenditure Breakdown'!M28 -> 4. DC Equipment | F12: ='Expenditure Breakdown'!I28 -> 119324.7 | H12: ='Expenditure Breakdown'!X28 -> 125550 | J12: =F12-H12 -> -6225.3
B13: ='Expenditure Breakdown'!L44 -> 5 | D13: ='Expenditure Breakdown'!M44 -> 5. Monitoring | F13: ='Expenditure Breakdown'!I44 -> 49000 | H13: ='Expenditure Breakdown'!X44 -> 34612.34 | J13: =F13-H13 -> 14387.66
B14: ='Expenditure Breakdown'!L52 -> 6 | D14: ='Expenditure Breakdown'!M52 -> 6. AC Equipment | F14: ='Expenditure Breakdown'!I52 -> 211265.43 | H14: ='Expenditure Breakdown'!X52 -> 19452 | J14: =F14-H14 -> 191813.43
B15: ='Expenditure Breakdown'!L70 -> 7 | D15: ='Expenditure Breakdown'!M70 -> 7.BESS | F15: ='Expenditure Breakdown'!I70 -> 0 | H15: ='Expenditure Breakdown'!X70 -> 0 | J15: =F15-H15 -> 0
B16: ='Expenditure Breakdown'!L79 -> 8 | D16: ='Expenditure Breakdown'!M79 -> 8. Product Add On | F16: ='Expenditure Breakdown'!I79 -> 131091 | H16: ='Expenditure Breakdown'!X79 -> 105855.76 | J16: =F16-H16 -> 25235.24
B17: ='Expenditure Breakdown'!L89 -> 9 | D17: ='Expenditure Breakdown'!M89 -> 9. AC & DC installation | F17: ='Expenditure Breakdown'!I89 -> 136510 | H17: ='Expenditure Breakdown'!X89 -> 152000 | J17: =F17-H17 -> -15490
B18: ='Expenditure Breakdown'!L102 -> 10 | D18: ='Expenditure Breakdown'!M102 -> 10. Site Logistics | F18: ='Expenditure Breakdown'!I102 -> 25523.903 | H18: ='Expenditure Breakdown'!X102 -> 14150 | J18: =F18-H18 -> 11373.903
B19: ='Expenditure Breakdown'!L118 -> 11 | D19: ='Expenditure Breakdown'!M118 -> 11. Due Dilligence | F19: ='Expenditure Breakdown'!I118 -> 89000 | H19: ='Expenditure Breakdown'!X118 -> 87150 | J19: =F19-H19 -> 1850
B20: ='Expenditure Breakdown'!L124 -> 12 | D20: ='Expenditure Breakdown'!M124 -> 12. BDP Commission | F20: ='Expenditure Breakdown'!I124 -> 0 | H20: ='Expenditure Breakdown'!X124 -> 0 | J20: =F20-H20 -> 0
B21: ='Expenditure Breakdown'!L127 -> 13 | D21: ='Expenditure Breakdown'!M128 -> 13. Engineering | F21: ='Expenditure Breakdown'!I127 -> 17291.832 | H21: ='Expenditure Breakdown'!X127 -> 23490.942 | J21: =F21-H21 -> -6199.1103
B22: ='Expenditure Breakdown'!L134 -> 14 | D22: ='Expenditure Breakdown'!M134 -> 14. General Expenses | F22: ='Expenditure Breakdown'!I134 -> 1925 | H22: ='Expenditure Breakdown'!X134 -> 1925 | J22: =F22-H22 -> 0
B23: ='Expenditure Breakdown'!L147 -> 15 | D23: ='Expenditure Breakdown'!M147 -> 15. Service Add On | F23: ='Expenditure Breakdown'!I147 -> 0 | H23: ='Expenditure Breakdown'!X147 -> 150000 | J23: =F23-H23 -> -150000
D25: check: | F25: ='Expenditure Breakdown'!I2-'Expenditure Tracking'!F5 -> 0 | G25: =#REF!-G5 -> #REF! | H25: ='Expenditure Breakdown'!X2-H5 -> 0

Sheet Expenditure Breakdown
B2: COSTED EXPENDITURE BREAKDOWN | I2: =SUM(I6:I159) -> 1533654.4 | J2: =SUM(J6:J159) -> 1879275.4 | L2: ACTUAL EXPENDITURE BREAKDOWN | R2: FINANCE ONLY | X2: =SUM(X6:X159) -> 1370745.5
B4: No. | C4: Product / Service | D4: Description of Work | E4: QTY | F4: Rate / Unit | G4: Budget Total | H4: FORECASTED PAYMENT DATE | I4: Total COS | J4: =IF(J2-'Revenue Tracking'!D4>=0, "Total Revenue", "ERROR on REV" ) -> Total Revenue | L4: No. | M4: Product/ Service | N4: Description of Work | O4: QTY | P4: Rate / Unit | Q4: Actual Total | R4: PO NUMBER | S4: INVOICE NUMBER | T4: INVOICE RAISED DATE | U4: REVENUE RECOGNITION AMOUNT | V4: CHECK | W4: FINANCE PAYMENT DATE | X4: Total COS
B6: 1 | C6: Panels | D6: Panels Budget | G6: =D160 -> 461648.54 | H6: ='Project Plan'!E36+60 -> 46122 | I6: =SUM(G6:G11) -> 461648.54 | J6: =F160 -> 577060.68 | L6: 1 | M6: 1. Panels | N6: Jinko Tiger Neo N-type66HL4M-BDV - 610W | O6: 293 | P6: =1220 -> 1220 | Q6: =O6*P6 -> 357460 | S6: MSA Energy - INV0003571 | T6: 46053 | U6: =(Q6/$X$6*$J$6) -> 577060.68 | V6: =J6-SUM(U6:U11) -> 0 | W6: 46111 | X6: =SUM(Q6:Q11) -> 357460
B7: 1 | D7: Delivery Budget | L7: 1 | M7: 1. Panels | Q7: =O7*P7 -> 0 | U7: =(Q7/$X$6*$J$6) -> 0
B8: 1 | L8: 1 | M8: 1. Panels | T8: =IF(W8>1,EOMONTH(W8,0),"") | U8: =(Q8/$X$6*$J$6) -> 0
B9: 1 | L9: 1 | M9: 1. Panels | T9: =IF(W9>1,EOMONTH(W9,0),"") | U9: =(Q9/$X$6*$J$6) -> 0
B10: 1 | L10: 1 | M10: 1. Panels | T10: =IF(W10>1,EOMONTH(W10,0),"") | U10: =(Q10/$X$6*$J$6) -> 0
B11: 1 | L11: 1 | M11: 1. Panels | T11: =IF(W11>1,EOMONTH(W11,0),"") | U11: =(Q11/$X$6*$J$6) -> 0 | Y11: BUDGET | Z11: Installer Allocation
T12: =IF(W12>1,EOMONTH(W12,0),"") | Y12: AC Equipment | Z12: =G52 -> 211265.43
B13: 2 | C13: Inverters | D13: Inverter Budget | G13: =D161 -> 140000 | H13: ='Project Plan'!E22+60 -> 46122 | I13: =SUM(G13:G19) -> 140000 | J13: =F161 -> 175000 | L13: 2 | M13: 2. Inverters | U13: =(Q13/$X$13*$J$13) -> 0 | V13: =J13-SUM(U13:U19) -> 0 | X13: =SUM(Q13:Q19) -> 137740 | Y13: DC Equipment | Z13: =G29 -> 79942.7
B14: 2 | L14: 2 | M14: 2. Inverters | N14: Huawei 100KTL | O14: 2 | P14: 68870 | Q14: =O14*P14 -> 137740 | S14: MSA Energy - INV0003571 | T14: =T6 -> 46053 | U14: =(Q14/$X$13*$J$13) -> 175000 | W14: =W6 -> 46111 | Y14: AC Labour | Z14: =G89 -> 44530
B15: 2 | L15: 2 | M15: 2. Inverters | T15: =IF(W15>1,EOMONTH(W15,0),"") | U15: =(Q15/$X$13*$J$13) -> 0 | Y15: DC Labour | Z15: =G90 -> 91980
B16: 2 | L16: 2 | M16: 2. Inverters | T16: =IF(W16>1,EOMONTH(W16,0),"") | U16: =(Q16/$X$13*$J$13) -> 0 | Y16: Offloading | Z16: =G102 -> 8500
B17: 2 | L17: 2 | M17: 2. Inverters | T17: =IF(W17>1,EOMONTH(W17,0),"") | U17: =(Q17/$X$13*$J$13) -> 0 | Y17: Scaffolding | Z17: =G103 -> 17023.903
B18: 2 | L18: 2 | M18: 2. Inverters | T18: =IF(W18>1,EOMONTH(W18,0),"") | U18: =(Q18/$X$13*$J$13) -> 0 | Y18: Storage | Z18: =G105 -> 0
B19: 2 | L19: 2 | M19: 2. Inverters | T19: =IF(W19>1,EOMONTH(W19,0),"") | U19: =(Q19/$X$13*$J$13) -> 0 | Y19: Telehandler | Z19: 0
T20: =IF(W20>1,EOMONTH(W20,0),"") | Y20: Trenching | Z20: 0
B21: 3 | C21: Mounting Structures | D21: Structure Budget | G21: =D162 -> 151074 | H21: ='Project Plan'!E30+30 -> 46092 | I21: =SUM(G21:G26) -> 151074 | J21: =F162 -> 188842.5 | L21: 3 | M21: 3. Mounting Structures | N21: Schletter Structure | Q21: 130360.8 | T21: 46081 | U21: =(Q21/$X$21*$J$21) -> 152564.08 | V21: =J21-SUM(U21:U26) -> 0 | W21: =T21+30 -> 46111 | X21: =SUM(Q21:Q26) -> 161359.47 | Y21: Other | Z21: 0
B22: 3 | L22: 3 | M22: 3. Mounting Structures | N22: Surface Protection Mats | O22: 65 | P22: 31.54 | Q22: 2050.1 | R22: Allocated from Red Rocket | S22: Allocated from Red Rocket | T22: 46053 | U22: =(Q22/$X$21*$J$21) -> 2399.2767 | W22: 46053 | Y22: Total | Z22: =SUM(Z12:Z21) -> 453242.03
B23: 3 | L23: 3 | M23: 3. Mounting Structures | T23: =IF(W23>1,EOMONTH(W23,0),"") | U23: =(Q23/$X$21*$J$21) -> 0 | Y23: Less 15% | Z23: =+Z22*0.85 -> 385255.72
B24: 3 | L24: 3 | M24: 3. Mounting Structures | T24: =IF(W24>1,EOMONTH(W24,0),"") | U24: =(Q24/$X$21*$J$21) -> 0 | Y24: R/Wp | Z24: =Z23/'Project Plan'!$E$3/1000 -> 2.164358
B25: 3 | L25: 3 | M25: 3. Mounting Structures | T25: =IF(W25>1,EOMONTH(W25,0),"") | U25: =(Q25/$X$21*$J$21) -> 0
B26: 3 | L26: 3 | M26: 3. Mounting Structures | N26: Lintels | Q26: 28948.57 | R26: PO4589-7AP-20260129 - RV Approved | S26: Lintels for Africa - 234145 | T26: 46053 | U26: =(Q26/$X$21*$J$21) -> 33879.142 | W26: 46058 | Y26: ACTUAL | Z26: Installer Price - Photon Solar
T27: =IF(W27>1,EOMONTH(W27,0),"") | Y27: =Y12 -> AC Equipment | Z27: 19452
B28: 4 | C28: DC Equipment | D28: DC Cable Budget | E28: 2813 | G28: 39382 | H28: ='Project Plan'!E32+60 -> 46122 | I28: =SUM(G28:G42) -> 119324.7 | J28: =F163 -> 149155.88 | L28: 4 | M28: 4. DC Equipment | N28: DC Cable | O28: 4000 | P28: 14 | Q28: =O28*P28 -> 56000 | S28: MSA Energy - INV0003571 | T28: 46053 | U28: =(Q28/$X$28*$J$28) -> 66529.104 | V28: =J28-SUM(U28:U42) -> 0 | W28: =W6 -> 46111 | X28: =SUM(Q28:Q42) -> 125550 | Y28: =Y13 -> DC Equipment | Z28: 69550
B29: 4 | D29: DC Equipment Budget | G29: =D163-G28 -> 79942.7 | H29: ='Project Plan'!G28 -> 46080 | L29: 4 | M29: 4. DC Equipment | T29: =IF(W29>1,EOMONTH(W29,0),"") | U29: =(Q29/$X$28*$J$28) -> 0 | Y29: =Y14 -> AC Labour | Z29: 48000
B30: 4 | L30: 4 | M30: 4. DC Equipment | T30: =IF(W30>1,EOMONTH(W30,0),"") | U30: =(Q30/$X$28*$J$28) -> 0 | Y30: =Y15 -> DC Labour | Z30: 104000
B31: 4 | L31: 4 | M31: 4. DC Equipment | T31: =IF(W31>1,EOMONTH(W31,0),"") | U31: =(Q31/$X$28*$J$28) -> 0 | Y31: Lifelines | Z31: 0
B32: 4 | L32: 4 | M32: 4. DC Equipment | N32: Project Kick Off | O32: =Z28 -> 69550 | P32: 0.1 | Q32: =$O$32*P32 -> 6955 | T32: =T90 -> 46081 | U32: =(Q32/$X$28*$J$28) -> 8262.6771 | W32: =W90 -> 46062 | Y32: Forklift | Z32: 0
B33: 4 | L33: 4 | M33: 4. DC Equipment | N33: Site Establishment | P33: 0.15 | Q33: =$O$32*P33 -> 10432.5 | T33: =T91 -> 46081 | U33: =(Q33/$X$28*$J$28) -> 12394.016 | W33: =W91 -> 46062 | Y33: Geda | Z33: 9900
B34: 4 | L34: 4 | M34: 4. DC Equipment | N34: AC Installation Complete | P34: 0.2 | Q34: =$O$32*P34 -> 13910 | T34: =T92 -> 46081 | U34: =(Q34/$X$28*$J$28) -> 16525.354 | W34: =W92 -> 46077 | Y34: Logistics | Z34: 0
B35: 4 | L35: 4 | M35: 4. DC Equipment | N35: DC Installation Complete | P35: 0.25 | Q35: =$O$32*P35 -> 17387.5 | T35: =T93 -> 46112 | U35: =(Q35/$X$28*$J$28) -> 20656.693 | W35: =W93 -> 46087 | Y35: Waste Skip | Z35: 4250
B36: 4 | L36: 4 | M36: 4. DC Equipment | N36: Commissioning Complete | P36: 0.1 | Q36: =$O$32*P36 -> 6955 | T36: =T94 -> 46112 | U36: =(Q36/$X$28*$J$28) -> 8262.6771 | W36: =W94 -> 46098 | Y36: Miscellaneous | Z36: 13400
B37: 4 | L37: 4 | M37: 4. DC Equipment | N37: Site De-establisment | P37: 0.1 | Q37: =$O$32*P37 -> 6955 | T37: =T95 -> 46112 | U37: =(Q37/$X$28*$J$28) -> 8262.6771 | W37: =W95 -> 46099 | Y37: Other | Z37: 0
B38: 4 | L38: 4 | M38: 4. DC Equipment | N38: Handover Document Complete | P38: 0.05 | Q38: =$O$32*P38 -> 3477.5 | T38: =T96 -> 46112 | U38: =(Q38/$X$28*$J$28) -> 4131.3386 | W38: =W96 -> 46099 | Y38: Total | Z38: =SUM(Z27:Z37) -> 268552
B39: 4 | L39: 4 | M39: 4. DC Equipment | N39: End of Defects Period | P39: 0.05 | Q39: =$O$32*P39 -> 3477.5 | T39: =T97 -> 46142 | U39: =(Q39/$X$28*$J$28) -> 4131.3386 | W39: =W97 -> 46122 | Y39: R/Wp | Z39: =Z38/'Project Plan'!$E$3/1000 -> 1.5087191
B40: 4 | L40: 4 | M40: 4. DC Equipment | T40: =IF(W40>1,EOMONTH(W40,0),"") | U40: =(Q40/$X$28*$J$28) -> 0
B41: 4 | L41: 4 | M41: 4. DC Equipment | T41: =IF(W41>1,EOMONTH(W41,0),"") | U41: =(Q41/$X$28*$J$28) -> 0
B42: 4 | L42: 4 | M42: 4. DC Equipment | T42: =IF(W42>1,EOMONTH(W42,0),"") | U42: =(Q42/$X$28*$J$28) -> 0
T43: =IF(W43>1,EOMONTH(W43,0),"")
...

Sheet Cashflow
D1: [RT: Double Check the first date is always a MONDAY] | F1: 45971 | G1: =F1+7 -> 45978 | H1: =G1+7 -> 45985 | I1: =H1+7 -> 45992 | J1: =I1+7 -> 45999 | K1: =J1+7 -> 46006 | L1: =K1+7 -> 46013 | M1: =L1+7 -> 46020 | N1: =M1+7 -> 46027 | ... KF1: =KE1+7 -> 47973
A2: PLANNED | C2: CHECK | D2: CHECK
B3: Planned Revenue | C3: ='Revenue Tracking'!D4 -> 1879275.4 | D3: =SUM(F3:KF3) -> 1879275.4 | F3: =SUMIFS('Revenue Tracking'!$F$13:$F$20, 'Revenue Tracking'!$H$13:$H$20, ">="&F1,'Revenue Tracking'!$H$13:$H$20, "<"&G1) -> 0 | G3: =SUMIFS('Revenue Tracking'!$F$13:$F$20, 'Revenue Tracking'!$H$13:$H$20, ">="&G1,'Revenue Tracking'!$H$13:$H$20, "<"&H1) -> 0 | H3: =SUMIFS('Revenue Tracking'!$F$13:$F$20, 'Revenue Tracking'!$H$13:$H$20, ">="&H1,'Revenue Tracking'!$H$13:$H$20, "<"&I1) -> 0 | I3: =SUMIFS('Revenue Tracking'!$F$13:$F$20, 'Revenue Tracking'!$H$13:$H$20, ">="&I1,'Revenue Tracking'!$H$13:$H$20, "<"&J1) -> 0 | J3: =SUMIFS('Revenue Tracking'!$F$13:$F$20, 'Revenue Tracking'!$H$13:$H$20, ">="&J1,'Revenue Tracking'!$H$13:$H$20, "<"&K1) -> 469818.85 | K3: =SUMIFS('Revenue Tracking'!$F$13:$F$20, 'Revenue Tracking'!$H$13:$H$20, ">="&K1,'Revenue Tracking'!$H$13:$H$20, "<"&L1) -> 0 | L3: =SUMIFS('Revenue Tracking'!$F$13:$F$20, 'Revenue Tracking'!$H$13:$H$20, ">="&L1,'Revenue Tracking'!$H$13:$H$20, "<"&M1) -> 0 | M3: =SUMIFS('Revenue Tracking'!$F$13:$F$20, 'Revenue Tracking'!$H$13:$H$20, ">="&M1,'Revenue Tracking'!$H$13:$H$20, "<"&N1) -> 0 | ... KE3: =SUMIFS('Revenue Tracking'!$F$13:$F$20, 'Revenue Tracking'!$H$13:$H$20, ">="&KE1,'Revenue Tracking'!$H$13:$H$20, "<"&KF1) -> 0 | KF3: =SUMIFS('Revenue Tracking'!$F$13:$F$20, 'Revenue Tracking'!$H$13:$H$20, ">="&KF1,'Revenue Tracking'!$H$13:$H$20, "<"&#REF!) -> 0
B4: Planned Revenue - Cumulative | F4: =F3 -> 0 | G4: =F4+G3 -> 0 | H4: =G4+H3 -> 0 | I4: =H4+I3 -> 0 | J4: =I4+J3 -> 469818.85 | K4: =J4+K3 -> 469818.85 | L4: =K4+L3 -> 469818.85 | M4: =L4+M3 -> 469818.85 | N4: =M4+N3 -> 469818.85 | ... KF4: =KE4+KF3 -> 1879275.4
B5: Planned Expenditure | C5: ='Revenue Tracking'!D5 -> 1533654.4 | D5: =SUM(F5:KF5) -> 1533654.4 | F5: =SUMIFS('Expenditure Breakdown'!$G$6:$G$166, 'Expenditure Breakdown'!$H$6:$H$166, ">="&F1,'Expenditure Breakdown'!$H$6:$H$166, "<"&G1) -> 0 | G5: =SUMIFS('Expenditure Breakdown'!$G$6:$G$166, 'Expenditure Breakdown'!$H$6:$H$166, ">="&G1,'Expenditure Breakdown'!$H$6:$H$166, "<"&H1) -> 0 | H5: =SUMIFS('Expenditure Breakdown'!$G$6:$G$166, 'Expenditure Breakdown'!$H$6:$H$166, ">="&H1,'Expenditure Breakdown'!$H$6:$H$166, "<"&I1) -> 0 | I5: =SUMIFS('Expenditure Breakdown'!$G$6:$G$166, 'Expenditure Breakdown'!$H$6:$H$166, ">="&I1,'Expenditure Breakdown'!$H$6:$H$166, "<"&J1) -> 0 | J5: =SUMIFS('Expenditure Breakdown'!$G$6:$G$166, 'Expenditure Breakdown'!$H$6:$H$166, ">="&J1,'Expenditure Breakdown'!$H$6:$H$166, "<"&K1) -> 0 | K5: =SUMIFS('Expenditure Breakdown'!$G$6:$G$166, 'Expenditure Breakdown'!$H$6:$H$166, ">="&K1,'Expenditure Breakdown'!$H$6:$H$166, "<"&L1) -> 0 | L5: =SUMIFS('Expenditure Breakdown'!$G$6:$G$166, 'Expenditure Breakdown'!$H$6:$H$166, ">="&L1,'Expenditure Breakdown'!$H$6:$H$166, "<"&M1) -> 0 | M5: =SUMIFS('Expenditure Breakdown'!$G$6:$G$166, 'Expenditure Breakdown'!$H$6:$H$166, ">="&M1,'Expenditure Breakdown'!$H$6:$H$166, "<"&N1) -> 0 | ... KE5: =SUMIFS('Expenditure Breakdown'!$G$6:$G$166, 'Expenditure Breakdown'!$H$6:$H$166, ">="&KE1,'Expenditure Breakdown'!$H$6:$H$166, "<"&KF1) -> 0 | KF5: =SUMIFS('Expenditure Breakdown'!$G$6:$G$166, 'Expenditure Breakdown'!$H$6:$H$166, ">="&KF1,'Expenditure Breakdown'!$H$6:$H$166, "<"&#REF!) -> 0
B6: Planned Expenditure - Cumulative | F6: =F5 -> 0 | G6: =F6+G5 -> 0 | H6: =G6+H5 -> 0 | I6: =H6+I5 -> 0 | J6: =I6+J5 -> 0 | K6: =J6+K5 -> 0 | L6: =K6+L5 -> 0 | M6: =L6+M5 -> 0 | N6: =M6+N5 -> 0 | ... KF6: =KE6+KF5 -> 1533654.4
B7: PLANNED CashFlow | F7: =F4-F6 -> 0 | G7: =G4-G6 -> 0 | H7: =H4-H6 -> 0 | I7: =I4-I6 -> 0 | J7: =J4-J6 -> 469818.85 | K7: =K4-K6 -> 469818.85 | L7: =L4-L6 -> 469818.85 | M7: =M4-M6 -> 469818.85 | ... KF7: =KF4-KF6 -> 345620.99
A8: ACTUAL | C8: CHECK | D8: CHECK
B9: Actual + Planned Revenue | C9: ='Revenue Tracking'!F4 -> 1879275.4 | D9: =SUM(F9:KF9) -> 1879275.4 | F9: =SUMIFS('Revenue Tracking'!$F$13:$F$20, 'Revenue Tracking'!$P$13:$P$20, ">="&F1,'Revenue Tracking'!$P$13:$P$20, "<"&G1) -> 0 | G9: =SUMIFS('Revenue Tracking'!$F$13:$F$20, 'Revenue Tracking'!$P$13:$P$20, ">="&G1,'Revenue Tracking'!$P$13:$P$20, "<"&H1) -> 0 | H9: =SUMIFS('Revenue Tracking'!$F$13:$F$20, 'Revenue Tracking'!$P$13:$P$20, ">="&H1,'Revenue Tracking'!$P$13:$P$20, "<"&I1) -> 0 | I9: =SUMIFS('Revenue Tracking'!$F$13:$F$20, 'Revenue Tracking'!$P$13:$P$20, ">="&I1,'Revenue Tracking'!$P$13:$P$20, "<"&J1) -> 0 | J9: =SUMIFS('Revenue Tracking'!$F$13:$F$20, 'Revenue Tracking'!$P$13:$P$20, ">="&J1,'Revenue Tracking'!$P$13:$P$20, "<"&K1) -> 869.56522 | K9: =SUMIFS('Revenue Tracking'!$F$13:$F$20, 'Revenue Tracking'!$P$13:$P$20, ">="&K1,'Revenue Tracking'!$P$13:$P$20, "<"&L1) -> 0 | L9: =SUMIFS('Revenue Tracking'!$F$13:$F$20, 'Revenue Tracking'!$P$13:$P$20, ">="&L1,'Revenue Tracking'!$P$13:$P$20, "<"&M1) -> 0 | M9: =SUMIFS('Revenue Tracking'!$F$13:$F$20, 'Revenue Tracking'!$P$13:$P$20, ">="&M1,'Revenue Tracking'!$P$13:$P$20, "<"&N1) -> 0 | ... KE9: =SUMIFS('Revenue Tracking'!$F$13:$F$20, 'Revenue Tracking'!$P$13:$P$20, ">="&KE1,'Revenue Tracking'!$P$13:$P$20, "<"&KF1) -> 0 | KF9: =SUMIFS('Revenue Tracking'!$F$13:$F$20, 'Revenue Tracking'!$P$13:$P$20, ">="&KF1,'Revenue Tracking'!$P$13:$P$20, "<"&#REF!) -> 0
B10: Actual + Planned Revenue - Cumulative | F10: =F9 -> 0 | G10: =F10+G9 -> 0 | H10: =G10+H9 -> 0 | I10: =H10+I9 -> 0 | J10: =I10+J9 -> 869.56522 | K10: =J10+K9 -> 869.56522 | L10: =K10+L9 -> 869.56522 | M10: =L10+M9 -> 869.56522 | N10: =M10+N9 -> 869.56522 | ... KF10: =KE10+KF9 -> 1879275.4
B11: Actual + Planned Expenditure | C11: ='Revenue Tracking'!F5 -> 1370745.5 | D11: =SUM(F11:KF11) -> 1370745.5 | F11: =SUMIFS('Expenditure Breakdown'!$Q$6:$Q$166, 'Expenditure Breakdown'!$W$6:$W$166, ">="&F1,'Expenditure Breakdown'!$W$6:$W$166, "<"&G1) -> 8572.5 | G11: =SUMIFS('Expenditure Breakdown'!$Q$6:$Q$166, 'Expenditure Breakdown'!$W$6:$W$166, ">="&G1,'Expenditure Breakdown'!$W$6:$W$166, "<"&H1) -> 0 | H11: =SUMIFS('Expenditure Breakdown'!$Q$6:$Q$166, 'Expenditure Breakdown'!$W$6:$W$166, ">="&H1,'Expenditure Breakdown'!$W$6:$W$166, "<"&I1) -> 0 | I11: =SUMIFS('Expenditure Breakdown'!$Q$6:$Q$166, 'Expenditure Breakdown'!$W$6:$W$166, ">="&I1,'Expenditure Breakdown'!$W$6:$W$166, "<"&J1) -> 0 | J11: =SUMIFS('Expenditure Breakdown'!$Q$6:$Q$166, 'Expenditure Breakdown'!$W$6:$W$166, ">="&J1,'Expenditure Breakdown'!$W$6:$W$166, "<"&K1) -> 0 | K11: =SUMIFS('Expenditure Breakdown'!$Q$6:$Q$166, 'Expenditure Breakdown'!$W$6:$W$166, ">="&K1,'Expenditure Breakdown'!$W$6:$W$166, "<"&L1) -> 0 | L11: =SUMIFS('Expenditure Breakdown'!$Q$6:$Q$166, 'Expenditure Breakdown'!$W$6:$W$166, ">="&L1,'Expenditure Breakdown'!$W$6:$W$166, "<"&M1) -> 0 | M11: =SUMIFS('Expenditure Breakdown'!$Q$6:$Q$166, 'Expenditure Breakdown'!$W$6:$W$166, ">="&M1,'Expenditure Breakdown'!$W$6:$W$166, "<"&N1) -> 0 | ... KE11: =SUMIFS('Expenditure Breakdown'!$Q$6:$Q$166, 'Expenditure Breakdown'!$W$6:$W$166, ">="&KE1,'Expenditure Breakdown'!$W$6:$W$166, "<"&KF1) -> 0 | KF11: =SUMIFS('Expenditure Breakdown'!$Q$6:$Q$166, 'Expenditure Breakdown'!$W$6:$W$166, ">="&KF1,'Expenditure Breakdown'!$W$6:$W$166, "<"&#REF!) -> 0
B12: Actual + Planned Expenditure - Cumulative | F12: =F11 -> 8572.5 | G12: =F12+G11 -> 8572.5 | H12: =G12+H11 -> 8572.5 | I12: =H12+I11 -> 8572.5 | J12: =I12+J11 -> 8572.5 | K12: =J12+K11 -> 8572.5 | L12: =K12+L11 -> 8572.5 | M12: =L12+M11 -> 8572.5 | N12: =M12+N11 -> 8572.5 | ... KF12: =KE12+KF11 -> 1370745.5
B14: ACTUAL CashFlow | F14: =F10-F12 -> -8572.5 | G14: =G10-G12 -> -8572.5 | H14: =H10-H12 -> -8572.5 | I14: =I10-I12 -> -8572.5 | J14: =J10-J12 -> -7702.9348 | K14: =K10-K12 -> -7702.9348 | L14: =L10-L12 -> -7702.9348 | M14: =M10-M12 -> -7702.9348 | ... KF14: =KF10-KF12 -> 508529.88
C16: CHECK | D16: CHECK
B17: Revenue Recognition | C17: =C3-D17 -> 0 | D17: =SUM(F17:KF17) -> 1879275.4 | F17: =SUMIFS('Expenditure Breakdown'!$U$6:$U$166, 'Expenditure Breakdown'!$T$6:$T$166, ">="&F1,'Expenditure Breakdown'!$T$6:$T$166, "<"&G1) -> 0 | G17: =SUMIFS('Expenditure Breakdown'!$U$6:$U$166, 'Expenditure Breakdown'!$T$6:$T$166, ">="&G1,'Expenditure Breakdown'!$T$6:$T$166, "<"&H1) -> 0 | H17: =SUMIFS('Expenditure Breakdown'!$U$6:$U$166, 'Expenditure Breakdown'!$T$6:$T$166, ">="&H1,'Expenditure Breakdown'!$T$6:$T$166, "<"&I1) -> 0 | I17: =SUMIFS('Expenditure Breakdown'!$U$6:$U$166, 'Expenditure Breakdown'!$T$6:$T$166, ">="&I1,'Expenditure Breakdown'!$T$6:$T$166, "<"&J1) -> 0 | J17: =SUMIFS('Expenditure Breakdown'!$U$6:$U$166, 'Expenditure Breakdown'!$T$6:$T$166, ">="&J1,'Expenditure Breakdown'!$T$6:$T$166, "<"&K1) -> 0 | K17: =SUMIFS('Expenditure Breakdown'!$U$6:$U$166, 'Expenditure Breakdown'!$T$6:$T$166, ">="&K1,'Expenditure Breakdown'!$T$6:$T$166, "<"&L1) -> 0 | L17: =SUMIFS('Expenditure Breakdown'!$U$6:$U$166, 'Expenditure Breakdown'!$T$6:$T$166, ">="&L1,'Expenditure Breakdown'!$T$6:$T$166, "<"&M1) -> 0 | M17: =SUMIFS('Expenditure Breakdown'!$U$6:$U$166, 'Expenditure Breakdown'!$T$6:$T$166, ">="&M1,'Expenditure Breakdown'!$T$6:$T$166, "<"&N1) -> 9727.1945 | ... KE17: =SUMIFS('Expenditure Breakdown'!$U$6:$U$166, 'Expenditure Breakdown'!$T$6:$T$166, ">="&KE1,'Expenditure Breakdown'!$T$6:$T$166, "<"&KF1) -> 0 | KF17: =SUMIFS('Expenditure Breakdown'!$U$6:$U$166, 'Expenditure Breakdown'!$T$6:$T$166, ">="&KF1,'Expenditure Breakdown'!$T$6:$T$166, "<"&#REF!) -> 0
B18: Revenue Recognition Cumulative | C18: =D17-D18 -> -221708.67 | D18: =MAX(F18:KF18) -> 2100984.1 | F18: =F17 -> 0 | G18: =F18+G17 -> 0 | H18: =G18+H17 -> 0 | I18: =H18+I17 -> 0 | J18: =I18+J17 -> 0 | K18: =J18+K17 -> 0 | L18: =K18+L17 -> 0 | M18: =L18+M17 -> 9727.1945 | N18: =M18+N17 -> 9727.1945 | ... KF18: =KE18+KF17 -> 1879275.4

Sheet Finance - Revenue
A3: Sum of REVENUE RECOGNITION AMOUNT | B3: Column Labels
A4: Row Labels | B4: (blank) | C4: 46022 | E4: 46053 | F4: 46081 | G4: 46112 | H4: 46142 | I4: 46111 | J4: Grand Total
A5: (blank)
A6: 1. Panels | B6: 0 | D6: 0 | E6: 577060.68 | J6: 577060.68
A7: 2. Inverters | B7: 0 | D7: 0 | E7: 175000 | J7: 175000
A8: 3. Mounting Structures | D8: 0 | E8: 188842.5 | J8: 188842.5
A9: 4. DC Equipment | D9: 0 | E9: 21928.216 | F9: 100913.8 | G9: 21928.216 | H9: 4385.6431 | J9: 149155.87
A10: 5. Monitoring | D10: 0 | E10: 10517.677 | F10: 50732.323 | J10: 61250
A11: 6. AC Equipment | D11: 0 | E11: 26800.942 | F11: 205119.71 | G11: 26800.942 | H11: 5360.1883 | J11: 264081.78
A12: 8. Product Add On | B12: 0 | D12: 0 | F12: 144498.77 | I12: 18670.539 | J12: 163169.31
A13: 9. AC & DC installation | D13: 0 | E13: 37919.444 | F13: 68255 | G13: 37919.444 | H13: 7583.8889 | J13: 151677.78
A14: 10. Site Logistics | D14: 0 | E14: 7089.9731 | F14: 12761.952 | G14: 7089.9731 | H14: 1417.9946 | J14: 28359.892
A15: 11. Due Dilligence | C15: 9727.1945 | D15: 0 | G15: 89161.694 | J15: 98888.889
A16: 13. Engineering | D16: 0 | G16: 19649.809 | J16: 19649.809
A17: 14. General Expenses | D17: 0 | E17: 534.72222 | F17: 534.72222 | G17: 534.72222 | H17: 534.72222 | J17: 2138.8889
A18: 15. Service Add On
A19: 12. BDP Commission
A20: 7.BESS
A21: Grand Total | B21: 0 | C21: 9727.1945 | D21: 0 | E21: 1045694.1 | F21: 582816.28 | G21: 203084.8 | H21: 19282.437 | I21: 18670.539 | J21: 1879275.4

Sheet Finance - COS
A3: Sum of Actual Total | B3: Column Labels
A4: Row Labels | B4: (blank) | C4: 46022 | E4: 46053 | F4: 46081 | G4: 46112 | H4: 46142 | I4: 46111 | J4: Grand Total
A5: (blank)
A6: 1. Panels | B6: 0 | E6: 356240 | J6: 356240
A7: 2. Inverters | E7: 137740 | J7: 137740
A8: 3. Mounting Structures | E8: 151074 | J8: 151074
A9: 4. DC Equipment | E9: 19985.675 | F9: 91974.215 | G9: 19985.675 | H9: 3997.135 | J9: 135942.7
A10: 5. Monitoring | E10: 8500 | F10: 41000 | J10: 49500
A11: 6. AC Equipment | E11: 15351.517 | F11: 117492.09 | G11: 15351.517 | H11: 3070.3033 | J11: 151265.43
A12: 8. Product Add On | F12: 116091 | I12: 15000 | J12: 131091
A13: 9. AC & DC installation | E13: 34127.5 | F13: 61429.5 | G13: 34127.5 | H13: 6825.5 | J13: 136510
A14: 10. Site Logistics | E14: 6828.0591 | F14: 12290.506 | G14: 6828.0591 | H14: 1365.6118 | J14: 27312.236
A15: 11. Due Dilligence | C15: 8572.5 | G15: 78577.5 | J15: 87150
A16: 13. Engineering | G16: 23490.942 | J16: 23490.942
A17: 14. General Expenses | E17: 481.25 | F17: 481.25 | G17: 481.25 | H17: 481.25 | J17: 1925
A18: 15. Service Add On
A19: 12. BDP Commission | D19: 0 | J19: 0
A20: 7.BESS
A21: Grand Total | B21: 0 | C21: 8572.5 | D21: 0 | E21: 730328 | F21: 440758.56 | G21: 178842.44 | H21: 15739.8 | I21: 15000 | J21: 1389241.3

Sheet Data
C2: Public holidays | F2: Drop down list
C3: 45658 | D3: New Years Day | F3: Approved
C4: 45737 | D4: Human Rights day | F4: Pending
C5: 45765 | D5: Good Friday | F5: Declined
C6: 45768 | D6: Family Day | F6: Abanded
C7: 45774 | D7: Freedom Day
C8: 45765 | D8: Freedom DayObserved
C9: 45778 | D9: Workers day
C10: 45824 | D10: Youth Day Holiday
C11: 45878 | D11: Womens Day
C12: 45924 | D12: Heritage Day
C13: 46007 | D13: Day of Reconciliation | H13: Manual dates
C14: 46016 | D14: Christmas Day
C15: 46017 | D15: Day of Goodwill
C16: 46006 | D16: Builders Break
C17: 46007 | D17: Builders Break
C18: 46008 | D18: Builders Break
C19: 46009 | D19: Builders Break
C20: 46010 | D20: Builders Break
C21: 46011 | D21: Builders Break
C22: 46012 | D22: Builders Break
C23: 46013 | D23: Builders Break
C24: 46014 | D24: Builders Break
C25: 46015 | D25: Builders Break
... C40: 46030 | D40: Builders Break
D41: Builders Break
D42: Builders Break
D43: Builders Break
D44: Builders Break
D45: Builders Break
D46: Builders Break
D47: Builders Break
D48: Builders Break
C49: 46102 | D49: Human Rights day
C50: 46115 | D50: Good Friday
C51: 46118 | D51: Family Day
C52: 46139 | D52: Freedom Day
C53: 46143 | D53: Workers day
C54: 46189 | D54: Youth Day Holiday
C55: 46243 | D55: Womens Day
...
