Workbook

Sheet Installation Completion
A2: Solar PV Commissioning Report & Procedure
B4: SITE DETAILS
B5: Site Name
B6: Size
B7: Location
B8: Inspector
B9: Installer
B10: Date | D10: 0
B12: PRODUCT DETAILS
B13: Inverters | G13: Qty:
B14: Modules | G14: Qty:
B15: Monitoring
B16: MCCB & Relay
B17: Gen Integration
A47: Checklist of Components Installed
B49: Instructions:
B50: Do not fill in the grey areas as they are not applicable
B51: The first section of the report is a visual inspection of items already completed
B52: The second part requires measements with the necessary measurement tools
B53: Where there are special conditions or items to note please complete the notes area per section
B55: Please select Yes or No for the following: | F55: Yes/No | N55: Yes
B56: You have received the correct module and string layout | N56: No
B57: You have received the correct SLD
B58: Junction Boxes
B59: Trenching
B60: Walkways & Catladders
B61: DC Units
B62: Sensors/weather station
B63: Generator Integration
B64: Inverter Overhang and/or Enclosure
A68: Visual Installation Inspection Report
B71: TO BE DONE BEFORE COMMISSIONING TESTS
B73: ROOF | G73: Inspection 1 Accept / Reject | H73: Inspection 2 Accept / Reject
B74: 1 | C74: Has the entry roof report been completed and submitted
B75: 2 | C75: Is the current roof in good condition
B76: 3 | C76: Were there existing leaks prior to installation
B77: 4 | C77: For sheet metals with roof penetrations: Has all holes been sealed
B78: 5 | C78: High traffic areas: Has there been any damage due to foot traffic
B79: 6 | C79: High traffic areas: If yes above, has the damaged areas been fixed
B80: 7 | C80: Has the exit roof report been completed and submitted
...

Sheet Installation Test Report
A2: Testing Installation Inspection Report
A5: ATTACH SLD AND STRING LAYOUT
B6: 1 page per inverter
A7: INVERTER _______________ SERIAL NUMBER _________________
A9: Test point | C9: All new cables
A10: Reason for test | C10: Testing is performed on to confirm correct voltages, amps and no earth leakage
C11: Use appropriate tools to measure and record (eg. Seaward, Sonel PV tester)
A12: Instructions | C12: - When testing DC off, test with DC switch disconnected
C13: - When testing + to Earth and - to earth, DC must be off
C14: - For SolarEdge no need to test voltage for DC on. Confirm DC voltage from the screen/app. When testing the DC ensure that the fuses are open
C15: - For Huawei confirm DC on voltage with Sun2000 App
C16: - For others confirm with what is available
C17: - Test continuity if there are fuses
C18: - To test insulation resistance, the system must be off and disconnected from the inverter and you need a Seward or Megohmmeter. Set meter to 1000V. SURGE PROTECTION MUST BE DISCONNECTED & fuses open
A19: Reject if: | C19: - Voltage readings do not line up with the string layout
C20: - SE: High voltage between strings when system is offline i.e. anything greater than 20V
C21: - Insulation resistance is greater than 0.2 ohms
A22: Earthing | C22: Circle the method of earthing here:
C23: Earthing results can be completed in the table below or in the earthing tests section
C24: Per String | D24: Per Inverter | E24: Per Arrray | F24: Per Roof
A26: MPPT/ String | B26: Module count | C26: DC Voc (+-) | D26: + to Earth (>1M.ohm) | E26: - to Earth (>1M.ohm) | F26: Module temperature | G26: String Isc (Ampere) | H26: Irradiation (W/m2)
A27: 1 String 1
A28: 1 String 2
A29: 2 String 1
A30: 2 String 2
A31: 3 String 1
A32: 3 String 2
A33: 4 String 1
A34: 4 String 2
A35: 5 String 1
A36: 5 String 2
A37: 6 String 1
A38: 6 String 2
... A50: 12 String 2
A52: BATTERY | C52: Fuse amps | D52: DC Off V (+-) | E52: DC On V (+-) | F52: + to Earth (>1m.ohm) | G52: - to Earth (>1m.ohm) | H52: Earth Result
A53: 1
A54: 2
A55: 3
A56: 4
B58: Earthing Tests: Area ______
...

Sheet Battery Commissioning
B1: Tel: | C1: +27 21 828 4202 +27 11 028 8060
B2: E-mail: | C2: info@emergy.co.za
B3: Physical: | C3: 19 Queenspark Avenue, Salt River, Cape Town
C4: 89 Bute Lane, Sandton, Johannesburg
B5: Postal: | C5: PO Box 23877, Claremont 7735
B7: Battery Commisioning Certificate
A10: Project: | C10: ='Installation Completion'!D5 -> 0 | G10: Commissioning Date: | H10: ='Installation Completion'!D10 -> 0
A11: Date: | G11: Handover Date:
B13: Battery Details
B14: Battery 1 | G14: Battery 2
B15: Battery Brand | G15: Battery Brand
B16: Battery Type | G16: Battery Type
B17: Battery Rating | G17: Battery Rating
B18: Battery CB/Fuse rating | G18: Battery CB/Fuse rating
B20: Battery 3 | G20: Battery 4
B21: Battery Brand | G21: Battery Brand
B22: Battery Type | G22: Battery Type
B23: Battery Rating | G23: Battery Rating
B24: Battery CB/Fuse rating | G24: Battery CB/Fuse rating
B26: Battery 5 | G26: Battery 6
B27: Battery Brand | G27: Battery Brand
... B30: Battery CB/Fuse rating | G30: Battery CB/Fuse rating
B32: Battery - Voltage Checks
B33: Test Results | D33: BMS functional (Y/N) | E33: Vdc above fuse | F33: Vdc below fuse | G33: Vdc on DC box/inverter | H33: DC + to earth | I33: DC - to earth | J33: Earth bonding ≤0.2 ohm
B34: Battery 1
B35: Battery 2
B36: Battery 3
B37: Battery 4
B38: Battery 5
B39: Battery 6
B42: Battery Commissioning
B43: Commissioning Type | D43: Firmware updated (Y/N) | E43: Breaker functional (Y/N) | F43: BMS communi-cating (Y/N) | G43: Battery profile/protocol correct (Y/N) | H43: Inverter reading BMS (Y/N) | I43: Battery charge setting (A) | J43: Battery discharge setting (A)
B44: Battery 1
B45: Battery 2
B46: Battery 3
B47: Battery 4
B48: Battery 5
B49: Battery 6
B51: Notes:

Sheet Meter Commisioning Certificate
B1: Tel: | C1: +27 21 828 4202 +27 11 028 8060
B2: E-mail: | C2: info@emergy.co.za
B3: Physical: | C3: 19 Queenspark Avenue, Salt River, Cape Town
C4: 89 Bute Lane, Sandton, Johannesburg
B5: Postal: | C5: PO Box 23877, Claremont 7735
B7: Meter Commisioning Certificate
A10: Project: | C10: ='Installation Completion'!D5 -> 0 | G10: Commissioning Date: | H10: ='Installation Completion'!D10 -> 0
A11: Date: | G11: Handover Date: | H11: #VALUE!
B13: Meter Details
B14: Meter Brand
B15: Meter Type
D17: Production | E17: Consumption | F17: Export/Import
B18: Metered data
B20: Voltage Checks
B21: Test Results | D21: V1 - V2 | E21: V2 - V3 | F21: V3 - V1 | G21: V1 - N | H21: V2 - N | I21: V3 - N | J21: N - PE
B22: At Meter Breaker
B23: On the Meter
B25: Current Transformer Checks
B26: CT Brand
B27: CT Size
B28: CT Direction
B29: CT location
B31: Connection Type and testing
B32: Connection Type | D32: Ethernet | E32: Router | F32: GSM Modem
B33: Select Applicable:
B34: Data Plan
B35: Tested
B37: Notes:

Sheet Fault Notification Form
B1: Tel: | C1: +27 21 828 4202 +27 11 028 8060
B2: E-mail: | C2: info@emergy.co.za
B3: Physical: | C3: 19 Queenspark Avenue, Salt River, Cape Town
C4: 89 Bute Lane, Sandton, Johannesburg
B5: Postal: | C5: PO Box 23877, Claremont 7735
B7: Fault Notification Form
B10: Project: | C10: ='Installation Completion'!D5 -> 0 | H10: Notified By:
B11: Handover Date: | C11: ='Installation Completion'!D10 -> 0 | H11: Date Notified:
B13: CLIENT
B14: Please explain the fault? | M14: Client to xplain the issue as found
B19: What is your proposed resolution method? | M19: What the client wants
B25: EMERGENT ENERGY
B26: Investigation | M26: Response from EE
D32: Yes No | E32: Justification
B33: Fault Classification installation/component | M33: Refer to the contract definition, any open items, consequential damages from client, lack of maintenance etc etc
B37: Fault Resolution | M37: What is proposed / agree interanlly to rectify
B42: EMERGENT ENERGY | D42: Yes No | E42: Action | I42: Date Closed
B43: Fault Rectified
D46: Client Acceptance :
D47: Project Manager :
E48: Name | F48: Signature | H48: Date

Sheet O&M Handover
A2: Solar PV Handover to O&M Checklist
B4: SITE DETAILS
B5: Site Name | D5: ='Installation Completion'!D5 -> 0
B6: Size | D6: ='Installation Completion'!D6 -> 0
B7: Location | D7: ='Installation Completion'!D7 -> 0
B8: Inspector | D8: ='Installation Completion'!D8 -> 0
B9: Installer | D9: ='Installation Completion'!D9 -> 0
B10: Date | D10: ='Installation Completion'!D10 -> 0
B12: PRODUCT DETAILS
B13: Inverters | D13: ='Installation Completion'!D13 -> 0
B14: Modules | D14: ='Installation Completion'!D14 -> 0
B15: Monitoring | D15: ='Installation Completion'!D15 -> 0
A47: Projects to Matriarch Questionnaire
B50: Documentation | G50: Yes / No
B51: 1 | C51: Documents saved per the Documents Requirements sheet?
B52: 2 | C52: Final Yield confirmation from design engineer or business developer
B53: 3 | C53: Roof type _______________________
B54: =B53+1 -> 4 | C54: SolarEdge: Site mapper completed, loaded and correct?
B55: =B54+1 -> 5 | C55: Is there gen integration? If yes, who installed it?
B56: =B55+1 -> 6 | C56: Gen details provided? Which gen integration device was used _________________
B57: =B56+1 -> 7 | C57: Is there any other generator installed onsite?
B58: =B57+1 -> 8 | C58: Does export limitation need to be activated?
B59: =B58+1 -> 9 | C59: Is the clients phases balanced?
B60: =B59+1 -> 10 | C60: Purchase Contract Type: Out right purchase LTO Roof Rental
B61: =B60+1 -> 11 | C61: Maintenance Contract Type: Monitoring O&M PG
B62: =B61+1 -> 12 | C62: Are there any other monitoring platform details? Save in Document Requirements sheet
B63: =B62+1 -> 13 | C63: Internet provider? __________________
B64: =B63+1 -> 14 | C64: Has physical shutdown of the system been done in order to test the generator integration
B65: =B64+1 -> 15 | C65: Has a grid isolation test on the clients solar breaker been conducted? "Loadshedding"
... B68: =B67+1 -> 18 | C68: Are there major shading obstructions?
B69: Notes:
B72: Onsite Contact/Access Details | G72: Yes / No
B73: 1 | C73: Who installed the PV system? ______________________________ Provide contact details below.
B74: =B73+1 -> 2 | C74: Owner name, contact number and contact email: ________________________________________________ Portfolio Client?_______________________
B75: =B74+1 -> 3 | C75: Maintenance contact name, contact number and contact email:
B76: =B75+1 -> 4 | C76: Is there security control when accessing the site? Provide access details below Yes No
B77: =B76+1 -> 5 | C77: Detail H&S requirements. I.e. Do we need to submit a H&S file, wear harness, etc.?
B78: =B77+1 -> 6 | C78: List inverter access details. I.e. Padlock key to be collected at security, ladder, location, etc.
B79: =B78+1 -> 7 | C79: List combiner box access details. I.e. Padlock key to be collected at security, ladder, location, etc.
B80: =B79+1 -> 8 | C80: List roof access details. I.e. Padlock key to be collected at security, ladder, etc.
...

Sheet Document Requirements
A1: Phase | B1: Document | C1: Responsible | D1: Location
A2: Pre-Construction | B2: Final Costing Sheet | C2: Sales | D2: D:\Dropbox (Emergent Energy)\Emergent Energy Team Folder\01 - Clients\01 - active projects (1)\PROJECT_NAME\PM\0. Planning\Final Costing and CP
B3: Signed Cost Proposal | C3: Sales | D3: D:\Dropbox (Emergent Energy)\Emergent Energy Team Folder\01 - Clients\01 - active projects (1)\PROJECT_NAME\PM\0. Planning\Final Design Details
B4: Signed O&M Contract | C4: Sales | D4: D:\Dropbox (Emergent Energy)\Emergent Energy Team Folder\01 - Clients\01 - active projects (1)\PROJECT_NAME\PM\1. Contractual and Admin
B5: Consumption Details/Considerations | C5: Sales/Designer | D5: To be discussed with Sales/Designer
B6: Final PV Sol Design | C6: Designer/PM | D6: D:\Dropbox (Emergent Energy)\Emergent Energy Team Folder\01 - Clients\01 - active projects (1)\PROJECT_NAME\PM\0. Planning\Final Design Details
B7: CSV File from PV Sol | C7: Designer/PM | D7: D:\Dropbox (Emergent Energy)\Emergent Energy Team Folder\01 - Clients\01 - active projects (1)\PROJECT_NAME\PM\0. Planning\Final Design Details
B8: Structural Engineers Report | C8: Projects Team | D8: D:\Dropbox (Emergent Energy)\Emergent Energy Team Folder\01 - Clients\01 - active projects (1)\PROJECT_NAME\PM\4. Commissioning\Commissioning Report\Appendices
B9: Single Line Diagram | C9: Designer/PM | D9: D:\Dropbox (Emergent Energy)\Emergent Energy Team Folder\01 - Clients\01 - active projects (1)\PROJECT_NAME\PM\3. Construction\Drawings\Electrical
B10: If applicable: Spares List | C10: Sales | D10: D:\Dropbox (Emergent Energy)\Emergent Energy Team Folder\01 - Clients\01 - active projects (1)\PROJECT_NAME\PM\4. Commissioning\Commissioning Report\Appendices
B11: Entry Roof Report | C11: Projects Team | D11: D:\Dropbox (Emergent Energy)\Emergent Energy Team Folder\01 - Clients\01 - active projects (1)\PROJECT_NAME\PM\4. Commissioning\Commissioning Report\Appendices
B12: SSEG Documentation Installation Approval | C12: Designer | D12: D:\Dropbox (Emergent Energy)\Emergent Energy Team Folder\01 - Clients\01 - active projects (1)\PROJECT_NAME\PM\4. Commissioning\SSEG
A13: Post Construction | B13: Red Team Inspection Forms | C13: Red Team | D13: D:\Dropbox (Emergent Energy)\Emergent Energy Team Folder\01 - Clients\01 - active projects (1)\PROJECT_NAME\PM\5. Quality Control
B14: Inverter Seward Test Results/Commissioning Forms | C14: PM | D14: D:\Dropbox (Emergent Energy)\Emergent Energy Team Folder\01 - Clients\01 - active projects (1)\PROJECT_NAME\PM\4. Commissioning\Commissioning Forms
B15: Continuity Tests | C15: PM | D15: D:\Dropbox (Emergent Energy)\Emergent Energy Team Folder\01 - Clients\01 - active projects (1)\PROJECT_NAME\PM\4. Commissioning\Commissioning Forms
B16: AC Tests | C16: PM | D16: D:\Dropbox (Emergent Energy)\Emergent Energy Team Folder\01 - Clients\01 - active projects (1)\PROJECT_NAME\PM\4. Commissioning\Commissioning Forms
B17: Meter Commissioning | C17: PM | D17: D:\Dropbox (Emergent Energy)\Emergent Energy Team Folder\01 - Clients\01 - active projects (1)\PROJECT_NAME\PM\4. Commissioning\Commissioning Forms
B18: Site Layout Drawing | C18: PM | D18: D:\Dropbox (Emergent Energy)\Emergent Energy Team Folder\01 - Clients\01 - active projects (1)\PROJECT_NAME\PM\4. Commissioning\Commissioning Report\Appendices
B19: Communication SLD - with IP's | C19: Designer/PM | D19: D:\Dropbox (Emergent Energy)\Emergent Energy Team Folder\01 - Clients\01 - active projects (1)\PROJECT_NAME\PM\3. Construction\Drawings
B20: Commissioning Report | C20: PM | D20: D:\Dropbox (Emergent Energy)\Emergent Energy Team Folder\01 - Clients\01 - active projects (1)\PROJECT_NAME\PM\4. Commissioning\Commissioning Report
B21: PR Eng Signoff | C21: Projects Team | D21: D:\Dropbox (Emergent Energy)\Emergent Energy Team Folder\01 - Clients\01 - active projects (1)\PROJECT_NAME\PM\4. Commissioning\SSEG
B22: COC | C22: Projects Team | D22: D:\Dropbox (Emergent Energy)\Emergent Energy Team Folder\01 - Clients\01 - active projects (1)\PROJECT_NAME\PM\4. Commissioning\Commissioning Report\Appendices
B23: Product Datasheets | C23: PM | D23: D:\Dropbox (Emergent Energy)\Emergent Energy Team Folder\01 - Clients\01 - active projects (1)\PROJECT_NAME\PM\4. Commissioning\Commissioning Report\Appendices
B24: Product Warranty Documentation | C24: PM | D24: D:\Dropbox (Emergent Energy)\Emergent Energy Team Folder\01 - Clients\01 - active projects (1)\PROJECT_NAME\PM\4. Commissioning\Commissioning Report\Appendices
B25: Installer Defects Form | C25: Projects Team | D25: D:\Dropbox (Emergent Energy)\Emergent Energy Team Folder\01 - Clients\01 - active projects (1)\PROJECT_NAME\PM\4. Commissioning\Commissioning Report\Appendices
... B27: SSEG Documentation Commissioning Approval | C27: Designer | D27: D:\Dropbox (Emergent Energy)\Emergent Energy Team Folder\01 - Clients\01 - active projects (1)\PROJECT_NAME\PM\4. Commissioning\SSEG
B28: Exit Roof Report | D28: D:\Dropbox (Emergent Energy)\Emergent Energy Team Folder\01 - Clients\01 - active projects (1)\PROJECT_NAME\PM\4. Commissioning\Commissioning Report\Appendices
B29: Photos: | C29: PM | D29: D:\Dropbox (Emergent Energy)\Emergent Energy Team Folder\01 - Clients\01 - active projects (1)\PROJECT_NAME\PM\3. Construction\Photographs
B30: - Inverter Inputs
B31: - Inverter Room
B32: - PV Module Installation
B33: - AC DB: with connections
B34: - Comms DB
B35: - Client Solar Breaker
B36: - Relays: Both
B37: - Client DB Room
B38: - Earthing

Sheet End of Defects
B1: Tel: | C1: +27 21 828 4202 +27 11 028 8060
B2: E-mail: | C2: info@emergy.co.za
B3: Physical: | C3: 19 Queenspark Avenue, Salt River, Cape Town
C4: 89 Bute Lane, Sandton, Johannesburg
B5: Postal: | C5: PO Box 23877, Claremont 7735
B7: End of Defects
L8: These Guidelines and Instructions can be include in the RFQ data pack template to be sent to the installer for quoting. The project specification should be expanded to include all of this information as a single source of info for the installer. Also, ICS is to form the basis of the new Installer Completion Certificate and Pre-commission tests
B10: Project: | C10: #VALUE! | G10: Installer: | H10: #VALUE!
B11: Date: | G11: For Installer:
G12: For Emergent Energy:
B14: VOLTAGES TO BE COMPARED WITH COMMISSIONING REPORT RESULTS
B16: MOUNTING STRUCTURE | H16: Pass | I16: Fail
B17: 1 | C17: Rust on bolts
B18: =B17+1 -> 2 | C18: Rust on mounting structure
B19: =B18+1 -> 3 | C19: Damaged mounting structure
B20: =B19+1 -> 4 | C20: Module clamps in correct position
B21: Notes:
B24: PV MODULES | H24: Pass | I24: Fail
B25: 1 | C25: PV modules secure in place
B26: =B25+1 -> 2 | C26: No damaged modules
B27: =B26+1 -> 3 | C27: No damaged cells
B28: Notes:
B31: TRUNKING, CABLE ROUTE & COMBINER BOXES | H31: Pass | I31: Fail
B32: 1 | C32: All trunking still in place i.e. in place securely
B33: =B32+1 -> 2 | C33: No cables are exposed in trunking | M33: OK□ No OK□
B34: =B33+1 -> 3 | C34: All glands still in place | M34: □ □
B35: =B34+1 -> 4 | C35: Cables are neatly attached to sub-structure
B36: =B35+1 -> 5 | C36: All tagging is still in place | M36: Emergent Accept / Reject
B37: =B36+1 -> 6 | C37: All tagging is still visible | M37: Emergent
B38: =B37+1 -> 7 | C38: Combiner boxes securely mounted
B39: =B38+1 -> 8 | C39: Tagging still visible on combiner boxes
B40: =B39+1 -> 9 | C40: Fuses functioning properly
B41: Notes:
B44: CHECKLIST FOR INVERTER | H44: Pass | I44: Fail
B45: 1 | C45: Confirm DC voltage of each MPPT
B46: =B45+1 -> 2 | C46: Confirm DC amps for each MPPT
B47: =B46+1 -> 3 | C47: Confirm AC voltage and amps
B48: =B47+1 -> 4 | C48: Inverter fan replacement warning light not on
B49: =B48+1 -> 5 | C49: All ducting and glands are in place and secure
B50: =B49+1 -> 6 | C50: Inverter labelled
...
