Workbook

Sheet Inverter 1
B1: SITE: | C1: Kroonstad PnP | F1: DATE: | G1: 22/09/2025 | J1: INVERTER 1
B3: Open Circuit volatge test
C7: S1 | D7: S2 | E7: S3 | F7: S4 | G7: S5 | H7: S6 | I7: S7 | J7: S8 | K7: S9 | L7: S10 | M7: S11 | N7: S12 | O7: S13 | P7: S14 | Q7: S15 | R7: S16 | S7: S17 | T7: S18 | U7: S19 | V7: S20
B8: V_theo | C8: =AA9*$AA$18+(1+$AA$19*($AA$15-25)) -> 884.69 | D8: =AB9*$AA$18+(1+$AA$19*($AB$15-25)) -> 884.44 | E8: =AC9*$AA$18+(1+$AA$19*($AC$15-25)) -> 884.44 | F8: =AD9*$AA$18+(1+$AA$19*($AD$15-25)) -> 884.44 | G8: =AE9*$AA$18+(1+$AA$19*($AE$15-25)) -> 884.44 | H8: =AF9*$AA$18+(1+$AA$19*($AF$15-25)) -> 884.44 | I8: =AG9*$AA$18+(1+$AA$19*($AG$15-25)) -> 884.44 | J8: =AH9*$AA$18+(1+$AA$19*($AH$15-25)) -> 884.44 | K8: =AI9*$AA$18+(1+$AA$19*($AI$15-25)) -> 884.44 | L8: =AJ9*$AA$18+(1+$AA$19*($AJ$15-25)) -> 884.44 | M8: =AK9*$AA$18+(1+$AA$19*($AK$15-25)) -> 884.44 | N8: =AL9*$AA$18+(1+$AA$19*($AL$15-25)) -> 884.44 | O8: =AM9*$AA$18+(1+$AA$19*($AM$15-25)) -> 1 | P8: =AN9*$AA$18+(1+$AA$19*($AN$15-25)) -> 1 | Q8: =AO9*$AA$18+(1+$AA$19*($AO$15-25)) -> 1 | R8: =AP9*$AA$18+(1+$AA$19*($AP$15-25)) -> 1 | S8: =AQ9*$AA$18+(1+$AA$19*($AQ$15-25)) -> 1 | T8: =AR9*$AA$18+(1+$AA$19*($AR$15-25)) -> 1 | U8: =AS9*$AA$18+(1+$AA$19*($AS$15-25)) -> 1 | V8: =AT9*$AA$18+(1+$AA$19*($AT$15-25)) -> 1 | Z8: Inverter 1 | AA8: S1 | AB8: S2 | AC8: S3 | AD8: S4 | AE8: S5 | AF8: S6 | AG8: S7 | AH8: S8 | AI8: S9 | AJ8: S10 | AK8: S11 | AL8: S12 | AM8: S13 | AN8: S14 | AO8: S15 | AP8: S16 | AQ8: S17 | AR8: S18 | AS8: S19 | AT8: S20
B9: (1-7%) | C9: =C8*(1-7%) -> 822.7617 | D9: =D8*(1-7%) -> 822.5292 | E9: =E8*(1-7%) -> 822.5292 | F9: =F8*(1-7%) -> 822.5292 | G9: =G8*(1-7%) -> 822.5292 | H9: =H8*(1-7%) -> 822.5292 | I9: =I8*(1-7%) -> 822.5292 | J9: =J8*(1-7%) -> 822.5292 | ... V9: =V8*(1-7%) -> 0.93 | Z9: Module No. | AA9: 18 | AB9: 18 | AC9: 18 | AD9: 18 | AE9: 18 | AF9: 18 | AG9: 18 | AH9: 18 | AI9: 18 | AJ9: 18 | AK9: 18 | AL9: 18
B10: (1+7%) | C10: =C8*(1+7%) -> 946.6183 | D10: =D8*(1+7%) -> 946.3508 | E10: =E8*(1+7%) -> 946.3508 | F10: =F8*(1+7%) -> 946.3508 | G10: =G8*(1+7%) -> 946.3508 | H10: =H8*(1+7%) -> 946.3508 | I10: =I8*(1+7%) -> 946.3508 | J10: =J8*(1+7%) -> 946.3508 | ... V10: =V8*(1+7%) -> 1.07 | Z10: Open Circuit Voltage (Voc in V) | AA10: 826 | AB10: 825 | AC10: 823 | AD10: 824 | AE10: 829 | AF10: 823 | AG10: 823 | AH10: 823 | AI10: 829 | AJ10: 829 | AK10: 829 | AL10: 828
Z11: Short Circuit Voltage (Vsc in V) | AA11: =AA10-((AA18-AA20)*AA9) -> 675.88 | AB11: =AB10-((AA18-AA20)*AB9) -> 674.88 | AC11: =AC10-((AA18-AA20)*AC9) -> 672.88 | AD11: =AD10-((AA18-AA20)*AD9) -> 673.88 | AE11: =AE10-((AA18-AA20)*AE9) -> 678.88 | AF11: =AF10-((AA18-AA20)*AF9) -> 672.88 | AG11: =AG10-((AA18-AA20)*AG9) -> 672.88 | AH11: =AH10-((AA18-AA20)*AH9) -> 672.88 | AI11: =AI10-((AA18-AA20)*AI9) -> 678.88 | AJ11: =AJ10-((AA18-AA20)*AJ9) -> 678.88 | AK11: =AK10-((AA18-AA20)*AK9) -> 678.88 | AL11: =AL10-((AA18-AA20)*AL9) -> 677.88 | AM11: =AM10-((AA18-AA20)*AM9) -> 0 | AN11: =AN10-((AA18-AA20)*AN9) -> 0 | AO11: =AO10-((AA18-AA20)*AO9) -> 0 | AP11: =AP10-((AA18-AA20)*AP9) -> 0 | AQ11: =AQ10-((AA18-AA20)*AQ9) -> 0 | AR11: =AR10-((AA18-AA20)*AR9) -> 0 | AS11: =AS10-((AA18-AA20)*AS9) -> 0 | AT11: =AT10-((AA18-AA20)*AT9) -> 0
Z12: Insulation Resistance (mΩ) | AA12: 323.3 | AB12: 337.7 | AC12: 315 | AD12: 327 | AE12: 377 | AF12: 388 | AG12: 383 | AH12: 408 | AI12: 374 | AJ12: 365 | AK12: 376 | AL12: 356
C13: =IF(AND(C9<AA10,AA10<C10),"Passed","Failed") -> Passed | D13: =IF(AND(D9<AB10,AB10<D10),"Passed","Failed") -> Passed | E13: =IF(AND(E9<AC10,AC10<E10),"Passed","Failed") -> Passed | F13: =IF(AND(F9<AD10,AD10<F10),"Passed","Failed") -> Passed | G13: =IF(AND(G9<AE10,AE10<G10),"Passed","Failed") -> Passed | H13: =IF(AND(H9<AF10,AF10<H10),"Passed","Failed") -> Passed | I13: =IF(AND(I9<AG10,AG10<I10),"Passed","Failed") -> Passed | J13: =IF(AND(J9<AH10,AH10<J10),"Passed","Failed") -> Passed | ... V13: =IF(AND(V9<AT10,AT10<V10),"Passed","Failed") -> Failed | Z13: Irradiance (W) | AA13: 647 | AB13: 603 | AC13: 646 | AD13: 642 | AE13: 630 | AF13: 642 | AG13: 628 | AH13: 637 | AI13: 634 | AJ13: 648 | AK13: 651 | AL13: 598
O14: N/A | P14: N/A | Q14: N/A | R14: N/A | S14: N/A | T14: N/A | U14: N/A | V14: N/A | Z14: Isc (A) | AA14: 10.37 | AB14: 11.01 | AC14: 10.41 | AD14: 10.49 | AE14: 10.52 | AF14: 10.41 | AG14: 10.46 | AH14: 10.5 | AI14: 10.48 | AJ14: 10.53 | AK14: 10.45 | AL14: 10.45
Z15: Cell Temp | AA15: 24 | AB15: 25 | AC15: 25 | AD15: 25 | AE15: 25 | AF15: 25 | AG15: 25 | AH15: 25 | AI15: 25 | AJ15: 25 | AK15: 25 | AL15: 25 | AM15: 25 | AN15: 25 | AO15: 25 | AP15: 25 | AQ15: 25 | AR15: 25 | AS15: 25 | AT15: 25
C17: S1 | D17: S2 | E17: S3 | F17: S4 | G17: S5 | H17: S6 | I17: S7 | J17: S8 | K17: S9 | L17: S10 | M17: S11 | N17: S12 | O17: S13 | P17: S14 | Q17: S15 | R17: S16 | S17: S17 | T17: S18 | U17: S19 | V17: S20 | Z17: Module Details
B18: I_theo | C18: =($AA$22*(AA13/$AA$25))+(1+$AA$24*($AA$15-25)) -> 11.35876 | D18: =($AA$22*(AB13/$AA$25))+(1+$AA$24*($AB$15-25)) -> 10.69624 | E18: =($AA$22*(AC13/$AA$25))+(1+$AA$24*($AC$15-25)) -> 11.38768 | F18: =($AA$22*(AD13/$AA$25))+(1+$AA$24*($AD$15-25)) -> 11.32336 | G18: =($AA$22*(AE13/$AA$25))+(1+$AA$24*($AE$15-25)) -> 11.1304 | H18: =($AA$22*(AF13/$AA$25))+(1+$AA$24*($AF$15-25)) -> 11.32336 | I18: =($AA$22*(AG13/$AA$25))+(1+$AA$24*($AG$15-25)) -> 11.09824 | J18: =($AA$22*(AH13/$AA$25))+(1+$AA$24*($AH$15-25)) -> 11.24296 | K18: =($AA$22*(AI13/$AA$25))+(1+$AA$24*($AI$15-25)) -> 11.19472 | L18: =($AA$22*(AJ13/$AA$25))+(1+$AA$24*($AJ$15-25)) -> 11.41984 | M18: =($AA$22*(AK13/$AA$25))+(1+$AA$24*($AK$15-25)) -> 11.46808 | N18: =($AA$22*(AL13/$AA$25))+(1+$AA$24*($AL$15-25)) -> 10.61584 | O18: =($AA$22*(AM13/$AA$25))+(1+$AA$24*($AM$15-25)) -> 1 | P18: =($AA$22*(AN13/$AA$25))+(1+$AA$24*($AN$15-25)) -> 1 | Q18: =($AA$22*(AO13/$AA$25))+(1+$AA$24*($AO$15-25)) -> 1 | R18: =($AA$22*(AP13/$AA$25))+(1+$AA$24*($AP$15-25)) -> 1 | S18: =($AA$22*(AQ13/$AA$25))+(1+$AA$24*($AQ$15-25)) -> 1 | T18: =($AA$22*(AR13/$AA$25))+(1+$AA$24*($AR$15-25)) -> 1 | U18: =($AA$22*(AS13/$AA$25))+(1+$AA$24*($AS$15-25)) -> 1 | V18: =($AA$22*(AT13/$AA$25))+(1+$AA$24*($AT$15-25)) -> 1 | Z18: Vo | AA18: 49.08 | AB18: V | AC18: Jinko 620 BDV
B19: (1-10%) | C19: =C18*(1-10%) -> 10.222884 | D19: =D18*(1-10%) -> 9.626616 | E19: =E18*(1-10%) -> 10.248912 | F19: =F18*(1-10%) -> 10.191024 | G19: =G18*(1-10%) -> 10.01736 | H19: =H18*(1-10%) -> 10.191024 | I19: =I18*(1-10%) -> 9.988416 | J19: =J18*(1-10%) -> 10.118664 | ... V19: =V18*(1-10%) -> 0.9 | Z19: CT | AA19: -0.25 | AB19: %/Degree C | AC19: Temperature coefficient
B20: (1+10%) | C20: =C18*(1+10%) -> 12.494636 | D20: =D18*(1+10%) -> 11.765864 | E20: =E18*(1+10%) -> 12.526448 | F20: =F18*(1+10%) -> 12.455696 | G20: =G18*(1+10%) -> 12.24344 | H20: =H18*(1+10%) -> 12.455696 | I20: =I18*(1+10%) -> 12.208064 | J20: =J18*(1+10%) -> 12.367256 | ... V20: =V18*(1+10%) -> 1.1 | Z20: Vsc | AA20: 40.74 | AB20: V
B21: Isc (A) | C21: =AA14 -> 10.37 | D21: =AB14 -> 11.01 | E21: =AC14 -> 10.41 | F21: =AD14 -> 10.49 | G21: =AE14 -> 10.52 | H21: =AF14 -> 10.41 | I21: =AG14 -> 10.46 | J21: =AH14 -> 10.5 | ... V21: =AT14 -> 0
Z22: Iscm | AA22: 16.08 | AB22: A | AC22: Nominal short circuit of pv modules from data sheet
Z23: I | AA23: Table above | AB23: W/m^2 | AC23: Irradiation on on strings of tested panel
C24: =IF(AND(C19<C21,C21<C20),"Passed","Failed") -> Passed | D24: =IF(AND(D19<D21,D21<D20),"Passed","Failed") -> Passed | E24: =IF(AND(E19<E21,E21<E20),"Passed","Failed") -> Passed | F24: =IF(AND(F19<F21,F21<F20),"Passed","Failed") -> Passed | G24: =IF(AND(G19<G21,G21<G20),"Passed","Failed") -> Passed | H24: =IF(AND(H19<H21,H21<H20),"Passed","Failed") -> Passed | I24: =IF(AND(I19<I21,I21<I20),"Passed","Failed") -> Passed | J24: =IF(AND(J19<J21,J21<J20),"Passed","Failed") -> Passed | ... V24: =IF(AND(V19<V21,V21<V20),"Passed","Failed") -> Failed | Z24: C_I | AA24: 0.045 | AB24: %/Degree C | AC24: Current Temp coefficient
O25: N/A | P25: N/A | Q25: N/A | R25: N/A | S25: N/A | T25: N/A | U25: N/A | V25: N/A | Z25: I_STC | AA25: 1000 | AB25: W/m^2 | AC25: Standard irradiation

Sheet Inverter 2
B1: SITE: | C1: ='Inverter 1'!C1 -> Kroonstad PnP | F1: DATE: | G1: 22/09/2025 | J1: INVERTER 2
B3: Open Circuit volatge test
C7: S1 | D7: S2 | E7: S3 | F7: S4 | G7: S5 | H7: S6 | I7: S7 | J7: S8 | K7: S9 | L7: S10 | M7: S11 | N7: S12 | O7: S13 | P7: S14 | Q7: S15 | R7: S16 | S7: S17 | T7: S18 | U7: S19 | V7: S20
B8: V_theo | C8: =AA9*$AA$18+(1+$AA$19*($AA$15-25)) -> 884.44 | D8: =AB9*$AA$18+(1+$AA$19*($AB$15-25)) -> 884.44 | E8: =AC9*$AA$18+(1+$AA$19*($AC$15-25)) -> 884.44 | F8: =AD9*$AA$18+(1+$AA$19*($AD$15-25)) -> 884.44 | G8: =AE9*$AA$18+(1+$AA$19*($AE$15-25)) -> 884.44 | H8: =AF9*$AA$18+(1+$AA$19*($AF$15-25)) -> 835.36 | I8: =AG9*$AA$18+(1+$AA$19*($AG$15-25)) -> 786.28 | J8: =AH9*$AA$18+(1+$AA$19*($AH$15-25)) -> 786.28 | K8: =AI9*$AA$18+(1+$AA$19*($AI$15-25)) -> 884.44 | L8: =AJ9*$AA$18+(1+$AA$19*($AJ$15-25)) -> 884.44 | M8: =AK9*$AA$18+(1+$AA$19*($AK$15-25)) -> 884.44 | N8: =AL9*$AA$18+(1+$AA$19*($AL$15-25)) -> 884.44 | O8: =AM9*$AA$18+(1+$AA$19*($AM$15-25)) -> 1 | P8: =AN9*$AA$18+(1+$AA$19*($AN$15-25)) -> 1 | Q8: =AO9*$AA$18+(1+$AA$19*($AO$15-25)) -> 1 | R8: =AP9*$AA$18+(1+$AA$19*($AP$15-25)) -> 1 | S8: =AQ9*$AA$18+(1+$AA$19*($AQ$15-25)) -> 1 | T8: =AR9*$AA$18+(1+$AA$19*($AR$15-25)) -> 1 | U8: =AS9*$AA$18+(1+$AA$19*($AS$15-25)) -> 1 | V8: =AT9*$AA$18+(1+$AA$19*($AT$15-25)) -> 1 | Z8: Inverter 2 | AA8: S1 | AB8: S2 | AC8: S3 | AD8: S4 | AE8: S5 | AF8: S6 | AG8: S7 | AH8: S8 | AI8: S9 | AJ8: S10 | AK8: S11 | AL8: S12 | AM8: S13 | AN8: S14 | AO8: S15 | AP8: S16 | AQ8: S17 | AR8: S18 | AS8: S19 | AT8: S20
B9: (1-7%) | C9: =C8*(1-7%) -> 822.5292 | D9: =D8*(1-7%) -> 822.5292 | E9: =E8*(1-7%) -> 822.5292 | F9: =F8*(1-7%) -> 822.5292 | G9: =G8*(1-7%) -> 822.5292 | H9: =H8*(1-7%) -> 776.8848 | I9: =I8*(1-7%) -> 731.2404 | J9: =J8*(1-7%) -> 731.2404 | ... V9: =V8*(1-7%) -> 0.93 | Z9: Module No. | AA9: 18 | AB9: 18 | AC9: 18 | AD9: 18 | AE9: 18 | AF9: 17 | AG9: 16 | AH9: 16 | AI9: 18 | AJ9: 18 | AK9: 18 | AL9: 18
B10: (1+7%) | C10: =C8*(1+7%) -> 946.3508 | D10: =D8*(1+7%) -> 946.3508 | E10: =E8*(1+7%) -> 946.3508 | F10: =F8*(1+7%) -> 946.3508 | G10: =G8*(1+7%) -> 946.3508 | H10: =H8*(1+7%) -> 893.8352 | I10: =I8*(1+7%) -> 841.3196 | J10: =J8*(1+7%) -> 841.3196 | ... V10: =V8*(1+7%) -> 1.07 | Z10: Open Circuit Voltage (Voc in V) | AA10: 827 | AB10: 826 | AC10: 824 | AD10: 826 | AE10: 824 | AF10: 778 | AG10: 732 | AH10: 733 | AI10: 823 | AJ10: 829 | AK10: 823 | AL10: 828
Z11: Short Circuit Voltage (Vsc in V) | AA11: =AA10-((AA18-AA20)*AA9) -> 676.88 | AB11: =AB10-((AA18-AA20)*AB9) -> 675.88 | AC11: =AC10-((AA18-AA20)*AC9) -> 673.88 | AD11: =AD10-((AA18-AA20)*AD9) -> 675.88 | AE11: =AE10-((AA18-AA20)*AE9) -> 673.88 | AF11: =AF10-((AA18-AA20)*AF9) -> 636.22 | AG11: =AG10-((AA18-AA20)*AG9) -> 598.56 | AH11: =AH10-((AA18-AA20)*AH9) -> 599.56 | AI11: =AI10-((AA18-AA20)*AI9) -> 672.88 | AJ11: =AJ10-((AA18-AA20)*AJ9) -> 678.88 | AK11: =AK10-((AA18-AA20)*AK9) -> 672.88 | AL11: =AL10-((AA18-AA20)*AL9) -> 677.88 | AM11: =AM10-((AA18-AA20)*AM9) -> 0 | AN11: =AN10-((AA18-AA20)*AN9) -> 0 | AO11: =AO10-((AA18-AA20)*AO9) -> 0 | AP11: =AP10-((AA18-AA20)*AP9) -> 0 | AQ11: =AQ10-((AA18-AA20)*AQ9) -> 0 | AR11: =AR10-((AA18-AA20)*AR9) -> 0 | AS11: =AS10-((AA18-AA20)*AS9) -> 0 | AT11: =AT10-((AA18-AA20)*AT9) -> 0
Z12: Insulation Resistance (mΩ) | AA12: 366 | AB12: 356 | AC12: 345 | AD12: 358 | AE12: 357 | AF12: 411 | AG12: 450 | AH12: 427 | AI12: 414 | AJ12: 407 | AK12: 358 | AL12: 392
C13: =IF(AND(C9<AA10,AA10<C10),"Passed","Failed") -> Passed | D13: =IF(AND(D9<AB10,AB10<D10),"Passed","Failed") -> Passed | E13: =IF(AND(E9<AC10,AC10<E10),"Passed","Failed") -> Passed | F13: =IF(AND(F9<AD10,AD10<F10),"Passed","Failed") -> Passed | G13: =IF(AND(G9<AE10,AE10<G10),"Passed","Failed") -> Passed | H13: =IF(AND(H9<AF10,AF10<H10),"Passed","Failed") -> Passed | I13: =IF(AND(I9<AG10,AG10<I10),"Passed","Failed") -> Passed | J13: =IF(AND(J9<AH10,AH10<J10),"Passed","Failed") -> Passed | ... V13: =IF(AND(V9<AT10,AT10<V10),"Passed","Failed") -> Failed | Z13: Irradiance (W) | AA13: 636 | AB13: 644 | AC13: 633 | AD13: 644 | AE13: 641 | AF13: 634 | AG13: 598 | AH13: 590 | AI13: 592 | AJ13: 617 | AK13: 635 | AL13: 632
O14: N/A | P14: N/A | Q14: N/A | R14: N/A | S14: N/A | T14: N/A | U14: N/A | V14: N/A | Z14: Isc (A) | AA14: 10.65 | AB14: 10.6 | AC14: 10.48 | AD14: 10.6 | AE14: 10.6 | AF14: 10.38 | AG14: 9.87 | AH14: 9.82 | AI14: 9.84 | AJ14: 10.09 | AK14: 10.19 | AL14: 10.14
Z15: Cell Temp | AA15: 25 | AB15: 25 | AC15: 25 | AD15: 25 | AE15: 25 | AF15: 25 | AG15: 25 | AH15: 25 | AI15: 25 | AJ15: 25 | AK15: 25 | AL15: 25 | AM15: 25 | AN15: 25 | AO15: 25 | AP15: 25 | AQ15: 25 | AR15: 25 | AS15: 25 | AT15: 25
C17: S1 | D17: S2 | E17: S3 | F17: S4 | G17: S5 | H17: S6 | I17: S7 | J17: S8 | K17: S9 | L17: S10 | M17: S11 | N17: S12 | O17: S13 | P17: S14 | Q17: S15 | R17: S16 | S17: S17 | T17: S18 | U17: S19 | V17: S20 | Z17: Module Details
B18: I_theo | C18: =($AA$22*(AA13/$AA$25))+(1+$AA$24*($AA$15-25)) -> 11.22688 | D18: =($AA$22*(AB13/$AA$25))+(1+$AA$24*($AB$15-25)) -> 11.35552 | E18: =($AA$22*(AC13/$AA$25))+(1+$AA$24*($AC$15-25)) -> 11.17864 | F18: =($AA$22*(AD13/$AA$25))+(1+$AA$24*($AD$15-25)) -> 11.35552 | G18: =($AA$22*(AE13/$AA$25))+(1+$AA$24*($AE$15-25)) -> 11.30728 | H18: =($AA$22*(AF13/$AA$25))+(1+$AA$24*($AF$15-25)) -> 11.19472 | I18: =($AA$22*(AG13/$AA$25))+(1+$AA$24*($AG$15-25)) -> 10.61584 | J18: =($AA$22*(AH13/$AA$25))+(1+$AA$24*($AH$15-25)) -> 10.4872 | K18: =($AA$22*(AI13/$AA$25))+(1+$AA$24*($AI$15-25)) -> 10.51936 | L18: =($AA$22*(AJ13/$AA$25))+(1+$AA$24*($AJ$15-25)) -> 10.92136 | M18: =($AA$22*(AK13/$AA$25))+(1+$AA$24*($AK$15-25)) -> 11.2108 | N18: =($AA$22*(AL13/$AA$25))+(1+$AA$24*($AL$15-25)) -> 11.16256 | O18: =($AA$22*(AM13/$AA$25))+(1+$AA$24*($AM$15-25)) -> 1 | P18: =($AA$22*(AN13/$AA$25))+(1+$AA$24*($AN$15-25)) -> 1 | Q18: =($AA$22*(AO13/$AA$25))+(1+$AA$24*($AO$15-25)) -> 1 | R18: =($AA$22*(AP13/$AA$25))+(1+$AA$24*($AP$15-25)) -> 1 | S18: =($AA$22*(AQ13/$AA$25))+(1+$AA$24*($AQ$15-25)) -> 1 | T18: =($AA$22*(AR13/$AA$25))+(1+$AA$24*($AR$15-25)) -> 1 | U18: =($AA$22*(AS13/$AA$25))+(1+$AA$24*($AS$15-25)) -> 1 | V18: =($AA$22*(AT13/$AA$25))+(1+$AA$24*($AT$15-25)) -> 1 | Z18: Vo | AA18: 49.08 | AB18: V | AC18: Jinko 620 BDV
B19: (1-10%) | C19: =C18*(1-10%) -> 10.104192 | D19: =D18*(1-10%) -> 10.219968 | E19: =E18*(1-10%) -> 10.060776 | F19: =F18*(1-10%) -> 10.219968 | G19: =G18*(1-10%) -> 10.176552 | H19: =H18*(1-10%) -> 10.075248 | I19: =I18*(1-10%) -> 9.554256 | J19: =J18*(1-10%) -> 9.43848 | ... V19: =V18*(1-10%) -> 0.9 | Z19: CT | AA19: -0.25 | AB19: %/Degree C | AC19: Temperature coefficient
B20: (1+10%) | C20: =C18*(1+10%) -> 12.349568 | D20: =D18*(1+10%) -> 12.491072 | E20: =E18*(1+10%) -> 12.296504 | F20: =F18*(1+10%) -> 12.491072 | G20: =G18*(1+10%) -> 12.438008 | H20: =H18*(1+10%) -> 12.314192 | I20: =I18*(1+10%) -> 11.677424 | J20: =J18*(1+10%) -> 11.53592 | ... V20: =V18*(1+10%) -> 1.1 | Z20: Vsc | AA20: 40.74 | AB20: V
B21: Isc (A) | C21: =AA14 -> 10.65 | D21: =AB14 -> 10.6 | E21: =AC14 -> 10.48 | F21: =AD14 -> 10.6 | G21: =AE14 -> 10.6 | H21: =AF14 -> 10.38 | I21: =AG14 -> 9.87 | J21: =AH14 -> 9.82 | ... V21: =AT14 -> 0
Z22: Iscm | AA22: 16.08 | AB22: A | AC22: Nominal short circuit of pv modules from data sheet
Z23: I | AA23: Table above | AB23: W/m^2 | AC23: Irradiation on on strings of tested panel
C24: =IF(AND(C19<C21,C21<C20),"Passed","Failed") -> Passed | D24: =IF(AND(D19<D21,D21<D20),"Passed","Failed") -> Passed | E24: =IF(AND(E19<E21,E21<E20),"Passed","Failed") -> Passed | F24: =IF(AND(F19<F21,F21<F20),"Passed","Failed") -> Passed | G24: =IF(AND(G19<G21,G21<G20),"Passed","Failed") -> Passed | H24: =IF(AND(H19<H21,H21<H20),"Passed","Failed") -> Passed | I24: =IF(AND(I19<I21,I21<I20),"Passed","Failed") -> Passed | J24: =IF(AND(J19<J21,J21<J20),"Passed","Failed") -> Passed | ... V24: =IF(AND(V19<V21,V21<V20),"Passed","Failed") -> Failed | Z24: C_I | AA24: 0.045 | AB24: %/Degree C | AC24: Current Temp coefficient
O25: N/A | P25: N/A | Q25: N/A | R25: N/A | S25: N/A | T25: N/A | U25: N/A | V25: N/A | Z25: I_STC | AA25: 1000 | AB25: W/m^2 | AC25: Standard irradiation

Sheet Inverter 3
B1: SITE: | C1: ='Inverter 1'!C1 -> Kroonstad PnP | F1: DATE: | G1: 22/09/2025 | J1: INVERTER 3
B3: Open Circuit volatge test
C7: S1 | D7: S2 | E7: S3 | F7: S4 | G7: S5 | H7: S6 | I7: S7 | J7: S8 | K7: S9 | L7: S10 | M7: S11 | N7: S12 | O7: S13 | P7: S14 | Q7: S15 | R7: S16 | S7: S17 | T7: S18 | U7: S19 | V7: S20
B8: V_theo | C8: =AA9*$AA$18+(1+$AA$19*($AA$15-25)) -> 884.44 | D8: =AB9*$AA$18+(1+$AA$19*($AB$15-25)) -> 884.44 | E8: =AC9*$AA$18+(1+$AA$19*($AC$15-25)) -> 884.44 | F8: =AD9*$AA$18+(1+$AA$19*($AD$15-25)) -> 884.44 | G8: =AE9*$AA$18+(1+$AA$19*($AE$15-25)) -> 884.44 | H8: =AF9*$AA$18+(1+$AA$19*($AF$15-25)) -> 786.28 | I8: =AG9*$AA$18+(1+$AA$19*($AG$15-25)) -> 786.28 | J8: =AH9*$AA$18+(1+$AA$19*($AH$15-25)) -> 786.28 | K8: =AI9*$AA$18+(1+$AA$19*($AI$15-25)) -> 786.28 | L8: =AJ9*$AA$18+(1+$AA$19*($AJ$15-25)) -> 786.28 | M8: =AK9*$AA$18+(1+$AA$19*($AK$15-25)) -> 786.28 | N8: =AL9*$AA$18+(1+$AA$19*($AL$15-25)) -> 786.28 | O8: =AM9*$AA$18+(1+$AA$19*($AM$15-25)) -> 1 | P8: =AN9*$AA$18+(1+$AA$19*($AN$15-25)) -> 1 | Q8: =AO9*$AA$18+(1+$AA$19*($AO$15-25)) -> 1 | R8: =AP9*$AA$18+(1+$AA$19*($AP$15-25)) -> 1 | S8: =AQ9*$AA$18+(1+$AA$19*($AQ$15-25)) -> 1 | T8: =AR9*$AA$18+(1+$AA$19*($AR$15-25)) -> 1 | U8: =AS9*$AA$18+(1+$AA$19*($AS$15-25)) -> 1 | V8: =AT9*$AA$18+(1+$AA$19*($AT$15-25)) -> 1 | Z8: Inverter 3 | AA8: S1 | AB8: S2 | AC8: S3 | AD8: S4 | AE8: S5 | AF8: S6 | AG8: S7 | AH8: S8 | AI8: S9 | AJ8: S10 | AK8: S11 | AL8: S12 | AM8: S13 | AN8: S14 | AO8: S15 | AP8: S16 | AQ8: S17 | AR8: S18 | AS8: S19 | AT8: S20
B9: (1-7%) | C9: =C8*(1-7%) -> 822.5292 | D9: =D8*(1-7%) -> 822.5292 | E9: =E8*(1-7%) -> 822.5292 | F9: =F8*(1-7%) -> 822.5292 | G9: =G8*(1-7%) -> 822.5292 | H9: =H8*(1-7%) -> 731.2404 | I9: =I8*(1-7%) -> 731.2404 | J9: =J8*(1-7%) -> 731.2404 | ... V9: =V8*(1-7%) -> 0.93 | Z9: Module No. | AA9: 18 | AB9: 18 | AC9: 18 | AD9: 18 | AE9: 18 | AF9: 16 | AG9: 16 | AH9: 16 | AI9: 16 | AJ9: 16 | AK9: 16 | AL9: 16
B10: (1+7%) | C10: =C8*(1+7%) -> 946.3508 | D10: =D8*(1+7%) -> 946.3508 | E10: =E8*(1+7%) -> 946.3508 | F10: =F8*(1+7%) -> 946.3508 | G10: =G8*(1+7%) -> 946.3508 | H10: =H8*(1+7%) -> 841.3196 | I10: =I8*(1+7%) -> 841.3196 | J10: =J8*(1+7%) -> 841.3196 | ... V10: =V8*(1+7%) -> 1.07 | Z10: Open Circuit Voltage (Voc in V) | AA10: 824 | AB10: 825 | AC10: 825 | AD10: 825 | AE10: 824 | AF10: 733 | AG10: 739 | AH10: 738 | AI10: 737 | AJ10: 737 | AK10: 738 | AL10: 739
Z11: Short Circuit Voltage (Vsc in V) | AA11: =AA10-((AA18-AA20)*AA9) -> 673.88 | AB11: =AB10-((AA18-AA20)*AB9) -> 674.88 | AC11: =AC10-((AA18-AA20)*AC9) -> 674.88 | AD11: =AD10-((AA18-AA20)*AD9) -> 674.88 | AE11: =AE10-((AA18-AA20)*AE9) -> 673.88 | AF11: =AF10-((AA18-AA20)*AF9) -> 599.56 | AG11: =AG10-((AA18-AA20)*AG9) -> 605.56 | AH11: =AH10-((AA18-AA20)*AH9) -> 604.56 | AI11: =AI10-((AA18-AA20)*AI9) -> 603.56 | AJ11: =AJ10-((AA18-AA20)*AJ9) -> 603.56 | AK11: =AK10-((AA18-AA20)*AK9) -> 604.56 | AL11: =AL10-((AA18-AA20)*AL9) -> 605.56 | AM11: =AM10-((AA18-AA20)*AM9) -> 0 | AN11: =AN10-((AA18-AA20)*AN9) -> 0 | AO11: =AO10-((AA18-AA20)*AO9) -> 0 | AP11: =AP10-((AA18-AA20)*AP9) -> 0 | AQ11: =AQ10-((AA18-AA20)*AQ9) -> 0 | AR11: =AR10-((AA18-AA20)*AR9) -> 0 | AS11: =AS10-((AA18-AA20)*AS9) -> 0 | AT11: =AT10-((AA18-AA20)*AT9) -> 0
Z12: Insulation Resistance (mΩ) | AA12: 345 | AB12: 375 | AC12: 399 | AD12: 346 | AE12: 356 | AF12: 405 | AG12: 454 | AH12: 401 | AI12: 392 | AJ12: 402 | AK12: 377 | AL12: 415
C13: =IF(AND(C9<AA10,AA10<C10),"Passed","Failed") -> Passed | D13: =IF(AND(D9<AB10,AB10<D10),"Passed","Failed") -> Passed | E13: =IF(AND(E9<AC10,AC10<E10),"Passed","Failed") -> Passed | F13: =IF(AND(F9<AD10,AD10<F10),"Passed","Failed") -> Passed | G13: =IF(AND(G9<AE10,AE10<G10),"Passed","Failed") -> Passed | H13: =IF(AND(H9<AF10,AF10<H10),"Passed","Failed") -> Passed | I13: =IF(AND(I9<AG10,AG10<I10),"Passed","Failed") -> Passed | J13: =IF(AND(J9<AH10,AH10<J10),"Passed","Failed") -> Passed | ... V13: =IF(AND(V9<AT10,AT10<V10),"Passed","Failed") -> Failed | Z13: Irradiance (W) | AA13: 635 | AB13: 638 | AC13: 631 | AD13: 633 | AE13: 630 | AF13: 634 | AG13: 658 | AH13: 640 | AI13: 655 | AJ13: 632 | AK13: 636 | AL13: 640
O14: N/A | P14: N/A | Q14: N/A | R14: N/A | S14: N/A | T14: N/A | U14: N/A | V14: N/A | Z14: Isc (A) | AA14: 10.28 | AB14: 10.18 | AC14: 10.34 | AD14: 10.45 | AE14: 10.53 | AF14: 10.27 | AG14: 11.12 | AH14: 10.3 | AI14: 10.49 | AJ14: 10.79 | AK14: 10.84 | AL14: 11.05
Z15: Cell Temp | AA15: 25 | AB15: 25 | AC15: 25 | AD15: 25 | AE15: 25 | AF15: 25 | AG15: 25 | AH15: 25 | AI15: 25 | AJ15: 25 | AK15: 25 | AL15: 25 | AM15: 25 | AN15: 25 | AO15: 25 | AP15: 25 | AQ15: 25 | AR15: 25 | AS15: 25 | AT15: 25
C17: S1 | D17: S2 | E17: S3 | F17: S4 | G17: S5 | H17: S6 | I17: S7 | J17: S8 | K17: S9 | L17: S10 | M17: S11 | N17: S12 | O17: S13 | P17: S14 | Q17: S15 | R17: S16 | S17: S17 | T17: S18 | U17: S19 | V17: S20 | Z17: Module Details
B18: I_theo | C18: =($AA$22*(AA13/$AA$25))+(1+$AA$24*($AA$15-25)) -> 11.2108 | D18: =($AA$22*(AB13/$AA$25))+(1+$AA$24*($AB$15-25)) -> 11.25904 | E18: =($AA$22*(AC13/$AA$25))+(1+$AA$24*($AC$15-25)) -> 11.14648 | F18: =($AA$22*(AD13/$AA$25))+(1+$AA$24*($AD$15-25)) -> 11.17864 | G18: =($AA$22*(AE13/$AA$25))+(1+$AA$24*($AE$15-25)) -> 11.1304 | H18: =($AA$22*(AF13/$AA$25))+(1+$AA$24*($AF$15-25)) -> 11.19472 | I18: =($AA$22*(AG13/$AA$25))+(1+$AA$24*($AG$15-25)) -> 11.58064 | J18: =($AA$22*(AH13/$AA$25))+(1+$AA$24*($AH$15-25)) -> 11.2912 | K18: =($AA$22*(AI13/$AA$25))+(1+$AA$24*($AI$15-25)) -> 11.5324 | L18: =($AA$22*(AJ13/$AA$25))+(1+$AA$24*($AJ$15-25)) -> 11.16256 | M18: =($AA$22*(AK13/$AA$25))+(1+$AA$24*($AK$15-25)) -> 11.22688 | N18: =($AA$22*(AL13/$AA$25))+(1+$AA$24*($AL$15-25)) -> 11.2912 | O18: =($AA$22*(AM13/$AA$25))+(1+$AA$24*($AM$15-25)) -> 1 | P18: =($AA$22*(AN13/$AA$25))+(1+$AA$24*($AN$15-25)) -> 1 | Q18: =($AA$22*(AO13/$AA$25))+(1+$AA$24*($AO$15-25)) -> 1 | R18: =($AA$22*(AP13/$AA$25))+(1+$AA$24*($AP$15-25)) -> 1 | S18: =($AA$22*(AQ13/$AA$25))+(1+$AA$24*($AQ$15-25)) -> 1 | T18: =($AA$22*(AR13/$AA$25))+(1+$AA$24*($AR$15-25)) -> 1 | U18: =($AA$22*(AS13/$AA$25))+(1+$AA$24*($AS$15-25)) -> 1 | V18: =($AA$22*(AT13/$AA$25))+(1+$AA$24*($AT$15-25)) -> 1 | Z18: Vo | AA18: 49.08 | AB18: V | AC18: Jinko 620 BDV
B19: (1-10%) | C19: =C18*(1-10%) -> 10.08972 | D19: =D18*(1-10%) -> 10.133136 | E19: =E18*(1-10%) -> 10.031832 | F19: =F18*(1-10%) -> 10.060776 | G19: =G18*(1-10%) -> 10.01736 | H19: =H18*(1-10%) -> 10.075248 | I19: =I18*(1-10%) -> 10.422576 | J19: =J18*(1-10%) -> 10.16208 | ... V19: =V18*(1-10%) -> 0.9 | Z19: CT | AA19: -0.25 | AB19: %/Degree C | AC19: Temperature coefficient
B20: (1+10%) | C20: =C18*(1+10%) -> 12.33188 | D20: =D18*(1+10%) -> 12.384944 | E20: =E18*(1+10%) -> 12.261128 | F20: =F18*(1+10%) -> 12.296504 | G20: =G18*(1+10%) -> 12.24344 | H20: =H18*(1+10%) -> 12.314192 | I20: =I18*(1+10%) -> 12.738704 | J20: =J18*(1+10%) -> 12.42032 | ... V20: =V18*(1+10%) -> 1.1 | Z20: Vsc | AA20: 40.74 | AB20: V
B21: Isc (A) | C21: =AA14 -> 10.28 | D21: =AB14 -> 10.18 | E21: =AC14 -> 10.34 | F21: =AD14 -> 10.45 | G21: =AE14 -> 10.53 | H21: =AF14 -> 10.27 | I21: =AG14 -> 11.12 | J21: =AH14 -> 10.3 | ... V21: =AT14 -> 0
Z22: Iscm | AA22: 16.08 | AB22: A | AC22: Nominal short circuit of pv modules from data sheet
Z23: I | AA23: Table above | AB23: W/m^2 | AC23: Irradiation on on strings of tested panel
C24: =IF(AND(C19<C21,C21<C20),"Passed","Failed") -> Passed | D24: =IF(AND(D19<D21,D21<D20),"Passed","Failed") -> Passed | E24: =IF(AND(E19<E21,E21<E20),"Passed","Failed") -> Passed | F24: =IF(AND(F19<F21,F21<F20),"Passed","Failed") -> Passed | G24: =IF(AND(G19<G21,G21<G20),"Passed","Failed") -> Passed | H24: =IF(AND(H19<H21,H21<H20),"Passed","Failed") -> Passed | I24: =IF(AND(I19<I21,I21<I20),"Passed","Failed") -> Passed | J24: =IF(AND(J19<J21,J21<J20),"Passed","Failed") -> Passed | ... V24: =IF(AND(V19<V21,V21<V20),"Passed","Failed") -> Failed | Z24: C_I | AA24: 0.045 | AB24: %/Degree C | AC24: Current Temp coefficient
O25: N/A | P25: N/A | Q25: N/A | R25: N/A | S25: N/A | T25: N/A | U25: N/A | V25: N/A | Z25: I_STC | AA25: 1000 | AB25: W/m^2 | AC25: Standard irradiation

Sheet Inverter 4
B1: SITE: | C1: ='Inverter 1'!C1 -> Kroonstad PnP | F1: DATE: | J1: INVERTER 4
B3: Open Circuit volatge test
C7: S1 | D7: S2 | E7: S3 | F7: S4 | G7: S5 | H7: S6 | I7: S7 | J7: S8 | K7: S9 | L7: S10 | M7: S11 | N7: S12 | O7: S13 | P7: S14 | Q7: S15 | R7: S16 | S7: S17 | T7: S18 | U7: S19 | V7: S20
B8: V_theo | C8: =AA9*$AA$18+(1+$AA$19*($AA$15-25)) -> 1 | D8: =AB9*$AA$18+(1+$AA$19*($AB$15-25)) -> 1 | E8: =AC9*$AA$18+(1+$AA$19*($AC$15-25)) -> 1 | F8: =AD9*$AA$18+(1+$AA$19*($AD$15-25)) -> 1 | G8: =AE9*$AA$18+(1+$AA$19*($AE$15-25)) -> 1 | H8: =AF9*$AA$18+(1+$AA$19*($AF$15-25)) -> 1 | I8: =AG9*$AA$18+(1+$AA$19*($AG$15-25)) -> 1 | J8: =AH9*$AA$18+(1+$AA$19*($AH$15-25)) -> 1 | K8: =AI9*$AA$18+(1+$AA$19*($AI$15-25)) -> 1 | L8: =AJ9*$AA$18+(1+$AA$19*($AJ$15-25)) -> 1 | M8: =AK9*$AA$18+(1+$AA$19*($AK$15-25)) -> 1 | N8: =AL9*$AA$18+(1+$AA$19*($AL$15-25)) -> 1 | O8: =AM9*$AA$18+(1+$AA$19*($AM$15-25)) -> 1 | P8: =AN9*$AA$18+(1+$AA$19*($AN$15-25)) -> 1 | Q8: =AO9*$AA$18+(1+$AA$19*($AO$15-25)) -> 1 | R8: =AP9*$AA$18+(1+$AA$19*($AP$15-25)) -> 1 | S8: =AQ9*$AA$18+(1+$AA$19*($AQ$15-25)) -> 1 | T8: =AR9*$AA$18+(1+$AA$19*($AR$15-25)) -> 1 | U8: =AS9*$AA$18+(1+$AA$19*($AS$15-25)) -> 1 | V8: =AT9*$AA$18+(1+$AA$19*($AT$15-25)) -> 1 | Z8: Inverter 4 | AA8: S1 | AB8: S2 | AC8: S3 | AD8: S4 | AE8: S5 | AF8: S6 | AG8: S7 | AH8: S8 | AI8: S9 | AJ8: S10 | AK8: S11 | AL8: S12 | AM8: S13 | AN8: S14 | AO8: S15 | AP8: S16 | AQ8: S17 | AR8: S18 | AS8: S19 | AT8: S20
B9: (1-7%) | C9: =C8*(1-7%) -> 0.93 | D9: =D8*(1-7%) -> 0.93 | E9: =E8*(1-7%) -> 0.93 | F9: =F8*(1-7%) -> 0.93 | G9: =G8*(1-7%) -> 0.93 | H9: =H8*(1-7%) -> 0.93 | I9: =I8*(1-7%) -> 0.93 | J9: =J8*(1-7%) -> 0.93 | ... V9: =V8*(1-7%) -> 0.93 | Z9: Module No.
B10: (1+7%) | C10: =C8*(1+7%) -> 1.07 | D10: =D8*(1+7%) -> 1.07 | E10: =E8*(1+7%) -> 1.07 | F10: =F8*(1+7%) -> 1.07 | G10: =G8*(1+7%) -> 1.07 | H10: =H8*(1+7%) -> 1.07 | I10: =I8*(1+7%) -> 1.07 | J10: =J8*(1+7%) -> 1.07 | ... V10: =V8*(1+7%) -> 1.07 | Z10: Open Circuit Voltage (Voc in V)
Z11: Short Circuit Voltage (Vsc in V) | AA11: =AA10-((AA18-AA20)*AA9) -> 0 | AB11: =AB10-((AA18-AA20)*AB9) -> 0 | AC11: =AC10-((AA18-AA20)*AC9) -> 0 | AD11: =AD10-((AA18-AA20)*AD9) -> 0 | AE11: =AE10-((AA18-AA20)*AE9) -> 0 | AF11: =AF10-((AA18-AA20)*AF9) -> 0 | AG11: =AG10-((AA18-AA20)*AG9) -> 0 | AH11: =AH10-((AA18-AA20)*AH9) -> 0 | AI11: =AI10-((AA18-AA20)*AI9) -> 0 | AJ11: =AJ10-((AA18-AA20)*AJ9) -> 0 | AK11: =AK10-((AA18-AA20)*AK9) -> 0 | AL11: =AL10-((AA18-AA20)*AL9) -> 0 | AM11: =AM10-((AA18-AA20)*AM9) -> 0 | AN11: =AN10-((AA18-AA20)*AN9) -> 0 | AO11: =AO10-((AA18-AA20)*AO9) -> 0 | AP11: =AP10-((AA18-AA20)*AP9) -> 0 | AQ11: =AQ10-((AA18-AA20)*AQ9) -> 0 | AR11: =AR10-((AA18-AA20)*AR9) -> 0 | AS11: =AS10-((AA18-AA20)*AS9) -> 0 | AT11: =AT10-((AA18-AA20)*AT9) -> 0
Z12: Insulation Resistance (mΩ)
C13: =IF(AND(C9<AA10,AA10<C10),"Passed","Failed") -> Failed | D13: =IF(AND(D9<AB10,AB10<D10),"Passed","Failed") -> Failed | E13: =IF(AND(E9<AC10,AC10<E10),"Passed","Failed") -> Failed | F13: =IF(AND(F9<AD10,AD10<F10),"Passed","Failed") -> Failed | G13: =IF(AND(G9<AE10,AE10<G10),"Passed","Failed") -> Failed | H13: =IF(AND(H9<AF10,AF10<H10),"Passed","Failed") -> Failed | I13: =IF(AND(I9<AG10,AG10<I10),"Passed","Failed") -> Failed | J13: =IF(AND(J9<AH10,AH10<J10),"Passed","Failed") -> Failed | ... V13: =IF(AND(V9<AT10,AT10<V10),"Passed","Failed") -> Failed | Z13: Irradiance (W)
Z14: Isc (A)
Z15: Cell Temp | AA15: 25 | AB15: 25 | AC15: 25 | AD15: 25 | AE15: 25 | AF15: 25 | AG15: 25 | AH15: 25 | AI15: 25 | AJ15: 25 | AK15: 25 | AL15: 25 | AM15: 25 | AN15: 25 | AO15: 25 | AP15: 25 | AQ15: 25 | AR15: 25 | AS15: 25 | AT15: 25
C17: S1 | D17: S2 | E17: S3 | F17: S4 | G17: S5 | H17: S6 | I17: S7 | J17: S8 | K17: S9 | L17: S10 | M17: S11 | N17: S12 | O17: S13 | P17: S14 | Q17: S15 | R17: S16 | S17: S17 | T17: S18 | U17: S19 | V17: S20 | Z17: Module Details
B18: I_theo | C18: =($AA$22*(AA13/$AA$25))+(1+$AA$24*($AA$15-25)) -> 1 | D18: =($AA$22*(AB13/$AA$25))+(1+$AA$24*($AB$15-25)) -> 1 | E18: =($AA$22*(AC13/$AA$25))+(1+$AA$24*($AC$15-25)) -> 1 | F18: =($AA$22*(AD13/$AA$25))+(1+$AA$24*($AD$15-25)) -> 1 | G18: =($AA$22*(AE13/$AA$25))+(1+$AA$24*($AE$15-25)) -> 1 | H18: =($AA$22*(AF13/$AA$25))+(1+$AA$24*($AF$15-25)) -> 1 | I18: =($AA$22*(AG13/$AA$25))+(1+$AA$24*($AG$15-25)) -> 1 | J18: =($AA$22*(AH13/$AA$25))+(1+$AA$24*($AH$15-25)) -> 1 | K18: =($AA$22*(AI13/$AA$25))+(1+$AA$24*($AI$15-25)) -> 1 | L18: =($AA$22*(AJ13/$AA$25))+(1+$AA$24*($AJ$15-25)) -> 1 | M18: =($AA$22*(AK13/$AA$25))+(1+$AA$24*($AK$15-25)) -> 1 | N18: =($AA$22*(AL13/$AA$25))+(1+$AA$24*($AL$15-25)) -> 1 | O18: =($AA$22*(AM13/$AA$25))+(1+$AA$24*($AM$15-25)) -> 1 | P18: =($AA$22*(AN13/$AA$25))+(1+$AA$24*($AN$15-25)) -> 1 | Q18: =($AA$22*(AO13/$AA$25))+(1+$AA$24*($AO$15-25)) -> 1 | R18: =($AA$22*(AP13/$AA$25))+(1+$AA$24*($AP$15-25)) -> 1 | S18: =($AA$22*(AQ13/$AA$25))+(1+$AA$24*($AQ$15-25)) -> 1 | T18: =($AA$22*(AR13/$AA$25))+(1+$AA$24*($AR$15-25)) -> 1 | U18: =($AA$22*(AS13/$AA$25))+(1+$AA$24*($AS$15-25)) -> 1 | V18: =($AA$22*(AT13/$AA$25))+(1+$AA$24*($AT$15-25)) -> 1 | Z18: Vo | AA18: 49.75 | AB18: V | AC18: JAM72S30 545/MR
B19: (1-10%) | C19: =C18*(1-10%) -> 0.9 | D19: =D18*(1-10%) -> 0.9 | E19: =E18*(1-10%) -> 0.9 | F19: =F18*(1-10%) -> 0.9 | G19: =G18*(1-10%) -> 0.9 | H19: =H18*(1-10%) -> 0.9 | I19: =I18*(1-10%) -> 0.9 | J19: =J18*(1-10%) -> 0.9 | ... V19: =V18*(1-10%) -> 0.9 | Z19: CT | AA19: -0.275 | AB19: %/Degree C | AC19: Temperature coefficient
B20: (1+10%) | C20: =C18*(1+10%) -> 1.1 | D20: =D18*(1+10%) -> 1.1 | E20: =E18*(1+10%) -> 1.1 | F20: =F18*(1+10%) -> 1.1 | G20: =G18*(1+10%) -> 1.1 | H20: =H18*(1+10%) -> 1.1 | I20: =I18*(1+10%) -> 1.1 | J20: =J18*(1+10%) -> 1.1 | ... V20: =V18*(1+10%) -> 1.1 | Z20: Vsc | AA20: 41.8 | AB20: V
B21: Isc (A) | C21: =AA14 -> 0 | D21: =AB14 -> 0 | E21: =AC14 -> 0 | F21: =AD14 -> 0 | G21: =AE14 -> 0 | H21: =AF14 -> 0 | I21: =AG14 -> 0 | J21: =AH14 -> 0 | ... V21: =AT14 -> 0
Z22: Iscm | AA22: 13.93 | AB22: A | AC22: Nominal short circuit of pv modules from data sheet
Z23: I | AA23: Table above | AB23: W/m^2 | AC23: Irradiation on on strings of tested panel
C24: =IF(AND(C19<C21,C21<C20),"Passed","Failed") -> Failed | D24: =IF(AND(D19<D21,D21<D20),"Passed","Failed") -> Failed | E24: =IF(AND(E19<E21,E21<E20),"Passed","Failed") -> Failed | F24: =IF(AND(F19<F21,F21<F20),"Passed","Failed") -> Failed | G24: =IF(AND(G19<G21,G21<G20),"Passed","Failed") -> Failed | H24: =IF(AND(H19<H21,H21<H20),"Passed","Failed") -> Failed | I24: =IF(AND(I19<I21,I21<I20),"Passed","Failed") -> Failed | J24: =IF(AND(J19<J21,J21<J20),"Passed","Failed") -> Failed | ... V24: =IF(AND(V19<V21,V21<V20),"Passed","Failed") -> Failed | Z24: C_I | AA24: 0.045 | AB24: %/Degree C | AC24: Current Temp coefficient
Z25: I_STC | AA25: 1000 | AB25: W/m^2 | AC25: Standard irradiation

Sheet Inverter 5
B1: SITE: | C1: ='Inverter 1'!C1 -> Kroonstad PnP | F1: DATE: | J1: INVERTER 5
B3: Open Circuit volatge test
C7: S1 | D7: S2 | E7: S3 | F7: S4 | G7: S5 | H7: S6 | I7: S7 | J7: S8 | K7: S9 | L7: S10 | M7: S11 | N7: S12 | O7: S13 | P7: S14 | Q7: S15 | R7: S16 | S7: S17 | T7: S18 | U7: S19 | V7: S20
B8: V_theo | C8: =AA9*$AA$18+(1+$AA$19*($AA$15-25)) -> 1 | D8: =AB9*$AA$18+(1+$AA$19*($AB$15-25)) -> 1 | E8: =AC9*$AA$18+(1+$AA$19*($AC$15-25)) -> 1 | F8: =AD9*$AA$18+(1+$AA$19*($AD$15-25)) -> 1 | G8: =AE9*$AA$18+(1+$AA$19*($AE$15-25)) -> 1 | H8: =AF9*$AA$18+(1+$AA$19*($AF$15-25)) -> 1 | I8: =AG9*$AA$18+(1+$AA$19*($AG$15-25)) -> 1 | J8: =AH9*$AA$18+(1+$AA$19*($AH$15-25)) -> 1 | K8: =AI9*$AA$18+(1+$AA$19*($AI$15-25)) -> 1 | L8: =AJ9*$AA$18+(1+$AA$19*($AJ$15-25)) -> 1 | M8: =AK9*$AA$18+(1+$AA$19*($AK$15-25)) -> 1 | N8: =AL9*$AA$18+(1+$AA$19*($AL$15-25)) -> 1 | O8: =AM9*$AA$18+(1+$AA$19*($AM$15-25)) -> 1 | P8: =AN9*$AA$18+(1+$AA$19*($AN$15-25)) -> 1 | Q8: =AO9*$AA$18+(1+$AA$19*($AO$15-25)) -> 1 | R8: =AP9*$AA$18+(1+$AA$19*($AP$15-25)) -> 1 | S8: =AQ9*$AA$18+(1+$AA$19*($AQ$15-25)) -> 1 | T8: =AR9*$AA$18+(1+$AA$19*($AR$15-25)) -> 1 | U8: =AS9*$AA$18+(1+$AA$19*($AS$15-25)) -> 1 | V8: =AT9*$AA$18+(1+$AA$19*($AT$15-25)) -> 1 | Z8: Inverter 5 | AA8: S1 | AB8: S2 | AC8: S3 | AD8: S4 | AE8: S5 | AF8: S6 | AG8: S7 | AH8: S8 | AI8: S9 | AJ8: S10 | AK8: S11 | AL8: S12 | AM8: S13 | AN8: S14 | AO8: S15 | AP8: S16 | AQ8: S17 | AR8: S18 | AS8: S19 | AT8: S20
B9: (1-7%) | C9: =C8*(1-7%) -> 0.93 | D9: =D8*(1-7%) -> 0.93 | E9: =E8*(1-7%) -> 0.93 | F9: =F8*(1-7%) -> 0.93 | G9: =G8*(1-7%) -> 0.93 | H9: =H8*(1-7%) -> 0.93 | I9: =I8*(1-7%) -> 0.93 | J9: =J8*(1-7%) -> 0.93 | ... V9: =V8*(1-7%) -> 0.93 | Z9: Module No.
B10: (1+7%) | C10: =C8*(1+7%) -> 1.07 | D10: =D8*(1+7%) -> 1.07 | E10: =E8*(1+7%) -> 1.07 | F10: =F8*(1+7%) -> 1.07 | G10: =G8*(1+7%) -> 1.07 | H10: =H8*(1+7%) -> 1.07 | I10: =I8*(1+7%) -> 1.07 | J10: =J8*(1+7%) -> 1.07 | ... V10: =V8*(1+7%) -> 1.07 | Z10: Open Circuit Voltage (Voc in V)
Z11: Short Circuit Voltage (Vsc in V) | AA11: =AA10-((AA18-AA20)*AA9) -> 0 | AB11: =AB10-((AA18-AA20)*AB9) -> 0 | AC11: =AC10-((AA18-AA20)*AC9) -> 0 | AD11: =AD10-((AA18-AA20)*AD9) -> 0 | AE11: =AE10-((AA18-AA20)*AE9) -> 0 | AF11: =AF10-((AA18-AA20)*AF9) -> 0 | AG11: =AG10-((AA18-AA20)*AG9) -> 0 | AH11: =AH10-((AA18-AA20)*AH9) -> 0 | AI11: =AI10-((AA18-AA20)*AI9) -> 0 | AJ11: =AJ10-((AA18-AA20)*AJ9) -> 0 | AK11: =AK10-((AA18-AA20)*AK9) -> 0 | AL11: =AL10-((AA18-AA20)*AL9) -> 0 | AM11: =AM10-((AA18-AA20)*AM9) -> 0 | AN11: =AN10-((AA18-AA20)*AN9) -> 0 | AO11: =AO10-((AA18-AA20)*AO9) -> 0 | AP11: =AP10-((AA18-AA20)*AP9) -> 0 | AQ11: =AQ10-((AA18-AA20)*AQ9) -> 0 | AR11: =AR10-((AA18-AA20)*AR9) -> 0 | AS11: =AS10-((AA18-AA20)*AS9) -> 0 | AT11: =AT10-((AA18-AA20)*AT9) -> 0
Z12: Insulation Resistance (mΩ)
C13: =IF(AND(C9<AA10,AA10<C10),"Passed","Failed") -> Failed | D13: =IF(AND(D9<AB10,AB10<D10),"Passed","Failed") -> Failed | E13: =IF(AND(E9<AC10,AC10<E10),"Passed","Failed") -> Failed | F13: =IF(AND(F9<AD10,AD10<F10),"Passed","Failed") -> Failed | G13: =IF(AND(G9<AE10,AE10<G10),"Passed","Failed") -> Failed | H13: =IF(AND(H9<AF10,AF10<H10),"Passed","Failed") -> Failed | I13: =IF(AND(I9<AG10,AG10<I10),"Passed","Failed") -> Failed | J13: =IF(AND(J9<AH10,AH10<J10),"Passed","Failed") -> Failed | ... V13: =IF(AND(V9<AT10,AT10<V10),"Passed","Failed") -> Failed | Z13: Irradiance (W)
Z14: Isc (A)
Z15: Cell Temp | AA15: 25 | AB15: 25 | AC15: 25 | AD15: 25 | AE15: 25 | AF15: 25 | AG15: 25 | AH15: 25 | AI15: 25 | AJ15: 25 | AK15: 25 | AL15: 25 | AM15: 25 | AN15: 25 | AO15: 25 | AP15: 25 | AQ15: 25 | AR15: 25 | AS15: 25 | AT15: 25
C17: S1 | D17: S2 | E17: S3 | F17: S4 | G17: S5 | H17: S6 | I17: S7 | J17: S8 | K17: S9 | L17: S10 | M17: S11 | N17: S12 | O17: S13 | P17: S14 | Q17: S15 | R17: S16 | S17: S17 | T17: S18 | U17: S19 | V17: S20 | Z17: Module Details
B18: I_theo | C18: =($AA$22*(AA13/$AA$25))+(1+$AA$24*($AA$15-25)) -> 1 | D18: =($AA$22*(AB13/$AA$25))+(1+$AA$24*($AB$15-25)) -> 1 | E18: =($AA$22*(AC13/$AA$25))+(1+$AA$24*($AC$15-25)) -> 1 | F18: =($AA$22*(AD13/$AA$25))+(1+$AA$24*($AD$15-25)) -> 1 | G18: =($AA$22*(AE13/$AA$25))+(1+$AA$24*($AE$15-25)) -> 1 | H18: =($AA$22*(AF13/$AA$25))+(1+$AA$24*($AF$15-25)) -> 1 | I18: =($AA$22*(AG13/$AA$25))+(1+$AA$24*($AG$15-25)) -> 1 | J18: =($AA$22*(AH13/$AA$25))+(1+$AA$24*($AH$15-25)) -> 1 | K18: =($AA$22*(AI13/$AA$25))+(1+$AA$24*($AI$15-25)) -> 1 | L18: =($AA$22*(AJ13/$AA$25))+(1+$AA$24*($AJ$15-25)) -> 1 | M18: =($AA$22*(AK13/$AA$25))+(1+$AA$24*($AK$15-25)) -> 1 | N18: =($AA$22*(AL13/$AA$25))+(1+$AA$24*($AL$15-25)) -> 1 | O18: =($AA$22*(AM13/$AA$25))+(1+$AA$24*($AM$15-25)) -> 1 | P18: =($AA$22*(AN13/$AA$25))+(1+$AA$24*($AN$15-25)) -> 1 | Q18: =($AA$22*(AO13/$AA$25))+(1+$AA$24*($AO$15-25)) -> 1 | R18: =($AA$22*(AP13/$AA$25))+(1+$AA$24*($AP$15-25)) -> 1 | S18: =($AA$22*(AQ13/$AA$25))+(1+$AA$24*($AQ$15-25)) -> 1 | T18: =($AA$22*(AR13/$AA$25))+(1+$AA$24*($AR$15-25)) -> 1 | U18: =($AA$22*(AS13/$AA$25))+(1+$AA$24*($AS$15-25)) -> 1 | V18: =($AA$22*(AT13/$AA$25))+(1+$AA$24*($AT$15-25)) -> 1 | Z18: Vo | AA18: 49.75 | AB18: V | AC18: JAM72S30 545/MR
B19: (1-10%) | C19: =C18*(1-10%) -> 0.9 | D19: =D18*(1-10%) -> 0.9 | E19: =E18*(1-10%) -> 0.9 | F19: =F18*(1-10%) -> 0.9 | G19: =G18*(1-10%) -> 0.9 | H19: =H18*(1-10%) -> 0.9 | I19: =I18*(1-10%) -> 0.9 | J19: =J18*(1-10%) -> 0.9 | ... V19: =V18*(1-10%) -> 0.9 | Z19: CT | AA19: -0.275 | AB19: %/Degree C | AC19: Temperature coefficient
B20: (1+10%) | C20: =C18*(1+10%) -> 1.1 | D20: =D18*(1+10%) -> 1.1 | E20: =E18*(1+10%) -> 1.1 | F20: =F18*(1+10%) -> 1.1 | G20: =G18*(1+10%) -> 1.1 | H20: =H18*(1+10%) -> 1.1 | I20: =I18*(1+10%) -> 1.1 | J20: =J18*(1+10%) -> 1.1 | ... V20: =V18*(1+10%) -> 1.1 | Z20: Vsc | AA20: 41.8 | AB20: V
B21: Isc (A) | C21: =AA14 -> 0 | D21: =AB14 -> 0 | E21: =AC14 -> 0 | F21: =AD14 -> 0 | G21: =AE14 -> 0 | H21: =AF14 -> 0 | I21: =AG14 -> 0 | J21: =AH14 -> 0 | ... V21: =AT14 -> 0
Z22: Iscm | AA22: 13.93 | AB22: A | AC22: Nominal short circuit of pv modules from data sheet
Z23: I | AA23: Table above | AB23: W/m^2 | AC23: Irradiation on on strings of tested panel
C24: =IF(AND(C19<C21,C21<C20),"Passed","Failed") -> Failed | D24: =IF(AND(D19<D21,D21<D20),"Passed","Failed") -> Failed | E24: =IF(AND(E19<E21,E21<E20),"Passed","Failed") -> Failed | F24: =IF(AND(F19<F21,F21<F20),"Passed","Failed") -> Failed | G24: =IF(AND(G19<G21,G21<G20),"Passed","Failed") -> Failed | H24: =IF(AND(H19<H21,H21<H20),"Passed","Failed") -> Failed | I24: =IF(AND(I19<I21,I21<I20),"Passed","Failed") -> Failed | J24: =IF(AND(J19<J21,J21<J20),"Passed","Failed") -> Failed | ... V24: =IF(AND(V19<V21,V21<V20),"Passed","Failed") -> Failed | Z24: C_I | AA24: 0.045 | AB24: %/Degree C | AC24: Current Temp coefficient
Z25: I_STC | AA25: 1000 | AB25: W/m^2 | AC25: Standard irradiation

Sheet Inverter 6
B1: SITE: | C1: ='Inverter 1'!C1 -> Kroonstad PnP | F1: DATE: | J1: INVERTER 6
B3: Open Circuit volatge test
C7: S1 | D7: S2 | E7: S3 | F7: S4 | G7: S5 | H7: S6 | I7: S7 | J7: S8 | K7: S9 | L7: S10 | M7: S11 | N7: S12 | O7: S13 | P7: S14 | Q7: S15 | R7: S16 | S7: S17 | T7: S18 | U7: S19 | V7: S20
B8: V_theo | C8: =AA9*$AA$18+(1+$AA$19*($AA$15-25)) -> 1 | D8: =AB9*$AA$18+(1+$AA$19*($AB$15-25)) -> 1 | E8: =AC9*$AA$18+(1+$AA$19*($AC$15-25)) -> 1 | F8: =AD9*$AA$18+(1+$AA$19*($AD$15-25)) -> 1 | G8: =AE9*$AA$18+(1+$AA$19*($AE$15-25)) -> 1 | H8: =AF9*$AA$18+(1+$AA$19*($AF$15-25)) -> 1 | I8: =AG9*$AA$18+(1+$AA$19*($AG$15-25)) -> 1 | J8: =AH9*$AA$18+(1+$AA$19*($AH$15-25)) -> 1 | K8: =AI9*$AA$18+(1+$AA$19*($AI$15-25)) -> 1 | L8: =AJ9*$AA$18+(1+$AA$19*($AJ$15-25)) -> 1 | M8: =AK9*$AA$18+(1+$AA$19*($AK$15-25)) -> 1 | N8: =AL9*$AA$18+(1+$AA$19*($AL$15-25)) -> 1 | O8: =AM9*$AA$18+(1+$AA$19*($AM$15-25)) -> 1 | P8: =AN9*$AA$18+(1+$AA$19*($AN$15-25)) -> 1 | Q8: =AO9*$AA$18+(1+$AA$19*($AO$15-25)) -> 1 | R8: =AP9*$AA$18+(1+$AA$19*($AP$15-25)) -> 1 | S8: =AQ9*$AA$18+(1+$AA$19*($AQ$15-25)) -> 1 | T8: =AR9*$AA$18+(1+$AA$19*($AR$15-25)) -> 1 | U8: =AS9*$AA$18+(1+$AA$19*($AS$15-25)) -> 1 | V8: =AT9*$AA$18+(1+$AA$19*($AT$15-25)) -> 1 | Z8: Inverter 6 | AA8: S1 | AB8: S2 | AC8: S3 | AD8: S4 | AE8: S5 | AF8: S6 | AG8: S7 | AH8: S8 | AI8: S9 | AJ8: S10 | AK8: S11 | AL8: S12 | AM8: S13 | AN8: S14 | AO8: S15 | AP8: S16 | AQ8: S17 | AR8: S18 | AS8: S19 | AT8: S20
B9: (1-7%) | C9: =C8*(1-7%) -> 0.93 | D9: =D8*(1-7%) -> 0.93 | E9: =E8*(1-7%) -> 0.93 | F9: =F8*(1-7%) -> 0.93 | G9: =G8*(1-7%) -> 0.93 | H9: =H8*(1-7%) -> 0.93 | I9: =I8*(1-7%) -> 0.93 | J9: =J8*(1-7%) -> 0.93 | ... V9: =V8*(1-7%) -> 0.93 | Z9: Module No.
B10: (1+7%) | C10: =C8*(1+7%) -> 1.07 | D10: =D8*(1+7%) -> 1.07 | E10: =E8*(1+7%) -> 1.07 | F10: =F8*(1+7%) -> 1.07 | G10: =G8*(1+7%) -> 1.07 | H10: =H8*(1+7%) -> 1.07 | I10: =I8*(1+7%) -> 1.07 | J10: =J8*(1+7%) -> 1.07 | ... V10: =V8*(1+7%) -> 1.07 | Z10: Open Circuit Voltage (Voc in V)
Z11: Short Circuit Voltage (Vsc in V) | AA11: =AA10-((AA18-AA20)*AA9) -> 0 | AB11: =AB10-((AA18-AA20)*AB9) -> 0 | AC11: =AC10-((AA18-AA20)*AC9) -> 0 | AD11: =AD10-((AA18-AA20)*AD9) -> 0 | AE11: =AE10-((AA18-AA20)*AE9) -> 0 | AF11: =AF10-((AA18-AA20)*AF9) -> 0 | AG11: =AG10-((AA18-AA20)*AG9) -> 0 | AH11: =AH10-((AA18-AA20)*AH9) -> 0 | AI11: =AI10-((AA18-AA20)*AI9) -> 0 | AJ11: =AJ10-((AA18-AA20)*AJ9) -> 0 | AK11: =AK10-((AA18-AA20)*AK9) -> 0 | AL11: =AL10-((AA18-AA20)*AL9) -> 0 | AM11: =AM10-((AA18-AA20)*AM9) -> 0 | AN11: =AN10-((AA18-AA20)*AN9) -> 0 | AO11: =AO10-((AA18-AA20)*AO9) -> 0 | AP11: =AP10-((AA18-AA20)*AP9) -> 0 | AQ11: =AQ10-((AA18-AA20)*AQ9) -> 0 | AR11: =AR10-((AA18-AA20)*AR9) -> 0 | AS11: =AS10-((AA18-AA20)*AS9) -> 0 | AT11: =AT10-((AA18-AA20)*AT9) -> 0
Z12: Insulation Resistance (mΩ)
C13: =IF(AND(C9<AA10,AA10<C10),"Passed","Failed") -> Failed | D13: =IF(AND(D9<AB10,AB10<D10),"Passed","Failed") -> Failed | E13: =IF(AND(E9<AC10,AC10<E10),"Passed","Failed") -> Failed | F13: =IF(AND(F9<AD10,AD10<F10),"Passed","Failed") -> Failed | G13: =IF(AND(G9<AE10,AE10<G10),"Passed","Failed") -> Failed | H13: =IF(AND(H9<AF10,AF10<H10),"Passed","Failed") -> Failed | I13: =IF(AND(I9<AG10,AG10<I10),"Passed","Failed") -> Failed | J13: =IF(AND(J9<AH10,AH10<J10),"Passed","Failed") -> Failed | ... V13: =IF(AND(V9<AT10,AT10<V10),"Passed","Failed") -> Failed | Z13: Irradiance (W)
Z14: Isc (A)
Z15: Cell Temp | AA15: 25 | AB15: 25 | AC15: 25 | AD15: 25 | AE15: 25 | AF15: 25 | AG15: 25 | AH15: 25 | AI15: 25 | AJ15: 25 | AK15: 25 | AL15: 25 | AM15: 25 | AN15: 25 | AO15: 25 | AP15: 25 | AQ15: 25 | AR15: 25 | AS15: 25 | AT15: 25
C17: S1 | D17: S2 | E17: S3 | F17: S4 | G17: S5 | H17: S6 | I17: S7 | J17: S8 | K17: S9 | L17: S10 | M17: S11 | N17: S12 | O17: S13 | P17: S14 | Q17: S15 | R17: S16 | S17: S17 | T17: S18 | U17: S19 | V17: S20 | Z17: Module Details
B18: I_theo | C18: =($AA$22*(AA13/$AA$25))+(1+$AA$24*($AA$15-25)) -> 1 | D18: =($AA$22*(AB13/$AA$25))+(1+$AA$24*($AB$15-25)) -> 1 | E18: =($AA$22*(AC13/$AA$25))+(1+$AA$24*($AC$15-25)) -> 1 | F18: =($AA$22*(AD13/$AA$25))+(1+$AA$24*($AD$15-25)) -> 1 | G18: =($AA$22*(AE13/$AA$25))+(1+$AA$24*($AE$15-25)) -> 1 | H18: =($AA$22*(AF13/$AA$25))+(1+$AA$24*($AF$15-25)) -> 1 | I18: =($AA$22*(AG13/$AA$25))+(1+$AA$24*($AG$15-25)) -> 1 | J18: =($AA$22*(AH13/$AA$25))+(1+$AA$24*($AH$15-25)) -> 1 | K18: =($AA$22*(AI13/$AA$25))+(1+$AA$24*($AI$15-25)) -> 1 | L18: =($AA$22*(AJ13/$AA$25))+(1+$AA$24*($AJ$15-25)) -> 1 | M18: =($AA$22*(AK13/$AA$25))+(1+$AA$24*($AK$15-25)) -> 1 | N18: =($AA$22*(AL13/$AA$25))+(1+$AA$24*($AL$15-25)) -> 1 | O18: =($AA$22*(AM13/$AA$25))+(1+$AA$24*($AM$15-25)) -> 1 | P18: =($AA$22*(AN13/$AA$25))+(1+$AA$24*($AN$15-25)) -> 1 | Q18: =($AA$22*(AO13/$AA$25))+(1+$AA$24*($AO$15-25)) -> 1 | R18: =($AA$22*(AP13/$AA$25))+(1+$AA$24*($AP$15-25)) -> 1 | S18: =($AA$22*(AQ13/$AA$25))+(1+$AA$24*($AQ$15-25)) -> 1 | T18: =($AA$22*(AR13/$AA$25))+(1+$AA$24*($AR$15-25)) -> 1 | U18: =($AA$22*(AS13/$AA$25))+(1+$AA$24*($AS$15-25)) -> 1 | V18: =($AA$22*(AT13/$AA$25))+(1+$AA$24*($AT$15-25)) -> 1 | Z18: Vo | AA18: 49.75 | AB18: V | AC18: JAM72S30 545/MR
B19: (1-10%) | C19: =C18*(1-10%) -> 0.9 | D19: =D18*(1-10%) -> 0.9 | E19: =E18*(1-10%) -> 0.9 | F19: =F18*(1-10%) -> 0.9 | G19: =G18*(1-10%) -> 0.9 | H19: =H18*(1-10%) -> 0.9 | I19: =I18*(1-10%) -> 0.9 | J19: =J18*(1-10%) -> 0.9 | ... V19: =V18*(1-10%) -> 0.9 | Z19: CT | AA19: -0.275 | AB19: %/Degree C | AC19: Temperature coefficient
B20: (1+10%) | C20: =C18*(1+10%) -> 1.1 | D20: =D18*(1+10%) -> 1.1 | E20: =E18*(1+10%) -> 1.1 | F20: =F18*(1+10%) -> 1.1 | G20: =G18*(1+10%) -> 1.1 | H20: =H18*(1+10%) -> 1.1 | I20: =I18*(1+10%) -> 1.1 | J20: =J18*(1+10%) -> 1.1 | ... V20: =V18*(1+10%) -> 1.1 | Z20: Vsc | AA20: 41.8 | AB20: V
B21: Isc (A) | C21: =AA14 -> 0 | D21: =AB14 -> 0 | E21: =AC14 -> 0 | F21: =AD14 -> 0 | G21: =AE14 -> 0 | H21: =AF14 -> 0 | I21: =AG14 -> 0 | J21: =AH14 -> 0 | ... V21: =AT14 -> 0
Z22: Iscm | AA22: 13.93 | AB22: A | AC22: Nominal short circuit of pv modules from data sheet
Z23: I | AA23: Table above | AB23: W/m^2 | AC23: Irradiation on on strings of tested panel
C24: =IF(AND(C19<C21,C21<C20),"Passed","Failed") -> Failed | D24: =IF(AND(D19<D21,D21<D20),"Passed","Failed") -> Failed | E24: =IF(AND(E19<E21,E21<E20),"Passed","Failed") -> Failed | F24: =IF(AND(F19<F21,F21<F20),"Passed","Failed") -> Failed | G24: =IF(AND(G19<G21,G21<G20),"Passed","Failed") -> Failed | H24: =IF(AND(H19<H21,H21<H20),"Passed","Failed") -> Failed | I24: =IF(AND(I19<I21,I21<I20),"Passed","Failed") -> Failed | J24: =IF(AND(J19<J21,J21<J20),"Passed","Failed") -> Failed | ... V24: =IF(AND(V19<V21,V21<V20),"Passed","Failed") -> Failed | Z24: C_I | AA24: 0.045 | AB24: %/Degree C | AC24: Current Temp coefficient
Z25: I_STC | AA25: 1000 | AB25: W/m^2 | AC25: Standard irradiation

Sheet Inverter 7
B1: SITE: | C1: ='Inverter 1'!C1 -> Kroonstad PnP | F1: DATE: | J1: INVERTER 7
B3: Open Circuit volatge test
C7: S1 | D7: S2 | E7: S3 | F7: S4 | G7: S5 | H7: S6 | I7: S7 | J7: S8 | K7: S9 | L7: S10 | M7: S11 | N7: S12 | O7: S13 | P7: S14 | Q7: S15 | R7: S16 | S7: S17 | T7: S18 | U7: S19 | V7: S20
B8: V_theo | C8: =AA9*$AA$18+(1+$AA$19*($AA$15-25)) -> 1 | D8: =AB9*$AA$18+(1+$AA$19*($AB$15-25)) -> 1 | E8: =AC9*$AA$18+(1+$AA$19*($AC$15-25)) -> 1 | F8: =AD9*$AA$18+(1+$AA$19*($AD$15-25)) -> 1 | G8: =AE9*$AA$18+(1+$AA$19*($AE$15-25)) -> 1 | H8: =AF9*$AA$18+(1+$AA$19*($AF$15-25)) -> 1 | I8: =AG9*$AA$18+(1+$AA$19*($AG$15-25)) -> 1 | J8: =AH9*$AA$18+(1+$AA$19*($AH$15-25)) -> 1 | K8: =AI9*$AA$18+(1+$AA$19*($AI$15-25)) -> 1 | L8: =AJ9*$AA$18+(1+$AA$19*($AJ$15-25)) -> 1 | M8: =AK9*$AA$18+(1+$AA$19*($AK$15-25)) -> 1 | N8: =AL9*$AA$18+(1+$AA$19*($AL$15-25)) -> 1 | O8: =AM9*$AA$18+(1+$AA$19*($AM$15-25)) -> 1 | P8: =AN9*$AA$18+(1+$AA$19*($AN$15-25)) -> 1 | Q8: =AO9*$AA$18+(1+$AA$19*($AO$15-25)) -> 1 | R8: =AP9*$AA$18+(1+$AA$19*($AP$15-25)) -> 1 | S8: =AQ9*$AA$18+(1+$AA$19*($AQ$15-25)) -> 1 | T8: =AR9*$AA$18+(1+$AA$19*($AR$15-25)) -> 1 | U8: =AS9*$AA$18+(1+$AA$19*($AS$15-25)) -> 1 | V8: =AT9*$AA$18+(1+$AA$19*($AT$15-25)) -> 1 | Z8: Inverter 7 | AA8: S1 | AB8: S2 | AC8: S3 | AD8: S4 | AE8: S5 | AF8: S6 | AG8: S7 | AH8: S8 | AI8: S9 | AJ8: S10 | AK8: S11 | AL8: S12 | AM8: S13 | AN8: S14 | AO8: S15 | AP8: S16 | AQ8: S17 | AR8: S18 | AS8: S19 | AT8: S20
B9: (1-7%) | C9: =C8*(1-7%) -> 0.93 | D9: =D8*(1-7%) -> 0.93 | E9: =E8*(1-7%) -> 0.93 | F9: =F8*(1-7%) -> 0.93 | G9: =G8*(1-7%) -> 0.93 | H9: =H8*(1-7%) -> 0.93 | I9: =I8*(1-7%) -> 0.93 | J9: =J8*(1-7%) -> 0.93 | ... V9: =V8*(1-7%) -> 0.93 | Z9: Module No.
B10: (1+7%) | C10: =C8*(1+7%) -> 1.07 | D10: =D8*(1+7%) -> 1.07 | E10: =E8*(1+7%) -> 1.07 | F10: =F8*(1+7%) -> 1.07 | G10: =G8*(1+7%) -> 1.07 | H10: =H8*(1+7%) -> 1.07 | I10: =I8*(1+7%) -> 1.07 | J10: =J8*(1+7%) -> 1.07 | ... V10: =V8*(1+7%) -> 1.07 | Z10: Open Circuit Voltage (Voc in V)
Z11: Short Circuit Voltage (Vsc in V) | AA11: =AA10-((AA18-AA20)*AA9) -> 0 | AB11: =AB10-((AA18-AA20)*AB9) -> 0 | AC11: =AC10-((AA18-AA20)*AC9) -> 0 | AD11: =AD10-((AA18-AA20)*AD9) -> 0 | AE11: =AE10-((AA18-AA20)*AE9) -> 0 | AF11: =AF10-((AA18-AA20)*AF9) -> 0 | AG11: =AG10-((AA18-AA20)*AG9) -> 0 | AH11: =AH10-((AA18-AA20)*AH9) -> 0 | AI11: =AI10-((AA18-AA20)*AI9) -> 0 | AJ11: =AJ10-((AA18-AA20)*AJ9) -> 0 | AK11: =AK10-((AA18-AA20)*AK9) -> 0 | AL11: =AL10-((AA18-AA20)*AL9) -> 0 | AM11: =AM10-((AA18-AA20)*AM9) -> 0 | AN11: =AN10-((AA18-AA20)*AN9) -> 0 | AO11: =AO10-((AA18-AA20)*AO9) -> 0 | AP11: =AP10-((AA18-AA20)*AP9) -> 0 | AQ11: =AQ10-((AA18-AA20)*AQ9) -> 0 | AR11: =AR10-((AA18-AA20)*AR9) -> 0 | AS11: =AS10-((AA18-AA20)*AS9) -> 0 | AT11: =AT10-((AA18-AA20)*AT9) -> 0
Z12: Insulation Resistance (mΩ)
C13: =IF(AND(C9<AA10,AA10<C10),"Passed","Failed") -> Failed | D13: =IF(AND(D9<AB10,AB10<D10),"Passed","Failed") -> Failed | E13: =IF(AND(E9<AC10,AC10<E10),"Passed","Failed") -> Failed | F13: =IF(AND(F9<AD10,AD10<F10),"Passed","Failed") -> Failed | G13: =IF(AND(G9<AE10,AE10<G10),"Passed","Failed") -> Failed | H13: =IF(AND(H9<AF10,AF10<H10),"Passed","Failed") -> Failed | I13: =IF(AND(I9<AG10,AG10<I10),"Passed","Failed") -> Failed | J13: =IF(AND(J9<AH10,AH10<J10),"Passed","Failed") -> Failed | ... V13: =IF(AND(V9<AT10,AT10<V10),"Passed","Failed") -> Failed | Z13: Irradiance (W)
Z14: Isc (A)
Z15: Cell Temp | AA15: 25 | AB15: 25 | AC15: 25 | AD15: 25 | AE15: 25 | AF15: 25 | AG15: 25 | AH15: 25 | AI15: 25 | AJ15: 25 | AK15: 25 | AL15: 25 | AM15: 25 | AN15: 25 | AO15: 25 | AP15: 25 | AQ15: 25 | AR15: 25 | AS15: 25 | AT15: 25
C17: S1 | D17: S2 | E17: S3 | F17: S4 | G17: S5 | H17: S6 | I17: S7 | J17: S8 | K17: S9 | L17: S10 | M17: S11 | N17: S12 | O17: S13 | P17: S14 | Q17: S15 | R17: S16 | S17: S17 | T17: S18 | U17: S19 | V17: S20 | Z17: Module Details
B18: I_theo | C18: =($AA$22*(AA13/$AA$25))+(1+$AA$24*($AA$15-25)) -> 1 | D18: =($AA$22*(AB13/$AA$25))+(1+$AA$24*($AB$15-25)) -> 1 | E18: =($AA$22*(AC13/$AA$25))+(1+$AA$24*($AC$15-25)) -> 1 | F18: =($AA$22*(AD13/$AA$25))+(1+$AA$24*($AD$15-25)) -> 1 | G18: =($AA$22*(AE13/$AA$25))+(1+$AA$24*($AE$15-25)) -> 1 | H18: =($AA$22*(AF13/$AA$25))+(1+$AA$24*($AF$15-25)) -> 1 | I18: =($AA$22*(AG13/$AA$25))+(1+$AA$24*($AG$15-25)) -> 1 | J18: =($AA$22*(AH13/$AA$25))+(1+$AA$24*($AH$15-25)) -> 1 | K18: =($AA$22*(AI13/$AA$25))+(1+$AA$24*($AI$15-25)) -> 1 | L18: =($AA$22*(AJ13/$AA$25))+(1+$AA$24*($AJ$15-25)) -> 1 | M18: =($AA$22*(AK13/$AA$25))+(1+$AA$24*($AK$15-25)) -> 1 | N18: =($AA$22*(AL13/$AA$25))+(1+$AA$24*($AL$15-25)) -> 1 | O18: =($AA$22*(AM13/$AA$25))+(1+$AA$24*($AM$15-25)) -> 1 | P18: =($AA$22*(AN13/$AA$25))+(1+$AA$24*($AN$15-25)) -> 1 | Q18: =($AA$22*(AO13/$AA$25))+(1+$AA$24*($AO$15-25)) -> 1 | R18: =($AA$22*(AP13/$AA$25))+(1+$AA$24*($AP$15-25)) -> 1 | S18: =($AA$22*(AQ13/$AA$25))+(1+$AA$24*($AQ$15-25)) -> 1 | T18: =($AA$22*(AR13/$AA$25))+(1+$AA$24*($AR$15-25)) -> 1 | U18: =($AA$22*(AS13/$AA$25))+(1+$AA$24*($AS$15-25)) -> 1 | V18: =($AA$22*(AT13/$AA$25))+(1+$AA$24*($AT$15-25)) -> 1 | Z18: Vo | AA18: 49.75 | AB18: V | AC18: JAM72S30 545/MR
B19: (1-10%) | C19: =C18*(1-10%) -> 0.9 | D19: =D18*(1-10%) -> 0.9 | E19: =E18*(1-10%) -> 0.9 | F19: =F18*(1-10%) -> 0.9 | G19: =G18*(1-10%) -> 0.9 | H19: =H18*(1-10%) -> 0.9 | I19: =I18*(1-10%) -> 0.9 | J19: =J18*(1-10%) -> 0.9 | ... V19: =V18*(1-10%) -> 0.9 | Z19: CT | AA19: -0.275 | AB19: %/Degree C | AC19: Temperature coefficient
B20: (1+10%) | C20: =C18*(1+10%) -> 1.1 | D20: =D18*(1+10%) -> 1.1 | E20: =E18*(1+10%) -> 1.1 | F20: =F18*(1+10%) -> 1.1 | G20: =G18*(1+10%) -> 1.1 | H20: =H18*(1+10%) -> 1.1 | I20: =I18*(1+10%) -> 1.1 | J20: =J18*(1+10%) -> 1.1 | ... V20: =V18*(1+10%) -> 1.1 | Z20: Vsc | AA20: 41.8 | AB20: V
B21: Isc (A) | C21: =AA14 -> 0 | D21: =AB14 -> 0 | E21: =AC14 -> 0 | F21: =AD14 -> 0 | G21: =AE14 -> 0 | H21: =AF14 -> 0 | I21: =AG14 -> 0 | J21: =AH14 -> 0 | ... V21: =AT14 -> 0
Z22: Iscm | AA22: 13.93 | AB22: A | AC22: Nominal short circuit of pv modules from data sheet
Z23: I | AA23: Table above | AB23: W/m^2 | AC23: Irradiation on on strings of tested panel
C24: =IF(AND(C19<C21,C21<C20),"Passed","Failed") -> Failed | D24: =IF(AND(D19<D21,D21<D20),"Passed","Failed") -> Failed | E24: =IF(AND(E19<E21,E21<E20),"Passed","Failed") -> Failed | F24: =IF(AND(F19<F21,F21<F20),"Passed","Failed") -> Failed | G24: =IF(AND(G19<G21,G21<G20),"Passed","Failed") -> Failed | H24: =IF(AND(H19<H21,H21<H20),"Passed","Failed") -> Failed | I24: =IF(AND(I19<I21,I21<I20),"Passed","Failed") -> Failed | J24: =IF(AND(J19<J21,J21<J20),"Passed","Failed") -> Failed | ... V24: =IF(AND(V19<V21,V21<V20),"Passed","Failed") -> Failed | Z24: C_I | AA24: 0.045 | AB24: %/Degree C | AC24: Current Temp coefficient
Z25: I_STC | AA25: 1000 | AB25: W/m^2 | AC25: Standard irradiation

Sheet Inverter 8
B1: SITE: | C1: ='Inverter 1'!C1 -> Kroonstad PnP | F1: DATE: | J1: INVERTER 8
B3: Open Circuit volatge test
C7: S1 | D7: S2 | E7: S3 | F7: S4 | G7: S5 | H7: S6 | I7: S7 | J7: S8 | K7: S9 | L7: S10 | M7: S11 | N7: S12 | O7: S13 | P7: S14 | Q7: S15 | R7: S16 | S7: S17 | T7: S18 | U7: S19 | V7: S20
B8: V_theo | C8: =AA9*$AA$18+(1+$AA$19*($AA$15-25)) -> 1 | D8: =AB9*$AA$18+(1+$AA$19*($AB$15-25)) -> 1 | E8: =AC9*$AA$18+(1+$AA$19*($AC$15-25)) -> 1 | F8: =AD9*$AA$18+(1+$AA$19*($AD$15-25)) -> 1 | G8: =AE9*$AA$18+(1+$AA$19*($AE$15-25)) -> 1 | H8: =AF9*$AA$18+(1+$AA$19*($AF$15-25)) -> 1 | I8: =AG9*$AA$18+(1+$AA$19*($AG$15-25)) -> 1 | J8: =AH9*$AA$18+(1+$AA$19*($AH$15-25)) -> 1 | K8: =AI9*$AA$18+(1+$AA$19*($AI$15-25)) -> 1 | L8: =AJ9*$AA$18+(1+$AA$19*($AJ$15-25)) -> 1 | M8: =AK9*$AA$18+(1+$AA$19*($AK$15-25)) -> 1 | N8: =AL9*$AA$18+(1+$AA$19*($AL$15-25)) -> 1 | O8: =AM9*$AA$18+(1+$AA$19*($AM$15-25)) -> 1 | P8: =AN9*$AA$18+(1+$AA$19*($AN$15-25)) -> 1 | Q8: =AO9*$AA$18+(1+$AA$19*($AO$15-25)) -> 1 | R8: =AP9*$AA$18+(1+$AA$19*($AP$15-25)) -> 1 | S8: =AQ9*$AA$18+(1+$AA$19*($AQ$15-25)) -> 1 | T8: =AR9*$AA$18+(1+$AA$19*($AR$15-25)) -> 1 | U8: =AS9*$AA$18+(1+$AA$19*($AS$15-25)) -> 1 | V8: =AT9*$AA$18+(1+$AA$19*($AT$15-25)) -> 1 | Z8: Inverter 8 | AA8: S1 | AB8: S2 | AC8: S3 | AD8: S4 | AE8: S5 | AF8: S6 | AG8: S7 | AH8: S8 | AI8: S9 | AJ8: S10 | AK8: S11 | AL8: S12 | AM8: S13 | AN8: S14 | AO8: S15 | AP8: S16 | AQ8: S17 | AR8: S18 | AS8: S19 | AT8: S20
B9: (1-7%) | C9: =C8*(1-7%) -> 0.93 | D9: =D8*(1-7%) -> 0.93 | E9: =E8*(1-7%) -> 0.93 | F9: =F8*(1-7%) -> 0.93 | G9: =G8*(1-7%) -> 0.93 | H9: =H8*(1-7%) -> 0.93 | I9: =I8*(1-7%) -> 0.93 | J9: =J8*(1-7%) -> 0.93 | ... V9: =V8*(1-7%) -> 0.93 | Z9: Module No.
B10: (1+7%) | C10: =C8*(1+7%) -> 1.07 | D10: =D8*(1+7%) -> 1.07 | E10: =E8*(1+7%) -> 1.07 | F10: =F8*(1+7%) -> 1.07 | G10: =G8*(1+7%) -> 1.07 | H10: =H8*(1+7%) -> 1.07 | I10: =I8*(1+7%) -> 1.07 | J10: =J8*(1+7%) -> 1.07 | ... V10: =V8*(1+7%) -> 1.07 | Z10: Open Circuit Voltage (Voc in V)
Z11: Short Circuit Voltage (Vsc in V) | AA11: =AA10-((AA18-AA20)*AA9) -> 0 | AB11: =AB10-((AA18-AA20)*AB9) -> 0 | AC11: =AC10-((AA18-AA20)*AC9) -> 0 | AD11: =AD10-((AA18-AA20)*AD9) -> 0 | AE11: =AE10-((AA18-AA20)*AE9) -> 0 | AF11: =AF10-((AA18-AA20)*AF9) -> 0 | AG11: =AG10-((AA18-AA20)*AG9) -> 0 | AH11: =AH10-((AA18-AA20)*AH9) -> 0 | AI11: =AI10-((AA18-AA20)*AI9) -> 0 | AJ11: =AJ10-((AA18-AA20)*AJ9) -> 0 | AK11: =AK10-((AA18-AA20)*AK9) -> 0 | AL11: =AL10-((AA18-AA20)*AL9) -> 0 | AM11: =AM10-((AA18-AA20)*AM9) -> 0 | AN11: =AN10-((AA18-AA20)*AN9) -> 0 | AO11: =AO10-((AA18-AA20)*AO9) -> 0 | AP11: =AP10-((AA18-AA20)*AP9) -> 0 | AQ11: =AQ10-((AA18-AA20)*AQ9) -> 0 | AR11: =AR10-((AA18-AA20)*AR9) -> 0 | AS11: =AS10-((AA18-AA20)*AS9) -> 0 | AT11: =AT10-((AA18-AA20)*AT9) -> 0
Z12: Insulation Resistance (mΩ)
C13: =IF(AND(C9<AA10,AA10<C10),"Passed","Failed") -> Failed | D13: =IF(AND(D9<AB10,AB10<D10),"Passed","Failed") -> Failed | E13: =IF(AND(E9<AC10,AC10<E10),"Passed","Failed") -> Failed | F13: =IF(AND(F9<AD10,AD10<F10),"Passed","Failed") -> Failed | G13: =IF(AND(G9<AE10,AE10<G10),"Passed","Failed") -> Failed | H13: =IF(AND(H9<AF10,AF10<H10),"Passed","Failed") -> Failed | I13: =IF(AND(I9<AG10,AG10<I10),"Passed","Failed") -> Failed | J13: =IF(AND(J9<AH10,AH10<J10),"Passed","Failed") -> Failed | ... V13: =IF(AND(V9<AT10,AT10<V10),"Passed","Failed") -> Failed | Z13: Irradiance (W)
Z14: Isc (A)
Z15: Cell Temp | AA15: 25 | AB15: 25 | AC15: 25 | AD15: 25 | AE15: 25 | AF15: 25 | AG15: 25 | AH15: 25 | AI15: 25 | AJ15: 25 | AK15: 25 | AL15: 25 | AM15: 25 | AN15: 25 | AO15: 25 | AP15: 25 | AQ15: 25 | AR15: 25 | AS15: 25 | AT15: 25
C17: S1 | D17: S2 | E17: S3 | F17: S4 | G17: S5 | H17: S6 | I17: S7 | J17: S8 | K17: S9 | L17: S10 | M17: S11 | N17: S12 | O17: S13 | P17: S14 | Q17: S15 | R17: S16 | S17: S17 | T17: S18 | U17: S19 | V17: S20 | Z17: Module Details
B18: I_theo | C18: =($AA$22*(AA13/$AA$25))+(1+$AA$24*($AA$15-25)) -> 1 | D18: =($AA$22*(AB13/$AA$25))+(1+$AA$24*($AB$15-25)) -> 1 | E18: =($AA$22*(AC13/$AA$25))+(1+$AA$24*($AC$15-25)) -> 1 | F18: =($AA$22*(AD13/$AA$25))+(1+$AA$24*($AD$15-25)) -> 1 | G18: =($AA$22*(AE13/$AA$25))+(1+$AA$24*($AE$15-25)) -> 1 | H18: =($AA$22*(AF13/$AA$25))+(1+$AA$24*($AF$15-25)) -> 1 | I18: =($AA$22*(AG13/$AA$25))+(1+$AA$24*($AG$15-25)) -> 1 | J18: =($AA$22*(AH13/$AA$25))+(1+$AA$24*($AH$15-25)) -> 1 | K18: =($AA$22*(AI13/$AA$25))+(1+$AA$24*($AI$15-25)) -> 1 | L18: =($AA$22*(AJ13/$AA$25))+(1+$AA$24*($AJ$15-25)) -> 1 | M18: =($AA$22*(AK13/$AA$25))+(1+$AA$24*($AK$15-25)) -> 1 | N18: =($AA$22*(AL13/$AA$25))+(1+$AA$24*($AL$15-25)) -> 1 | O18: =($AA$22*(AM13/$AA$25))+(1+$AA$24*($AM$15-25)) -> 1 | P18: =($AA$22*(AN13/$AA$25))+(1+$AA$24*($AN$15-25)) -> 1 | Q18: =($AA$22*(AO13/$AA$25))+(1+$AA$24*($AO$15-25)) -> 1 | R18: =($AA$22*(AP13/$AA$25))+(1+$AA$24*($AP$15-25)) -> 1 | S18: =($AA$22*(AQ13/$AA$25))+(1+$AA$24*($AQ$15-25)) -> 1 | T18: =($AA$22*(AR13/$AA$25))+(1+$AA$24*($AR$15-25)) -> 1 | U18: =($AA$22*(AS13/$AA$25))+(1+$AA$24*($AS$15-25)) -> 1 | V18: =($AA$22*(AT13/$AA$25))+(1+$AA$24*($AT$15-25)) -> 1 | Z18: Vo | AA18: 49.75 | AB18: V | AC18: JAM72S30 545/MR
B19: (1-10%) | C19: =C18*(1-10%) -> 0.9 | D19: =D18*(1-10%) -> 0.9 | E19: =E18*(1-10%) -> 0.9 | F19: =F18*(1-10%) -> 0.9 | G19: =G18*(1-10%) -> 0.9 | H19: =H18*(1-10%) -> 0.9 | I19: =I18*(1-10%) -> 0.9 | J19: =J18*(1-10%) -> 0.9 | ... V19: =V18*(1-10%) -> 0.9 | Z19: CT | AA19: -0.275 | AB19: %/Degree C | AC19: Temperature coefficient
B20: (1+10%) | C20: =C18*(1+10%) -> 1.1 | D20: =D18*(1+10%) -> 1.1 | E20: =E18*(1+10%) -> 1.1 | F20: =F18*(1+10%) -> 1.1 | G20: =G18*(1+10%) -> 1.1 | H20: =H18*(1+10%) -> 1.1 | I20: =I18*(1+10%) -> 1.1 | J20: =J18*(1+10%) -> 1.1 | ... V20: =V18*(1+10%) -> 1.1 | Z20: Vsc | AA20: 41.8 | AB20: V
B21: Isc (A) | C21: =AA14 -> 0 | D21: =AB14 -> 0 | E21: =AC14 -> 0 | F21: =AD14 -> 0 | G21: =AE14 -> 0 | H21: =AF14 -> 0 | I21: =AG14 -> 0 | J21: =AH14 -> 0 | ... V21: =AT14 -> 0
Z22: Iscm | AA22: 13.93 | AB22: A | AC22: Nominal short circuit of pv modules from data sheet
Z23: I | AA23: Table above | AB23: W/m^2 | AC23: Irradiation on on strings of tested panel
C24: =IF(AND(C19<C21,C21<C20),"Passed","Failed") -> Failed | D24: =IF(AND(D19<D21,D21<D20),"Passed","Failed") -> Failed | E24: =IF(AND(E19<E21,E21<E20),"Passed","Failed") -> Failed | F24: =IF(AND(F19<F21,F21<F20),"Passed","Failed") -> Failed | G24: =IF(AND(G19<G21,G21<G20),"Passed","Failed") -> Failed | H24: =IF(AND(H19<H21,H21<H20),"Passed","Failed") -> Failed | I24: =IF(AND(I19<I21,I21<I20),"Passed","Failed") -> Failed | J24: =IF(AND(J19<J21,J21<J20),"Passed","Failed") -> Failed | ... V24: =IF(AND(V19<V21,V21<V20),"Passed","Failed") -> Failed | Z24: C_I | AA24: 0.045 | AB24: %/Degree C | AC24: Current Temp coefficient
Z25: I_STC | AA25: 1000 | AB25: W/m^2 | AC25: Standard irradiation

Sheet Inverter 9
B1: SITE: | C1: ='Inverter 1'!C1 -> Kroonstad PnP | F1: DATE: | J1: INVERTER 9
B3: Open Circuit volatge test
C7: S1 | D7: S2 | E7: S3 | F7: S4 | G7: S5 | H7: S6 | I7: S7 | J7: S8 | K7: S9 | L7: S10 | M7: S11 | N7: S12 | O7: S13 | P7: S14 | Q7: S15 | R7: S16 | S7: S17 | T7: S18 | U7: S19 | V7: S20
B8: V_theo | C8: =AA9*$AA$18+(1+$AA$19*($AA$15-25)) -> 1 | D8: =AB9*$AA$18+(1+$AA$19*($AB$15-25)) -> 1 | E8: =AC9*$AA$18+(1+$AA$19*($AC$15-25)) -> 1 | F8: =AD9*$AA$18+(1+$AA$19*($AD$15-25)) -> 1 | G8: =AE9*$AA$18+(1+$AA$19*($AE$15-25)) -> 1 | H8: =AF9*$AA$18+(1+$AA$19*($AF$15-25)) -> 1 | I8: =AG9*$AA$18+(1+$AA$19*($AG$15-25)) -> 1 | J8: =AH9*$AA$18+(1+$AA$19*($AH$15-25)) -> 1 | K8: =AI9*$AA$18+(1+$AA$19*($AI$15-25)) -> 1 | L8: =AJ9*$AA$18+(1+$AA$19*($AJ$15-25)) -> 1 | M8: =AK9*$AA$18+(1+$AA$19*($AK$15-25)) -> 1 | N8: =AL9*$AA$18+(1+$AA$19*($AL$15-25)) -> 1 | O8: =AM9*$AA$18+(1+$AA$19*($AM$15-25)) -> 1 | P8: =AN9*$AA$18+(1+$AA$19*($AN$15-25)) -> 1 | Q8: =AO9*$AA$18+(1+$AA$19*($AO$15-25)) -> 1 | R8: =AP9*$AA$18+(1+$AA$19*($AP$15-25)) -> 1 | S8: =AQ9*$AA$18+(1+$AA$19*($AQ$15-25)) -> 1 | T8: =AR9*$AA$18+(1+$AA$19*($AR$15-25)) -> 1 | U8: =AS9*$AA$18+(1+$AA$19*($AS$15-25)) -> 1 | V8: =AT9*$AA$18+(1+$AA$19*($AT$15-25)) -> 1 | Z8: Inverter 9 | AA8: S1 | AB8: S2 | AC8: S3 | AD8: S4 | AE8: S5 | AF8: S6 | AG8: S7 | AH8: S8 | AI8: S9 | AJ8: S10 | AK8: S11 | AL8: S12 | AM8: S13 | AN8: S14 | AO8: S15 | AP8: S16 | AQ8: S17 | AR8: S18 | AS8: S19 | AT8: S20
