Workbook
Name Inverter_Capacity: #REF!
Name Inverter_Supplier: #REF!
Name Project_Size: 'Finance - Revenue'!Projectsize
Name Project_Size: Projectsize
Name Projectsize: #REF!
Name Projectsize: #REF!
Name Security_Serv: #REF!
Name Security_Serv: #REF!
Name SSS: #REF!
Name SSS: #REF!
Name USD_ZAR: #REF!

Sheet Certificate - Financial Close
B2: Emergent Energy – Financial Close Completion Certificate | H2: FINANCIAL CLOSE CERTIFICATE
B4: Project Name: | C4: ='Project Plan'!E2 -> Steelpark
B5: COO: | C5: Johannes Potgieter
B6: Programme Manager: | C6: Roedolph Venter
B7: HoPD: | C7: Natasha Watkins-Baker
B9: Date of Phase Completion:
B10: Phase Deliverables Checklist: (Y/N)
B11: Product Agreement
B12: EPC Agreement
B13: O&M Agreeement
B14: Cost Proposal
B15: Deposit Received
B16: Risks / Notes
B18: Acknowledgement and Acceptance:
B19: Role | C19: Name | D19: Signature | E19: Date

Sheet Certificate - Planning
B2: Emergent Energy – Planning Phase Completion Certificate | H2: PLANNING CERTIFICATE
B4: Project Name: | C4: ='Project Plan'!E2 -> Steelpark
B5: Client Representative:
B6: Programme Manager: | C6: Roedolph Venter
B7: Project Manager: | C7: ='Project Plan'!E5 -> Justin Franke
B8: Project Engineer:
B10: Date of Phase Completion:
B11: Phase Deliverables Checklist: (Y/N)
B12: Project Introduction Presentation
B13: Project Brief | C13: Completed
B14: Engineering Pack | C14: Completed
B15: BOQ | C15: Partially Completed
B16: PO – Material & Equipment
B17: PO - Contractors
B18: HSE – NOC
B19: HSE – EE File
B20: HSE – Contractor File
B21: SSEG Application
B22: Risks / Notes
B24: Acknowledgement and Acceptance:
B25: Role | C25: Name | D25: Signature | E25: Date

Sheet Change Register
F1: Change Register
B3: ID | C3: Description | D3: Supporting Image (If Applicable) | E3: Impact | F3: Proposed Date | G3: Proposed By | H3: Status | I3: Approved By | J3: Approved Date | K3: Results / Comments
B4: DEC001 | C4: Change inverters from 2x 50KTL to 1x100KTL | E4: Engineering change, drawings updated | F4: 45992 | G4: Dean | H4: Approved | I4: Simon & JP | J4: 45992
B5: DEC002 | C5: Roof profile confirmation - Solar compatible | E5: Roof replacement
B6: DEC003
B7: DEC004
B8: DEC005
B9: DEC006
B10: DEC007
B11: DEC008
B12: DEC009
B13: DEC010
B14: DEC011
B15: DEC012
B16: DEC013
B17: DEC014
... B33: DEC030

Sheet BOQ
B2: Item | C2: Supplier | D2: Description | E2: Quantity | F2: Comments
B3: PV Module | C3: Menlo | D3: Jinko 590W - JKM590N-72HL4-BDV | E3: 221
B4: DC Cable Red & Black | C4: Menlo | D4: Enco PV Cable | E4: 4000
B5: Inverters | C5: Menlo | D5: Huawei 100KTL - SUN2000-100-KTL-M2 | E5: 1 | F5: Take note, this has changed to 1x 100KTL
B6: Mounting Structure | C6: Schletter
B7: Current Transformers (Production)
B8: Current Transformers (Consumption)
B9: Solar Production Meter (Techistter)
B10: Grid Consumption Meter
B11: Wi-Fi Router & Sim
B12: Switch
B13: Back Up Battery
B14: PVDB | C14: Switchboard
B23: Supplier List
B24: Accuenergy
B25: Krannich
B26: Menlo
B27: Red Pole
B28: Schletter
B29: Switchboard
B30: Techsitter

Sheet Compliance
B2: HSE
B4: Description | C4: Status | D4: Approved By | E4: Date | F4: Results / Comments
B5: NOC | F5: In Progress
B6: 7.1 Agreement | F6: In Progress
B7: 13.2 Agreement | F7: In Progress
B8: EE File | F8: In Progress
B9: Subbie File | F9: Not appointed
B16: SSEG
B18: Description | C18: Status | D18: Approved By | E18: Date | F18: Results / Comments
B19: SSEG Application
B20: PTI
B21: Commissioning Approval

Sheet Project Plan
N1: =TODAY() -> 46077 | O1: =TODAY() -> 46077
C2: PROJECT PLAN | E2: Steelpark | I2: Net Work Days | K2: =NETWORKDAYS(I20,K41,Data!C3:C60) -> 26 | N2: 0 | O2: 1
C3: PROJECT SIZE (kWp) | E3: 130 | I3: Total Weeks | K3: =K2/5 -> 5.2
C4: PROJECT DEVELOPER | E4: Natasha Watkins-Baker | I4: kW/Week Installation Rate | K4: =E3/K3 -> 25
C5: PROJECT MANAGERS | E5: Justin Franke
C6: CONTRACT VALUE | E6: 1441230.5
C7: Phase: | E7: Planning
B8: No. | C8: HIGH LEVEL PROGRAMME | E8: Planned Start | F8: Duration | G8: Planned End | I8: Actual Start | J8: Duration | K8: Actual End | M8: Status | N8: Expected Status | O8: Comment
F9: =G41-E21 -> 35 | J9: =K41-I21 -> 35 | M9: =AVERAGE(M11,M20,M23,M30,M37,M41,M50,M46) -> 0.090824275 | N9: =AVERAGE(N11,N20,N23,N30,N37,N41,N50,N46) -> 0.090824275 | S9: =TODAY() -> 46077 | T9: =TODAY() -> 46077
S10: 1 | T10: 0
B11: 1 | C11: Project Initiation | E11: =MIN(E12:E19) -> 45986 | F11: =G11-E11 -> 97 | G11: =MAX(G12:G19) -> 46083 | I11: =MIN(I12:I19) -> 45986 | J11: =K11-I11 -> 97 | K11: =MAX(K12:K19) -> 46083 | M11: =(J12*M12+J15*M15+J16*M16+J17*M17+J18*M18)/SUM(J12:J18) -> 0.10326087 | N11: =(J12*M12+J15*M15+J16*M16+J17*M17+J18*M18)/SUM(J12:J18) -> 0.10326087
B12: 1.1 | C12: Project Charter Handover | E12: 45986 | F12: 1 | G12: =WORKDAY.INTL(E12,F12,1,Data!$C$3:$C$60) -> 45987 | I12: 45986 | J12: 1 | K12: =WORKDAY.INTL(I12,J12,1,Data!$C$3:$C$60) -> 45987 | M12: 1 | N12: =_xlfn.LET( _xlpm.s,VALUE($I12), _xlpm.e,VALUE($K12), IF(OR(_xlpm.s="",_xlpm.e=""),"", IF(_xlpm.e<=_xlpm.s, IF(TODAY()>=_xlpm.e,1,0), MAX(0,MIN(1,(TODAY()-_xlpm.s)/(_xlpm.e-_xlpm.s))))) ) -> 1 | S12: Milestone | T12: Start Date | U12: Duration | V12: End Date
B13: 1.2 | C13: Client Roof Replacement | E13: 46053 | F13: 21 | G13: =WORKDAY.INTL(E13,F13,1,Data!$C$3:$C$60) -> 46083 | I13: 46053 | J13: 21 | K13: =WORKDAY.INTL(I13,J13,1,Data!$C$3:$C$60) -> 46083 | M13: 0.4 | N13: =_xlfn.LET( _xlpm.s,VALUE($I13), _xlpm.e,VALUE($K13), IF(OR(_xlpm.s="",_xlpm.e=""),"", IF(_xlpm.e<=_xlpm.s, IF(TODAY()>=_xlpm.e,1,0), MAX(0,MIN(1,(TODAY()-_xlpm.s)/(_xlpm.e-_xlpm.s))))) ) -> 0.8 | O13: Start date 19 Feb | S13: =C11 -> Project Initiation | T13: =I11 -> 45986 | U13: =J11 -> 97 | V13: =K11 -> 46083
B14: 1.3 | C14: DB Works on Client side | E14: 46003 | F14: 10 | G14: =WORKDAY.INTL(E14,F14,1,Data!$C$3:$C$60) -> 46052 | I14: 46003 | J14: 10 | K14: =WORKDAY.INTL(I14,J14,1,Data!$C$3:$C$60) -> 46052 | M14: 1 | N14: =_xlfn.LET( _xlpm.s,VALUE($I14), _xlpm.e,VALUE($K14), IF(OR(_xlpm.s="",_xlpm.e=""),"", IF(_xlpm.e<=_xlpm.s, IF(TODAY()>=_xlpm.e,1,0), MAX(0,MIN(1,(TODAY()-_xlpm.s)/(_xlpm.e-_xlpm.s))))) ) -> 1 | S14: =C20 -> Site Establishment | T14: =I20 -> 46076 | U14: =J20 -> 1 | V14: =K20 -> 46077
B15: 1.4 | C15: HSE Readiness and Signoff | E15: 46062 | F15: 5 | G15: =WORKDAY.INTL(E15,F15,1,Data!$C$3:$C$60) -> 46069 | I15: 46062 | J15: 11 | K15: =WORKDAY.INTL(I15,J15,1,Data!$C$3:$C$60) -> 46077 | M15: 0.25 | N15: =_xlfn.LET( _xlpm.s,VALUE($I15), _xlpm.e,VALUE($K15), IF(OR(_xlpm.s="",_xlpm.e=""),"", IF(_xlpm.e<=_xlpm.s, IF(TODAY()>=_xlpm.e,1,0), MAX(0,MIN(1,(TODAY()-_xlpm.s)/(_xlpm.e-_xlpm.s))))) ) -> 1 | S15: =C23 -> AC Installation | T15: =I23 -> 46039 | U15: =J23 -> 45 | V15: =K23 -> 46084
B16: 1.5 | C16: Project Introduction | E16: 46069 | F16: 1 | G16: =WORKDAY.INTL(E16,F16,1,Data!$C$3:$C$60) -> 46070 | I16: 46069 | J16: 1 | K16: =WORKDAY.INTL(I16,J16,1,Data!$C$3:$C$60) -> 46070 | M16: 1 | N16: =_xlfn.LET( _xlpm.s,VALUE($I16), _xlpm.e,VALUE($K16), IF(OR(_xlpm.s="",_xlpm.e=""),"", IF(_xlpm.e<=_xlpm.s, IF(TODAY()>=_xlpm.e,1,0), MAX(0,MIN(1,(TODAY()-_xlpm.s)/(_xlpm.e-_xlpm.s))))) ) -> 1 | S16: =C30 -> DC Works | T16: =I30 -> 46076 | U16: =J30 -> 24 | V16: =K30 -> 46100
B17: 1.6 | C17: Installer Kick Off | E17: =E16 -> 46069 | F17: 1 | G17: =WORKDAY.INTL(E17,F17,1,Data!$C$3:$C$60) -> 46070 | I17: =I16 -> 46069 | J17: 1 | K17: =WORKDAY.INTL(I17,J17,1,Data!$C$3:$C$60) -> 46070 | M17: 0 | N17: =_xlfn.LET( _xlpm.s,VALUE($I17), _xlpm.e,VALUE($K17), IF(OR(_xlpm.s="",_xlpm.e=""),"", IF(_xlpm.e<=_xlpm.s, IF(TODAY()>=_xlpm.e,1,0), MAX(0,MIN(1,(TODAY()-_xlpm.s)/(_xlpm.e-_xlpm.s))))) ) -> 1 | S17: =C37 -> Module installation | T17: =I37 -> 46076 | U17: =J37 -> 22 | V17: =K37 -> 46098
B18: 1.7 | C18: Project Review | E18: =E17 -> 46069 | F18: 1 | G18: =WORKDAY.INTL(E18,F18,1,Data!$C$3:$C$60) -> 46070 | I18: =I17 -> 46069 | J18: 1 | K18: =WORKDAY.INTL(I18,J18,1,Data!$C$3:$C$60) -> 46070 | M18: 0 | N18: =_xlfn.LET( _xlpm.s,VALUE($I18), _xlpm.e,VALUE($K18), IF(OR(_xlpm.s="",_xlpm.e=""),"", IF(_xlpm.e<=_xlpm.s, IF(TODAY()>=_xlpm.e,1,0), MAX(0,MIN(1,(TODAY()-_xlpm.s)/(_xlpm.e-_xlpm.s))))) ) -> 1 | S18: =C41 -> Commissioning | T18: =I41 -> 46100 | U18: =J41 -> 11 | V18: =K41 -> 46111
S19: =C46 -> QA Inspections | T19: =I46 -> 46104 | U19: =J46 -> 8 | V19: =K46 -> 46112
B20: 2 | C20: Site Establishment | E20: =MIN(E21:E22) -> 46076 | F20: =G20-E20 -> 1 | G20: =MAX(G21:G22) -> 46077 | I20: =MIN(I21:I22) -> 46076 | J20: =K20-I20 -> 1 | K20: =MAX(K21:K22) -> 46077 | M20: =(J21*M21)/J20 -> 0 | N20: =(J21*M21)/J20 -> 0 | S20: =C50 -> Project Closure | T20: =I50 -> 46104 | U20: =J50 -> 18 | V20: =K50 -> 46122
B21: 2.1 | C21: Solar Contractor Establishment | E21: =E18+7 -> 46076 | F21: 1 | G21: =E21+F21 -> 46077 | I21: =I18+7 -> 46076 | J21: 1 | K21: =I21+J21 -> 46077 | M21: 0 | N21: =_xlfn.LET( _xlpm.s,VALUE($I21), _xlpm.e,VALUE($K21), IF(OR(_xlpm.s="",_xlpm.e=""),"", IF(_xlpm.e<=_xlpm.s, IF(TODAY()>=_xlpm.e,1,0), MAX(0,MIN(1,(TODAY()-_xlpm.s)/(_xlpm.e-_xlpm.s))))) ) -> 1
B23: 3 | C23: AC Installation | E23: =MIN(E24:E29) -> 46039 | F23: =G23-E23 -> 45 | G23: =MAX(G24:G29) -> 46084 | I23: =MIN(I24:I29) -> 46039 | J23: =K23-I23 -> 45 | K23: =MAX(K24:K29) -> 46084 | M23: =(J24*M24+J25*M25+J26*M26+J27*M27+J28*M28)/SUM(J24:J28) -> 0.62333333 | N23: =(J24*M24+J25*M25+J26*M26+J27*M27+J28*M28)/SUM(J24:J28) -> 0.62333333
B24: 3.1 | C24: Inverters delivered | E24: =WORKDAY.INTL(E21,0,1,Data!$C$3:$C$60) -> 46076 | F24: 1 | G24: =WORKDAY.INTL(E24,F24,1,Data!$C$3:$C$60) -> 46077 | I24: =WORKDAY.INTL(I21,0,1,Data!$C$3:$C$60) -> 46076 | J24: 1 | K24: =WORKDAY.INTL(I24,J24,1,Data!$C$3:$C$60) -> 46077 | M24: 0 | N24: =_xlfn.LET( _xlpm.s,VALUE($I24), _xlpm.e,VALUE($K24), IF(OR(_xlpm.s="",_xlpm.e=""),"", IF(_xlpm.e<=_xlpm.s, IF(TODAY()>=_xlpm.e,1,0), MAX(0,MIN(1,(TODAY()-_xlpm.s)/(_xlpm.e-_xlpm.s))))) ) -> 1
B25: 3.2 | C25: Inverters Mounted | E25: =WORKDAY.INTL(G24,0,1,Data!$C$3:$C$60) -> 46077 | F25: 1 | G25: =WORKDAY.INTL(E25,F25,1,Data!$C$3:$C$60) -> 46078 | I25: =WORKDAY.INTL(K24,0,1,Data!$C$3:$C$60) -> 46077 | J25: 1 | K25: =WORKDAY.INTL(I25,J25,1,Data!$C$3:$C$60) -> 46078 | M25: 0 | N25: =_xlfn.LET( _xlpm.s,VALUE($I25), _xlpm.e,VALUE($K25), IF(OR(_xlpm.s="",_xlpm.e=""),"", IF(_xlpm.e<=_xlpm.s, IF(TODAY()>=_xlpm.e,1,0), MAX(0,MIN(1,(TODAY()-_xlpm.s)/(_xlpm.e-_xlpm.s))))) ) -> 0
B26: 3.3 | C26: Solar DB Lead Time | E26: =WORKDAY.INTL(E16,0,1,Data!$C$3:$C$60)-30 -> 46039 | F26: 20 | G26: =WORKDAY.INTL(E26,F26,1,Data!$C$3:$C$60) -> 46066 | I26: =WORKDAY.INTL(I16,0,1,Data!$C$3:$C$60)-30 -> 46039 | J26: 22 | K26: =WORKDAY.INTL(I26,J26,1,Data!$C$3:$C$60) -> 46070 | M26: 0.85 | N26: =_xlfn.LET( _xlpm.s,VALUE($I26), _xlpm.e,VALUE($K26), IF(OR(_xlpm.s="",_xlpm.e=""),"", IF(_xlpm.e<=_xlpm.s, IF(TODAY()>=_xlpm.e,1,0), MAX(0,MIN(1,(TODAY()-_xlpm.s)/(_xlpm.e-_xlpm.s))))) ) -> 1
B27: 3.4 | C27: AC Works | E27: =WORKDAY.INTL(E25,0,1,Data!$C$3:$C$60) -> 46077 | F27: 5 | G27: =WORKDAY.INTL(E27,F27,1,Data!$C$3:$C$60) -> 46084 | I27: =WORKDAY.INTL(I25,0,1,Data!$C$3:$C$60) -> 46077 | J27: 5 | K27: =WORKDAY.INTL(I27,J27,1,Data!$C$3:$C$60) -> 46084 | M27: 0 | N27: =_xlfn.LET( _xlpm.s,VALUE($I27), _xlpm.e,VALUE($K27), IF(OR(_xlpm.s="",_xlpm.e=""),"", IF(_xlpm.e<=_xlpm.s, IF(TODAY()>=_xlpm.e,1,0), MAX(0,MIN(1,(TODAY()-_xlpm.s)/(_xlpm.e-_xlpm.s))))) ) -> 0
B28: 3.5 | C28: AC Tie-In | E28: =WORKDAY.INTL(E27,0,1,Data!$C$3:$C$60) -> 46077 | F28: 1 | G28: =WORKDAY.INTL(E28,F28,1,Data!$C$3:$C$60) -> 46078 | I28: =WORKDAY.INTL(I27,0,1,Data!$C$3:$C$60) -> 46077 | J28: 1 | K28: =WORKDAY.INTL(I28,J28,1,Data!$C$3:$C$60) -> 46078 | M28: 0 | N28: =_xlfn.LET( _xlpm.s,VALUE($I28), _xlpm.e,VALUE($K28), IF(OR(_xlpm.s="",_xlpm.e=""),"", IF(_xlpm.e<=_xlpm.s, IF(TODAY()>=_xlpm.e,1,0), MAX(0,MIN(1,(TODAY()-_xlpm.s)/(_xlpm.e-_xlpm.s))))) ) -> 0
B30: 4 | C30: DC Works | E30: =MIN(E32:E36) -> 46076 | F30: =G30-E30 -> 24 | G30: =MAX(G32:G36) -> 46100 | I30: =MIN(I32:I36) -> 46076 | J30: =K30-I30 -> 24 | K30: =MAX(K32:K36) -> 46100 | M30: =(J32*M32+J33*M33+J35*M35)/SUM(J32:J35) -> 0 | N30: =(J32*M32+J33*M33+J35*M35)/SUM(J32:J35) -> 0
B32: 4.1 | C32: Mounting Structure delivered | E32: =E21 -> 46076 | F32: 1 | G32: =WORKDAY.INTL(E32,F32,1,Data!$C$3:$C$60) -> 46077 | I32: =I21 -> 46076 | J32: 1 | K32: =WORKDAY.INTL(I32,J32,1,Data!$C$3:$C$60) -> 46077 | M32: 0 | N32: =_xlfn.LET( _xlpm.s,VALUE($I32), _xlpm.e,VALUE($K32), IF(OR(_xlpm.s="",_xlpm.e=""),"", IF(_xlpm.e<=_xlpm.s, IF(TODAY()>=_xlpm.e,1,0), MAX(0,MIN(1,(TODAY()-_xlpm.s)/(_xlpm.e-_xlpm.s))))) ) -> 1
B33: 4.2 | C33: Mounting Structure installation | E33: =WORKDAY.INTL(G13,0,1,Data!$C$3:$C$60)+7 -> 46090 | F33: 2 | G33: =WORKDAY.INTL(E33,F33,1,Data!$C$3:$C$60) -> 46092 | I33: =WORKDAY.INTL(K13,0,1,Data!$C$3:$C$60)+7 -> 46090 | J33: 2 | K33: =WORKDAY.INTL(I33,J33,1,Data!$C$3:$C$60) -> 46092 | M33: 0 | N33: =_xlfn.LET( _xlpm.s,VALUE($I33), _xlpm.e,VALUE($K33), IF(OR(_xlpm.s="",_xlpm.e=""),"", IF(_xlpm.e<=_xlpm.s, IF(TODAY()>=_xlpm.e,1,0), MAX(0,MIN(1,(TODAY()-_xlpm.s)/(_xlpm.e-_xlpm.s))))) ) -> 0
B34: 4.3 | C34: DC Cable delivered | E34: =E32 -> 46076 | F34: 1 | G34: =WORKDAY.INTL(E34,F34,1,Data!$C$3:$C$60) -> 46077 | I34: =I32 -> 46076 | J34: 1 | K34: =WORKDAY.INTL(I34,J34,1,Data!$C$3:$C$60) -> 46077 | M34: 0 | N34: =_xlfn.LET( _xlpm.s,VALUE($I34), _xlpm.e,VALUE($K34), IF(OR(_xlpm.s="",_xlpm.e=""),"", IF(_xlpm.e<=_xlpm.s, IF(TODAY()>=_xlpm.e,1,0), MAX(0,MIN(1,(TODAY()-_xlpm.s)/(_xlpm.e-_xlpm.s))))) ) -> 1
B35: 4.4 | C35: DC Stringing | E35: =WORKDAY.INTL(G39,0,1,Data!$C$3:$C$60)-3 -> 46095 | F35: 4 | G35: =WORKDAY.INTL(E35,F35,1,Data!$C$3:$C$60) -> 46100 | I35: =WORKDAY.INTL(K39,0,1,Data!$C$3:$C$60)-3 -> 46095 | J35: 4 | K35: =WORKDAY.INTL(I35,J35,1,Data!$C$3:$C$60) -> 46100 | M35: 0 | N35: =_xlfn.LET( _xlpm.s,VALUE($I35), _xlpm.e,VALUE($K35), IF(OR(_xlpm.s="",_xlpm.e=""),"", IF(_xlpm.e<=_xlpm.s, IF(TODAY()>=_xlpm.e,1,0), MAX(0,MIN(1,(TODAY()-_xlpm.s)/(_xlpm.e-_xlpm.s))))) ) -> 0
B37: 5 | C37: Module installation | E37: =MIN(E38:E40) -> 46076 | F37: =G37-E37 -> 22 | G37: =MAX(G38:G40) -> 46098 | I37: =MIN(I38:I40) -> 46076 | J37: =K37-I37 -> 22 | K37: =MAX(K38:K40) -> 46098 | M37: =(J38*M38+J39*M39)/SUM(J38:J39) -> 0 | N37: =(J38*M38+J39*M39)/SUM(J38:J39) -> 0
B38: 5.1 | C38: Module delivery | E38: =WORKDAY.INTL(E21,0,1,Data!$C$3:$C$60) -> 46076 | F38: 1 | G38: =WORKDAY.INTL(E38,F38,1,Data!$C$3:$C$60) -> 46077 | I38: =WORKDAY.INTL(I21,0,1,Data!$C$3:$C$60) -> 46076 | J38: 1 | K38: =WORKDAY.INTL(I38,J38,1,Data!$C$3:$C$60) -> 46077 | M38: 0 | N38: =_xlfn.LET( _xlpm.s,VALUE($I38), _xlpm.e,VALUE($K38), IF(OR(_xlpm.s="",_xlpm.e=""),"", IF(_xlpm.e<=_xlpm.s, IF(TODAY()>=_xlpm.e,1,0), MAX(0,MIN(1,(TODAY()-_xlpm.s)/(_xlpm.e-_xlpm.s))))) ) -> 1
B39: 5.2 | C39: Module mounting | E39: =G33 -> 46092 | F39: 4 | G39: =WORKDAY.INTL(E39,F39,1,Data!$C$3:$C$60) -> 46098 | I39: =K33 -> 46092 | J39: 4 | K39: =WORKDAY.INTL(I39,J39,1,Data!$C$3:$C$60) -> 46098 | M39: 0 | N39: =_xlfn.LET( _xlpm.s,VALUE($I39), _xlpm.e,VALUE($K39), IF(OR(_xlpm.s="",_xlpm.e=""),"", IF(_xlpm.e<=_xlpm.s, IF(TODAY()>=_xlpm.e,1,0), MAX(0,MIN(1,(TODAY()-_xlpm.s)/(_xlpm.e-_xlpm.s))))) ) -> 0
B41: 6 | C41: Commissioning | E41: =MIN(E42:E45) -> 46100 | F41: =G41-E41 -> 11 | G41: =MAX(G42:G45) -> 46111 | I41: =MIN(I42:I45) -> 46100 | J41: =K41-I41 -> 11 | K41: =MAX(K42:K45) -> 46111 | M41: =(J42*M42+J43*M43+J44*M44)/SUM(J42:J44) -> 0 | N41: =(J42*M42+J43*M43+J44*M44)/SUM(J42:J44) -> 0
B42: 6.1 | C42: Commissioning | E42: =WORKDAY.INTL(MAX(G23,G30,G37),0,1,Data!$C$3:$C$60) -> 46100 | F42: 1 | G42: =WORKDAY.INTL(E42,F42,1,Data!$C$3:$C$60) -> 46101 | I42: =WORKDAY.INTL(MAX(K23,K30,K37),0,1,Data!$C$3:$C$60) -> 46100 | J42: 1 | K42: =WORKDAY.INTL(I42,J42,1,Data!$C$3:$C$60) -> 46101 | M42: 0 | N42: =_xlfn.LET( _xlpm.s,VALUE($I42), _xlpm.e,VALUE($K42), IF(OR(_xlpm.s="",_xlpm.e=""),"", IF(_xlpm.e<=_xlpm.s, IF(TODAY()>=_xlpm.e,1,0), MAX(0,MIN(1,(TODAY()-_xlpm.s)/(_xlpm.e-_xlpm.s))))) ) -> 0
B43: 6.2 | C43: Practical Completion | E43: =WORKDAY.INTL(G42,0,1,Data!$C$3:$C$60) -> 46101 | F43: 1 | G43: =WORKDAY.INTL(E43,F43,1,Data!$C$3:$C$60) -> 46104 | I43: =WORKDAY.INTL(K42,0,1,Data!$C$3:$C$60) -> 46101 | J43: 1 | K43: =WORKDAY.INTL(I43,J43,1,Data!$C$3:$C$60) -> 46104 | M43: 0 | N43: =_xlfn.LET( _xlpm.s,VALUE($I43), _xlpm.e,VALUE($K43), IF(OR(_xlpm.s="",_xlpm.e=""),"", IF(_xlpm.e<=_xlpm.s, IF(TODAY()>=_xlpm.e,1,0), MAX(0,MIN(1,(TODAY()-_xlpm.s)/(_xlpm.e-_xlpm.s))))) ) -> 0
B44: 6.3 | C44: System Performance Monitoring | E44: =WORKDAY.INTL(G43,0,1,Data!$C$3:$C$60) -> 46104 | F44: 5 | G44: =WORKDAY.INTL(E44,F44,1,Data!$C$3:$C$60) -> 46111 | I44: =WORKDAY.INTL(K43,0,1,Data!$C$3:$C$60) -> 46104 | J44: 5 | K44: =WORKDAY.INTL(I44,J44,1,Data!$C$3:$C$60) -> 46111 | M44: 0 | N44: =_xlfn.LET( _xlpm.s,VALUE($I44), _xlpm.e,VALUE($K44), IF(OR(_xlpm.s="",_xlpm.e=""),"", IF(_xlpm.e<=_xlpm.s, IF(TODAY()>=_xlpm.e,1,0), MAX(0,MIN(1,(TODAY()-_xlpm.s)/(_xlpm.e-_xlpm.s))))) ) -> 0
B46: 7 | C46: QA Inspections | E46: =MIN(E47:E49) -> 46104 | F46: =G46-E46 -> 8 | G46: =MAX(G47:G49) -> 46112 | I46: =MIN(I47:I49) -> 46104 | J46: =K46-I46 -> 8 | K46: =MAX(K47:K49) -> 46112 | M46: =(J47*M47+J48*M48)/SUM(J47:J48) -> 0 | N46: =(J47*M47+J48*M48)/SUM(J47:J48) -> 0
...

Sheet Expenditure Breakdown
B2: COSTED EXPENDITURE BREAKDOWN | I2: =SUM(I6:I166) -> 1194452.5 | J2: =SUM(J6:J166) -> 1399380.6 | L2: ACTUAL EXPENDITURE BREAKDOWN | R2: FINANCE ONLY | X2: =SUM(X6:X166) -> 828370.34
B4: No. | C4: Product / Service | D4: Description of Work | E4: QTY | F4: Rate / Unit | G4: Budget Total | H4: FORECASTED PAYMENT DATE | I4: Total COS | J4: =IF(J2-'Revenue Tracking'!D4>=0, "Total Revenue", "ERROR on REV" ) -> ERROR on REV | L4: No. | M4: Product/ Service | N4: Description of Work | O4: QTY | P4: Rate / Unit | Q4: Actual Total | R4: PO NUMBER | S4: INVOICE NUMBER | T4: INVOICE RAISED DATE | U4: REVENUE RECOGNITION AMOUNT | V4: CHECK | W4: FINANCE PAYMENT DATE | X4: Total COS
B6: 1 | C6: Panels | D6: Panels Budget | G6: =D167 -> 370794.53 | H6: ='Project Plan'!E38+60 -> 46136 | I6: =SUM(G6:G11) -> 370794.53 | J6: =F167 -> 452188.45 | L6: 1 | M6: 1. Panels | N6: Jinko 590W - JKM590N-72HL4-BDV - Menlo | O6: 221 | P6: 1180 | Q6: =O6*P6 -> 260780 | T6: 46081 | U6: =(Q6/$X$6*$J$6) -> 452188.45 | V6: =J6-SUM(U6:U11) -> 0 | W6: ='Project Plan'!I38+60 -> 46136 | X6: =SUM(Q6:Q11) -> 260780
B7: 1 | D7: Delivery Budget | L7: 1 | M7: 1. Panels | P7: =P6/590 -> 2 | T7: =IF(W7>1,EOMONTH(W7,0),"") | U7: =(Q7/$X$6*$J$6) -> 0
B8: 1 | L8: 1 | M8: 1. Panels | T8: =IF(W8>1,EOMONTH(W8,0),"") | U8: =(Q8/$X$6*$J$6) -> 0
B9: 1 | L9: 1 | M9: 1. Panels | T9: =IF(W9>1,EOMONTH(W9,0),"") | U9: =(Q9/$X$6*$J$6) -> 0
B10: 1 | L10: 1 | M10: 1. Panels | T10: =IF(W10>1,EOMONTH(W10,0),"") | U10: =(Q10/$X$6*$J$6) -> 0
B11: 1 | L11: 1 | M11: 1. Panels | T11: =IF(W11>1,EOMONTH(W11,0),"") | U11: =(Q11/$X$6*$J$6) -> 0 | Y11: BUDGET | Z11: Installer Allocation
T12: =IF(W12>1,EOMONTH(W12,0),"") | Y12: AC Equipment | Z12: =G58 -> 198443.49
B13: 2 | C13: Inverters | D13: Inverter Budget | G13: =D168 -> 95000 | H13: ='Project Plan'!E24+60 -> 46136 | I13: =SUM(G13:G19) -> 95000 | J13: =F168 -> 115853.66 | L13: 2 | M13: 2. Inverters | U13: =(Q13/$X$13*$J$13) -> 0 | V13: =J13-SUM(U13:U19) -> 0 | X13: =SUM(Q13:Q19) -> 69000 | Y13: DC Equipment | Z13: =G34 -> 50822.8
B14: 2 | L14: 2 | M14: 2. Inverters | N14: Huawei 100KTL - Use stock from Mayo Macs | O14: 1 | P14: 69000 | Q14: =O14*P14 -> 69000 | T14: =T6 -> 46081 | U14: =(Q14/$X$13*$J$13) -> 115853.66 | W14: =W6 -> 46136 | Y14: AC Labour | Z14: =G95 -> 32490
B15: 2 | L15: 2 | M15: 2. Inverters | T15: =IF(W15>1,EOMONTH(W15,0),"") | U15: =(Q15/$X$13*$J$13) -> 0 | Y15: DC Labour | Z15: =G96 -> 75810
B16: 2 | L16: 2 | M16: 2. Inverters | T16: =IF(W16>1,EOMONTH(W16,0),"") | U16: =(Q16/$X$13*$J$13) -> 0 | Y16: Offloading | Z16: =G108 -> 8500
B17: 2 | L17: 2 | M17: 2. Inverters | T17: =IF(W17>1,EOMONTH(W17,0),"") | U17: =(Q17/$X$13*$J$13) -> 0 | Y17: Scaffolding | Z17: =G109 -> 21741.9
B18: 2 | L18: 2 | M18: 2. Inverters | T18: =IF(W18>1,EOMONTH(W18,0),"") | U18: =(Q18/$X$13*$J$13) -> 0 | Y18: Storage | Z18: =G111 -> 0
B19: 2 | L19: 2 | M19: 2. Inverters | T19: =IF(W19>1,EOMONTH(W19,0),"") | U19: =(Q19/$X$13*$J$13) -> 0 | Y19: Telehandler | Z19: 0
T20: =IF(W20>1,EOMONTH(W20,0),"")
B21: 3 | C21: Mounting Structures | D21: Structure Budget | G21: =D169 -> 58482 | H21: ='Project Plan'!E32+30 -> 46106 | I21: =SUM(G21:G31) -> 58482 | J21: =F169 -> 71319.512 | L21: 3 | M21: 3. Mounting Structures | N21: Schletter Structure | U21: =(Q21/$X$21*$J$21) -> 0 | V21: =J21-SUM(U21:U31) -> 0 | X21: =SUM(Q21:Q31) -> 15616.04 | Y21: Other | Z21: 0
B22: 3 | L22: 3 | M22: 3. Mounting Structures | N22: Clampfit Pro | O22: 400 | P22: 22.73 | Q22: =O22*P22 -> 9092 | T22: 46081 | U22: =(Q22/$X$21*$J$21) -> 41523.78 | W22: 03/31/2026 | Y22: Total | Z22: =SUM(Z12:Z21) -> 387808.19
L23: 3 | M23: 3. Mounting Structures | N23: Clampfit Pro | O23: 74 | P23: 23.96 | Q23: =O23*P23 -> 1773.04 | S23: Allocated from Joburg Streroom | T23: 46081 | U23: =(Q23/$X$21*$J$21) -> 8097.5937 | W23: 46081
L24: 3 | M24: 3. Mounting Structures | N24: Clampfit Pro | O24: =200-74 -> 126 | S24: Joburg Storeroom | T24: 46081 | U24: =(Q24/$X$21*$J$21) -> 0 | W24: 46081
B25: 3 | L25: 3 | M25: 3. Mounting Structures | N25: Mid Clamps | O25: 100 | P25: 10.95 | Q25: =O25*P25 -> 1095 | S25: Allocated from Cpt Storeroom | T25: 46081 | U25: =(Q25/$X$21*$J$21) -> 5000.9392 | W25: 46081 | Y25: Less 15% | Z25: =+Z22*0.85 -> 329636.96
L26: 3 | M26: 3. Mounting Structures | N26: Mid Clamps | O26: 100 | P26: 11.52 | Q26: =O26*P26 -> 1152 | S26: Allocated from Cpt Storeroom | T26: 46081 | U26: =(Q26/$X$21*$J$21) -> 5261.262 | W26: 46081
L27: 3 | M27: 3. Mounting Structures | N27: Mid Clamps | O27: 200 | S27: Joburg Storeroom | T27: 46081 | U27: =(Q27/$X$21*$J$21) -> 0 | W27: 46081
B28: 3 | L28: 3 | M28: 3. Mounting Structures | N28: End Clamps | O28: 200 | P28: 12.52 | Q28: =O28*P28 -> 2504 | T28: 46081 | U28: =(Q28/$X$21*$J$21) -> 11435.938 | W28: 03/31/2026 | Y28: R/Wp | Z28: =Z25/'Project Plan'!$E$3/1000 -> 2.5356689
L29: 3 | M29: 3. Mounting Structures | T29: 46081 | U29: =(Q29/$X$21*$J$21) -> 0 | W29: 46081
B30: 3 | L30: 3 | M30: 3. Mounting Structures | N30: Screws | O30: =O22*2 -> 800 | T30: 46081 | U30: =(Q30/$X$21*$J$21) -> 0 | W30: 46081
B31: 3 | L31: 3 | M31: 3. Mounting Structures | N31: Screws | O31: 1000 | Q31: 0 | S31: Joburg Storeroom | T31: 46081 | U31: =(Q31/$X$21*$J$21) -> 0 | W31: 46081 | Y31: ACTUAL - Leading Edge Power | Z31: Installer Price | AB31: ACTUAL - Happy Solar | AC31: Installer Price | AE31: ACTUAL - Cosmic Sun | AF31: Installer Price
T32: =IF(W32>1,EOMONTH(W32,0),"") | Y32: =Y12 -> AC Equipment | Z32: 35629.45 | AB32: AC Equipment | AC32: 85150 | AE32: AC Equipment | AF32: 41000
B33: 4 | C33: DC Equipment | D33: DC Cable Budget | E33: 1328 | G33: 18592 | H33: ='Project Plan'!E34+60 -> 46136 | I33: =SUM(G33:G47) -> 69414.8 | J33: =F170 -> 84652.195 | L33: 4 | M33: 4. DC Equipment | N33: DC Cable - Menlo | O33: 2000 | P33: 14 | Q33: =O33*P33 -> 28000 | T33: =T6 -> 46081 | U33: =(Q33/$X$33*$J$33) -> 24553.021 | V33: =J33-SUM(U33:U47) -> 0 | W33: =W6 -> 46136 | X33: =SUM(Q33:Q47) -> 96536.45 | Y33: =Y13 -> DC Equipment | Z33: 72341.45 | AB33: DC Equipment | AC33: 54990 | AE33: DC Equipment | AF33: 69107.78
B34: 4 | D34: DC Equipment Budget | G34: =D170-G33 -> 50822.8 | H34: ='Project Plan'!G30 -> 46100 | L34: 4 | M34: 4. DC Equipment | N34: Check DC Cable Stock | T34: =IF(W34>1,EOMONTH(W34,0),"") | U34: =(Q34/$X$33*$J$33) -> 0 | Y34: =Y14 -> AC Labour | Z34: 41239.56 | AA34: =Z34/'Project Plan'!$E$3/1000 -> 0.31722738 | AB34: AC Labour | AC34: 84500 | AD34: =AC34/'Project Plan'!$E$3/1000 -> 0.65 | AE34: AC Labour | AF34: 42900 | AG34: =AF34/'Project Plan'!$E$3/1000 -> 0.33
B35: 4 | L35: 4 | M35: 4. DC Equipment | T35: =IF(W35>1,EOMONTH(W35,0),"") | U35: =(Q35/$X$33*$J$33) -> 0 | Y35: =Y15 -> DC Labour | Z35: 90230.36 | AA35: =Z35/'Project Plan'!$E$3/1000 -> 0.69407969 | AB35: DC Labour | AC35: 106210 | AD35: =AC35/'Project Plan'!$E$3/1000 -> 0.817 | AE35: DC Labour | AF35: 93600 | AG35: =AF35/'Project Plan'!$E$3/1000 -> 0.72
B36: 4 | L36: 4 | M36: 4. DC Equipment | T36: =IF(W36>1,EOMONTH(W36,0),"") | U36: =(Q36/$X$33*$J$33) -> 0 | Y36: Offloading | Z36: 12000 | AB36: Logistics | AC36: 114000 | AE36: Offloading | AF36: 7150
B37: 4 | L37: 4 | M37: 4. DC Equipment | N37: Project Kick Off | O37: =Z50 -> 68536.45 | P37: 0.1 | Q37: =$O$37*P37 -> 6853.645 | R37: PO4620-SSP-20260212 - RV Approved | S37: Leading Edge Energy Inv: INV-0186 | T37: 46081 | U37: =(Q37/$X$33*$J$33) -> 6009.9174 | W37: =W96 -> 46073 | Y37: Geda Lift | Z37: 12397 | AB37: Forklift | AC37: 0 | AE37: Roof Access | AF37: 5775
B38: 4 | L38: 4 | M38: 4. DC Equipment | N38: Site Establishment | P38: 0.15 | Q38: =$O$37*P38 -> 10280.467 | S38: Leading Edge Energy Inv: INV-0187 | T38: 46081 | U38: =(Q38/$X$33*$J$33) -> 9014.8762 | W38: =W97 -> 46076 | Y38: Storage | Z38: 9450 | AB38: Geda | AC38: 0 | AE38: Site Container | AF38: 6600
B39: 4 | L39: 4 | M39: 4. DC Equipment | N39: AC Installation Complete | P39: 0.2 | Q39: =$O$37*P39 -> 13707.29 | T39: 46081 | U39: =(Q39/$X$33*$J$33) -> 12019.835 | W39: =W98 -> 46091 | Y39: Toilet Rental | Z39: 1600 | AB39: Logistics | AC39: 0 | AE39: HSE Compliance | AF39: 4500
B40: 4 | L40: 4 | M40: 4. DC Equipment | N40: DC Installation Complete | P40: 0.25 | Q40: =$O$37*P40 -> 17134.112 | T40: =T99 -> 46112 | U40: =(Q40/$X$33*$J$33) -> 15024.794 | W40: =W99 -> 46107 | Y40: Travel | Z40: 9345.93 | AB40: HSE | AC40: 0 | AE40: HSE | AF40: 0
B41: 4 | L41: 4 | M41: 4. DC Equipment | N41: Commissioning Complete | P41: 0.1 | Q41: =$O$37*P41 -> 6853.645 | T41: =T100 -> 46142 | U41: =(Q41/$X$33*$J$33) -> 6009.9174 | W41: =W100 -> 46118 | Y41: COC | Z41: 4500 | AB41: Other | AC41: 0 | AE41: Other | AF41: 0
B42: 4 | L42: 4 | M42: 4. DC Equipment | N42: Site De-establisment | P42: 0.1 | Q42: =$O$37*P42 -> 6853.645 | T42: =T101 -> 46142 | U42: =(Q42/$X$33*$J$33) -> 6009.9174 | W42: =W101 -> 46119 | Y42: HSE | Z42: 6750 | AB42: Other | AC42: 0 | AE42: Other | AF42: 0
B43: 4 | L43: 4 | M43: 4. DC Equipment | N43: Handover Document Complete | P43: 0.05 | Q43: =$O$37*P43 -> 3426.8225 | T43: =T102 -> 46142 | U43: =(Q43/$X$33*$J$33) -> 3004.9587 | W43: =W102 -> 46119 | Y43: Total | Z43: =SUM(Z32:Z42) -> 295483.75 | AB43: Total | AC43: =SUM(AC32:AC42) -> 444850 | AE43: Total | AF43: =SUM(AF32:AF42) -> 270632.78
...

Sheet Revenue Tracking
B2: HIGH LEVEL PROJECT REVENUE TRACKING
D3: COSTED | F3: ACTUAL | L3: FINANCIAL REVIEW | N3: TIMELINE REVIEW | T3: 2026 Budget Revenue | U3: 2026 Budget COS | V3: 2026 Actual Revenue | W3: 2026 Actual COS
B4: 1 | C4: Planned Revenue | D4: ='Project Plan'!E6 -> 1441230.5 | F4: 1399380.6 | N4: Start Date | T4: =SUMIFS('Expenditure Breakdown'!$U:$U, 'Expenditure Breakdown'!$T:$T, ">"&DATE(2025,8,31), 'Expenditure Breakdown'!$T:$T, "<="&DATE(2026,8,31)) -> 1399380.6 | U4: =SUMIFS('Expenditure Breakdown'!$Q:$Q, 'Expenditure Breakdown'!$T:$T, ">"&DATE(2025,8,31), 'Expenditure Breakdown'!$T:$T, "<="&DATE(2026,8,31)) -> 828370.34 | V4: =SUMIFS('Expenditure Breakdown'!$U:$U, 'Expenditure Breakdown'!$T:$T, ">"&DATE(2025,8,31), 'Expenditure Breakdown'!$T:$T, "<="&DATE(2026,8,31), 'Expenditure Breakdown'!$S:$S, "<>") -> 294328.26 | W4: =SUMIFS('Expenditure Breakdown'!$Q:$Q, 'Expenditure Breakdown'!$T:$T, ">"&DATE(2025,8,31), 'Expenditure Breakdown'!$T:$T, "<="&DATE(2026,8,31), 'Expenditure Breakdown'!$S:$S, "<>") -> 178144.35
B5: 2 | C5: Planned Expenditure | D5: =+'Expenditure Tracking'!F5 -> 1194452.5 | F5: =+'Expenditure Tracking'!H5 -> 828370.34 | G5: VO PM LIMIT | H5: CURRENT VO Total
B6: 3 | C6: Planned Profit | D6: =+D4-D5 -> 246778.02 | F6: =+F4-F5 -> 571010.27 | G6: =D6*0.05 -> 12338.901 | H6: =SUMIF('Expenditure Breakdown'!N:N,"*VO*",'Expenditure Breakdown'!Q:Q) -> 0 | N6: End Date - PC
B7: 4 | C7: Planned Margin | D7: =+D6/D4 -> 0.17122731 | F7: =+F6/F4 -> 0.408045
B10: CONTRACT
B12: No. | C12: PAYMENT MILESTONE | E12: % | F12: VALUE | H12: PLANNED PAYMENT DATE | L12: INVOICE NUMBER | N12: INVOICE RAISED DATE | P12: PAYMENT RECEIVED DATE | R12: MILESTONE NOTES & COMMENTS
B13: 1 | C13: Acceptance and Initial Deposit | E13: 0.5 | F13: =$F$4*E13 -> 699690.3 | H13: 46053 | L13: 004942 | N13: 46066 | P13: 46080 | AO13: ='Change Register'!$Q$14+ 7 -> 7
B14: 2 | C14: Delivery of Panels | E14: 0.25 | F14: =$F$4*E14 -> 349845.15 | H14: ='Project Plan'!G38+7 -> 46084 | P14: ='Project Plan'!K38+7 -> 46084
B15: 3 | C15: Delivery of Inverters | E15: 0.1 | F15: =$F$4*E15 -> 139938.06 | H15: ='Project Plan'!G24+7 -> 46084 | P15: ='Project Plan'!K24+7 -> 46084
B16: 4 | C16: Practical Completion | E16: 0.1 | F16: =$F$4*E16 -> 139938.06 | H16: ='Project Plan'!G41+7 -> 46118 | P16: ='Project Plan'!K41+7 -> 46118
B17: 5 | C17: Handover | E17: 0.05 | F17: =$F$4*E17 -> 69969.03 | H17: ='Project Plan'!G52+7 -> 46128 | P17: ='Project Plan'!K52+7 -> 46121
B18: 6 | E18: 0 | H18: =H17 -> 46128 | P18: =P17 -> 46121
B19: 7 | C19: - | E19: 0 | F19: =$D$4*E19 -> 0
E21: =SUM(E13:E19) -> 1 | F21: =SUM(F13:F19) -> 1399380.6
B23: KEY: | C23: contains an error (in result or a check has failed)
C24: Red Font - IF TEXT : content not yet confirmed
C25: Red Font - IF NUMBER: Negative value
C26: Anything in yellow is a concern or risk for noting or action
C27: confirmed
C28: [ADD INITIALS: comment for noting in square brackets, use colour or red to draw attention if important]
C29: [RT: When adding rows into sheet, ensure you insert between first and last row of each category]
C30: end of sheet - do not insert information below/beyond this
B40: No. | C40: PAYMENT MILESTONE | E40: % | F40: VALUE
B41: 1 | C41: Deposit - Project commencement | E41: 0.35 | F41: =$F$47*E41 -> 489783.21
B42: 2 | C42: Delivery of Panels | E42: 0.3 | F42: =$F$47*E42 -> 419814.18
B43: 3 | C43: Delivery of Inverters | E43: 0.2 | F43: =$F$47*E43 -> 279876.12
B44: 4 | C44: Practical Completion | E44: 0.1 | F44: =$F$47*E44 -> 139938.06
B45: 5 | C45: Handover | E45: 0.05 | F45: =$F$47*E45 -> 69969.03
C46: Total | E46: =SUM(E41:E45) -> 1 | F46: =SUM(F41:F45) -> 1399380.6
E47: =SUM(E41:E45) -> 1 | F47: =F21 -> 1399380.6

Sheet Expenditure Tracking
B2: HIGH LEVEL PROJECT EXPENDITURE TRACKING
F4: COSTED | H4: ACTUAL | J4: Difference from Costed
B5: EXPENDITURE | F5: =SUM(F9:F23) -> 1194452.5 | H5: =SUM(H9:H23) -> 828370.34 | J5: =SUM(J9:J23) -> 366082.11
B7: No. | D7: Item | F7: Costed Expenditure | H7: Actual Expenditure | J7: Saving / Overrun | L7: Comments on variations from planned expenditure
B9: ='Expenditure Breakdown'!L6 -> 1 | D9: ='Expenditure Breakdown'!M6 -> 1. Panels | F9: ='Expenditure Breakdown'!I6 -> 370794.53 | H9: ='Expenditure Breakdown'!X6 -> 260780 | J9: =F9-H9 -> 110014.53
B10: ='Expenditure Breakdown'!L13 -> 2 | D10: ='Expenditure Breakdown'!M13 -> 2. Inverters | F10: ='Expenditure Breakdown'!I13 -> 95000 | H10: ='Expenditure Breakdown'!X13 -> 69000 | J10: =F10-H10 -> 26000
B11: ='Expenditure Breakdown'!L21 -> 3 | D11: ='Expenditure Breakdown'!M21 -> 3. Mounting Structures | F11: ='Expenditure Breakdown'!I21 -> 58482 | H11: ='Expenditure Breakdown'!X21 -> 15616.04 | J11: =F11-H11 -> 42865.96
B12: ='Expenditure Breakdown'!L33 -> 4 | D12: ='Expenditure Breakdown'!M33 -> 4. DC Equipment | F12: ='Expenditure Breakdown'!I33 -> 69414.8 | H12: ='Expenditure Breakdown'!X33 -> 96536.45 | J12: =F12-H12 -> -27121.65
B13: ='Expenditure Breakdown'!L49 -> 5 | D13: ='Expenditure Breakdown'!M49 -> 5. Monitoring | F13: ='Expenditure Breakdown'!I49 -> 49000 | H13: ='Expenditure Breakdown'!X49 -> 47441.44 | J13: =F13-H13 -> 1558.56
B14: ='Expenditure Breakdown'!L58 -> 6 | D14: ='Expenditure Breakdown'!M58 -> 6. AC Equipment | F14: ='Expenditure Breakdown'!I58 -> 198443.49 | H14: ='Expenditure Breakdown'!X58 -> 58297.93 | J14: =F14-H14 -> 140145.56 | L14: Check with Natasha reduction of price
B15: ='Expenditure Breakdown'!L76 -> 7 | D15: ='Expenditure Breakdown'!M76 -> 7.BESS | F15: ='Expenditure Breakdown'!I76 -> 0 | H15: ='Expenditure Breakdown'!X76 -> 0 | J15: =F15-H15 -> 0
B16: ='Expenditure Breakdown'!L85 -> 8 | D16: ='Expenditure Breakdown'!M85 -> 8. Product Add On | F16: ='Expenditure Breakdown'!I85 -> 4000 | H16: ='Expenditure Breakdown'!X85 -> 3600 | J16: =F16-H16 -> 400
B17: ='Expenditure Breakdown'!L95 -> 9 | D17: ='Expenditure Breakdown'!M95 -> 9. AC & DC installation | F17: ='Expenditure Breakdown'!I95 -> 108300 | H17: ='Expenditure Breakdown'!X95 -> 119228.19 | J17: =F17-H17 -> -10928.19
B18: ='Expenditure Breakdown'!L108 -> 10 | D18: ='Expenditure Breakdown'!M108 -> 10. Site Logistics | F18: ='Expenditure Breakdown'!I108 -> 59041.9 | H18: ='Expenditure Breakdown'!X108 -> 49844.432 | J18: =F18-H18 -> 9197.4675
B19: ='Expenditure Breakdown'!L124 -> 11 | D19: ='Expenditure Breakdown'!M124 -> 11. Due Dilligence | F19: ='Expenditure Breakdown'!I124 -> 89000 | H19: ='Expenditure Breakdown'!X124 -> 87910.48 | J19: =F19-H19 -> 1089.52
B20: ='Expenditure Breakdown'!L131 -> 12 | D20: ='Expenditure Breakdown'!M131 -> 12. BDP Commission | F20: ='Expenditure Breakdown'!I131 -> 0 | H20: ='Expenditure Breakdown'!X131 -> 0 | J20: =F20-H20 -> 0
B21: ='Expenditure Breakdown'!L134 -> 13 | D21: ='Expenditure Breakdown'!M135 -> 13. Engineering | F21: ='Expenditure Breakdown'!I134 -> 90875.739 | H21: ='Expenditure Breakdown'!X134 -> 18015.381 | J21: =F21-H21 -> 72860.358
B22: ='Expenditure Breakdown'!L141 -> 14 | D22: ='Expenditure Breakdown'!M141 -> 14. General Expenses | F22: ='Expenditure Breakdown'!I141 -> 2100 | H22: ='Expenditure Breakdown'!X141 -> 2100 | J22: =F22-H22 -> 0
B23: ='Expenditure Breakdown'!L154 -> 15 | D23: ='Expenditure Breakdown'!M154 -> 15. Service Add On | F23: ='Expenditure Breakdown'!I154 -> 0 | H23: ='Expenditure Breakdown'!X154 -> 0 | J23: =F23-H23 -> 0
D25: check: | F25: ='Expenditure Breakdown'!I2-'Expenditure Tracking'!F5 -> 0 | G25: =#REF!-G5 -> #REF! | H25: ='Expenditure Breakdown'!X2-H5 -> 0

Sheet Cashflow
D1: [RT: Double Check the first date is always a MONDAY] | F1: 45971 | G1: =F1+7 -> 45978 | H1: =G1+7 -> 45985 | I1: =H1+7 -> 45992 | J1: =I1+7 -> 45999 | K1: =J1+7 -> 46006 | L1: =K1+7 -> 46013 | M1: =L1+7 -> 46020 | N1: =M1+7 -> 46027 | ... KF1: =KE1+7 -> 47973
A2: PLANNED | C2: CHECK | D2: CHECK
B3: Planned Revenue | C3: ='Revenue Tracking'!D4 -> 1441230.5 | D3: =SUM(F3:KF3) -> 1399380.6 | F3: =SUMIFS('Revenue Tracking'!$F$13:$F$19, 'Revenue Tracking'!$H$13:$H$19, ">="&F1,'Revenue Tracking'!$H$13:$H$19, "<"&G1) -> 0 | G3: =SUMIFS('Revenue Tracking'!$F$13:$F$19, 'Revenue Tracking'!$H$13:$H$19, ">="&G1,'Revenue Tracking'!$H$13:$H$19, "<"&H1) -> 0 | H3: =SUMIFS('Revenue Tracking'!$F$13:$F$19, 'Revenue Tracking'!$H$13:$H$19, ">="&H1,'Revenue Tracking'!$H$13:$H$19, "<"&I1) -> 0 | I3: =SUMIFS('Revenue Tracking'!$F$13:$F$19, 'Revenue Tracking'!$H$13:$H$19, ">="&I1,'Revenue Tracking'!$H$13:$H$19, "<"&J1) -> 0 | J3: =SUMIFS('Revenue Tracking'!$F$13:$F$19, 'Revenue Tracking'!$H$13:$H$19, ">="&J1,'Revenue Tracking'!$H$13:$H$19, "<"&K1) -> 0 | K3: =SUMIFS('Revenue Tracking'!$F$13:$F$19, 'Revenue Tracking'!$H$13:$H$19, ">="&K1,'Revenue Tracking'!$H$13:$H$19, "<"&L1) -> 0 | L3: =SUMIFS('Revenue Tracking'!$F$13:$F$19, 'Revenue Tracking'!$H$13:$H$19, ">="&L1,'Revenue Tracking'!$H$13:$H$19, "<"&M1) -> 0 | M3: =SUMIFS('Revenue Tracking'!$F$13:$F$19, 'Revenue Tracking'!$H$13:$H$19, ">="&M1,'Revenue Tracking'!$H$13:$H$19, "<"&N1) -> 0 | ... KE3: =SUMIFS('Revenue Tracking'!$F$13:$F$19, 'Revenue Tracking'!$H$13:$H$19, ">="&KE1,'Revenue Tracking'!$H$13:$H$19, "<"&KF1) -> 0 | KF3: =SUMIFS('Revenue Tracking'!$F$13:$F$19, 'Revenue Tracking'!$H$13:$H$19, ">="&KF1,'Revenue Tracking'!$H$13:$H$19, "<"&#REF!) -> 0
B4: Planned Revenue - Cumulative | F4: =F3 -> 0 | G4: =F4+G3 -> 0 | H4: =G4+H3 -> 0 | I4: =H4+I3 -> 0 | J4: =I4+J3 -> 0 | K4: =J4+K3 -> 0 | L4: =K4+L3 -> 0 | M4: =L4+M3 -> 0 | N4: =M4+N3 -> 0 | ... KF4: =KE4+KF3 -> 1399380.6
B5: Planned Expenditure | C5: ='Revenue Tracking'!D5 -> 1194452.5 | D5: =SUM(F5:KF5) -> 1194452.5 | F5: =SUMIFS('Expenditure Breakdown'!$G$6:$G$173, 'Expenditure Breakdown'!$H$6:$H$173, ">="&F1,'Expenditure Breakdown'!$H$6:$H$173, "<"&G1) -> 0 | G5: =SUMIFS('Expenditure Breakdown'!$G$6:$G$173, 'Expenditure Breakdown'!$H$6:$H$173, ">="&G1,'Expenditure Breakdown'!$H$6:$H$173, "<"&H1) -> 0 | H5: =SUMIFS('Expenditure Breakdown'!$G$6:$G$173, 'Expenditure Breakdown'!$H$6:$H$173, ">="&H1,'Expenditure Breakdown'!$H$6:$H$173, "<"&I1) -> 0 | I5: =SUMIFS('Expenditure Breakdown'!$G$6:$G$173, 'Expenditure Breakdown'!$H$6:$H$173, ">="&I1,'Expenditure Breakdown'!$H$6:$H$173, "<"&J1) -> 0 | J5: =SUMIFS('Expenditure Breakdown'!$G$6:$G$173, 'Expenditure Breakdown'!$H$6:$H$173, ">="&J1,'Expenditure Breakdown'!$H$6:$H$173, "<"&K1) -> 0 | K5: =SUMIFS('Expenditure Breakdown'!$G$6:$G$173, 'Expenditure Breakdown'!$H$6:$H$173, ">="&K1,'Expenditure Breakdown'!$H$6:$H$173, "<"&L1) -> 0 | L5: =SUMIFS('Expenditure Breakdown'!$G$6:$G$173, 'Expenditure Breakdown'!$H$6:$H$173, ">="&L1,'Expenditure Breakdown'!$H$6:$H$173, "<"&M1) -> 0 | M5: =SUMIFS('Expenditure Breakdown'!$G$6:$G$173, 'Expenditure Breakdown'!$H$6:$H$173, ">="&M1,'Expenditure Breakdown'!$H$6:$H$173, "<"&N1) -> 0 | ... KE5: =SUMIFS('Expenditure Breakdown'!$G$6:$G$173, 'Expenditure Breakdown'!$H$6:$H$173, ">="&KE1,'Expenditure Breakdown'!$H$6:$H$173, "<"&KF1) -> 0 | KF5: =SUMIFS('Expenditure Breakdown'!$G$6:$G$173, 'Expenditure Breakdown'!$H$6:$H$173, ">="&KF1,'Expenditure Breakdown'!$H$6:$H$173, "<"&#REF!) -> 0
B6: Planned Expenditure - Cumulative | F6: =F5 -> 0 | G6: =F6+G5 -> 0 | H6: =G6+H5 -> 0 | I6: =H6+I5 -> 0 | J6: =I6+J5 -> 0 | K6: =J6+K5 -> 0 | L6: =K6+L5 -> 0 | M6: =L6+M5 -> 0 | N6: =M6+N5 -> 0 | ... KF6: =KE6+KF5 -> 1194452.5
B7: PLANNED CashFlow | F7: =F4-F6 -> 0 | G7: =G4-G6 -> 0 | H7: =H4-H6 -> 0 | I7: =I4-I6 -> 0 | J7: =J4-J6 -> 0 | K7: =K4-K6 -> 0 | L7: =L4-L6 -> 0 | M7: =M4-M6 -> 0 | ... KF7: =KF4-KF6 -> 204928.15
A8: ACTUAL | C8: CHECK | D8: CHECK
B9: Actual + Planned Revenue | C9: ='Revenue Tracking'!F4 -> 1399380.6 | D9: =SUM(F9:KF9) -> 1399380.6 | F9: =SUMIFS('Revenue Tracking'!$F$13:$F$19, 'Revenue Tracking'!$P$13:$P$19, ">="&F1,'Revenue Tracking'!$P$13:$P$19, "<"&G1) -> 0 | G9: =SUMIFS('Revenue Tracking'!$F$13:$F$19, 'Revenue Tracking'!$P$13:$P$19, ">="&G1,'Revenue Tracking'!$P$13:$P$19, "<"&H1) -> 0 | H9: =SUMIFS('Revenue Tracking'!$F$13:$F$19, 'Revenue Tracking'!$P$13:$P$19, ">="&H1,'Revenue Tracking'!$P$13:$P$19, "<"&I1) -> 0 | I9: =SUMIFS('Revenue Tracking'!$F$13:$F$19, 'Revenue Tracking'!$P$13:$P$19, ">="&I1,'Revenue Tracking'!$P$13:$P$19, "<"&J1) -> 0 | J9: =SUMIFS('Revenue Tracking'!$F$13:$F$19, 'Revenue Tracking'!$P$13:$P$19, ">="&J1,'Revenue Tracking'!$P$13:$P$19, "<"&K1) -> 0 | K9: =SUMIFS('Revenue Tracking'!$F$13:$F$19, 'Revenue Tracking'!$P$13:$P$19, ">="&K1,'Revenue Tracking'!$P$13:$P$19, "<"&L1) -> 0 | L9: =SUMIFS('Revenue Tracking'!$F$13:$F$19, 'Revenue Tracking'!$P$13:$P$19, ">="&L1,'Revenue Tracking'!$P$13:$P$19, "<"&M1) -> 0 | M9: =SUMIFS('Revenue Tracking'!$F$13:$F$19, 'Revenue Tracking'!$P$13:$P$19, ">="&M1,'Revenue Tracking'!$P$13:$P$19, "<"&N1) -> 0 | ... KE9: =SUMIFS('Revenue Tracking'!$F$13:$F$19, 'Revenue Tracking'!$P$13:$P$19, ">="&KE1,'Revenue Tracking'!$P$13:$P$19, "<"&KF1) -> 0 | KF9: =SUMIFS('Revenue Tracking'!$F$13:$F$19, 'Revenue Tracking'!$P$13:$P$19, ">="&KF1,'Revenue Tracking'!$P$13:$P$19, "<"&#REF!) -> 0
B10: Actual + Planned Revenue - Cumulative | F10: =F9 -> 0 | G10: =F10+G9 -> 0 | H10: =G10+H9 -> 0 | I10: =H10+I9 -> 0 | J10: =I10+J9 -> 0 | K10: =J10+K9 -> 0 | L10: =K10+L9 -> 0 | M10: =L10+M9 -> 0 | N10: =M10+N9 -> 0 | ... KF10: =KE10+KF9 -> 1399380.6
B11: Actual + Planned Expenditure | C11: ='Revenue Tracking'!F5 -> 828370.34 | D11: =SUM(F11:KF11) -> 799694.34 | F11: =SUMIFS('Expenditure Breakdown'!$Q$6:$Q$173, 'Expenditure Breakdown'!$W$6:$W$173, ">="&F1,'Expenditure Breakdown'!$W$6:$W$173, "<"&G1) -> 0 | G11: =SUMIFS('Expenditure Breakdown'!$Q$6:$Q$173, 'Expenditure Breakdown'!$W$6:$W$173, ">="&G1,'Expenditure Breakdown'!$W$6:$W$173, "<"&H1) -> 0 | H11: =SUMIFS('Expenditure Breakdown'!$Q$6:$Q$173, 'Expenditure Breakdown'!$W$6:$W$173, ">="&H1,'Expenditure Breakdown'!$W$6:$W$173, "<"&I1) -> 1742.08 | I11: =SUMIFS('Expenditure Breakdown'!$Q$6:$Q$173, 'Expenditure Breakdown'!$W$6:$W$173, ">="&I1,'Expenditure Breakdown'!$W$6:$W$173, "<"&J1) -> 0 | J11: =SUMIFS('Expenditure Breakdown'!$Q$6:$Q$173, 'Expenditure Breakdown'!$W$6:$W$173, ">="&J1,'Expenditure Breakdown'!$W$6:$W$173, "<"&K1) -> 0 | K11: =SUMIFS('Expenditure Breakdown'!$Q$6:$Q$173, 'Expenditure Breakdown'!$W$6:$W$173, ">="&K1,'Expenditure Breakdown'!$W$6:$W$173, "<"&L1) -> 0 | L11: =SUMIFS('Expenditure Breakdown'!$Q$6:$Q$173, 'Expenditure Breakdown'!$W$6:$W$173, ">="&L1,'Expenditure Breakdown'!$W$6:$W$173, "<"&M1) -> 9900 | M11: =SUMIFS('Expenditure Breakdown'!$Q$6:$Q$173, 'Expenditure Breakdown'!$W$6:$W$173, ">="&M1,'Expenditure Breakdown'!$W$6:$W$173, "<"&N1) -> 0 | ... KE11: =SUMIFS('Expenditure Breakdown'!$Q$6:$Q$173, 'Expenditure Breakdown'!$W$6:$W$173, ">="&KE1,'Expenditure Breakdown'!$W$6:$W$173, "<"&KF1) -> 0 | KF11: =SUMIFS('Expenditure Breakdown'!$Q$6:$Q$173, 'Expenditure Breakdown'!$W$6:$W$173, ">="&KF1,'Expenditure Breakdown'!$W$6:$W$173, "<"&#REF!) -> 0
B12: Actual + Planned Expenditure - Cumulative | F12: =F11 -> 0 | G12: =F12+G11 -> 0 | H12: =G12+H11 -> 1742.08 | I12: =H12+I11 -> 1742.08 | J12: =I12+J11 -> 1742.08 | K12: =J12+K11 -> 1742.08 | L12: =K12+L11 -> 11642.08 | M12: =L12+M11 -> 11642.08 | N12: =M12+N11 -> 14512.08 | ... KF12: =KE12+KF11 -> 799694.34
B14: ACTUAL CashFlow | F14: =F10-F12 -> 0 | G14: =G10-G12 -> 0 | H14: =H10-H12 -> -1742.08 | I14: =I10-I12 -> -1742.08 | J14: =J10-J12 -> -1742.08 | K14: =K10-K12 -> -1742.08 | L14: =L10-L12 -> -11642.08 | M14: =M10-M12 -> -11642.08 | ... KF14: =KF10-KF12 -> 599686.27
C16: CHECK | D16: CHECK
B17: Revenue Recognition | C17: =C3-D17 -> 41849.87 | D17: =SUM(F17:KF17) -> 1399380.6 | F17: =SUMIFS('Expenditure Breakdown'!$U$6:$U$173, 'Expenditure Breakdown'!$T$6:$T$173, ">="&F1,'Expenditure Breakdown'!$T$6:$T$173, "<"&G1) -> 0 | G17: =SUMIFS('Expenditure Breakdown'!$U$6:$U$173, 'Expenditure Breakdown'!$T$6:$T$173, ">="&G1,'Expenditure Breakdown'!$T$6:$T$173, "<"&H1) -> 0 | H17: =SUMIFS('Expenditure Breakdown'!$U$6:$U$173, 'Expenditure Breakdown'!$T$6:$T$173, ">="&H1,'Expenditure Breakdown'!$T$6:$T$173, "<"&I1) -> 0 | I17: =SUMIFS('Expenditure Breakdown'!$U$6:$U$173, 'Expenditure Breakdown'!$T$6:$T$173, ">="&I1,'Expenditure Breakdown'!$T$6:$T$173, "<"&J1) -> 0 | J17: =SUMIFS('Expenditure Breakdown'!$U$6:$U$173, 'Expenditure Breakdown'!$T$6:$T$173, ">="&J1,'Expenditure Breakdown'!$T$6:$T$173, "<"&K1) -> 0 | K17: =SUMIFS('Expenditure Breakdown'!$U$6:$U$173, 'Expenditure Breakdown'!$T$6:$T$173, ">="&K1,'Expenditure Breakdown'!$T$6:$T$173, "<"&L1) -> 0 | L17: =SUMIFS('Expenditure Breakdown'!$U$6:$U$173, 'Expenditure Breakdown'!$T$6:$T$173, ">="&L1,'Expenditure Breakdown'!$T$6:$T$173, "<"&M1) -> 0 | M17: =SUMIFS('Expenditure Breakdown'!$U$6:$U$173, 'Expenditure Breakdown'!$T$6:$T$173, ">="&M1,'Expenditure Breakdown'!$T$6:$T$173, "<"&N1) -> 0 | ... KE17: =SUMIFS('Expenditure Breakdown'!$U$6:$U$173, 'Expenditure Breakdown'!$T$6:$T$173, ">="&KE1,'Expenditure Breakdown'!$T$6:$T$173, "<"&KF1) -> 0 | KF17: =SUMIFS('Expenditure Breakdown'!$U$6:$U$173, 'Expenditure Breakdown'!$T$6:$T$173, ">="&KF1,'Expenditure Breakdown'!$T$6:$T$173, "<"&#REF!) -> 0
B18: Revenue Recognition Cumulative | C18: =D17-D18 -> 0 | D18: =MAX(F18:KF18) -> 1399380.6 | F18: =F17 -> 0 | G18: =F18+G17 -> 0 | H18: =G18+H17 -> 0 | I18: =H18+I17 -> 0 | J18: =I18+J17 -> 0 | K18: =J18+K17 -> 0 | L18: =K18+L17 -> 0 | M18: =L18+M17 -> 0 | N18: =M18+N17 -> 0 | ... KF18: =KE18+KF17 -> 1399380.6

Sheet Finance - Revenue
A3: Sum of REVENUE RECOGNITION AMOUNT | B3: Column Labels
A4: Row Labels | B4: (blank) | D4: 46053 | E4: 46081 | F4: 46112 | G4: 46142 | H4: 46173 | I4: Grand Total
A5: (blank)
A6: 1. Panels | C6: 0 | E6: 452188.45 | I6: 452188.45
A7: 2. Inverters | B7: 0 | C7: 0 | E7: 115853.66 | I7: 115853.66
A8: 3. Mounting Structures | C8: 0 | E8: 71319.512 | I8: 71319.512
A9: 4. DC Equipment | C9: 0 | E9: 39577.814 | F9: 27044.628 | G9: 18029.752 | I9: 84652.195
A10: 5. Monitoring | C10: 0 | D10: 10964.574 | E10: 37903.887 | G10: 10887.636 | I10: 59756.098
A11: 6. AC Equipment | C11: 0 | E11: 137527.9 | F11: 62685.812 | G11: 41790.542 | I11: 242004.25
A12: 8. Product Add On
A13: 9. AC & DC installation | C13: 0 | E13: 31852.941 | F13: 57335.294 | G13: 38223.529 | I13: 127411.76
A14: 10. Site Logistics | C14: 0 | E14: 17365.265 | F14: 31257.476 | G14: 20838.318 | I14: 69461.059
A15: 11. Due Dilligence | D15: 23026.569 | E15: 59552.56 | F15: 7146.3072 | G15: 14980.446 | I15: 104705.88
A16: 13. Engineering | C16: 0 | F16: 106912.63 | I16: 106912.63
A17: 14. General Expenses | C17: 0 | E17: 617.64706 | F17: 617.64706 | G17: 617.64706 | H17: 617.64706 | I17: 2470.5882
A18: 15. Service Add On
A19: 12. BDP Commission
A20: 7.BESS
A21: Grand Total | B21: 0 | C21: 0 | D21: 33991.143 | E21: 963759.64 | F21: 292999.8 | G21: 145367.87 | H21: 617.64706 | I21: 1436736.1

Sheet Finance - COS
A3: Sum of Actual Total | B3: Column Labels
A4: Row Labels | B4: (blank) | D4: 46053 | E4: 46081 | F4: 46112 | G4: 46142 | H4: 46173 | I4: Grand Total
A5: (blank)
A6: 1. Panels | E6: 260780 | I6: 260780
A7: 2. Inverters | E7: 69000 | I7: 69000
A8: 3. Mounting Structures | E8: 29315.1 | I8: 29315.1
A9: 4. DC Equipment | E9: 45134.113 | F9: 30841.403 | G9: 20560.935 | I9: 96536.45
A10: 5. Monitoring | D10: 8659.1 | E10: 29934 | G10: 8598.34 | I10: 47191.44
A11: 6. AC Equipment | E11: 33129.963 | F11: 15100.781 | G11: 10067.187 | I11: 58297.93
A12: 8. Product Add On
A13: 9. AC & DC installation | E13: 29807.048 | F13: 53652.686 | G13: 35768.457 | I13: 119228.19
A14: 10. Site Logistics | E14: 12461.108 | F14: 22429.994 | G14: 14953.329 | I14: 49844.43
A15: 11. Due Dilligence | D15: 19332.98 | E15: 50000 | F15: 6000 | G15: 12577.5 | I15: 87910.48
A16: 13. Engineering | F16: 95172.661 | I16: 95172.661
A17: 14. General Expenses | E17: 525 | F17: 525 | G17: 525 | H17: 525 | I17: 2100
A18: 15. Service Add On
A19: 12. BDP Commission | C19: 0 | I19: 0
A20: 7.BESS
A21: Grand Total | C21: 0 | D21: 27992.08 | E21: 560086.33 | F21: 223722.52 | G21: 103050.75 | H21: 525 | I21: 915376.68

Sheet Data
C2: Public holidays | F2: Drop down list
C3: 45658 | D3: New Years Day | F3: Approved
C4: 45737 | D4: Human Rights day | F4: Pending
C5: 45765 | D5: Good Friday | F5: Declined
C6: 45768 | D6: Family Day | F6: Abanded
C7: 45774 | D7: Freedom Day
C8: 45765 | D8: Freedom DayObserved
C9: 45778 | D9: Workers day
C10: 45824 | D10: Youth Day Holiday
C11: 45878 | D11: Womens Day
C12: 45924 | D12: Heritage Day
C13: 46007 | D13: Day of Reconciliation | H13: Manual dates
C14: 46016 | D14: Christmas Day
C15: 46017 | D15: Day of Goodwill
C16: 46006 | D16: Builders Break
C17: 46007 | D17: Builders Break
C18: 46008 | D18: Builders Break
C19: 46009 | D19: Builders Break
C20: 46010 | D20: Builders Break
C21: 46011 | D21: Builders Break
C22: 46012 | D22: Builders Break
C23: 46013 | D23: Builders Break
C24: 46014 | D24: Builders Break
C25: 46015 | D25: Builders Break
... C60: 46382 | D60: Day of Goodwill
