Workbook
Name Inverter_Capacity: #REF!
Name Inverter_Supplier: #REF!
Name Project_Size: 'Finance - Revenue'!Projectsize
Name Project_Size: Projectsize
Name Projectsize: #REF!
Name Projectsize: #REF!
Name Security_Serv: #REF!
Name Security_Serv: #REF!
Name SSS: #REF!
Name SSS: #REF!
Name USD_ZAR: #REF!

Sheet Certificate - Financial Close
B2: Emergent Energy – Financial Close Completion Certificate | H2: FINANCIAL CLOSE CERTIFICATE
B4: Project Name: | C4: ='Project Plan'!E2 -> Westway BESS
B5: COO: | C5: Johannes Potgieter
B6: Programme Manager: | C6: Roedolph Venter
B7: HoPD: | C7: Natasha Watkins-Baker
B9: Date of Phase Completion:
B10: Phase Deliverables Checklist: (Y/N)
B11: Product Agreement
B12: EPC Agreement
B13: O&M Agreeement
B14: Cost Proposal
B15: Deposit Received
B16: Risks / Notes
B18: Acknowledgement and Acceptance:
B19: Role | C19: Name | D19: Signature | E19: Date

Sheet Certificate - Planning
B2: Emergent Energy – Planning Phase Completion Certificate | H2: PLANNING CERTIFICATE
B4: Project Name: | C4: ='Project Plan'!E2 -> Westway BESS
B5: Client Representative:
B6: Programme Manager: | C6: Roedolph Venter
B7: Project Manager: | C7: ='Project Plan'!E5 -> Lloyd Brown
B8: Project Engineer:
B10: Date of Phase Completion:
B11: Phase Deliverables Checklist: (Y/N)
B12: Project Introduction Presentation
B13: Project Brief
B14: Engineering Pack
B15: BOQ
B16: PO – Material & Equipment
B17: PO - Contractors
B18: HSE – NOC
B19: HSE – EE File
B20: HSE – Contractor File
... B24: Acknowledgement and Acceptance:
B25: Role | C25: Name | D25: Signature | E25: Date

Sheet Change Register
F1: Change Register
B3: ID | C3: Description | D3: Supporting Image (If Applicable) | E3: Impact | F3: Proposed Date | G3: Proposed By | H3: Status | I3: Approved By | J3: Approved Date | K3: Results / Comments
B4: DEC001
B5: DEC002
B6: DEC003
B7: DEC004
B8: DEC005
B9: DEC006
B10: DEC007
B11: DEC008
B12: DEC009
B13: DEC010
B14: DEC011
B15: DEC012
... B33: DEC030

Sheet BOQ
B2: Item | C2: Supplier | D2: Description | E2: Quantity | F2: Comments
B3: PV Module
B4: DC Cable Red & Black
B5: Inverters
B6: Mounting Structure
B7: Current Transformers (Production)
B8: Current Transformers (Consumption)
B9: Solar Production Meter (Techistter)
B10: Grid Consumption Meter
B11: Wi-Fi Router & Sim
B12: Switch
B13: Back Up Battery
B14: PVDB
... B30: Techsitter

Sheet Compliance
B2: HSE
B4: Description | C4: Status | D4: Approved By | E4: Date | F4: Results / Comments
B5: NOC | F5: In progress
B6: 7.1 Agreement | F6: In progress
B7: 13.2 Agreement | F7: In progress
B8: EE File | F8: In progress
B9: Subbie File | F9: Not appointed yet
B16: SSEG
B18: Description | C18: Status | D18: Approved By | E18: Date | F18: Results / Comments
B19: SSEG Application
B20: PTI
B21: Commissioning Approval

Sheet Revenue Tracking
B2: HIGH LEVEL PROJECT REVENUE TRACKING | U2: 2026 Budget Revenue | V2: 2026 Budget COS | W2: 2026 Actual Revenue | X2: 2026 Actual COS
D3: COSTED | F3: ACTUAL | L3: FINANCIAL REVIEW | N3: TIMELINE REVIEW | U3: =SUMIFS('Expenditure Breakdown'!$U:$U, 'Expenditure Breakdown'!$T:$T, ">"&DATE(2025,8,31), 'Expenditure Breakdown'!$T:$T, "<="&DATE(2026,8,31)) -> 823858.26 | V3: =SUMIFS('Expenditure Breakdown'!$Q:$Q, 'Expenditure Breakdown'!$T:$T, ">"&DATE(2025,8,31), 'Expenditure Breakdown'!$T:$T, "<="&DATE(2026,8,31)) -> 585065.51 | W3: =SUMIFS('Expenditure Breakdown'!$U:$U, 'Expenditure Breakdown'!$T:$T, ">"&DATE(2025,8,31), 'Expenditure Breakdown'!$T:$T, "<="&DATE(2026,8,31), 'Expenditure Breakdown'!$S:$S, "<>") -> 0 | X3: =SUMIFS('Expenditure Breakdown'!$Q:$Q, 'Expenditure Breakdown'!$T:$T, ">"&DATE(2025,8,31), 'Expenditure Breakdown'!$T:$T, "<="&DATE(2026,8,31), 'Expenditure Breakdown'!$S:$S, "<>") -> 0
B4: 1 | C4: Planned Revenue | D4: ='Project Plan'!E6 -> 823858.49 | F4: =F21 -> 823858.49 | N4: Start Date
B5: 2 | C5: Planned Expenditure | D5: =+'Expenditure Tracking'!F5 -> 725014.91 | F5: =+'Expenditure Tracking'!H5 -> 585065.51 | H5: VO vs Costed Margin
B6: 3 | C6: Planned Profit | D6: =+D4-D5 -> 98843.574 | F6: =+F4-F5 -> 238792.98 | H6: =D6*0.05 -> 4942.1787 | N6: End Date - PC
B7: 4 | C7: Planned Margin | D7: =+D6/D4 -> 0.1199764 | F7: =+F6/F4 -> 0.28984708 | H7: =SUMIF('Expenditure Breakdown'!N:N,"*VO*",'Expenditure Breakdown'!Q:Q) -> 0
B10: CONTRACT
B12: No. | C12: PAYMENT MILESTONE | E12: % | F12: VALUE | H12: PLANNED PAYMENT DATE | L12: INVOICE NUMBER | N12: INVOICE RAISED DATE | P12: PAYMENT RECEIVED DATE | R12: MILESTONE REQUIREMENTS & COMMENTS | S12: MILESTONE DOCUMENTS RECEIVED
B13: 1 | C13: Acceptance and Initial Deposit | E13: 0.2 | F13: =$D$4*E13 -> 164771.7 | H13: 46015 | L13: 004900 | N13: 46003 | P13: 46020 | S13: FALSE | AP13: ='Change Register'!$Q$14+ 7 -> 7
B14: 2 | C14: Delivery of batteries | E14: 0 | F14: =$D$4*E14 -> 0 | S14: FALSE
B15: 3 | C15: Delivery of Inverter | E15: 0 | F15: =$D$4*E15 -> 0 | S15: FALSE
B16: 4 | C16: Practical Completion | E16: 0 | F16: =$D$4*E16 -> 0 | S16: FALSE
B17: 5 | C17: Handover | E17: 0.8 | F17: =$D$4*E17 -> 659086.79 | H17: 46088 | L17: 004948 | N17: 46079 | P17: 46088 | S17: FALSE
B18: 6 | C18: - | E18: 0 | F18: =$D$4*E18 -> 0 | S18: FALSE
B19: 7 | C19: - | E19: 0 | F19: =$D$4*E19 -> 0 | S19: FALSE
E21: =SUM(E13:E19) -> 1 | F21: =SUM(F13:F19) -> 823858.49
B23: KEY: | C23: contains an error (in result or a check has failed)
C24: Red Font - IF TEXT : content not yet confirmed
C25: Red Font - IF NUMBER: Negative value
C26: Anything in yellow is a concern or risk for noting or action
C27: confirmed
C28: [ADD INITIALS: comment for noting in square brackets, use colour or red to draw attention if important]
C29: [RT: When adding rows into sheet, ensure you insert between first and last row of each category]
C30: end of sheet - do not insert information below/beyond this
B40: No. | C40: PAYMENT MILESTONE | E40: % | F40: VALUE
B41: 1 | C41: Deposit - Project commencement | E41: 0.35 | F41: =$F$47*E41 -> 288350.47
B42: 2 | C42: Delivery of Panels | E42: 0.3 | F42: =$F$47*E42 -> 247157.55
B43: 3 | C43: Delivery of Inverters | E43: 0.2 | F43: =$F$47*E43 -> 164771.7
B44: 4 | C44: Practical Completion | E44: 0.1 | F44: =$F$47*E44 -> 82385.849
B45: 5 | C45: Handover | E45: 0.05 | F45: =$F$47*E45 -> 41192.924
C46: Total | E46: =SUM(E41:E45) -> 1 | F46: =SUM(F41:F45) -> 823858.49
E47: =SUM(E41:E45) -> 1 | F47: =F21 -> 823858.49

Sheet Project Plan
N1: =TODAY() -> 46077 | O1: =TODAY() -> 46077
C2: PROJECT PLAN | E2: Westway BESS | I2: Net Work Days | K2: =NETWORKDAYS(I19,K40,Data!C3:C60) -> 15 | N2: 0 | O2: 1
C3: PROJECT SIZE (kWh) | E3: 100 | I3: Total Weeks | K3: =K2/5 -> 3
C4: PROJECT DEVELOPER | E4: Gordon Upton | I4: kW/Week Installation Rate | K4: =E3/K3 -> 33.333333
C5: PROJECT MANAGERS | E5: Lloyd Brown
C6: CONTRACT VALUE | E6: 823858.49
C7: Phase: | E7: Planning
B8: No. | C8: HIGH LEVEL PROGRAMME | E8: Planned Start | F8: Duration | G8: Planned End | I8: Actual Start | J8: Duration | K8: Actual End | M8: Status | N8: Expected Status | O8: Comment
F9: =G40-E20 -> 18 | J9: =K40-I20 -> 18 | M9: =AVERAGE(M11,M19,M22,M29,M40,M49,M45) -> 0.071428571 | N9: =AVERAGE(N11,N19,N22,N29,N40,N49,N45) -> 0.37142818 | S9: =TODAY() -> 46077 | T9: =TODAY() -> 46077
S10: 1 | T10: 0
B11: 1 | C11: Project Initiation | E11: =MIN(E12:E18) -> 46038 | F11: =G11-E11 -> 20 | G11: =MAX(G12:G18) -> 46058 | I11: =MIN(I12:I18) -> 46038 | J11: =K11-I11 -> 34 | K11: =MAX(K12:K18) -> 46072 | M11: =(J12*M12+J13*M13+J14*M14+J15*M15+J17*M17)/SUM(J12:J17) -> 0.5 | N11: =(J12*M12+J13*M13+J14*M14+J15*M15+J17*M17)/SUM(J12:J17) -> 0.5
B12: 1.1 | C12: Project Charter Handover | E12: 46038 | F12: 1 | G12: =WORKDAY.INTL(E12,F12,1,Data!$C$3:$C$60) -> 46041 | I12: 46038 | J12: 1 | K12: =WORKDAY.INTL(I12,J12,1,Data!$C$3:$C$60) -> 46041 | M12: 1 | N12: =_xlfn.LET( _xlpm.s,VALUE($I12), _xlpm.e,VALUE($K12), IF(OR(_xlpm.s="",_xlpm.e=""),"", IF(_xlpm.e<=_xlpm.s, IF(TODAY()>=_xlpm.e,1,0), MAX(0,MIN(1,(TODAY()-_xlpm.s)/(_xlpm.e-_xlpm.s))))) ) -> 1 | S12: Milestone | T12: Start Date | U12: Duration | V12: End Date
B13: 1.2 | C13: HSE Readiness and Signoff | E13: =G12 -> 46041 | F13: 10 | G13: =WORKDAY.INTL(E13,F13,1,Data!$C$3:$C$60) -> 46055 | I13: 46062 | J13: 5 | K13: =WORKDAY.INTL(I13,J13,1,Data!$C$3:$C$60) -> 46069 | M13: 0 | N13: =_xlfn.LET( _xlpm.s,VALUE($I13), _xlpm.e,VALUE($K13), IF(OR(_xlpm.s="",_xlpm.e=""),"", IF(_xlpm.e<=_xlpm.s, IF(TODAY()>=_xlpm.e,1,0), MAX(0,MIN(1,(TODAY()-_xlpm.s)/(_xlpm.e-_xlpm.s))))) ) -> 1 | S13: =C11 -> Project Initiation | T13: =I11 -> 46038 | U13: =J11 -> 34 | V13: =K11 -> 46072
B14: 1.3 | C14: Project Introduction | E14: =WORKDAY.INTL(G13,0,1,Data!$C$3:$C$60) -> 46055 | F14: 1 | G14: =WORKDAY.INTL(E14,F14,1,Data!$C$3:$C$60) -> 46056 | I14: =WORKDAY.INTL(K13,0,1,Data!$C$3:$C$60) -> 46069 | J14: 1 | K14: =WORKDAY.INTL(I14,J14,1,Data!$C$3:$C$60) -> 46070 | M14: 0 | N14: =_xlfn.LET( _xlpm.s,VALUE($I14), _xlpm.e,VALUE($K14), IF(OR(_xlpm.s="",_xlpm.e=""),"", IF(_xlpm.e<=_xlpm.s, IF(TODAY()>=_xlpm.e,1,0), MAX(0,MIN(1,(TODAY()-_xlpm.s)/(_xlpm.e-_xlpm.s))))) ) -> 1 | S14: =C19 -> Site Establishment | T14: =I19 -> 46076 | U14: =J19 -> 1 | V14: =K19 -> 46077
B15: 1.4 | C15: Technical Meeting | E15: 46040 | F15: 10 | G15: =WORKDAY.INTL(E15,F15,1,Data!$C$3:$C$60) -> 46052 | I15: 46040 | J15: 10 | K15: =WORKDAY.INTL(I15,J15,1,Data!$C$3:$C$60) -> 46052 | M15: 1 | N15: =_xlfn.LET( _xlpm.s,VALUE($I15), _xlpm.e,VALUE($K15), IF(OR(_xlpm.s="",_xlpm.e=""),"", IF(_xlpm.e<=_xlpm.s, IF(TODAY()>=_xlpm.e,1,0), MAX(0,MIN(1,(TODAY()-_xlpm.s)/(_xlpm.e-_xlpm.s))))) ) -> 1 | S15: =C22 -> AC Installation | T15: =I22 -> 46076 | U15: =J22 -> 2 | V15: =K22 -> 46078
C16: Post Tests Review | I16: 46058 | J16: 2 | K16: =WORKDAY.INTL(I16,J16,1,Data!$C$3:$C$60) -> 46062
B17: 1.5 | C17: Project Review | E17: =WORKDAY.INTL(G13,0,1,Data!$C$3:$C$60) -> 46055 | F17: 3 | G17: =WORKDAY.INTL(E17,F17,1,Data!$C$3:$C$60) -> 46058 | I17: =WORKDAY.INTL(K13,0,1,Data!$C$3:$C$60) -> 46069 | J17: 3 | K17: =WORKDAY.INTL(I17,J17,1,Data!$C$3:$C$60) -> 46072 | M17: 0 | N17: =_xlfn.LET( _xlpm.s,VALUE($I17), _xlpm.e,VALUE($K17), IF(OR(_xlpm.s="",_xlpm.e=""),"", IF(_xlpm.e<=_xlpm.s, IF(TODAY()>=_xlpm.e,1,0), MAX(0,MIN(1,(TODAY()-_xlpm.s)/(_xlpm.e-_xlpm.s))))) ) -> 1 | S17: =C29 -> BESS Works | T17: =I29 -> 46074 | U17: =J29 -> 4 | V17: =K29 -> 46078
S18: =C36 -> 0 | T18: =I36 -> 0 | U18: =J36 -> 0 | V18: =K36 -> 0
B19: 2 | C19: Site Establishment | E19: =MIN(E20:E21) -> 46076 | F19: =G19-E19 -> 1 | G19: =MAX(G20:G21) -> 46077 | I19: =MIN(I20:I21) -> 46076 | J19: =K19-I19 -> 1 | K19: =MAX(K20:K21) -> 46077 | M19: =(J20*M20)/J19 -> 0 | N19: =(K20*N20)/K19 -> 1 | S19: =C40 -> Commissioning | T19: =I40 -> 46078 | U19: =J40 -> 16 | V19: =K40 -> 46094
B20: 2.1 | C20: Solar Contractor Establishment | E20: 46076 | F20: 1 | G20: =E20+F20 -> 46077 | I20: 46076 | J20: 1 | K20: =I20+J20 -> 46077 | M20: 0 | N20: =_xlfn.LET( _xlpm.s,VALUE($I20), _xlpm.e,VALUE($K20), IF(OR(_xlpm.s="",_xlpm.e=""),"", IF(_xlpm.e<=_xlpm.s, IF(TODAY()>=_xlpm.e,1,0), MAX(0,MIN(1,(TODAY()-_xlpm.s)/(_xlpm.e-_xlpm.s))))) ) -> 1 | S20: =C45 -> QA Inspections | T20: =I45 -> 46094 | U20: =J45 -> 5 | V20: =K45 -> 46099
S21: =C49 -> Project Closure | T21: =I49 -> 46097 | U21: =J49 -> 10 | V21: =K49 -> 46107
B22: 3 | C22: AC Installation | E22: =MIN(E23:E28) -> 46076 | F22: =G22-E22 -> 2 | G22: =MAX(G23:G28) -> 46078 | I22: =MIN(I23:I28) -> 46076 | J22: =K22-I22 -> 2 | K22: =MAX(K23:K28) -> 46078 | M22: =(J23*M23+J24*M24+J25*M25+J26*M26+J27*M27)/SUM(J23:J27) -> 0 | N22: =(J23*N23+J24*N24+J25*N25+J26*N26+J27*N27)/SUM(J23:J27) -> 0.6
B23: 3.1 | C23: Inverters delivered | E23: =WORKDAY.INTL(E20,0,1,Data!$C$3:$C$60) -> 46076 | F23: 1 | G23: =WORKDAY.INTL(E23,F23,1,Data!$C$3:$C$60) -> 46077 | I23: =WORKDAY.INTL(I20,0,1,Data!$C$3:$C$60) -> 46076 | J23: 1 | K23: =WORKDAY.INTL(I23,J23,1,Data!$C$3:$C$60) -> 46077 | M23: 0 | N23: =_xlfn.LET( _xlpm.s,VALUE($I23), _xlpm.e,VALUE($K23), IF(OR(_xlpm.s="",_xlpm.e=""),"", IF(_xlpm.e<=_xlpm.s, IF(TODAY()>=_xlpm.e,1,0), MAX(0,MIN(1,(TODAY()-_xlpm.s)/(_xlpm.e-_xlpm.s))))) ) -> 1
B24: 3.2 | C24: Inverters Mounted | E24: =WORKDAY.INTL(G23,0,1,Data!$C$3:$C$60) -> 46077 | F24: 1 | G24: =WORKDAY.INTL(E24,F24,1,Data!$C$3:$C$60) -> 46078 | I24: =WORKDAY.INTL(K23,0,1,Data!$C$3:$C$60) -> 46077 | J24: 1 | K24: =WORKDAY.INTL(I24,J24,1,Data!$C$3:$C$60) -> 46078 | M24: 0 | N24: =_xlfn.LET( _xlpm.s,VALUE($I24), _xlpm.e,VALUE($K24), IF(OR(_xlpm.s="",_xlpm.e=""),"", IF(_xlpm.e<=_xlpm.s, IF(TODAY()>=_xlpm.e,1,0), MAX(0,MIN(1,(TODAY()-_xlpm.s)/(_xlpm.e-_xlpm.s))))) ) -> 0
B25: 3.3 | C25: DB Lead Time - N/A
B26: 3.4 | C26: AC Works | E26: =WORKDAY.INTL(E23,0,1,Data!$C$3:$C$60) -> 46076 | F26: 2 | G26: =WORKDAY.INTL(E26,F26,1,Data!$C$3:$C$60) -> 46078 | I26: =WORKDAY.INTL(I23,0,1,Data!$C$3:$C$60) -> 46076 | J26: 2 | K26: =WORKDAY.INTL(I26,J26,1,Data!$C$3:$C$60) -> 46078 | M26: 0 | N26: =_xlfn.LET( _xlpm.s,VALUE($I26), _xlpm.e,VALUE($K26), IF(OR(_xlpm.s="",_xlpm.e=""),"", IF(_xlpm.e<=_xlpm.s, IF(TODAY()>=_xlpm.e,1,0), MAX(0,MIN(1,(TODAY()-_xlpm.s)/(_xlpm.e-_xlpm.s))))) ) -> 0.5
B27: 3.5 | C27: AC Tie-In | E27: =WORKDAY.INTL(E26,0,1,Data!$C$3:$C$60) -> 46076 | F27: 1 | G27: =WORKDAY.INTL(E27,F27,1,Data!$C$3:$C$60) -> 46077 | I27: =WORKDAY.INTL(I26,0,1,Data!$C$3:$C$60) -> 46076 | J27: 1 | K27: =WORKDAY.INTL(I27,J27,1,Data!$C$3:$C$60) -> 46077 | M27: 0 | N27: =_xlfn.LET( _xlpm.s,VALUE($I27), _xlpm.e,VALUE($K27), IF(OR(_xlpm.s="",_xlpm.e=""),"", IF(_xlpm.e<=_xlpm.s, IF(TODAY()>=_xlpm.e,1,0), MAX(0,MIN(1,(TODAY()-_xlpm.s)/(_xlpm.e-_xlpm.s))))) ) -> 1
B29: 4 | C29: BESS Works | E29: =MIN(E31:E35) -> 46074 | F29: =G29-E29 -> 4 | G29: =MAX(G31:G35) -> 46078 | I29: =MIN(I31:I35) -> 46074 | J29: =K29-I29 -> 4 | K29: =MAX(K31:K35) -> 46078 | M29: =(J31*M31+J32*M32+J34*M34)/SUM(J31:J34) -> 0 | N29: =(K31*N31+K32*N32+K34*N34)/SUM(K31:K34) -> 0.49999729
B31: 4.1 | C31: Batteries delivered | E31: =E20 -> 46076 | F31: 1 | G31: =WORKDAY.INTL(E31,F31,1,Data!$C$3:$C$60) -> 46077 | I31: =I20 -> 46076 | J31: 1 | K31: =WORKDAY.INTL(I31,J31,1,Data!$C$3:$C$60) -> 46077 | M31: 0 | N31: =_xlfn.LET( _xlpm.s,VALUE($I31), _xlpm.e,VALUE($K31), IF(OR(_xlpm.s="",_xlpm.e=""),"", IF(_xlpm.e<=_xlpm.s, IF(TODAY()>=_xlpm.e,1,0), MAX(0,MIN(1,(TODAY()-_xlpm.s)/(_xlpm.e-_xlpm.s))))) ) -> 1
B32: 4.2 | C32: Batteries Installation | E32: =WORKDAY.INTL(G31,0,1,Data!$C$3:$C$60) -> 46077 | F32: 1 | G32: =WORKDAY.INTL(E32,F32,1,Data!$C$3:$C$60) -> 46078 | I32: =WORKDAY.INTL(K31,0,1,Data!$C$3:$C$60) -> 46077 | J32: 1 | K32: =WORKDAY.INTL(I32,J32,1,Data!$C$3:$C$60) -> 46078 | M32: 0 | N32: =_xlfn.LET( _xlpm.s,VALUE($I32), _xlpm.e,VALUE($K32), IF(OR(_xlpm.s="",_xlpm.e=""),"", IF(_xlpm.e<=_xlpm.s, IF(TODAY()>=_xlpm.e,1,0), MAX(0,MIN(1,(TODAY()-_xlpm.s)/(_xlpm.e-_xlpm.s))))) ) -> 0
B33: 4.3 | C33: DC Cable Material delivered | E33: =E31 -> 46076 | F33: 1 | G33: =WORKDAY.INTL(E33,F33,1,Data!$C$3:$C$60) -> 46077 | I33: =I20 -> 46076 | J33: 1 | K33: =WORKDAY.INTL(I33,J33,1,Data!$C$3:$C$60) -> 46077 | M33: 0 | N33: =_xlfn.LET( _xlpm.s,VALUE($I33), _xlpm.e,VALUE($K33), IF(OR(_xlpm.s="",_xlpm.e=""),"", IF(_xlpm.e<=_xlpm.s, IF(TODAY()>=_xlpm.e,1,0), MAX(0,MIN(1,(TODAY()-_xlpm.s)/(_xlpm.e-_xlpm.s))))) ) -> 1
B34: 4.4 | C34: DC Cable Installation | E34: =WORKDAY.INTL(G33,0,1,Data!$C$3:$C$60)-3 -> 46074 | F34: 2 | G34: =WORKDAY.INTL(E34,F34,1,Data!$C$3:$C$60) -> 46077 | I34: =WORKDAY.INTL(K33,0,1,Data!$C$3:$C$60)-3 -> 46074 | J34: 2 | K34: =WORKDAY.INTL(I34,J34,1,Data!$C$3:$C$60) -> 46077 | M34: 0 | N34: =_xlfn.LET( _xlpm.s,VALUE($I34), _xlpm.e,VALUE($K34), IF(OR(_xlpm.s="",_xlpm.e=""),"", IF(_xlpm.e<=_xlpm.s, IF(TODAY()>=_xlpm.e,1,0), MAX(0,MIN(1,(TODAY()-_xlpm.s)/(_xlpm.e-_xlpm.s))))) ) -> 1
B40: 6 | C40: Commissioning | E40: =MIN(E41:E44) -> 46078 | F40: =G40-E40 -> 16 | G40: =MAX(G41:G44) -> 46094 | I40: =MIN(I41:I44) -> 46078 | J40: =K40-I40 -> 16 | K40: =MAX(K41:K44) -> 46094 | M40: =(J41*M41+J42*M42+J43*M43)/SUM(J41:J43) -> 0 | N40: =(K41*N41+K42*N42)/SUM(K41:K42) -> 0
B41: 6.1 | C41: Commissioning | E41: =WORKDAY.INTL(MAX(G22,G29),0,1,Data!$C$3:$C$60) -> 46078 | F41: 1 | G41: =WORKDAY.INTL(E41,F41,1,Data!$C$3:$C$60) -> 46079 | I41: =WORKDAY.INTL(MAX(K22,K29),0,1,Data!$C$3:$C$60) -> 46078 | J41: 1 | K41: =WORKDAY.INTL(I41,J41,1,Data!$C$3:$C$60) -> 46079 | M41: 0 | N41: =_xlfn.LET( _xlpm.s,VALUE($I41), _xlpm.e,VALUE($K41), IF(OR(_xlpm.s="",_xlpm.e=""),"", IF(_xlpm.e<=_xlpm.s, IF(TODAY()>=_xlpm.e,1,0), MAX(0,MIN(1,(TODAY()-_xlpm.s)/(_xlpm.e-_xlpm.s))))) ) -> 0
B42: 6.2 | C42: Practical Completion | E42: =WORKDAY.INTL(G41,0,1,Data!$C$3:$C$60) -> 46079 | F42: 1 | G42: =WORKDAY.INTL(E42,F42,1,Data!$C$3:$C$60) -> 46080 | I42: =WORKDAY.INTL(K41,0,1,Data!$C$3:$C$60) -> 46079 | J42: 1 | K42: =WORKDAY.INTL(I42,J42,1,Data!$C$3:$C$60) -> 46080 | M42: 0 | N42: =_xlfn.LET( _xlpm.s,VALUE($I42), _xlpm.e,VALUE($K42), IF(OR(_xlpm.s="",_xlpm.e=""),"", IF(_xlpm.e<=_xlpm.s, IF(TODAY()>=_xlpm.e,1,0), MAX(0,MIN(1,(TODAY()-_xlpm.s)/(_xlpm.e-_xlpm.s))))) ) -> 0
B43: 6.3 | C43: System Performance Monitoring | E43: =WORKDAY.INTL(G42,0,1,Data!$C$3:$C$60) -> 46080 | F43: 10 | G43: =WORKDAY.INTL(E43,F43,1,Data!$C$3:$C$60) -> 46094 | I43: =WORKDAY.INTL(K42,0,1,Data!$C$3:$C$60) -> 46080 | J43: 10 | K43: =WORKDAY.INTL(I43,J43,1,Data!$C$3:$C$60) -> 46094 | M43: 0 | N43: =_xlfn.LET( _xlpm.s,VALUE($I43), _xlpm.e,VALUE($K43), IF(OR(_xlpm.s="",_xlpm.e=""),"", IF(_xlpm.e<=_xlpm.s, IF(TODAY()>=_xlpm.e,1,0), MAX(0,MIN(1,(TODAY()-_xlpm.s)/(_xlpm.e-_xlpm.s))))) ) -> 0
B45: 7 | C45: QA Inspections | E45: =MIN(E46:E48) -> 46094 | F45: =G45-E45 -> 5 | G45: =MAX(G46:G48) -> 46099 | I45: =MIN(I46:I48) -> 46094 | J45: =K45-I45 -> 5 | K45: =MAX(K46:K48) -> 46099 | M45: =(J46*M46+J47*M47)/SUM(J46:J47) -> 0 | N45: =(K46*N46)/SUM(K46) -> 0
B46: 7.1 | C46: Red-Team Inspection | E46: =WORKDAY.INTL(G43,0,1,Data!$C$3:$C$60) -> 46094 | F46: 1 | G46: =WORKDAY.INTL(E46,F46,1,Data!$C$3:$C$60) -> 46097 | I46: =WORKDAY.INTL(K43,0,1,Data!$C$3:$C$60) -> 46094 | J46: 1 | K46: =WORKDAY.INTL(I46,J46,1,Data!$C$3:$C$60) -> 46097 | M46: 0 | N46: =_xlfn.LET( _xlpm.s,VALUE($I46), _xlpm.e,VALUE($K46), IF(OR(_xlpm.s="",_xlpm.e=""),"", IF(_xlpm.e<=_xlpm.s, IF(TODAY()>=_xlpm.e,1,0), MAX(0,MIN(1,(TODAY()-_xlpm.s)/(_xlpm.e-_xlpm.s))))) ) -> 0
B47: 7.2 | C47: Snags completion | E47: =G46 -> 46097 | F47: 2 | G47: =WORKDAY.INTL(E47,F47,1,Data!$C$3:$C$60) -> 46099 | I47: =K46 -> 46097 | J47: 2 | K47: =WORKDAY.INTL(I47,J47,1,Data!$C$3:$C$60) -> 46099 | M47: 0 | N47: =_xlfn.LET( _xlpm.s,VALUE($I47), _xlpm.e,VALUE($K47), IF(OR(_xlpm.s="",_xlpm.e=""),"", IF(_xlpm.e<=_xlpm.s, IF(TODAY()>=_xlpm.e,1,0), MAX(0,MIN(1,(TODAY()-_xlpm.s)/(_xlpm.e-_xlpm.s))))) ) -> 0
B49: 8 | C49: Project Closure | E49: =MIN(E50:E52) -> 46097 | F49: =G49-E49 -> 10 | G49: =MAX(G50:G52) -> 46107 | I49: =MIN(I50:I52) -> 46097 | J49: =K49-I49 -> 10 | K49: =MAX(K50:K52) -> 46107 | M49: =(J50*M50+J51*M51+J52*M52)/SUM(J50:J52) -> 0 | N49: =(K47*N47+K43*N43+K50*N50+K51*N51+K52*N52)/SUM(K47:K52) -> 0
...

Sheet Expenditure Breakdown
B2: COSTED EXPENDITURE BREAKDOWN | I2: =SUM(I6:I180) -> 725014.91 | J2: =SUM(J6:J180) -> 823858.26 | L2: ACTUAL EXPENDITURE BREAKDOWN | R2: FINANCE ONLY | X2: =SUM(X6:X180) -> 585065.51
B4: No. | C4: Product / Service | D4: Description of Work | E4: QTY | F4: Rate / Unit | G4: Budget Total | H4: FORECASTED PAYMENT DATE | I4: Total COS | J4: =IF(J2-'Revenue Tracking'!D4>=0, "Total Revenue", "ERROR on REV" ) -> ERROR on REV | L4: No. | M4: Product/ Service | N4: Description of Work | O4: QTY | P4: Rate / Unit | Q4: Actual Total | R4: PO NUMBER | S4: INVOICE NUMBER | T4: INVOICE RAISED DATE | U4: REVENUE RECOGNITION AMOUNT | V4: CHECK | W4: FINANCE PAYMENT DATE | X4: Total COS
B6: 1 | C6: Panels | I6: =SUM(G6:G11) -> 0 | J6: =F181 -> 0 | L6: 1 | M6: 1. Panels | V6: =J6-SUM(U6:U11) -> 0 | X6: =SUM(Q6:Q11) -> 0
B7: 1 | L7: 1 | M7: 1. Panels
B8: 1 | L8: 1 | M8: 1. Panels
B9: 1 | L9: 1 | M9: 1. Panels
B10: 1 | L10: 1 | M10: 1. Panels
B11: 1 | L11: 1 | M11: 1. Panels | Y11: BUDGET | Z11: Installer Allocation
Y12: AC Equipment | Z12: =G52 -> 0
B13: 2 | C13: Inverters | I13: =SUM(G13:G19) -> 0 | J13: =F182 -> 0 | L13: 2 | M13: 2. Inverters | V13: =J13-SUM(U13:U19) -> 0 | X13: =SUM(Q13:Q19) -> 0 | Y13: DC Equipment | Z13: =G29 -> 0
B14: 2 | L14: 2 | M14: 2. Inverters | Y14: AC Labour | Z14: =G110 -> 0
B15: 2 | L15: 2 | M15: 2. Inverters | Y15: DC Labour | Z15: =G111 -> 0
B16: 2 | L16: 2 | M16: 2. Inverters | Y16: Offloading | Z16: =G123 -> 0
B17: 2 | L17: 2 | M17: 2. Inverters | Y17: Scaffolding | Z17: =G124 -> 0
B18: 2 | L18: 2 | M18: 2. Inverters | Y18: Storage | Z18: =G126 -> 0
B19: 2 | L19: 2 | M19: 2. Inverters | Y19: Telehandler | Z19: 0
Y20: Trenching | Z20: 0
B21: 3 | C21: Mounting Structures | I21: =SUM(G21:G26) -> 0 | J21: =F183 -> 0 | L21: 3 | M21: 3. Mounting Structures | V21: =J21-SUM(U21:U26) -> 0 | X21: =SUM(Q21:Q26) -> 0 | Y21: Other | Z21: 0
B22: 3 | L22: 3 | M22: 3. Mounting Structures | Y22: Total | Z22: =SUM(Z12:Z21) -> 0
B23: 3 | L23: 3 | M23: 3. Mounting Structures | Y23: Less 15% | Z23: =+Z22*0.85 -> 0
B24: 3 | L24: 3 | M24: 3. Mounting Structures | Y24: R/Wp | Z24: =Z23/'Project Plan'!$E$3/1000 -> 0
B25: 3 | L25: 3 | M25: 3. Mounting Structures
B26: 3 | L26: 3 | M26: 3. Mounting Structures | Y26: ACTUAL | Z26: Installer Price
Y27: =Y12 -> AC Equipment | Z27: 151265.43
B28: 4 | C28: DC Equipment | I28: =SUM(G28:G42) -> 0 | J28: =F184 -> 0 | L28: 4 | M28: 4. DC Equipment | V28: =J28-SUM(U28:U42) -> 0 | X28: =SUM(Q28:Q42) -> 0 | Y28: =Y13 -> DC Equipment | Z28: 79942.7
B29: 4 | L29: 4 | M29: 4. DC Equipment | Y29: =Y14 -> AC Labour | Z29: 44530
B30: 4 | L30: 4 | M30: 4. DC Equipment | Y30: =Y15 -> DC Labour | Z30: 91980
B31: 4 | L31: 4 | M31: 4. DC Equipment | Y31: Lifelines | Z31: 8500
B32: 4 | L32: 4 | M32: 4. DC Equipment | Y32: Forklift | Z32: 17023.903
B33: 4 | L33: 4 | M33: 4. DC Equipment | Y33: Geda | Z33: 1788.3333
B34: 4 | L34: 4 | M34: 4. DC Equipment | Y34: Logistics | Z34: 0
B35: 4 | L35: 4 | M35: 4. DC Equipment | Y35: Trenching | Z35: 0
B36: 4 | L36: 4 | M36: 4. DC Equipment | Y36: Other | Z36: 0
B37: 4 | L37: 4 | M37: 4. DC Equipment | Y37: Other | Z37: 0
B38: 4 | L38: 4 | M38: 4. DC Equipment | Y38: Total | Z38: =SUM(Z27:Z37) -> 395030.36
B39: 4 | L39: 4 | M39: 4. DC Equipment | Y39: R/Wp | Z39: =Z38/'Project Plan'!$E$3/1000 -> 3.9503036
B40: 4 | L40: 4 | M40: 4. DC Equipment
B41: 4 | L41: 4 | M41: 4. DC Equipment
B42: 4 | L42: 4 | M42: 4. DC Equipment
B44: 5 | C44: Monitoring | I44: =D186 -> 0 | J44: =F186 -> 0 | L44: 5 | M44: 5. Monitoring | X44: =SUM(Q44:Q50) -> 0
...

Sheet Expenditure Tracking
B2: HIGH LEVEL PROJECT EXPENDITURE TRACKING
F4: COSTED | H4: ACTUAL | J4: Difference from Costed
B5: EXPENDITURE | F5: =SUM(F9:F23) -> 725014.91 | H5: =SUM(H9:H23) -> 585065.51 | J5: =SUM(J9:J23) -> 139949.4
B7: No. | D7: Item | F7: Costed Expenditure | H7: Actual Expenditure | J7: Saving / Overrun | L7: Comments on variations from planned expenditure
B9: ='Expenditure Breakdown'!L6 -> 1 | D9: ='Expenditure Breakdown'!M6 -> 1. Panels | F9: ='Expenditure Breakdown'!I6 -> 0 | H9: ='Expenditure Breakdown'!X6 -> 0 | J9: =F9-H9 -> 0
B10: ='Expenditure Breakdown'!L13 -> 2 | D10: ='Expenditure Breakdown'!M13 -> 2. Inverters | F10: ='Expenditure Breakdown'!I13 -> 0 | H10: ='Expenditure Breakdown'!X13 -> 0 | J10: =F10-H10 -> 0
B11: ='Expenditure Breakdown'!L21 -> 3 | D11: ='Expenditure Breakdown'!M21 -> 3. Mounting Structures | F11: ='Expenditure Breakdown'!I21 -> 0 | H11: ='Expenditure Breakdown'!X21 -> 0 | J11: =F11-H11 -> 0
B12: ='Expenditure Breakdown'!L28 -> 4 | D12: ='Expenditure Breakdown'!M28 -> 4. DC Equipment | F12: ='Expenditure Breakdown'!I28 -> 0 | H12: ='Expenditure Breakdown'!X28 -> 0 | J12: =F12-H12 -> 0
B13: ='Expenditure Breakdown'!L44 -> 5 | D13: ='Expenditure Breakdown'!M44 -> 5. Monitoring | F13: ='Expenditure Breakdown'!I44 -> 0 | H13: ='Expenditure Breakdown'!X44 -> 0 | J13: =F13-H13 -> 0
B14: ='Expenditure Breakdown'!L52 -> 6 | D14: ='Expenditure Breakdown'!M52 -> 6. AC Equipment | F14: ='Expenditure Breakdown'!I52 -> 0 | H14: ='Expenditure Breakdown'!X52 -> 0 | J14: =F14-H14 -> 0
B15: ='Expenditure Breakdown'!L70 -> 7 | D15: ='Expenditure Breakdown'!M70 -> 7.BESS | F15: ='Expenditure Breakdown'!I70 -> 724139.91 | H15: ='Expenditure Breakdown'!X70 -> 573781 | J15: =F15-H15 -> 150358.91
B16: ='Expenditure Breakdown'!L100 -> 8 | D16: ='Expenditure Breakdown'!M100 -> 8. Product Add On | F16: ='Expenditure Breakdown'!I100 -> 0 | H16: ='Expenditure Breakdown'!X100 -> 0 | J16: =F16-H16 -> 0
B17: ='Expenditure Breakdown'!L110 -> 9 | D17: ='Expenditure Breakdown'!M110 -> 9. AC & DC installation | F17: ='Expenditure Breakdown'!I110 -> 0 | H17: ='Expenditure Breakdown'!X110 -> 0 | J17: =F17-H17 -> 0
B18: ='Expenditure Breakdown'!L123 -> 10 | D18: ='Expenditure Breakdown'!M123 -> 10. Site Logistics | F18: ='Expenditure Breakdown'!I123 -> 0 | H18: ='Expenditure Breakdown'!X123 -> 0 | J18: =F18-H18 -> 0
B19: ='Expenditure Breakdown'!L139 -> 11 | D19: ='Expenditure Breakdown'!M139 -> 11. Due Dilligence | F19: ='Expenditure Breakdown'!I139 -> 0 | H19: ='Expenditure Breakdown'!X139 -> 0 | J19: =F19-H19 -> 0
B20: ='Expenditure Breakdown'!L145 -> 12 | D20: ='Expenditure Breakdown'!M145 -> 12. BDP Commission | F20: ='Expenditure Breakdown'!I145 -> 0 | H20: ='Expenditure Breakdown'!X145 -> 0 | J20: =F20-H20 -> 0
B21: ='Expenditure Breakdown'!L148 -> 13 | D21: ='Expenditure Breakdown'!M149 -> 13. Engineering | F21: ='Expenditure Breakdown'!I148 -> 0 | H21: ='Expenditure Breakdown'!X148 -> 10409.511 | J21: =F21-H21 -> -10409.511
B22: ='Expenditure Breakdown'!L155 -> 14 | D22: ='Expenditure Breakdown'!M155 -> 14. General Expenses | F22: ='Expenditure Breakdown'!I155 -> 875 | H22: ='Expenditure Breakdown'!X155 -> 875 | J22: =F22-H22 -> 0
B23: ='Expenditure Breakdown'!L168 -> 15 | D23: ='Expenditure Breakdown'!M168 -> 15. Service Add On | F23: ='Expenditure Breakdown'!I168 -> 0 | H23: ='Expenditure Breakdown'!X168 -> 0 | J23: =F23-H23 -> 0
D25: check: | F25: ='Expenditure Breakdown'!I2-'Expenditure Tracking'!F5 -> 0 | G25: =#REF!-G5 -> #REF! | H25: ='Expenditure Breakdown'!X2-H5 -> 0

Sheet Cashflow
D1: [RT: Double Check the first date is always a MONDAY] | F1: 46006 | G1: =F1+7 -> 46013 | H1: =G1+7 -> 46020 | I1: =H1+7 -> 46027 | J1: =I1+7 -> 46034 | K1: =J1+7 -> 46041 | L1: =K1+7 -> 46048 | M1: =L1+7 -> 46055 | N1: =M1+7 -> 46062 | ... KF1: =KE1+7 -> 48008
A2: PLANNED | C2: CHECK | D2: CHECK
B3: Planned Revenue | C3: ='Revenue Tracking'!D4 -> 823858.49 | D3: =SUM(F3:KF3) -> 823858.49 | F3: =SUMIFS('Revenue Tracking'!$F$13:$F$19, 'Revenue Tracking'!$H$13:$H$19, ">="&F1,'Revenue Tracking'!$H$13:$H$19, "<"&G1) -> 0 | G3: =SUMIFS('Revenue Tracking'!$F$13:$F$19, 'Revenue Tracking'!$H$13:$H$19, ">="&G1,'Revenue Tracking'!$H$13:$H$19, "<"&H1) -> 164771.7 | H3: =SUMIFS('Revenue Tracking'!$F$13:$F$19, 'Revenue Tracking'!$H$13:$H$19, ">="&H1,'Revenue Tracking'!$H$13:$H$19, "<"&I1) -> 0 | I3: =SUMIFS('Revenue Tracking'!$F$13:$F$19, 'Revenue Tracking'!$H$13:$H$19, ">="&I1,'Revenue Tracking'!$H$13:$H$19, "<"&J1) -> 0 | J3: =SUMIFS('Revenue Tracking'!$F$13:$F$19, 'Revenue Tracking'!$H$13:$H$19, ">="&J1,'Revenue Tracking'!$H$13:$H$19, "<"&K1) -> 0 | K3: =SUMIFS('Revenue Tracking'!$F$13:$F$19, 'Revenue Tracking'!$H$13:$H$19, ">="&K1,'Revenue Tracking'!$H$13:$H$19, "<"&L1) -> 0 | L3: =SUMIFS('Revenue Tracking'!$F$13:$F$19, 'Revenue Tracking'!$H$13:$H$19, ">="&L1,'Revenue Tracking'!$H$13:$H$19, "<"&M1) -> 0 | M3: =SUMIFS('Revenue Tracking'!$F$13:$F$19, 'Revenue Tracking'!$H$13:$H$19, ">="&M1,'Revenue Tracking'!$H$13:$H$19, "<"&N1) -> 0 | ... KE3: =SUMIFS('Revenue Tracking'!$F$13:$F$19, 'Revenue Tracking'!$H$13:$H$19, ">="&KE1,'Revenue Tracking'!$H$13:$H$19, "<"&KF1) -> 0 | KF3: =SUMIFS('Revenue Tracking'!$F$13:$F$19, 'Revenue Tracking'!$H$13:$H$19, ">="&KF1,'Revenue Tracking'!$H$13:$H$19, "<"&#REF!) -> 0
B4: Planned Revenue - Cumulative | F4: =F3 -> 0 | G4: =F4+G3 -> 164771.7 | H4: =G4+H3 -> 164771.7 | I4: =H4+I3 -> 164771.7 | J4: =I4+J3 -> 164771.7 | K4: =J4+K3 -> 164771.7 | L4: =K4+L3 -> 164771.7 | M4: =L4+M3 -> 164771.7 | N4: =M4+N3 -> 164771.7 | ... KF4: =KE4+KF3 -> 823858.49
B5: Planned Expenditure | C5: ='Revenue Tracking'!D5 -> 725014.91 | D5: =SUM(F5:KF5) -> 725014.91 | F5: =SUMIFS('Expenditure Breakdown'!$G$6:$G$187, 'Expenditure Breakdown'!$H$6:$H$187, ">="&F1,'Expenditure Breakdown'!$H$6:$H$187, "<"&G1) -> 0 | G5: =SUMIFS('Expenditure Breakdown'!$G$6:$G$187, 'Expenditure Breakdown'!$H$6:$H$187, ">="&G1,'Expenditure Breakdown'!$H$6:$H$187, "<"&H1) -> 0 | H5: =SUMIFS('Expenditure Breakdown'!$G$6:$G$187, 'Expenditure Breakdown'!$H$6:$H$187, ">="&H1,'Expenditure Breakdown'!$H$6:$H$187, "<"&I1) -> 0 | I5: =SUMIFS('Expenditure Breakdown'!$G$6:$G$187, 'Expenditure Breakdown'!$H$6:$H$187, ">="&I1,'Expenditure Breakdown'!$H$6:$H$187, "<"&J1) -> 0 | J5: =SUMIFS('Expenditure Breakdown'!$G$6:$G$187, 'Expenditure Breakdown'!$H$6:$H$187, ">="&J1,'Expenditure Breakdown'!$H$6:$H$187, "<"&K1) -> 0 | K5: =SUMIFS('Expenditure Breakdown'!$G$6:$G$187, 'Expenditure Breakdown'!$H$6:$H$187, ">="&K1,'Expenditure Breakdown'!$H$6:$H$187, "<"&L1) -> 0 | L5: =SUMIFS('Expenditure Breakdown'!$G$6:$G$187, 'Expenditure Breakdown'!$H$6:$H$187, ">="&L1,'Expenditure Breakdown'!$H$6:$H$187, "<"&M1) -> 0 | M5: =SUMIFS('Expenditure Breakdown'!$G$6:$G$187, 'Expenditure Breakdown'!$H$6:$H$187, ">="&M1,'Expenditure Breakdown'!$H$6:$H$187, "<"&N1) -> 0 | ... KE5: =SUMIFS('Expenditure Breakdown'!$G$6:$G$187, 'Expenditure Breakdown'!$H$6:$H$187, ">="&KE1,'Expenditure Breakdown'!$H$6:$H$187, "<"&KF1) -> 0 | KF5: =SUMIFS('Expenditure Breakdown'!$G$6:$G$187, 'Expenditure Breakdown'!$H$6:$H$187, ">="&KF1,'Expenditure Breakdown'!$H$6:$H$187, "<"&#REF!) -> 0
B6: Planned Expenditure - Cumulative | F6: =F5 -> 0 | G6: =F6+G5 -> 0 | H6: =G6+H5 -> 0 | I6: =H6+I5 -> 0 | J6: =I6+J5 -> 0 | K6: =J6+K5 -> 0 | L6: =K6+L5 -> 0 | M6: =L6+M5 -> 0 | N6: =M6+N5 -> 0 | ... KF6: =KE6+KF5 -> 725014.91
B7: PLANNED CashFlow | F7: =F4-F6 -> 0 | G7: =G4-G6 -> 164771.7 | H7: =H4-H6 -> 164771.7 | I7: =I4-I6 -> 164771.7 | J7: =J4-J6 -> 164771.7 | K7: =K4-K6 -> 164771.7 | L7: =L4-L6 -> 164771.7 | M7: =M4-M6 -> 164771.7 | ... KF7: =KF4-KF6 -> 98843.574
A8: ACTUAL | C8: CHECK | D8: CHECK
B9: Actual + Planned Revenue | C9: ='Revenue Tracking'!F4 -> 823858.49 | D9: =SUM(F9:KF9) -> 823858.49 | F9: =SUMIFS('Revenue Tracking'!$F$13:$F$19, 'Revenue Tracking'!$P$13:$P$19, ">="&F1,'Revenue Tracking'!$P$13:$P$19, "<"&G1) -> 0 | G9: =SUMIFS('Revenue Tracking'!$F$13:$F$19, 'Revenue Tracking'!$P$13:$P$19, ">="&G1,'Revenue Tracking'!$P$13:$P$19, "<"&H1) -> 0 | H9: =SUMIFS('Revenue Tracking'!$F$13:$F$19, 'Revenue Tracking'!$P$13:$P$19, ">="&H1,'Revenue Tracking'!$P$13:$P$19, "<"&I1) -> 164771.7 | I9: =SUMIFS('Revenue Tracking'!$F$13:$F$19, 'Revenue Tracking'!$P$13:$P$19, ">="&I1,'Revenue Tracking'!$P$13:$P$19, "<"&J1) -> 0 | J9: =SUMIFS('Revenue Tracking'!$F$13:$F$19, 'Revenue Tracking'!$P$13:$P$19, ">="&J1,'Revenue Tracking'!$P$13:$P$19, "<"&K1) -> 0 | K9: =SUMIFS('Revenue Tracking'!$F$13:$F$19, 'Revenue Tracking'!$P$13:$P$19, ">="&K1,'Revenue Tracking'!$P$13:$P$19, "<"&L1) -> 0 | L9: =SUMIFS('Revenue Tracking'!$F$13:$F$19, 'Revenue Tracking'!$P$13:$P$19, ">="&L1,'Revenue Tracking'!$P$13:$P$19, "<"&M1) -> 0 | M9: =SUMIFS('Revenue Tracking'!$F$13:$F$19, 'Revenue Tracking'!$P$13:$P$19, ">="&M1,'Revenue Tracking'!$P$13:$P$19, "<"&N1) -> 0 | ... KE9: =SUMIFS('Revenue Tracking'!$F$13:$F$19, 'Revenue Tracking'!$P$13:$P$19, ">="&KE1,'Revenue Tracking'!$P$13:$P$19, "<"&KF1) -> 0 | KF9: =SUMIFS('Revenue Tracking'!$F$13:$F$19, 'Revenue Tracking'!$P$13:$P$19, ">="&KF1,'Revenue Tracking'!$P$13:$P$19, "<"&#REF!) -> 0
B10: Actual + Planned Revenue - Cumulative | F10: =F9 -> 0 | G10: =F10+G9 -> 0 | H10: =G10+H9 -> 164771.7 | I10: =H10+I9 -> 164771.7 | J10: =I10+J9 -> 164771.7 | K10: =J10+K9 -> 164771.7 | L10: =K10+L9 -> 164771.7 | M10: =L10+M9 -> 164771.7 | N10: =M10+N9 -> 164771.7 | ... KF10: =KE10+KF9 -> 823858.49
B11: Actual + Planned Expenditure | C11: ='Revenue Tracking'!F5 -> 585065.51 | D11: =SUM(F11:KF11) -> 585065.51 | F11: =SUMIFS('Expenditure Breakdown'!$Q$6:$Q$187, 'Expenditure Breakdown'!$W$6:$W$187, ">="&F1,'Expenditure Breakdown'!$W$6:$W$187, "<"&G1) -> 0 | G11: =SUMIFS('Expenditure Breakdown'!$Q$6:$Q$187, 'Expenditure Breakdown'!$W$6:$W$187, ">="&G1,'Expenditure Breakdown'!$W$6:$W$187, "<"&H1) -> 0 | H11: =SUMIFS('Expenditure Breakdown'!$Q$6:$Q$187, 'Expenditure Breakdown'!$W$6:$W$187, ">="&H1,'Expenditure Breakdown'!$W$6:$W$187, "<"&I1) -> 0 | I11: =SUMIFS('Expenditure Breakdown'!$Q$6:$Q$187, 'Expenditure Breakdown'!$W$6:$W$187, ">="&I1,'Expenditure Breakdown'!$W$6:$W$187, "<"&J1) -> 0 | J11: =SUMIFS('Expenditure Breakdown'!$Q$6:$Q$187, 'Expenditure Breakdown'!$W$6:$W$187, ">="&J1,'Expenditure Breakdown'!$W$6:$W$187, "<"&K1) -> 0 | K11: =SUMIFS('Expenditure Breakdown'!$Q$6:$Q$187, 'Expenditure Breakdown'!$W$6:$W$187, ">="&K1,'Expenditure Breakdown'!$W$6:$W$187, "<"&L1) -> 0 | L11: =SUMIFS('Expenditure Breakdown'!$Q$6:$Q$187, 'Expenditure Breakdown'!$W$6:$W$187, ">="&L1,'Expenditure Breakdown'!$W$6:$W$187, "<"&M1) -> 0 | M11: =SUMIFS('Expenditure Breakdown'!$Q$6:$Q$187, 'Expenditure Breakdown'!$W$6:$W$187, ">="&M1,'Expenditure Breakdown'!$W$6:$W$187, "<"&N1) -> 0 | ... KE11: =SUMIFS('Expenditure Breakdown'!$Q$6:$Q$187, 'Expenditure Breakdown'!$W$6:$W$187, ">="&KE1,'Expenditure Breakdown'!$W$6:$W$187, "<"&KF1) -> 0 | KF11: =SUMIFS('Expenditure Breakdown'!$Q$6:$Q$187, 'Expenditure Breakdown'!$W$6:$W$187, ">="&KF1,'Expenditure Breakdown'!$W$6:$W$187, "<"&#REF!) -> 0
B12: Actual + Planned Expenditure - Cumulative | F12: =F11 -> 0 | G12: =F12+G11 -> 0 | H12: =G12+H11 -> 0 | I12: =H12+I11 -> 0 | J12: =I12+J11 -> 0 | K12: =J12+K11 -> 0 | L12: =K12+L11 -> 0 | M12: =L12+M11 -> 0 | N12: =M12+N11 -> 0 | ... KF12: =KE12+KF11 -> 585065.51
B14: ACTUAL CashFlow | F14: =F10-F12 -> 0 | G14: =G10-G12 -> 0 | H14: =H10-H12 -> 164771.7 | I14: =I10-I12 -> 164771.7 | J14: =J10-J12 -> 164771.7 | K14: =K10-K12 -> 164771.7 | L14: =L10-L12 -> 164771.7 | M14: =M10-M12 -> 164771.7 | ... KF14: =KF10-KF12 -> 238792.98
C16: CHECK | D16: CHECK
B17: Revenue Recognition | C17: =C3-D17 -> 0.22222222 | D17: =SUM(F17:KF17) -> 823858.26 | F17: =SUMIFS('Expenditure Breakdown'!$U$6:$U$187, 'Expenditure Breakdown'!$T$6:$T$187, ">="&F1,'Expenditure Breakdown'!$T$6:$T$187, "<"&G1) -> 0 | G17: =SUMIFS('Expenditure Breakdown'!$U$6:$U$187, 'Expenditure Breakdown'!$T$6:$T$187, ">="&G1,'Expenditure Breakdown'!$T$6:$T$187, "<"&H1) -> 0 | H17: =SUMIFS('Expenditure Breakdown'!$U$6:$U$187, 'Expenditure Breakdown'!$T$6:$T$187, ">="&H1,'Expenditure Breakdown'!$T$6:$T$187, "<"&I1) -> 0 | I17: =SUMIFS('Expenditure Breakdown'!$U$6:$U$187, 'Expenditure Breakdown'!$T$6:$T$187, ">="&I1,'Expenditure Breakdown'!$T$6:$T$187, "<"&J1) -> 0 | J17: =SUMIFS('Expenditure Breakdown'!$U$6:$U$187, 'Expenditure Breakdown'!$T$6:$T$187, ">="&J1,'Expenditure Breakdown'!$T$6:$T$187, "<"&K1) -> 0 | K17: =SUMIFS('Expenditure Breakdown'!$U$6:$U$187, 'Expenditure Breakdown'!$T$6:$T$187, ">="&K1,'Expenditure Breakdown'!$T$6:$T$187, "<"&L1) -> 0 | L17: =SUMIFS('Expenditure Breakdown'!$U$6:$U$187, 'Expenditure Breakdown'!$T$6:$T$187, ">="&L1,'Expenditure Breakdown'!$T$6:$T$187, "<"&M1) -> 0 | M17: =SUMIFS('Expenditure Breakdown'!$U$6:$U$187, 'Expenditure Breakdown'!$T$6:$T$187, ">="&M1,'Expenditure Breakdown'!$T$6:$T$187, "<"&N1) -> 0 | ... KE17: =SUMIFS('Expenditure Breakdown'!$U$6:$U$187, 'Expenditure Breakdown'!$T$6:$T$187, ">="&KE1,'Expenditure Breakdown'!$T$6:$T$187, "<"&KF1) -> 0 | KF17: =SUMIFS('Expenditure Breakdown'!$U$6:$U$187, 'Expenditure Breakdown'!$T$6:$T$187, ">="&KF1,'Expenditure Breakdown'!$T$6:$T$187, "<"&#REF!) -> 0
B18: Revenue Recognition Cumulative | C18: =D17-D18 -> 0 | D18: =MAX(F18:KF18) -> 823858.26 | F18: =F17 -> 0 | G18: =F18+G17 -> 0 | H18: =G18+H17 -> 0 | I18: =H18+I17 -> 0 | J18: =I18+J17 -> 0 | K18: =J18+K17 -> 0 | L18: =K18+L17 -> 0 | M18: =L18+M17 -> 0 | N18: =M18+N17 -> 0 | ... KF18: =KE18+KF17 -> 823858.26

Sheet Finance - Revenue
A3: Sum of REVENUE RECOGNITION AMOUNT | B3: Column Labels
A4: Row Labels | B4: (blank) | C4: 46022 | E4: 46053 | F4: 46081 | G4: 46112 | H4: 46142 | I4: 46111 | J4: Grand Total
A5: (blank)
A6: 1. Panels | B6: 0 | D6: 0 | E6: 577060.68 | J6: 577060.68
A7: 2. Inverters | B7: 0 | D7: 0 | E7: 175000 | J7: 175000
A8: 3. Mounting Structures | D8: 0 | E8: 188842.5 | J8: 188842.5
A9: 4. DC Equipment | D9: 0 | E9: 21928.216 | F9: 100913.8 | G9: 21928.216 | H9: 4385.6431 | J9: 149155.87
A10: 5. Monitoring | D10: 0 | E10: 10517.677 | F10: 50732.323 | J10: 61250
A11: 6. AC Equipment | D11: 0 | E11: 30740.993 | F11: 196451.6 | G11: 30740.993 | H11: 6148.1987 | J11: 264081.78
A12: 8. Product Add On | B12: 0 | D12: 0 | F12: 144498.77 | I12: 18670.539 | J12: 163169.31
A13: 9. AC & DC installation | D13: 0 | E13: 37919.444 | F13: 68255 | G13: 37919.444 | H13: 7583.8889 | J13: 151677.78
A14: 10. Site Logistics | D14: 0 | E14: 7089.9731 | F14: 12761.952 | G14: 7089.9731 | H14: 1417.9946 | J14: 28359.892
A15: 11. Due Dilligence | C15: 11164.109 | D15: 0 | G15: 87724.78 | J15: 98888.889
A16: 13. Engineering | D16: 0 | G16: 19649.809 | J16: 19649.809
A17: 14. General Expenses | C17: 534.72222 | D17: 0 | E17: 534.72222 | F17: 534.72222 | G17: 534.72222 | J17: 2138.8889
A18: 15. Service Add On
A19: 12. BDP Commission
A20: 7.BESS
A21: Grand Total | B21: 0 | C21: 11698.831 | D21: 0 | E21: 1049634.2 | F21: 574148.16 | G21: 205587.94 | H21: 19535.725 | I21: 18670.539 | J21: 1879275.4

Sheet Finance - COS
A3: Sum of Actual Total | B3: Column Labels
A4: Row Labels | B4: (blank) | C4: 46022 | E4: 46053 | F4: 46081 | G4: 46112 | H4: 46142 | I4: 46111 | J4: Grand Total
A5: (blank)
A6: 1. Panels | B6: 0 | E6: 356240 | J6: 356240
A7: 2. Inverters | E7: 137740 | J7: 137740
A8: 3. Mounting Structures | E8: 151074 | J8: 151074
A9: 4. DC Equipment | E9: 19985.675 | F9: 91974.215 | G9: 19985.675 | H9: 3997.135 | J9: 135942.7
A10: 5. Monitoring | E10: 8500 | F10: 41000 | J10: 49500
A11: 6. AC Equipment | E11: 17608.369 | F11: 112527.01 | G11: 17608.369 | H11: 3521.6738 | J11: 151265.43
A12: 8. Product Add On | F12: 116091 | I12: 15000 | J12: 131091
A13: 9. AC & DC installation | E13: 34127.5 | F13: 61429.5 | G13: 34127.5 | H13: 6825.5 | J13: 136510
A14: 10. Site Logistics | E14: 6828.0591 | F14: 12290.506 | G14: 6828.0591 | H14: 1365.6118 | J14: 27312.236
A15: 11. Due Dilligence | C15: 10000 | G15: 78577.5 | J15: 88577.5
A16: 13. Engineering | G16: 23490.942 | J16: 23490.942
A17: 14. General Expenses | C17: 481.25 | E17: 481.25 | F17: 481.25 | G17: 481.25 | J17: 1925
A18: 15. Service Add On
A19: 12. BDP Commission | D19: 0 | J19: 0
A20: 7.BESS
A21: Grand Total | B21: 0 | C21: 10481.25 | D21: 0 | E21: 732584.85 | F21: 435793.49 | G21: 181099.3 | H21: 15709.921 | I21: 15000 | J21: 1390668.8

Sheet Data
C2: Public holidays | F2: Drop down list
C3: 45658 | D3: New Years Day | F3: Approved
C4: 45737 | D4: Human Rights day | F4: Pending
C5: 45765 | D5: Good Friday | F5: Declined
C6: 45768 | D6: Family Day | F6: Abanded
C7: 45774 | D7: Freedom Day
C8: 45765 | D8: Freedom DayObserved
C9: 45778 | D9: Workers day
C10: 45824 | D10: Youth Day Holiday
C11: 45878 | D11: Womens Day
C12: 45924 | D12: Heritage Day
C13: 46007 | D13: Day of Reconciliation | H13: Manual dates
C14: 46016 | D14: Christmas Day
C15: 46017 | D15: Day of Goodwill
C16: 46006 | D16: Builders Break
C17: 46007 | D17: Builders Break
C18: 46008 | D18: Builders Break
C19: 46009 | D19: Builders Break
C20: 46010 | D20: Builders Break
C21: 46011 | D21: Builders Break
C22: 46012 | D22: Builders Break
C23: 46013 | D23: Builders Break
C24: 46014 | D24: Builders Break
C25: 46015 | D25: Builders Break
... C40: 46030 | D40: Builders Break
D41: Builders Break
D42: Builders Break
D43: Builders Break
D44: Builders Break
D45: Builders Break
D46: Builders Break
D47: Builders Break
D48: Builders Break
C49: 46102 | D49: Human Rights day
C50: 46115 | D50: Good Friday
C51: 46118 | D51: Family Day
C52: 46139 | D52: Freedom Day
C53: 46143 | D53: Workers day
C54: 46189 | D54: Youth Day Holiday
C55: 46243 | D55: Womens Day
...
