Workbook
Name Inverter_Capacity: #REF!
Name Inverter_Supplier: #REF!
Name Project_Size: 'Finance - Revenue'!Projectsize
Name Project_Size: Projectsize
Name Projectsize: #REF!
Name Projectsize: #REF!
Name Security_Serv: #REF!
Name Security_Serv: #REF!
Name SSS: #REF!
Name SSS: #REF!
Name USD_ZAR: #REF!

Sheet Certificate - Financial Close
B2: Emergent Energy – Financial Close Completion Certificate | H2: FINANCIAL CLOSE CERTIFICATE
B4: Project Name: | C4: ='Project Plan'!E2 -> Topsteel
B5: COO: | C5: Johannes Potgieter
B6: Programme Manager: | C6: Roedolph Venter
B7: HoPD: | C7: Natasha Watkins-Baker
B9: Date of Phase Completion:
B10: Phase Deliverables Checklist: (Y/N)
B11: Product Agreement
B12: EPC Agreement
B13: O&M Agreeement
B14: Cost Proposal
B15: Deposit Received
B16: Risks / Notes
B18: Acknowledgement and Acceptance:
B19: Role | C19: Name | D19: Signature | E19: Date

Sheet Certificate - Planning
B2: Emergent Energy – Planning Phase Completion Certificate | H2: PLANNING CERTIFICATE
B4: Project Name: | C4: ='Project Plan'!E2 -> Topsteel
B5: Client Representative:
B6: Programme Manager: | C6: Roedolph Venter
B7: Project Manager: | C7: ='Project Plan'!E5 -> Justin Franke
B8: Project Engineer:
B10: Date of Phase Completion:
B11: Phase Deliverables Checklist: (Y/N)
B12: Project Introduction Presentation | C12: Y
B13: Project Brief | C13: Y
B14: Engineering Pack
B15: BOQ | C15: Y
B16: PO – Material & Equipment | C16: Y
B17: PO - Contractors | C17: Y
B18: HSE – NOC | C18: Y
B19: HSE – EE File
B20: HSE – Contractor File
B21: SSEG Application | C21: Y
B22: Risks / Notes | C22: PVDB Board lead time
B24: Acknowledgement and Acceptance:
B25: Role | C25: Name | D25: Signature | E25: Date

Sheet Change Register
F1: Change Register
B3: ID | C3: Description | D3: Supporting Image (If Applicable) | E3: Impact | F3: Proposed Date | G3: Proposed By | H3: Status | I3: Approved By | J3: Approved Date | K3: Results / Comments
B4: DEC001
B5: DEC002
B6: DEC003
B7: DEC004
B8: DEC005
B9: DEC006
B10: DEC007
B11: DEC008
B12: DEC009
B13: DEC010
B14: DEC011
B15: DEC012
... B33: DEC030

Sheet BOQ
B2: Item | C2: Supplier | D2: Description | E2: Quantity | F2: Comments
B3: PV Module | C3: MSA | D3: 610W Jinko Solar | E3: 448
B4: DC Cable Red & Black | C4: MSA | E4: 6000
B5: Inverters | C5: MSA | D5: Huawei 100KTL | E5: 2
B6: Mounting Structure | C6: Schletter | D6: Kliplok Seamclamp | E6: 273kWp
B7: Current Transformers (Production) | C7: Accuenergy | D7: AcuCT-2031-600/5A | E7: 3
B8: Current Transformers (Consumption)
B9: Solar Production Meter (Techistter) | C9: Techsitter | D9: Revenue Grade Meter | E9: 1
B10: Grid Consumption Meter
B11: Wi-Fi Router & Sim | C11: Accuenergy | D11: Teltonika RTU241 | E11: 1
B12: Switch | C12: Accuenergy | D12: TSW200 5 port Ethernet | E12: 1
B13: Back Up Battery | C13: Red Pole | D13: RP-12V-18AH LiFePo4 | E13: 1
B14: PVDB | C14: Switchboard | E14: 1
B23: Supplier List
B24: Accuenergy
B25: Krannich
B26: Menlo
B27: Red Pole
B28: Schletter
B29: Switchboard
B30: Techsitter
B31: MSA

Sheet Compliance
B2: HSE
B4: Description | C4: Status | D4: Approved By | E4: Date | F4: Results / Comments
B5: NOC | F5: In progress
B6: 7.1 Agreement | F6: In progress
B7: 13.2 Agreement | F7: In progress
B8: EE File | F8: In progress
B9: Subbie File | F9: Not appointed yet
B16: SSEG
B18: Description | C18: Status | D18: Approved By | E18: Date | F18: Results / Comments
B19: SSEG Application
B20: PTI
B21: Commissioning Approval

Sheet Project Plan
N1: =TODAY() -> 46069 | O1: =TODAY() -> 46069
C2: PROJECT PLAN | E2: Topsteel | I2: Net Work Days | K2: =NETWORKDAYS(I18,K39,Data!C3:C60) -> 39 | N2: 0 | O2: 1
C3: PROJECT SIZE (kWp) | E3: 273 | I3: Total Weeks | K3: =K2/5 -> 7.8
C4: PROJECT DEVELOPER | E4: Cole Bisset | I4: kW/Week Installation Rate | K4: =E3/K3 -> 35
C5: PROJECT MANAGERS | E5: Justin Franke
C6: CONTRACT VALUE | E6: 2345835.9
C7: Phase: | E7: Construction
B8: No. | C8: HIGH LEVEL PROGRAMME | E8: Planned Start | F8: Duration | G8: Planned End | I8: Actual Start | J8: Duration | K8: Actual End | M8: Status | N8: Expected Status | O8: Comment
F9: =G39-E19 -> 42 | J9: =K39-I19 -> 52 | M9: =AVERAGE(M11,M18,M21,M28,M35,M39,M48,M44) -> 0.40513393 | N9: =AVERAGE(N11,N18,N21,N28,N35,N39,N48,N44) -> 0.41850549 | S9: =TODAY() -> 46069 | T9: =TODAY() -> 46069
S10: 1 | T10: 0
B11: 1 | C11: Project Initiation | E11: =MIN(E12:E17) -> 46036 | F11: =G11-E11 -> 16 | G11: =MAX(G12:G17) -> 46052 | I11: =MIN(I12:I17) -> 46036 | J11: =K11-I11 -> 16 | K11: =MAX(K12:K17) -> 46052 | M11: =(J12*M12+J13*M13+J14*M14+J15*M15+J16*M16)/SUM(J12:J16) -> 1 | N11: =(K12*N12+K13*N13+K14*N14+K15*N15+K16*N16)/SUM(K12:K16) -> 1
B12: 1.1 | C12: Project Charter Handover | E12: 46036 | F12: 1 | G12: =WORKDAY.INTL(E12,F12,1,Data!$C$3:$C$60) -> 46037 | I12: 46036 | J12: 1 | K12: =WORKDAY.INTL(I12,J12,1,Data!$C$3:$C$60) -> 46037 | M12: 1 | N12: =_xlfn.LET( _xlpm.s,VALUE($I12), _xlpm.e,VALUE($K12), IF(OR(_xlpm.s="",_xlpm.e=""),"", IF(_xlpm.e<=_xlpm.s, IF(TODAY()>=_xlpm.e,1,0), MAX(0,MIN(1,(TODAY()-_xlpm.s)/(_xlpm.e-_xlpm.s))))) ) -> 1 | S12: Milestone | T12: Start Date | U12: Duration | V12: End Date
B13: 1.2 | C13: HSE Readiness and Signoff | E13: =G12 -> 46037 | F13: 8 | G13: =WORKDAY.INTL(E13,F13,1,Data!$C$3:$C$60) -> 46049 | I13: =K12 -> 46037 | J13: 8 | K13: =WORKDAY.INTL(I13,J13,1,Data!$C$3:$C$60) -> 46049 | M13: 1 | N13: =_xlfn.LET( _xlpm.s,VALUE($I13), _xlpm.e,VALUE($K13), IF(OR(_xlpm.s="",_xlpm.e=""),"", IF(_xlpm.e<=_xlpm.s, IF(TODAY()>=_xlpm.e,1,0), MAX(0,MIN(1,(TODAY()-_xlpm.s)/(_xlpm.e-_xlpm.s))))) ) -> 1 | S13: =C11 -> Project Initiation | T13: =I11 -> 46036 | U13: =J11 -> 16 | V13: =K11 -> 46052
B14: 1.3 | C14: Project Introduction | E14: =WORKDAY.INTL(G13,0,1,Data!$C$3:$C$60) -> 46049 | F14: 1 | G14: =WORKDAY.INTL(E14,F14,1,Data!$C$3:$C$60) -> 46050 | I14: =WORKDAY.INTL(K13,0,1,Data!$C$3:$C$60) -> 46049 | J14: 1 | K14: =WORKDAY.INTL(I14,J14,1,Data!$C$3:$C$60) -> 46050 | M14: 1 | N14: =_xlfn.LET( _xlpm.s,VALUE($I14), _xlpm.e,VALUE($K14), IF(OR(_xlpm.s="",_xlpm.e=""),"", IF(_xlpm.e<=_xlpm.s, IF(TODAY()>=_xlpm.e,1,0), MAX(0,MIN(1,(TODAY()-_xlpm.s)/(_xlpm.e-_xlpm.s))))) ) -> 1 | S14: =C18 -> Site Establishment | T14: =I18 -> 46049 | U14: =J18 -> 1 | V14: =K18 -> 46050
B15: 1.4 | C15: Installer Kick Off | E15: =WORKDAY.INTL(E13,0,1,Data!$C$3:$C$60)+14 -> 46051 | F15: 1 | G15: =WORKDAY.INTL(E15,F15,1,Data!$C$3:$C$60) -> 46052 | I15: =WORKDAY.INTL(I13,0,1,Data!$C$3:$C$60)+14 -> 46051 | J15: 1 | K15: =WORKDAY.INTL(I15,J15,1,Data!$C$3:$C$60) -> 46052 | M15: 1 | N15: =_xlfn.LET( _xlpm.s,VALUE($I15), _xlpm.e,VALUE($K15), IF(OR(_xlpm.s="",_xlpm.e=""),"", IF(_xlpm.e<=_xlpm.s, IF(TODAY()>=_xlpm.e,1,0), MAX(0,MIN(1,(TODAY()-_xlpm.s)/(_xlpm.e-_xlpm.s))))) ) -> 1 | S15: =C21 -> AC Installation | T15: =I21 -> 46035 | U15: =J21 -> 41 | V15: =K21 -> 46076
B16: 1.5 | C16: Project Review | E16: =WORKDAY.INTL(E15,0,1,Data!$C$3:$C$60)-4 -> 46047 | F16: 1 | G16: =WORKDAY.INTL(E16,F16,1,Data!$C$3:$C$60) -> 46048 | I16: =WORKDAY.INTL(I15,0,1,Data!$C$3:$C$60)-4 -> 46047 | J16: 1 | K16: =WORKDAY.INTL(I16,J16,1,Data!$C$3:$C$60) -> 46048 | M16: 1 | N16: =_xlfn.LET( _xlpm.s,VALUE($I16), _xlpm.e,VALUE($K16), IF(OR(_xlpm.s="",_xlpm.e=""),"", IF(_xlpm.e<=_xlpm.s, IF(TODAY()>=_xlpm.e,1,0), MAX(0,MIN(1,(TODAY()-_xlpm.s)/(_xlpm.e-_xlpm.s))))) ) -> 1 | S16: =C28 -> DC Works | T16: =I28 -> 46049 | U16: =J28 -> 43 | V16: =K28 -> 46092
S17: =C35 -> Module installation | T17: =I35 -> 46049 | U17: =J35 -> 34 | V17: =K35 -> 46083
B18: 2 | C18: Site Establishment | E18: =MIN(E19:E20) -> 46049 | F18: =G18-E18 -> 1 | G18: =MAX(G19:G20) -> 46050 | I18: =MIN(I19:I20) -> 46049 | J18: =K18-I18 -> 1 | K18: =MAX(K19:K20) -> 46050 | M18: =(J19*M19)/J18 -> 1 | N18: =(K19*N19)/K18 -> 1 | S18: =C39 -> Commissioning | T18: =I39 -> 46092 | U18: =J39 -> 9 | V18: =K39 -> 46101
B19: 2.1 | C19: Solar Contractor Establishment | E19: =G16+1 -> 46049 | F19: 1 | G19: =E19+F19 -> 46050 | I19: =K16+1 -> 46049 | J19: 1 | K19: =I19+J19 -> 46050 | M19: 1 | N19: =_xlfn.LET( _xlpm.s,VALUE($I19), _xlpm.e,VALUE($K19), IF(OR(_xlpm.s="",_xlpm.e=""),"", IF(_xlpm.e<=_xlpm.s, IF(TODAY()>=_xlpm.e,1,0), MAX(0,MIN(1,(TODAY()-_xlpm.s)/(_xlpm.e-_xlpm.s))))) ) -> 1 | S19: =C44 -> QA Inspections | T19: =I44 -> 46094 | U19: =J44 -> 6 | V19: =K44 -> 46100
S20: =C48 -> Project Closure | T20: =I48 -> 46097 | U20: =J48 -> 16 | V20: =K48 -> 46113
B21: 3 | C21: AC Installation | E21: =MIN(E22:E27) -> 46035 | F21: =G21-E21 -> 36 | G21: =MAX(G22:G27) -> 46071 | I21: =MIN(I22:I27) -> 46035 | J21: =K21-I21 -> 41 | K21: =MAX(K22:K27) -> 46076 | M21: =(J22*M22+J23*M23+J24*M24+J25*M25+J26*M26)/SUM(J22:J26) -> 0.70138889 | N21: =(J22*N22+J23*N23+J24*N24+J25*N25+J26*N26)/SUM(J22:J26) -> 0.80836139
B22: 3.1 | C22: Inverters delivered | E22: =WORKDAY.INTL(G19,0,1,Data!$C$3:$C$60) -> 46050 | F22: 1 | G22: =WORKDAY.INTL(E22,F22,1,Data!$C$3:$C$60) -> 46051 | I22: =WORKDAY.INTL(K19,0,1,Data!$C$3:$C$60) -> 46050 | J22: 1 | K22: =WORKDAY.INTL(I22,J22,1,Data!$C$3:$C$60) -> 46051 | M22: 1 | N22: =_xlfn.LET( _xlpm.s,VALUE($I22), _xlpm.e,VALUE($K22), IF(OR(_xlpm.s="",_xlpm.e=""),"", IF(_xlpm.e<=_xlpm.s, IF(TODAY()>=_xlpm.e,1,0), MAX(0,MIN(1,(TODAY()-_xlpm.s)/(_xlpm.e-_xlpm.s))))) ) -> 1
B23: 3.2 | C23: Inverters Mounted | E23: =WORKDAY.INTL(G22,0,1,Data!$C$3:$C$60) -> 46051 | F23: 1 | G23: =WORKDAY.INTL(E23,F23,1,Data!$C$3:$C$60) -> 46052 | I23: 46063 | J23: 1 | K23: =WORKDAY.INTL(I23,J23,1,Data!$C$3:$C$60) -> 46064 | M23: 1 | N23: =_xlfn.LET( _xlpm.s,VALUE($I23), _xlpm.e,VALUE($K23), IF(OR(_xlpm.s="",_xlpm.e=""),"", IF(_xlpm.e<=_xlpm.s, IF(TODAY()>=_xlpm.e,1,0), MAX(0,MIN(1,(TODAY()-_xlpm.s)/(_xlpm.e-_xlpm.s))))) ) -> 1
B24: 3.3 | C24: Solar DB Lead Time | E24: =WORKDAY.INTL(E14,0,1,Data!$C$3:$C$60)-14 -> 46035 | F24: 25 | G24: =WORKDAY.INTL(E24,F24,1,Data!$C$3:$C$60) -> 46070 | I24: =WORKDAY.INTL(I14,0,1,Data!$C$3:$C$60)-14 -> 46035 | J24: 26 | K24: =WORKDAY.INTL(I24,J24,1,Data!$C$3:$C$60) -> 46071 | M24: 0.8 | N24: =_xlfn.LET( _xlpm.s,VALUE($I24), _xlpm.e,VALUE($K24), IF(OR(_xlpm.s="",_xlpm.e=""),"", IF(_xlpm.e<=_xlpm.s, IF(TODAY()>=_xlpm.e,1,0), MAX(0,MIN(1,(TODAY()-_xlpm.s)/(_xlpm.e-_xlpm.s))))) ) -> 0.94444444
B25: 3.4 | C25: AC Works | E25: =E22 -> 46050 | F25: 15 | G25: =WORKDAY.INTL(E25,F25,1,Data!$C$3:$C$60) -> 46071 | I25: 46065 | J25: 7 | K25: =WORKDAY.INTL(I25,J25,1,Data!$C$3:$C$60) -> 46076 | M25: 0.35 | N25: =_xlfn.LET( _xlpm.s,VALUE($I25), _xlpm.e,VALUE($K25), IF(OR(_xlpm.s="",_xlpm.e=""),"", IF(_xlpm.e<=_xlpm.s, IF(TODAY()>=_xlpm.e,1,0), MAX(0,MIN(1,(TODAY()-_xlpm.s)/(_xlpm.e-_xlpm.s))))) ) -> 0.36363636
B26: 3.5 | C26: AC Tie-In | E26: =WORKDAY.INTL(E25,0,1,Data!$C$3:$C$60) -> 46050 | F26: 1 | G26: =WORKDAY.INTL(E26,F26,1,Data!$C$3:$C$60) -> 46051 | I26: 46074 | J26: 1 | K26: =WORKDAY.INTL(I26,J26,1,Data!$C$3:$C$60) -> 46076 | M26: 0 | N26: =_xlfn.LET( _xlpm.s,VALUE($I26), _xlpm.e,VALUE($K26), IF(OR(_xlpm.s="",_xlpm.e=""),"", IF(_xlpm.e<=_xlpm.s, IF(TODAY()>=_xlpm.e,1,0), MAX(0,MIN(1,(TODAY()-_xlpm.s)/(_xlpm.e-_xlpm.s))))) ) -> 0
B28: 4 | C28: DC Works | E28: =MIN(E30:E34) -> 46049 | F28: =G28-E28 -> 31 | G28: =MAX(G30:G34) -> 46080 | I28: =MIN(I30:I34) -> 46049 | J28: =K28-I28 -> 43 | K28: =MAX(K30:K34) -> 46092 | M28: =(J30*M30+J31*M31+J33*M33)/SUM(J30:J33) -> 0.42857143 | N28: =(J30*N30+J31*N31+J33*N33)/SUM(J30:J33) -> 0.42857143
B30: 4.1 | C30: Mounting Structure delivered | E30: =E19 -> 46049 | F30: 1 | G30: =WORKDAY.INTL(E30,F30,1,Data!$C$3:$C$60) -> 46050 | I30: =I19 -> 46049 | J30: 1 | K30: =WORKDAY.INTL(I30,J30,1,Data!$C$3:$C$60) -> 46050 | M30: 1 | N30: =_xlfn.LET( _xlpm.s,VALUE($I30), _xlpm.e,VALUE($K30), IF(OR(_xlpm.s="",_xlpm.e=""),"", IF(_xlpm.e<=_xlpm.s, IF(TODAY()>=_xlpm.e,1,0), MAX(0,MIN(1,(TODAY()-_xlpm.s)/(_xlpm.e-_xlpm.s))))) ) -> 1
B31: 4.2 | C31: Mounting Structure installation | E31: =WORKDAY.INTL(G30,0,1,Data!$C$3:$C$60) -> 46050 | F31: 3 | G31: =WORKDAY.INTL(E31,F31,1,Data!$C$3:$C$60) -> 46055 | I31: 46062 | J31: 5 | K31: =WORKDAY.INTL(I31,J31,1,Data!$C$3:$C$60) -> 46069 | M31: 1 | N31: =_xlfn.LET( _xlpm.s,VALUE($I31), _xlpm.e,VALUE($K31), IF(OR(_xlpm.s="",_xlpm.e=""),"", IF(_xlpm.e<=_xlpm.s, IF(TODAY()>=_xlpm.e,1,0), MAX(0,MIN(1,(TODAY()-_xlpm.s)/(_xlpm.e-_xlpm.s))))) ) -> 1
B32: 4.3 | C32: DC Cable delivered | E32: 46057 | F32: 1 | G32: =WORKDAY.INTL(E32,F32,1,Data!$C$3:$C$60) -> 46058 | I32: 46051 | J32: 1 | K32: =WORKDAY.INTL(I32,J32,1,Data!$C$3:$C$60) -> 46052 | M32: 1 | N32: =_xlfn.LET( _xlpm.s,VALUE($I32), _xlpm.e,VALUE($K32), IF(OR(_xlpm.s="",_xlpm.e=""),"", IF(_xlpm.e<=_xlpm.s, IF(TODAY()>=_xlpm.e,1,0), MAX(0,MIN(1,(TODAY()-_xlpm.s)/(_xlpm.e-_xlpm.s))))) ) -> 1
B33: 4.4 | C33: DC Stringing | E33: =WORKDAY.INTL(G37,0,1,Data!$C$3:$C$60)-3 -> 46066 | F33: 10 | G33: =WORKDAY.INTL(E33,F33,1,Data!$C$3:$C$60) -> 46080 | I33: =K37 -> 46083 | J33: 7 | K33: =WORKDAY.INTL(I33,J33,1,Data!$C$3:$C$60) -> 46092 | M33: 0 | N33: =_xlfn.LET( _xlpm.s,VALUE($I33), _xlpm.e,VALUE($K33), IF(OR(_xlpm.s="",_xlpm.e=""),"", IF(_xlpm.e<=_xlpm.s, IF(TODAY()>=_xlpm.e,1,0), MAX(0,MIN(1,(TODAY()-_xlpm.s)/(_xlpm.e-_xlpm.s))))) ) -> 0
B35: 5 | C35: Module installation | E35: =MIN(E36:E38) -> 46049 | F35: =G35-E35 -> 20 | G35: =MAX(G36:G38) -> 46069 | I35: =MIN(I36:I38) -> 46049 | J35: =K35-I35 -> 34 | K35: =MAX(K36:K38) -> 46083 | M35: =(J36*M36+J37*M37)/SUM(J36:J37) -> 0.11111111 | N35: =(J36*M36+J37*M37)/SUM(J36:J37) -> 0.11111111
B36: 5.1 | C36: Module delivery | E36: =WORKDAY.INTL(E19,0,1,Data!$C$3:$C$60) -> 46049 | F36: 1 | G36: =WORKDAY.INTL(E36,F36,1,Data!$C$3:$C$60) -> 46050 | I36: =WORKDAY.INTL(I19,0,1,Data!$C$3:$C$60) -> 46049 | J36: 1 | K36: =WORKDAY.INTL(I36,J36,1,Data!$C$3:$C$60) -> 46050 | M36: 1 | N36: =_xlfn.LET( _xlpm.s,VALUE($I36), _xlpm.e,VALUE($K36), IF(OR(_xlpm.s="",_xlpm.e=""),"", IF(_xlpm.e<=_xlpm.s, IF(TODAY()>=_xlpm.e,1,0), MAX(0,MIN(1,(TODAY()-_xlpm.s)/(_xlpm.e-_xlpm.s))))) ) -> 1
B37: 5.2 | C37: Module mounting | E37: =G31 -> 46055 | F37: 10 | G37: =WORKDAY.INTL(E37,F37,1,Data!$C$3:$C$60) -> 46069 | I37: 46071 | J37: 8 | K37: =WORKDAY.INTL(I37,J37,1,Data!$C$3:$C$60) -> 46083 | M37: 0 | N37: =_xlfn.LET( _xlpm.s,VALUE($I37), _xlpm.e,VALUE($K37), IF(OR(_xlpm.s="",_xlpm.e=""),"", IF(_xlpm.e<=_xlpm.s, IF(TODAY()>=_xlpm.e,1,0), MAX(0,MIN(1,(TODAY()-_xlpm.s)/(_xlpm.e-_xlpm.s))))) ) -> 0
B39: 6 | C39: Commissioning | E39: =MIN(E40:E43) -> 46080 | F39: =G39-E39 -> 11 | G39: =MAX(G40:G43) -> 46091 | I39: =MIN(I40:I43) -> 46092 | J39: =K39-I39 -> 9 | K39: =MAX(K40:K43) -> 46101 | M39: =(J40*M40+J41*M41+J42*M42)/SUM(J40:J42) -> 0 | N39: =(K40*N40+K41*N41)/SUM(K40:K41) -> 0
B40: 6.1 | C40: Commissioning | E40: =WORKDAY.INTL(MAX(G21,G28,G35),0,1,Data!$C$3:$C$60) -> 46080 | F40: 1 | G40: =WORKDAY.INTL(E40,F40,1,Data!$C$3:$C$60) -> 46083 | I40: =WORKDAY.INTL(MAX(K21,K28,K35),0,1,Data!$C$3:$C$60) -> 46092 | J40: 1 | K40: =WORKDAY.INTL(I40,J40,1,Data!$C$3:$C$60) -> 46093 | M40: 0 | N40: =_xlfn.LET( _xlpm.s,VALUE($I40), _xlpm.e,VALUE($K40), IF(OR(_xlpm.s="",_xlpm.e=""),"", IF(_xlpm.e<=_xlpm.s, IF(TODAY()>=_xlpm.e,1,0), MAX(0,MIN(1,(TODAY()-_xlpm.s)/(_xlpm.e-_xlpm.s))))) ) -> 0
B41: 6.2 | C41: Practical Completion | E41: =WORKDAY.INTL(G40,0,1,Data!$C$3:$C$60) -> 46083 | F41: 1 | G41: =WORKDAY.INTL(E41,F41,1,Data!$C$3:$C$60) -> 46084 | I41: =WORKDAY.INTL(K40,0,1,Data!$C$3:$C$60) -> 46093 | J41: 1 | K41: =WORKDAY.INTL(I41,J41,1,Data!$C$3:$C$60) -> 46094 | M41: 0 | N41: =_xlfn.LET( _xlpm.s,VALUE($I41), _xlpm.e,VALUE($K41), IF(OR(_xlpm.s="",_xlpm.e=""),"", IF(_xlpm.e<=_xlpm.s, IF(TODAY()>=_xlpm.e,1,0), MAX(0,MIN(1,(TODAY()-_xlpm.s)/(_xlpm.e-_xlpm.s))))) ) -> 0
B42: 6.3 | C42: System Performance Monitoring | E42: =WORKDAY.INTL(G41,0,1,Data!$C$3:$C$60) -> 46084 | F42: 5 | G42: =WORKDAY.INTL(E42,F42,1,Data!$C$3:$C$60) -> 46091 | I42: =WORKDAY.INTL(K41,0,1,Data!$C$3:$C$60) -> 46094 | J42: 5 | K42: =WORKDAY.INTL(I42,J42,1,Data!$C$3:$C$60) -> 46101 | M42: 0 | N42: =_xlfn.LET( _xlpm.s,VALUE($I42), _xlpm.e,VALUE($K42), IF(OR(_xlpm.s="",_xlpm.e=""),"", IF(_xlpm.e<=_xlpm.s, IF(TODAY()>=_xlpm.e,1,0), MAX(0,MIN(1,(TODAY()-_xlpm.s)/(_xlpm.e-_xlpm.s))))) ) -> 0
B44: 7 | C44: QA Inspections | E44: =MIN(E45:E47) -> 46084 | F44: =G44-E44 -> 8 | G44: =MAX(G45:G47) -> 46092 | I44: =MIN(I45:I47) -> 46094 | J44: =K44-I44 -> 6 | K44: =MAX(K45:K47) -> 46100 | M44: =(J45*M45+J46*M46)/SUM(J45:J46) -> 0 | N44: =(K45*N45)/SUM(K45) -> 0
B45: 7.1 | C45: Red-Team Inspection | E45: =WORKDAY.INTL(E42,0,1,Data!$C$3:$C$60) -> 46084 | F45: 3 | G45: =WORKDAY.INTL(E45,F45,1,Data!$C$3:$C$60) -> 46087 | I45: =WORKDAY.INTL(I42,0,1,Data!$C$3:$C$60) -> 46094 | J45: 1 | K45: =WORKDAY.INTL(I45,J45,1,Data!$C$3:$C$60) -> 46097 | M45: 0 | N45: =_xlfn.LET( _xlpm.s,VALUE($I45), _xlpm.e,VALUE($K45), IF(OR(_xlpm.s="",_xlpm.e=""),"", IF(_xlpm.e<=_xlpm.s, IF(TODAY()>=_xlpm.e,1,0), MAX(0,MIN(1,(TODAY()-_xlpm.s)/(_xlpm.e-_xlpm.s))))) ) -> 0
...

Sheet Revenue Tracking
B2: HIGH LEVEL PROJECT REVENUE TRACKING | U2: 2026 Budget Revenue | V2: 2026 Budget COS | W2: 2026 Actual Revenue | X2: 2026 Actual COS
D3: COSTED | F3: ACTUAL | L3: FINANCIAL REVIEW | N3: TIMELINE REVIEW | U3: =SUMIFS('Expenditure Breakdown'!$U:$U, 'Expenditure Breakdown'!$T:$T, ">"&DATE(2025,8,31), 'Expenditure Breakdown'!$T:$T, "<="&DATE(2026,8,31)) -> 2345835.9 | V3: =SUMIFS('Expenditure Breakdown'!$Q:$Q, 'Expenditure Breakdown'!$T:$T, ">"&DATE(2025,8,31), 'Expenditure Breakdown'!$T:$T, "<="&DATE(2026,8,31)) -> 1673413.8 | W3: =SUMIFS('Expenditure Breakdown'!$U:$U, 'Expenditure Breakdown'!$T:$T, ">"&DATE(2025,8,31), 'Expenditure Breakdown'!$T:$T, "<="&DATE(2026,8,31), 'Expenditure Breakdown'!$S:$S, "<>") -> 1677832.4 | X3: =SUMIFS('Expenditure Breakdown'!$Q:$Q, 'Expenditure Breakdown'!$T:$T, ">"&DATE(2025,8,31), 'Expenditure Breakdown'!$T:$T, "<="&DATE(2026,8,31), 'Expenditure Breakdown'!$S:$S, "<>") -> 1126805.1
B4: 1 | C4: Planned Revenue | D4: ='Project Plan'!E6 -> 2345835.9 | F4: =F21 -> 2345835.9 | N4: Start Date
B5: 2 | C5: Planned Expenditure | D5: =+'Expenditure Tracking'!F5 -> 1920067.6 | F5: =+'Expenditure Tracking'!H5 -> 1673413.8 | G5: VO PM LIMIT | H5: CURRENT VO Total
B6: 3 | C6: Planned Profit | D6: =+D4-D5 -> 425768.27 | F6: =+F4-F5 -> 672422.06 | G6: =D6*0.05 -> 21288.414 | H6: 0 | N6: End Date - PC
B7: 4 | C7: Planned Margin | D7: =+D6/D4 -> 0.1814996 | F7: =+F6/F4 -> 0.28664497
B10: CONTRACT
B12: No. | C12: PAYMENT MILESTONE | E12: % | F12: VALUE | H12: PLANNED PAYMENT DATE | L12: INVOICE NUMBER | N12: INVOICE RAISED DATE | P12: PAYMENT RECEIVED DATE | R12: MILESTONE REQUIREMENTS & COMMENTS | S12: MILESTONE DOCUMENTS RECEIVED
B13: 1 | C13: Acceptance and Initial Deposit | E13: 0.5 | F13: =$D$4*E13 -> 1172917.9 | H13: 46022 | L13: 004890 | N13: 45993 | P13: 46009 | S13: FALSE | AP13: ='Change Register'!$Q$14+ 7 -> 7
B14: 2 | C14: Delivery of Panels | E14: 0.25 | F14: =$D$4*E14 -> 586458.97 | H14: ='Project Plan'!G36+7 -> 46057 | L14: 004937 | N14: 46058 | P14: 46066 | S14: FALSE
B15: 3 | C15: Delivery of Inverters | E15: 0.1 | F15: =$D$4*E15 -> 234583.59 | H15: ='Project Plan'!G22+7 -> 46058 | L15: 004937 | N15: 46058 | P15: 46066 | S15: FALSE
B16: 4 | C16: Practical Completion | E16: 0.1 | F16: =$D$4*E16 -> 234583.59 | H16: ='Project Plan'!G39+7 -> 46098 | P16: ='Project Plan'!K39+21 -> 46122 | S16: FALSE
B17: 5 | C17: Handover | E17: 0.05 | F17: =$D$4*E17 -> 117291.79 | H17: ='Project Plan'!G50+7 -> 46106 | P17: ='Project Plan'!K50+21 -> 46128 | S17: FALSE
B18: 6 | C18: - | E18: 0 | F18: =$D$4*E18 -> 0 | S18: FALSE
B19: 7 | C19: - | E19: 0 | F19: =$D$4*E19 -> 0 | S19: FALSE
E21: =SUM(E13:E19) -> 1 | F21: =SUM(F13:F19) -> 2345835.9
B23: KEY: | C23: contains an error (in result or a check has failed)
C24: Red Font - IF TEXT : content not yet confirmed
C25: Red Font - IF NUMBER: Negative value
C26: Anything in yellow is a concern or risk for noting or action
C27: confirmed
C28: [ADD INITIALS: comment for noting in square brackets, use colour or red to draw attention if important]
C29: [RT: When adding rows into sheet, ensure you insert between first and last row of each category]
C30: end of sheet - do not insert information below/beyond this
B40: No. | C40: PAYMENT MILESTONE | E40: % | F40: VALUE
B41: 1 | C41: Deposit - Project commencement | E41: 0.35 | F41: =$F$47*E41 -> 821042.56
B42: 2 | C42: Delivery of Panels | E42: 0.3 | F42: =$F$47*E42 -> 703750.77
B43: 3 | C43: Delivery of Inverters | E43: 0.2 | F43: =$F$47*E43 -> 469167.18
B44: 4 | C44: Practical Completion | E44: 0.1 | F44: =$F$47*E44 -> 234583.59
B45: 5 | C45: Handover | E45: 0.05 | F45: =$F$47*E45 -> 117291.79
C46: Total | E46: =SUM(E41:E45) -> 1 | F46: =SUM(F41:F45) -> 2345835.9
E47: =SUM(E41:E45) -> 1 | F47: =F21 -> 2345835.9

Sheet Expenditure Tracking
B2: HIGH LEVEL PROJECT EXPENDITURE TRACKING
F4: COSTED | H4: ACTUAL | J4: Difference from Costed
B5: EXPENDITURE | F5: =SUM(F9:F23) -> 1920067.6 | H5: =SUM(H9:H23) -> 1673413.8 | J5: =SUM(J9:J23) -> 246653.79
B7: No. | D7: Item | F7: Costed Expenditure | H7: Actual Expenditure | J7: Saving / Overrun | L7: Comments on variations from planned expenditure
B9: ='Expenditure Breakdown'!L6 -> 1 | D9: ='Expenditure Breakdown'!M6 -> 1. Panels | F9: ='Expenditure Breakdown'!I6 -> 597474.8 | H9: ='Expenditure Breakdown'!X6 -> 546560 | J9: =F9-H9 -> 50914.8
B10: ='Expenditure Breakdown'!L13 -> 2 | D10: ='Expenditure Breakdown'!M13 -> 2. Inverters | F10: ='Expenditure Breakdown'!I13 -> 210000 | H10: ='Expenditure Breakdown'!X13 -> 206611.05 | J10: =F10-H10 -> 3388.95
B11: ='Expenditure Breakdown'!L21 -> 3 | D11: ='Expenditure Breakdown'!M21 -> 3. Mounting Structures | F11: ='Expenditure Breakdown'!I21 -> 109312 | H11: ='Expenditure Breakdown'!X21 -> 45028 | J11: =F11-H11 -> 64284
B12: ='Expenditure Breakdown'!L28 -> 4 | D12: ='Expenditure Breakdown'!M28 -> 4. DC Equipment | F12: ='Expenditure Breakdown'!I28 -> 209866.8 | H12: ='Expenditure Breakdown'!X28 -> 218112.78 | J12: =F12-H12 -> -8245.98
B13: ='Expenditure Breakdown'!L44 -> 5 | D13: ='Expenditure Breakdown'!M44 -> 5. Monitoring | F13: ='Expenditure Breakdown'!I44 -> 49000 | H13: ='Expenditure Breakdown'!X44 -> 37582.84 | J13: =F13-H13 -> 11417.16
B14: ='Expenditure Breakdown'!L52 -> 6 | D14: ='Expenditure Breakdown'!M52 -> 6. AC Equipment | F14: ='Expenditure Breakdown'!I52 -> 349524.55 | H14: ='Expenditure Breakdown'!X52 -> 162851.62 | J14: =F14-H14 -> 186672.93
B15: ='Expenditure Breakdown'!L70 -> 7 | D15: ='Expenditure Breakdown'!M70 -> 7.BESS | F15: ='Expenditure Breakdown'!I70 -> 0 | H15: ='Expenditure Breakdown'!X70 -> 0 | J15: =F15-H15 -> 0
B16: ='Expenditure Breakdown'!L79 -> 8 | D16: ='Expenditure Breakdown'!M79 -> 8. Product Add On | F16: ='Expenditure Breakdown'!I79 -> 0 | H16: ='Expenditure Breakdown'!X79 -> 0 | J16: =F16-H16 -> 0
B17: ='Expenditure Breakdown'!L89 -> 9 | D17: ='Expenditure Breakdown'!M89 -> 9. AC & DC installation | F17: ='Expenditure Breakdown'!I89 -> 217280 | H17: ='Expenditure Breakdown'!X89 -> 286650 | J17: =F17-H17 -> -69370
B18: ='Expenditure Breakdown'!L102 -> 10 | D18: ='Expenditure Breakdown'!M102 -> 10. Site Logistics | F18: ='Expenditure Breakdown'!I102 -> 60238.267 | H18: ='Expenditure Breakdown'!X102 -> 51200 | J18: =F18-H18 -> 9038.2667
B19: ='Expenditure Breakdown'!L118 -> 11 | D19: ='Expenditure Breakdown'!M118 -> 11. Due Dilligence | F19: ='Expenditure Breakdown'!I118 -> 89000 | H19: ='Expenditure Breakdown'!X118 -> 84500 | J19: =F19-H19 -> 4500
B20: ='Expenditure Breakdown'!L124 -> 12 | D20: ='Expenditure Breakdown'!M124 -> 12. BDP Commission | F20: ='Expenditure Breakdown'!I124 -> 0 | H20: ='Expenditure Breakdown'!X124 -> 0 | J20: =F20-H20 -> 0
B21: ='Expenditure Breakdown'!L127 -> 13 | D21: ='Expenditure Breakdown'!M128 -> 13. Engineering | F21: ='Expenditure Breakdown'!I127 -> 23646.205 | H21: ='Expenditure Breakdown'!X127 -> 29322.949 | J21: =F21-H21 -> -5676.7435
B22: ='Expenditure Breakdown'!L134 -> 14 | D22: ='Expenditure Breakdown'!M134 -> 14. General Expenses | F22: ='Expenditure Breakdown'!I134 -> 4725 | H22: ='Expenditure Breakdown'!X134 -> 4994.6 | J22: =F22-H22 -> -269.6
B23: ='Expenditure Breakdown'!L147 -> 15 | D23: ='Expenditure Breakdown'!M147 -> 15. Service Add On | F23: ='Expenditure Breakdown'!I147 -> 0 | H23: ='Expenditure Breakdown'!X147 -> 0 | J23: =F23-H23 -> 0
D25: check: | F25: ='Expenditure Breakdown'!I2-'Expenditure Tracking'!F5 -> 0 | G25: =#REF!-G5 -> #REF! | H25: ='Expenditure Breakdown'!X2-H5 -> 0

Sheet Expenditure Breakdown
B2: COSTED EXPENDITURE BREAKDOWN | I2: =SUM(I6:I159) -> 1920067.6 | J2: =SUM(J6:J159) -> 2345835.9 | L2: ACTUAL EXPENDITURE BREAKDOWN | R2: FINANCE ONLY | X2: =SUM(X6:X159) -> 1673413.8
B4: No. | C4: Product / Service | D4: Description of Work | E4: QTY | F4: Rate / Unit | G4: Budget Total | H4: FORECASTED PAYMENT DATE | I4: Total COS | J4: =IF(J2-'Revenue Tracking'!D4>=0, "Total Revenue", "ERROR on REV" ) -> ERROR on REV | L4: No. | M4: Product/ Service | N4: Description of Work | O4: QTY | P4: Rate / Unit | Q4: Actual Total | R4: PO NUMBER | S4: INVOICE NUMBER | T4: INVOICE RAISED DATE | U4: REVENUE RECOGNITION AMOUNT | V4: CHECK | W4: FINANCE PAYMENT DATE | X4: Total COS
B6: 1 | C6: Panels | D6: Panels Budget | G6: =D160 -> 597474.8 | H6: ='Project Plan'!E36+60 -> 46109 | I6: =SUM(G6:G11) -> 597474.8 | J6: =F160 -> 746843.5 | L6: 1 | M6: 1. Panels | N6: Panel Size -- 610W a | O6: 448 | P6: 1220 | Q6: =O6*P6 -> 546560 | S6: MSA Energy INV0003560 | T6: 46053 | U6: 746843.5 | V6: =J6-SUM(U6:U11) -> 0 | W6: 46107 | X6: =SUM(Q6:Q11) -> 546560
B7: 1 | D7: Delivery Budget | L7: 1 | M7: 1. Panels | T7: =IF(W7>1,EOMONTH(W7,0),"") | U7: 0
B8: 1 | L8: 1 | M8: 1. Panels | T8: =IF(W8>1,EOMONTH(W8,0),"") | U8: 0
B9: 1 | L9: 1 | M9: 1. Panels | T9: =IF(W9>1,EOMONTH(W9,0),"") | U9: 0
B10: 1 | L10: 1 | M10: 1. Panels | T10: =IF(W10>1,EOMONTH(W10,0),"") | U10: 0
B11: 1 | L11: 1 | M11: 1. Panels | T11: =IF(W11>1,EOMONTH(W11,0),"") | U11: 0 | Y11: BUDGET | Z11: Installer Allocation
T12: =IF(W12>1,EOMONTH(W12,0),"") | Y12: AC Equipment | Z12: =G52 -> 349524.55 | AA12: Includes the PVDB price, see price below in actual excluding DB price. This is what the contractor can quote us for.
B13: 2 | C13: Inverters | D13: Inverter Budget | G13: =D161 -> 210000 | H13: ='Project Plan'!E22+60 -> 46110 | I13: =SUM(G13:G19) -> 210000 | J13: =F161 -> 262500 | L13: 2 | M13: 2. Inverters | U13: 0 | V13: =J13-SUM(U13:U19) -> 0 | X13: =SUM(Q13:Q19) -> 206611.05 | Y13: DC Equipment | Z13: =G29 -> 130066.8
B14: 2 | L14: 2 | M14: 2. Inverters | N14: Huawei 100KTL | O14: 3 | P14: 68870.35 | Q14: =O14*P14 -> 206611.05 | S14: MSA Energy INV0003560 | T14: =T6 -> 46053 | U14: 262500 | W14: =W6 -> 46107 | Y14: AC Labour | Z14: =G89 -> 68320
B15: 2 | L15: 2 | M15: 2. Inverters | T15: =IF(W15>1,EOMONTH(W15,0),"") | U15: 0 | Y15: DC Labour | Z15: =G90 -> 148960
B16: 2 | L16: 2 | M16: 2. Inverters | T16: =IF(W16>1,EOMONTH(W16,0),"") | U16: 0 | Y16: Offloading | Z16: =G102 -> 8500
B17: 2 | L17: 2 | M17: 2. Inverters | T17: =IF(W17>1,EOMONTH(W17,0),"") | U17: 0 | Y17: Scaffolding | Z17: =G103 -> 18228.267
B18: 2 | L18: 2 | M18: 2. Inverters | T18: =IF(W18>1,EOMONTH(W18,0),"") | U18: 0 | Y18: Storage | Z18: =G105 -> 1110
B19: 2 | L19: 2 | M19: 2. Inverters | T19: =IF(W19>1,EOMONTH(W19,0),"") | U19: 0 | Y19: Telehandler | Z19: 0
T20: =IF(W20>1,EOMONTH(W20,0),"") | Y20: Trenching | Z20: 0
B21: 3 | C21: Mounting Structures | D21: Structure Budget | G21: =D162 -> 109312 | H21: ='Project Plan'!E30+30 -> 46079 | I21: =SUM(G21:G26) -> 109312 | J21: =F162 -> 136640 | L21: 3 | M21: 3. Mounting Structures | N21: Schletter Structure | Q21: 45028 | R21: PO4564-TPS-20260121 - RV Approved | S21: Schletter Inv: INV002586 | T21: 46053 | U21: 136640 | V21: =J21-SUM(U21:U26) -> 0 | W21: 46080 | X21: =SUM(Q21:Q26) -> 45028 | Y21: Other | Z21: 0
B22: 3 | L22: 3 | M22: 3. Mounting Structures | T22: =IF(W22>1,EOMONTH(W22,0),"") | U22: 0 | Y22: Total | Z22: =SUM(Z12:Z21) -> 724709.62
B23: 3 | L23: 3 | M23: 3. Mounting Structures | T23: =IF(W23>1,EOMONTH(W23,0),"") | U23: 0 | Y23: Less 15% | Z23: =+Z22*0.85 -> 616003.18
B24: 3 | L24: 3 | M24: 3. Mounting Structures | T24: =IF(W24>1,EOMONTH(W24,0),"") | U24: 0 | Y24: R/Wp | Z24: =Z23/'Project Plan'!$E$3/1000 -> 2.2564219
B25: 3 | L25: 3 | M25: 3. Mounting Structures | T25: =IF(W25>1,EOMONTH(W25,0),"") | U25: 0
B26: 3 | L26: 3 | M26: 3. Mounting Structures | T26: =IF(W26>1,EOMONTH(W26,0),"") | U26: 0 | Y26: ACTUAL | Z26: Installer Price Cosmic Sun
T27: =IF(W27>1,EOMONTH(W27,0),"") | Y27: =Y12 -> AC Equipment | Z27: 79500
B28: 4 | C28: DC Equipment | D28: DC Cable Budget | E28: 5700 | G28: 79800 | H28: ='Project Plan'!E32+60 -> 46117 | I28: =SUM(G28:G42) -> 209866.8 | J28: =F163 -> 262333.5 | L28: 4 | M28: 4. DC Equipment | N28: DC Cable | O28: 6000 | P28: 13.99 | Q28: =O28*P28 -> 83940 | S28: MSA Energy INV0003560 | T28: 46053 | U28: 100958.2 | V28: =J28-SUM(U28:U42) -> 0 | W28: =W6 -> 46107 | X28: =SUM(Q28:Q42) -> 218112.78 | Y28: =Y13 -> DC Equipment | Z28: 134172.78
B29: 4 | D29: DC Equipment Budget | G29: =D163-G28 -> 130066.8 | H29: ='Project Plan'!G28 -> 46080 | L29: 4 | M29: 4. DC Equipment | T29: =IF(W29>1,EOMONTH(W29,0),"") | U29: =(Q29/$X$28*$J$28) -> 0 | Y29: =Y14 -> AC Labour | Z29: 90090
B30: 4 | L30: 4 | M30: 4. DC Equipment | T30: =IF(W30>1,EOMONTH(W30,0),"") | U30: =(Q30/$X$28*$J$28) -> 0 | Y30: =Y15 -> DC Labour | Z30: 196560
B31: 4 | L31: 4 | M31: 4. DC Equipment | T31: =IF(W31>1,EOMONTH(W31,0),"") | U31: =(Q31/$X$28*$J$28) -> 0 | Y31: Offloading | Z31: 2750
B32: 4 | L32: 4 | M32: 4. DC Equipment | N32: Project Kick Off | O32: =Z28 -> 134172.78 | P32: 0.1 | Q32: =$O$32*P32 -> 13417.278 | S32: Cosmic Sun - CS_TPS_001 | T32: =T90 -> 46053 | U32: 16137.53 | W32: 46051 | Y32: Roof Access (Geda Lift) | Z32: 11550
B33: 4 | L33: 4 | M33: 4. DC Equipment | N33: Site Establishment | P33: 0.15 | Q33: =$O$32*P33 -> 20125.917 | S33: Cosmic Sun - CS_TPS_002 | T33: 46053 | U33: 24206.295 | W33: =W91 -> 46058 | Y33: HSE | Z33: 4500
B34: 4 | L34: 4 | M34: 4. DC Equipment | N34: AC Installation Complete | P34: 0.2 | Q34: =$O$32*P34 -> 26834.556 | T34: =T92 -> 46112 | U34: =(Q34/$X$28*$J$28) -> 32275.06 | W34: =W92 -> 46083 | Y34: Logistics | Z34: 0
B35: 4 | L35: 4 | M35: 4. DC Equipment | N35: DC Installation Complete | P35: 0.25 | Q35: =$O$32*P35 -> 33543.195 | T35: =T93 -> 46112 | U35: =(Q35/$X$28*$J$28) -> 40343.825 | W35: =W93 -> 46099 | Y35: Trenching | Z35: 0
B36: 4 | L36: 4 | M36: 4. DC Equipment | N36: Commissioning Complete | P36: 0.1 | Q36: =$O$32*P36 -> 13417.278 | T36: =T94 -> 46112 | U36: =(Q36/$X$28*$J$28) -> 16137.53 | W36: =W94 -> 46108 | Y36: Other | Z36: 0
B37: 4 | L37: 4 | M37: 4. DC Equipment | N37: Site De-establisment | P37: 0.1 | Q37: =$O$32*P37 -> 13417.278 | T37: =T95 -> 46112 | U37: =(Q37/$X$28*$J$28) -> 16137.53 | W37: =W95 -> 46107 | Y37: Other | Z37: 0
B38: 4 | L38: 4 | M38: 4. DC Equipment | N38: Handover Document Complete | P38: 0.05 | Q38: =$O$32*P38 -> 6708.639 | T38: =T96 -> 46112 | U38: =(Q38/$X$28*$J$28) -> 8068.7649 | W38: =W96 -> 46107 | Y38: Total | Z38: =SUM(Z27:Z37) -> 519122.78
B39: 4 | L39: 4 | M39: 4. DC Equipment | N39: End of Defects Period | P39: 0.05 | Q39: =$O$32*P39 -> 6708.639 | T39: =T97 -> 46142 | U39: =(Q39/$X$28*$J$28) -> 8068.7649 | W39: =W97 -> 46130 | Y39: R/Wp | Z39: =Z38/'Project Plan'!$E$3/1000 -> 1.9015486
B40: 4 | L40: 4 | M40: 4. DC Equipment | T40: =IF(W40>1,EOMONTH(W40,0),"") | U40: =(Q40/$X$28*$J$28) -> 0
B41: 4 | L41: 4 | M41: 4. DC Equipment | T41: =IF(W41>1,EOMONTH(W41,0),"") | U41: =(Q41/$X$28*$J$28) -> 0
B42: 4 | L42: 4 | M42: 4. DC Equipment | T42: =IF(W42>1,EOMONTH(W42,0),"") | U42: =(Q42/$X$28*$J$28) -> 0
T43: =IF(W43>1,EOMONTH(W43,0),"")
...

Sheet Cashflow
D1: [RT: Double Check the first date is always a MONDAY] | F1: 45964 | G1: =F1+7 -> 45971 | H1: =G1+7 -> 45978 | I1: =H1+7 -> 45985 | J1: =I1+7 -> 45992 | K1: =J1+7 -> 45999 | L1: =K1+7 -> 46006 | M1: =L1+7 -> 46013 | N1: =M1+7 -> 46020 | ... KE1: =KD1+7 -> 47959
A2: PLANNED | C2: CHECK | D2: CHECK
B3: Planned Revenue | C3: ='Revenue Tracking'!D4 -> 2345835.9 | D3: =SUM(F3:KE3) -> 2345835.9 | F3: =SUMIFS('Revenue Tracking'!$F$13:$F$19, 'Revenue Tracking'!$H$13:$H$19, ">="&F1,'Revenue Tracking'!$H$13:$H$19, "<"&G1) -> 0 | G3: =SUMIFS('Revenue Tracking'!$F$13:$F$19, 'Revenue Tracking'!$H$13:$H$19, ">="&G1,'Revenue Tracking'!$H$13:$H$19, "<"&H1) -> 0 | H3: =SUMIFS('Revenue Tracking'!$F$13:$F$19, 'Revenue Tracking'!$H$13:$H$19, ">="&H1,'Revenue Tracking'!$H$13:$H$19, "<"&I1) -> 0 | I3: =SUMIFS('Revenue Tracking'!$F$13:$F$19, 'Revenue Tracking'!$H$13:$H$19, ">="&I1,'Revenue Tracking'!$H$13:$H$19, "<"&J1) -> 0 | J3: =SUMIFS('Revenue Tracking'!$F$13:$F$19, 'Revenue Tracking'!$H$13:$H$19, ">="&J1,'Revenue Tracking'!$H$13:$H$19, "<"&K1) -> 0 | K3: =SUMIFS('Revenue Tracking'!$F$13:$F$19, 'Revenue Tracking'!$H$13:$H$19, ">="&K1,'Revenue Tracking'!$H$13:$H$19, "<"&L1) -> 0 | L3: =SUMIFS('Revenue Tracking'!$F$13:$F$19, 'Revenue Tracking'!$H$13:$H$19, ">="&L1,'Revenue Tracking'!$H$13:$H$19, "<"&M1) -> 0 | M3: =SUMIFS('Revenue Tracking'!$F$13:$F$19, 'Revenue Tracking'!$H$13:$H$19, ">="&M1,'Revenue Tracking'!$H$13:$H$19, "<"&N1) -> 0 | ... KD3: =SUMIFS('Revenue Tracking'!$F$13:$F$19, 'Revenue Tracking'!$H$13:$H$19, ">="&KD1,'Revenue Tracking'!$H$13:$H$19, "<"&KE1) -> 0 | KE3: =SUMIFS('Revenue Tracking'!$F$13:$F$19, 'Revenue Tracking'!$H$13:$H$19, ">="&KE1,'Revenue Tracking'!$H$13:$H$19, "<"&#REF!) -> 0
B4: Planned Revenue - Cumulative | F4: =F3 -> 0 | G4: =F4+G3 -> 0 | H4: =G4+H3 -> 0 | I4: =H4+I3 -> 0 | J4: =I4+J3 -> 0 | K4: =J4+K3 -> 0 | L4: =K4+L3 -> 0 | M4: =L4+M3 -> 0 | N4: =M4+N3 -> 1172917.9 | ... KE4: =KD4+KE3 -> 2345835.9
B5: Planned Expenditure | C5: ='Revenue Tracking'!D5 -> 1920067.6 | D5: =SUM(F5:KE5) -> 1920067.6 | F5: =SUMIFS('Expenditure Breakdown'!$G$6:$G$166, 'Expenditure Breakdown'!$H$6:$H$166, ">="&F1,'Expenditure Breakdown'!$H$6:$H$166, "<"&G1) -> 0 | G5: =SUMIFS('Expenditure Breakdown'!$G$6:$G$166, 'Expenditure Breakdown'!$H$6:$H$166, ">="&G1,'Expenditure Breakdown'!$H$6:$H$166, "<"&H1) -> 0 | H5: =SUMIFS('Expenditure Breakdown'!$G$6:$G$166, 'Expenditure Breakdown'!$H$6:$H$166, ">="&H1,'Expenditure Breakdown'!$H$6:$H$166, "<"&I1) -> 0 | I5: =SUMIFS('Expenditure Breakdown'!$G$6:$G$166, 'Expenditure Breakdown'!$H$6:$H$166, ">="&I1,'Expenditure Breakdown'!$H$6:$H$166, "<"&J1) -> 0 | J5: =SUMIFS('Expenditure Breakdown'!$G$6:$G$166, 'Expenditure Breakdown'!$H$6:$H$166, ">="&J1,'Expenditure Breakdown'!$H$6:$H$166, "<"&K1) -> 0 | K5: =SUMIFS('Expenditure Breakdown'!$G$6:$G$166, 'Expenditure Breakdown'!$H$6:$H$166, ">="&K1,'Expenditure Breakdown'!$H$6:$H$166, "<"&L1) -> 0 | L5: =SUMIFS('Expenditure Breakdown'!$G$6:$G$166, 'Expenditure Breakdown'!$H$6:$H$166, ">="&L1,'Expenditure Breakdown'!$H$6:$H$166, "<"&M1) -> 0 | M5: =SUMIFS('Expenditure Breakdown'!$G$6:$G$166, 'Expenditure Breakdown'!$H$6:$H$166, ">="&M1,'Expenditure Breakdown'!$H$6:$H$166, "<"&N1) -> 0 | ... KD5: =SUMIFS('Expenditure Breakdown'!$G$6:$G$166, 'Expenditure Breakdown'!$H$6:$H$166, ">="&KD1,'Expenditure Breakdown'!$H$6:$H$166, "<"&KE1) -> 0 | KE5: =SUMIFS('Expenditure Breakdown'!$G$6:$G$166, 'Expenditure Breakdown'!$H$6:$H$166, ">="&KE1,'Expenditure Breakdown'!$H$6:$H$166, "<"&#REF!) -> 0
B6: Planned Expenditure - Cumulative | F6: =F5 -> 0 | G6: =F6+G5 -> 0 | H6: =G6+H5 -> 0 | I6: =H6+I5 -> 0 | J6: =I6+J5 -> 0 | K6: =J6+K5 -> 0 | L6: =K6+L5 -> 0 | M6: =L6+M5 -> 0 | N6: =M6+N5 -> 0 | ... KE6: =KD6+KE5 -> 1920067.6
B7: PLANNED CashFlow | F7: =F4-F6 -> 0 | G7: =G4-G6 -> 0 | H7: =H4-H6 -> 0 | I7: =I4-I6 -> 0 | J7: =J4-J6 -> 0 | K7: =K4-K6 -> 0 | L7: =L4-L6 -> 0 | M7: =M4-M6 -> 0 | ... KE7: =KE4-KE6 -> 425768.27
A8: ACTUAL | C8: CHECK | D8: CHECK
B9: Actual + Planned Revenue | C9: ='Revenue Tracking'!F4 -> 2345835.9 | D9: =SUM(F9:KE9) -> 2345835.9 | F9: =SUMIFS('Revenue Tracking'!$F$13:$F$19, 'Revenue Tracking'!$P$13:$P$19, ">="&F1,'Revenue Tracking'!$P$13:$P$19, "<"&G1) -> 0 | G9: =SUMIFS('Revenue Tracking'!$F$13:$F$19, 'Revenue Tracking'!$P$13:$P$19, ">="&G1,'Revenue Tracking'!$P$13:$P$19, "<"&H1) -> 0 | H9: =SUMIFS('Revenue Tracking'!$F$13:$F$19, 'Revenue Tracking'!$P$13:$P$19, ">="&H1,'Revenue Tracking'!$P$13:$P$19, "<"&I1) -> 0 | I9: =SUMIFS('Revenue Tracking'!$F$13:$F$19, 'Revenue Tracking'!$P$13:$P$19, ">="&I1,'Revenue Tracking'!$P$13:$P$19, "<"&J1) -> 0 | J9: =SUMIFS('Revenue Tracking'!$F$13:$F$19, 'Revenue Tracking'!$P$13:$P$19, ">="&J1,'Revenue Tracking'!$P$13:$P$19, "<"&K1) -> 0 | K9: =SUMIFS('Revenue Tracking'!$F$13:$F$19, 'Revenue Tracking'!$P$13:$P$19, ">="&K1,'Revenue Tracking'!$P$13:$P$19, "<"&L1) -> 0 | L9: =SUMIFS('Revenue Tracking'!$F$13:$F$19, 'Revenue Tracking'!$P$13:$P$19, ">="&L1,'Revenue Tracking'!$P$13:$P$19, "<"&M1) -> 1172917.9 | M9: =SUMIFS('Revenue Tracking'!$F$13:$F$19, 'Revenue Tracking'!$P$13:$P$19, ">="&M1,'Revenue Tracking'!$P$13:$P$19, "<"&N1) -> 0 | ... KD9: =SUMIFS('Revenue Tracking'!$F$13:$F$19, 'Revenue Tracking'!$P$13:$P$19, ">="&KD1,'Revenue Tracking'!$P$13:$P$19, "<"&KE1) -> 0 | KE9: =SUMIFS('Revenue Tracking'!$F$13:$F$19, 'Revenue Tracking'!$P$13:$P$19, ">="&KE1,'Revenue Tracking'!$P$13:$P$19, "<"&#REF!) -> 0
B10: Actual + Planned Revenue - Cumulative | F10: =F9 -> 0 | G10: =F10+G9 -> 0 | H10: =G10+H9 -> 0 | I10: =H10+I9 -> 0 | J10: =I10+J9 -> 0 | K10: =J10+K9 -> 0 | L10: =K10+L9 -> 1172917.9 | M10: =L10+M9 -> 1172917.9 | N10: =M10+N9 -> 1172917.9 | ... KE10: =KD10+KE9 -> 2345835.9
B11: Actual + Planned Expenditure | C11: ='Revenue Tracking'!F5 -> 1673413.8 | D11: =SUM(F11:KE11) -> 1665913.8 | F11: =SUMIFS('Expenditure Breakdown'!$Q$6:$Q$166, 'Expenditure Breakdown'!$W$6:$W$166, ">="&F1,'Expenditure Breakdown'!$W$6:$W$166, "<"&G1) -> 0 | G11: =SUMIFS('Expenditure Breakdown'!$Q$6:$Q$166, 'Expenditure Breakdown'!$W$6:$W$166, ">="&G1,'Expenditure Breakdown'!$W$6:$W$166, "<"&H1) -> 0 | H11: =SUMIFS('Expenditure Breakdown'!$Q$6:$Q$166, 'Expenditure Breakdown'!$W$6:$W$166, ">="&H1,'Expenditure Breakdown'!$W$6:$W$166, "<"&I1) -> 0 | I11: =SUMIFS('Expenditure Breakdown'!$Q$6:$Q$166, 'Expenditure Breakdown'!$W$6:$W$166, ">="&I1,'Expenditure Breakdown'!$W$6:$W$166, "<"&J1) -> 0 | J11: =SUMIFS('Expenditure Breakdown'!$Q$6:$Q$166, 'Expenditure Breakdown'!$W$6:$W$166, ">="&J1,'Expenditure Breakdown'!$W$6:$W$166, "<"&K1) -> 0 | K11: =SUMIFS('Expenditure Breakdown'!$Q$6:$Q$166, 'Expenditure Breakdown'!$W$6:$W$166, ">="&K1,'Expenditure Breakdown'!$W$6:$W$166, "<"&L1) -> 0 | L11: =SUMIFS('Expenditure Breakdown'!$Q$6:$Q$166, 'Expenditure Breakdown'!$W$6:$W$166, ">="&L1,'Expenditure Breakdown'!$W$6:$W$166, "<"&M1) -> 0 | M11: =SUMIFS('Expenditure Breakdown'!$Q$6:$Q$166, 'Expenditure Breakdown'!$W$6:$W$166, ">="&M1,'Expenditure Breakdown'!$W$6:$W$166, "<"&N1) -> 0 | ... KD11: =SUMIFS('Expenditure Breakdown'!$Q$6:$Q$166, 'Expenditure Breakdown'!$W$6:$W$166, ">="&KD1,'Expenditure Breakdown'!$W$6:$W$166, "<"&KE1) -> 0 | KE11: =SUMIFS('Expenditure Breakdown'!$Q$6:$Q$166, 'Expenditure Breakdown'!$W$6:$W$166, ">="&KE1,'Expenditure Breakdown'!$W$6:$W$166, "<"&#REF!) -> 0
B12: Actual + Planned Expenditure - Cumulative | F12: =F11 -> 0 | G12: =F12+G11 -> 0 | H12: =G12+H11 -> 0 | I12: =H12+I11 -> 0 | J12: =I12+J11 -> 0 | K12: =J12+K11 -> 0 | L12: =K12+L11 -> 0 | M12: =L12+M11 -> 0 | N12: =M12+N11 -> 0 | ... KE12: =KD12+KE11 -> 1665913.8
B14: ACTUAL CashFlow | F14: =F10-F12 -> 0 | G14: =G10-G12 -> 0 | H14: =H10-H12 -> 0 | I14: =I10-I12 -> 0 | J14: =J10-J12 -> 0 | K14: =K10-K12 -> 0 | L14: =L10-L12 -> 1172917.9 | M14: =M10-M12 -> 1172917.9 | ... KE14: =KE10-KE12 -> 679922.06
C16: CHECK | D16: CHECK
B17: Revenue Recognition | C17: =C3-D17 -> 0.00064656464 | D17: =SUM(F17:KE17) -> 2345835.9 | F17: =SUMIFS('Expenditure Breakdown'!$U$6:$U$166, 'Expenditure Breakdown'!$T$6:$T$166, ">="&F1,'Expenditure Breakdown'!$T$6:$T$166, "<"&G1) -> 0 | G17: =SUMIFS('Expenditure Breakdown'!$U$6:$U$166, 'Expenditure Breakdown'!$T$6:$T$166, ">="&G1,'Expenditure Breakdown'!$T$6:$T$166, "<"&H1) -> 0 | H17: =SUMIFS('Expenditure Breakdown'!$U$6:$U$166, 'Expenditure Breakdown'!$T$6:$T$166, ">="&H1,'Expenditure Breakdown'!$T$6:$T$166, "<"&I1) -> 0 | I17: =SUMIFS('Expenditure Breakdown'!$U$6:$U$166, 'Expenditure Breakdown'!$T$6:$T$166, ">="&I1,'Expenditure Breakdown'!$T$6:$T$166, "<"&J1) -> 0 | J17: =SUMIFS('Expenditure Breakdown'!$U$6:$U$166, 'Expenditure Breakdown'!$T$6:$T$166, ">="&J1,'Expenditure Breakdown'!$T$6:$T$166, "<"&K1) -> 0 | K17: =SUMIFS('Expenditure Breakdown'!$U$6:$U$166, 'Expenditure Breakdown'!$T$6:$T$166, ">="&K1,'Expenditure Breakdown'!$T$6:$T$166, "<"&L1) -> 0 | L17: =SUMIFS('Expenditure Breakdown'!$U$6:$U$166, 'Expenditure Breakdown'!$T$6:$T$166, ">="&L1,'Expenditure Breakdown'!$T$6:$T$166, "<"&M1) -> 0 | M17: =SUMIFS('Expenditure Breakdown'!$U$6:$U$166, 'Expenditure Breakdown'!$T$6:$T$166, ">="&M1,'Expenditure Breakdown'!$T$6:$T$166, "<"&N1) -> 0 | ... KD17: =SUMIFS('Expenditure Breakdown'!$U$6:$U$166, 'Expenditure Breakdown'!$T$6:$T$166, ">="&KD1,'Expenditure Breakdown'!$T$6:$T$166, "<"&KE1) -> 0 | KE17: =SUMIFS('Expenditure Breakdown'!$U$6:$U$166, 'Expenditure Breakdown'!$T$6:$T$166, ">="&KE1,'Expenditure Breakdown'!$T$6:$T$166, "<"&#REF!) -> 0
B18: Revenue Recognition Cumulative | C18: =D17-D18 -> 0 | D18: =MAX(F18:KE18) -> 2345835.9 | F18: =F17 -> 0 | G18: =F18+G17 -> 0 | H18: =G18+H17 -> 0 | I18: =H18+I17 -> 0 | J18: =I18+J17 -> 0 | K18: =J18+K17 -> 0 | L18: =K18+L17 -> 0 | M18: =L18+M17 -> 0 | N18: =M18+N17 -> 9231.2696 | ... KE18: =KD18+KE17 -> 2345835.9

Sheet Finance - Revenue
A3: Sum of REVENUE RECOGNITION AMOUNT | B3: Column Labels
A4: Row Labels | B4: (blank) | C4: 46022 | E4: 46053 | F4: 46081 | G4: 46112 | H4: 46142 | I4: Grand Total
A5: (blank)
A6: 1. Panels | D6: 0 | E6: 746843.5 | I6: 746843.5
A7: 2. Inverters | B7: 0 | D7: 0 | E7: 262500 | I7: 262500
A8: 3. Mounting Structures | D8: 0 | E8: 136640 | I8: 136640
A9: 4. DC Equipment | D9: 0 | E9: 141302.03 | G9: 88756.414 | H9: 32275.06 | I9: 262333.5
A10: 5. Monitoring | D10: 0 | E10: 36804.003 | F10: 24445.997 | I10: 61250
A11: 6. AC Equipment | D11: 0 | E11: 53321.549 | F11: 223619.5 | G11: 117307.41 | H11: 42657.239 | I11: 436905.69
A12: 8. Product Add On | B12: 0 | I12: 0
A13: 9. AC & DC installation | D13: 0 | E13: 60355.556 | G13: 132782.22 | H13: 48284.444 | I13: 241422.22
A14: 10. Site Logistics | D14: 0 | E14: 6144.094 | G14: 55872.038 | H14: 4915.2752 | I14: 66931.407
A15: 11. Due Dilligence | C15: 8777.1203 | D15: 0 | G15: 7021.6963 | H15: 83090.072 | I15: 98888.889
A16: 13. Engineering | D16: 0 | G16: 26870.688 | I16: 26870.688
A17: 14. General Expenses | C17: 454.1493 | D17: 0 | E17: 1070.8896 | F17: 1241.6535 | G17: 1241.6535 | H17: 1241.6535 | I17: 5249.9994
A18: 15. Service Add On
A19: 12. BDP Commission
A20: 7.BESS
A21: Grand Total | B21: 0 | C21: 9231.2696 | D21: 0 | E21: 1444981.6 | F21: 249307.15 | G21: 429852.12 | H21: 212463.74 | I21: 2345835.9

Sheet Finance - COS
A3: Sum of Actual Total | B3: Column Labels
A4: Row Labels | B4: (blank) | C4: 46022 | E4: 46053 | F4: 46081 | G4: 46112 | H4: 46142 | I4: Grand Total
A5: (blank)
A6: 1. Panels | E6: 546560 | I6: 546560
A7: 2. Inverters | E7: 206611.05 | I7: 206611.05
A8: 3. Mounting Structures | E8: 45028 | I8: 45028
A9: 4. DC Equipment | E9: 117483.2 | G9: 73795.029 | H9: 26834.556 | I9: 218112.78
A10: 5. Monitoring | E10: 22582.84 | F10: 15000 | I10: 37582.84
A11: 6. AC Equipment | E11: 19875 | F11: 83351.62 | G11: 43725 | H11: 15900 | I11: 162851.62
A12: 8. Product Add On
A13: 9. AC & DC installation | E13: 71662.5 | G13: 157657.5 | H13: 57330 | I13: 286650
A14: 10. Site Logistics | E14: 4700 | G14: 42740 | H14: 3760 | I14: 51200
A15: 11. Due Dilligence | C15: 7500 | G15: 6000 | H15: 71000 | I15: 84500
A16: 13. Engineering | G16: 29322.949 | I16: 29322.949
A17: 14. General Expenses | C17: 447.44 | E17: 1003.41 | F17: 1181.25 | G17: 1181.25 | H17: 1181.25 | I17: 4994.6
A18: 15. Service Add On
A19: 12. BDP Commission | D19: 0 | I19: 0
A20: 7.BESS
A21: Grand Total | C21: 7947.44 | D21: 0 | E21: 1035506 | F21: 99532.87 | G21: 354421.73 | H21: 176005.81 | I21: 1673413.8

Sheet Data
C2: Public holidays | F2: Drop down list
C3: 45658 | D3: New Years Day | F3: Approved
C4: 45737 | D4: Human Rights day | F4: Pending
C5: 45765 | D5: Good Friday | F5: Declined
C6: 45768 | D6: Family Day | F6: Abanded
C7: 45774 | D7: Freedom Day
C8: 45765 | D8: Freedom DayObserved
C9: 45778 | D9: Workers day
C10: 45824 | D10: Youth Day Holiday
C11: 45878 | D11: Womens Day
C12: 45924 | D12: Heritage Day
C13: 46007 | D13: Day of Reconciliation | H13: Manual dates
C14: 46016 | D14: Christmas Day
C15: 46017 | D15: Day of Goodwill
C16: 46006 | D16: Builders Break
C17: 46007 | D17: Builders Break
C18: 46008 | D18: Builders Break
C19: 46009 | D19: Builders Break
C20: 46010 | D20: Builders Break
C21: 46011 | D21: Builders Break
C22: 46012 | D22: Builders Break
C23: 46013 | D23: Builders Break
C24: 46014 | D24: Builders Break
C25: 46015 | D25: Builders Break
... C40: 46030 | D40: Builders Break
D41: Builders Break
D42: Builders Break
D43: Builders Break
D44: Builders Break
D45: Builders Break
D46: Builders Break
D47: Builders Break
D48: Builders Break
C49: 46102 | D49: Human Rights day
C50: 46115 | D50: Good Friday
C51: 46118 | D51: Family Day
C52: 46139 | D52: Freedom Day
C53: 46143 | D53: Workers day
C54: 46189 | D54: Youth Day Holiday
C55: 46243 | D55: Womens Day
...
