Workbook
Name Inverter_Capacity: #REF!
Name Inverter_Supplier: #REF!
Name Project_Size: 'Finance - Revenue'!Projectsize
Name Project_Size: Projectsize
Name Projectsize: #REF!
Name Projectsize: #REF!
Name Security_Serv: #REF!
Name Security_Serv: #REF!
Name SSS: #REF!
Name SSS: #REF!
Name USD_ZAR: #REF!

Sheet Certificate - Financial Close
B2: Emergent Energy – Financial Close Completion Certificate | H2: FINANCIAL CLOSE CERTIFICATE
B4: Project Name: | C4: ='Project Plan'!E2 -> De Drift
B5: COO: | C5: Johannes Potgieter
B6: Programme Manager: | C6: Roedolph Venter
B7: HoPD: | C7: Natasha Watkins-Baker
B9: Date of Phase Completion:
B10: Phase Deliverables Checklist: (Y/N)
B11: Product Agreement
B12: EPC Agreement
B13: O&M Agreeement
B14: Cost Proposal
B15: Deposit Received
B16: Risks / Notes
B18: Acknowledgement and Acceptance:
B19: Role | C19: Name | D19: Signature | E19: Date

Sheet Certificate - Planning
B2: Emergent Energy – Planning Phase Completion Certificate | H2: PLANNING CERTIFICATE
B4: Project Name: | C4: ='Project Plan'!E2 -> De Drift
B5: Client Representative:
B6: Programme Manager: | C6: Roedolph Venter
B7: Project Manager: | C7: ='Project Plan'!E5 -> Justin Franke
B8: Project Engineer:
B10: Date of Phase Completion:
B11: Phase Deliverables Checklist: (Y/N)
B12: Project Introduction Presentation
B13: Project Brief
B14: Engineering Pack
B15: BOQ
B16: PO – Material & Equipment
B17: PO - Contractors
B18: HSE – NOC
B19: HSE – EE File
B20: HSE – Contractor File
... B24: Acknowledgement and Acceptance:
B25: Role | C25: Name | D25: Signature | E25: Date

Sheet Change Register
F1: Change Register
B3: ID | C3: Description | D3: Supporting Image (If Applicable) | E3: Impact | F3: Proposed Date | G3: Proposed By | H3: Status | I3: Approved By | J3: Approved Date | K3: Results / Comments
B4: DEC001
B5: DEC002
B6: DEC003
B7: DEC004
B8: DEC005
B9: DEC006
B10: DEC007
B11: DEC008
B12: DEC009
B13: DEC010
B14: DEC011
B15: DEC012
... B33: DEC030

Sheet BOQ
B2: Item | C2: Supplier | D2: Description | E2: Quantity | F2: Comments
B3: PV Module
B4: DC Cable Red & Black
B5: Inverters
B6: Mounting Structure
B7: Current Transformers (Production)
B8: Current Transformers (Consumption)
B9: Solar Production Meter (Techistter)
B10: Grid Consumption Meter
B11: Wi-Fi Router & Sim
B12: Switch
B13: Back Up Battery
B14: PVDB
... B30: Techsitter

Sheet Compliance
B2: HSE
B4: Description | C4: Status | D4: Approved By | E4: Date | F4: Results / Comments
B5: NOC | F5: In progress
B6: 7.1 Agreement | F6: In progress
B7: 13.2 Agreement | F7: In progress
B8: EE File | F8: In progress
B9: Subbie File | F9: Not appointed yet
B16: SSEG
B18: Description | C18: Status | D18: Approved By | E18: Date | F18: Results / Comments
B19: SSEG Application
B20: PTI
B21: Commissioning Approval

Sheet Project Plan
N1: =TODAY() -> 46076 | O1: =TODAY() -> 46076
C2: PROJECT PLAN | E2: De Drift | I2: Net Work Days | K2: =NETWORKDAYS(I20,K41,Data!C3:C60) -> 46 | N2: 0 | O2: 1
C3: PROJECT SIZE (kWp) | E3: 800 | I3: Total Weeks | K3: =K2/5 -> 9.2
C4: PROJECT DEVELOPER | E4: Peet Verreynne | I4: kW/Week Installation Rate | K4: =E3/K3 -> 86.956522
C5: PROJECT MANAGERS | E5: Justin Franke
C6: CONTRACT VALUE | E6: 5965612.5
C7: Phase: | E7: Planning
B8: No. | C8: HIGH LEVEL PROGRAMME | E8: Planned Start | F8: Duration | G8: Planned End | I8: Actual Start | J8: Duration | K8: Actual End | M8: Status | N8: Expected Status | O8: Comment
F9: =G41-E21 -> 69 | J9: =K41-I21 -> 69 | M9: =AVERAGE(M11,M20,M23,M30,M37,M41,M50,M46) -> 0.044642857 | N9: =AVERAGE(N11,N20,N23,N30,N37,N41,N50,N46) -> 0.044318182 | S9: =TODAY() -> 46076 | T9: =TODAY() -> 46076
S10: 1 | T10: 0
B11: 1 | C11: Project Initiation | E11: =MIN(E12:E19) -> 45992 | F11: =G11-E11 -> 141 | G11: =MAX(G12:G19) -> 46133 | I11: =MIN(I12:I19) -> 45992 | J11: =K11-I11 -> 141 | K11: =MAX(K12:K19) -> 46133 | M11: =AVERAGE(M12:M18) -> 0.35714286 | N11: =AVERAGE(N12:N18) -> 0.35454545
B12: 1.1 | C12: Project Charter Handover | E12: 46044 | F12: 1 | G12: =WORKDAY.INTL(E12,F12,1,Data!$C$3:$C$60) -> 46045 | I12: 46044 | J12: 1 | K12: =WORKDAY.INTL(I12,J12,1,Data!$C$3:$C$60) -> 46045 | M12: 1 | N12: =_xlfn.LET( _xlpm.s,VALUE($I12), _xlpm.e,VALUE($K12), IF(OR(_xlpm.s="",_xlpm.e=""),"", IF(_xlpm.e<=_xlpm.s, IF(TODAY()>=_xlpm.e,1,0), MAX(0,MIN(1,(TODAY()-_xlpm.s)/(_xlpm.e-_xlpm.s))))) ) -> 1 | S12: Milestone | T12: Start Date | U12: Duration | V12: End Date | W12: Progress
C13: Contracts | E13: 45992 | F13: 15 | G13: =WORKDAY.INTL(E13,F13,1,Data!$C$3:$C$60) -> 46048 | I13: 45992 | J13: 15 | K13: =WORKDAY.INTL(I13,J13,1,Data!$C$3:$C$60) -> 46048 | M13: 1 | N13: 1 | S13: =C11 -> Project Initiation | T13: =I11 -> 45992 | U13: =J11 -> 141 | V13: =K11 -> 46133 | W13: =M11 -> 0.35714286
C14: Site building & Roof Signoff | E14: 46023 | F14: 65 | G14: =WORKDAY.INTL(E14,F14,1,Data!$C$3:$C$60) -> 46133 | I14: 46023 | J14: 65 | K14: =WORKDAY.INTL(I14,J14,1,Data!$C$3:$C$60) -> 46133 | M14: 0.5 | N14: =_xlfn.LET( _xlpm.s,VALUE($I14), _xlpm.e,VALUE($K14), IF(OR(_xlpm.s="",_xlpm.e=""),"", IF(_xlpm.e<=_xlpm.s, IF(TODAY()>=_xlpm.e,1,0), MAX(0,MIN(1,(TODAY()-_xlpm.s)/(_xlpm.e-_xlpm.s))))) ) -> 0.48181818 | S14: =C20 -> Site Establishment | T14: =I20 -> 46106 | U14: =J20 -> 1 | V14: =K20 -> 46107 | W14: =M20 -> 0
B15: 1.2 | C15: HSE Readiness and Signoff | E15: =G14-30 -> 46103 | F15: 15 | G15: =WORKDAY.INTL(E15,F15,1,Data!$C$3:$C$60) -> 46126 | I15: =K14-30 -> 46103 | J15: 15 | K15: =WORKDAY.INTL(I15,J15,1,Data!$C$3:$C$60) -> 46126 | M15: 0 | N15: =_xlfn.LET( _xlpm.s,VALUE($I15), _xlpm.e,VALUE($K15), IF(OR(_xlpm.s="",_xlpm.e=""),"", IF(_xlpm.e<=_xlpm.s, IF(TODAY()>=_xlpm.e,1,0), MAX(0,MIN(1,(TODAY()-_xlpm.s)/(_xlpm.e-_xlpm.s))))) ) -> 0 | S15: =C23 -> AC Installation | T15: =I23 -> 46107 | U15: =J23 -> 53 | V15: =K23 -> 46160 | W15: =M23 -> 0
B16: 1.3 | C16: Project Introduction | E16: =WORKDAY.INTL(G15,0,1,Data!$C$3:$C$60) -> 46126 | F16: 1 | G16: =WORKDAY.INTL(E16,F16,1,Data!$C$3:$C$60) -> 46127 | I16: =WORKDAY.INTL(K15,0,1,Data!$C$3:$C$60) -> 46126 | J16: 1 | K16: =WORKDAY.INTL(I16,J16,1,Data!$C$3:$C$60) -> 46127 | M16: 0 | N16: =_xlfn.LET( _xlpm.s,VALUE($I16), _xlpm.e,VALUE($K16), IF(OR(_xlpm.s="",_xlpm.e=""),"", IF(_xlpm.e<=_xlpm.s, IF(TODAY()>=_xlpm.e,1,0), MAX(0,MIN(1,(TODAY()-_xlpm.s)/(_xlpm.e-_xlpm.s))))) ) -> 0 | S16: =C30 -> DC Works | T16: =I30 -> 46106 | U16: =J30 -> 57 | V16: =K30 -> 46163 | W16: =M30 -> 0
B17: 1.4 | C17: Installer Kick Off | E17: =WORKDAY.INTL(E15,0,1,Data!$C$3:$C$60)+14 -> 46117 | F17: 1 | G17: =WORKDAY.INTL(E17,F17,1,Data!$C$3:$C$60) -> 46119 | I17: =WORKDAY.INTL(I15,0,1,Data!$C$3:$C$60)+14 -> 46117 | J17: 1 | K17: =WORKDAY.INTL(I17,J17,1,Data!$C$3:$C$60) -> 46119 | M17: 0 | N17: =_xlfn.LET( _xlpm.s,VALUE($I17), _xlpm.e,VALUE($K17), IF(OR(_xlpm.s="",_xlpm.e=""),"", IF(_xlpm.e<=_xlpm.s, IF(TODAY()>=_xlpm.e,1,0), MAX(0,MIN(1,(TODAY()-_xlpm.s)/(_xlpm.e-_xlpm.s))))) ) -> 0 | S17: =C37 -> Module installation | T17: =I37 -> 46106 | U17: =J37 -> 36 | V17: =K37 -> 46142 | W17: =M37 -> 0
B18: 1.5 | C18: Project Review | E18: =WORKDAY.INTL(E17,0,1,Data!$C$3:$C$60)-4 -> 46113 | F18: 1 | G18: =WORKDAY.INTL(E18,F18,1,Data!$C$3:$C$60) -> 46114 | I18: =WORKDAY.INTL(I17,0,1,Data!$C$3:$C$60)-4 -> 46113 | J18: 1 | K18: =WORKDAY.INTL(I18,J18,1,Data!$C$3:$C$60) -> 46114 | M18: 0 | N18: =_xlfn.LET( _xlpm.s,VALUE($I18), _xlpm.e,VALUE($K18), IF(OR(_xlpm.s="",_xlpm.e=""),"", IF(_xlpm.e<=_xlpm.s, IF(TODAY()>=_xlpm.e,1,0), MAX(0,MIN(1,(TODAY()-_xlpm.s)/(_xlpm.e-_xlpm.s))))) ) -> 0 | S18: =C41 -> Commissioning | T18: =I41 -> 46163 | U18: =J41 -> 12 | V18: =K41 -> 46175 | W18: =M41 -> 0
S19: =C46 -> QA Inspections | T19: =I46 -> 46168 | U19: =J46 -> 8 | V19: =K46 -> 46176 | W19: =M46 -> 0
B20: 2 | C20: Site Establishment | E20: =MIN(E21:E22) -> 46106 | F20: =G20-E20 -> 1 | G20: =MAX(G21:G22) -> 46107 | I20: =MIN(I21:I22) -> 46106 | J20: =K20-I20 -> 1 | K20: =MAX(K21:K22) -> 46107 | M20: =(J21*M21)/J20 -> 0 | N20: =(J21*M21)/J20 -> 0 | S20: =C50 -> Project Closure | T20: =I50 -> 46171 | U20: =J50 -> 19 | V20: =K50 -> 46190 | W20: =M50 -> 0
B21: 2.1 | C21: Solar Contractor Establishment | E21: 46106 | F21: 1 | G21: =E21+F21 -> 46107 | I21: 46106 | J21: 1 | K21: =I21+J21 -> 46107 | M21: 0 | N21: =_xlfn.LET( _xlpm.s,VALUE($I21), _xlpm.e,VALUE($K21), IF(OR(_xlpm.s="",_xlpm.e=""),"", IF(_xlpm.e<=_xlpm.s, IF(TODAY()>=_xlpm.e,1,0), MAX(0,MIN(1,(TODAY()-_xlpm.s)/(_xlpm.e-_xlpm.s))))) ) -> 0 | O21: Building construction - End March
B23: 3 | C23: AC Installation | E23: =MIN(E24:E29) -> 46107 | F23: =G23-E23 -> 53 | G23: =MAX(G24:G29) -> 46160 | I23: =MIN(I24:I29) -> 46107 | J23: =K23-I23 -> 53 | K23: =MAX(K24:K29) -> 46160 | M23: =(J24*M24+J25*M25+J26*M26+J27*M27+J28*M28)/SUM(J24:J28) -> 0 | N23: =(J24*N24+J25*N25+J26*N26+J27*N27+J28*N28)/SUM(J24:J28) -> 0
B24: 3.1 | C24: Inverters delivered | E24: =WORKDAY.INTL(G21,0,1,Data!$C$3:$C$60) -> 46107 | F24: 1 | G24: =WORKDAY.INTL(E24,F24,1,Data!$C$3:$C$60) -> 46108 | I24: =WORKDAY.INTL(K21,0,1,Data!$C$3:$C$60) -> 46107 | J24: 1 | K24: =WORKDAY.INTL(I24,J24,1,Data!$C$3:$C$60) -> 46108 | M24: 0 | N24: =_xlfn.LET( _xlpm.s,VALUE($I24), _xlpm.e,VALUE($K24), IF(OR(_xlpm.s="",_xlpm.e=""),"", IF(_xlpm.e<=_xlpm.s, IF(TODAY()>=_xlpm.e,1,0), MAX(0,MIN(1,(TODAY()-_xlpm.s)/(_xlpm.e-_xlpm.s))))) ) -> 0
B25: 3.2 | C25: Inverters Mounted | E25: =WORKDAY.INTL(G24,0,1,Data!$C$3:$C$60) -> 46108 | F25: 1 | G25: =WORKDAY.INTL(E25,F25,1,Data!$C$3:$C$60) -> 46111 | I25: =WORKDAY.INTL(K24,0,1,Data!$C$3:$C$60) -> 46108 | J25: 1 | K25: =WORKDAY.INTL(I25,J25,1,Data!$C$3:$C$60) -> 46111 | M25: 0 | N25: =_xlfn.LET( _xlpm.s,VALUE($I25), _xlpm.e,VALUE($K25), IF(OR(_xlpm.s="",_xlpm.e=""),"", IF(_xlpm.e<=_xlpm.s, IF(TODAY()>=_xlpm.e,1,0), MAX(0,MIN(1,(TODAY()-_xlpm.s)/(_xlpm.e-_xlpm.s))))) ) -> 0
B26: 3.3 | C26: Solar DB Lead Time | E26: =WORKDAY.INTL(E16,0,1,Data!$C$3:$C$60)-14 -> 46112 | F26: 30 | G26: =WORKDAY.INTL(E26,F26,1,Data!$C$3:$C$60) -> 46160 | I26: =WORKDAY.INTL(I16,0,1,Data!$C$3:$C$60)-14 -> 46112 | J26: 30 | K26: =WORKDAY.INTL(I26,J26,1,Data!$C$3:$C$60) -> 46160 | M26: 0 | N26: =_xlfn.LET( _xlpm.s,VALUE($I26), _xlpm.e,VALUE($K26), IF(OR(_xlpm.s="",_xlpm.e=""),"", IF(_xlpm.e<=_xlpm.s, IF(TODAY()>=_xlpm.e,1,0), MAX(0,MIN(1,(TODAY()-_xlpm.s)/(_xlpm.e-_xlpm.s))))) ) -> 0
B27: 3.4 | C27: AC Works | E27: =E24 -> 46107 | F27: 15 | G27: =WORKDAY.INTL(E27,F27,1,Data!$C$3:$C$60) -> 46132 | I27: =I24 -> 46107 | J27: 15 | K27: =WORKDAY.INTL(I27,J27,1,Data!$C$3:$C$60) -> 46132 | M27: 0 | N27: =_xlfn.LET( _xlpm.s,VALUE($I27), _xlpm.e,VALUE($K27), IF(OR(_xlpm.s="",_xlpm.e=""),"", IF(_xlpm.e<=_xlpm.s, IF(TODAY()>=_xlpm.e,1,0), MAX(0,MIN(1,(TODAY()-_xlpm.s)/(_xlpm.e-_xlpm.s))))) ) -> 0
B28: 3.5 | C28: AC Tie-In | E28: =WORKDAY.INTL(E27,0,1,Data!$C$3:$C$60) -> 46107 | F28: 1 | G28: =WORKDAY.INTL(E28,F28,1,Data!$C$3:$C$60) -> 46108 | I28: =WORKDAY.INTL(I27,0,1,Data!$C$3:$C$60) -> 46107 | J28: 1 | K28: =WORKDAY.INTL(I28,J28,1,Data!$C$3:$C$60) -> 46108 | M28: 0 | N28: =_xlfn.LET( _xlpm.s,VALUE($I28), _xlpm.e,VALUE($K28), IF(OR(_xlpm.s="",_xlpm.e=""),"", IF(_xlpm.e<=_xlpm.s, IF(TODAY()>=_xlpm.e,1,0), MAX(0,MIN(1,(TODAY()-_xlpm.s)/(_xlpm.e-_xlpm.s))))) ) -> 0
B30: 4 | C30: DC Works | E30: =MIN(E32:E36) -> 46106 | F30: =G30-E30 -> 57 | G30: =MAX(G32:G36) -> 46163 | I30: =MIN(I32:I36) -> 46106 | J30: =K30-I30 -> 57 | K30: =MAX(K32:K36) -> 46163 | M30: =(J32*M32+J33*M33+J35*M35)/SUM(J32:J35) -> 0 | N30: =(J32*N32+J33*N33+J35*N35)/SUM(J32:J35) -> 0
B32: 4.1 | C32: Mounting Structure delivered | E32: =E21 -> 46106 | F32: 1 | G32: =WORKDAY.INTL(E32,F32,1,Data!$C$3:$C$60) -> 46107 | I32: =I21 -> 46106 | J32: 1 | K32: =WORKDAY.INTL(I32,J32,1,Data!$C$3:$C$60) -> 46107 | M32: 0 | N32: =_xlfn.LET( _xlpm.s,VALUE($I32), _xlpm.e,VALUE($K32), IF(OR(_xlpm.s="",_xlpm.e=""),"", IF(_xlpm.e<=_xlpm.s, IF(TODAY()>=_xlpm.e,1,0), MAX(0,MIN(1,(TODAY()-_xlpm.s)/(_xlpm.e-_xlpm.s))))) ) -> 0
B33: 4.2 | C33: Mounting Structure installation | E33: =WORKDAY.INTL(G32,0,1,Data!$C$3:$C$60) -> 46107 | F33: 5 | G33: =WORKDAY.INTL(E33,F33,1,Data!$C$3:$C$60) -> 46114 | I33: =WORKDAY.INTL(K32,0,1,Data!$C$3:$C$60) -> 46107 | J33: 5 | K33: =WORKDAY.INTL(I33,J33,1,Data!$C$3:$C$60) -> 46114 | M33: 0 | N33: =_xlfn.LET( _xlpm.s,VALUE($I33), _xlpm.e,VALUE($K33), IF(OR(_xlpm.s="",_xlpm.e=""),"", IF(_xlpm.e<=_xlpm.s, IF(TODAY()>=_xlpm.e,1,0), MAX(0,MIN(1,(TODAY()-_xlpm.s)/(_xlpm.e-_xlpm.s))))) ) -> 0
B34: 4.3 | C34: DC Cable delivered | E34: =E32 -> 46106 | F34: 1 | G34: =WORKDAY.INTL(E34,F34,1,Data!$C$3:$C$60) -> 46107 | I34: =I32 -> 46106 | J34: 1 | K34: =WORKDAY.INTL(I34,J34,1,Data!$C$3:$C$60) -> 46107 | M34: 0 | N34: =_xlfn.LET( _xlpm.s,VALUE($I34), _xlpm.e,VALUE($K34), IF(OR(_xlpm.s="",_xlpm.e=""),"", IF(_xlpm.e<=_xlpm.s, IF(TODAY()>=_xlpm.e,1,0), MAX(0,MIN(1,(TODAY()-_xlpm.s)/(_xlpm.e-_xlpm.s))))) ) -> 0
B35: 4.4 | C35: DC Stringing | E35: =WORKDAY.INTL(G39,0,1,Data!$C$3:$C$60)-3 -> 46139 | F35: 17 | G35: =WORKDAY.INTL(E35,F35,1,Data!$C$3:$C$60) -> 46163 | I35: =WORKDAY.INTL(K39,0,1,Data!$C$3:$C$60)-3 -> 46139 | J35: 17 | K35: =WORKDAY.INTL(I35,J35,1,Data!$C$3:$C$60) -> 46163 | M35: 0 | N35: =_xlfn.LET( _xlpm.s,VALUE($I35), _xlpm.e,VALUE($K35), IF(OR(_xlpm.s="",_xlpm.e=""),"", IF(_xlpm.e<=_xlpm.s, IF(TODAY()>=_xlpm.e,1,0), MAX(0,MIN(1,(TODAY()-_xlpm.s)/(_xlpm.e-_xlpm.s))))) ) -> 0
B37: 5 | C37: Module installation | E37: =MIN(E38:E40) -> 46106 | F37: =G37-E37 -> 36 | G37: =MAX(G38:G40) -> 46142 | I37: =MIN(I38:I40) -> 46106 | J37: =K37-I37 -> 36 | K37: =MAX(K38:K40) -> 46142 | M37: =(J38*M38+J39*M39)/SUM(J38:J39) -> 0 | N37: =(J38*N38+J39*N39)/SUM(J38:J39) -> 0
B38: 5.1 | C38: Module delivery | E38: =WORKDAY.INTL(E21,0,1,Data!$C$3:$C$60) -> 46106 | F38: 1 | G38: =WORKDAY.INTL(E38,F38,1,Data!$C$3:$C$60) -> 46107 | I38: =WORKDAY.INTL(I21,0,1,Data!$C$3:$C$60) -> 46106 | J38: 1 | K38: =WORKDAY.INTL(I38,J38,1,Data!$C$3:$C$60) -> 46107 | M38: 0 | N38: =_xlfn.LET( _xlpm.s,VALUE($I38), _xlpm.e,VALUE($K38), IF(OR(_xlpm.s="",_xlpm.e=""),"", IF(_xlpm.e<=_xlpm.s, IF(TODAY()>=_xlpm.e,1,0), MAX(0,MIN(1,(TODAY()-_xlpm.s)/(_xlpm.e-_xlpm.s))))) ) -> 0
B39: 5.2 | C39: Module mounting | E39: 46120 | F39: 15 | G39: =WORKDAY.INTL(E39,F39,1,Data!$C$3:$C$60) -> 46142 | I39: 46120 | J39: 15 | K39: =WORKDAY.INTL(I39,J39,1,Data!$C$3:$C$60) -> 46142 | M39: 0 | N39: =_xlfn.LET( _xlpm.s,VALUE($I39), _xlpm.e,VALUE($K39), IF(OR(_xlpm.s="",_xlpm.e=""),"", IF(_xlpm.e<=_xlpm.s, IF(TODAY()>=_xlpm.e,1,0), MAX(0,MIN(1,(TODAY()-_xlpm.s)/(_xlpm.e-_xlpm.s))))) ) -> 0
B41: 6 | C41: Commissioning | E41: =MIN(E42:E45) -> 46163 | F41: =G41-E41 -> 12 | G41: =MAX(G42:G45) -> 46175 | I41: =MIN(I42:I45) -> 46163 | J41: =K41-I41 -> 12 | K41: =MAX(K42:K45) -> 46175 | M41: =(J42*M42+J43*M43+J44*M44)/SUM(J42:J44) -> 0 | N41: =(J42*N42+J43*N43+J44*N44)/SUM(J42:J44) -> 0
B42: 6.1 | C42: Commissioning | E42: 46163 | F42: 2 | G42: =WORKDAY.INTL(E42,F42,1,Data!$C$3:$C$60) -> 46167 | I42: 46163 | J42: 2 | K42: =WORKDAY.INTL(I42,J42,1,Data!$C$3:$C$60) -> 46167 | M42: 0 | N42: =_xlfn.LET( _xlpm.s,VALUE($I42), _xlpm.e,VALUE($K42), IF(OR(_xlpm.s="",_xlpm.e=""),"", IF(_xlpm.e<=_xlpm.s, IF(TODAY()>=_xlpm.e,1,0), MAX(0,MIN(1,(TODAY()-_xlpm.s)/(_xlpm.e-_xlpm.s))))) ) -> 0
B43: 6.2 | C43: Practical Completion | E43: =WORKDAY.INTL(G42,0,1,Data!$C$3:$C$60) -> 46167 | F43: 1 | G43: =WORKDAY.INTL(E43,F43,1,Data!$C$3:$C$60) -> 46168 | I43: =WORKDAY.INTL(K42,0,1,Data!$C$3:$C$60) -> 46167 | J43: 1 | K43: =WORKDAY.INTL(I43,J43,1,Data!$C$3:$C$60) -> 46168 | M43: 0 | N43: =_xlfn.LET( _xlpm.s,VALUE($I43), _xlpm.e,VALUE($K43), IF(OR(_xlpm.s="",_xlpm.e=""),"", IF(_xlpm.e<=_xlpm.s, IF(TODAY()>=_xlpm.e,1,0), MAX(0,MIN(1,(TODAY()-_xlpm.s)/(_xlpm.e-_xlpm.s))))) ) -> 0
B44: 6.3 | C44: System Performance Monitoring | E44: =WORKDAY.INTL(G43,0,1,Data!$C$3:$C$60) -> 46168 | F44: 5 | G44: =WORKDAY.INTL(E44,F44,1,Data!$C$3:$C$60) -> 46175 | I44: =WORKDAY.INTL(K43,0,1,Data!$C$3:$C$60) -> 46168 | J44: 5 | K44: =WORKDAY.INTL(I44,J44,1,Data!$C$3:$C$60) -> 46175 | M44: 0 | N44: =_xlfn.LET( _xlpm.s,VALUE($I44), _xlpm.e,VALUE($K44), IF(OR(_xlpm.s="",_xlpm.e=""),"", IF(_xlpm.e<=_xlpm.s, IF(TODAY()>=_xlpm.e,1,0), MAX(0,MIN(1,(TODAY()-_xlpm.s)/(_xlpm.e-_xlpm.s))))) ) -> 0
B46: 7 | C46: QA Inspections | E46: =MIN(E47:E49) -> 46168 | F46: =G46-E46 -> 8 | G46: =MAX(G47:G49) -> 46176 | I46: =MIN(I47:I49) -> 46168 | J46: =K46-I46 -> 8 | K46: =MAX(K47:K49) -> 46176 | M46: =(J47*N47+J48*N48)/SUM(J47:J48) -> 0 | N46: =(J47*M47+J48*M48)/SUM(J47:J48) -> 0
...

Sheet Revenue Tracking
B2: HIGH LEVEL PROJECT REVENUE TRACKING | T2: 2026 Budget Revenue | U2: 2026 Budget COS | V2: 2026 Actual Revenue | W2: 2026 Actual COS
D3: COSTED | F3: ACTUAL | L3: FINANCIAL REVIEW | N3: TIMELINE REVIEW | T3: =SUMIFS('Expenditure Breakdown'!$U:$U, 'Expenditure Breakdown'!$T:$T, ">"&DATE(2025,8,31), 'Expenditure Breakdown'!$T:$T, "<="&DATE(2026,8,31)) -> 5965612.5 | U3: =SUMIFS('Expenditure Breakdown'!$Q:$Q, 'Expenditure Breakdown'!$T:$T, ">"&DATE(2025,8,31), 'Expenditure Breakdown'!$T:$T, "<="&DATE(2026,8,31)) -> 4357754.6 | V3: =SUMIFS('Expenditure Breakdown'!$U:$U, 'Expenditure Breakdown'!$T:$T, ">"&DATE(2025,8,31), 'Expenditure Breakdown'!$T:$T, "<="&DATE(2026,8,31), 'Expenditure Breakdown'!$S:$S, "<>") -> 0 | W3: =SUMIFS('Expenditure Breakdown'!$Q:$Q, 'Expenditure Breakdown'!$T:$T, ">"&DATE(2025,8,31), 'Expenditure Breakdown'!$T:$T, "<="&DATE(2026,8,31), 'Expenditure Breakdown'!$S:$S, "<>") -> 0
B4: 1 | C4: Planned Revenue | D4: ='Project Plan'!E6 -> 5965612.5 | F4: =F21 -> 5965612.5 | N4: Start Date
B5: 2 | C5: Planned Expenditure | D5: =+'Expenditure Tracking'!F5 -> 5125523.7 | F5: =+'Expenditure Tracking'!H5 -> 4357754.6
B6: 3 | C6: Planned Profit | D6: =+D4-D5 -> 840088.82 | F6: =+F4-F5 -> 1607857.9 | N6: End Date - PC
B7: 4 | C7: Planned Margin | D7: =+D6/D4 -> 0.14082189 | F7: =+F6/F4 -> 0.26952101
B10: CONTRACT
B12: No. | C12: PAYMENT MILESTONE | E12: % | F12: VALUE | H12: PLANNED PAYMENT DATE | L12: INVOICE NUMBER | N12: INVOICE RAISED DATE | P12: PAYMENT RECEIVED DATE | R12: MILESTONE NOTES & COMMENTS
B13: 1 | C13: Acceptance and Initial Deposit | E13: 0.35 | F13: =$D$4*E13 -> 2087964.4 | H13: 46081 | P13: ='Project Plan'!I21-14 -> 46092 | AO13: ='Change Register'!$Q$14+ 7 -> 7
B14: 2 | C14: Delivery of Panels | E14: 0.3 | F14: =$D$4*E14 -> 1789683.7 | H14: ='Project Plan'!G38+7 -> 46114 | P14: ='Project Plan'!K38+7 -> 46114
B15: 3 | C15: Delivery of Inverters | E15: 0.2 | F15: =$D$4*E15 -> 1193122.5 | H15: ='Project Plan'!G24+7 -> 46115 | P15: ='Project Plan'!K24+7 -> 46115
B16: 4 | C16: Practical Completion | E16: 0.1 | F16: =$D$4*E16 -> 596561.25 | H16: ='Project Plan'!G41+7 -> 46182 | P16: ='Project Plan'!K41+7 -> 46182
B17: 5 | C17: Handover | E17: 0.05 | F17: =$D$4*E17 -> 298280.62 | H17: ='Project Plan'!G52+365 -> 46548 | P17: ='Project Plan'!K52+365 -> 46548
B18: 6 | C18: - | E18: 0 | F18: =$D$4*E18 -> 0
B19: 7 | C19: - | E19: 0 | F19: =$D$4*E19 -> 0
E21: =SUM(E13:E19) -> 1 | F21: =SUM(F13:F19) -> 5965612.5
B23: KEY: | C23: contains an error (in result or a check has failed)
C24: Red Font - IF TEXT : content not yet confirmed
C25: Red Font - IF NUMBER: Negative value
C26: Anything in yellow is a concern or risk for noting or action
C27: confirmed
C28: [ADD INITIALS: comment for noting in square brackets, use colour or red to draw attention if important]
C29: [RT: When adding rows into sheet, ensure you insert between first and last row of each category]
C30: end of sheet - do not insert information below/beyond this
B40: No. | C40: PAYMENT MILESTONE | E40: % | F40: VALUE
B41: 1 | C41: Deposit - Project commencement | E41: 0.35 | F41: =$F$47*E41 -> 2087964.4
B42: 2 | C42: Delivery of Panels | E42: 0.3 | F42: =$F$47*E42 -> 1789683.7
B43: 3 | C43: Delivery of Inverters | E43: 0.2 | F43: =$F$47*E43 -> 1193122.5
B44: 4 | C44: Practical Completion | E44: 0.1 | F44: =$F$47*E44 -> 596561.25
B45: 5 | C45: Handover | E45: 0.05 | F45: =$F$47*E45 -> 298280.62
C46: Total | E46: =SUM(E41:E45) -> 1 | F46: =SUM(F41:F45) -> 5965612.5
E47: =SUM(E41:E45) -> 1 | F47: =F21 -> 5965612.5

Sheet Expenditure Tracking
B2: HIGH LEVEL PROJECT EXPENDITURE TRACKING
F4: COSTED | H4: ACTUAL | J4: Difference from Costed
B5: EXPENDITURE | F5: =SUM(F9:F23) -> 5125523.7 | H5: =SUM(H9:H23) -> 4357754.6 | J5: =SUM(J9:J23) -> 767769.07
B7: No. | D7: Item | F7: Costed Expenditure | H7: Actual Expenditure | J7: Saving / Overrun | L7: Comments on variations from planned expenditure
B9: ='Expenditure Breakdown'!L6 -> 1 | D9: ='Expenditure Breakdown'!M6 -> 1. Panels | F9: ='Expenditure Breakdown'!I6 -> 1856118.2 | H9: ='Expenditure Breakdown'!X6 -> 1600840 | J9: =F9-H9 -> 255278.16
B10: ='Expenditure Breakdown'!L13 -> 2 | D10: ='Expenditure Breakdown'!M13 -> 2. Inverters | F10: ='Expenditure Breakdown'!I13 -> 490000 | H10: ='Expenditure Breakdown'!X13 -> 476000 | J10: =F10-H10 -> 14000
B11: ='Expenditure Breakdown'!L21 -> 3 | D11: ='Expenditure Breakdown'!M21 -> 3. Mounting Structures | F11: ='Expenditure Breakdown'!I21 -> 320128 | H11: ='Expenditure Breakdown'!X21 -> 280000 | J11: =F11-H11 -> 40128
B12: ='Expenditure Breakdown'!L28 -> 4 | D12: ='Expenditure Breakdown'!M28 -> 4. DC Equipment | F12: ='Expenditure Breakdown'!I28 -> 635424.2 | H12: ='Expenditure Breakdown'!X28 -> 604125.57 | J12: =F12-H12 -> 31298.63
B13: ='Expenditure Breakdown'!L44 -> 5 | D13: ='Expenditure Breakdown'!M44 -> 5. Monitoring | F13: ='Expenditure Breakdown'!I44 -> 174000 | H13: ='Expenditure Breakdown'!X44 -> 49500 | J13: =F13-H13 -> 124500
B14: ='Expenditure Breakdown'!L52 -> 6 | D14: ='Expenditure Breakdown'!M52 -> 6. AC Equipment | F14: ='Expenditure Breakdown'!I52 -> 639916.75 | H14: ='Expenditure Breakdown'!X52 -> 453044.65 | J14: =F14-H14 -> 186872.1
B15: ='Expenditure Breakdown'!L70 -> 7 | D15: ='Expenditure Breakdown'!M70 -> 7.BESS | F15: ='Expenditure Breakdown'!I70 -> 0 | H15: ='Expenditure Breakdown'!X70 -> 0 | J15: =F15-H15 -> 0
B16: ='Expenditure Breakdown'!L79 -> 8 | D16: ='Expenditure Breakdown'!M79 -> 8. Product Add On | F16: ='Expenditure Breakdown'!I79 -> 0 | H16: ='Expenditure Breakdown'!X79 -> 0 | J16: =F16-H16 -> 0
B17: ='Expenditure Breakdown'!L89 -> 9 | D17: ='Expenditure Breakdown'!M89 -> 9. AC & DC installation | F17: ='Expenditure Breakdown'!I89 -> 636320 | H17: ='Expenditure Breakdown'!X89 -> 540872 | J17: =F17-H17 -> 95448
B18: ='Expenditure Breakdown'!L102 -> 10 | D18: ='Expenditure Breakdown'!M102 -> 10. Site Logistics | F18: ='Expenditure Breakdown'!I102 -> 156487.33 | H18: ='Expenditure Breakdown'!X102 -> 147414.23 | J18: =F18-H18 -> 9073.1
B19: ='Expenditure Breakdown'!L118 -> 11 | D19: ='Expenditure Breakdown'!M118 -> 11. Due Dilligence | F19: ='Expenditure Breakdown'!I118 -> 140024 | H19: ='Expenditure Breakdown'!X118 -> 117388 | J19: =F19-H19 -> 22636
B20: ='Expenditure Breakdown'!L124 -> 12 | D20: ='Expenditure Breakdown'!M124 -> 12. BDP Commission | F20: ='Expenditure Breakdown'!I124 -> 0 | H20: ='Expenditure Breakdown'!X124 -> 0 | J20: =F20-H20 -> 0
B21: ='Expenditure Breakdown'!L127 -> 13 | D21: ='Expenditure Breakdown'!M128 -> 13. Engineering | F21: ='Expenditure Breakdown'!I127 -> 63105.231 | H21: ='Expenditure Breakdown'!X127 -> 74570.156 | J21: =F21-H21 -> -11464.926
B22: ='Expenditure Breakdown'!L134 -> 14 | D22: ='Expenditure Breakdown'!M134 -> 14. General Expenses | F22: ='Expenditure Breakdown'!I134 -> 14000 | H22: ='Expenditure Breakdown'!X134 -> 14000 | J22: =F22-H22 -> 0
B23: ='Expenditure Breakdown'!L147 -> 15 | D23: ='Expenditure Breakdown'!M147 -> 15. Service Add On | F23: ='Expenditure Breakdown'!I147 -> 0 | H23: ='Expenditure Breakdown'!X147 -> 0 | J23: =F23-H23 -> 0
D25: check: | F25: ='Expenditure Breakdown'!I2-'Expenditure Tracking'!F5 -> 0 | G25: =#REF!-G5 -> #REF! | H25: ='Expenditure Breakdown'!X2-H5 -> 0

Sheet Expenditure Breakdown
B2: COSTED EXPENDITURE BREAKDOWN | I2: =SUM(I6:I159) -> 5125523.7 | J2: =SUM(J6:J159) -> 5965612.5 | L2: ACTUAL EXPENDITURE BREAKDOWN | R2: FINANCE ONLY | X2: =SUM(X6:X159) -> 4357754.6
B4: No. | C4: Product / Service | D4: Description of Work | E4: QTY | F4: Rate / Unit | G4: Budget Total | H4: FORECASTED PAYMENT DATE | I4: Total COS | J4: =IF(J2-'Revenue Tracking'!D4>=0, "Total Revenue", "ERROR on REV" ) -> ERROR on REV | L4: No. | M4: Product/ Service | N4: Description of Work | O4: QTY | P4: Rate / Unit | Q4: Actual Total | R4: PO NUMBER | S4: INVOICE NUMBER | T4: INVOICE RAISED DATE | U4: REVENUE RECOGNITION AMOUNT | V4: CHECK | W4: FINANCE PAYMENT DATE | X4: Total COS
B6: 1 | C6: Panels | D6: Panels Budget | G6: =D160 -> 1856118.2 | H6: ='Project Plan'!E38+60 -> 46166 | I6: =SUM(G6:G11) -> 1856118.2 | J6: =F160 -> 2183668.4 | L6: 1 | M6: 1. Panels | N6: Jinko Tiger Neo N-type66HL4M-BDV - 620W | O6: 1291 | P6: 1240 | Q6: =O6*P6 -> 1600840 | T6: 46142 | U6: =(Q6/$X$6*$J$6) -> 2183668.4 | V6: =J6-SUM(U6:U11) -> 0 | W6: ='Project Plan'!I38+60 -> 46166 | X6: =SUM(Q6:Q11) -> 1600840
B7: 1 | D7: Delivery Budget | L7: 1 | M7: 1. Panels | T7: =IF(W7>1,EOMONTH(W7,0),"") | U7: =(Q7/$X$6*$J$6) -> 0
B8: 1 | L8: 1 | M8: 1. Panels | T8: =IF(W8>1,EOMONTH(W8,0),"") | U8: =(Q8/$X$6*$J$6) -> 0
B9: 1 | L9: 1 | M9: 1. Panels | T9: =IF(W9>1,EOMONTH(W9,0),"") | U9: =(Q9/$X$6*$J$6) -> 0
B10: 1 | L10: 1 | M10: 1. Panels | T10: =IF(W10>1,EOMONTH(W10,0),"") | U10: =(Q10/$X$6*$J$6) -> 0
B11: 1 | L11: 1 | M11: 1. Panels | T11: =IF(W11>1,EOMONTH(W11,0),"") | U11: =(Q11/$X$6*$J$6) -> 0 | Y11: BUDGET | Z11: Installer Allocation
T12: =IF(W12>1,EOMONTH(W12,0),"") | Y12: AC Equipment | Z12: =G52 -> 639916.75 | AA12: Includes the PVDB price, see price below in actual excluding DB price. This is what the contractor can quote us for.
B13: 2 | C13: Inverters | D13: Inverter Budget | G13: =D161 -> 490000 | H13: ='Project Plan'!E24+60 -> 46167 | I13: =SUM(G13:G19) -> 490000 | J13: =F161 -> 576470.59 | L13: 2 | M13: 2. Inverters | U13: =(Q13/$X$13*$J$13) -> 0 | V13: =J13-SUM(U13:U19) -> 0 | X13: =SUM(Q13:Q19) -> 476000 | Y13: DC Equipment | Z13: =G29 -> 381324.2
B14: 2 | L14: 2 | M14: 2. Inverters | N14: Huawei 100KTL | O14: 7 | P14: 68000 | Q14: =O14*P14 -> 476000 | T14: =T6 -> 46142 | U14: =(Q14/$X$13*$J$13) -> 576470.59 | W14: =W6 -> 46166 | Y14: AC Labour | Z14: =G89 -> 200080
B15: 2 | L15: 2 | M15: 2. Inverters | T15: =IF(W15>1,EOMONTH(W15,0),"") | U15: =(Q15/$X$13*$J$13) -> 0 | Y15: DC Labour | Z15: =G90 -> 436240
B16: 2 | L16: 2 | M16: 2. Inverters | T16: =IF(W16>1,EOMONTH(W16,0),"") | U16: =(Q16/$X$13*$J$13) -> 0 | Y16: Offloading | Z16: =G102 -> 8500
B17: 2 | L17: 2 | M17: 2. Inverters | T17: =IF(W17>1,EOMONTH(W17,0),"") | U17: =(Q17/$X$13*$J$13) -> 0 | Y17: Scaffolding | Z17: =G103 -> 42120.667
B18: 2 | L18: 2 | M18: 2. Inverters | T18: =IF(W18>1,EOMONTH(W18,0),"") | U18: =(Q18/$X$13*$J$13) -> 0 | Y18: Storage | Z18: =G105 -> 9866.6667
B19: 2 | L19: 2 | M19: 2. Inverters | T19: =IF(W19>1,EOMONTH(W19,0),"") | U19: =(Q19/$X$13*$J$13) -> 0 | Y19: Telehandler | Z19: 0
T20: =IF(W20>1,EOMONTH(W20,0),"") | Y20: Trenching | Z20: 0
B21: 3 | C21: Mounting Structures | D21: Structure Budget | G21: =D162 -> 320128 | H21: ='Project Plan'!E32+30 -> 46136 | I21: =SUM(G21:G26) -> 320128 | J21: =F162 -> 376621.18 | L21: 3 | M21: 3. Mounting Structures | N21: Schletter Structure | Q21: 280000 | T21: 46142 | U21: =(Q21/$X$21*$J$21) -> 376621.18 | V21: =J21-SUM(U21:U26) -> 0 | W21: =T21+30 -> 46172 | X21: =SUM(Q21:Q26) -> 280000 | Y21: Other | Z21: 0
B22: 3 | L22: 3 | M22: 3. Mounting Structures | T22: =IF(W22>1,EOMONTH(W22,0),"") | U22: =(Q22/$X$21*$J$21) -> 0 | Y22: Total | Z22: =SUM(Z12:Z21) -> 1718048.3
B23: 3 | L23: 3 | M23: 3. Mounting Structures | T23: =IF(W23>1,EOMONTH(W23,0),"") | U23: =(Q23/$X$21*$J$21) -> 0 | Y23: Less 15% | Z23: =+Z22*0.85 -> 1460341
B24: 3 | L24: 3 | M24: 3. Mounting Structures | T24: =IF(W24>1,EOMONTH(W24,0),"") | U24: =(Q24/$X$21*$J$21) -> 0 | Y24: R/Wp | Z24: =Z23/'Project Plan'!$E$3/1000 -> 1.8254263
B25: 3 | L25: 3 | M25: 3. Mounting Structures | T25: =IF(W25>1,EOMONTH(W25,0),"") | U25: =(Q25/$X$21*$J$21) -> 0
B26: 3 | L26: 3 | M26: 3. Mounting Structures | T26: =IF(W26>1,EOMONTH(W26,0),"") | U26: =(Q26/$X$21*$J$21) -> 0 | Y26: ACTUAL | Z26: Installer Price
T27: =IF(W27>1,EOMONTH(W27,0),"") | Y27: =Y12 -> AC Equipment | Z27: =Z12*0.85-200000 -> 343929.24
B28: 4 | C28: DC Equipment | D28: DC Cable Budget | E28: 18150 | G28: 254100 | H28: ='Project Plan'!E34+60 -> 46166 | I28: =SUM(G28:G42) -> 635424.2 | J28: =F163 -> 747557.88 | L28: 4 | M28: 4. DC Equipment | N28: DC Cable | O28: 20000 | P28: 14 | Q28: =O28*P28 -> 280000 | T28: =T6 -> 46142 | U28: =(Q28/$X$28*$J$28) -> 346477.98 | V28: =J28-SUM(U28:U42) -> 0 | W28: =W6 -> 46166 | X28: =SUM(Q28:Q42) -> 604125.57 | Y28: =Y13 -> DC Equipment | Z28: =Z13*0.85 -> 324125.57
B29: 4 | D29: DC Equipment Budget | G29: =D163-G28 -> 381324.2 | H29: ='Project Plan'!G30 -> 46163 | L29: 4 | M29: 4. DC Equipment | T29: =IF(W29>1,EOMONTH(W29,0),"") | U29: =(Q29/$X$28*$J$28) -> 0 | Y29: =Y14 -> AC Labour | Z29: =Z14*0.85 -> 170068
B30: 4 | L30: 4 | M30: 4. DC Equipment | T30: =IF(W30>1,EOMONTH(W30,0),"") | U30: =(Q30/$X$28*$J$28) -> 0 | Y30: =Y15 -> DC Labour | Z30: =Z15*0.85 -> 370804
B31: 4 | L31: 4 | M31: 4. DC Equipment | T31: =IF(W31>1,EOMONTH(W31,0),"") | U31: =(Q31/$X$28*$J$28) -> 0 | Y31: Lifelines | Z31: =Z16*0.85 -> 7225
B32: 4 | L32: 4 | M32: 4. DC Equipment | N32: Project Kick Off | O32: =Z28 -> 324125.57 | P32: 0.1 | Q32: =$O$32*P32 -> 32412.557 | T32: =T90 -> 46112 | U32: =(Q32/$X$28*$J$28) -> 40107.99 | W32: =W90 -> 46099 | Y32: Forklift | Z32: =Z17*0.85 -> 35802.567
B33: 4 | L33: 4 | M33: 4. DC Equipment | N33: Site Establishment | P33: 0.15 | Q33: =$O$32*P33 -> 48618.835 | T33: =T91 -> 46112 | U33: =(Q33/$X$28*$J$28) -> 60161.985 | W33: =W91 -> 46106 | Y33: Geda | Z33: =Z18*0.85 -> 8386.6667
B34: 4 | L34: 4 | M34: 4. DC Equipment | N34: AC Installation Complete | P34: 0.2 | Q34: =$O$32*P34 -> 64825.114 | T34: =T92 -> 46173 | U34: =(Q34/$X$28*$J$28) -> 80215.981 | W34: =W92 -> 46167 | Y34: Logistics | Z34: 0
B35: 4 | L35: 4 | M35: 4. DC Equipment | N35: DC Installation Complete | P35: 0.25 | Q35: =$O$32*P35 -> 81031.392 | T35: =T93 -> 46173 | U35: =(Q35/$X$28*$J$28) -> 100269.98 | W35: =W93 -> 46170 | Y35: Trenching | Z35: 0
B36: 4 | L36: 4 | M36: 4. DC Equipment | N36: Commissioning Complete | P36: 0.1 | Q36: =$O$32*P36 -> 32412.557 | T36: =T94 -> 46203 | U36: =(Q36/$X$28*$J$28) -> 40107.99 | W36: =W94 -> 46182 | Y36: Other | Z36: 0
B37: 4 | L37: 4 | M37: 4. DC Equipment | N37: Site De-establisment | P37: 0.1 | Q37: =$O$32*P37 -> 32412.557 | T37: =T95 -> 46203 | U37: =(Q37/$X$28*$J$28) -> 40107.99 | W37: =W95 -> 46183 | Y37: Other | Z37: 0
B38: 4 | L38: 4 | M38: 4. DC Equipment | N38: Handover Document Complete | P38: 0.05 | Q38: =$O$32*P38 -> 16206.278 | T38: =T96 -> 46203 | U38: =(Q38/$X$28*$J$28) -> 20053.995 | W38: =W96 -> 46183 | Y38: Total | Z38: =SUM(Z27:Z37) -> 1260341
B39: 4 | L39: 4 | M39: 4. DC Equipment | N39: End of Defects Period | P39: 0.05 | Q39: =$O$32*P39 -> 16206.278 | T39: =T97 -> 46234 | U39: =(Q39/$X$28*$J$28) -> 20053.995 | W39: =W97 -> 46206 | Y39: R/Wp | Z39: =Z38/'Project Plan'!$E$3/1000 -> 1.5754263
B40: 4 | L40: 4 | M40: 4. DC Equipment | T40: =IF(W40>1,EOMONTH(W40,0),"") | U40: =(Q40/$X$28*$J$28) -> 0
B41: 4 | L41: 4 | M41: 4. DC Equipment | T41: =IF(W41>1,EOMONTH(W41,0),"") | U41: =(Q41/$X$28*$J$28) -> 0
B42: 4 | L42: 4 | M42: 4. DC Equipment | T42: =IF(W42>1,EOMONTH(W42,0),"") | U42: =(Q42/$X$28*$J$28) -> 0
T43: =IF(W43>1,EOMONTH(W43,0),"")
...

Sheet Cashflow
D1: [RT: Double Check the first date is always a MONDAY] | F1: 46027 | G1: =F1+7 -> 46034 | H1: =G1+7 -> 46041 | I1: =H1+7 -> 46048 | J1: =I1+7 -> 46055 | K1: =J1+7 -> 46062 | L1: =K1+7 -> 46069 | M1: =L1+7 -> 46076 | N1: =M1+7 -> 46083 | ... KE1: =KD1+7 -> 48022
A2: PLANNED | C2: CHECK | D2: CHECK
B3: Planned Revenue | C3: ='Revenue Tracking'!D4 -> 5965612.5 | D3: =SUM(F3:KE3) -> 5965612.5 | F3: =SUMIFS('Revenue Tracking'!$F$13:$F$19, 'Revenue Tracking'!$H$13:$H$19, ">="&F1,'Revenue Tracking'!$H$13:$H$19, "<"&G1) -> 0 | G3: =SUMIFS('Revenue Tracking'!$F$13:$F$19, 'Revenue Tracking'!$H$13:$H$19, ">="&G1,'Revenue Tracking'!$H$13:$H$19, "<"&H1) -> 0 | H3: =SUMIFS('Revenue Tracking'!$F$13:$F$19, 'Revenue Tracking'!$H$13:$H$19, ">="&H1,'Revenue Tracking'!$H$13:$H$19, "<"&I1) -> 0 | I3: =SUMIFS('Revenue Tracking'!$F$13:$F$19, 'Revenue Tracking'!$H$13:$H$19, ">="&I1,'Revenue Tracking'!$H$13:$H$19, "<"&J1) -> 0 | J3: =SUMIFS('Revenue Tracking'!$F$13:$F$19, 'Revenue Tracking'!$H$13:$H$19, ">="&J1,'Revenue Tracking'!$H$13:$H$19, "<"&K1) -> 0 | K3: =SUMIFS('Revenue Tracking'!$F$13:$F$19, 'Revenue Tracking'!$H$13:$H$19, ">="&K1,'Revenue Tracking'!$H$13:$H$19, "<"&L1) -> 0 | L3: =SUMIFS('Revenue Tracking'!$F$13:$F$19, 'Revenue Tracking'!$H$13:$H$19, ">="&L1,'Revenue Tracking'!$H$13:$H$19, "<"&M1) -> 0 | M3: =SUMIFS('Revenue Tracking'!$F$13:$F$19, 'Revenue Tracking'!$H$13:$H$19, ">="&M1,'Revenue Tracking'!$H$13:$H$19, "<"&N1) -> 2087964.4 | ... KD3: =SUMIFS('Revenue Tracking'!$F$13:$F$19, 'Revenue Tracking'!$H$13:$H$19, ">="&KD1,'Revenue Tracking'!$H$13:$H$19, "<"&KE1) -> 0 | KE3: =SUMIFS('Revenue Tracking'!$F$13:$F$19, 'Revenue Tracking'!$H$13:$H$19, ">="&KE1,'Revenue Tracking'!$H$13:$H$19, "<"&#REF!) -> 0
B4: Planned Revenue - Cumulative | F4: =F3 -> 0 | G4: =F4+G3 -> 0 | H4: =G4+H3 -> 0 | I4: =H4+I3 -> 0 | J4: =I4+J3 -> 0 | K4: =J4+K3 -> 0 | L4: =K4+L3 -> 0 | M4: =L4+M3 -> 2087964.4 | N4: =M4+N3 -> 2087964.4 | ... KE4: =KD4+KE3 -> 5965612.5
B5: Planned Expenditure | C5: ='Revenue Tracking'!D5 -> 5125523.7 | D5: =SUM(F5:KE5) -> 5125523.7 | F5: =SUMIFS('Expenditure Breakdown'!$G$6:$G$166, 'Expenditure Breakdown'!$H$6:$H$166, ">="&F1,'Expenditure Breakdown'!$H$6:$H$166, "<"&G1) -> 0 | G5: =SUMIFS('Expenditure Breakdown'!$G$6:$G$166, 'Expenditure Breakdown'!$H$6:$H$166, ">="&G1,'Expenditure Breakdown'!$H$6:$H$166, "<"&H1) -> 0 | H5: =SUMIFS('Expenditure Breakdown'!$G$6:$G$166, 'Expenditure Breakdown'!$H$6:$H$166, ">="&H1,'Expenditure Breakdown'!$H$6:$H$166, "<"&I1) -> 0 | I5: =SUMIFS('Expenditure Breakdown'!$G$6:$G$166, 'Expenditure Breakdown'!$H$6:$H$166, ">="&I1,'Expenditure Breakdown'!$H$6:$H$166, "<"&J1) -> 0 | J5: =SUMIFS('Expenditure Breakdown'!$G$6:$G$166, 'Expenditure Breakdown'!$H$6:$H$166, ">="&J1,'Expenditure Breakdown'!$H$6:$H$166, "<"&K1) -> 0 | K5: =SUMIFS('Expenditure Breakdown'!$G$6:$G$166, 'Expenditure Breakdown'!$H$6:$H$166, ">="&K1,'Expenditure Breakdown'!$H$6:$H$166, "<"&L1) -> 0 | L5: =SUMIFS('Expenditure Breakdown'!$G$6:$G$166, 'Expenditure Breakdown'!$H$6:$H$166, ">="&L1,'Expenditure Breakdown'!$H$6:$H$166, "<"&M1) -> 0 | M5: =SUMIFS('Expenditure Breakdown'!$G$6:$G$166, 'Expenditure Breakdown'!$H$6:$H$166, ">="&M1,'Expenditure Breakdown'!$H$6:$H$166, "<"&N1) -> 0 | ... KD5: =SUMIFS('Expenditure Breakdown'!$G$6:$G$166, 'Expenditure Breakdown'!$H$6:$H$166, ">="&KD1,'Expenditure Breakdown'!$H$6:$H$166, "<"&KE1) -> 0 | KE5: =SUMIFS('Expenditure Breakdown'!$G$6:$G$166, 'Expenditure Breakdown'!$H$6:$H$166, ">="&KE1,'Expenditure Breakdown'!$H$6:$H$166, "<"&#REF!) -> 0
B6: Planned Expenditure - Cumulative | F6: =F5 -> 0 | G6: =F6+G5 -> 0 | H6: =G6+H5 -> 0 | I6: =H6+I5 -> 0 | J6: =I6+J5 -> 0 | K6: =J6+K5 -> 0 | L6: =K6+L5 -> 0 | M6: =L6+M5 -> 0 | N6: =M6+N5 -> 0 | ... KE6: =KD6+KE5 -> 5125523.7
B7: PLANNED CashFlow | F7: =F4-F6 -> 0 | G7: =G4-G6 -> 0 | H7: =H4-H6 -> 0 | I7: =I4-I6 -> 0 | J7: =J4-J6 -> 0 | K7: =K4-K6 -> 0 | L7: =L4-L6 -> 0 | M7: =M4-M6 -> 2087964.4 | ... KE7: =KE4-KE6 -> 840088.82
A8: ACTUAL | C8: CHECK | D8: CHECK
B9: Actual + Planned Revenue | C9: ='Revenue Tracking'!F4 -> 5965612.5 | D9: =SUM(F9:KE9) -> 5965612.5 | F9: =SUMIFS('Revenue Tracking'!$F$13:$F$19, 'Revenue Tracking'!$P$13:$P$19, ">="&F1,'Revenue Tracking'!$P$13:$P$19, "<"&G1) -> 0 | G9: =SUMIFS('Revenue Tracking'!$F$13:$F$19, 'Revenue Tracking'!$P$13:$P$19, ">="&G1,'Revenue Tracking'!$P$13:$P$19, "<"&H1) -> 0 | H9: =SUMIFS('Revenue Tracking'!$F$13:$F$19, 'Revenue Tracking'!$P$13:$P$19, ">="&H1,'Revenue Tracking'!$P$13:$P$19, "<"&I1) -> 0 | I9: =SUMIFS('Revenue Tracking'!$F$13:$F$19, 'Revenue Tracking'!$P$13:$P$19, ">="&I1,'Revenue Tracking'!$P$13:$P$19, "<"&J1) -> 0 | J9: =SUMIFS('Revenue Tracking'!$F$13:$F$19, 'Revenue Tracking'!$P$13:$P$19, ">="&J1,'Revenue Tracking'!$P$13:$P$19, "<"&K1) -> 0 | K9: =SUMIFS('Revenue Tracking'!$F$13:$F$19, 'Revenue Tracking'!$P$13:$P$19, ">="&K1,'Revenue Tracking'!$P$13:$P$19, "<"&L1) -> 0 | L9: =SUMIFS('Revenue Tracking'!$F$13:$F$19, 'Revenue Tracking'!$P$13:$P$19, ">="&L1,'Revenue Tracking'!$P$13:$P$19, "<"&M1) -> 0 | M9: =SUMIFS('Revenue Tracking'!$F$13:$F$19, 'Revenue Tracking'!$P$13:$P$19, ">="&M1,'Revenue Tracking'!$P$13:$P$19, "<"&N1) -> 0 | ... KD9: =SUMIFS('Revenue Tracking'!$F$13:$F$19, 'Revenue Tracking'!$P$13:$P$19, ">="&KD1,'Revenue Tracking'!$P$13:$P$19, "<"&KE1) -> 0 | KE9: =SUMIFS('Revenue Tracking'!$F$13:$F$19, 'Revenue Tracking'!$P$13:$P$19, ">="&KE1,'Revenue Tracking'!$P$13:$P$19, "<"&#REF!) -> 0
B10: Actual + Planned Revenue - Cumulative | F10: =F9 -> 0 | G10: =F10+G9 -> 0 | H10: =G10+H9 -> 0 | I10: =H10+I9 -> 0 | J10: =I10+J9 -> 0 | K10: =J10+K9 -> 0 | L10: =K10+L9 -> 0 | M10: =L10+M9 -> 0 | N10: =M10+N9 -> 0 | ... KE10: =KD10+KE9 -> 5965612.5
B11: Actual + Planned Expenditure | C11: ='Revenue Tracking'!F5 -> 4357754.6 | D11: =SUM(F11:KE11) -> 4357754.6 | F11: =SUMIFS('Expenditure Breakdown'!$Q$6:$Q$166, 'Expenditure Breakdown'!$W$6:$W$166, ">="&F1,'Expenditure Breakdown'!$W$6:$W$166, "<"&G1) -> 0 | G11: =SUMIFS('Expenditure Breakdown'!$Q$6:$Q$166, 'Expenditure Breakdown'!$W$6:$W$166, ">="&G1,'Expenditure Breakdown'!$W$6:$W$166, "<"&H1) -> 0 | H11: =SUMIFS('Expenditure Breakdown'!$Q$6:$Q$166, 'Expenditure Breakdown'!$W$6:$W$166, ">="&H1,'Expenditure Breakdown'!$W$6:$W$166, "<"&I1) -> 0 | I11: =SUMIFS('Expenditure Breakdown'!$Q$6:$Q$166, 'Expenditure Breakdown'!$W$6:$W$166, ">="&I1,'Expenditure Breakdown'!$W$6:$W$166, "<"&J1) -> 0 | J11: =SUMIFS('Expenditure Breakdown'!$Q$6:$Q$166, 'Expenditure Breakdown'!$W$6:$W$166, ">="&J1,'Expenditure Breakdown'!$W$6:$W$166, "<"&K1) -> 0 | K11: =SUMIFS('Expenditure Breakdown'!$Q$6:$Q$166, 'Expenditure Breakdown'!$W$6:$W$166, ">="&K1,'Expenditure Breakdown'!$W$6:$W$166, "<"&L1) -> 0 | L11: =SUMIFS('Expenditure Breakdown'!$Q$6:$Q$166, 'Expenditure Breakdown'!$W$6:$W$166, ">="&L1,'Expenditure Breakdown'!$W$6:$W$166, "<"&M1) -> 0 | M11: =SUMIFS('Expenditure Breakdown'!$Q$6:$Q$166, 'Expenditure Breakdown'!$W$6:$W$166, ">="&M1,'Expenditure Breakdown'!$W$6:$W$166, "<"&N1) -> 0 | ... KD11: =SUMIFS('Expenditure Breakdown'!$Q$6:$Q$166, 'Expenditure Breakdown'!$W$6:$W$166, ">="&KD1,'Expenditure Breakdown'!$W$6:$W$166, "<"&KE1) -> 0 | KE11: =SUMIFS('Expenditure Breakdown'!$Q$6:$Q$166, 'Expenditure Breakdown'!$W$6:$W$166, ">="&KE1,'Expenditure Breakdown'!$W$6:$W$166, "<"&#REF!) -> 0
B12: Actual + Planned Expenditure - Cumulative | F12: =F11 -> 0 | G12: =F12+G11 -> 0 | H12: =G12+H11 -> 0 | I12: =H12+I11 -> 0 | J12: =I12+J11 -> 0 | K12: =J12+K11 -> 0 | L12: =K12+L11 -> 0 | M12: =L12+M11 -> 0 | N12: =M12+N11 -> 0 | ... KE12: =KD12+KE11 -> 4357754.6
B14: ACTUAL CashFlow | F14: =F10-F12 -> 0 | G14: =G10-G12 -> 0 | H14: =H10-H12 -> 0 | I14: =I10-I12 -> 0 | J14: =J10-J12 -> 0 | K14: =K10-K12 -> 0 | L14: =L10-L12 -> 0 | M14: =M10-M12 -> 0 | ... KE14: =KE10-KE12 -> 1607857.9
C16: CHECK | D16: CHECK
B17: Revenue Recognition | C17: =C3-D17 -> 0 | D17: =SUM(F17:KE17) -> 5965612.5 | F17: =SUMIFS('Expenditure Breakdown'!$U$6:$U$166, 'Expenditure Breakdown'!$T$6:$T$166, ">="&F1,'Expenditure Breakdown'!$T$6:$T$166, "<"&G1) -> 0 | G17: =SUMIFS('Expenditure Breakdown'!$U$6:$U$166, 'Expenditure Breakdown'!$T$6:$T$166, ">="&G1,'Expenditure Breakdown'!$T$6:$T$166, "<"&H1) -> 0 | H17: =SUMIFS('Expenditure Breakdown'!$U$6:$U$166, 'Expenditure Breakdown'!$T$6:$T$166, ">="&H1,'Expenditure Breakdown'!$T$6:$T$166, "<"&I1) -> 0 | I17: =SUMIFS('Expenditure Breakdown'!$U$6:$U$166, 'Expenditure Breakdown'!$T$6:$T$166, ">="&I1,'Expenditure Breakdown'!$T$6:$T$166, "<"&J1) -> 0 | J17: =SUMIFS('Expenditure Breakdown'!$U$6:$U$166, 'Expenditure Breakdown'!$T$6:$T$166, ">="&J1,'Expenditure Breakdown'!$T$6:$T$166, "<"&K1) -> 0 | K17: =SUMIFS('Expenditure Breakdown'!$U$6:$U$166, 'Expenditure Breakdown'!$T$6:$T$166, ">="&K1,'Expenditure Breakdown'!$T$6:$T$166, "<"&L1) -> 0 | L17: =SUMIFS('Expenditure Breakdown'!$U$6:$U$166, 'Expenditure Breakdown'!$T$6:$T$166, ">="&L1,'Expenditure Breakdown'!$T$6:$T$166, "<"&M1) -> 0 | M17: =SUMIFS('Expenditure Breakdown'!$U$6:$U$166, 'Expenditure Breakdown'!$T$6:$T$166, ">="&M1,'Expenditure Breakdown'!$T$6:$T$166, "<"&N1) -> 121112.07 | ... KD17: =SUMIFS('Expenditure Breakdown'!$U$6:$U$166, 'Expenditure Breakdown'!$T$6:$T$166, ">="&KD1,'Expenditure Breakdown'!$T$6:$T$166, "<"&KE1) -> 0 | KE17: =SUMIFS('Expenditure Breakdown'!$U$6:$U$166, 'Expenditure Breakdown'!$T$6:$T$166, ">="&KE1,'Expenditure Breakdown'!$T$6:$T$166, "<"&#REF!) -> 0
B18: Revenue Recognition Cumulative | C18: =D17-D18 -> 0 | D18: =MAX(F18:KE18) -> 5965612.5 | F18: =F17 -> 0 | G18: =F18+G17 -> 0 | H18: =G18+H17 -> 0 | I18: =H18+I17 -> 0 | J18: =I18+J17 -> 0 | K18: =J18+K17 -> 0 | L18: =K18+L17 -> 0 | M18: =L18+M17 -> 121112.07 | N18: =M18+N17 -> 121112.07 | ... KE18: =KD18+KE17 -> 5965612.5

Sheet Finance - Revenue
A3: Sum of REVENUE RECOGNITION AMOUNT | B3: Column Labels
A4: Row Labels | B4: (blank) | D4: 46053 | E4: 46142 | F4: 46112 | G4: 46173 | H4: 46203 | I4: 46234 | J4: 46081 | K4: Grand Total
A5: (blank)
A6: 1. Panels | C6: 0 | E6: 2183668.4 | K6: 2183668.4
A7: 2. Inverters | B7: 0 | C7: 0 | E7: 576470.59 | K7: 576470.59
A8: 3. Mounting Structures | C8: 0 | E8: 376621.18 | K8: 376621.18
A9: 4. DC Equipment | C9: 0 | E9: 406639.97 | F9: 40107.99 | G9: 80215.981 | H9: 200539.95 | I9: 20053.995 | K9: 747557.88
A10: 5. Monitoring | C10: 0 | E10: 204705.88 | K10: 204705.88
A11: 6. AC Equipment | C11: 0 | E11: 79145.501 | F11: 277970.23 | G11: 105527.33 | H11: 263818.34 | I11: 26381.834 | K11: 752843.24
A12: 8. Product Add On
A13: 9. AC & DC installation | C13: 0 | E13: 106053.33 | F13: 70702.222 | G13: 141404.44 | H13: 353511.11 | I13: 35351.111 | K13: 707022.22
A14: 10. Site Logistics | C14: 0 | E14: 9096.4489 | F14: 6064.2993 | G14: 125360.42 | H14: 30321.496 | I14: 3032.1496 | K14: 173874.81
A15: 11. Due Dilligence | C15: 0 | H15: 126217.56 | I15: 29364.662 | K15: 155582.22
A16: 13. Engineering | C16: 0 | H16: 71710.489 | K16: 71710.489
A17: 14. General Expenses | C17: 0 | D17: 3888.8889 | E17: 3888.8889 | F17: 3888.8889 | J17: 3888.8889 | K17: 15555.556
A18: 15. Service Add On
A19: 12. BDP Commission
A20: 7.BESS
A21: Grand Total | B21: 0 | C21: 0 | D21: 3888.8889 | E21: 3946290.2 | F21: 398733.63 | G21: 452508.18 | H21: 1046118.9 | I21: 114183.75 | J21: 3888.8889 | K21: 5965612.5

Sheet Finance - COS
A3: Sum of Actual Total | B3: Column Labels
A4: Row Labels | B4: (blank) | D4: 46053 | E4: 46142 | F4: 46112 | G4: 46173 | H4: 46203 | I4: 46234 | J4: 46081 | K4: Grand Total
A5: (blank)
A6: 1. Panels | E6: 1600840 | K6: 1600840
A7: 2. Inverters | E7: 476000 | K7: 476000
A8: 3. Mounting Structures | E8: 280000 | K8: 280000
A9: 4. DC Equipment | E9: 328618.84 | F9: 32412.557 | G9: 64825.114 | H9: 162062.78 | I9: 16206.278 | K9: 604125.57
A10: 5. Monitoring | E10: 49500 | K10: 49500
A11: 6. AC Equipment | E11: 42464.593 | F11: 149141.68 | G11: 56619.458 | H11: 141548.64 | I11: 14154.864 | K11: 403929.24
A12: 8. Product Add On
A13: 9. AC & DC installation | E13: 81130.8 | F13: 54087.2 | G13: 108174.4 | H13: 270436 | I13: 27043.6 | K13: 540872
A14: 10. Site Logistics | E14: 7712.135 | F14: 5141.4233 | G14: 106282.85 | H14: 25707.117 | I14: 2570.7117 | K14: 147414.23
A15: 11. Due Dilligence | C15: 0 | H15: 86000 | I15: 20008 | K15: 106008
A16: 13. Engineering | H16: 74570.156 | K16: 74570.156
A17: 14. General Expenses | D17: 3500 | E17: 3500 | F17: 3500 | J17: 3500 | K17: 14000
A18: 15. Service Add On
A19: 12. BDP Commission | C19: 0 | K19: 0
A20: 7.BESS
A21: Grand Total | C21: 0 | D21: 3500 | E21: 2869766.4 | F21: 244282.86 | G21: 335901.82 | H21: 760324.7 | I21: 79983.455 | J21: 3500 | K21: 4297259.2

Sheet Data
C2: Public holidays | F2: Drop down list
C3: 45658 | D3: New Years Day | F3: Approved
C4: 45737 | D4: Human Rights day | F4: Pending
C5: 45765 | D5: Good Friday | F5: Declined
C6: 45768 | D6: Family Day | F6: Abanded
C7: 45774 | D7: Freedom Day
C8: 45765 | D8: Freedom DayObserved
C9: 45778 | D9: Workers day
C10: 45824 | D10: Youth Day Holiday
C11: 45878 | D11: Womens Day
C12: 45924 | D12: Heritage Day
C13: 46007 | D13: Day of Reconciliation | H13: Manual dates
C14: 46016 | D14: Christmas Day
C15: 46017 | D15: Day of Goodwill
C16: 46006 | D16: Builders Break
C17: 46007 | D17: Builders Break
C18: 46008 | D18: Builders Break
C19: 46009 | D19: Builders Break
C20: 46010 | D20: Builders Break
C21: 46011 | D21: Builders Break
C22: 46012 | D22: Builders Break
C23: 46013 | D23: Builders Break
C24: 46014 | D24: Builders Break
C25: 46015 | D25: Builders Break
... C60: 46382 | D60: Day of Goodwill
