Workbook
Name Inverter_Capacity: #REF!
Name Inverter_Supplier: #REF!
Name Project_Size: 'Certificate - Financial Close'!Projectsize
Name Project_Size: 'Finance (2)'!Projectsize
Name Project_Size: Projectsize
Name Projectsize: #REF!
Name Projectsize: #REF!
Name Projectsize: 'Project Margins'!$K$5
Name Security_Serv: #REF!
Name Security_Serv: #REF!
Name Security_Serv: #REF!
Name SSS: #REF!
Name SSS: #REF!
Name SSS: #REF!
Name USD_ZAR: #REF!

Sheet Sheet1
A1: PROJECT PLAN
A2: # | B2: Project Milestone | C2: Planned Start Date | D2: Duration (Work Days) | E2: Planned End Date | F2: Actual Start Date | H2: Actual End Date | J2: Comments | L2: =C3 -> 43831 | M2: =L2+3 -> 43834 | N2: =M2+7 -> 43841 | O2: =N2+7 -> 43848 | P2: =O2+7 -> 43855 | Q2: =P2+6 -> 43861 | R2: =Q2+1 -> 43862 | S2: =R2+7 -> 43869 | T2: =S2+7 -> 43876 | U2: =T2+7 -> 43883 | V2: =U2+6 -> 43889 | W2: =V2+7 -> 43896 | X2: =W2+7 -> 43903 | Y2: =X2+7 -> 43910 | Z2: =Y2+7 -> 43917 | AA2: =Z2+3 -> 43920 | AB2: =AA2+4 -> 43924 | AC2: =AB2+7 -> 43931 | AD2: =AC2+7 -> 43938 | AE2: =AD2+7 -> 43945 | AF2: =AE2+6 -> 43951 | AG2: =AF2+2 -> 43953 | AH2: =AG2+7 -> 43960 | AI2: =AH2+7 -> 43967 | AJ2: =AI2+7 -> 43974 | AK2: =AJ2+7 -> 43981 | AL2: =AK2+1 -> 43982 | AM2: =AL2+6 -> 43988 | AN2: =AM2+7 -> 43995 | AO2: =AN2+7 -> 44002 | AP2: =AO2+7 -> 44009 | AQ2: =AP2+3 -> 44012 | AR2: =AQ2+4 -> 44016 | AS2: =AR2+7 -> 44023 | AT2: =AS2+7 -> 44030 | AU2: =AT2+7 -> 44037 | AV2: =AU2+6 -> 44043 | AW2: =AV2+1 -> 44044 | AX2: =AW2+7 -> 44051 | AY2: =AX2+7 -> 44058 | AZ2: =AY2+7 -> 44065 | BA2: =AZ2+7 -> 44072 | BB2: =BA2+2 -> 44074 | BC2: =BB2+5 -> 44079 | BD2: =BC2+7 -> 44086 | BE2: =BD2+7 -> 44093 | BF2: =BE2+7 -> 44100 | BG2: =BF2+4 -> 44104
A3: 1 | B3: Contract Signature | C3: 43831 | D3: 1 | E3: 43832 | F3: 43831 | G3: 1 | H3: 43832 | L3: =IF(AND($F3<(L$2+7),$F3>L$2),1, IF(AND($H3<L$2+7,$H3>L$2),3, IF(AND($F3<=L$2, $H3>=L$2), 2, "" ))) -> 3 | M3: =IF(AND($F3<(M$2+7),$F3>M$2),1, IF(AND($H3<M$2+7,$H3>M$2),3, IF(AND($F3<=M$2, $H3>=M$2), 2, "" ))) | N3: =IF(AND($F3<(N$2+7),$F3>N$2),1, IF(AND($H3<N$2+7,$H3>N$2),3, IF(AND($F3<=N$2, $H3>=N$2), 2, "" ))) | O3: =IF(AND($F3<(O$2+7),$F3>O$2),1, IF(AND($H3<O$2+7,$H3>O$2),3, IF(AND($F3<=O$2, $H3>=O$2), 2, "" ))) | P3: =IF(AND($F3<(P$2+7),$F3>P$2),1, IF(AND($H3<P$2+7,$H3>P$2),3, IF(AND($F3<=P$2, $H3>=P$2), 2, "" ))) | Q3: =IF(AND($F3<(Q$2+7),$F3>Q$2),1, IF(AND($H3<Q$2+7,$H3>Q$2),3, IF(AND($F3<=Q$2, $H3>=Q$2), 2, "" ))) | R3: =IF(AND($F3<(R$2+7),$F3>R$2),1, IF(AND($H3<R$2+7,$H3>R$2),3, IF(AND($F3<=R$2, $H3>=R$2), 2, "" ))) | S3: =IF(AND($F3<(S$2+7),$F3>S$2),1, IF(AND($H3<S$2+7,$H3>S$2),3, IF(AND($F3<=S$2, $H3>=S$2), 2, "" ))) | ... AQ3: =IF(AND($F3<(AQ$2+7),$F3>AQ$2),1, IF(AND($H3<AQ$2+7,$H3>AQ$2),3, IF(AND($F3<=AQ$2, $H3>=AQ$2), 2, "" )))
A4: A | B4: PAYMENT MILESTONE 1: DEPOSIT | C4: 43832 | D4: 1 | E4: 43833 | F4: 43832 | G4: 1 | H4: 43833 | L4: =IF(AND($F4<(L$2+7),$F4>L$2),1, IF(AND($H4<L$2+7,$H4>L$2),3, IF(AND($F4<=L$2, $H4>=L$2), 2, "" ))) -> 1 | M4: =IF(AND($F4<(M$2+7),$F4>M$2),1, IF(AND($H4<M$2+7,$H4>M$2),3, IF(AND($F4<=M$2, $H4>=M$2), 2, "" ))) | N4: =IF(AND($F4<(N$2+7),$F4>N$2),1, IF(AND($H4<N$2+7,$H4>N$2),3, IF(AND($F4<=N$2, $H4>=N$2), 2, "" ))) | O4: =IF(AND($F4<(O$2+7),$F4>O$2),1, IF(AND($H4<O$2+7,$H4>O$2),3, IF(AND($F4<=O$2, $H4>=O$2), 2, "" ))) | P4: =IF(AND($F4<(P$2+7),$F4>P$2),1, IF(AND($H4<P$2+7,$H4>P$2),3, IF(AND($F4<=P$2, $H4>=P$2), 2, "" ))) | Q4: =IF(AND($F4<(Q$2+7),$F4>Q$2),1, IF(AND($H4<Q$2+7,$H4>Q$2),3, IF(AND($F4<=Q$2, $H4>=Q$2), 2, "" ))) | R4: =IF(AND($F4<(R$2+7),$F4>R$2),1, IF(AND($H4<R$2+7,$H4>R$2),3, IF(AND($F4<=R$2, $H4>=R$2), 2, "" ))) | S4: =IF(AND($F4<(S$2+7),$F4>S$2),1, IF(AND($H4<S$2+7,$H4>S$2),3, IF(AND($F4<=S$2, $H4>=S$2), 2, "" ))) | ... AQ4: =IF(AND($F4<(AQ$2+7),$F4>AQ$2),1, IF(AND($H4<AQ$2+7,$H4>AQ$2),3, IF(AND($F4<=AQ$2, $H4>=AQ$2), 2, "" )))
A5: 2 | B5: Structural and Electrical Due Diligences | C5: 43833 | D5: 5 | E5: 43840 | F5: 43833 | G5: 5 | H5: 43840 | L5: =IF(AND($F5<(L$2+7),$F5>L$2),1, IF(AND($H5<L$2+7,$H5>L$2),3, IF(AND($F5<=L$2, $H5>=L$2), 2, "" ))) -> 1 | M5: =IF(AND($F5<(M$2+7),$F5>M$2),1, IF(AND($H5<M$2+7,$H5>M$2),3, IF(AND($F5<=M$2, $H5>=M$2), 2, "" ))) -> 3 | N5: =IF(AND($F5<(N$2+7),$F5>N$2),1, IF(AND($H5<N$2+7,$H5>N$2),3, IF(AND($F5<=N$2, $H5>=N$2), 2, "" ))) | O5: =IF(AND($F5<(O$2+7),$F5>O$2),1, IF(AND($H5<O$2+7,$H5>O$2),3, IF(AND($F5<=O$2, $H5>=O$2), 2, "" ))) | P5: =IF(AND($F5<(P$2+7),$F5>P$2),1, IF(AND($H5<P$2+7,$H5>P$2),3, IF(AND($F5<=P$2, $H5>=P$2), 2, "" ))) | Q5: =IF(AND($F5<(Q$2+7),$F5>Q$2),1, IF(AND($H5<Q$2+7,$H5>Q$2),3, IF(AND($F5<=Q$2, $H5>=Q$2), 2, "" ))) | R5: =IF(AND($F5<(R$2+7),$F5>R$2),1, IF(AND($H5<R$2+7,$H5>R$2),3, IF(AND($F5<=R$2, $H5>=R$2), 2, "" ))) | S5: =IF(AND($F5<(S$2+7),$F5>S$2),1, IF(AND($H5<S$2+7,$H5>S$2),3, IF(AND($F5<=S$2, $H5>=S$2), 2, "" ))) | ... AQ5: =IF(AND($F5<(AQ$2+7),$F5>AQ$2),1, IF(AND($H5<AQ$2+7,$H5>AQ$2),3, IF(AND($F5<=AQ$2, $H5>=AQ$2), 2, "" )))
A6: 3 | B6: Design Confirmation | C6: 43841 | D6: 2 | E6: 43844 | F6: 43841 | G6: 2 | H6: 43844 | L6: =IF(AND($F6<(L$2+7),$F6>L$2),1, IF(AND($H6<L$2+7,$H6>L$2),3, IF(AND($F6<=L$2, $H6>=L$2), 2, "" ))) | M6: =IF(AND($F6<(M$2+7),$F6>M$2),1, IF(AND($H6<M$2+7,$H6>M$2),3, IF(AND($F6<=M$2, $H6>=M$2), 2, "" ))) | N6: =IF(AND($F6<(N$2+7),$F6>N$2),1, IF(AND($H6<N$2+7,$H6>N$2),3, IF(AND($F6<=N$2, $H6>=N$2), 2, "" ))) -> 3 | O6: =IF(AND($F6<(O$2+7),$F6>O$2),1, IF(AND($H6<O$2+7,$H6>O$2),3, IF(AND($F6<=O$2, $H6>=O$2), 2, "" ))) | P6: =IF(AND($F6<(P$2+7),$F6>P$2),1, IF(AND($H6<P$2+7,$H6>P$2),3, IF(AND($F6<=P$2, $H6>=P$2), 2, "" ))) | Q6: =IF(AND($F6<(Q$2+7),$F6>Q$2),1, IF(AND($H6<Q$2+7,$H6>Q$2),3, IF(AND($F6<=Q$2, $H6>=Q$2), 2, "" ))) | R6: =IF(AND($F6<(R$2+7),$F6>R$2),1, IF(AND($H6<R$2+7,$H6>R$2),3, IF(AND($F6<=R$2, $H6>=R$2), 2, "" ))) | S6: =IF(AND($F6<(S$2+7),$F6>S$2),1, IF(AND($H6<S$2+7,$H6>S$2),3, IF(AND($F6<=S$2, $H6>=S$2), 2, "" ))) | ... AQ6: =IF(AND($F6<(AQ$2+7),$F6>AQ$2),1, IF(AND($H6<AQ$2+7,$H6>AQ$2),3, IF(AND($F6<=AQ$2, $H6>=AQ$2), 2, "" )))
A7: 4 | B7: Equipment Procurement | C7: 43833 | E7: 43949 | F7: 43833 | H7: 43949 | L7: =IF(AND($F7<(L$2+7),$F7>L$2),1, IF(AND($H7<L$2+7,$H7>L$2),3, IF(AND($F7<=L$2, $H7>=L$2), 2, "" ))) -> 1 | M7: =IF(AND($F7<(M$2+7),$F7>M$2),1, IF(AND($H7<M$2+7,$H7>M$2),3, IF(AND($F7<=M$2, $H7>=M$2), 2, "" ))) -> 2 | N7: =IF(AND($F7<(N$2+7),$F7>N$2),1, IF(AND($H7<N$2+7,$H7>N$2),3, IF(AND($F7<=N$2, $H7>=N$2), 2, "" ))) -> 2 | O7: =IF(AND($F7<(O$2+7),$F7>O$2),1, IF(AND($H7<O$2+7,$H7>O$2),3, IF(AND($F7<=O$2, $H7>=O$2), 2, "" ))) -> 2 | P7: =IF(AND($F7<(P$2+7),$F7>P$2),1, IF(AND($H7<P$2+7,$H7>P$2),3, IF(AND($F7<=P$2, $H7>=P$2), 2, "" ))) -> 2 | Q7: =IF(AND($F7<(Q$2+7),$F7>Q$2),1, IF(AND($H7<Q$2+7,$H7>Q$2),3, IF(AND($F7<=Q$2, $H7>=Q$2), 2, "" ))) -> 2 | R7: =IF(AND($F7<(R$2+7),$F7>R$2),1, IF(AND($H7<R$2+7,$H7>R$2),3, IF(AND($F7<=R$2, $H7>=R$2), 2, "" ))) -> 2 | S7: =IF(AND($F7<(S$2+7),$F7>S$2),1, IF(AND($H7<S$2+7,$H7>S$2),3, IF(AND($F7<=S$2, $H7>=S$2), 2, "" ))) -> 2 | ... AQ7: =IF(AND($F7<(AQ$2+7),$F7>AQ$2),1, IF(AND($H7<AQ$2+7,$H7>AQ$2),3, IF(AND($F7<=AQ$2, $H7>=AQ$2), 2, "" )))
B8: Panel Procurement | C8: 43833 | D8: 5 | E8: 43840 | F8: 43833 | G8: 5 | H8: 43840 | L8: =IF(AND($F8<(L$2+7),$F8>L$2),1, IF(AND($H8<L$2+7,$H8>L$2),3, IF(AND($F8<=L$2, $H8>=L$2), 2, "" ))) -> 1 | M8: =IF(AND($F8<(M$2+7),$F8>M$2),1, IF(AND($H8<M$2+7,$H8>M$2),3, IF(AND($F8<=M$2, $H8>=M$2), 2, "" ))) -> 3 | N8: =IF(AND($F8<(N$2+7),$F8>N$2),1, IF(AND($H8<N$2+7,$H8>N$2),3, IF(AND($F8<=N$2, $H8>=N$2), 2, "" ))) | O8: =IF(AND($F8<(O$2+7),$F8>O$2),1, IF(AND($H8<O$2+7,$H8>O$2),3, IF(AND($F8<=O$2, $H8>=O$2), 2, "" ))) | P8: =IF(AND($F8<(P$2+7),$F8>P$2),1, IF(AND($H8<P$2+7,$H8>P$2),3, IF(AND($F8<=P$2, $H8>=P$2), 2, "" ))) | Q8: =IF(AND($F8<(Q$2+7),$F8>Q$2),1, IF(AND($H8<Q$2+7,$H8>Q$2),3, IF(AND($F8<=Q$2, $H8>=Q$2), 2, "" ))) | R8: =IF(AND($F8<(R$2+7),$F8>R$2),1, IF(AND($H8<R$2+7,$H8>R$2),3, IF(AND($F8<=R$2, $H8>=R$2), 2, "" ))) | S8: =IF(AND($F8<(S$2+7),$F8>S$2),1, IF(AND($H8<S$2+7,$H8>S$2),3, IF(AND($F8<=S$2, $H8>=S$2), 2, "" ))) | ... AQ8: =IF(AND($F8<(AQ$2+7),$F8>AQ$2),1, IF(AND($H8<AQ$2+7,$H8>AQ$2),3, IF(AND($F8<=AQ$2, $H8>=AQ$2), 2, "" )))
B9: Inverter Procurement | C9: 43941 | D9: 5 | E9: 43949 | F9: 43941 | G9: 5 | H9: 43949 | L9: =IF(AND($F9<(L$2+7),$F9>L$2),1, IF(AND($H9<L$2+7,$H9>L$2),3, IF(AND($F9<=L$2, $H9>=L$2), 2, "" ))) | M9: =IF(AND($F9<(M$2+7),$F9>M$2),1, IF(AND($H9<M$2+7,$H9>M$2),3, IF(AND($F9<=M$2, $H9>=M$2), 2, "" ))) | N9: =IF(AND($F9<(N$2+7),$F9>N$2),1, IF(AND($H9<N$2+7,$H9>N$2),3, IF(AND($F9<=N$2, $H9>=N$2), 2, "" ))) | O9: =IF(AND($F9<(O$2+7),$F9>O$2),1, IF(AND($H9<O$2+7,$H9>O$2),3, IF(AND($F9<=O$2, $H9>=O$2), 2, "" ))) | P9: =IF(AND($F9<(P$2+7),$F9>P$2),1, IF(AND($H9<P$2+7,$H9>P$2),3, IF(AND($F9<=P$2, $H9>=P$2), 2, "" ))) | Q9: =IF(AND($F9<(Q$2+7),$F9>Q$2),1, IF(AND($H9<Q$2+7,$H9>Q$2),3, IF(AND($F9<=Q$2, $H9>=Q$2), 2, "" ))) | R9: =IF(AND($F9<(R$2+7),$F9>R$2),1, IF(AND($H9<R$2+7,$H9>R$2),3, IF(AND($F9<=R$2, $H9>=R$2), 2, "" ))) | S9: =IF(AND($F9<(S$2+7),$F9>S$2),1, IF(AND($H9<S$2+7,$H9>S$2),3, IF(AND($F9<=S$2, $H9>=S$2), 2, "" ))) | ... AQ9: =IF(AND($F9<(AQ$2+7),$F9>AQ$2),1, IF(AND($H9<AQ$2+7,$H9>AQ$2),3, IF(AND($F9<=AQ$2, $H9>=AQ$2), 2, "" )))
B10: Mounting Structure Procurement | C10: 43941 | D10: 5 | E10: 43949 | F10: 43941 | G10: 5 | H10: 43949 | L10: =IF(AND($F10<(L$2+7),$F10>L$2),1, IF(AND($H10<L$2+7,$H10>L$2),3, IF(AND($F10<=L$2, $H10>=L$2), 2, "" ))) | M10: =IF(AND($F10<(M$2+7),$F10>M$2),1, IF(AND($H10<M$2+7,$H10>M$2),3, IF(AND($F10<=M$2, $H10>=M$2), 2, "" ))) | N10: =IF(AND($F10<(N$2+7),$F10>N$2),1, IF(AND($H10<N$2+7,$H10>N$2),3, IF(AND($F10<=N$2, $H10>=N$2), 2, "" ))) | O10: =IF(AND($F10<(O$2+7),$F10>O$2),1, IF(AND($H10<O$2+7,$H10>O$2),3, IF(AND($F10<=O$2, $H10>=O$2), 2, "" ))) | P10: =IF(AND($F10<(P$2+7),$F10>P$2),1, IF(AND($H10<P$2+7,$H10>P$2),3, IF(AND($F10<=P$2, $H10>=P$2), 2, "" ))) | Q10: =IF(AND($F10<(Q$2+7),$F10>Q$2),1, IF(AND($H10<Q$2+7,$H10>Q$2),3, IF(AND($F10<=Q$2, $H10>=Q$2), 2, "" ))) | R10: =IF(AND($F10<(R$2+7),$F10>R$2),1, IF(AND($H10<R$2+7,$H10>R$2),3, IF(AND($F10<=R$2, $H10>=R$2), 2, "" ))) | S10: =IF(AND($F10<(S$2+7),$F10>S$2),1, IF(AND($H10<S$2+7,$H10>S$2),3, IF(AND($F10<=S$2, $H10>=S$2), 2, "" ))) | ... AQ10: =IF(AND($F10<(AQ$2+7),$F10>AQ$2),1, IF(AND($H10<AQ$2+7,$H10>AQ$2),3, IF(AND($F10<=AQ$2, $H10>=AQ$2), 2, "" )))
B11: BOS Procurement | C11: 43941 | D11: 5 | E11: 43949 | F11: 43941 | G11: 5 | H11: 43949 | L11: =IF(AND($F11<(L$2+7),$F11>L$2),1, IF(AND($H11<L$2+7,$H11>L$2),3, IF(AND($F11<=L$2, $H11>=L$2), 2, "" ))) | M11: =IF(AND($F11<(M$2+7),$F11>M$2),1, IF(AND($H11<M$2+7,$H11>M$2),3, IF(AND($F11<=M$2, $H11>=M$2), 2, "" ))) | N11: =IF(AND($F11<(N$2+7),$F11>N$2),1, IF(AND($H11<N$2+7,$H11>N$2),3, IF(AND($F11<=N$2, $H11>=N$2), 2, "" ))) | O11: =IF(AND($F11<(O$2+7),$F11>O$2),1, IF(AND($H11<O$2+7,$H11>O$2),3, IF(AND($F11<=O$2, $H11>=O$2), 2, "" ))) | P11: =IF(AND($F11<(P$2+7),$F11>P$2),1, IF(AND($H11<P$2+7,$H11>P$2),3, IF(AND($F11<=P$2, $H11>=P$2), 2, "" ))) | Q11: =IF(AND($F11<(Q$2+7),$F11>Q$2),1, IF(AND($H11<Q$2+7,$H11>Q$2),3, IF(AND($F11<=Q$2, $H11>=Q$2), 2, "" ))) | R11: =IF(AND($F11<(R$2+7),$F11>R$2),1, IF(AND($H11<R$2+7,$H11>R$2),3, IF(AND($F11<=R$2, $H11>=R$2), 2, "" ))) | S11: =IF(AND($F11<(S$2+7),$F11>S$2),1, IF(AND($H11<S$2+7,$H11>S$2),3, IF(AND($F11<=S$2, $H11>=S$2), 2, "" ))) | ... AQ11: =IF(AND($F11<(AQ$2+7),$F11>AQ$2),1, IF(AND($H11<AQ$2+7,$H11>AQ$2),3, IF(AND($F11<=AQ$2, $H11>=AQ$2), 2, "" )))
A12: 5 | B12: Internal Project Kick off | C12: 43936 | D12: 5 | E12: 43943 | F12: 43936 | G12: 5 | H12: 43943
A13: 6 | B13: Client Project Kick-off | C13: 43963 | D13: 5 | E13: 43970 | F13: 43963 | G13: 5 | H13: 43970 | L13: =IF(AND($F13<(L$2+7),$F13>L$2),1, IF(AND($H13<L$2+7,$H13>L$2),3, IF(AND($F13<=L$2, $H13>=L$2), 2, "" ))) | M13: =IF(AND($F13<(M$2+7),$F13>M$2),1, IF(AND($H13<M$2+7,$H13>M$2),3, IF(AND($F13<=M$2, $H13>=M$2), 2, "" ))) | N13: =IF(AND($F13<(N$2+7),$F13>N$2),1, IF(AND($H13<N$2+7,$H13>N$2),3, IF(AND($F13<=N$2, $H13>=N$2), 2, "" ))) | O13: =IF(AND($F13<(O$2+7),$F13>O$2),1, IF(AND($H13<O$2+7,$H13>O$2),3, IF(AND($F13<=O$2, $H13>=O$2), 2, "" ))) | P13: =IF(AND($F13<(P$2+7),$F13>P$2),1, IF(AND($H13<P$2+7,$H13>P$2),3, IF(AND($F13<=P$2, $H13>=P$2), 2, "" ))) | Q13: =IF(AND($F13<(Q$2+7),$F13>Q$2),1, IF(AND($H13<Q$2+7,$H13>Q$2),3, IF(AND($F13<=Q$2, $H13>=Q$2), 2, "" ))) | R13: =IF(AND($F13<(R$2+7),$F13>R$2),1, IF(AND($H13<R$2+7,$H13>R$2),3, IF(AND($F13<=R$2, $H13>=R$2), 2, "" ))) | S13: =IF(AND($F13<(S$2+7),$F13>S$2),1, IF(AND($H13<S$2+7,$H13>S$2),3, IF(AND($F13<=S$2, $H13>=S$2), 2, "" ))) | ... AQ13: =IF(AND($F13<(AQ$2+7),$F13>AQ$2),1, IF(AND($H13<AQ$2+7,$H13>AQ$2),3, IF(AND($F13<=AQ$2, $H13>=AQ$2), 2, "" )))
A14: 7 | B14: Equipment Delivery | C14: 43983 | D14: 9 | E14: 43994 | F14: 43983 | G14: 9 | H14: 43994 | L14: =IF(AND($F14<(L$2+7),$F14>L$2),1, IF(AND($H14<L$2+7,$H14>L$2),3, IF(AND($F14<=L$2, $H14>=L$2), 2, "" ))) | M14: =IF(AND($F14<(M$2+7),$F14>M$2),1, IF(AND($H14<M$2+7,$H14>M$2),3, IF(AND($F14<=M$2, $H14>=M$2), 2, "" ))) | N14: =IF(AND($F14<(N$2+7),$F14>N$2),1, IF(AND($H14<N$2+7,$H14>N$2),3, IF(AND($F14<=N$2, $H14>=N$2), 2, "" ))) | O14: =IF(AND($F14<(O$2+7),$F14>O$2),1, IF(AND($H14<O$2+7,$H14>O$2),3, IF(AND($F14<=O$2, $H14>=O$2), 2, "" ))) | P14: =IF(AND($F14<(P$2+7),$F14>P$2),1, IF(AND($H14<P$2+7,$H14>P$2),3, IF(AND($F14<=P$2, $H14>=P$2), 2, "" ))) | Q14: =IF(AND($F14<(Q$2+7),$F14>Q$2),1, IF(AND($H14<Q$2+7,$H14>Q$2),3, IF(AND($F14<=Q$2, $H14>=Q$2), 2, "" ))) | R14: =IF(AND($F14<(R$2+7),$F14>R$2),1, IF(AND($H14<R$2+7,$H14>R$2),3, IF(AND($F14<=R$2, $H14>=R$2), 2, "" ))) | S14: =IF(AND($F14<(S$2+7),$F14>S$2),1, IF(AND($H14<S$2+7,$H14>S$2),3, IF(AND($F14<=S$2, $H14>=S$2), 2, "" ))) | ... AQ14: =IF(AND($F14<(AQ$2+7),$F14>AQ$2),1, IF(AND($H14<AQ$2+7,$H14>AQ$2),3, IF(AND($F14<=AQ$2, $H14>=AQ$2), 2, "" )))
B15: Mounting Structure Delivery | C15: 43983 | D15: 2 | E15: 43985 | F15: 43983 | G15: 2 | H15: 43985
B16: Panel Delivery | C16: 43990 | D16: 2 | E16: 43992 | F16: 43990 | G16: 2 | H16: 43992 | L16: =IF(AND($F16<(L$2+7),$F16>L$2),1, IF(AND($H16<L$2+7,$H16>L$2),3, IF(AND($F16<=L$2, $H16>=L$2), 2, "" ))) | M16: =IF(AND($F16<(M$2+7),$F16>M$2),1, IF(AND($H16<M$2+7,$H16>M$2),3, IF(AND($F16<=M$2, $H16>=M$2), 2, "" ))) | N16: =IF(AND($F16<(N$2+7),$F16>N$2),1, IF(AND($H16<N$2+7,$H16>N$2),3, IF(AND($F16<=N$2, $H16>=N$2), 2, "" ))) | O16: =IF(AND($F16<(O$2+7),$F16>O$2),1, IF(AND($H16<O$2+7,$H16>O$2),3, IF(AND($F16<=O$2, $H16>=O$2), 2, "" ))) | P16: =IF(AND($F16<(P$2+7),$F16>P$2),1, IF(AND($H16<P$2+7,$H16>P$2),3, IF(AND($F16<=P$2, $H16>=P$2), 2, "" ))) | Q16: =IF(AND($F16<(Q$2+7),$F16>Q$2),1, IF(AND($H16<Q$2+7,$H16>Q$2),3, IF(AND($F16<=Q$2, $H16>=Q$2), 2, "" ))) | R16: =IF(AND($F16<(R$2+7),$F16>R$2),1, IF(AND($H16<R$2+7,$H16>R$2),3, IF(AND($F16<=R$2, $H16>=R$2), 2, "" ))) | S16: =IF(AND($F16<(S$2+7),$F16>S$2),1, IF(AND($H16<S$2+7,$H16>S$2),3, IF(AND($F16<=S$2, $H16>=S$2), 2, "" ))) | ... AQ16: =IF(AND($F16<(AQ$2+7),$F16>AQ$2),1, IF(AND($H16<AQ$2+7,$H16>AQ$2),3, IF(AND($F16<=AQ$2, $H16>=AQ$2), 2, "" )))
B17: Generator Delivery | C17: 43983 | D17: 2 | E17: 43985 | F17: 43983 | G17: 2 | H17: 43985
A18: B | B18: PAYMENT MILESTONE 2: DELIVERY OF PV PANELS | C18: 43992 | D18: 2 | E18: 43994 | F18: 43992 | G18: 2 | H18: 43994
B19: Inverter Delivery | C19: 43983 | D19: 2 | E19: 43985 | F19: 43983 | G19: 2 | H19: 43985 | L19: =IF(AND($F19<(L$2+7),$F19>L$2),1, IF(AND($H19<L$2+7,$H19>L$2),3, IF(AND($F19<=L$2, $H19>=L$2), 2, "" ))) | M19: =IF(AND($F19<(M$2+7),$F19>M$2),1, IF(AND($H19<M$2+7,$H19>M$2),3, IF(AND($F19<=M$2, $H19>=M$2), 2, "" ))) | N19: =IF(AND($F19<(N$2+7),$F19>N$2),1, IF(AND($H19<N$2+7,$H19>N$2),3, IF(AND($F19<=N$2, $H19>=N$2), 2, "" ))) | O19: =IF(AND($F19<(O$2+7),$F19>O$2),1, IF(AND($H19<O$2+7,$H19>O$2),3, IF(AND($F19<=O$2, $H19>=O$2), 2, "" ))) | P19: =IF(AND($F19<(P$2+7),$F19>P$2),1, IF(AND($H19<P$2+7,$H19>P$2),3, IF(AND($F19<=P$2, $H19>=P$2), 2, "" ))) | Q19: =IF(AND($F19<(Q$2+7),$F19>Q$2),1, IF(AND($H19<Q$2+7,$H19>Q$2),3, IF(AND($F19<=Q$2, $H19>=Q$2), 2, "" ))) | R19: =IF(AND($F19<(R$2+7),$F19>R$2),1, IF(AND($H19<R$2+7,$H19>R$2),3, IF(AND($F19<=R$2, $H19>=R$2), 2, "" ))) | S19: =IF(AND($F19<(S$2+7),$F19>S$2),1, IF(AND($H19<S$2+7,$H19>S$2),3, IF(AND($F19<=S$2, $H19>=S$2), 2, "" ))) | ... AQ19: =IF(AND($F19<(AQ$2+7),$F19>AQ$2),1, IF(AND($H19<AQ$2+7,$H19>AQ$2),3, IF(AND($F19<=AQ$2, $H19>=AQ$2), 2, "" )))
B20: BOS Delivery | C20: 43983 | D20: 1 | E20: 43984 | F20: 43983 | G20: 1 | H20: 43984 | L20: =IF(AND($F20<(L$2+7),$F20>L$2),1, IF(AND($H20<L$2+7,$H20>L$2),3, IF(AND($F20<=L$2, $H20>=L$2), 2, "" ))) | M20: =IF(AND($F20<(M$2+7),$F20>M$2),1, IF(AND($H20<M$2+7,$H20>M$2),3, IF(AND($F20<=M$2, $H20>=M$2), 2, "" ))) | N20: =IF(AND($F20<(N$2+7),$F20>N$2),1, IF(AND($H20<N$2+7,$H20>N$2),3, IF(AND($F20<=N$2, $H20>=N$2), 2, "" ))) | O20: =IF(AND($F20<(O$2+7),$F20>O$2),1, IF(AND($H20<O$2+7,$H20>O$2),3, IF(AND($F20<=O$2, $H20>=O$2), 2, "" ))) | P20: =IF(AND($F20<(P$2+7),$F20>P$2),1, IF(AND($H20<P$2+7,$H20>P$2),3, IF(AND($F20<=P$2, $H20>=P$2), 2, "" ))) | Q20: =IF(AND($F20<(Q$2+7),$F20>Q$2),1, IF(AND($H20<Q$2+7,$H20>Q$2),3, IF(AND($F20<=Q$2, $H20>=Q$2), 2, "" ))) | R20: =IF(AND($F20<(R$2+7),$F20>R$2),1, IF(AND($H20<R$2+7,$H20>R$2),3, IF(AND($F20<=R$2, $H20>=R$2), 2, "" ))) | S20: =IF(AND($F20<(S$2+7),$F20>S$2),1, IF(AND($H20<S$2+7,$H20>S$2),3, IF(AND($F20<=S$2, $H20>=S$2), 2, "" ))) | ... AQ20: =IF(AND($F20<(AQ$2+7),$F20>AQ$2),1, IF(AND($H20<AQ$2+7,$H20>AQ$2),3, IF(AND($F20<=AQ$2, $H20>=AQ$2), 2, "" )))
A21: C | B21: PAYMENT MILESTONE 3: DELIVERY OF INVERTERS AND BOS | C21: 43985 | D21: 2 | E21: 43987 | F21: 43985 | G21: 2 | H21: 43987
A22: 8 | B22: Installation | C22: 43990 | D22: 22 | E22: 44012 | F22: 43990 | G22: 22 | H22: 44012 | L22: =IF(AND($F22<(L$2+7),$F22>L$2),1, IF(AND($H22<L$2+7,$H22>L$2),3, IF(AND($F22<=L$2, $H22>=L$2), 2, "" ))) | M22: =IF(AND($F22<(M$2+7),$F22>M$2),1, IF(AND($H22<M$2+7,$H22>M$2),3, IF(AND($F22<=M$2, $H22>=M$2), 2, "" ))) | N22: =IF(AND($F22<(N$2+7),$F22>N$2),1, IF(AND($H22<N$2+7,$H22>N$2),3, IF(AND($F22<=N$2, $H22>=N$2), 2, "" ))) | O22: =IF(AND($F22<(O$2+7),$F22>O$2),1, IF(AND($H22<O$2+7,$H22>O$2),3, IF(AND($F22<=O$2, $H22>=O$2), 2, "" ))) | P22: =IF(AND($F22<(P$2+7),$F22>P$2),1, IF(AND($H22<P$2+7,$H22>P$2),3, IF(AND($F22<=P$2, $H22>=P$2), 2, "" ))) | Q22: =IF(AND($F22<(Q$2+7),$F22>Q$2),1, IF(AND($H22<Q$2+7,$H22>Q$2),3, IF(AND($F22<=Q$2, $H22>=Q$2), 2, "" ))) | R22: =IF(AND($F22<(R$2+7),$F22>R$2),1, IF(AND($H22<R$2+7,$H22>R$2),3, IF(AND($F22<=R$2, $H22>=R$2), 2, "" ))) | S22: =IF(AND($F22<(S$2+7),$F22>S$2),1, IF(AND($H22<S$2+7,$H22>S$2),3, IF(AND($F22<=S$2, $H22>=S$2), 2, "" ))) | ... AQ22: =IF(AND($F22<(AQ$2+7),$F22>AQ$2),1, IF(AND($H22<AQ$2+7,$H22>AQ$2),3, IF(AND($F22<=AQ$2, $H22>=AQ$2), 2, "" ))) -> 2
B23: Site Establishment | C23: 43990 | D23: 1 | E23: 43991 | F23: 43990 | G23: 1 | H23: 43991 | J23: Installation placed on hold due to Covid-19 case | L23: =IF(AND($F23<(L$2+7),$F23>L$2),1, IF(AND($H23<L$2+7,$H23>L$2),3, IF(AND($F23<=L$2, $H23>=L$2), 2, "" ))) | M23: =IF(AND($F23<(M$2+7),$F23>M$2),1, IF(AND($H23<M$2+7,$H23>M$2),3, IF(AND($F23<=M$2, $H23>=M$2), 2, "" ))) | N23: =IF(AND($F23<(N$2+7),$F23>N$2),1, IF(AND($H23<N$2+7,$H23>N$2),3, IF(AND($F23<=N$2, $H23>=N$2), 2, "" ))) | O23: =IF(AND($F23<(O$2+7),$F23>O$2),1, IF(AND($H23<O$2+7,$H23>O$2),3, IF(AND($F23<=O$2, $H23>=O$2), 2, "" ))) | P23: =IF(AND($F23<(P$2+7),$F23>P$2),1, IF(AND($H23<P$2+7,$H23>P$2),3, IF(AND($F23<=P$2, $H23>=P$2), 2, "" ))) | Q23: =IF(AND($F23<(Q$2+7),$F23>Q$2),1, IF(AND($H23<Q$2+7,$H23>Q$2),3, IF(AND($F23<=Q$2, $H23>=Q$2), 2, "" ))) | R23: =IF(AND($F23<(R$2+7),$F23>R$2),1, IF(AND($H23<R$2+7,$H23>R$2),3, IF(AND($F23<=R$2, $H23>=R$2), 2, "" ))) | S23: =IF(AND($F23<(S$2+7),$F23>S$2),1, IF(AND($H23<S$2+7,$H23>S$2),3, IF(AND($F23<=S$2, $H23>=S$2), 2, "" ))) | ... AQ23: =IF(AND($F23<(AQ$2+7),$F23>AQ$2),1, IF(AND($H23<AQ$2+7,$H23>AQ$2),3, IF(AND($F23<=AQ$2, $H23>=AQ$2), 2, "" )))
A24: 9 | B24: DC Works | C24: 43991 | D24: 16 | E24: 44012 | F24: 43991 | G24: 16 | H24: 44012 | L24: =IF(AND($F24<(L$2+7),$F24>L$2),1, IF(AND($H24<L$2+7,$H24>L$2),3, IF(AND($F24<=L$2, $H24>=L$2), 2, "" ))) | M24: =IF(AND($F24<(M$2+7),$F24>M$2),1, IF(AND($H24<M$2+7,$H24>M$2),3, IF(AND($F24<=M$2, $H24>=M$2), 2, "" ))) | N24: =IF(AND($F24<(N$2+7),$F24>N$2),1, IF(AND($H24<N$2+7,$H24>N$2),3, IF(AND($F24<=N$2, $H24>=N$2), 2, "" ))) | O24: =IF(AND($F24<(O$2+7),$F24>O$2),1, IF(AND($H24<O$2+7,$H24>O$2),3, IF(AND($F24<=O$2, $H24>=O$2), 2, "" ))) | P24: =IF(AND($F24<(P$2+7),$F24>P$2),1, IF(AND($H24<P$2+7,$H24>P$2),3, IF(AND($F24<=P$2, $H24>=P$2), 2, "" ))) | Q24: =IF(AND($F24<(Q$2+7),$F24>Q$2),1, IF(AND($H24<Q$2+7,$H24>Q$2),3, IF(AND($F24<=Q$2, $H24>=Q$2), 2, "" ))) | R24: =IF(AND($F24<(R$2+7),$F24>R$2),1, IF(AND($H24<R$2+7,$H24>R$2),3, IF(AND($F24<=R$2, $H24>=R$2), 2, "" ))) | S24: =IF(AND($F24<(S$2+7),$F24>S$2),1, IF(AND($H24<S$2+7,$H24>S$2),3, IF(AND($F24<=S$2, $H24>=S$2), 2, "" ))) | ... AQ24: =IF(AND($F24<(AQ$2+7),$F24>AQ$2),1, IF(AND($H24<AQ$2+7,$H24>AQ$2),3, IF(AND($F24<=AQ$2, $H24>=AQ$2), 2, "" ))) -> 2
B25: Mounting structure Installation | C25: 43991 | D25: 4 | E25: 43997 | F25: 43991 | G25: 4 | H25: 43997 | L25: =IF(AND($F25<(L$2+7),$F25>L$2),1, IF(AND($H25<L$2+7,$H25>L$2),3, IF(AND($F25<=L$2, $H25>=L$2), 2, "" ))) | M25: =IF(AND($F25<(M$2+7),$F25>M$2),1, IF(AND($H25<M$2+7,$H25>M$2),3, IF(AND($F25<=M$2, $H25>=M$2), 2, "" ))) | N25: =IF(AND($F25<(N$2+7),$F25>N$2),1, IF(AND($H25<N$2+7,$H25>N$2),3, IF(AND($F25<=N$2, $H25>=N$2), 2, "" ))) | O25: =IF(AND($F25<(O$2+7),$F25>O$2),1, IF(AND($H25<O$2+7,$H25>O$2),3, IF(AND($F25<=O$2, $H25>=O$2), 2, "" ))) | P25: =IF(AND($F25<(P$2+7),$F25>P$2),1, IF(AND($H25<P$2+7,$H25>P$2),3, IF(AND($F25<=P$2, $H25>=P$2), 2, "" ))) | Q25: =IF(AND($F25<(Q$2+7),$F25>Q$2),1, IF(AND($H25<Q$2+7,$H25>Q$2),3, IF(AND($F25<=Q$2, $H25>=Q$2), 2, "" ))) | R25: =IF(AND($F25<(R$2+7),$F25>R$2),1, IF(AND($H25<R$2+7,$H25>R$2),3, IF(AND($F25<=R$2, $H25>=R$2), 2, "" ))) | S25: =IF(AND($F25<(S$2+7),$F25>S$2),1, IF(AND($H25<S$2+7,$H25>S$2),3, IF(AND($F25<=S$2, $H25>=S$2), 2, "" ))) | ... AQ25: =IF(AND($F25<(AQ$2+7),$F25>AQ$2),1, IF(AND($H25<AQ$2+7,$H25>AQ$2),3, IF(AND($F25<=AQ$2, $H25>=AQ$2), 2, "" )))
B26: Cable tray Installation | C26: 43997 | D26: 3 | E26: 44004 | F26: 43997 | G26: 3 | H26: 44004 | L26: =IF(AND($F26<(L$2+7),$F26>L$2),1, IF(AND($H26<L$2+7,$H26>L$2),3, IF(AND($F26<=L$2, $H26>=L$2), 2, "" ))) | M26: =IF(AND($F26<(M$2+7),$F26>M$2),1, IF(AND($H26<M$2+7,$H26>M$2),3, IF(AND($F26<=M$2, $H26>=M$2), 2, "" ))) | N26: =IF(AND($F26<(N$2+7),$F26>N$2),1, IF(AND($H26<N$2+7,$H26>N$2),3, IF(AND($F26<=N$2, $H26>=N$2), 2, "" ))) | O26: =IF(AND($F26<(O$2+7),$F26>O$2),1, IF(AND($H26<O$2+7,$H26>O$2),3, IF(AND($F26<=O$2, $H26>=O$2), 2, "" ))) | P26: =IF(AND($F26<(P$2+7),$F26>P$2),1, IF(AND($H26<P$2+7,$H26>P$2),3, IF(AND($F26<=P$2, $H26>=P$2), 2, "" ))) | Q26: =IF(AND($F26<(Q$2+7),$F26>Q$2),1, IF(AND($H26<Q$2+7,$H26>Q$2),3, IF(AND($F26<=Q$2, $H26>=Q$2), 2, "" ))) | R26: =IF(AND($F26<(R$2+7),$F26>R$2),1, IF(AND($H26<R$2+7,$H26>R$2),3, IF(AND($F26<=R$2, $H26>=R$2), 2, "" ))) | S26: =IF(AND($F26<(S$2+7),$F26>S$2),1, IF(AND($H26<S$2+7,$H26>S$2),3, IF(AND($F26<=S$2, $H26>=S$2), 2, "" ))) | ... AQ26: =IF(AND($F26<(AQ$2+7),$F26>AQ$2),1, IF(AND($H26<AQ$2+7,$H26>AQ$2),3, IF(AND($F26<=AQ$2, $H26>=AQ$2), 2, "" )))
B27: DC Cable Installation | C27: 44004 | D27: 2 | E27: 44006 | F27: 44004 | G27: 2 | H27: 44006 | L27: =IF(AND($F27<(L$2+7),$F27>L$2),1, IF(AND($H27<L$2+7,$H27>L$2),3, IF(AND($F27<=L$2, $H27>=L$2), 2, "" ))) | M27: =IF(AND($F27<(M$2+7),$F27>M$2),1, IF(AND($H27<M$2+7,$H27>M$2),3, IF(AND($F27<=M$2, $H27>=M$2), 2, "" ))) | N27: =IF(AND($F27<(N$2+7),$F27>N$2),1, IF(AND($H27<N$2+7,$H27>N$2),3, IF(AND($F27<=N$2, $H27>=N$2), 2, "" ))) | O27: =IF(AND($F27<(O$2+7),$F27>O$2),1, IF(AND($H27<O$2+7,$H27>O$2),3, IF(AND($F27<=O$2, $H27>=O$2), 2, "" ))) | P27: =IF(AND($F27<(P$2+7),$F27>P$2),1, IF(AND($H27<P$2+7,$H27>P$2),3, IF(AND($F27<=P$2, $H27>=P$2), 2, "" ))) | Q27: =IF(AND($F27<(Q$2+7),$F27>Q$2),1, IF(AND($H27<Q$2+7,$H27>Q$2),3, IF(AND($F27<=Q$2, $H27>=Q$2), 2, "" ))) | R27: =IF(AND($F27<(R$2+7),$F27>R$2),1, IF(AND($H27<R$2+7,$H27>R$2),3, IF(AND($F27<=R$2, $H27>=R$2), 2, "" ))) | S27: =IF(AND($F27<(S$2+7),$F27>S$2),1, IF(AND($H27<S$2+7,$H27>S$2),3, IF(AND($F27<=S$2, $H27>=S$2), 2, "" ))) | ... AQ27: =IF(AND($F27<(AQ$2+7),$F27>AQ$2),1, IF(AND($H27<AQ$2+7,$H27>AQ$2),3, IF(AND($F27<=AQ$2, $H27>=AQ$2), 2, "" )))
B28: Module Installation | C28: 44006 | D28: 4 | E28: 44012 | F28: 44006 | G28: 4 | H28: 44012 | L28: =IF(AND($F28<(L$2+7),$F28>L$2),1, IF(AND($H28<L$2+7,$H28>L$2),3, IF(AND($F28<=L$2, $H28>=L$2), 2, "" ))) | M28: =IF(AND($F28<(M$2+7),$F28>M$2),1, IF(AND($H28<M$2+7,$H28>M$2),3, IF(AND($F28<=M$2, $H28>=M$2), 2, "" ))) | N28: =IF(AND($F28<(N$2+7),$F28>N$2),1, IF(AND($H28<N$2+7,$H28>N$2),3, IF(AND($F28<=N$2, $H28>=N$2), 2, "" ))) | O28: =IF(AND($F28<(O$2+7),$F28>O$2),1, IF(AND($H28<O$2+7,$H28>O$2),3, IF(AND($F28<=O$2, $H28>=O$2), 2, "" ))) | P28: =IF(AND($F28<(P$2+7),$F28>P$2),1, IF(AND($H28<P$2+7,$H28>P$2),3, IF(AND($F28<=P$2, $H28>=P$2), 2, "" ))) | Q28: =IF(AND($F28<(Q$2+7),$F28>Q$2),1, IF(AND($H28<Q$2+7,$H28>Q$2),3, IF(AND($F28<=Q$2, $H28>=Q$2), 2, "" ))) | R28: =IF(AND($F28<(R$2+7),$F28>R$2),1, IF(AND($H28<R$2+7,$H28>R$2),3, IF(AND($F28<=R$2, $H28>=R$2), 2, "" ))) | S28: =IF(AND($F28<(S$2+7),$F28>S$2),1, IF(AND($H28<S$2+7,$H28>S$2),3, IF(AND($F28<=S$2, $H28>=S$2), 2, "" ))) | ... AQ28: =IF(AND($F28<(AQ$2+7),$F28>AQ$2),1, IF(AND($H28<AQ$2+7,$H28>AQ$2),3, IF(AND($F28<=AQ$2, $H28>=AQ$2), 2, "" ))) -> 2
B29: Earth Cable Installation | C29: 44004 | D29: 1 | E29: 44005 | F29: 44004 | G29: 1 | H29: 44005 | L29: =IF(AND($F29<(L$2+7),$F29>L$2),1, IF(AND($H29<L$2+7,$H29>L$2),3, IF(AND($F29<=L$2, $H29>=L$2), 2, "" ))) | M29: =IF(AND($F29<(M$2+7),$F29>M$2),1, IF(AND($H29<M$2+7,$H29>M$2),3, IF(AND($F29<=M$2, $H29>=M$2), 2, "" ))) | N29: =IF(AND($F29<(N$2+7),$F29>N$2),1, IF(AND($H29<N$2+7,$H29>N$2),3, IF(AND($F29<=N$2, $H29>=N$2), 2, "" ))) | O29: =IF(AND($F29<(O$2+7),$F29>O$2),1, IF(AND($H29<O$2+7,$H29>O$2),3, IF(AND($F29<=O$2, $H29>=O$2), 2, "" ))) | P29: =IF(AND($F29<(P$2+7),$F29>P$2),1, IF(AND($H29<P$2+7,$H29>P$2),3, IF(AND($F29<=P$2, $H29>=P$2), 2, "" ))) | Q29: =IF(AND($F29<(Q$2+7),$F29>Q$2),1, IF(AND($H29<Q$2+7,$H29>Q$2),3, IF(AND($F29<=Q$2, $H29>=Q$2), 2, "" ))) | R29: =IF(AND($F29<(R$2+7),$F29>R$2),1, IF(AND($H29<R$2+7,$H29>R$2),3, IF(AND($F29<=R$2, $H29>=R$2), 2, "" ))) | S29: =IF(AND($F29<(S$2+7),$F29>S$2),1, IF(AND($H29<S$2+7,$H29>S$2),3, IF(AND($F29<=S$2, $H29>=S$2), 2, "" ))) | ... AQ29: =IF(AND($F29<(AQ$2+7),$F29>AQ$2),1, IF(AND($H29<AQ$2+7,$H29>AQ$2),3, IF(AND($F29<=AQ$2, $H29>=AQ$2), 2, "" )))
A30: 10 | B30: AC Works | C30: 43991 | D30: 8 | E30: 44000 | F30: 43991 | G30: 8 | H30: 44000
B31: Inverters Installation | C31: 43991 | D31: 2 | E31: 43993 | F31: 43991 | G31: 2 | H31: 43993 | L31: =IF(AND($F31<(L$2+7),$F31>L$2),1, IF(AND($H31<L$2+7,$H31>L$2),3, IF(AND($F31<=L$2, $H31>=L$2), 2, "" ))) | M31: =IF(AND($F31<(M$2+7),$F31>M$2),1, IF(AND($H31<M$2+7,$H31>M$2),3, IF(AND($F31<=M$2, $H31>=M$2), 2, "" ))) | N31: =IF(AND($F31<(N$2+7),$F31>N$2),1, IF(AND($H31<N$2+7,$H31>N$2),3, IF(AND($F31<=N$2, $H31>=N$2), 2, "" ))) | O31: =IF(AND($F31<(O$2+7),$F31>O$2),1, IF(AND($H31<O$2+7,$H31>O$2),3, IF(AND($F31<=O$2, $H31>=O$2), 2, "" ))) | P31: =IF(AND($F31<(P$2+7),$F31>P$2),1, IF(AND($H31<P$2+7,$H31>P$2),3, IF(AND($F31<=P$2, $H31>=P$2), 2, "" ))) | Q31: =IF(AND($F31<(Q$2+7),$F31>Q$2),1, IF(AND($H31<Q$2+7,$H31>Q$2),3, IF(AND($F31<=Q$2, $H31>=Q$2), 2, "" ))) | R31: =IF(AND($F31<(R$2+7),$F31>R$2),1, IF(AND($H31<R$2+7,$H31>R$2),3, IF(AND($F31<=R$2, $H31>=R$2), 2, "" ))) | S31: =IF(AND($F31<(S$2+7),$F31>S$2),1, IF(AND($H31<S$2+7,$H31>S$2),3, IF(AND($F31<=S$2, $H31>=S$2), 2, "" ))) | ... AQ31: =IF(AND($F31<(AQ$2+7),$F31>AQ$2),1, IF(AND($H31<AQ$2+7,$H31>AQ$2),3, IF(AND($F31<=AQ$2, $H31>=AQ$2), 2, "" )))
B32: AC BOS Installation | C32: 43993 | D32: 3 | E32: 44000 | F32: 43993 | G32: 3 | H32: 44000 | L32: =IF(AND($F32<(L$2+7),$F32>L$2),1, IF(AND($H32<L$2+7,$H32>L$2),3, IF(AND($F32<=L$2, $H32>=L$2), 2, "" ))) | M32: =IF(AND($F32<(M$2+7),$F32>M$2),1, IF(AND($H32<M$2+7,$H32>M$2),3, IF(AND($F32<=M$2, $H32>=M$2), 2, "" ))) | N32: =IF(AND($F32<(N$2+7),$F32>N$2),1, IF(AND($H32<N$2+7,$H32>N$2),3, IF(AND($F32<=N$2, $H32>=N$2), 2, "" ))) | O32: =IF(AND($F32<(O$2+7),$F32>O$2),1, IF(AND($H32<O$2+7,$H32>O$2),3, IF(AND($F32<=O$2, $H32>=O$2), 2, "" ))) | P32: =IF(AND($F32<(P$2+7),$F32>P$2),1, IF(AND($H32<P$2+7,$H32>P$2),3, IF(AND($F32<=P$2, $H32>=P$2), 2, "" ))) | Q32: =IF(AND($F32<(Q$2+7),$F32>Q$2),1, IF(AND($H32<Q$2+7,$H32>Q$2),3, IF(AND($F32<=Q$2, $H32>=Q$2), 2, "" ))) | R32: =IF(AND($F32<(R$2+7),$F32>R$2),1, IF(AND($H32<R$2+7,$H32>R$2),3, IF(AND($F32<=R$2, $H32>=R$2), 2, "" ))) | S32: =IF(AND($F32<(S$2+7),$F32>S$2),1, IF(AND($H32<S$2+7,$H32>S$2),3, IF(AND($F32<=S$2, $H32>=S$2), 2, "" ))) | ... AQ32: =IF(AND($F32<(AQ$2+7),$F32>AQ$2),1, IF(AND($H32<AQ$2+7,$H32>AQ$2),3, IF(AND($F32<=AQ$2, $H32>=AQ$2), 2, "" )))
B33: AC Cable/Tie-In | C33: 43992 | D33: 3 | E33: 43997 | F33: 43992 | G33: 3 | H33: 43997 | L33: =IF(AND($F33<(L$2+7),$F33>L$2),1, IF(AND($H33<L$2+7,$H33>L$2),3, IF(AND($F33<=L$2, $H33>=L$2), 2, "" ))) | M33: =IF(AND($F33<(M$2+7),$F33>M$2),1, IF(AND($H33<M$2+7,$H33>M$2),3, IF(AND($F33<=M$2, $H33>=M$2), 2, "" ))) | N33: =IF(AND($F33<(N$2+7),$F33>N$2),1, IF(AND($H33<N$2+7,$H33>N$2),3, IF(AND($F33<=N$2, $H33>=N$2), 2, "" ))) | O33: =IF(AND($F33<(O$2+7),$F33>O$2),1, IF(AND($H33<O$2+7,$H33>O$2),3, IF(AND($F33<=O$2, $H33>=O$2), 2, "" ))) | P33: =IF(AND($F33<(P$2+7),$F33>P$2),1, IF(AND($H33<P$2+7,$H33>P$2),3, IF(AND($F33<=P$2, $H33>=P$2), 2, "" ))) | Q33: =IF(AND($F33<(Q$2+7),$F33>Q$2),1, IF(AND($H33<Q$2+7,$H33>Q$2),3, IF(AND($F33<=Q$2, $H33>=Q$2), 2, "" ))) | R33: =IF(AND($F33<(R$2+7),$F33>R$2),1, IF(AND($H33<R$2+7,$H33>R$2),3, IF(AND($F33<=R$2, $H33>=R$2), 2, "" ))) | S33: =IF(AND($F33<(S$2+7),$F33>S$2),1, IF(AND($H33<S$2+7,$H33>S$2),3, IF(AND($F33<=S$2, $H33>=S$2), 2, "" ))) | ... AQ33: =IF(AND($F33<(AQ$2+7),$F33>AQ$2),1, IF(AND($H33<AQ$2+7,$H33>AQ$2),3, IF(AND($F33<=AQ$2, $H33>=AQ$2), 2, "" )))
B34: Monitoring Platform Installation | C34: 43997 | D34: 1 | E34: 44000 | F34: 43997 | G34: 1 | H34: 44000
A35: 11 | B35: Completion | C35: 44000 | D35: 14 | E35: 44014 | F35: 44000 | G35: 14 | H35: 44014 | L35: =IF(AND($F35<(L$2+7),$F35>L$2),1, IF(AND($H35<L$2+7,$H35>L$2),3, IF(AND($F35<=L$2, $H35>=L$2), 2, "" ))) | M35: =IF(AND($F35<(M$2+7),$F35>M$2),1, IF(AND($H35<M$2+7,$H35>M$2),3, IF(AND($F35<=M$2, $H35>=M$2), 2, "" ))) | N35: =IF(AND($F35<(N$2+7),$F35>N$2),1, IF(AND($H35<N$2+7,$H35>N$2),3, IF(AND($F35<=N$2, $H35>=N$2), 2, "" ))) | O35: =IF(AND($F35<(O$2+7),$F35>O$2),1, IF(AND($H35<O$2+7,$H35>O$2),3, IF(AND($F35<=O$2, $H35>=O$2), 2, "" ))) | P35: =IF(AND($F35<(P$2+7),$F35>P$2),1, IF(AND($H35<P$2+7,$H35>P$2),3, IF(AND($F35<=P$2, $H35>=P$2), 2, "" ))) | Q35: =IF(AND($F35<(Q$2+7),$F35>Q$2),1, IF(AND($H35<Q$2+7,$H35>Q$2),3, IF(AND($F35<=Q$2, $H35>=Q$2), 2, "" ))) | R35: =IF(AND($F35<(R$2+7),$F35>R$2),1, IF(AND($H35<R$2+7,$H35>R$2),3, IF(AND($F35<=R$2, $H35>=R$2), 2, "" ))) | S35: =IF(AND($F35<(S$2+7),$F35>S$2),1, IF(AND($H35<S$2+7,$H35>S$2),3, IF(AND($F35<=S$2, $H35>=S$2), 2, "" ))) | ... AQ35: =IF(AND($F35<(AQ$2+7),$F35>AQ$2),1, IF(AND($H35<AQ$2+7,$H35>AQ$2),3, IF(AND($F35<=AQ$2, $H35>=AQ$2), 2, "" ))) -> 3
B36: DC Works | C36: 44012 | D36: 2 | E36: 44014 | F36: 44012 | G36: 2 | H36: 44014 | L36: =IF(AND($F36<(L$2+7),$F36>L$2),1, IF(AND($H36<L$2+7,$H36>L$2),3, IF(AND($F36<=L$2, $H36>=L$2), 2, "" ))) | M36: =IF(AND($F36<(M$2+7),$F36>M$2),1, IF(AND($H36<M$2+7,$H36>M$2),3, IF(AND($F36<=M$2, $H36>=M$2), 2, "" ))) | N36: =IF(AND($F36<(N$2+7),$F36>N$2),1, IF(AND($H36<N$2+7,$H36>N$2),3, IF(AND($F36<=N$2, $H36>=N$2), 2, "" ))) | O36: =IF(AND($F36<(O$2+7),$F36>O$2),1, IF(AND($H36<O$2+7,$H36>O$2),3, IF(AND($F36<=O$2, $H36>=O$2), 2, "" ))) | P36: =IF(AND($F36<(P$2+7),$F36>P$2),1, IF(AND($H36<P$2+7,$H36>P$2),3, IF(AND($F36<=P$2, $H36>=P$2), 2, "" ))) | Q36: =IF(AND($F36<(Q$2+7),$F36>Q$2),1, IF(AND($H36<Q$2+7,$H36>Q$2),3, IF(AND($F36<=Q$2, $H36>=Q$2), 2, "" ))) | R36: =IF(AND($F36<(R$2+7),$F36>R$2),1, IF(AND($H36<R$2+7,$H36>R$2),3, IF(AND($F36<=R$2, $H36>=R$2), 2, "" ))) | S36: =IF(AND($F36<(S$2+7),$F36>S$2),1, IF(AND($H36<S$2+7,$H36>S$2),3, IF(AND($F36<=S$2, $H36>=S$2), 2, "" ))) | ... AQ36: =IF(AND($F36<(AQ$2+7),$F36>AQ$2),1, IF(AND($H36<AQ$2+7,$H36>AQ$2),3, IF(AND($F36<=AQ$2, $H36>=AQ$2), 2, "" ))) -> 3
B37: AC Works | C37: 44000 | D37: 2 | E37: 44004 | F37: 44000 | G37: 2 | H37: 44004 | L37: =IF(AND($F37<(L$2+7),$F37>L$2),1, IF(AND($H37<L$2+7,$H37>L$2),3, IF(AND($F37<=L$2, $H37>=L$2), 2, "" ))) | M37: =IF(AND($F37<(M$2+7),$F37>M$2),1, IF(AND($H37<M$2+7,$H37>M$2),3, IF(AND($F37<=M$2, $H37>=M$2), 2, "" ))) | N37: =IF(AND($F37<(N$2+7),$F37>N$2),1, IF(AND($H37<N$2+7,$H37>N$2),3, IF(AND($F37<=N$2, $H37>=N$2), 2, "" ))) | O37: =IF(AND($F37<(O$2+7),$F37>O$2),1, IF(AND($H37<O$2+7,$H37>O$2),3, IF(AND($F37<=O$2, $H37>=O$2), 2, "" ))) | P37: =IF(AND($F37<(P$2+7),$F37>P$2),1, IF(AND($H37<P$2+7,$H37>P$2),3, IF(AND($F37<=P$2, $H37>=P$2), 2, "" ))) | Q37: =IF(AND($F37<(Q$2+7),$F37>Q$2),1, IF(AND($H37<Q$2+7,$H37>Q$2),3, IF(AND($F37<=Q$2, $H37>=Q$2), 2, "" ))) | R37: =IF(AND($F37<(R$2+7),$F37>R$2),1, IF(AND($H37<R$2+7,$H37>R$2),3, IF(AND($F37<=R$2, $H37>=R$2), 2, "" ))) | S37: =IF(AND($F37<(S$2+7),$F37>S$2),1, IF(AND($H37<S$2+7,$H37>S$2),3, IF(AND($F37<=S$2, $H37>=S$2), 2, "" ))) | ... AQ37: =IF(AND($F37<(AQ$2+7),$F37>AQ$2),1, IF(AND($H37<AQ$2+7,$H37>AQ$2),3, IF(AND($F37<=AQ$2, $H37>=AQ$2), 2, "" )))
A38: D | B38: PAYMENT MILESTONE 4: PRACTICAL COMPLETION | C38: 44012 | D38: 1 | E38: 44013 | F38: 44012 | G38: 1 | H38: 44013 | L38: =IF(AND($F38<(L$2+7),$F38>L$2),1, IF(AND($H38<L$2+7,$H38>L$2),3, IF(AND($F38<=L$2, $H38>=L$2), 2, "" ))) | M38: =IF(AND($F38<(M$2+7),$F38>M$2),1, IF(AND($H38<M$2+7,$H38>M$2),3, IF(AND($F38<=M$2, $H38>=M$2), 2, "" ))) | N38: =IF(AND($F38<(N$2+7),$F38>N$2),1, IF(AND($H38<N$2+7,$H38>N$2),3, IF(AND($F38<=N$2, $H38>=N$2), 2, "" ))) | O38: =IF(AND($F38<(O$2+7),$F38>O$2),1, IF(AND($H38<O$2+7,$H38>O$2),3, IF(AND($F38<=O$2, $H38>=O$2), 2, "" ))) | P38: =IF(AND($F38<(P$2+7),$F38>P$2),1, IF(AND($H38<P$2+7,$H38>P$2),3, IF(AND($F38<=P$2, $H38>=P$2), 2, "" ))) | Q38: =IF(AND($F38<(Q$2+7),$F38>Q$2),1, IF(AND($H38<Q$2+7,$H38>Q$2),3, IF(AND($F38<=Q$2, $H38>=Q$2), 2, "" ))) | R38: =IF(AND($F38<(R$2+7),$F38>R$2),1, IF(AND($H38<R$2+7,$H38>R$2),3, IF(AND($F38<=R$2, $H38>=R$2), 2, "" ))) | S38: =IF(AND($F38<(S$2+7),$F38>S$2),1, IF(AND($H38<S$2+7,$H38>S$2),3, IF(AND($F38<=S$2, $H38>=S$2), 2, "" ))) | ... AQ38: =IF(AND($F38<(AQ$2+7),$F38>AQ$2),1, IF(AND($H38<AQ$2+7,$H38>AQ$2),3, IF(AND($F38<=AQ$2, $H38>=AQ$2), 2, "" ))) -> 3
A39: 12 | B39: Commissioning | C39: 43997 | D39: 22 | E39: 44019 | F39: 43997 | G39: 22 | H39: 44019 | L39: =IF(AND($F39<(L$2+7),$F39>L$2),1, IF(AND($H39<L$2+7,$H39>L$2),3, IF(AND($F39<=L$2, $H39>=L$2), 2, "" ))) | M39: =IF(AND($F39<(M$2+7),$F39>M$2),1, IF(AND($H39<M$2+7,$H39>M$2),3, IF(AND($F39<=M$2, $H39>=M$2), 2, "" ))) | N39: =IF(AND($F39<(N$2+7),$F39>N$2),1, IF(AND($H39<N$2+7,$H39>N$2),3, IF(AND($F39<=N$2, $H39>=N$2), 2, "" ))) | O39: =IF(AND($F39<(O$2+7),$F39>O$2),1, IF(AND($H39<O$2+7,$H39>O$2),3, IF(AND($F39<=O$2, $H39>=O$2), 2, "" ))) | P39: =IF(AND($F39<(P$2+7),$F39>P$2),1, IF(AND($H39<P$2+7,$H39>P$2),3, IF(AND($F39<=P$2, $H39>=P$2), 2, "" ))) | Q39: =IF(AND($F39<(Q$2+7),$F39>Q$2),1, IF(AND($H39<Q$2+7,$H39>Q$2),3, IF(AND($F39<=Q$2, $H39>=Q$2), 2, "" ))) | R39: =IF(AND($F39<(R$2+7),$F39>R$2),1, IF(AND($H39<R$2+7,$H39>R$2),3, IF(AND($F39<=R$2, $H39>=R$2), 2, "" ))) | S39: =IF(AND($F39<(S$2+7),$F39>S$2),1, IF(AND($H39<S$2+7,$H39>S$2),3, IF(AND($F39<=S$2, $H39>=S$2), 2, "" ))) | ... AQ39: =IF(AND($F39<(AQ$2+7),$F39>AQ$2),1, IF(AND($H39<AQ$2+7,$H39>AQ$2),3, IF(AND($F39<=AQ$2, $H39>=AQ$2), 2, "" ))) -> 2
B40: Snag List | C40: 44014 | D40: 3 | E40: 44019 | F40: 44014 | G40: 3 | H40: 44019
...

Sheet Revenue Tracking
B2: HIGH LEVEL PROJECT REVENUE TRACKING
D3: PLANNED | F3: ACTUAL | H3: FR - Date | J3: 2023 Rev & COS RECOGNISED | K3: PLANNED | L3: ACTUAL
B4: 1 | C4: Planned Revenue | D4: ='Project Plan'!E9 -> 20939009 | F4: =F32 -> 20939009 | H4: 20939009 | J4: 12809926 | K4: 8129083.1 | L4: =F4-J4 -> 8129083.1
B5: 2 | C5: Planned Expenditure | D5: =+'Expenditure Tracking'!F5 -> 18682950 | F5: =+'Expenditure Tracking'!H5 -> 19234297 | H5: 18820454 | J5: 11843153 | K5: 6186351.1 | L5: =F5-J5 -> 7391144.5
B6: 3 | C6: Planned Profit | D6: =+D4-D5 -> 2256058.8 | F6: =+F4-F5 -> 1704711.5 | H6: 2118554.7 | J6: =J4-J5 -> 966772.97 | K6: =K4-K5 -> 1942732 | L6: =L4-L5 -> 737938.53
B7: 4 | C7: Planned Margin | D7: =+D6/D4 -> 0.1077443 | F7: =+F6/F4 -> 0.08141319 | H7: 0.10117741
B10: CONTRACT | D10: =+D4/'Project Plan'!E3/1000 -> 11.965626
L11: [Finance only]
B12: No. | C12: PAYMENT MILESTONE | E12: % | F12: VALUE | H12: PLANNED PAYMENT DATE | J12: ACTUAL PAYMENT DATE | L12: INVOICE RAISED DATE | N12: MILESTONE NOTES
B13: 1 | C13: Initial deposit | E13: 0.3 | F13: =535734.1725/1.15 -> 465855.8 | H13: =+'Project Plan'!G16+7 -> 44971 | J13: 45386 | L13: 004359 | N13: Add notes relating to the payment / assessment of milestone, draw from EPC contract or CP
F14: =2000000/1.15 -> 1739130.4 | H14: 44971 | J14: 45387 | L14: 004359
F15: =2000000/1.15 -> 1739130.4 | H15: 44971 | J15: 45392 | L15: 004359
F16: =2000000/1.15 -> 1739130.4 | H16: 44971 | J16: 45397 | L16: 004359
F17: =6281702.63091813-F13-F14-F15-F16 -> 598455.52 | H17: 44971 | J17: 45398 | L17: 004359
B18: 2 | C18: Delivery of Main Equipment(Inverters & BOS) | E18: 0.2 | F18: 1140674.9 | H18: 44970 | J18: 45398 | L18: 004359
F19: 1739130.4 | H19: 44970 | J19: 45399 | L19: 004359
F20: =4187801.75394542-F18-F19 -> 1307996.4 | H20: 44970 | J20: 45401 | L20: 004359
B21: 3 | C21: Delivery of Main Equipment(Solar Panels) | E21: 0.25 | F21: 431134.03 | H21: =+'Project Plan'!G23+7+30 -> 45148 | J21: 45401 | L21: 004359
F22: 1739130.4 | H22: 45148 | J22: 45407 | L22: 004359
F23: 1739130.4 | H23: 45148 | J23: 45408 | L23: 004359
F24: =1000000/1.15 -> 869565.22 | H24: 45148 | J24: 45411 | L24: 004359
F25: =5234752.19243177-F21-F22-F23-F24 -> 455792.08 | H25: 45148 | J25: 45412 | L25: 004359
B26: 4 | C26: Installation Complete(Physical Completion) | E26: 0.1 | F26: =$D$4*E26 -> 2093900.9 | H26: =+'Project Plan'!G37+7+30 -> 45205 | J26: 45473 | L26: 004409
B27: 5 | C27: Commissioing Complete(Testing and Checks Complete) | E27: 0.1 | F27: =$D$4*E27 -> 2093900.9 | H27: =+'Project Plan'!G45+7+30 -> 45318 | J27: 45473 | L27: 004409
B28: 6 | C28: Handover complete | E28: 0.05 | F28: =$D$4*E28 -> 1046950.4 | H28: =+H27+7+30 -> 45355 | J28: 45473 | L28: 004409
B29: 6 | E29: 0 | F29: =$D$4*E29 -> 0
B30: 7 | C30: - | E30: 0 | F30: =$D$4*E30 -> 0
E32: =SUM(E13:E30) -> 1 | F32: =SUM(F13:F30) -> 20939009
B34: KEY: | C34: contains an error (in result or a check has failed)
C35: Red Font - IF TEXT : content not yet confirmed
C36: Red Font - IF NUMBER: Negative value
C37: Anything in yellow is a concern or risk for noting or action
C38: confirmed
C39: [ADD INITIALS: comment for noting in square brackets, use colour or red to draw attention if important]
C40: [RT: When adding rows into sheet, ensure you insert between first and last row of each category]
C41: end of sheet - do not insert information below/beyond this
B51: No. | C51: PAYMENT MILESTONE | E51: % | F51: VALUE
B52: 1 | C52: Deposit - Project commencement | E52: 0.35 | F52: =$F$58*E52 -> 7328653.1
B53: 2 | C53: Delivery of Panels | E53: 0.3 | F53: =$F$58*E53 -> 6281702.6
B54: 3 | C54: Delivery of Inverters | E54: 0.2 | F54: =$F$58*E54 -> 4187801.8
...

Sheet Project Plan
C2: PROJECT PLAN | E2: Mega Park Extension
C3: PROJECT SIZE (kWp) | E3: 1749.93
C4: SITE ADDRESS | E4: 17 Mill Rd, Unclear, Cape Town, 7530
C5: BUSINESS DEVELOPER | E5: Natasha Watkins Baker
C6: PROJECT MANAGERS | E6: Roedolph/Simon
C7: PROJECT COORDINATOR | E7: Refiloe Mohohlo
C8: INSTALLER | E8: Smart Solar
C9: CONTRACT VALUE | E9: 20939009
C10: Phase: | E10: DLP
B11: No. | C11: HIGH LEVEL PROGRAMME | E11: Planned Start | F11: Duration (days) | G11: Planned End | I11: Actual Start | J11: Duration (days) | K11: Actual End | M11: Status | O11: Comment
F12: =G45-E20 -> 185 | J12: =K45-I20 -> 234 | M12: =AVERAGE(M14,M19,M22,M29,M36,M42,M47,M57) -> 1
B14: 1 | C14: Project Initiation | E14: =MIN(E15:E17) -> 44798 | F14: =SUM(F15:F17) -> 3 | G14: =MAX(G15:G17) -> 45062 | I14: =MIN(I15:I17) -> 44798 | J14: =SUM(J15:J17) -> 3 | K14: =MAX(K15:K17) -> 45062 | M14: =(J15*M15+J16*M16+J17*M17)/J14 -> 1
B15: 1.1 | C15: Internal Handover | E15: 44798 | F15: 1 | G15: =WORKDAY.INTL(E15,F15,1,Data!$C$3:$C$14) -> 44799 | I15: 44798 | J15: 1 | K15: =WORKDAY.INTL(I15,J15,1,Data!$C$3:$C$14) -> 44799 | M15: 1
B16: 1.2 | C16: Internal kick off | E16: 44963 | F16: 1 | G16: =WORKDAY.INTL(E16,F16,1,Data!$C$3:$C$14) -> 44964 | I16: 44963 | J16: 1 | K16: =WORKDAY.INTL(I16,J16,1,Data!$C$3:$C$14) -> 44964 | M16: 1
B17: 1.3 | C17: Client kick off | E17: 45061 | F17: 1 | G17: =WORKDAY.INTL(E17,F17,1,Data!$C$3:$C$14) -> 45062 | I17: 45061 | J17: 1 | K17: =WORKDAY.INTL(I17,J17,1,Data!$C$3:$C$14) -> 45062 | M17: 1
B19: 2 | C19: Site Establishment | E19: =MIN(E20:E21) -> 45096 | F19: =SUM(F20:F21) -> 2 | G19: =MAX(G20) -> 45098 | I19: =MIN(I20:I21) -> 45096 | J19: =SUM(J20:J21) -> 3 | K19: =MAX(K20) -> 45099 | M19: =(J20*M20)/J19 -> 1
B20: 2.1 | C20: Installer on site and roof assessment | E20: 45096 | F20: 2 | G20: =WORKDAY.INTL(E20,F20,1,Data!$C$3:$C$14) -> 45098 | I20: 45096 | J20: 3 | K20: =WORKDAY.INTL(I20,J20,1,Data!$C$3:$C$14) -> 45099 | M20: 1
B22: 3 | C22: AC Installation | E22: =MIN(E23:E27) -> 45091 | F22: =SUM(F23:F27) -> 90 | G22: =MAX(G23:G27) -> 45204 | I22: =MIN(I23:I27) -> 45092 | J22: =SUM(J23:J27) -> 179 | K22: =MAX(K23:K27) -> 45335 | M22: =(J23*M23+J24*M24+J25*M25+J26*M26+J27*M27)/J22 -> 1
B23: 3.1 | C23: Inverters delivered | E23: 45110 | F23: 1 | G23: =+F23+E23 -> 45111 | I23: 45153 | J23: 1 | K23: =+J23+I23 -> 45154 | M23: 1
B24: 3.2 | C24: Inverters Mounted | E24: =WORKDAY.INTL(G23,0,1,Data!$C$3:$C$14) -> 45111 | F24: 8 | G24: =WORKDAY.INTL(E24,F24,1,Data!$C$3:$C$14) -> 45121 | I24: 45261 | J24: 4 | K24: =WORKDAY.INTL(I24,J24,1,Data!$C$3:$C$14) -> 45267 | M24: 1
B25: 3.3 | C25: Solar DB lead time | E25: =+G20-7 -> 45091 | F25: 40 | G25: =WORKDAY.INTL(E25,F25,1,Data!$C$3:$C$14) -> 45147 | I25: =+K20-7 -> 45092 | J25: 73 | K25: =WORKDAY.INTL(I25,J25,1,Data!$C$3:$C$14) -> 45195 | M25: 1
B26: 3.4 | C26: AC Works | E26: =WORKDAY.INTL(G25,0,1,Data!$C$3:$C$14) -> 45147 | F26: 40 | G26: =WORKDAY.INTL(E26,F26,1,Data!$C$3:$C$14) -> 45203 | I26: =K25 -> 45195 | J26: 100 | K26: =WORKDAY.INTL(I26,J26,1,Data!$C$3:$C$14) -> 45335 | M26: 1 | O26: RT: too long need to push
B27: 3.5 | C27: AC Tie - in | E27: =G26 -> 45203 | F27: 1 | G27: =WORKDAY.INTL(E27,F27,1,Data!$C$3:$C$14) -> 45204 | I27: 45223 | J27: 1 | K27: =WORKDAY.INTL(I27,J27,1,Data!$C$3:$C$14) -> 45224 | M27: 1 | O27: RV: Schedule PrEng
B29: 4 | C29: DC Works | E29: =MIN(E30:E34) -> 45096 | F29: =SUM(F30:F34) -> 103 | G29: =MAX(G30:G34) -> 45239 | I29: =MIN(I30:I34) -> 45099 | J29: =SUM(J30:J34) -> 155 | K29: =MAX(K30:K34) -> 45273 | M29: =(J30*M30+J31*M31+J32*M32+J33*M33+J34*M34)/J29 -> 1
B30: 4.1 | C30: Mounting Structure delivered | E30: 45096 | F30: 1 | G30: =WORKDAY.INTL(E30,F30,1,Data!$C$3:$C$14) -> 45097 | I30: 45099 | J30: 1 | K30: =WORKDAY.INTL(I30,J30,1,Data!$C$3:$C$14) -> 45100 | M30: 1
B31: 4.2 | C31: Mounting Structure installation | E31: =WORKDAY.INTL(G30,0,1,Data!$C$3:$C$14) -> 45097 | F31: 50 | G31: =WORKDAY.INTL(E31,F31,1,Data!$C$3:$C$14) -> 45167 | I31: =WORKDAY.INTL(K30,0,1,Data!$C$3:$C$14) -> 45100 | J31: 50 | K31: =WORKDAY.INTL(I31,J31,1,Data!$C$3:$C$14) -> 45170 | M31: 1
B32: 4.3 | C32: DC Cable delivered | E32: =+G31 -> 45167 | F32: 1 | G32: =WORKDAY.INTL(E32,F32,1,Data!$C$3:$C$14) -> 45168 | I32: =+K31 -> 45170 | J32: 1 | K32: =WORKDAY.INTL(I32,J32,1,Data!$C$3:$C$14) -> 45173 | M32: 1
B33: 4.4 | C33: DC Cable Trays installation | E33: =+G32 -> 45168 | F33: 30 | G33: =WORKDAY.INTL(E33,F33,1,Data!$C$3:$C$14) -> 45210 | I33: =+K32 -> 45173 | J33: 72 | K33: =WORKDAY.INTL(I33,J33,1,Data!$C$3:$C$14) -> 45273 | M33: 1
B34: 4.5 | C34: DC Cabling | E34: =+G33 -> 45210 | F34: 21 | G34: =WORKDAY.INTL(E34,F34,1,Data!$C$3:$C$14) -> 45239 | I34: =+I31+45 -> 45145 | J34: 31 | K34: =WORKDAY.INTL(I34,J34,1,Data!$C$3:$C$14) -> 45188 | M34: 1
B36: 5 | C36: Module installation | E36: =MIN(E37:E40) -> 45167 | F36: =SUM(F37:F41) -> 73 | G36: =MAX(G37:G40) -> 45267 | I36: =MIN(I37:I40) -> 45170 | J36: =SUM(J37:J41) -> 51 | K36: =MAX(K37:K40) -> 45240 | M36: =(J37*M37+J38*M38+J39*M39+J40*M40)/J36 -> 1
B37: 5.1 | C37: Module delivery - Batch 1 | E37: =+G31 -> 45167 | F37: 1 | G37: =WORKDAY.INTL(E37,F37,1,Data!$C$3:$C$14) -> 45168 | I37: =+K31 -> 45170 | J37: 1 | K37: =WORKDAY.INTL(I37,J37,1,Data!$C$3:$C$14) -> 45173 | M37: 1 | O37: RT: we need to start mounting in phases before all MS is complete | P37: {=_xlfn.LET(_xlpm.w,$B$10:$B$53,_xlpm.r,$M$10:$M$53,_xlpm.v,IF(ISNUMBER(_xlpm.r),_xlpm.r,IFERROR(VALUE(SUBSTITUTE(_xlpm.r,"%",""))/100,0)),_xlpm.g,IFERROR(VALUE(LEFT(_xlpm.w,1)),0),_xlpm.bdOnly,(SUMPRODUCT((_xlpm.w="1.1")*(_xlpm.v>0))>0)*(SUMPRODUCT((_xlpm.w<>"1.1")*(_xlpm.v>0))=0),_xlpm.anyConstr,SUMPRODUCT((_xlpm.g>=2)*(_xlpm.g<=6)*(_xlpm.v>0))>0,_xlpm.anyQA,SUMPRODUCT((_xlpm.g=7)*(_xlpm.v>0))>0,_xlpm.anyHO,SUMPRODUCT((_xlpm.g=8)*(_xlpm.v>0))>0,_xlpm.anyPlan,SUMPRODUCT((_xlpm.g=1)*(_xlpm.v>0))>0,IF(_xlpm.bdOnly,"1. Financial Close",IF(_xlpm.anyConstr,"3. Construction",IF(_xlpm.anyQA,"4. QA",IF(_xlpm.anyHO,"5. Handover",IF(_xlpm.anyPlan,"2. Planning","1. Financial Close"))))))} -> 3. Construction | Q37: {=_xlfn.LET(_xlpm.w,$B$10:$B$53,_xlpm.r,$N$10:$N$53,_xlpm.v,IF(ISNUMBER(_xlpm.r),_xlpm.r,IFERROR(VALUE(SUBSTITUTE(_xlpm.r,"%",""))/100,0)),_xlpm.g,IFERROR(VALUE(LEFT(_xlpm.w,1)),0),_xlpm.bdOnly,(SUMPRODUCT((_xlpm.w="1.1")*(_xlpm.v>0))>0)*(SUMPRODUCT((_xlpm.w<>"1.1")*(_xlpm.v>0))=0),_xlpm.anyConstr,SUMPRODUCT((_xlpm.g>=2)*(_xlpm.g<=6)*(_xlpm.v>0))>0,_xlpm.anyQA,SUMPRODUCT((_xlpm.g=7)*(_xlpm.v>0))>0,_xlpm.anyHO,SUMPRODUCT((_xlpm.g=8)*(_xlpm.v>0))>0,_xlpm.anyPlan,SUMPRODUCT((_xlpm.g=1)*(_xlpm.v>0))>0,IF(_xlpm.bdOnly,"1. Financial Close",IF(_xlpm.anyConstr,"3. Construction",IF(_xlpm.anyQA,"4. QA",IF(_xlpm.anyHO,"5. Handover",IF(_xlpm.anyPlan,"2. Planning","1. Financial Close"))))))} -> 1. Financial Close
B38: 5.2 | C38: Module delivery - Batch 2 | E38: =+G37+7 -> 45175 | F38: 1 | G38: =WORKDAY.INTL(E38,F38,1,Data!$C$3:$C$14) -> 45176 | I38: =+K37+7 -> 45180 | J38: 1 | K38: =WORKDAY.INTL(I38,J38,1,Data!$C$3:$C$14) -> 45181 | M38: 1
B39: 5.3 | C39: Module delivery - Batch 3 | E39: =+G38+7 -> 45183 | F39: 1 | G39: =WORKDAY.INTL(E39,F39,1,Data!$C$3:$C$14) -> 45184 | I39: =+K38+7 -> 45188 | J39: 1 | K39: =WORKDAY.INTL(I39,J39,1,Data!$C$3:$C$14) -> 45189 | M39: 1
B40: 5.4 | C40: Module mounting | E40: =WORKDAY.INTL(G37,0,1,Data!$C$3:$C$14)+1 -> 45169 | F40: 70 | G40: =WORKDAY.INTL(E40,F40,1,Data!$C$3:$C$14) -> 45267 | I40: =WORKDAY.INTL(K37,0,1,Data!$C$3:$C$14)+1 -> 45174 | J40: 48 | K40: =WORKDAY.INTL(I40,J40,1,Data!$C$3:$C$14) -> 45240 | M40: 1 | O40: RT: too long need to push
B42: 6 | C42: Commissioning | E42: =MIN(E43:E45) -> 0 | F42: =SUM(F43:F46) -> 13 | G42: =MAX(G43:G45) -> 45281 | I42: =MIN(I43:I45) -> 45317 | J42: =SUM(J43:J46) -> 6 | K42: =MAX(K43:K45) -> 45330 | M42: 1
B43: 6.1 | C43: Cold commissioning | E43: =WORKDAY.INTL(G40,0,1,Data!$C$3:$C$14) -> 45267 | F43: 3 | G43: =WORKDAY.INTL(E43,F43,1,Data!$C$3:$C$14) -> 45272 | I43: 45317 | J43: 1 | K43: =WORKDAY.INTL(I43,J43,1,Data!$C$3:$C$14) -> 45320 | M43: 1 | O43: 6x inverters are switched on, not all of them have strings plugged in.
B44: 6.2 | C44: Cold commissioning - Phased | E44: =WORKDAY.INTL(G41,0,1,Data!$C$3:$C$14) -> 0 | F44: 3 | G44: =WORKDAY.INTL(E44,F44,1,Data!$C$3:$C$14) -> 4 | I44: 45321 | J44: 1 | K44: =WORKDAY.INTL(I44,J44,1,Data!$C$3:$C$14) -> 45322 | M44: 1
B45: 6.3 | C45: Practical Completion | E45: =WORKDAY.INTL(G43,0,1,Data!$C$3:$C$14) -> 45272 | F45: 7 | G45: =WORKDAY.INTL(E45,F45,1,Data!$C$3:$C$14) -> 45281 | I45: =WORKDAY.INTL(K43,0,1,Data!$C$3:$C$14)+4 -> 45324 | J45: 4 | K45: =WORKDAY.INTL(I45,J45,1,Data!$C$3:$C$14) -> 45330 | M45: 1 | O45: Next 6x inverters to be switched.
B47: 7 | C47: Project Closure | E47: =MIN(E48:E55) -> 45302 | F47: =SUM(F48:F53) -> 12 | G47: =MAX(G48:G55) -> 45322 | I47: =MIN(I48:I55) -> 45330 | J47: =SUM(J48:J53) -> 58 | K47: =MAX(K48:K55) -> 45425 | M47: 1
B48: 7.1 | C48: Equipment serial numbers | E48: =WORKDAY.INTL(E50,0,1,Data!$C$3:$C$14) -> 45302 | F48: 0 | G48: =WORKDAY.INTL(E48,F48,1,Data!$C$3:$C$14) -> 45302 | I48: =WORKDAY.INTL(K45,0,1,Data!$C$3:$C$14) -> 45330 | J48: 1 | K48: =WORKDAY.INTL(I48,J48,1,Data!$C$3:$C$14) -> 45331 | M48: 1
...

Sheet Data
C2: Public holidays | F2: Drop down list
C3: 44197 | F3: Approved
C4: 44277 | F4: Pending
C5: 44288 | F5: Declined
C6: 44291 | F6: Abanded
C7: 44313
C8: 44317
C9: 44363
C10: 44417
C11: 44463
C12: 44546
C13: 44555 | H13: Manual dates
C14: 44556

Sheet Expenditure Tracking
B2: HIGH LEVEL PROJECT EXPENDITURE TRACKING
F4: PLANNED | H4: ACTUAL | J4: Difference
B5: EXPENDITURE | F5: =SUM(F9:F22) -> 18682950 | H5: =SUM(H9:H22) -> 19234297 | J5: =SUM(J9:J22) -> -551347.32
B7: No. | D7: Item | F7: Planned Expenditure | H7: Actual Expenditure | J7: Saving / Overrun | L7: Comments on variations from planned expenditure
B9: ='Expenditure Breakdown'!B6 -> 1 | D9: ='Expenditure Breakdown'!C6 -> Panels | F9: ='Expenditure Breakdown'!J6 -> 8604405.8 | H9: ='Expenditure Breakdown'!V6 -> 7861415.3 | J9: =F9-H9 -> 742990.53
B10: ='Expenditure Breakdown'!B28 -> 2 | D10: ='Expenditure Breakdown'!C28 -> Inverters | F10: =+'Expenditure Breakdown'!J28 -> 1020000 | H10: =+'Expenditure Breakdown'!V28 -> 1056455 | J10: =F10-H10 -> -36455
B11: ='Expenditure Breakdown'!B34 -> 3 | D11: ='Expenditure Breakdown'!C34 -> Mounting Structures | F11: =+'Expenditure Breakdown'!J34 -> 524979 | H11: =+'Expenditure Breakdown'!V34 -> 351446.8 | J11: =F11-H11 -> 173532.2
B12: ='Expenditure Breakdown'!B40 -> 4 | D12: ='Expenditure Breakdown'!C40 -> DC Equipment | F12: =+'Expenditure Breakdown'!J40 -> 637505.76 | H12: =+'Expenditure Breakdown'!V40 -> 1160597.8 | J12: =F12-H12 -> -523092
B13: ='Expenditure Breakdown'!B54 -> 5 | D13: ='Expenditure Breakdown'!C54 -> Monitoring | F13: =+'Expenditure Breakdown'!J54 -> 24567 | H13: =+'Expenditure Breakdown'!V54 -> 102506.6 | J13: =F13-H13 -> -77939.6
B14: ='Expenditure Breakdown'!B76 -> 6 | D14: ='Expenditure Breakdown'!C76 -> AC Equipment | F14: =+'Expenditure Breakdown'!J76 -> 637698.26 | H14: =+'Expenditure Breakdown'!V76 -> 954731.35 | J14: =F14-H14 -> -317033.09
B15: ='Expenditure Breakdown'!B88 -> 7 | D15: ='Expenditure Breakdown'!C88 -> Product Add On | F15: ='Expenditure Breakdown'!J88 -> 4530000 | H15: ='Expenditure Breakdown'!V88 -> 625278.52 | J15: =F15-H15 -> 3904721.5
B16: ='Expenditure Breakdown'!B106 -> 8 | D16: ='Expenditure Breakdown'!C106 -> AC & DC installation | F16: =+'Expenditure Breakdown'!J106 -> 1661472 | H16: =+'Expenditure Breakdown'!V106 -> 1378000 | J16: =F16-H16 -> 283472
B17: ='Expenditure Breakdown'!B116 -> 9 | D17: ='Expenditure Breakdown'!C116 -> Site Logistics | F17: =+'Expenditure Breakdown'!J116 -> 289840.03 | H17: =+'Expenditure Breakdown'!V116 -> 143094.86 | J17: =F17-H17 -> 146745.17
B18: ='Expenditure Breakdown'!B134 -> 10 | D18: ='Expenditure Breakdown'!C134 -> Due Dilligence | F18: ='Expenditure Breakdown'!J134 -> 78746.85 | H18: ='Expenditure Breakdown'!V134 -> 54897.75 | J18: =F18-H18 -> 23849.1
B19: ='Expenditure Breakdown'!B142 -> 11 | D19: ='Expenditure Breakdown'!C142 -> BDP Commission | F19: =+'Expenditure Breakdown'!J142 -> 0 | H19: =+'Expenditure Breakdown'!V142 -> 0 | J19: =F19-H19 -> 0
B20: ='Expenditure Breakdown'!B144 -> 12 | D20: ='Expenditure Breakdown'!C144 -> Engineering | F20: =+'Expenditure Breakdown'!J144 -> 661555.24 | H20: =+'Expenditure Breakdown'!V144 -> 133516.32 | J20: =F20-H20 -> 528038.92
B21: ='Expenditure Breakdown'!B155 -> 13 | D21: ='Expenditure Breakdown'!C155 -> General Expenses | F21: =+'Expenditure Breakdown'!J155 -> 12180 | H21: =+'Expenditure Breakdown'!V155 -> 5372.6 | J21: =F21-H21 -> 6807.4
B22: ='Expenditure Breakdown'!B170 -> 14 | D22: ='Expenditure Breakdown'!C170 -> Service Add On | F22: =+'Expenditure Breakdown'!J170 -> 0 | H22: =+'Expenditure Breakdown'!V170 -> 5406984.4 | J22: =F22-H22 -> -5406984.4
D24: check: | F24: ='Expenditure Breakdown'!J2-F5 -> 0 | G24: ='Expenditure Breakdown'!#REF!-G5 -> #REF! | H24: ='Expenditure Breakdown'!V2-H5 -> 0

Sheet Installer Payment Schedule

Sheet Expenditure Breakdown
B2: PLANNED EXPENDITURE BREAKDOWN | J2: =SUM(J6:J214) -> 18682950 | L2: ACTUAL EXPENDITURE BREAKDOWN | V2: =SUM(V6:V214) -> 19234297 | W2: Comment
B4: No. | C4: Product / Service | D4: Description of Work | E4: QTY | F4: Rate / Unit | G4: Budget Total | H4: Payment date | J4: Total | L4: No. | M4: Prodcut / Service | N4: Description of Work | O4: QTY | P4: Rate / Unit | Q4: Actual Total | R4: Payment date | T4: PO NUMBER | U4: [Finance Only] INVOICE RECEIPT DATE | V4: Total
B6: 1 | C6: Panels | D6: Longi 455 | E6: 3846 | F6: 0.1 | G6: =$C$11*F6 -> 860440.58 | H6: ='Project Plan'!G20 -> 45098 | J6: =SUM(G6:G26) -> 8604405.8 | L6: =B6 -> 1 | M6: Panels | N6: Jinko 550Wp | O6: 3182 | P6: 0.1 | Q6: =+N11*P6 -> 799123.45 | R6: 45090 | T6: =Q6+Q11 -> 2093284.6 | U6: 45107 | V6: =SUM(Q6:Q26) -> 7861415.3 | X6: RT: this is from the PO Dayne signed: | Y6: Jinko ORDER 22 May
L7: 1 | M7: Panels | Q7: 379626.82 | R7: 45344 | U7: 45107
L8: 1 | M8: Panels | Q8: 881171.97 | R8: 45373 | U8: 45107
L9: 1 | M9: Panels | Q9: 1554041.6 | R9: 45376 | U9: 45107
L10: 1 | M10: Panels | Q10: 3083109.5 | R10: 45384 | U10: 45107
B11: 1 | C11: 8604405.8 | D11: 7265214 | F11: 0.9 | G11: =$C$11*F11 -> 7743965.2 | H11: =H6+30 -> 45128 | L11: 1 | M11: Panels | N11: 7991234.5 | P11: 0.9 | Q11: =7192111.01640814-Q7-Q8-Q9-Q10 -> 1294161.2 | R11: 45384 | U11: 45107 | Y11: =117849/(930*550) -> 0.23039883 | Z11: USD/Wp FCA Walvis Bay
L12: 1 | M12: Panels | N12: Allocated to 26 Marine Drive | O12: -75 | P12: =Q12/O12 -> 2511.39 | Q12: -188354.25 | R12: 45443 | U12: 45443
B13: 1 | D13: Module delivery to site | G13: 0 | H13: =H11 -> 45128 | L13: 1 | M13: Panels | N13: Shipping and Clearing | Q13: 39939.25 | R13: 45199 | U13: 45169 | X13: USD RoE: | Y13: 19.5 | Z13: as of 22 May
L14: 1 | M14: Panels | Q14: 3997.43 | R14: 45139 | U14: 45169
B15: 1 | L15: 1 | M15: Panels | N15: Shipping and Clearing | Y15: =(Y11)*Y13 -> 4.4927771 | Z15: per Wp
D16: Cash handling / Admin fees on | L16: 1 | M16: Panels
L17: 1 | M17: Panels | N17: Balance of order that went to Sable Square (6 Pallets)
L18: 1 | M18: Panels | N18: Jinko 550W | O18: 186
L19: 1 | M19: Panels
L20: 1 | M20: Panels | N20: Cash handling / Admin fees on | Q20: 5328.39 | R20: 45105 | U20: 45107
L21: 1 | M21: Panels
L22: 1 | M22: Panels | N22: Silver solutions - Forklift hire | Q22: 4300 | R22: 45225 | U22: 45230
L23: 1 | M23: Panels
L24: 1 | M24: Panels | N24: Delivery to storage | Q24: 4550 | R24: 45246 | U24: 45230
B25: 1 | L25: =B25 -> 1 | M25: Panels | N25: Handling in/Handling out | Q25: 420 | R25: 45246 | U25: 45230
B26: 1 | L26: =B26 -> 1 | M26: Panels | Y26: =+'Project Plan'!E3*Y15*1000 -> 7862045.5 | Z26: final price tbc once FEC booked
B28: 2 | C28: Inverters | D28: SMA 110 | E28: 12 | F28: 85000 | G28: =E28*F28 -> 1020000 | H28: ='Project Plan'!G23+30 -> 45141 | J28: =SUM(G28:G32) -> 1020000 | L28: =B28 -> 2 | M28: Inverters | N28: Huawei 100ktl - Deposit | O28: 12 | P28: 89060 | Q28: =O28*P28*0.1 -> 106872 | R28: 45155 | U28: 45169 | V28: =SUM(Q28:Q32) -> 1056455 | W28: changed from 89000
B29: 2 | H29: =H28 -> 45141 | L29: =B29 -> 2 | M29: Inverters | N29: Huawei 100KTl - Balance | Q29: =O28*P28*0.9 -> 961848 | R29: 45202 | U29: 45169
L30: 2 | M30: Inverters | N30: Huawei 100KTl - Replace faulty Inverter | Q30: 76795 | R30: 45474 | U30: 45443
B31: 2 | L31: =B31 -> 2 | M31: Inverters | N31: Huawei 100KTl - RMA from Supplaier allocated to Stock | Q31: -89060 | R31: 45535 | U31: 45535
B32: 2 | L32: =B32 -> 2 | M32: Inverters
B34: 3 | C34: Mounting Structures | D34: Lumax | G34: =+'Project Plan'!E3*0.3*1000 -> 524979 | H34: ='Project Plan'!G30+30 -> 45127 | J34: =SUM(G34:G38) -> 524979 | L34: =B34 -> 3 | M34: Mounting Structures | N34: Schletter | P34: =Q34/'Project Plan'!E3/1000 -> 0.18316276 | Q34: 320522 | R34: 45148 | U34: 45107 | V34: =SUM(Q34:Q38) -> 351446.8
B35: 3 | L35: =B35 -> 3 | M35: Mounting Structures | Q35: 24371 | R35: 45148 | U35: 45107
M36: Mounting Structures | N36: Schletter - Additional Clamps | Q36: 6553.8 | R36: 45351 | U36: 45351
B37: 3 | L37: =B37 -> 3 | M37: Mounting Structures | N37: Stock allocated to Dekro Paint | Q37: =18280.34*-1 -> -18280.34 | R37: 45138 | U37: =U35 -> 45107
B38: 3 | L38: =B38 -> 3 | M38: Mounting Structures | N38: Received the stock back from Dekro Paint | Q38: =Q37*-1 -> 18280.34 | R38: 45138 | U38: =U37 -> 45107
B40: 4 | C40: DC Equipment | D40: DC Cable | E40: 29292 | F40: 11.28 | G40: =E40*F40 -> 330413.76 | H40: =+'Project Plan'!K32+30 -> 45203 | J40: =SUM(G40:G51) -> 637505.76 | L40: =B40 -> 4 | M40: DC Equipment | N40: DC Cable - Red - Delivered | O40: 20000 | P40: 13.92 | Q40: =O40*P40 -> 278400 | R40: 45169 | T40: Rubicon Bulk Order | U40: 45169 | V40: =SUM(Q40:Q51) -> 1160597.8
B41: 4 | D41: Earth Cable | E41: =+E40 -> 29292 | F41: 10.3 | G41: =E41*F41 -> 301707.6 | H41: =+H40 -> 45203 | L41: =B41 -> 4 | M41: DC Equipment | N41: DC Cable - Black - Delivered | O41: 20000 | P41: 13.92 | Q41: =O41*P41 -> 278400 | R41: =R40 -> 45169 | T41: Rubicon Bulk Order | U41: 45169
M43: DC Equipment | N43: DC Cable - Zonn - Red | O43: 3500 | P43: 15.47 | Q43: =O43*P43 -> 54145 | R43: 45205 | U43: 45169
M44: DC Equipment | N44: DC Cable - Zonn - Black | O44: 3500 | P44: 14.6 | Q44: =O44*P44 -> 51100 | R44: 45205 | U44: 45169
M46: DC Equipment | N46: DC Cable - KBE - Red - Krannich | O46: 3000 | P46: 14.28 | Q46: 42841.93 | R46: 45243 | T46: =SUM(Q46:Q47) -> 85683.86 | U46: 45230
M47: DC Equipment | N47: DC Cable - KBE - Black - Krannich | O47: 3000 | P47: 14.28 | Q47: 42841.93 | R47: 45243 | U47: 45230
Q48: 725 | R48: 45243 | U48: 45230
...

Sheet Expenditure Breakdown-IDC
A2: ACTUAL EXPENDITURE BREAKDOWN | H2: =SUM(H6:H93) -> 18009414
A4: No. | B4: Prodcut / Service | C4: Description of Work | D4: QTY | E4: Rate / Unit | F4: Actual Total | G4: Payment date | H4: Total | I4: DIRECTORY & COMMENTS (The below indicates the directory of the invoices for the associated material/service that incurred an expense during the project)
A6: 1 | B6: Panels | C6: Jinko 550W Solar Panel - Deposit | D6: 3182 | E6: 0.1 | F6: 799123.45 | G6: 45090 | H6: 8049769.5 | I6: IDC Funding\Busamed+Spear Round2\Busamed+Spear Shared Folder\7. Drawdown Requests\Mega Park Phase 2\Invoices\1. Panels
A7: 1 | B7: Panels | C7: Jinko 550W Solar Panel - Balance | E7: 0.9 | F7: 7192111 | G7: 45327
A8: 1 | B8: Panels | C8: Shipping and Clearing | F8: 39939.25 | G8: 45199
A9: 1 | B9: Panels | C9: Shipping and Clearing | F9: 3997.43 | G9: 45139
A10: 1 | B10: Panels | C10: Cash handling / Admin fees on | F10: 5328.39 | G10: 45105
A11: 1 | B11: Panels | C11: Silver solutions - Forklift hire | F11: 4300 | G11: 45225
A12: 1 | B12: Panels | C12: Delivery to storage | F12: 4550 | G12: 45246
A13: 1 | B13: Panels | C13: Handling in/Handling out | F13: 420 | G13: 45246
A15: 2 | B15: Inverters | C15: Huawei 100ktl - Deposit | D15: 12 | E15: 89060 | F15: 106872 | G15: 45155 | H15: 1068720 | I15: IDC Funding\Busamed+Spear Round2\Busamed+Spear Shared Folder\7. Drawdown Requests\Mega Park Phase 2\Invoices\2. Inverters
A16: 2 | B16: Inverters | C16: Huawei 100KTl - Balance | F16: 961848 | G16: 45202
A18: 3 | B18: Mounting Structures | C18: Schletter | F18: 320522 | G18: 45148 | H18: 351446.8 | I18: IDC Funding\Busamed+Spear Round2\Busamed+Spear Shared Folder\7. Drawdown Requests\Mega Park Phase 2\Invoices\3. Balance of System
