Workbook
Name Inverter_Capacity: #REF!
Name Inverter_Supplier: #REF!
Name Project_Size: 'Finance - Revenue'!Projectsize
Name Project_Size: Projectsize
Name Projectsize: #REF!
Name Projectsize: #REF!
Name Security_Serv: #REF!
Name Security_Serv: #REF!
Name SSS: #REF!
Name SSS: #REF!
Name USD_ZAR: #REF!

Sheet Certificate - Financial Close
B2: Emergent Energy – Financial Close Completion Certificate | H2: FINANCIAL CLOSE CERTIFICATE
B4: Project Name: | C4: ='Project Plan'!E2 -> PnP Bethal
B5: COO: | C5: Johannes Potgieter
B6: Programme Manager: | C6: Roedolph Venter
B7: HoPD: | C7: Natasha Watkins-Baker
B9: Date of Phase Completion:
B10: Phase Deliverables Checklist: (Y/N)
B11: Product Agreement
B12: EPC Agreement
B13: O&M Agreeement
B14: Cost Proposal
B15: Deposit Received
B16: Risks / Notes
B18: Acknowledgement and Acceptance:
B19: Role | C19: Name | D19: Signature | E19: Date

Sheet Certificate - Planning
B2: Emergent Energy – Planning Phase Completion Certificate | H2: PLANNING CERTIFICATE
B4: Project Name: | C4: ='Project Plan'!E2 -> PnP Bethal
B5: Client Representative:
B6: Programme Manager: | C6: Roedolph Venter
B7: Project Manager: | C7: ='Project Plan'!E5 -> Eon Van Rensburg
B8: Project Engineer:
B10: Date of Phase Completion:
B11: Phase Deliverables Checklist: (Y/N)
B12: Project Introduction Presentation
B13: Project Brief
B14: Engineering Pack
B15: BOQ
B16: PO – Material & Equipment
B17: PO - Contractors
B18: HSE – NOC
B19: HSE – EE File
B20: HSE – Contractor File
... B24: Acknowledgement and Acceptance:
B25: Role | C25: Name | D25: Signature | E25: Date

Sheet Change Register
F1: Change Register
B3: ID | C3: Description | D3: Supporting Image (If Applicable) | E3: Impact | F3: Proposed Date | G3: Proposed By | H3: Status | I3: Approved By | J3: Approved Date | K3: Results / Comments
B4: DEC001
B5: DEC002
B6: DEC003
B7: DEC004
B8: DEC005
B9: DEC006
B10: DEC007
B11: DEC008
B12: DEC009
B13: DEC010
B14: DEC011
B15: DEC012
... B33: DEC030

Sheet BOQ
B2: Item | C2: Supplier | D2: Description | E2: Quantity | F2: Comments
B3: PV Module | C3: Menlo | D3: JKM620N-66HL4M-BDV | E3: 565
B4: DC Cable Red & Black | C4: Menlo | D4: DC cable | E4: 10000
B5: Inverters | C5: Herholdts | D5: Sungrow 125kW and 2 X 25kW Hybrid inverter | E5: 3
B6: Mounting Structure | C6: Schletter | D6: 420kWp IBR | E6: 1
B7: Current Transformers (Production) | C7: Techsitter | D7: 600/5A | E7: 3
B8: Current Transformers (Consumption) | C8: Accuenergy | D8: 1500A 16" + 1000A 16" | E8: 3 + 3
B9: Solar Production Meter (Techistter) | C9: Techsitter | D9: Techsitter Meter | E9: 1
B10: Grid Consumption Meter | C10: Accuenergy | D10: Acurev1313 | E10: 2
B11: Wi-Fi Router & Sim | C11: Accuenergy | D11: Teltonika RUT241 | E11: 1
B12: Switch | C12: Accuenergy | D12: Teltonika TSW2000 8 Port | E12: 1
B13: Back Up Battery | C13: Herholdts | D13: 25kWh Sungrow battery | E13: 4
B14: PVDB | C14: Switchboard | D14: Complete PVDB | E14: 1
B15: Comms DB | C15: Switchboard | D15: Comms DB enclosure | E15: 1
B23: Supplier List
B24: Accuenergy
B25: Krannich
B26: Menlo
B27: Red Pole
B28: Schletter
B29: Switchboard
B30: Techsitter
B31: Herholdts

Sheet Compliance
B2: HSE
B4: Description | C4: Status | D4: Approved By | E4: Date | F4: Results / Comments
B5: NOC | F5: In progress
B6: 7.1 Agreement | F6: In progress
B7: 13.2 Agreement | F7: In progress
B8: EE File | F8: In progress
B9: Subbie File | F9: Not appointed yet
B16: SSEG
B18: Description | C18: Status | D18: Approved By | E18: Date | F18: Results / Comments
B19: SSEG Application
B20: PTI
B21: Commissioning Approval

Sheet Project Plan
N1: =TODAY() -> 46085 | O1: =TODAY() -> 46085
C2: PROJECT PLAN | E2: PnP Bethal | I2: Net Work Days | K2: =NETWORKDAYS(I19,K43,Data!C3:C60) -> 42 | N2: 0 | O2: 1
C3: PROJECT SIZE (kWp) | E3: 420 | I3: Total Weeks | K3: =K2/5 -> 8.4
C4: PROJECT DEVELOPER | E4: Megan Moore | I4: kW/Week Installation Rate | K4: =E3/K3 -> 50
C5: PROJECT MANAGERS | E5: Eon Van Rensburg
C6: CONTRACT VALUE | E6: 4119606.9
C7: Phase: | E7: Planning
B8: No. | C8: HIGH LEVEL PROGRAMME | E8: Planned Start | F8: Duration | G8: Planned End | I8: Actual Start | J8: Duration | K8: Actual End | M8: Status | N8: Expected Status | O8: Comment
F9: =G43-E20 -> 63 | J9: =K43-I20 -> 63 | M9: =AVERAGE(M11,M19,M22,M32,M39,M43,M52,M48) -> 0.022912886 | N9: =AVERAGE(N11,N19,N22,N32,N39,N43,N52,N48) -> 0.026202359 | S9: =TODAY() -> 46085 | T9: =TODAY() -> 46085
S10: 1 | T10: 0
B11: 1 | C11: Project Initiation | E11: =MIN(E12:E18) -> 46043 | F11: =G11-E11 -> 50 | G11: =MAX(G12:G18) -> 46093 | I11: =MIN(I12:I18) -> 46043 | J11: =K11-I11 -> 50 | K11: =MAX(K12:K18) -> 46093 | M11: =(J12*M12+J14*M14+J15*M15+J16*M16+J17*M17)/SUM(J12:J17) -> 0.13157895 | N11: =(J12*N12+J14*N14+J15*N15+J16*N16+J17*N17)/SUM(J12:J17) -> 0.15789474
B12: 1.1 | C12: Project Charter Handover | E12: 46043 | F12: 1 | G12: 46043 | I12: 46043 | J12: 1 | K12: 46043 | M12: 1 | N12: =_xlfn.LET( _xlpm.s,VALUE($I12), _xlpm.e,VALUE($K12), IF(OR(_xlpm.s="",_xlpm.e=""),"", IF(_xlpm.e<=_xlpm.s, IF(TODAY()>=_xlpm.e,1,0), MAX(0,MIN(1,(TODAY()-_xlpm.s)/(_xlpm.e-_xlpm.s))))) ) -> 1 | S12: Milestone | T12: Start Date | U12: Duration | V12: End Date
C13: Deposit | E13: =E12 -> 46043 | F13: 25 | G13: =WORKDAY.INTL(E13,F13,1,Data!$C$3:$C$60) -> 46078 | I13: =I12 -> 46043 | J13: 25 | K13: =WORKDAY.INTL(I13,J13,1,Data!$C$3:$C$60) -> 46078 | M13: 1 | N13: 1 | S13: =C11 -> Project Initiation | T13: =I11 -> 46043 | U13: =J11 -> 50 | V13: =K11 -> 46093
B14: 1.2 | C14: HSE Readiness and Signoff | E14: =G13 -> 46078 | F14: 5 | G14: =WORKDAY.INTL(E14,F14,1,Data!$C$3:$C$60) -> 46085 | I14: =K13 -> 46078 | J14: 5 | K14: =WORKDAY.INTL(I14,J14,1,Data!$C$3:$C$60) -> 46085 | M14: 0.8 | N14: =_xlfn.LET( _xlpm.s,VALUE($I14), _xlpm.e,VALUE($K14), IF(OR(_xlpm.s="",_xlpm.e=""),"", IF(_xlpm.e<=_xlpm.s, IF(TODAY()>=_xlpm.e,1,0), MAX(0,MIN(1,(TODAY()-_xlpm.s)/(_xlpm.e-_xlpm.s))))) ) -> 1 | S14: =C19 -> Site Establishment | T14: =I19 -> 46090 | U14: =J19 -> 1 | V14: =K19 -> 46091
B15: 1.3 | C15: Project Introduction | E15: =WORKDAY.INTL(G14,0,1,Data!$C$3:$C$60) -> 46085 | F15: 1 | G15: =WORKDAY.INTL(E15,F15,1,Data!$C$3:$C$60) -> 46086 | I15: =WORKDAY.INTL(K14,0,1,Data!$C$3:$C$60) -> 46085 | J15: 1 | K15: =WORKDAY.INTL(I15,J15,1,Data!$C$3:$C$60) -> 46086 | M15: 0 | N15: =_xlfn.LET( _xlpm.s,VALUE($I15), _xlpm.e,VALUE($K15), IF(OR(_xlpm.s="",_xlpm.e=""),"", IF(_xlpm.e<=_xlpm.s, IF(TODAY()>=_xlpm.e,1,0), MAX(0,MIN(1,(TODAY()-_xlpm.s)/(_xlpm.e-_xlpm.s))))) ) -> 0 | S15: =C22 -> AC Installation | T15: =I22 -> 46071 | U15: =J22 -> 63 | V15: =K22 -> 46134
B16: 1.4 | C16: Installer Kick Off | E16: =WORKDAY.INTL(E14,0,1,Data!$C$3:$C$60)+14 -> 46092 | F16: 1 | G16: =WORKDAY.INTL(E16,F16,1,Data!$C$3:$C$60) -> 46093 | I16: =WORKDAY.INTL(I14,0,1,Data!$C$3:$C$60)+14 -> 46092 | J16: 1 | K16: =WORKDAY.INTL(I16,J16,1,Data!$C$3:$C$60) -> 46093 | M16: 0 | N16: =_xlfn.LET( _xlpm.s,VALUE($I16), _xlpm.e,VALUE($K16), IF(OR(_xlpm.s="",_xlpm.e=""),"", IF(_xlpm.e<=_xlpm.s, IF(TODAY()>=_xlpm.e,1,0), MAX(0,MIN(1,(TODAY()-_xlpm.s)/(_xlpm.e-_xlpm.s))))) ) -> 0 | S16: =C32 -> DC Works | T16: =I32 -> 46090 | U16: =J32 -> 23 | V16: =K32 -> 46113
B17: 1.5 | C17: Project Review | E17: =WORKDAY.INTL(G14,0,1,Data!$C$3:$C$60) -> 46085 | F17: 5 | G17: =WORKDAY.INTL(E17,F17,1,Data!$C$3:$C$60) -> 46092 | I17: =WORKDAY.INTL(K14,0,1,Data!$C$3:$C$60) -> 46085 | J17: 5 | K17: =WORKDAY.INTL(I17,J17,1,Data!$C$3:$C$60) -> 46092 | M17: 0 | N17: =_xlfn.LET( _xlpm.s,VALUE($I17), _xlpm.e,VALUE($K17), IF(OR(_xlpm.s="",_xlpm.e=""),"", IF(_xlpm.e<=_xlpm.s, IF(TODAY()>=_xlpm.e,1,0), MAX(0,MIN(1,(TODAY()-_xlpm.s)/(_xlpm.e-_xlpm.s))))) ) -> 0 | S17: =C39 -> Module installation | T17: =I39 -> 46090 | U17: =J39 -> 17 | V17: =K39 -> 46107
S18: =C43 -> Commissioning | T18: =I43 -> 46134 | U18: =J43 -> 19 | V18: =K43 -> 46153
B19: 2 | C19: Site Establishment | E19: =MIN(E20:E21) -> 46090 | F19: =G19-E19 -> 1 | G19: =MAX(G20:G21) -> 46091 | I19: =MIN(I20:I21) -> 46090 | J19: =K19-I19 -> 1 | K19: =MAX(K20:K21) -> 46091 | M19: =(J20*M20)/J19 -> 0 | N19: =(K20*N20)/K19 -> 0 | S19: =C48 -> QA Inspections | T19: =I48 -> 46146 | U19: =J48 -> 8 | V19: =K48 -> 46154
B20: 2.1 | C20: Solar Contractor Establishment | E20: 46090 | F20: 1 | G20: =E20+F20 -> 46091 | I20: 46090 | J20: 1 | K20: =I20+J20 -> 46091 | M20: 0 | N20: =_xlfn.LET( _xlpm.s,VALUE($I20), _xlpm.e,VALUE($K20), IF(OR(_xlpm.s="",_xlpm.e=""),"", IF(_xlpm.e<=_xlpm.s, IF(TODAY()>=_xlpm.e,1,0), MAX(0,MIN(1,(TODAY()-_xlpm.s)/(_xlpm.e-_xlpm.s))))) ) -> 0 | S20: =C52 -> Project Closure | T20: =I52 -> 46149 | U20: =J52 -> 13 | V20: =K52 -> 46162
B22: 3 | C22: AC Installation | E22: =MIN(E23:E31) -> 46071 | F22: =G22-E22 -> 63 | G22: =MAX(G23:G31) -> 46134 | I22: =MIN(I23:I31) -> 46071 | J22: =K22-I22 -> 63 | K22: =MAX(K23:K31) -> 46134 | M22: =(J23*M23+J24*M24+J25*M25+J27*M27+J30*M30)/SUM(J23:J30) -> 0.051724138 | N22: =(J23*M23+J24*M24+J25*M25+J27*M27+J30*M30)/SUM(J23:J30) -> 0.051724138
B23: 3.1 | C23: Inverters delivered | E23: =WORKDAY.INTL(E20,0,1,Data!$C$3:$C$60) -> 46090 | F23: 1 | G23: =WORKDAY.INTL(E23,F23,1,Data!$C$3:$C$60) -> 46091 | I23: =WORKDAY.INTL(I20,0,1,Data!$C$3:$C$60) -> 46090 | J23: 1 | K23: =WORKDAY.INTL(I23,J23,1,Data!$C$3:$C$60) -> 46091 | M23: 0 | N23: =_xlfn.LET( _xlpm.s,VALUE($I23), _xlpm.e,VALUE($K23), IF(OR(_xlpm.s="",_xlpm.e=""),"", IF(_xlpm.e<=_xlpm.s, IF(TODAY()>=_xlpm.e,1,0), MAX(0,MIN(1,(TODAY()-_xlpm.s)/(_xlpm.e-_xlpm.s))))) ) -> 0
B24: 3.2 | C24: Inverters Mounted | E24: =WORKDAY.INTL(G23,0,1,Data!$C$3:$C$60) -> 46091 | F24: 1 | G24: =WORKDAY.INTL(E24,F24,1,Data!$C$3:$C$60) -> 46092 | I24: =WORKDAY.INTL(K23,0,1,Data!$C$3:$C$60) -> 46091 | J24: 1 | K24: =WORKDAY.INTL(I24,J24,1,Data!$C$3:$C$60) -> 46092 | M24: 0 | N24: =_xlfn.LET( _xlpm.s,VALUE($I24), _xlpm.e,VALUE($K24), IF(OR(_xlpm.s="",_xlpm.e=""),"", IF(_xlpm.e<=_xlpm.s, IF(TODAY()>=_xlpm.e,1,0), MAX(0,MIN(1,(TODAY()-_xlpm.s)/(_xlpm.e-_xlpm.s))))) ) -> 0
B25: 3.3 | C25: Solar DB Lead Time | E25: =WORKDAY.INTL(E15,0,1,Data!$C$3:$C$60)-14 -> 46071 | F25: 30 | G25: =WORKDAY.INTL(E25,F25,1,Data!$C$3:$C$60) -> 46113 | I25: =WORKDAY.INTL(I15,0,1,Data!$C$3:$C$60)-14 -> 46071 | J25: 30 | K25: =WORKDAY.INTL(I25,J25,1,Data!$C$3:$C$60) -> 46113 | M25: 0.1 | N25: =_xlfn.LET( _xlpm.s,VALUE($I25), _xlpm.e,VALUE($K25), IF(OR(_xlpm.s="",_xlpm.e=""),"", IF(_xlpm.e<=_xlpm.s, IF(TODAY()>=_xlpm.e,1,0), MAX(0,MIN(1,(TODAY()-_xlpm.s)/(_xlpm.e-_xlpm.s))))) ) -> 0.33333333
B26: 3.4 | C26: BESS Delivery | E26: =E24 -> 46091 | F26: 1 | G26: =G23 -> 46091 | I26: =I24 -> 46091 | J26: 1 | K26: =K23 -> 46091 | M26: 0 | N26: =_xlfn.LET( _xlpm.s,VALUE($I26), _xlpm.e,VALUE($K26), IF(OR(_xlpm.s="",_xlpm.e=""),"", IF(_xlpm.e<=_xlpm.s, IF(TODAY()>=_xlpm.e,1,0), MAX(0,MIN(1,(TODAY()-_xlpm.s)/(_xlpm.e-_xlpm.s))))) ) -> 0
B27: 3.5 | C27: AC Works - BESS | E27: =WORKDAY.INTL(G25,0,1,Data!$C$3:$C$60) -> 46113 | F27: 10 | G27: =WORKDAY.INTL(E27,F27,1,Data!$C$3:$C$60) -> 46129 | I27: =WORKDAY.INTL(K25,0,1,Data!$C$3:$C$60) -> 46113 | J27: 10 | K27: =WORKDAY.INTL(I27,J27,1,Data!$C$3:$C$60) -> 46129 | M27: 0 | N27: =_xlfn.LET( _xlpm.s,VALUE($I27), _xlpm.e,VALUE($K27), IF(OR(_xlpm.s="",_xlpm.e=""),"", IF(_xlpm.e<=_xlpm.s, IF(TODAY()>=_xlpm.e,1,0), MAX(0,MIN(1,(TODAY()-_xlpm.s)/(_xlpm.e-_xlpm.s))))) ) -> 0
B28: 3.6 | C28: AC Tie-In - BESS | E28: =WORKDAY.INTL(G27,0,1,Data!$C$3:$C$60) -> 46129 | F28: 2 | G28: =WORKDAY.INTL(E28,F28,1,Data!$C$3:$C$60) -> 46133 | I28: =WORKDAY.INTL(K27,0,1,Data!$C$3:$C$60) -> 46129 | J28: 2 | K28: =WORKDAY.INTL(I28,J28,1,Data!$C$3:$C$60) -> 46133 | M28: 0 | N28: =_xlfn.LET( _xlpm.s,VALUE($I28), _xlpm.e,VALUE($K28), IF(OR(_xlpm.s="",_xlpm.e=""),"", IF(_xlpm.e<=_xlpm.s, IF(TODAY()>=_xlpm.e,1,0), MAX(0,MIN(1,(TODAY()-_xlpm.s)/(_xlpm.e-_xlpm.s))))) ) -> 0
B29: 3.7 | C29: AC Works - Solar | E29: =G25 -> 46113 | F29: 12 | G29: =WORKDAY.INTL(E29,F29,1,Data!$C$3:$C$60) -> 46133 | I29: =K25 -> 46113 | J29: 12 | K29: =WORKDAY.INTL(I29,J29,1,Data!$C$3:$C$60) -> 46133 | M29: 0 | N29: =_xlfn.LET( _xlpm.s,VALUE($I29), _xlpm.e,VALUE($K29), IF(OR(_xlpm.s="",_xlpm.e=""),"", IF(_xlpm.e<=_xlpm.s, IF(TODAY()>=_xlpm.e,1,0), MAX(0,MIN(1,(TODAY()-_xlpm.s)/(_xlpm.e-_xlpm.s))))) ) -> 0
B30: 3.8 | C30: AC Tie-In - Solar | E30: =G29 -> 46133 | F30: 1 | G30: =WORKDAY.INTL(E30,F30,1,Data!$C$3:$C$60) -> 46134 | I30: =K29 -> 46133 | J30: 1 | K30: =WORKDAY.INTL(I30,J30,1,Data!$C$3:$C$60) -> 46134 | M30: 0 | N30: =_xlfn.LET( _xlpm.s,VALUE($I30), _xlpm.e,VALUE($K30), IF(OR(_xlpm.s="",_xlpm.e=""),"", IF(_xlpm.e<=_xlpm.s, IF(TODAY()>=_xlpm.e,1,0), MAX(0,MIN(1,(TODAY()-_xlpm.s)/(_xlpm.e-_xlpm.s))))) ) -> 0
B32: 4 | C32: DC Works | E32: =MIN(E34:E38) -> 46090 | F32: =G32-E32 -> 23 | G32: =MAX(G34:G38) -> 46113 | I32: =MIN(I34:I38) -> 46090 | J32: =K32-I32 -> 23 | K32: =MAX(K34:K38) -> 46113 | M32: =(J34*M34+J35*M35+J37*M37)/SUM(J34:J37) -> 0 | N32: =(J34*M34+J35*M35+J37*M37)/SUM(J34:J37) -> 0
B34: 4.1 | C34: Mounting Structure delivered | E34: =E20 -> 46090 | F34: 1 | G34: =WORKDAY.INTL(E34,F34,1,Data!$C$3:$C$60) -> 46091 | I34: =I20 -> 46090 | J34: 1 | K34: =WORKDAY.INTL(I34,J34,1,Data!$C$3:$C$60) -> 46091 | M34: 0 | N34: =_xlfn.LET( _xlpm.s,VALUE($I34), _xlpm.e,VALUE($K34), IF(OR(_xlpm.s="",_xlpm.e=""),"", IF(_xlpm.e<=_xlpm.s, IF(TODAY()>=_xlpm.e,1,0), MAX(0,MIN(1,(TODAY()-_xlpm.s)/(_xlpm.e-_xlpm.s))))) ) -> 0
B35: 4.2 | C35: Mounting Structure installation | E35: =WORKDAY.INTL(G34,0,1,Data!$C$3:$C$60) -> 46091 | F35: 3 | G35: =WORKDAY.INTL(E35,F35,1,Data!$C$3:$C$60) -> 46094 | I35: =WORKDAY.INTL(K34,0,1,Data!$C$3:$C$60) -> 46091 | J35: 3 | K35: =WORKDAY.INTL(I35,J35,1,Data!$C$3:$C$60) -> 46094 | M35: 0 | N35: =_xlfn.LET( _xlpm.s,VALUE($I35), _xlpm.e,VALUE($K35), IF(OR(_xlpm.s="",_xlpm.e=""),"", IF(_xlpm.e<=_xlpm.s, IF(TODAY()>=_xlpm.e,1,0), MAX(0,MIN(1,(TODAY()-_xlpm.s)/(_xlpm.e-_xlpm.s))))) ) -> 0
B36: 4.3 | C36: DC Cable delivered | E36: =E34 -> 46090 | F36: 1 | G36: =WORKDAY.INTL(E36,F36,1,Data!$C$3:$C$60) -> 46091 | I36: =WORKDAY.INTL(I20,0,1,Data!$C$3:$C$60) -> 46090 | J36: 1 | K36: =WORKDAY.INTL(I36,J36,1,Data!$C$3:$C$60) -> 46091 | M36: 0 | N36: =_xlfn.LET( _xlpm.s,VALUE($I36), _xlpm.e,VALUE($K36), IF(OR(_xlpm.s="",_xlpm.e=""),"", IF(_xlpm.e<=_xlpm.s, IF(TODAY()>=_xlpm.e,1,0), MAX(0,MIN(1,(TODAY()-_xlpm.s)/(_xlpm.e-_xlpm.s))))) ) -> 0
B37: 4.4 | C37: DC Stringing | E37: =WORKDAY.INTL(G41,0,1,Data!$C$3:$C$60)-3 -> 46104 | F37: 7 | G37: =WORKDAY.INTL(E37,F37,1,Data!$C$3:$C$60) -> 46113 | I37: =WORKDAY.INTL(K41,0,1,Data!$C$3:$C$60)-3 -> 46104 | J37: 7 | K37: =WORKDAY.INTL(I37,J37,1,Data!$C$3:$C$60) -> 46113 | M37: 0 | N37: =_xlfn.LET( _xlpm.s,VALUE($I37), _xlpm.e,VALUE($K37), IF(OR(_xlpm.s="",_xlpm.e=""),"", IF(_xlpm.e<=_xlpm.s, IF(TODAY()>=_xlpm.e,1,0), MAX(0,MIN(1,(TODAY()-_xlpm.s)/(_xlpm.e-_xlpm.s))))) ) -> 0
B39: 5 | C39: Module installation | E39: =MIN(E40:E42) -> 46090 | F39: =G39-E39 -> 17 | G39: =MAX(G40:G42) -> 46107 | I39: =MIN(I40:I42) -> 46090 | J39: =K39-I39 -> 17 | K39: =MAX(K40:K42) -> 46107 | M39: =(J40*M40+J41*M41)/SUM(J40:J41) -> 0 | N39: =(J40*M40+J41*M41)/SUM(J40:J41) -> 0
B40: 5.1 | C40: Module delivery | E40: =WORKDAY.INTL(E20,0,1,Data!$C$3:$C$60) -> 46090 | F40: 1 | G40: =WORKDAY.INTL(E40,F40,1,Data!$C$3:$C$60) -> 46091 | I40: =WORKDAY.INTL(I20,0,1,Data!$C$3:$C$60) -> 46090 | J40: 1 | K40: =WORKDAY.INTL(I40,J40,1,Data!$C$3:$C$60) -> 46091 | M40: 0 | N40: =_xlfn.LET( _xlpm.s,VALUE($I40), _xlpm.e,VALUE($K40), IF(OR(_xlpm.s="",_xlpm.e=""),"", IF(_xlpm.e<=_xlpm.s, IF(TODAY()>=_xlpm.e,1,0), MAX(0,MIN(1,(TODAY()-_xlpm.s)/(_xlpm.e-_xlpm.s))))) ) -> 0
B41: 5.2 | C41: Module mounting | E41: =G35 -> 46094 | F41: 9 | G41: =WORKDAY.INTL(E41,F41,1,Data!$C$3:$C$60) -> 46107 | I41: =K35 -> 46094 | J41: 9 | K41: =WORKDAY.INTL(I41,J41,1,Data!$C$3:$C$60) -> 46107 | M41: 0 | N41: =_xlfn.LET( _xlpm.s,VALUE($I41), _xlpm.e,VALUE($K41), IF(OR(_xlpm.s="",_xlpm.e=""),"", IF(_xlpm.e<=_xlpm.s, IF(TODAY()>=_xlpm.e,1,0), MAX(0,MIN(1,(TODAY()-_xlpm.s)/(_xlpm.e-_xlpm.s))))) ) -> 0
B43: 6 | C43: Commissioning | E43: =MIN(E44:E47) -> 46134 | F43: =G43-E43 -> 19 | G43: =MAX(G44:G47) -> 46153 | I43: =MIN(I44:I47) -> 46134 | J43: =K43-I43 -> 19 | K43: =MAX(K44:K47) -> 46153 | M43: =(J44*M44+J45*M45+J46*M46)/SUM(J44:J46) -> 0 | N43: =(J44*M44+J45*M45+J46*M46)/SUM(J44:J46) -> 0
B44: 6.1 | C44: Solar Commissioning | E44: =WORKDAY.INTL(MAX(G22,G32,G39),0,1,Data!$C$3:$C$60) -> 46134 | F44: 1 | G44: =WORKDAY.INTL(E44,F44,1,Data!$C$3:$C$60) -> 46135 | I44: =WORKDAY.INTL(MAX(K22,K32,K39),0,1,Data!$C$3:$C$60) -> 46134 | J44: 1 | K44: =WORKDAY.INTL(I44,J44,1,Data!$C$3:$C$60) -> 46135 | M44: 0 | N44: =_xlfn.LET( _xlpm.s,VALUE($I44), _xlpm.e,VALUE($K44), IF(OR(_xlpm.s="",_xlpm.e=""),"", IF(_xlpm.e<=_xlpm.s, IF(TODAY()>=_xlpm.e,1,0), MAX(0,MIN(1,(TODAY()-_xlpm.s)/(_xlpm.e-_xlpm.s))))) ) -> 0
B45: 6.2 | C45: BESS Commissioning | E45: =WORKDAY.INTL(G44,0,1,Data!$C$3:$C$60)+7 -> 46142 | F45: 1 | G45: =WORKDAY.INTL(E45,F45,1,Data!$C$3:$C$60) -> 46146 | I45: =WORKDAY.INTL(K44,0,1,Data!$C$3:$C$60)+7 -> 46142 | J45: 1 | K45: =WORKDAY.INTL(I45,J45,1,Data!$C$3:$C$60) -> 46146 | M45: 0 | N45: =_xlfn.LET( _xlpm.s,VALUE($I45), _xlpm.e,VALUE($K45), IF(OR(_xlpm.s="",_xlpm.e=""),"", IF(_xlpm.e<=_xlpm.s, IF(TODAY()>=_xlpm.e,1,0), MAX(0,MIN(1,(TODAY()-_xlpm.s)/(_xlpm.e-_xlpm.s))))) ) -> 0
...

Sheet Revenue Tracking
B2: HIGH LEVEL PROJECT REVENUE TRACKING | T2: 2026 Budget Revenue | U2: 2026 Budget COS | V2: 2026 Actual Revenue | W2: 2026 Actual COS
D3: COSTED | F3: ACTUAL | L3: FINANCIAL REVIEW | N3: TIMELINE REVIEW | T3: =SUMIFS('Expenditure Breakdown'!$U:$U, 'Expenditure Breakdown'!$T:$T, ">"&DATE(2025,8,31), 'Expenditure Breakdown'!$T:$T, "<="&DATE(2026,8,31)) -> 4119606.9 | U3: =SUMIFS('Expenditure Breakdown'!$Q:$Q, 'Expenditure Breakdown'!$T:$T, ">"&DATE(2025,8,31), 'Expenditure Breakdown'!$T:$T, "<="&DATE(2026,8,31)) -> 3357326.4 | V3: =SUMIFS('Expenditure Breakdown'!$U:$U, 'Expenditure Breakdown'!$T:$T, ">"&DATE(2025,8,31), 'Expenditure Breakdown'!$T:$T, "<="&DATE(2026,8,31), 'Expenditure Breakdown'!$S:$S, "<>") -> 23982.413 | W3: =SUMIFS('Expenditure Breakdown'!$Q:$Q, 'Expenditure Breakdown'!$T:$T, ">"&DATE(2025,8,31), 'Expenditure Breakdown'!$T:$T, "<="&DATE(2026,8,31), 'Expenditure Breakdown'!$S:$S, "<>") -> 21500
B4: 1 | C4: Planned Revenue | D4: ='Project Plan'!E6 -> 4119606.9 | F4: =F26 -> 4119606.9 | N4: Start Date
B5: 2 | C5: Planned Expenditure | D5: =+'Expenditure Tracking'!F5 -> 3462114.9 | F5: =+'Expenditure Tracking'!H5 -> 3357326.4 | G5: VO PM LIMIT | H5: CURRENT VO Total
B6: 3 | C6: Planned Profit | D6: =+D4-D5 -> 657491.96 | F6: =+F4-F5 -> 762280.45 | G6: =D6*0.05 -> 32874.598 | H6: =SUMIF('Expenditure Breakdown'!N:N,"*VO*",'Expenditure Breakdown'!Q:Q) -> 0 | N6: End Date - PC
B7: 4 | C7: Planned Margin | D7: =+D6/D4 -> 0.15960066 | F7: =+F6/F4 -> 0.18503718
L9: =F4*E13 -> 2059803.4
B10: CONTRACT
B12: No. | C12: PAYMENT MILESTONE | E12: % | F12: VALUE | H12: PLANNED PAYMENT DATE | L12: INVOICE NUMBER | N12: INVOICE RAISED DATE | P12: PAYMENT RECEIVED DATE | R12: MILESTONE NOTES & COMMENTS
B13: 1 | C13: Acceptance and Initial Deposit | E13: 0.5 | F13: =$D$4*E13 -> 2059803.4 | H13: 46081 | L13: 004913 | N13: 46066 | P13: 46072 | R13: We have a SSEG requirment from Standard Bank. Causing delays | AO13: ='Change Register'!$Q$14+ 7 -> 7
B14: 2 | C14: Delivery of Panels | E14: 0.2 | F14: =$D$4*E14 -> 823921.37 | H14: ='Project Plan'!E40+7 -> 46097 | P14: ='Project Plan'!I40+7 -> 46097
B15: 3 | C15: Delivery of Inverters | E15: 0.1 | F15: =$D$4*E15 -> 411960.69 | H15: ='Project Plan'!E23+7 -> 46097 | P15: ='Project Plan'!I24+7 -> 46098
B16: 4 | C16: Delivery of BESS | E16: 0.05 | F16: =$D$4*E16 -> 205980.34 | H16: ='Project Plan'!E26+7 -> 46098 | P16: ='Project Plan'!I26+7 -> 46098
B17: 5 | C17: Practical Completion Solar | E17: 0.05 | F17: =$D$4*E17 -> 205980.34 | H17: ='Project Plan'!E44+7 -> 46141 | P17: ='Project Plan'!I44+7 -> 46141
B18: 6 | C18: Practical Completion BESS | E18: 0.025 | F18: =$D$4*E18 -> 102990.17 | H18: ='Project Plan'!E45+7 -> 46149 | P18: ='Project Plan'!I45+7 -> 46149
B19: 7 | C19: Handover Solar | E19: 0.05 | F19: =$D$4*E19 -> 205980.34 | H19: ='Project Plan'!G54+7 -> 46163 | P19: ='Project Plan'!K52+7 -> 46169
B20: 8 | C20: Handover BESS | E20: 0.025 | F20: =$D$4*E20 -> 102990.17 | H20: =H19 -> 46163 | P20: =P19 -> 46169
B21: 9 | C21: - | E21: 0 | F21: =$D$4*E21 -> 0
B22: 10 | C22: - | E22: 0 | F22: =$D$4*E22 -> 0
B23: 11 | C23: - | E23: 0 | F23: =$D$4*E23 -> 0
B24: 12 | C24: - | E24: 0 | F24: =$D$4*E24 -> 0
E26: =SUM(E13:E24) -> 1 | F26: =SUM(F13:F24) -> 4119606.9
B28: KEY: | C28: contains an error (in result or a check has failed)
C29: Red Font - IF TEXT : content not yet confirmed
C30: Red Font - IF NUMBER: Negative value
C31: Anything in yellow is a concern or risk for noting or action
C32: confirmed
C33: [ADD INITIALS: comment for noting in square brackets, use colour or red to draw attention if important]
C34: [RT: When adding rows into sheet, ensure you insert between first and last row of each category]
C35: end of sheet - do not insert information below/beyond this
B45: No. | C45: PAYMENT MILESTONE | E45: % | F45: VALUE
B46: 1 | C46: Deposit - Project commencement | E46: 0.35 | F46: =$F$52*E46 -> 1441862.4
B47: 2 | C47: Delivery of Panels | E47: 0.3 | F47: =$F$52*E47 -> 1235882.1
B48: 3 | C48: Delivery of Inverters | E48: 0.2 | F48: =$F$52*E48 -> 823921.37
B49: 4 | C49: Practical Completion | E49: 0.1 | F49: =$F$52*E49 -> 411960.69
B50: 5 | C50: Handover | E50: 0.05 | F50: =$F$52*E50 -> 205980.34
C51: Total | E51: =SUM(E46:E50) -> 1 | F51: =SUM(F46:F50) -> 4119606.9
E52: =SUM(E46:E50) -> 1 | F52: =F26 -> 4119606.9

Sheet Expenditure Tracking
B2: HIGH LEVEL PROJECT EXPENDITURE TRACKING
F4: COSTED | H4: ACTUAL | J4: Difference from Costed
B5: EXPENDITURE | F5: =SUM(F9:F23) -> 3462114.9 | H5: =SUM(H9:H23) -> 3357326.4 | J5: =SUM(J9:J23) -> 104788.5
B7: No. | D7: Item | F7: Costed Expenditure | H7: Actual Expenditure | J7: Saving / Overrun | L7: Comments on variations from planned expenditure
B9: ='Expenditure Breakdown'!L6 -> 1 | D9: ='Expenditure Breakdown'!M6 -> 1. Panels | F9: ='Expenditure Breakdown'!I6 -> 934547.92 | H9: ='Expenditure Breakdown'!X6 -> 840000 | J9: =F9-H9 -> 94547.92
B10: ='Expenditure Breakdown'!L13 -> 2 | D10: ='Expenditure Breakdown'!M13 -> 2. Inverters | F10: ='Expenditure Breakdown'!I13 -> 204150 | H10: ='Expenditure Breakdown'!X13 -> 323590 | J10: =F10-H10 -> -119440
B11: ='Expenditure Breakdown'!L21 -> 3 | D11: ='Expenditure Breakdown'!M21 -> 3. Mounting Structures | F11: ='Expenditure Breakdown'!I21 -> 188856 | H11: ='Expenditure Breakdown'!X21 -> 111074 | J11: =F11-H11 -> 77782
B12: ='Expenditure Breakdown'!L28 -> 4 | D12: ='Expenditure Breakdown'!M28 -> 4. DC Equipment | F12: ='Expenditure Breakdown'!I28 -> 223700.8 | H12: ='Expenditure Breakdown'!X28 -> 318852.75 | J12: =F12-H12 -> -95151.95
B13: ='Expenditure Breakdown'!L45 -> 5 | D13: ='Expenditure Breakdown'!M45 -> 5. Monitoring | F13: ='Expenditure Breakdown'!I45 -> 174000 | H13: ='Expenditure Breakdown'!X45 -> 168000 | J13: =F13-H13 -> 6000
B14: ='Expenditure Breakdown'!L53 -> 6 | D14: ='Expenditure Breakdown'!M53 -> 6. AC Equipment | F14: ='Expenditure Breakdown'!I53 -> 413396.73 | H14: ='Expenditure Breakdown'!X53 -> 331844.57 | J14: =F14-H14 -> 81552.156
B15: ='Expenditure Breakdown'!L71 -> 7 | D15: ='Expenditure Breakdown'!M71 -> 7.BESS | F15: ='Expenditure Breakdown'!I71 -> 531293.91 | H15: ='Expenditure Breakdown'!X71 -> 303900 | J15: =F15-H15 -> 227393.91
B16: ='Expenditure Breakdown'!L80 -> 8 | D16: ='Expenditure Breakdown'!M80 -> 8. Product Add On | F16: ='Expenditure Breakdown'!I80 -> 245040.6 | H16: ='Expenditure Breakdown'!X80 -> 204500 | J16: =F16-H16 -> 40540.6
B17: ='Expenditure Breakdown'!L96 -> 9 | D17: ='Expenditure Breakdown'!M96 -> 9. AC & DC installation | F17: ='Expenditure Breakdown'!I96 -> 333680 | H17: ='Expenditure Breakdown'!X96 -> 534200 | J17: =F17-H17 -> -200520
B18: ='Expenditure Breakdown'!L109 -> 10 | D18: ='Expenditure Breakdown'!M109 -> 10. Site Logistics | F18: ='Expenditure Breakdown'!I109 -> 49217.111 | H18: ='Expenditure Breakdown'!X109 -> 45750 | J18: =F18-H18 -> 3467.1111
B19: ='Expenditure Breakdown'!L125 -> 11 | D19: ='Expenditure Breakdown'!M125 -> 11. Due Dilligence | F19: ='Expenditure Breakdown'!I125 -> 118984 | H19: ='Expenditure Breakdown'!X125 -> 118520 | J19: =F19-H19 -> 464
B20: ='Expenditure Breakdown'!L131 -> 12 | D20: ='Expenditure Breakdown'!M131 -> 12. BDP Commission | F20: ='Expenditure Breakdown'!I131 -> 0 | H20: ='Expenditure Breakdown'!X131 -> 0 | J20: =F20-H20 -> 0
B21: ='Expenditure Breakdown'!L134 -> 13 | D21: ='Expenditure Breakdown'!M135 -> 13. Engineering | F21: ='Expenditure Breakdown'!I134 -> 39647.831 | H21: ='Expenditure Breakdown'!X134 -> 51495.086 | J21: =F21-H21 -> -11847.255
B22: ='Expenditure Breakdown'!L141 -> 14 | D22: ='Expenditure Breakdown'!M141 -> 14. General Expenses | F22: ='Expenditure Breakdown'!I141 -> 5600 | H22: ='Expenditure Breakdown'!X141 -> 5600 | J22: =F22-H22 -> 0
B23: ='Expenditure Breakdown'!L154 -> 15 | D23: ='Expenditure Breakdown'!M154 -> 15. Service Add On | F23: ='Expenditure Breakdown'!I154 -> 0 | H23: ='Expenditure Breakdown'!X154 -> 0 | J23: =F23-H23 -> 0
D25: check: | F25: ='Expenditure Breakdown'!I2-'Expenditure Tracking'!F5 -> 0 | G25: =#REF!-G5 -> #REF! | H25: ='Expenditure Breakdown'!X2-H5 -> 0

Sheet Expenditure Breakdown
B2: COSTED EXPENDITURE BREAKDOWN | I2: =SUM(I6:I166) -> 3462114.9 | J2: =SUM(J6:J166) -> 4119606.9 | L2: ACTUAL EXPENDITURE BREAKDOWN | R2: FINANCE ONLY | X2: =SUM(X6:X166) -> 3357326.4
B4: No. | C4: Product / Service | D4: Description of Work | E4: QTY | F4: Rate / Unit | G4: Budget Total | H4: FORECASTED PAYMENT DATE | I4: Total COS | J4: =IF(J2-'Revenue Tracking'!D4>=0, "Total Revenue", "ERROR on REV" ) -> Total Revenue | L4: No. | M4: Product/ Service | N4: Description of Work | O4: QTY | P4: Rate / Unit | Q4: Actual Total | R4: PO NUMBER | S4: INVOICE NUMBER | T4: INVOICE RAISED DATE | U4: REVENUE RECOGNITION AMOUNT | V4: CHECK | W4: FINANCE PAYMENT DATE | X4: Total COS
B6: 1 | C6: Panels | D6: Panels Budget | G6: =D167 -> 934547.92 | H6: ='Project Plan'!E40+60 -> 46150 | I6: =SUM(G6:G11) -> 934547.92 | J6: =F167 -> 1139692.6 | L6: 1 | M6: 1. Panels | N6: Jinko 610W (MSA) | O6: ='Project Plan'!E3*1000/610 -> 688.52459 | P6: =2*610 -> 1220 | Q6: =O6*P6 -> 840000 | T6: 46112 | U6: =(Q6/$X$6*$J$6) -> 1139692.6 | V6: =J6-SUM(U6:U11) -> 0 | W6: ='Project Plan'!I40+60 -> 46150 | X6: =SUM(Q6:Q11) -> 840000
B7: 1 | D7: Delivery Budget | L7: 1 | M7: 1. Panels | Q7: =O7*P7 -> 0 | U7: =(Q7/$X$6*$J$6) -> 0
B8: 1 | L8: 1 | M8: 1. Panels | O8: =595*706 -> 420070 | T8: =IF(W8>1,EOMONTH(W8,0),"") | U8: =(Q8/$X$6*$J$6) -> 0
B9: 1 | L9: 1 | M9: 1. Panels | T9: =IF(W9>1,EOMONTH(W9,0),"") | U9: =(Q9/$X$6*$J$6) -> 0
B10: 1 | L10: 1 | M10: 1. Panels | T10: =IF(W10>1,EOMONTH(W10,0),"") | U10: =(Q10/$X$6*$J$6) -> 0
B11: 1 | L11: 1 | M11: 1. Panels | T11: =IF(W11>1,EOMONTH(W11,0),"") | U11: =(Q11/$X$6*$J$6) -> 0 | Y11: BUDGET | Z11: Installer Allocation
T12: =IF(W12>1,EOMONTH(W12,0),"") | Y12: AC Equipment | Z12: =G53 -> 413396.73
B13: 2 | C13: Inverters | D13: Inverter Budget - Sungrow 125kW | G13: =D168 -> 204150 | H13: ='Project Plan'!E23+60 -> 46150 | I13: =SUM(G13:G19) -> 204150 | J13: =F168 -> 248963.41 | L13: 2 | M13: 2. Inverters | U13: =(Q13/$X$13*$J$13) -> 0 | V13: =J13-SUM(U13:U19) -> 0 | X13: =SUM(Q13:Q19) -> 323590 | Y13: DC Equipment | Z13: =G29 -> 126260.8
B14: 2 | L14: 2 | M14: 2. Inverters | N14: Sungrow 125kW | O14: 3 | P14: 64990 | Q14: =O14*P14 -> 194970 | T14: =T6 -> 46112 | U14: =(Q14/$X$13*$J$13) -> 150005.86 | W14: =T14+30 -> 46142 | Y14: AC Labour | Z14: =G96 -> 104920 | AA14: =Z14/'Project Plan'!$E$3/1000 -> 0.24980952
B15: 2 | L15: 2 | M15: 2. Inverters | N15: Sungrow Wifi Comunication Module For Battery Inverter | Q15: 3900 | T15: =T14 -> 46112 | U15: =(Q15/$X$13*$J$13) -> 3000.5789 | W15: =W14 -> 46142 | Y15: DC Labour | Z15: =G97 -> 228760 | AA15: =Z15/'Project Plan'!$E$3/1000 -> 0.54466667
B16: 2 | L16: 2 | M16: 2. Inverters | N16: Sungrow 25kW 3P Hybrid inverter | O16: 2 | P16: 41540 | Q16: =O16*P16 -> 83080 | T16: 46112 | U16: =(Q16/$X$13*$J$13) -> 63920.024 | W16: =T16+30 -> 46142 | Y16: Offloading | Z16: =G109 -> 8500
B17: 2 | L17: 2 | M17: 2. Inverters | N17: Sungrow warranty extension to 10 years on the 125kW | O17: 3 | P17: 9880 | Q17: =O17*P17 -> 29640 | T17: =IF(W17>1,EOMONTH(W17,0),"") -> 46142 | U17: =(Q17/$X$13*$J$13) -> 22804.399 | W17: =W15 -> 46142 | Y17: Scaffolding | Z17: =G110 -> 15072.667
B18: 2 | L18: 2 | M18: 2. Inverters | N18: Sungrow warranty extension to 10 years on the 25 kW Hybrid inverter | O18: 2 | P18: 6000 | Q18: =O18*P18 -> 12000 | T18: 46142 | U18: =(Q18/$X$13*$J$13) -> 9232.5504 | W18: =T18+30 -> 46172 | Y18: Storage | Z18: =G112 -> 1644.4444
B19: 2 | L19: 2 | M19: 2. Inverters | T19: =IF(W19>1,EOMONTH(W19,0),"") | U19: =(Q19/$X$13*$J$13) -> 0 | Y19: BESS Installation | Z19: =G73+G74+G75+G76+G77 -> 143073.91
T20: =IF(W20>1,EOMONTH(W20,0),"") | Y20: Trenching | Z20: 0
B21: 3 | C21: Mounting Structures | D21: Structure Budget | G21: =D169 -> 188856 | H21: ='Project Plan'!E34+30 -> 46120 | I21: =SUM(G21:G26) -> 188856 | J21: =F169 -> 230312.2 | L21: 3 | M21: 3. Mounting Structures | N21: Schletter Structure - Possible Coega Stock | Q21: 111074 | T21: =T6 -> 46112 | U21: =(Q21/$X$21*$J$21) -> 230312.2 | V21: =J21-SUM(U21:U26) -> 0 | W21: =T21+30 -> 46142 | X21: =SUM(Q21:Q26) -> 111074 | Y21: Other | Z21: 0
B22: 3 | L22: 3 | M22: 3. Mounting Structures | T22: =IF(W22>1,EOMONTH(W22,0),"") | U22: =(Q22/$X$21*$J$21) -> 0 | Y22: Total | Z22: =SUM(Z12:Z21) -> 1041628.6
B23: 3 | L23: 3 | M23: 3. Mounting Structures | T23: =IF(W23>1,EOMONTH(W23,0),"") | U23: =(Q23/$X$21*$J$21) -> 0 | Y23: Less 15% | Z23: =+Z22*0.85 -> 885384.27
B24: 3 | L24: 3 | M24: 3. Mounting Structures | T24: =IF(W24>1,EOMONTH(W24,0),"") | U24: =(Q24/$X$21*$J$21) -> 0 | Y24: R/Wp | Z24: =Z23/'Project Plan'!$E$3/1000 -> 2.1080578
B25: 3 | L25: 3 | M25: 3. Mounting Structures | T25: =IF(W25>1,EOMONTH(W25,0),"") | U25: =(Q25/$X$21*$J$21) -> 0 | AB25: Not willing to quote | AE25: Only willing to do the AC
B26: 3 | L26: 3 | M26: 3. Mounting Structures | T26: =IF(W26>1,EOMONTH(W26,0),"") | U26: =(Q26/$X$21*$J$21) -> 0 | Y26: ACTUAL - Cosmic Sun | Z26: Installer Price | AB26: ACTUAL - GreenWay | AC26: Installer Price | AE26: ACTUAL - Matthews Group | AF26: Installer Price
T27: =IF(W27>1,EOMONTH(W27,0),"") | Y27: =Y12 -> AC Equipment | Z27: 157903.8 | AB27: AC Equipment | AE27: AC Equipment
B28: 4 | C28: DC Equipment | D28: DC Cable Budget | E28: 6960 | G28: 97440 | H28: ='Project Plan'!E36+60 -> 46150 | I28: =SUM(G28:G43) -> 223700.8 | J28: =F170 -> 272805.85 | L28: 4 | M28: 4. DC Equipment | Q28: =O28*P28 -> 0 | U28: =(Q28/$X$28*$J$28) -> 0 | V28: =J28-SUM(U28:U43) -> 0 | X28: =SUM(Q28:Q43) -> 318852.75 | Y28: =Y13 -> DC Equipment | Z28: 187552.75 | AB28: DC Equipment | AE28: DC Equipment
B29: 4 | D29: DC Equipment Budget | G29: =D170-G28 -> 126260.8 | H29: ='Project Plan'!G32 -> 46113 | L29: 4 | M29: 4. DC Equipment | N29: DC Cable - red from Coega Steel - Ziegler | O29: 4000 | P29: 13 | Q29: =O29*P29 -> 52000 | T29: 46112 | U29: =(Q29/$X$28*$J$28) -> 44490.456 | W29: 46112 | Y29: =Y14 -> AC Labour | Z29: 181800 | AA29: =Z29/'Project Plan'!$E$3/1000 -> 0.43285714 | AB29: AC Labour | AE29: AC Labour
B30: 4 | L30: 4 | M30: 4. DC Equipment | N30: DC Cable - black from Coega Steel - Ziegler | O30: 4000 | P30: 13 | Q30: =O30*P30 -> 52000 | T30: 46112 | U30: =(Q30/$X$28*$J$28) -> 44490.456 | W30: 46112 | Y30: =Y15 -> DC Labour | Z30: 352400 | AA30: =Z30/'Project Plan'!$E$3/1000 -> 0.83904762 | AB30: DC Labour | AE30: DC Labour
L31: 4 | M31: 4. DC Equipment | N31: DC Cable - red from JHB stock (Mahikeng) | O31: 1000 | P31: 13.65 | Q31: =O31*P31 -> 13650 | T31: 46112 | U31: =(Q31/$X$28*$J$28) -> 11678.745 | W31: 46112
B32: 4 | L32: 4 | M32: 4. DC Equipment | N32: DC Cable - black from JHB stock (Mahikeng) | O32: 1000 | P32: 13.65 | Q32: =O32*P32 -> 13650 | T32: 46112 | U32: =(Q32/$X$28*$J$28) -> 11678.745 | W32: 46112 | Y32: HSE | Z32: 4500 | AB32: HSE | AE32: HSE
B33: 4 | L33: 4 | M33: 4. DC Equipment | N33: Project Kick Off | O33: =Z28 -> 187552.75 | P33: 0.1 | Q33: =$O$33*P33 -> 18755.275 | T33: =T97 -> 46112 | U33: =(Q33/$X$28*$J$28) -> 16046.745 | W33: =W97 -> 46097 | Y33: Site Logistics | Z33: 41250 | AB33: Site Logistics | AE33: Site Logistics
B34: 4 | L34: 4 | M34: 4. DC Equipment | N34: Site Establishment | P34: 0.15 | Q34: =$O$33*P34 -> 28132.912 | T34: =T98 -> 46112 | U34: =(Q34/$X$28*$J$28) -> 24070.118 | W34: =W98 -> 46097 | Y34: Geda | Z34: 0 | AB34: Geda | AE34: Geda
B35: 4 | L35: 4 | M35: 4. DC Equipment | N35: AC Installation Complete | P35: 0.2 | Q35: =$O$33*P35 -> 37510.55 | T35: =T99 -> 46142 | U35: =(Q35/$X$28*$J$28) -> 32093.49 | W35: =W99 -> 46141 | Y35: BESS Installation | Z35: 0 | AB35: BESS Installation | AE35: BESS Installation
B36: 4 | L36: 4 | M36: 4. DC Equipment | N36: DC Installation Complete | P36: 0.25 | Q36: =$O$33*P36 -> 46888.188 | T36: =T100 -> 46142 | U36: =(Q36/$X$28*$J$28) -> 40116.863 | W36: =W100 -> 46120 | Y36: Trenching | Z36: 0 | AB36: Trenching | AE36: Trenching
B37: 4 | L37: 4 | M37: 4. DC Equipment | N37: Commissioning Complete | P37: 0.1 | Q37: =$O$33*P37 -> 18755.275 | T37: =T101 -> 46173 | U37: =(Q37/$X$28*$J$28) -> 16046.745 | W37: =W101 -> 46160 | Y37: Other | Z37: 0 | AB37: Other | AE37: Other
B38: 4 | L38: 4 | M38: 4. DC Equipment | N38: Site De-establisment | P38: 0.1 | Q38: =$O$33*P38 -> 18755.275 | T38: =T102 -> 46173 | U38: =(Q38/$X$28*$J$28) -> 16046.745 | W38: =W102 -> 46161 | Y38: Other | Z38: 0 | AB38: Other | AE38: Other
B39: 4 | L39: 4 | M39: 4. DC Equipment | N39: Handover Document Complete | P39: 0.05 | Q39: =$O$33*P39 -> 9377.6375 | T39: =T103 -> 46173 | U39: =(Q39/$X$28*$J$28) -> 8023.3726 | W39: =W103 -> 46161 | Y39: Total | Z39: =SUM(Z27:Z38) -> 925406.55 | AB39: Total | AC39: =SUM(AC27:AC38) -> 0 | AE39: Total | AF39: =SUM(AF27:AF38) -> 0
B40: 4 | L40: 4 | M40: 4. DC Equipment | N40: End of Defects Period | P40: 0.05 | Q40: =$O$33*P40 -> 9377.6375 | T40: =T104 -> 46203 | U40: =(Q40/$X$28*$J$28) -> 8023.3726 | W40: =W104 -> 46184 | Y40: R/Wp | Z40: =Z39/'Project Plan'!$E$3/1000 -> 2.2033489 | AB40: R/Wp | AC40: =AC39/'Project Plan'!$E$3/1000 -> 0 | AE40: R/Wp | AF40: =AF39/'Project Plan'!$E$3/1000 -> 0
B41: 4 | L41: 4 | M41: 4. DC Equipment | T41: =IF(W41>1,EOMONTH(W41,0),"") | U41: =(Q41/$X$28*$J$28) -> 0
B42: 4 | L42: 4 | M42: 4. DC Equipment | T42: =IF(W42>1,EOMONTH(W42,0),"") | U42: =(Q42/$X$28*$J$28) -> 0 | Y42: After Negotiations
B43: 4 | L43: 4 | M43: 4. DC Equipment | T43: =IF(W43>1,EOMONTH(W43,0),"") | U43: =(Q43/$X$28*$J$28) -> 0
...

Sheet Cashflow
D1: [RT: Double Check the first date is always a MONDAY] | F1: 46034 | G1: =F1+7 -> 46041 | H1: =G1+7 -> 46048 | I1: =H1+7 -> 46055 | J1: =I1+7 -> 46062 | K1: =J1+7 -> 46069 | L1: =K1+7 -> 46076 | M1: =L1+7 -> 46083 | N1: =M1+7 -> 46090 | ... KF1: =KE1+7 -> 48036
A2: PLANNED | C2: CHECK | D2: CHECK
B3: Planned Revenue | C3: ='Revenue Tracking'!D4 -> 4119606.9 | D3: =SUM(F3:KF3) -> 4119606.9 | F3: =SUMIFS('Revenue Tracking'!$F$13:$F$24, 'Revenue Tracking'!$H$13:$H$24, ">="&F1,'Revenue Tracking'!$H$13:$H$24, "<"&G1) -> 0 | G3: =SUMIFS('Revenue Tracking'!$F$13:$F$24, 'Revenue Tracking'!$H$13:$H$24, ">="&G1,'Revenue Tracking'!$H$13:$H$24, "<"&H1) -> 0 | H3: =SUMIFS('Revenue Tracking'!$F$13:$F$24, 'Revenue Tracking'!$H$13:$H$24, ">="&H1,'Revenue Tracking'!$H$13:$H$24, "<"&I1) -> 0 | I3: =SUMIFS('Revenue Tracking'!$F$13:$F$24, 'Revenue Tracking'!$H$13:$H$24, ">="&I1,'Revenue Tracking'!$H$13:$H$24, "<"&J1) -> 0 | J3: =SUMIFS('Revenue Tracking'!$F$13:$F$24, 'Revenue Tracking'!$H$13:$H$24, ">="&J1,'Revenue Tracking'!$H$13:$H$24, "<"&K1) -> 0 | K3: =SUMIFS('Revenue Tracking'!$F$13:$F$24, 'Revenue Tracking'!$H$13:$H$24, ">="&K1,'Revenue Tracking'!$H$13:$H$24, "<"&L1) -> 0 | L3: =SUMIFS('Revenue Tracking'!$F$13:$F$24, 'Revenue Tracking'!$H$13:$H$24, ">="&L1,'Revenue Tracking'!$H$13:$H$24, "<"&M1) -> 2059803.4 | M3: =SUMIFS('Revenue Tracking'!$F$13:$F$24, 'Revenue Tracking'!$H$13:$H$24, ">="&M1,'Revenue Tracking'!$H$13:$H$24, "<"&N1) -> 0 | ... KE3: =SUMIFS('Revenue Tracking'!$F$13:$F$24, 'Revenue Tracking'!$H$13:$H$24, ">="&KE1,'Revenue Tracking'!$H$13:$H$24, "<"&KF1) -> 0 | KF3: =SUMIFS('Revenue Tracking'!$F$13:$F$24, 'Revenue Tracking'!$H$13:$H$24, ">="&KF1,'Revenue Tracking'!$H$13:$H$24, "<"&#REF!) -> 0
B4: Planned Revenue - Cumulative | F4: =F3 -> 0 | G4: =F4+G3 -> 0 | H4: =G4+H3 -> 0 | I4: =H4+I3 -> 0 | J4: =I4+J3 -> 0 | K4: =J4+K3 -> 0 | L4: =K4+L3 -> 2059803.4 | M4: =L4+M3 -> 2059803.4 | N4: =M4+N3 -> 2059803.4 | ... KF4: =KE4+KF3 -> 4119606.9
B5: Planned Expenditure | C5: ='Revenue Tracking'!D5 -> 3462114.9 | D5: =SUM(F5:KF5) -> 3462114.9 | F5: =SUMIFS('Expenditure Breakdown'!$G$6:$G$173, 'Expenditure Breakdown'!$H$6:$H$173, ">="&F1,'Expenditure Breakdown'!$H$6:$H$173, "<"&G1) -> 0 | G5: =SUMIFS('Expenditure Breakdown'!$G$6:$G$173, 'Expenditure Breakdown'!$H$6:$H$173, ">="&G1,'Expenditure Breakdown'!$H$6:$H$173, "<"&H1) -> 0 | H5: =SUMIFS('Expenditure Breakdown'!$G$6:$G$173, 'Expenditure Breakdown'!$H$6:$H$173, ">="&H1,'Expenditure Breakdown'!$H$6:$H$173, "<"&I1) -> 0 | I5: =SUMIFS('Expenditure Breakdown'!$G$6:$G$173, 'Expenditure Breakdown'!$H$6:$H$173, ">="&I1,'Expenditure Breakdown'!$H$6:$H$173, "<"&J1) -> 0 | J5: =SUMIFS('Expenditure Breakdown'!$G$6:$G$173, 'Expenditure Breakdown'!$H$6:$H$173, ">="&J1,'Expenditure Breakdown'!$H$6:$H$173, "<"&K1) -> 0 | K5: =SUMIFS('Expenditure Breakdown'!$G$6:$G$173, 'Expenditure Breakdown'!$H$6:$H$173, ">="&K1,'Expenditure Breakdown'!$H$6:$H$173, "<"&L1) -> 0 | L5: =SUMIFS('Expenditure Breakdown'!$G$6:$G$173, 'Expenditure Breakdown'!$H$6:$H$173, ">="&L1,'Expenditure Breakdown'!$H$6:$H$173, "<"&M1) -> 89500 | M5: =SUMIFS('Expenditure Breakdown'!$G$6:$G$173, 'Expenditure Breakdown'!$H$6:$H$173, ">="&M1,'Expenditure Breakdown'!$H$6:$H$173, "<"&N1) -> 0 | ... KE5: =SUMIFS('Expenditure Breakdown'!$G$6:$G$173, 'Expenditure Breakdown'!$H$6:$H$173, ">="&KE1,'Expenditure Breakdown'!$H$6:$H$173, "<"&KF1) -> 0 | KF5: =SUMIFS('Expenditure Breakdown'!$G$6:$G$173, 'Expenditure Breakdown'!$H$6:$H$173, ">="&KF1,'Expenditure Breakdown'!$H$6:$H$173, "<"&#REF!) -> 0
B6: Planned Expenditure - Cumulative | F6: =F5 -> 0 | G6: =F6+G5 -> 0 | H6: =G6+H5 -> 0 | I6: =H6+I5 -> 0 | J6: =I6+J5 -> 0 | K6: =J6+K5 -> 0 | L6: =K6+L5 -> 89500 | M6: =L6+M5 -> 89500 | N6: =M6+N5 -> 89500 | ... KF6: =KE6+KF5 -> 3462114.9
B7: PLANNED CashFlow | F7: =F4-F6 -> 0 | G7: =G4-G6 -> 0 | H7: =H4-H6 -> 0 | I7: =I4-I6 -> 0 | J7: =J4-J6 -> 0 | K7: =K4-K6 -> 0 | L7: =L4-L6 -> 1970303.4 | M7: =M4-M6 -> 1970303.4 | ... KF7: =KF4-KF6 -> 657491.96
A8: ACTUAL | C8: CHECK | D8: CHECK
B9: Actual + Planned Revenue | C9: ='Revenue Tracking'!F4 -> 4119606.9 | D9: =SUM(F9:KF9) -> 4119606.9 | F9: =SUMIFS('Revenue Tracking'!$F$13:$F$24, 'Revenue Tracking'!$P$13:$P$24, ">="&F1,'Revenue Tracking'!$P$13:$P$24, "<"&G1) -> 0 | G9: =SUMIFS('Revenue Tracking'!$F$13:$F$24, 'Revenue Tracking'!$P$13:$P$24, ">="&G1,'Revenue Tracking'!$P$13:$P$24, "<"&H1) -> 0 | H9: =SUMIFS('Revenue Tracking'!$F$13:$F$24, 'Revenue Tracking'!$P$13:$P$24, ">="&H1,'Revenue Tracking'!$P$13:$P$24, "<"&I1) -> 0 | I9: =SUMIFS('Revenue Tracking'!$F$13:$F$24, 'Revenue Tracking'!$P$13:$P$24, ">="&I1,'Revenue Tracking'!$P$13:$P$24, "<"&J1) -> 0 | J9: =SUMIFS('Revenue Tracking'!$F$13:$F$24, 'Revenue Tracking'!$P$13:$P$24, ">="&J1,'Revenue Tracking'!$P$13:$P$24, "<"&K1) -> 0 | K9: =SUMIFS('Revenue Tracking'!$F$13:$F$24, 'Revenue Tracking'!$P$13:$P$24, ">="&K1,'Revenue Tracking'!$P$13:$P$24, "<"&L1) -> 2059803.4 | L9: =SUMIFS('Revenue Tracking'!$F$13:$F$24, 'Revenue Tracking'!$P$13:$P$24, ">="&L1,'Revenue Tracking'!$P$13:$P$24, "<"&M1) -> 0 | M9: =SUMIFS('Revenue Tracking'!$F$13:$F$24, 'Revenue Tracking'!$P$13:$P$24, ">="&M1,'Revenue Tracking'!$P$13:$P$24, "<"&N1) -> 0 | ... KE9: =SUMIFS('Revenue Tracking'!$F$13:$F$24, 'Revenue Tracking'!$P$13:$P$24, ">="&KE1,'Revenue Tracking'!$P$13:$P$24, "<"&KF1) -> 0 | KF9: =SUMIFS('Revenue Tracking'!$F$13:$F$24, 'Revenue Tracking'!$P$13:$P$24, ">="&KF1,'Revenue Tracking'!$P$13:$P$24, "<"&#REF!) -> 0
B10: Actual + Planned Revenue - Cumulative | F10: =F9 -> 0 | G10: =F10+G9 -> 0 | H10: =G10+H9 -> 0 | I10: =H10+I9 -> 0 | J10: =I10+J9 -> 0 | K10: =J10+K9 -> 2059803.4 | L10: =K10+L9 -> 2059803.4 | M10: =L10+M9 -> 2059803.4 | N10: =M10+N9 -> 2059803.4 | ... KF10: =KE10+KF9 -> 4119606.9
B11: Actual + Planned Expenditure | C11: ='Revenue Tracking'!F5 -> 3357326.4 | D11: =SUM(F11:KF11) -> 3357326.4 | F11: =SUMIFS('Expenditure Breakdown'!$Q$6:$Q$173, 'Expenditure Breakdown'!$W$6:$W$173, ">="&F1,'Expenditure Breakdown'!$W$6:$W$173, "<"&G1) -> 0 | G11: =SUMIFS('Expenditure Breakdown'!$Q$6:$Q$173, 'Expenditure Breakdown'!$W$6:$W$173, ">="&G1,'Expenditure Breakdown'!$W$6:$W$173, "<"&H1) -> 0 | H11: =SUMIFS('Expenditure Breakdown'!$Q$6:$Q$173, 'Expenditure Breakdown'!$W$6:$W$173, ">="&H1,'Expenditure Breakdown'!$W$6:$W$173, "<"&I1) -> 0 | I11: =SUMIFS('Expenditure Breakdown'!$Q$6:$Q$173, 'Expenditure Breakdown'!$W$6:$W$173, ">="&I1,'Expenditure Breakdown'!$W$6:$W$173, "<"&J1) -> 0 | J11: =SUMIFS('Expenditure Breakdown'!$Q$6:$Q$173, 'Expenditure Breakdown'!$W$6:$W$173, ">="&J1,'Expenditure Breakdown'!$W$6:$W$173, "<"&K1) -> 0 | K11: =SUMIFS('Expenditure Breakdown'!$Q$6:$Q$173, 'Expenditure Breakdown'!$W$6:$W$173, ">="&K1,'Expenditure Breakdown'!$W$6:$W$173, "<"&L1) -> 0 | L11: =SUMIFS('Expenditure Breakdown'!$Q$6:$Q$173, 'Expenditure Breakdown'!$W$6:$W$173, ">="&L1,'Expenditure Breakdown'!$W$6:$W$173, "<"&M1) -> 0 | M11: =SUMIFS('Expenditure Breakdown'!$Q$6:$Q$173, 'Expenditure Breakdown'!$W$6:$W$173, ">="&M1,'Expenditure Breakdown'!$W$6:$W$173, "<"&N1) -> 1400 | ... KE11: =SUMIFS('Expenditure Breakdown'!$Q$6:$Q$173, 'Expenditure Breakdown'!$W$6:$W$173, ">="&KE1,'Expenditure Breakdown'!$W$6:$W$173, "<"&KF1) -> 0 | KF11: =SUMIFS('Expenditure Breakdown'!$Q$6:$Q$173, 'Expenditure Breakdown'!$W$6:$W$173, ">="&KF1,'Expenditure Breakdown'!$W$6:$W$173, "<"&#REF!) -> 0
B12: Actual + Planned Expenditure - Cumulative | F12: =F11 -> 0 | G12: =F12+G11 -> 0 | H12: =G12+H11 -> 0 | I12: =H12+I11 -> 0 | J12: =I12+J11 -> 0 | K12: =J12+K11 -> 0 | L12: =K12+L11 -> 0 | M12: =L12+M11 -> 1400 | N12: =M12+N11 -> 1400 | ... KF12: =KE12+KF11 -> 3357326.4
B14: ACTUAL CashFlow | F14: =F10-F12 -> 0 | G14: =G10-G12 -> 0 | H14: =H10-H12 -> 0 | I14: =I10-I12 -> 0 | J14: =J10-J12 -> 0 | K14: =K10-K12 -> 2059803.4 | L14: =L10-L12 -> 2059803.4 | M14: =M10-M12 -> 2058403.4 | ... KF14: =KF10-KF12 -> 762280.45
C16: CHECK | D16: CHECK
B17: Revenue Recognition | C17: =C3-D17 -> 0 | D17: =SUM(F17:KF17) -> 4119606.9 | F17: =SUMIFS('Expenditure Breakdown'!$U$6:$U$173, 'Expenditure Breakdown'!$T$6:$T$173, ">="&F1,'Expenditure Breakdown'!$T$6:$T$173, "<"&G1) -> 0 | G17: =SUMIFS('Expenditure Breakdown'!$U$6:$U$173, 'Expenditure Breakdown'!$T$6:$T$173, ">="&G1,'Expenditure Breakdown'!$T$6:$T$173, "<"&H1) -> 0 | H17: =SUMIFS('Expenditure Breakdown'!$U$6:$U$173, 'Expenditure Breakdown'!$T$6:$T$173, ">="&H1,'Expenditure Breakdown'!$T$6:$T$173, "<"&I1) -> 0 | I17: =SUMIFS('Expenditure Breakdown'!$U$6:$U$173, 'Expenditure Breakdown'!$T$6:$T$173, ">="&I1,'Expenditure Breakdown'!$T$6:$T$173, "<"&J1) -> 0 | J17: =SUMIFS('Expenditure Breakdown'!$U$6:$U$173, 'Expenditure Breakdown'!$T$6:$T$173, ">="&J1,'Expenditure Breakdown'!$T$6:$T$173, "<"&K1) -> 0 | K17: =SUMIFS('Expenditure Breakdown'!$U$6:$U$173, 'Expenditure Breakdown'!$T$6:$T$173, ">="&K1,'Expenditure Breakdown'!$T$6:$T$173, "<"&L1) -> 0 | L17: =SUMIFS('Expenditure Breakdown'!$U$6:$U$173, 'Expenditure Breakdown'!$T$6:$T$173, ">="&L1,'Expenditure Breakdown'!$T$6:$T$173, "<"&M1) -> 1555.5556 | M17: =SUMIFS('Expenditure Breakdown'!$U$6:$U$173, 'Expenditure Breakdown'!$T$6:$T$173, ">="&M1,'Expenditure Breakdown'!$T$6:$T$173, "<"&N1) -> 0 | ... KE17: =SUMIFS('Expenditure Breakdown'!$U$6:$U$173, 'Expenditure Breakdown'!$T$6:$T$173, ">="&KE1,'Expenditure Breakdown'!$T$6:$T$173, "<"&KF1) -> 0 | KF17: =SUMIFS('Expenditure Breakdown'!$U$6:$U$173, 'Expenditure Breakdown'!$T$6:$T$173, ">="&KF1,'Expenditure Breakdown'!$T$6:$T$173, "<"&#REF!) -> 0
B18: Revenue Recognition Cumulative | C18: =D17-D18 -> 0 | D18: =MAX(F18:KF18) -> 4119606.9 | F18: =F17 -> 0 | G18: =F18+G17 -> 0 | H18: =G18+H17 -> 0 | I18: =H18+I17 -> 0 | J18: =I18+J17 -> 0 | K18: =J18+K17 -> 0 | L18: =K18+L17 -> 1555.5556 | M18: =L18+M17 -> 1555.5556 | N18: =M18+N17 -> 1555.5556 | ... KF18: =KE18+KF17 -> 4119606.9

Sheet Finance - Revenue
A3: Sum of REVENUE RECOGNITION AMOUNT | B3: Column Labels
A4: Row Labels | B4: (blank) | D4: 46081 | E4: 46112 | F4: 46142 | G4: 46173 | H4: 46203 | I4: Grand Total
A5: (blank)
A6: 1. Panels | B6: 0 | C6: 0 | E6: 1139692.6 | I6: 1139692.6
A7: 2. Inverters | B7: 0 | C7: 0 | E7: 216926.46 | F7: 32036.95 | I7: 248963.41
A8: 3. Mounting Structures | C8: 0 | E8: 230312.2 | I8: 230312.2
A9: 4. DC Equipment | C9: 0 | E9: 172685.85 | F9: 60072.001 | G9: 33373.334 | H9: 6674.6668 | I9: 272805.85
A10: 5. Monitoring | B10: 0 | C10: 0 | E10: 212195.12 | I10: 212195.12
A11: 6. AC Equipment | C11: 0 | E11: 348631.11 | F11: 93306.742 | G11: 51837.079 | H11: 10367.416 | I11: 504142.35
A12: 8. Product Add On | B12: 0 | C12: 0 | E12: 298830 | I12: 298830
A13: 9. AC & DC installation | C13: 0 | E13: 92688.889 | F13: 166840 | G13: 92688.889 | H13: 18537.778 | I13: 370755.56
A14: 10. Site Logistics | C14: 0 | E14: 35336.482 | F14: 11609.518 | G14: 6449.7324 | H14: 1289.9465 | I14: 54685.679
A15: 11. Due Dilligence | B15: 0 | E15: 112774.09 | G15: 19430.357 | I15: 132204.44
A16: 13. Engineering | C16: 0 | E16: 45054.353 | I16: 45054.353
A17: 14. General Expenses | C17: 0 | D17: 1555.5556 | E17: 1555.5556 | F17: 1555.5556 | G17: 1555.5556 | I17: 6222.2222
A18: 15. Service Add On
A19: 12. BDP Commission
A20: 7.BESS | B20: 0 | C20: 0 | E20: 303821.03 | F20: 299922.05 | I20: 603743.08
A21: Grand Total | B21: 0 | C21: 0 | D21: 1555.5556 | E21: 3210503.7 | F21: 665342.81 | G21: 205334.95 | H21: 36869.807 | I21: 4119606.9

Sheet Finance - COS
A3: Sum of Actual Total | B3: Column Labels
A4: Row Labels | B4: (blank) | D4: 46081 | E4: 46112 | F4: 46142 | G4: 46173 | H4: 46203 | I4: Grand Total
A5: (blank)
A6: 1. Panels | B6: 0 | E6: 987000 | I6: 987000
A7: 2. Inverters | E7: 281950 | F7: 41640 | I7: 323590
A8: 3. Mounting Structures | E8: 111074 | I8: 111074
A9: 4. DC Equipment | E9: 138830.42 | F9: 48294.756 | G9: 26830.42 | H9: 5366.084 | I9: 219321.68
A10: 5. Monitoring | E10: 156000 | I10: 156000
A11: 6. AC Equipment | E11: 271148.31 | F11: 72569.442 | G11: 40316.357 | H11: 8063.2713 | I11: 392097.38
A12: 8. Product Add On | E12: 204500 | I12: 204500
A13: 9. AC & DC installation | E13: 85907 | F13: 154632.6 | G13: 85907 | H13: 17181.4 | I13: 343628
A14: 10. Site Logistics | E14: 29358.636 | F14: 9645.545 | G14: 5358.6361 | H14: 1071.7272 | I14: 45434.544
A15: 11. Due Dilligence | E15: 73000 | G15: 12577.5 | I15: 85577.5
A16: 13. Engineering | E16: 51495.086 | I16: 51495.086
A17: 14. General Expenses | D17: 1400 | E17: 1400 | F17: 1400 | G17: 1400 | I17: 5600
A18: 15. Service Add On
A19: 12. BDP Commission | C19: 0 | I19: 0
A20: 7.BESS | E20: 303900 | F20: 300000 | I20: 603900
A21: Grand Total | B21: 0 | C21: 0 | D21: 1400 | E21: 2695563.4 | F21: 628182.34 | G21: 172389.91 | H21: 31682.483 | I21: 3529218.2

Sheet Data
C2: Public holidays | F2: Drop down list
C3: 45658 | D3: New Years Day | F3: Approved
C4: 45737 | D4: Human Rights day | F4: Pending
C5: 45765 | D5: Good Friday | F5: Declined
C6: 45768 | D6: Family Day | F6: Abanded
C7: 45774 | D7: Freedom Day
C8: 45765 | D8: Freedom DayObserved
C9: 45778 | D9: Workers day
C10: 45824 | D10: Youth Day Holiday
C11: 45878 | D11: Womens Day
C12: 45924 | D12: Heritage Day
C13: 46007 | D13: Day of Reconciliation | H13: Manual dates
C14: 46016 | D14: Christmas Day
C15: 46017 | D15: Day of Goodwill
C16: 46006 | D16: Builders Break
C17: 46007 | D17: Builders Break
C18: 46008 | D18: Builders Break
C19: 46009 | D19: Builders Break
C20: 46010 | D20: Builders Break
C21: 46011 | D21: Builders Break
C22: 46012 | D22: Builders Break
C23: 46013 | D23: Builders Break
C24: 46014 | D24: Builders Break
C25: 46015 | D25: Builders Break
... C40: 46030 | D40: Builders Break
D41: Builders Break
D42: Builders Break
D43: Builders Break
D44: Builders Break
D45: Builders Break
D46: Builders Break
D47: Builders Break
D48: Builders Break
C49: 46102 | D49: Human Rights day
C50: 46115 | D50: Good Friday
C51: 46118 | D51: Family Day
C52: 46139 | D52: Freedom Day
C53: 46143 | D53: Workers day
C54: 46189 | D54: Youth Day Holiday
C55: 46243 | D55: Womens Day
...
