Workbook
Name Inverter_Supplier: #REF!
Name Project_Size: 'Finance - Revenue'!Projectsize
Name Project_Size: Projectsize
Name Projectsize: #REF!
Name Projectsize: 'Project Margins'!$K$5
Name Security_Serv: #REF!
Name Security_Serv: #REF!
Name SSS: #REF!
Name SSS: #REF!
Name USD_ZAR: #REF!

Sheet Sheet1
A1: PROJECT PLAN
A2: # | B2: Project Milestone | C2: Planned Start Date | D2: Duration (Work Days) | E2: Planned End Date | F2: Actual Start Date | H2: Actual End Date | J2: Comments | L2: =C3 -> 43831 | M2: =L2+3 -> 43834 | N2: =M2+7 -> 43841 | O2: =N2+7 -> 43848 | P2: =O2+7 -> 43855 | Q2: =P2+6 -> 43861 | R2: =Q2+1 -> 43862 | S2: =R2+7 -> 43869 | T2: =S2+7 -> 43876 | U2: =T2+7 -> 43883 | V2: =U2+6 -> 43889 | W2: =V2+7 -> 43896 | X2: =W2+7 -> 43903 | Y2: =X2+7 -> 43910 | Z2: =Y2+7 -> 43917 | AA2: =Z2+3 -> 43920 | AB2: =AA2+4 -> 43924 | AC2: =AB2+7 -> 43931 | AD2: =AC2+7 -> 43938 | AE2: =AD2+7 -> 43945 | AF2: =AE2+6 -> 43951 | AG2: =AF2+2 -> 43953 | AH2: =AG2+7 -> 43960 | AI2: =AH2+7 -> 43967 | AJ2: =AI2+7 -> 43974 | AK2: =AJ2+7 -> 43981 | AL2: =AK2+1 -> 43982 | AM2: =AL2+6 -> 43988 | AN2: =AM2+7 -> 43995 | AO2: =AN2+7 -> 44002 | AP2: =AO2+7 -> 44009 | AQ2: =AP2+3 -> 44012 | AR2: =AQ2+4 -> 44016 | AS2: =AR2+7 -> 44023 | AT2: =AS2+7 -> 44030 | AU2: =AT2+7 -> 44037 | AV2: =AU2+6 -> 44043 | AW2: =AV2+1 -> 44044 | AX2: =AW2+7 -> 44051 | AY2: =AX2+7 -> 44058 | AZ2: =AY2+7 -> 44065 | BA2: =AZ2+7 -> 44072 | BB2: =BA2+2 -> 44074 | BC2: =BB2+5 -> 44079 | BD2: =BC2+7 -> 44086 | BE2: =BD2+7 -> 44093 | BF2: =BE2+7 -> 44100 | BG2: =BF2+4 -> 44104
A3: 1 | B3: Contract Signature | C3: 43831 | D3: 1 | E3: 43832 | F3: 43831 | G3: 1 | H3: 43832 | L3: =IF(AND($F3<(L$2+7),$F3>L$2),1, IF(AND($H3<L$2+7,$H3>L$2),3, IF(AND($F3<=L$2, $H3>=L$2), 2, "" ))) -> 3 | M3: =IF(AND($F3<(M$2+7),$F3>M$2),1, IF(AND($H3<M$2+7,$H3>M$2),3, IF(AND($F3<=M$2, $H3>=M$2), 2, "" ))) | N3: =IF(AND($F3<(N$2+7),$F3>N$2),1, IF(AND($H3<N$2+7,$H3>N$2),3, IF(AND($F3<=N$2, $H3>=N$2), 2, "" ))) | O3: =IF(AND($F3<(O$2+7),$F3>O$2),1, IF(AND($H3<O$2+7,$H3>O$2),3, IF(AND($F3<=O$2, $H3>=O$2), 2, "" ))) | P3: =IF(AND($F3<(P$2+7),$F3>P$2),1, IF(AND($H3<P$2+7,$H3>P$2),3, IF(AND($F3<=P$2, $H3>=P$2), 2, "" ))) | Q3: =IF(AND($F3<(Q$2+7),$F3>Q$2),1, IF(AND($H3<Q$2+7,$H3>Q$2),3, IF(AND($F3<=Q$2, $H3>=Q$2), 2, "" ))) | R3: =IF(AND($F3<(R$2+7),$F3>R$2),1, IF(AND($H3<R$2+7,$H3>R$2),3, IF(AND($F3<=R$2, $H3>=R$2), 2, "" ))) | S3: =IF(AND($F3<(S$2+7),$F3>S$2),1, IF(AND($H3<S$2+7,$H3>S$2),3, IF(AND($F3<=S$2, $H3>=S$2), 2, "" ))) | ... AQ3: =IF(AND($F3<(AQ$2+7),$F3>AQ$2),1, IF(AND($H3<AQ$2+7,$H3>AQ$2),3, IF(AND($F3<=AQ$2, $H3>=AQ$2), 2, "" )))
A4: A | B4: PAYMENT MILESTONE 1: DEPOSIT | C4: 43832 | D4: 1 | E4: 43833 | F4: 43832 | G4: 1 | H4: 43833 | L4: =IF(AND($F4<(L$2+7),$F4>L$2),1, IF(AND($H4<L$2+7,$H4>L$2),3, IF(AND($F4<=L$2, $H4>=L$2), 2, "" ))) -> 1 | M4: =IF(AND($F4<(M$2+7),$F4>M$2),1, IF(AND($H4<M$2+7,$H4>M$2),3, IF(AND($F4<=M$2, $H4>=M$2), 2, "" ))) | N4: =IF(AND($F4<(N$2+7),$F4>N$2),1, IF(AND($H4<N$2+7,$H4>N$2),3, IF(AND($F4<=N$2, $H4>=N$2), 2, "" ))) | O4: =IF(AND($F4<(O$2+7),$F4>O$2),1, IF(AND($H4<O$2+7,$H4>O$2),3, IF(AND($F4<=O$2, $H4>=O$2), 2, "" ))) | P4: =IF(AND($F4<(P$2+7),$F4>P$2),1, IF(AND($H4<P$2+7,$H4>P$2),3, IF(AND($F4<=P$2, $H4>=P$2), 2, "" ))) | Q4: =IF(AND($F4<(Q$2+7),$F4>Q$2),1, IF(AND($H4<Q$2+7,$H4>Q$2),3, IF(AND($F4<=Q$2, $H4>=Q$2), 2, "" ))) | R4: =IF(AND($F4<(R$2+7),$F4>R$2),1, IF(AND($H4<R$2+7,$H4>R$2),3, IF(AND($F4<=R$2, $H4>=R$2), 2, "" ))) | S4: =IF(AND($F4<(S$2+7),$F4>S$2),1, IF(AND($H4<S$2+7,$H4>S$2),3, IF(AND($F4<=S$2, $H4>=S$2), 2, "" ))) | ... AQ4: =IF(AND($F4<(AQ$2+7),$F4>AQ$2),1, IF(AND($H4<AQ$2+7,$H4>AQ$2),3, IF(AND($F4<=AQ$2, $H4>=AQ$2), 2, "" )))
A5: 2 | B5: Structural and Electrical Due Diligences | C5: 43833 | D5: 5 | E5: 43840 | F5: 43833 | G5: 5 | H5: 43840 | L5: =IF(AND($F5<(L$2+7),$F5>L$2),1, IF(AND($H5<L$2+7,$H5>L$2),3, IF(AND($F5<=L$2, $H5>=L$2), 2, "" ))) -> 1 | M5: =IF(AND($F5<(M$2+7),$F5>M$2),1, IF(AND($H5<M$2+7,$H5>M$2),3, IF(AND($F5<=M$2, $H5>=M$2), 2, "" ))) -> 3 | N5: =IF(AND($F5<(N$2+7),$F5>N$2),1, IF(AND($H5<N$2+7,$H5>N$2),3, IF(AND($F5<=N$2, $H5>=N$2), 2, "" ))) | O5: =IF(AND($F5<(O$2+7),$F5>O$2),1, IF(AND($H5<O$2+7,$H5>O$2),3, IF(AND($F5<=O$2, $H5>=O$2), 2, "" ))) | P5: =IF(AND($F5<(P$2+7),$F5>P$2),1, IF(AND($H5<P$2+7,$H5>P$2),3, IF(AND($F5<=P$2, $H5>=P$2), 2, "" ))) | Q5: =IF(AND($F5<(Q$2+7),$F5>Q$2),1, IF(AND($H5<Q$2+7,$H5>Q$2),3, IF(AND($F5<=Q$2, $H5>=Q$2), 2, "" ))) | R5: =IF(AND($F5<(R$2+7),$F5>R$2),1, IF(AND($H5<R$2+7,$H5>R$2),3, IF(AND($F5<=R$2, $H5>=R$2), 2, "" ))) | S5: =IF(AND($F5<(S$2+7),$F5>S$2),1, IF(AND($H5<S$2+7,$H5>S$2),3, IF(AND($F5<=S$2, $H5>=S$2), 2, "" ))) | ... AQ5: =IF(AND($F5<(AQ$2+7),$F5>AQ$2),1, IF(AND($H5<AQ$2+7,$H5>AQ$2),3, IF(AND($F5<=AQ$2, $H5>=AQ$2), 2, "" )))
A6: 3 | B6: Design Confirmation | C6: 43841 | D6: 2 | E6: 43844 | F6: 43841 | G6: 2 | H6: 43844 | L6: =IF(AND($F6<(L$2+7),$F6>L$2),1, IF(AND($H6<L$2+7,$H6>L$2),3, IF(AND($F6<=L$2, $H6>=L$2), 2, "" ))) | M6: =IF(AND($F6<(M$2+7),$F6>M$2),1, IF(AND($H6<M$2+7,$H6>M$2),3, IF(AND($F6<=M$2, $H6>=M$2), 2, "" ))) | N6: =IF(AND($F6<(N$2+7),$F6>N$2),1, IF(AND($H6<N$2+7,$H6>N$2),3, IF(AND($F6<=N$2, $H6>=N$2), 2, "" ))) -> 3 | O6: =IF(AND($F6<(O$2+7),$F6>O$2),1, IF(AND($H6<O$2+7,$H6>O$2),3, IF(AND($F6<=O$2, $H6>=O$2), 2, "" ))) | P6: =IF(AND($F6<(P$2+7),$F6>P$2),1, IF(AND($H6<P$2+7,$H6>P$2),3, IF(AND($F6<=P$2, $H6>=P$2), 2, "" ))) | Q6: =IF(AND($F6<(Q$2+7),$F6>Q$2),1, IF(AND($H6<Q$2+7,$H6>Q$2),3, IF(AND($F6<=Q$2, $H6>=Q$2), 2, "" ))) | R6: =IF(AND($F6<(R$2+7),$F6>R$2),1, IF(AND($H6<R$2+7,$H6>R$2),3, IF(AND($F6<=R$2, $H6>=R$2), 2, "" ))) | S6: =IF(AND($F6<(S$2+7),$F6>S$2),1, IF(AND($H6<S$2+7,$H6>S$2),3, IF(AND($F6<=S$2, $H6>=S$2), 2, "" ))) | ... AQ6: =IF(AND($F6<(AQ$2+7),$F6>AQ$2),1, IF(AND($H6<AQ$2+7,$H6>AQ$2),3, IF(AND($F6<=AQ$2, $H6>=AQ$2), 2, "" )))
A7: 4 | B7: Equipment Procurement | C7: 43833 | E7: 43949 | F7: 43833 | H7: 43949 | L7: =IF(AND($F7<(L$2+7),$F7>L$2),1, IF(AND($H7<L$2+7,$H7>L$2),3, IF(AND($F7<=L$2, $H7>=L$2), 2, "" ))) -> 1 | M7: =IF(AND($F7<(M$2+7),$F7>M$2),1, IF(AND($H7<M$2+7,$H7>M$2),3, IF(AND($F7<=M$2, $H7>=M$2), 2, "" ))) -> 2 | N7: =IF(AND($F7<(N$2+7),$F7>N$2),1, IF(AND($H7<N$2+7,$H7>N$2),3, IF(AND($F7<=N$2, $H7>=N$2), 2, "" ))) -> 2 | O7: =IF(AND($F7<(O$2+7),$F7>O$2),1, IF(AND($H7<O$2+7,$H7>O$2),3, IF(AND($F7<=O$2, $H7>=O$2), 2, "" ))) -> 2 | P7: =IF(AND($F7<(P$2+7),$F7>P$2),1, IF(AND($H7<P$2+7,$H7>P$2),3, IF(AND($F7<=P$2, $H7>=P$2), 2, "" ))) -> 2 | Q7: =IF(AND($F7<(Q$2+7),$F7>Q$2),1, IF(AND($H7<Q$2+7,$H7>Q$2),3, IF(AND($F7<=Q$2, $H7>=Q$2), 2, "" ))) -> 2 | R7: =IF(AND($F7<(R$2+7),$F7>R$2),1, IF(AND($H7<R$2+7,$H7>R$2),3, IF(AND($F7<=R$2, $H7>=R$2), 2, "" ))) -> 2 | S7: =IF(AND($F7<(S$2+7),$F7>S$2),1, IF(AND($H7<S$2+7,$H7>S$2),3, IF(AND($F7<=S$2, $H7>=S$2), 2, "" ))) -> 2 | ... AQ7: =IF(AND($F7<(AQ$2+7),$F7>AQ$2),1, IF(AND($H7<AQ$2+7,$H7>AQ$2),3, IF(AND($F7<=AQ$2, $H7>=AQ$2), 2, "" )))
B8: Panel Procurement | C8: 43833 | D8: 5 | E8: 43840 | F8: 43833 | G8: 5 | H8: 43840 | L8: =IF(AND($F8<(L$2+7),$F8>L$2),1, IF(AND($H8<L$2+7,$H8>L$2),3, IF(AND($F8<=L$2, $H8>=L$2), 2, "" ))) -> 1 | M8: =IF(AND($F8<(M$2+7),$F8>M$2),1, IF(AND($H8<M$2+7,$H8>M$2),3, IF(AND($F8<=M$2, $H8>=M$2), 2, "" ))) -> 3 | N8: =IF(AND($F8<(N$2+7),$F8>N$2),1, IF(AND($H8<N$2+7,$H8>N$2),3, IF(AND($F8<=N$2, $H8>=N$2), 2, "" ))) | O8: =IF(AND($F8<(O$2+7),$F8>O$2),1, IF(AND($H8<O$2+7,$H8>O$2),3, IF(AND($F8<=O$2, $H8>=O$2), 2, "" ))) | P8: =IF(AND($F8<(P$2+7),$F8>P$2),1, IF(AND($H8<P$2+7,$H8>P$2),3, IF(AND($F8<=P$2, $H8>=P$2), 2, "" ))) | Q8: =IF(AND($F8<(Q$2+7),$F8>Q$2),1, IF(AND($H8<Q$2+7,$H8>Q$2),3, IF(AND($F8<=Q$2, $H8>=Q$2), 2, "" ))) | R8: =IF(AND($F8<(R$2+7),$F8>R$2),1, IF(AND($H8<R$2+7,$H8>R$2),3, IF(AND($F8<=R$2, $H8>=R$2), 2, "" ))) | S8: =IF(AND($F8<(S$2+7),$F8>S$2),1, IF(AND($H8<S$2+7,$H8>S$2),3, IF(AND($F8<=S$2, $H8>=S$2), 2, "" ))) | ... AQ8: =IF(AND($F8<(AQ$2+7),$F8>AQ$2),1, IF(AND($H8<AQ$2+7,$H8>AQ$2),3, IF(AND($F8<=AQ$2, $H8>=AQ$2), 2, "" )))
B9: Inverter Procurement | C9: 43941 | D9: 5 | E9: 43949 | F9: 43941 | G9: 5 | H9: 43949 | L9: =IF(AND($F9<(L$2+7),$F9>L$2),1, IF(AND($H9<L$2+7,$H9>L$2),3, IF(AND($F9<=L$2, $H9>=L$2), 2, "" ))) | M9: =IF(AND($F9<(M$2+7),$F9>M$2),1, IF(AND($H9<M$2+7,$H9>M$2),3, IF(AND($F9<=M$2, $H9>=M$2), 2, "" ))) | N9: =IF(AND($F9<(N$2+7),$F9>N$2),1, IF(AND($H9<N$2+7,$H9>N$2),3, IF(AND($F9<=N$2, $H9>=N$2), 2, "" ))) | O9: =IF(AND($F9<(O$2+7),$F9>O$2),1, IF(AND($H9<O$2+7,$H9>O$2),3, IF(AND($F9<=O$2, $H9>=O$2), 2, "" ))) | P9: =IF(AND($F9<(P$2+7),$F9>P$2),1, IF(AND($H9<P$2+7,$H9>P$2),3, IF(AND($F9<=P$2, $H9>=P$2), 2, "" ))) | Q9: =IF(AND($F9<(Q$2+7),$F9>Q$2),1, IF(AND($H9<Q$2+7,$H9>Q$2),3, IF(AND($F9<=Q$2, $H9>=Q$2), 2, "" ))) | R9: =IF(AND($F9<(R$2+7),$F9>R$2),1, IF(AND($H9<R$2+7,$H9>R$2),3, IF(AND($F9<=R$2, $H9>=R$2), 2, "" ))) | S9: =IF(AND($F9<(S$2+7),$F9>S$2),1, IF(AND($H9<S$2+7,$H9>S$2),3, IF(AND($F9<=S$2, $H9>=S$2), 2, "" ))) | ... AQ9: =IF(AND($F9<(AQ$2+7),$F9>AQ$2),1, IF(AND($H9<AQ$2+7,$H9>AQ$2),3, IF(AND($F9<=AQ$2, $H9>=AQ$2), 2, "" )))
B10: Mounting Structure Procurement | C10: 43941 | D10: 5 | E10: 43949 | F10: 43941 | G10: 5 | H10: 43949 | L10: =IF(AND($F10<(L$2+7),$F10>L$2),1, IF(AND($H10<L$2+7,$H10>L$2),3, IF(AND($F10<=L$2, $H10>=L$2), 2, "" ))) | M10: =IF(AND($F10<(M$2+7),$F10>M$2),1, IF(AND($H10<M$2+7,$H10>M$2),3, IF(AND($F10<=M$2, $H10>=M$2), 2, "" ))) | N10: =IF(AND($F10<(N$2+7),$F10>N$2),1, IF(AND($H10<N$2+7,$H10>N$2),3, IF(AND($F10<=N$2, $H10>=N$2), 2, "" ))) | O10: =IF(AND($F10<(O$2+7),$F10>O$2),1, IF(AND($H10<O$2+7,$H10>O$2),3, IF(AND($F10<=O$2, $H10>=O$2), 2, "" ))) | P10: =IF(AND($F10<(P$2+7),$F10>P$2),1, IF(AND($H10<P$2+7,$H10>P$2),3, IF(AND($F10<=P$2, $H10>=P$2), 2, "" ))) | Q10: =IF(AND($F10<(Q$2+7),$F10>Q$2),1, IF(AND($H10<Q$2+7,$H10>Q$2),3, IF(AND($F10<=Q$2, $H10>=Q$2), 2, "" ))) | R10: =IF(AND($F10<(R$2+7),$F10>R$2),1, IF(AND($H10<R$2+7,$H10>R$2),3, IF(AND($F10<=R$2, $H10>=R$2), 2, "" ))) | S10: =IF(AND($F10<(S$2+7),$F10>S$2),1, IF(AND($H10<S$2+7,$H10>S$2),3, IF(AND($F10<=S$2, $H10>=S$2), 2, "" ))) | ... AQ10: =IF(AND($F10<(AQ$2+7),$F10>AQ$2),1, IF(AND($H10<AQ$2+7,$H10>AQ$2),3, IF(AND($F10<=AQ$2, $H10>=AQ$2), 2, "" )))
B11: BOS Procurement | C11: 43941 | D11: 5 | E11: 43949 | F11: 43941 | G11: 5 | H11: 43949 | L11: =IF(AND($F11<(L$2+7),$F11>L$2),1, IF(AND($H11<L$2+7,$H11>L$2),3, IF(AND($F11<=L$2, $H11>=L$2), 2, "" ))) | M11: =IF(AND($F11<(M$2+7),$F11>M$2),1, IF(AND($H11<M$2+7,$H11>M$2),3, IF(AND($F11<=M$2, $H11>=M$2), 2, "" ))) | N11: =IF(AND($F11<(N$2+7),$F11>N$2),1, IF(AND($H11<N$2+7,$H11>N$2),3, IF(AND($F11<=N$2, $H11>=N$2), 2, "" ))) | O11: =IF(AND($F11<(O$2+7),$F11>O$2),1, IF(AND($H11<O$2+7,$H11>O$2),3, IF(AND($F11<=O$2, $H11>=O$2), 2, "" ))) | P11: =IF(AND($F11<(P$2+7),$F11>P$2),1, IF(AND($H11<P$2+7,$H11>P$2),3, IF(AND($F11<=P$2, $H11>=P$2), 2, "" ))) | Q11: =IF(AND($F11<(Q$2+7),$F11>Q$2),1, IF(AND($H11<Q$2+7,$H11>Q$2),3, IF(AND($F11<=Q$2, $H11>=Q$2), 2, "" ))) | R11: =IF(AND($F11<(R$2+7),$F11>R$2),1, IF(AND($H11<R$2+7,$H11>R$2),3, IF(AND($F11<=R$2, $H11>=R$2), 2, "" ))) | S11: =IF(AND($F11<(S$2+7),$F11>S$2),1, IF(AND($H11<S$2+7,$H11>S$2),3, IF(AND($F11<=S$2, $H11>=S$2), 2, "" ))) | ... AQ11: =IF(AND($F11<(AQ$2+7),$F11>AQ$2),1, IF(AND($H11<AQ$2+7,$H11>AQ$2),3, IF(AND($F11<=AQ$2, $H11>=AQ$2), 2, "" )))
A12: 5 | B12: Internal Project Kick off | C12: 43936 | D12: 5 | E12: 43943 | F12: 43936 | G12: 5 | H12: 43943
A13: 6 | B13: Client Project Kick-off | C13: 43963 | D13: 5 | E13: 43970 | F13: 43963 | G13: 5 | H13: 43970 | L13: =IF(AND($F13<(L$2+7),$F13>L$2),1, IF(AND($H13<L$2+7,$H13>L$2),3, IF(AND($F13<=L$2, $H13>=L$2), 2, "" ))) | M13: =IF(AND($F13<(M$2+7),$F13>M$2),1, IF(AND($H13<M$2+7,$H13>M$2),3, IF(AND($F13<=M$2, $H13>=M$2), 2, "" ))) | N13: =IF(AND($F13<(N$2+7),$F13>N$2),1, IF(AND($H13<N$2+7,$H13>N$2),3, IF(AND($F13<=N$2, $H13>=N$2), 2, "" ))) | O13: =IF(AND($F13<(O$2+7),$F13>O$2),1, IF(AND($H13<O$2+7,$H13>O$2),3, IF(AND($F13<=O$2, $H13>=O$2), 2, "" ))) | P13: =IF(AND($F13<(P$2+7),$F13>P$2),1, IF(AND($H13<P$2+7,$H13>P$2),3, IF(AND($F13<=P$2, $H13>=P$2), 2, "" ))) | Q13: =IF(AND($F13<(Q$2+7),$F13>Q$2),1, IF(AND($H13<Q$2+7,$H13>Q$2),3, IF(AND($F13<=Q$2, $H13>=Q$2), 2, "" ))) | R13: =IF(AND($F13<(R$2+7),$F13>R$2),1, IF(AND($H13<R$2+7,$H13>R$2),3, IF(AND($F13<=R$2, $H13>=R$2), 2, "" ))) | S13: =IF(AND($F13<(S$2+7),$F13>S$2),1, IF(AND($H13<S$2+7,$H13>S$2),3, IF(AND($F13<=S$2, $H13>=S$2), 2, "" ))) | ... AQ13: =IF(AND($F13<(AQ$2+7),$F13>AQ$2),1, IF(AND($H13<AQ$2+7,$H13>AQ$2),3, IF(AND($F13<=AQ$2, $H13>=AQ$2), 2, "" )))
A14: 7 | B14: Equipment Delivery | C14: 43983 | D14: 9 | E14: 43994 | F14: 43983 | G14: 9 | H14: 43994 | L14: =IF(AND($F14<(L$2+7),$F14>L$2),1, IF(AND($H14<L$2+7,$H14>L$2),3, IF(AND($F14<=L$2, $H14>=L$2), 2, "" ))) | M14: =IF(AND($F14<(M$2+7),$F14>M$2),1, IF(AND($H14<M$2+7,$H14>M$2),3, IF(AND($F14<=M$2, $H14>=M$2), 2, "" ))) | N14: =IF(AND($F14<(N$2+7),$F14>N$2),1, IF(AND($H14<N$2+7,$H14>N$2),3, IF(AND($F14<=N$2, $H14>=N$2), 2, "" ))) | O14: =IF(AND($F14<(O$2+7),$F14>O$2),1, IF(AND($H14<O$2+7,$H14>O$2),3, IF(AND($F14<=O$2, $H14>=O$2), 2, "" ))) | P14: =IF(AND($F14<(P$2+7),$F14>P$2),1, IF(AND($H14<P$2+7,$H14>P$2),3, IF(AND($F14<=P$2, $H14>=P$2), 2, "" ))) | Q14: =IF(AND($F14<(Q$2+7),$F14>Q$2),1, IF(AND($H14<Q$2+7,$H14>Q$2),3, IF(AND($F14<=Q$2, $H14>=Q$2), 2, "" ))) | R14: =IF(AND($F14<(R$2+7),$F14>R$2),1, IF(AND($H14<R$2+7,$H14>R$2),3, IF(AND($F14<=R$2, $H14>=R$2), 2, "" ))) | S14: =IF(AND($F14<(S$2+7),$F14>S$2),1, IF(AND($H14<S$2+7,$H14>S$2),3, IF(AND($F14<=S$2, $H14>=S$2), 2, "" ))) | ... AQ14: =IF(AND($F14<(AQ$2+7),$F14>AQ$2),1, IF(AND($H14<AQ$2+7,$H14>AQ$2),3, IF(AND($F14<=AQ$2, $H14>=AQ$2), 2, "" )))
B15: Mounting Structure Delivery | C15: 43983 | D15: 2 | E15: 43985 | F15: 43983 | G15: 2 | H15: 43985
B16: Panel Delivery | C16: 43990 | D16: 2 | E16: 43992 | F16: 43990 | G16: 2 | H16: 43992 | L16: =IF(AND($F16<(L$2+7),$F16>L$2),1, IF(AND($H16<L$2+7,$H16>L$2),3, IF(AND($F16<=L$2, $H16>=L$2), 2, "" ))) | M16: =IF(AND($F16<(M$2+7),$F16>M$2),1, IF(AND($H16<M$2+7,$H16>M$2),3, IF(AND($F16<=M$2, $H16>=M$2), 2, "" ))) | N16: =IF(AND($F16<(N$2+7),$F16>N$2),1, IF(AND($H16<N$2+7,$H16>N$2),3, IF(AND($F16<=N$2, $H16>=N$2), 2, "" ))) | O16: =IF(AND($F16<(O$2+7),$F16>O$2),1, IF(AND($H16<O$2+7,$H16>O$2),3, IF(AND($F16<=O$2, $H16>=O$2), 2, "" ))) | P16: =IF(AND($F16<(P$2+7),$F16>P$2),1, IF(AND($H16<P$2+7,$H16>P$2),3, IF(AND($F16<=P$2, $H16>=P$2), 2, "" ))) | Q16: =IF(AND($F16<(Q$2+7),$F16>Q$2),1, IF(AND($H16<Q$2+7,$H16>Q$2),3, IF(AND($F16<=Q$2, $H16>=Q$2), 2, "" ))) | R16: =IF(AND($F16<(R$2+7),$F16>R$2),1, IF(AND($H16<R$2+7,$H16>R$2),3, IF(AND($F16<=R$2, $H16>=R$2), 2, "" ))) | S16: =IF(AND($F16<(S$2+7),$F16>S$2),1, IF(AND($H16<S$2+7,$H16>S$2),3, IF(AND($F16<=S$2, $H16>=S$2), 2, "" ))) | ... AQ16: =IF(AND($F16<(AQ$2+7),$F16>AQ$2),1, IF(AND($H16<AQ$2+7,$H16>AQ$2),3, IF(AND($F16<=AQ$2, $H16>=AQ$2), 2, "" )))
B17: Generator Delivery | C17: 43983 | D17: 2 | E17: 43985 | F17: 43983 | G17: 2 | H17: 43985
A18: B | B18: PAYMENT MILESTONE 2: DELIVERY OF PV PANELS | C18: 43992 | D18: 2 | E18: 43994 | F18: 43992 | G18: 2 | H18: 43994
B19: Inverter Delivery | C19: 43983 | D19: 2 | E19: 43985 | F19: 43983 | G19: 2 | H19: 43985 | L19: =IF(AND($F19<(L$2+7),$F19>L$2),1, IF(AND($H19<L$2+7,$H19>L$2),3, IF(AND($F19<=L$2, $H19>=L$2), 2, "" ))) | M19: =IF(AND($F19<(M$2+7),$F19>M$2),1, IF(AND($H19<M$2+7,$H19>M$2),3, IF(AND($F19<=M$2, $H19>=M$2), 2, "" ))) | N19: =IF(AND($F19<(N$2+7),$F19>N$2),1, IF(AND($H19<N$2+7,$H19>N$2),3, IF(AND($F19<=N$2, $H19>=N$2), 2, "" ))) | O19: =IF(AND($F19<(O$2+7),$F19>O$2),1, IF(AND($H19<O$2+7,$H19>O$2),3, IF(AND($F19<=O$2, $H19>=O$2), 2, "" ))) | P19: =IF(AND($F19<(P$2+7),$F19>P$2),1, IF(AND($H19<P$2+7,$H19>P$2),3, IF(AND($F19<=P$2, $H19>=P$2), 2, "" ))) | Q19: =IF(AND($F19<(Q$2+7),$F19>Q$2),1, IF(AND($H19<Q$2+7,$H19>Q$2),3, IF(AND($F19<=Q$2, $H19>=Q$2), 2, "" ))) | R19: =IF(AND($F19<(R$2+7),$F19>R$2),1, IF(AND($H19<R$2+7,$H19>R$2),3, IF(AND($F19<=R$2, $H19>=R$2), 2, "" ))) | S19: =IF(AND($F19<(S$2+7),$F19>S$2),1, IF(AND($H19<S$2+7,$H19>S$2),3, IF(AND($F19<=S$2, $H19>=S$2), 2, "" ))) | ... AQ19: =IF(AND($F19<(AQ$2+7),$F19>AQ$2),1, IF(AND($H19<AQ$2+7,$H19>AQ$2),3, IF(AND($F19<=AQ$2, $H19>=AQ$2), 2, "" )))
B20: BOS Delivery | C20: 43983 | D20: 1 | E20: 43984 | F20: 43983 | G20: 1 | H20: 43984 | L20: =IF(AND($F20<(L$2+7),$F20>L$2),1, IF(AND($H20<L$2+7,$H20>L$2),3, IF(AND($F20<=L$2, $H20>=L$2), 2, "" ))) | M20: =IF(AND($F20<(M$2+7),$F20>M$2),1, IF(AND($H20<M$2+7,$H20>M$2),3, IF(AND($F20<=M$2, $H20>=M$2), 2, "" ))) | N20: =IF(AND($F20<(N$2+7),$F20>N$2),1, IF(AND($H20<N$2+7,$H20>N$2),3, IF(AND($F20<=N$2, $H20>=N$2), 2, "" ))) | O20: =IF(AND($F20<(O$2+7),$F20>O$2),1, IF(AND($H20<O$2+7,$H20>O$2),3, IF(AND($F20<=O$2, $H20>=O$2), 2, "" ))) | P20: =IF(AND($F20<(P$2+7),$F20>P$2),1, IF(AND($H20<P$2+7,$H20>P$2),3, IF(AND($F20<=P$2, $H20>=P$2), 2, "" ))) | Q20: =IF(AND($F20<(Q$2+7),$F20>Q$2),1, IF(AND($H20<Q$2+7,$H20>Q$2),3, IF(AND($F20<=Q$2, $H20>=Q$2), 2, "" ))) | R20: =IF(AND($F20<(R$2+7),$F20>R$2),1, IF(AND($H20<R$2+7,$H20>R$2),3, IF(AND($F20<=R$2, $H20>=R$2), 2, "" ))) | S20: =IF(AND($F20<(S$2+7),$F20>S$2),1, IF(AND($H20<S$2+7,$H20>S$2),3, IF(AND($F20<=S$2, $H20>=S$2), 2, "" ))) | ... AQ20: =IF(AND($F20<(AQ$2+7),$F20>AQ$2),1, IF(AND($H20<AQ$2+7,$H20>AQ$2),3, IF(AND($F20<=AQ$2, $H20>=AQ$2), 2, "" )))
A21: C | B21: PAYMENT MILESTONE 3: DELIVERY OF INVERTERS AND BOS | C21: 43985 | D21: 2 | E21: 43987 | F21: 43985 | G21: 2 | H21: 43987
A22: 8 | B22: Installation | C22: 43990 | D22: 22 | E22: 44012 | F22: 43990 | G22: 22 | H22: 44012 | L22: =IF(AND($F22<(L$2+7),$F22>L$2),1, IF(AND($H22<L$2+7,$H22>L$2),3, IF(AND($F22<=L$2, $H22>=L$2), 2, "" ))) | M22: =IF(AND($F22<(M$2+7),$F22>M$2),1, IF(AND($H22<M$2+7,$H22>M$2),3, IF(AND($F22<=M$2, $H22>=M$2), 2, "" ))) | N22: =IF(AND($F22<(N$2+7),$F22>N$2),1, IF(AND($H22<N$2+7,$H22>N$2),3, IF(AND($F22<=N$2, $H22>=N$2), 2, "" ))) | O22: =IF(AND($F22<(O$2+7),$F22>O$2),1, IF(AND($H22<O$2+7,$H22>O$2),3, IF(AND($F22<=O$2, $H22>=O$2), 2, "" ))) | P22: =IF(AND($F22<(P$2+7),$F22>P$2),1, IF(AND($H22<P$2+7,$H22>P$2),3, IF(AND($F22<=P$2, $H22>=P$2), 2, "" ))) | Q22: =IF(AND($F22<(Q$2+7),$F22>Q$2),1, IF(AND($H22<Q$2+7,$H22>Q$2),3, IF(AND($F22<=Q$2, $H22>=Q$2), 2, "" ))) | R22: =IF(AND($F22<(R$2+7),$F22>R$2),1, IF(AND($H22<R$2+7,$H22>R$2),3, IF(AND($F22<=R$2, $H22>=R$2), 2, "" ))) | S22: =IF(AND($F22<(S$2+7),$F22>S$2),1, IF(AND($H22<S$2+7,$H22>S$2),3, IF(AND($F22<=S$2, $H22>=S$2), 2, "" ))) | ... AQ22: =IF(AND($F22<(AQ$2+7),$F22>AQ$2),1, IF(AND($H22<AQ$2+7,$H22>AQ$2),3, IF(AND($F22<=AQ$2, $H22>=AQ$2), 2, "" ))) -> 2
B23: Site Establishment | C23: 43990 | D23: 1 | E23: 43991 | F23: 43990 | G23: 1 | H23: 43991 | J23: Installation placed on hold due to Covid-19 case | L23: =IF(AND($F23<(L$2+7),$F23>L$2),1, IF(AND($H23<L$2+7,$H23>L$2),3, IF(AND($F23<=L$2, $H23>=L$2), 2, "" ))) | M23: =IF(AND($F23<(M$2+7),$F23>M$2),1, IF(AND($H23<M$2+7,$H23>M$2),3, IF(AND($F23<=M$2, $H23>=M$2), 2, "" ))) | N23: =IF(AND($F23<(N$2+7),$F23>N$2),1, IF(AND($H23<N$2+7,$H23>N$2),3, IF(AND($F23<=N$2, $H23>=N$2), 2, "" ))) | O23: =IF(AND($F23<(O$2+7),$F23>O$2),1, IF(AND($H23<O$2+7,$H23>O$2),3, IF(AND($F23<=O$2, $H23>=O$2), 2, "" ))) | P23: =IF(AND($F23<(P$2+7),$F23>P$2),1, IF(AND($H23<P$2+7,$H23>P$2),3, IF(AND($F23<=P$2, $H23>=P$2), 2, "" ))) | Q23: =IF(AND($F23<(Q$2+7),$F23>Q$2),1, IF(AND($H23<Q$2+7,$H23>Q$2),3, IF(AND($F23<=Q$2, $H23>=Q$2), 2, "" ))) | R23: =IF(AND($F23<(R$2+7),$F23>R$2),1, IF(AND($H23<R$2+7,$H23>R$2),3, IF(AND($F23<=R$2, $H23>=R$2), 2, "" ))) | S23: =IF(AND($F23<(S$2+7),$F23>S$2),1, IF(AND($H23<S$2+7,$H23>S$2),3, IF(AND($F23<=S$2, $H23>=S$2), 2, "" ))) | ... AQ23: =IF(AND($F23<(AQ$2+7),$F23>AQ$2),1, IF(AND($H23<AQ$2+7,$H23>AQ$2),3, IF(AND($F23<=AQ$2, $H23>=AQ$2), 2, "" )))
A24: 9 | B24: DC Works | C24: 43991 | D24: 16 | E24: 44012 | F24: 43991 | G24: 16 | H24: 44012 | L24: =IF(AND($F24<(L$2+7),$F24>L$2),1, IF(AND($H24<L$2+7,$H24>L$2),3, IF(AND($F24<=L$2, $H24>=L$2), 2, "" ))) | M24: =IF(AND($F24<(M$2+7),$F24>M$2),1, IF(AND($H24<M$2+7,$H24>M$2),3, IF(AND($F24<=M$2, $H24>=M$2), 2, "" ))) | N24: =IF(AND($F24<(N$2+7),$F24>N$2),1, IF(AND($H24<N$2+7,$H24>N$2),3, IF(AND($F24<=N$2, $H24>=N$2), 2, "" ))) | O24: =IF(AND($F24<(O$2+7),$F24>O$2),1, IF(AND($H24<O$2+7,$H24>O$2),3, IF(AND($F24<=O$2, $H24>=O$2), 2, "" ))) | P24: =IF(AND($F24<(P$2+7),$F24>P$2),1, IF(AND($H24<P$2+7,$H24>P$2),3, IF(AND($F24<=P$2, $H24>=P$2), 2, "" ))) | Q24: =IF(AND($F24<(Q$2+7),$F24>Q$2),1, IF(AND($H24<Q$2+7,$H24>Q$2),3, IF(AND($F24<=Q$2, $H24>=Q$2), 2, "" ))) | R24: =IF(AND($F24<(R$2+7),$F24>R$2),1, IF(AND($H24<R$2+7,$H24>R$2),3, IF(AND($F24<=R$2, $H24>=R$2), 2, "" ))) | S24: =IF(AND($F24<(S$2+7),$F24>S$2),1, IF(AND($H24<S$2+7,$H24>S$2),3, IF(AND($F24<=S$2, $H24>=S$2), 2, "" ))) | ... AQ24: =IF(AND($F24<(AQ$2+7),$F24>AQ$2),1, IF(AND($H24<AQ$2+7,$H24>AQ$2),3, IF(AND($F24<=AQ$2, $H24>=AQ$2), 2, "" ))) -> 2
B25: Mounting structure Installation | C25: 43991 | D25: 4 | E25: 43997 | F25: 43991 | G25: 4 | H25: 43997 | L25: =IF(AND($F25<(L$2+7),$F25>L$2),1, IF(AND($H25<L$2+7,$H25>L$2),3, IF(AND($F25<=L$2, $H25>=L$2), 2, "" ))) | M25: =IF(AND($F25<(M$2+7),$F25>M$2),1, IF(AND($H25<M$2+7,$H25>M$2),3, IF(AND($F25<=M$2, $H25>=M$2), 2, "" ))) | N25: =IF(AND($F25<(N$2+7),$F25>N$2),1, IF(AND($H25<N$2+7,$H25>N$2),3, IF(AND($F25<=N$2, $H25>=N$2), 2, "" ))) | O25: =IF(AND($F25<(O$2+7),$F25>O$2),1, IF(AND($H25<O$2+7,$H25>O$2),3, IF(AND($F25<=O$2, $H25>=O$2), 2, "" ))) | P25: =IF(AND($F25<(P$2+7),$F25>P$2),1, IF(AND($H25<P$2+7,$H25>P$2),3, IF(AND($F25<=P$2, $H25>=P$2), 2, "" ))) | Q25: =IF(AND($F25<(Q$2+7),$F25>Q$2),1, IF(AND($H25<Q$2+7,$H25>Q$2),3, IF(AND($F25<=Q$2, $H25>=Q$2), 2, "" ))) | R25: =IF(AND($F25<(R$2+7),$F25>R$2),1, IF(AND($H25<R$2+7,$H25>R$2),3, IF(AND($F25<=R$2, $H25>=R$2), 2, "" ))) | S25: =IF(AND($F25<(S$2+7),$F25>S$2),1, IF(AND($H25<S$2+7,$H25>S$2),3, IF(AND($F25<=S$2, $H25>=S$2), 2, "" ))) | ... AQ25: =IF(AND($F25<(AQ$2+7),$F25>AQ$2),1, IF(AND($H25<AQ$2+7,$H25>AQ$2),3, IF(AND($F25<=AQ$2, $H25>=AQ$2), 2, "" )))
B26: Cable tray Installation | C26: 43997 | D26: 3 | E26: 44004 | F26: 43997 | G26: 3 | H26: 44004 | L26: =IF(AND($F26<(L$2+7),$F26>L$2),1, IF(AND($H26<L$2+7,$H26>L$2),3, IF(AND($F26<=L$2, $H26>=L$2), 2, "" ))) | M26: =IF(AND($F26<(M$2+7),$F26>M$2),1, IF(AND($H26<M$2+7,$H26>M$2),3, IF(AND($F26<=M$2, $H26>=M$2), 2, "" ))) | N26: =IF(AND($F26<(N$2+7),$F26>N$2),1, IF(AND($H26<N$2+7,$H26>N$2),3, IF(AND($F26<=N$2, $H26>=N$2), 2, "" ))) | O26: =IF(AND($F26<(O$2+7),$F26>O$2),1, IF(AND($H26<O$2+7,$H26>O$2),3, IF(AND($F26<=O$2, $H26>=O$2), 2, "" ))) | P26: =IF(AND($F26<(P$2+7),$F26>P$2),1, IF(AND($H26<P$2+7,$H26>P$2),3, IF(AND($F26<=P$2, $H26>=P$2), 2, "" ))) | Q26: =IF(AND($F26<(Q$2+7),$F26>Q$2),1, IF(AND($H26<Q$2+7,$H26>Q$2),3, IF(AND($F26<=Q$2, $H26>=Q$2), 2, "" ))) | R26: =IF(AND($F26<(R$2+7),$F26>R$2),1, IF(AND($H26<R$2+7,$H26>R$2),3, IF(AND($F26<=R$2, $H26>=R$2), 2, "" ))) | S26: =IF(AND($F26<(S$2+7),$F26>S$2),1, IF(AND($H26<S$2+7,$H26>S$2),3, IF(AND($F26<=S$2, $H26>=S$2), 2, "" ))) | ... AQ26: =IF(AND($F26<(AQ$2+7),$F26>AQ$2),1, IF(AND($H26<AQ$2+7,$H26>AQ$2),3, IF(AND($F26<=AQ$2, $H26>=AQ$2), 2, "" )))
B27: DC Cable Installation | C27: 44004 | D27: 2 | E27: 44006 | F27: 44004 | G27: 2 | H27: 44006 | L27: =IF(AND($F27<(L$2+7),$F27>L$2),1, IF(AND($H27<L$2+7,$H27>L$2),3, IF(AND($F27<=L$2, $H27>=L$2), 2, "" ))) | M27: =IF(AND($F27<(M$2+7),$F27>M$2),1, IF(AND($H27<M$2+7,$H27>M$2),3, IF(AND($F27<=M$2, $H27>=M$2), 2, "" ))) | N27: =IF(AND($F27<(N$2+7),$F27>N$2),1, IF(AND($H27<N$2+7,$H27>N$2),3, IF(AND($F27<=N$2, $H27>=N$2), 2, "" ))) | O27: =IF(AND($F27<(O$2+7),$F27>O$2),1, IF(AND($H27<O$2+7,$H27>O$2),3, IF(AND($F27<=O$2, $H27>=O$2), 2, "" ))) | P27: =IF(AND($F27<(P$2+7),$F27>P$2),1, IF(AND($H27<P$2+7,$H27>P$2),3, IF(AND($F27<=P$2, $H27>=P$2), 2, "" ))) | Q27: =IF(AND($F27<(Q$2+7),$F27>Q$2),1, IF(AND($H27<Q$2+7,$H27>Q$2),3, IF(AND($F27<=Q$2, $H27>=Q$2), 2, "" ))) | R27: =IF(AND($F27<(R$2+7),$F27>R$2),1, IF(AND($H27<R$2+7,$H27>R$2),3, IF(AND($F27<=R$2, $H27>=R$2), 2, "" ))) | S27: =IF(AND($F27<(S$2+7),$F27>S$2),1, IF(AND($H27<S$2+7,$H27>S$2),3, IF(AND($F27<=S$2, $H27>=S$2), 2, "" ))) | ... AQ27: =IF(AND($F27<(AQ$2+7),$F27>AQ$2),1, IF(AND($H27<AQ$2+7,$H27>AQ$2),3, IF(AND($F27<=AQ$2, $H27>=AQ$2), 2, "" )))
B28: Module Installation | C28: 44006 | D28: 4 | E28: 44012 | F28: 44006 | G28: 4 | H28: 44012 | L28: =IF(AND($F28<(L$2+7),$F28>L$2),1, IF(AND($H28<L$2+7,$H28>L$2),3, IF(AND($F28<=L$2, $H28>=L$2), 2, "" ))) | M28: =IF(AND($F28<(M$2+7),$F28>M$2),1, IF(AND($H28<M$2+7,$H28>M$2),3, IF(AND($F28<=M$2, $H28>=M$2), 2, "" ))) | N28: =IF(AND($F28<(N$2+7),$F28>N$2),1, IF(AND($H28<N$2+7,$H28>N$2),3, IF(AND($F28<=N$2, $H28>=N$2), 2, "" ))) | O28: =IF(AND($F28<(O$2+7),$F28>O$2),1, IF(AND($H28<O$2+7,$H28>O$2),3, IF(AND($F28<=O$2, $H28>=O$2), 2, "" ))) | P28: =IF(AND($F28<(P$2+7),$F28>P$2),1, IF(AND($H28<P$2+7,$H28>P$2),3, IF(AND($F28<=P$2, $H28>=P$2), 2, "" ))) | Q28: =IF(AND($F28<(Q$2+7),$F28>Q$2),1, IF(AND($H28<Q$2+7,$H28>Q$2),3, IF(AND($F28<=Q$2, $H28>=Q$2), 2, "" ))) | R28: =IF(AND($F28<(R$2+7),$F28>R$2),1, IF(AND($H28<R$2+7,$H28>R$2),3, IF(AND($F28<=R$2, $H28>=R$2), 2, "" ))) | S28: =IF(AND($F28<(S$2+7),$F28>S$2),1, IF(AND($H28<S$2+7,$H28>S$2),3, IF(AND($F28<=S$2, $H28>=S$2), 2, "" ))) | ... AQ28: =IF(AND($F28<(AQ$2+7),$F28>AQ$2),1, IF(AND($H28<AQ$2+7,$H28>AQ$2),3, IF(AND($F28<=AQ$2, $H28>=AQ$2), 2, "" ))) -> 2
B29: Earth Cable Installation | C29: 44004 | D29: 1 | E29: 44005 | F29: 44004 | G29: 1 | H29: 44005 | L29: =IF(AND($F29<(L$2+7),$F29>L$2),1, IF(AND($H29<L$2+7,$H29>L$2),3, IF(AND($F29<=L$2, $H29>=L$2), 2, "" ))) | M29: =IF(AND($F29<(M$2+7),$F29>M$2),1, IF(AND($H29<M$2+7,$H29>M$2),3, IF(AND($F29<=M$2, $H29>=M$2), 2, "" ))) | N29: =IF(AND($F29<(N$2+7),$F29>N$2),1, IF(AND($H29<N$2+7,$H29>N$2),3, IF(AND($F29<=N$2, $H29>=N$2), 2, "" ))) | O29: =IF(AND($F29<(O$2+7),$F29>O$2),1, IF(AND($H29<O$2+7,$H29>O$2),3, IF(AND($F29<=O$2, $H29>=O$2), 2, "" ))) | P29: =IF(AND($F29<(P$2+7),$F29>P$2),1, IF(AND($H29<P$2+7,$H29>P$2),3, IF(AND($F29<=P$2, $H29>=P$2), 2, "" ))) | Q29: =IF(AND($F29<(Q$2+7),$F29>Q$2),1, IF(AND($H29<Q$2+7,$H29>Q$2),3, IF(AND($F29<=Q$2, $H29>=Q$2), 2, "" ))) | R29: =IF(AND($F29<(R$2+7),$F29>R$2),1, IF(AND($H29<R$2+7,$H29>R$2),3, IF(AND($F29<=R$2, $H29>=R$2), 2, "" ))) | S29: =IF(AND($F29<(S$2+7),$F29>S$2),1, IF(AND($H29<S$2+7,$H29>S$2),3, IF(AND($F29<=S$2, $H29>=S$2), 2, "" ))) | ... AQ29: =IF(AND($F29<(AQ$2+7),$F29>AQ$2),1, IF(AND($H29<AQ$2+7,$H29>AQ$2),3, IF(AND($F29<=AQ$2, $H29>=AQ$2), 2, "" )))
A30: 10 | B30: AC Works | C30: 43991 | D30: 8 | E30: 44000 | F30: 43991 | G30: 8 | H30: 44000
B31: Inverters Installation | C31: 43991 | D31: 2 | E31: 43993 | F31: 43991 | G31: 2 | H31: 43993 | L31: =IF(AND($F31<(L$2+7),$F31>L$2),1, IF(AND($H31<L$2+7,$H31>L$2),3, IF(AND($F31<=L$2, $H31>=L$2), 2, "" ))) | M31: =IF(AND($F31<(M$2+7),$F31>M$2),1, IF(AND($H31<M$2+7,$H31>M$2),3, IF(AND($F31<=M$2, $H31>=M$2), 2, "" ))) | N31: =IF(AND($F31<(N$2+7),$F31>N$2),1, IF(AND($H31<N$2+7,$H31>N$2),3, IF(AND($F31<=N$2, $H31>=N$2), 2, "" ))) | O31: =IF(AND($F31<(O$2+7),$F31>O$2),1, IF(AND($H31<O$2+7,$H31>O$2),3, IF(AND($F31<=O$2, $H31>=O$2), 2, "" ))) | P31: =IF(AND($F31<(P$2+7),$F31>P$2),1, IF(AND($H31<P$2+7,$H31>P$2),3, IF(AND($F31<=P$2, $H31>=P$2), 2, "" ))) | Q31: =IF(AND($F31<(Q$2+7),$F31>Q$2),1, IF(AND($H31<Q$2+7,$H31>Q$2),3, IF(AND($F31<=Q$2, $H31>=Q$2), 2, "" ))) | R31: =IF(AND($F31<(R$2+7),$F31>R$2),1, IF(AND($H31<R$2+7,$H31>R$2),3, IF(AND($F31<=R$2, $H31>=R$2), 2, "" ))) | S31: =IF(AND($F31<(S$2+7),$F31>S$2),1, IF(AND($H31<S$2+7,$H31>S$2),3, IF(AND($F31<=S$2, $H31>=S$2), 2, "" ))) | ... AQ31: =IF(AND($F31<(AQ$2+7),$F31>AQ$2),1, IF(AND($H31<AQ$2+7,$H31>AQ$2),3, IF(AND($F31<=AQ$2, $H31>=AQ$2), 2, "" )))
B32: AC BOS Installation | C32: 43993 | D32: 3 | E32: 44000 | F32: 43993 | G32: 3 | H32: 44000 | L32: =IF(AND($F32<(L$2+7),$F32>L$2),1, IF(AND($H32<L$2+7,$H32>L$2),3, IF(AND($F32<=L$2, $H32>=L$2), 2, "" ))) | M32: =IF(AND($F32<(M$2+7),$F32>M$2),1, IF(AND($H32<M$2+7,$H32>M$2),3, IF(AND($F32<=M$2, $H32>=M$2), 2, "" ))) | N32: =IF(AND($F32<(N$2+7),$F32>N$2),1, IF(AND($H32<N$2+7,$H32>N$2),3, IF(AND($F32<=N$2, $H32>=N$2), 2, "" ))) | O32: =IF(AND($F32<(O$2+7),$F32>O$2),1, IF(AND($H32<O$2+7,$H32>O$2),3, IF(AND($F32<=O$2, $H32>=O$2), 2, "" ))) | P32: =IF(AND($F32<(P$2+7),$F32>P$2),1, IF(AND($H32<P$2+7,$H32>P$2),3, IF(AND($F32<=P$2, $H32>=P$2), 2, "" ))) | Q32: =IF(AND($F32<(Q$2+7),$F32>Q$2),1, IF(AND($H32<Q$2+7,$H32>Q$2),3, IF(AND($F32<=Q$2, $H32>=Q$2), 2, "" ))) | R32: =IF(AND($F32<(R$2+7),$F32>R$2),1, IF(AND($H32<R$2+7,$H32>R$2),3, IF(AND($F32<=R$2, $H32>=R$2), 2, "" ))) | S32: =IF(AND($F32<(S$2+7),$F32>S$2),1, IF(AND($H32<S$2+7,$H32>S$2),3, IF(AND($F32<=S$2, $H32>=S$2), 2, "" ))) | ... AQ32: =IF(AND($F32<(AQ$2+7),$F32>AQ$2),1, IF(AND($H32<AQ$2+7,$H32>AQ$2),3, IF(AND($F32<=AQ$2, $H32>=AQ$2), 2, "" )))
B33: AC Cable/Tie-In | C33: 43992 | D33: 3 | E33: 43997 | F33: 43992 | G33: 3 | H33: 43997 | L33: =IF(AND($F33<(L$2+7),$F33>L$2),1, IF(AND($H33<L$2+7,$H33>L$2),3, IF(AND($F33<=L$2, $H33>=L$2), 2, "" ))) | M33: =IF(AND($F33<(M$2+7),$F33>M$2),1, IF(AND($H33<M$2+7,$H33>M$2),3, IF(AND($F33<=M$2, $H33>=M$2), 2, "" ))) | N33: =IF(AND($F33<(N$2+7),$F33>N$2),1, IF(AND($H33<N$2+7,$H33>N$2),3, IF(AND($F33<=N$2, $H33>=N$2), 2, "" ))) | O33: =IF(AND($F33<(O$2+7),$F33>O$2),1, IF(AND($H33<O$2+7,$H33>O$2),3, IF(AND($F33<=O$2, $H33>=O$2), 2, "" ))) | P33: =IF(AND($F33<(P$2+7),$F33>P$2),1, IF(AND($H33<P$2+7,$H33>P$2),3, IF(AND($F33<=P$2, $H33>=P$2), 2, "" ))) | Q33: =IF(AND($F33<(Q$2+7),$F33>Q$2),1, IF(AND($H33<Q$2+7,$H33>Q$2),3, IF(AND($F33<=Q$2, $H33>=Q$2), 2, "" ))) | R33: =IF(AND($F33<(R$2+7),$F33>R$2),1, IF(AND($H33<R$2+7,$H33>R$2),3, IF(AND($F33<=R$2, $H33>=R$2), 2, "" ))) | S33: =IF(AND($F33<(S$2+7),$F33>S$2),1, IF(AND($H33<S$2+7,$H33>S$2),3, IF(AND($F33<=S$2, $H33>=S$2), 2, "" ))) | ... AQ33: =IF(AND($F33<(AQ$2+7),$F33>AQ$2),1, IF(AND($H33<AQ$2+7,$H33>AQ$2),3, IF(AND($F33<=AQ$2, $H33>=AQ$2), 2, "" )))
B34: Monitoring Platform Installation | C34: 43997 | D34: 1 | E34: 44000 | F34: 43997 | G34: 1 | H34: 44000
A35: 11 | B35: Completion | C35: 44000 | D35: 14 | E35: 44014 | F35: 44000 | G35: 14 | H35: 44014 | L35: =IF(AND($F35<(L$2+7),$F35>L$2),1, IF(AND($H35<L$2+7,$H35>L$2),3, IF(AND($F35<=L$2, $H35>=L$2), 2, "" ))) | M35: =IF(AND($F35<(M$2+7),$F35>M$2),1, IF(AND($H35<M$2+7,$H35>M$2),3, IF(AND($F35<=M$2, $H35>=M$2), 2, "" ))) | N35: =IF(AND($F35<(N$2+7),$F35>N$2),1, IF(AND($H35<N$2+7,$H35>N$2),3, IF(AND($F35<=N$2, $H35>=N$2), 2, "" ))) | O35: =IF(AND($F35<(O$2+7),$F35>O$2),1, IF(AND($H35<O$2+7,$H35>O$2),3, IF(AND($F35<=O$2, $H35>=O$2), 2, "" ))) | P35: =IF(AND($F35<(P$2+7),$F35>P$2),1, IF(AND($H35<P$2+7,$H35>P$2),3, IF(AND($F35<=P$2, $H35>=P$2), 2, "" ))) | Q35: =IF(AND($F35<(Q$2+7),$F35>Q$2),1, IF(AND($H35<Q$2+7,$H35>Q$2),3, IF(AND($F35<=Q$2, $H35>=Q$2), 2, "" ))) | R35: =IF(AND($F35<(R$2+7),$F35>R$2),1, IF(AND($H35<R$2+7,$H35>R$2),3, IF(AND($F35<=R$2, $H35>=R$2), 2, "" ))) | S35: =IF(AND($F35<(S$2+7),$F35>S$2),1, IF(AND($H35<S$2+7,$H35>S$2),3, IF(AND($F35<=S$2, $H35>=S$2), 2, "" ))) | ... AQ35: =IF(AND($F35<(AQ$2+7),$F35>AQ$2),1, IF(AND($H35<AQ$2+7,$H35>AQ$2),3, IF(AND($F35<=AQ$2, $H35>=AQ$2), 2, "" ))) -> 3
B36: DC Works | C36: 44012 | D36: 2 | E36: 44014 | F36: 44012 | G36: 2 | H36: 44014 | L36: =IF(AND($F36<(L$2+7),$F36>L$2),1, IF(AND($H36<L$2+7,$H36>L$2),3, IF(AND($F36<=L$2, $H36>=L$2), 2, "" ))) | M36: =IF(AND($F36<(M$2+7),$F36>M$2),1, IF(AND($H36<M$2+7,$H36>M$2),3, IF(AND($F36<=M$2, $H36>=M$2), 2, "" ))) | N36: =IF(AND($F36<(N$2+7),$F36>N$2),1, IF(AND($H36<N$2+7,$H36>N$2),3, IF(AND($F36<=N$2, $H36>=N$2), 2, "" ))) | O36: =IF(AND($F36<(O$2+7),$F36>O$2),1, IF(AND($H36<O$2+7,$H36>O$2),3, IF(AND($F36<=O$2, $H36>=O$2), 2, "" ))) | P36: =IF(AND($F36<(P$2+7),$F36>P$2),1, IF(AND($H36<P$2+7,$H36>P$2),3, IF(AND($F36<=P$2, $H36>=P$2), 2, "" ))) | Q36: =IF(AND($F36<(Q$2+7),$F36>Q$2),1, IF(AND($H36<Q$2+7,$H36>Q$2),3, IF(AND($F36<=Q$2, $H36>=Q$2), 2, "" ))) | R36: =IF(AND($F36<(R$2+7),$F36>R$2),1, IF(AND($H36<R$2+7,$H36>R$2),3, IF(AND($F36<=R$2, $H36>=R$2), 2, "" ))) | S36: =IF(AND($F36<(S$2+7),$F36>S$2),1, IF(AND($H36<S$2+7,$H36>S$2),3, IF(AND($F36<=S$2, $H36>=S$2), 2, "" ))) | ... AQ36: =IF(AND($F36<(AQ$2+7),$F36>AQ$2),1, IF(AND($H36<AQ$2+7,$H36>AQ$2),3, IF(AND($F36<=AQ$2, $H36>=AQ$2), 2, "" ))) -> 3
B37: AC Works | C37: 44000 | D37: 2 | E37: 44004 | F37: 44000 | G37: 2 | H37: 44004 | L37: =IF(AND($F37<(L$2+7),$F37>L$2),1, IF(AND($H37<L$2+7,$H37>L$2),3, IF(AND($F37<=L$2, $H37>=L$2), 2, "" ))) | M37: =IF(AND($F37<(M$2+7),$F37>M$2),1, IF(AND($H37<M$2+7,$H37>M$2),3, IF(AND($F37<=M$2, $H37>=M$2), 2, "" ))) | N37: =IF(AND($F37<(N$2+7),$F37>N$2),1, IF(AND($H37<N$2+7,$H37>N$2),3, IF(AND($F37<=N$2, $H37>=N$2), 2, "" ))) | O37: =IF(AND($F37<(O$2+7),$F37>O$2),1, IF(AND($H37<O$2+7,$H37>O$2),3, IF(AND($F37<=O$2, $H37>=O$2), 2, "" ))) | P37: =IF(AND($F37<(P$2+7),$F37>P$2),1, IF(AND($H37<P$2+7,$H37>P$2),3, IF(AND($F37<=P$2, $H37>=P$2), 2, "" ))) | Q37: =IF(AND($F37<(Q$2+7),$F37>Q$2),1, IF(AND($H37<Q$2+7,$H37>Q$2),3, IF(AND($F37<=Q$2, $H37>=Q$2), 2, "" ))) | R37: =IF(AND($F37<(R$2+7),$F37>R$2),1, IF(AND($H37<R$2+7,$H37>R$2),3, IF(AND($F37<=R$2, $H37>=R$2), 2, "" ))) | S37: =IF(AND($F37<(S$2+7),$F37>S$2),1, IF(AND($H37<S$2+7,$H37>S$2),3, IF(AND($F37<=S$2, $H37>=S$2), 2, "" ))) | ... AQ37: =IF(AND($F37<(AQ$2+7),$F37>AQ$2),1, IF(AND($H37<AQ$2+7,$H37>AQ$2),3, IF(AND($F37<=AQ$2, $H37>=AQ$2), 2, "" )))
A38: D | B38: PAYMENT MILESTONE 4: PRACTICAL COMPLETION | C38: 44012 | D38: 1 | E38: 44013 | F38: 44012 | G38: 1 | H38: 44013 | L38: =IF(AND($F38<(L$2+7),$F38>L$2),1, IF(AND($H38<L$2+7,$H38>L$2),3, IF(AND($F38<=L$2, $H38>=L$2), 2, "" ))) | M38: =IF(AND($F38<(M$2+7),$F38>M$2),1, IF(AND($H38<M$2+7,$H38>M$2),3, IF(AND($F38<=M$2, $H38>=M$2), 2, "" ))) | N38: =IF(AND($F38<(N$2+7),$F38>N$2),1, IF(AND($H38<N$2+7,$H38>N$2),3, IF(AND($F38<=N$2, $H38>=N$2), 2, "" ))) | O38: =IF(AND($F38<(O$2+7),$F38>O$2),1, IF(AND($H38<O$2+7,$H38>O$2),3, IF(AND($F38<=O$2, $H38>=O$2), 2, "" ))) | P38: =IF(AND($F38<(P$2+7),$F38>P$2),1, IF(AND($H38<P$2+7,$H38>P$2),3, IF(AND($F38<=P$2, $H38>=P$2), 2, "" ))) | Q38: =IF(AND($F38<(Q$2+7),$F38>Q$2),1, IF(AND($H38<Q$2+7,$H38>Q$2),3, IF(AND($F38<=Q$2, $H38>=Q$2), 2, "" ))) | R38: =IF(AND($F38<(R$2+7),$F38>R$2),1, IF(AND($H38<R$2+7,$H38>R$2),3, IF(AND($F38<=R$2, $H38>=R$2), 2, "" ))) | S38: =IF(AND($F38<(S$2+7),$F38>S$2),1, IF(AND($H38<S$2+7,$H38>S$2),3, IF(AND($F38<=S$2, $H38>=S$2), 2, "" ))) | ... AQ38: =IF(AND($F38<(AQ$2+7),$F38>AQ$2),1, IF(AND($H38<AQ$2+7,$H38>AQ$2),3, IF(AND($F38<=AQ$2, $H38>=AQ$2), 2, "" ))) -> 3
A39: 12 | B39: Commissioning | C39: 43997 | D39: 22 | E39: 44019 | F39: 43997 | G39: 22 | H39: 44019 | L39: =IF(AND($F39<(L$2+7),$F39>L$2),1, IF(AND($H39<L$2+7,$H39>L$2),3, IF(AND($F39<=L$2, $H39>=L$2), 2, "" ))) | M39: =IF(AND($F39<(M$2+7),$F39>M$2),1, IF(AND($H39<M$2+7,$H39>M$2),3, IF(AND($F39<=M$2, $H39>=M$2), 2, "" ))) | N39: =IF(AND($F39<(N$2+7),$F39>N$2),1, IF(AND($H39<N$2+7,$H39>N$2),3, IF(AND($F39<=N$2, $H39>=N$2), 2, "" ))) | O39: =IF(AND($F39<(O$2+7),$F39>O$2),1, IF(AND($H39<O$2+7,$H39>O$2),3, IF(AND($F39<=O$2, $H39>=O$2), 2, "" ))) | P39: =IF(AND($F39<(P$2+7),$F39>P$2),1, IF(AND($H39<P$2+7,$H39>P$2),3, IF(AND($F39<=P$2, $H39>=P$2), 2, "" ))) | Q39: =IF(AND($F39<(Q$2+7),$F39>Q$2),1, IF(AND($H39<Q$2+7,$H39>Q$2),3, IF(AND($F39<=Q$2, $H39>=Q$2), 2, "" ))) | R39: =IF(AND($F39<(R$2+7),$F39>R$2),1, IF(AND($H39<R$2+7,$H39>R$2),3, IF(AND($F39<=R$2, $H39>=R$2), 2, "" ))) | S39: =IF(AND($F39<(S$2+7),$F39>S$2),1, IF(AND($H39<S$2+7,$H39>S$2),3, IF(AND($F39<=S$2, $H39>=S$2), 2, "" ))) | ... AQ39: =IF(AND($F39<(AQ$2+7),$F39>AQ$2),1, IF(AND($H39<AQ$2+7,$H39>AQ$2),3, IF(AND($F39<=AQ$2, $H39>=AQ$2), 2, "" ))) -> 2
B40: Snag List | C40: 44014 | D40: 3 | E40: 44019 | F40: 44014 | G40: 3 | H40: 44019
...

Sheet Revenue Tracking
B2: HIGH LEVEL PROJECT REVENUE TRACKING
D3: PLANNED | F3: ACTUAL | L3: FINANCIAL REVIEW | N3: TIMELINE REVIEW
B4: 1 | C4: Planned Revenue | D4: ='Project Plan'!E8 -> 11535559 | F4: =F22 -> 11729548 | L4: 11729548 | N4: Start Date
B5: 2 | C5: Planned Expenditure | D5: =+'Expenditure Tracking'!F5 -> 10556110 | F5: =+'Expenditure Tracking'!J5 -> 11989843 | G5: VO PM Limit | H5: Current VO Total | L5: 10805125 | N5: 45691
B6: 3 | C6: Planned Profit | D6: =+D4-D5 -> 979449.23 | F6: =+F4-F5 -> -260295 | G6: =D6*0.05 -> 48972.461 | H6: =SUMIF('Expenditure Breakdown'!O:O,"*VO*",'Expenditure Breakdown'!R:R) -> 893309.64 | L6: 924422.46 | N6: End Date - PC
B7: 4 | C7: Planned Margin | D7: =+D6/D4 -> 0.084906955 | F7: =+F6/F4 -> -0.022191393 | L7: 0.078811434 | N7: 45772
B10: CONTRACT
B12: No. | C12: PAYMENT MILESTONE | E12: % | F12: VALUE | H12: PLANNED PAYMENT DATE | L12: INVOICE NUMBER | N12: INVOICE RAISED DATE | P12: PAYMENT RECEIVED DATE | R12: MILESTONE NOTES & COMMENTS
B13: 1 | C13: Deposit | E13: 0.35 | F13: =$D$4*E13 -> 4037445.8 | H13: ='Project Plan'!G14+21 -> 45635 | L13: 004646 | N13: 45673 | P13: 45679
B14: 2 | C14: Delivery of Main Equipment (Solar Panels Inverters and Balance of System) | E14: 0.3 | F14: =$D$4*E14 -> 3460667.8 | H14: ='Project Plan'!E40+21 -> 45712 | L14: 004646 | N14: 45673 | P14: 45695
B15: 3 | C15: Delivery of Main Equipment (Inverters, Batteries and Balance of System) | E15: 0.2 | F15: =$D$4*E15 -> 2307111.9 | H15: ='Project Plan'!E26+21 -> 45733 | L15: 004646 | N15: 45673 | P15: 45679
B16: 4 | C16: Installation Completion Date (Physical Completion) | E16: 0.1 | F16: =$D$4*E16 -> 1153555.9 | H16: ='Project Plan'!G45+21 -> 45793 | L16: 004646 | N16: 45673 | P16: 45789
B17: 5 | C17: Handover | E17: 0.05 | F17: =$D$4*E17 -> 576777.97 | H17: ='Project Plan'!G56+21 -> 45810 | L17: 004646 | N17: 45673 | P17: 45835
B18: 6 | C18: VO - Roof Repairs | E18: 0.7 | F18: 73118.58 | H18: =H16 -> 45793 | L18: 004636 | N18: 45639 | P18: 45639
B19: 6 | C19: VO - Roof Repairs | F19: =149221.6-F18 -> 76103.02 | H19: =H17 -> 45810 | L19: 004636 | N19: 45639 | P19: 45701
B20: 6 | C20: VO - Roof Repairs | E20: 0.3 | F20: =149221.6*E20 -> 44766.48 | H20: =H16 -> 45793 | L20: 004654 | N20: 45684 | P20: 45701
E22: =SUM(E13:E20) -> 2 | F22: =SUM(F13:F20) -> 11729548
B24: KEY: | C24: contains an error (in result or a check has failed)
C25: Red Font - IF TEXT : content not yet confirmed | H25: =F17*1.15 -> 663294.67
C26: Red Font - IF NUMBER: Negative value
C27: Anything in yellow is a concern or risk for noting or action
C28: confirmed
C29: [ADD INITIALS: comment for noting in square brackets, use colour or red to draw attention if important]
C30: [RT: When adding rows into sheet, ensure you insert between first and last row of each category]
C31: end of sheet - do not insert information below/beyond this
L36: =6344558/1.15 -> 5517007 | N36: =L36-F13 -> 1479561.1
B41: No. | C41: PAYMENT MILESTONE | E41: % | F41: VALUE
B42: 1 | C42: Deposit - Project commencement | E42: 0.35 | F42: =$F$48*E42 -> 4105341.6
B43: 2 | C43: Delivery of Panels | E43: 0.3 | F43: =$F$48*E43 -> 3518864.3
B44: 3 | C44: Delivery of Inverters | E44: 0.2 | F44: =$F$48*E44 -> 2345909.5
B45: 4 | C45: Practical Completion | E45: 0.1 | F45: =$F$48*E45 -> 1172954.8
B46: 5 | C46: Handover | E46: 0.05 | F46: =$F$48*E46 -> 586477.38
C47: Total | E47: =SUM(E42:E46) -> 1 | F47: =SUM(F42:F46) -> 11729548
E48: =SUM(E42:E46) -> 1 | F48: =F22 -> 11729548

Sheet Project Plan
N1: =TODAY() -> 46087 | O1: =TODAY() -> 46087
C2: PROJECT PLAN | E2: Mayo Macs | N2: 0 | O2: 1
C3: PROJECT SIZE (kWp) | E3: 400
C4: SITE ADDRESS
C5: BUSINESS DEVELOPER | E5: Megan
C6: PROJECT MANAGERS | E6: JT
C7: INSTALLER | E7: TBC
C8: CONTRACT VALUE | E8: 11535559
C9: Phase: | E9: DLP
B10: No. | C10: HIGH LEVEL PROGRAMME | E10: Planned Start | F10: Duration (days) | G10: Planned End | I10: Actual Start | J10: Duration (days) | K10: Actual End | M10: Status | O10: Comment
F11: =G45-E21 -> 81 | J11: =K45-I21 -> 93 | M11: =AVERAGE(M13,M20,M24,M33,M39,M43,M51,M48) -> 1 | N11: =AVERAGE(N13,N20,N24,N33,N39,N43,N51,N48) -> 1
B13: 1 | C13: Project Initiation | E13: 45594 | F13: 25 | G13: 45619 | I13: =MIN(I14:I18) -> 45611 | J13: 25 | K13: =MAX(K14:K18) -> 45685 | M13: =(J14*M14+J15*M15+J16*M16+J17*M17+J18*M18)/SUM(J14:J18) -> 1 | N13: =(K14*N14+K15*N15+K16*N16+K17*N17+K18*N18)/SUM(K14:K18) -> 1
B14: 1.1 | C14: BD Handover | E14: 45611 | F14: 1 | G14: =WORKDAY.INTL(E14,F14,1,Data!$C$3:$C$26) -> 45614 | I14: 45611 | J14: 1 | K14: =WORKDAY.INTL(I14,J14,1,Data!$C$3:$C$26) -> 45614 | M14: 1 | N14: 1
B15: 1.2 | C15: Project Introduction | E15: 45673 | F15: 1 | G15: =WORKDAY.INTL(E15,F15,1,Data!$C$3:$C$26) -> 45674 | I15: 45673 | J15: 1 | K15: =WORKDAY.INTL(I15,J15,1,Data!$C$3:$C$26) -> 45674 | M15: 1 | N15: 1
B16: 1.3 | C16: HSE | E16: 45667 | F16: 10 | G16: =WORKDAY.INTL(E16,F16,1,Data!$C$3:$C$26) -> 45681 | I16: 45667 | J16: 10 | K16: =WORKDAY.INTL(I16,J16,1,Data!$C$3:$C$26) -> 45681 | M16: 1 | N16: 1
B17: 1.4 | C17: Installer Kick Off | E17: =E21-7 -> 45684 | F17: 1 | G17: =WORKDAY.INTL(E17,F17,1,Data!$C$3:$C$26) -> 45685 | I17: =I21-7 -> 45684 | J17: 1 | K17: =WORKDAY.INTL(I17,J17,1,Data!$C$3:$C$26) -> 45685 | M17: 1 | N17: 1
B18: 1.5 | C18: Project Review | E18: 45679 | F18: 1 | G18: =WORKDAY.INTL(E18,F18,1,Data!$C$3:$C$26) -> 45680 | I18: 45679 | J18: 1 | K18: =WORKDAY.INTL(I18,J18,1,Data!$C$3:$C$26) -> 45680 | M18: 1 | N18: 1
B20: 2 | C20: Site Establishment | E20: =MIN(E21:E23) -> 45684 | F20: =G20-E20 -> 8 | G20: =MAX(G21) -> 45692 | I20: =MIN(I21:I23) -> 45684 | J20: =K20-I20 -> 9 | K20: =MAX(K21) -> 45693 | M20: 1 | N20: 1
B21: 2.1 | C21: Installer on site & Roof Assessment | E21: 45691 | F21: 1 | G21: =WORKDAY.INTL(E21,F21,1,Data!$C$3:$C$26) -> 45692 | I21: 45691 | J21: 2 | K21: =WORKDAY.INTL(I21,J21,1,Data!$C$3:$C$26) -> 45693 | M21: 1 | N21: 1 | S21: =NETWORKDAYS(I21,K53) -> 155
B22: 2.2 | C22: Battery/Inverter Room Construction | E22: 45684 | F22: 30 | G22: =WORKDAY.INTL(E22,F22,1,Data!$C$3:$C$26) -> 45726 | I22: 45684 | J22: 40 | K22: =WORKDAY.INTL(I22,J22,1,Data!$C$3:$C$26) -> 45741 | M22: 1 | N22: 1 | S22: =NETWORKDAYS(I22,K54) -> 160
B24: 3 | C24: AC Installation | E24: =MIN(E25:E31) -> 45672 | F24: =G24-E24 -> 84 | G24: =MAX(G25:G31) -> 45756 | I24: =MIN(I25:I31) -> 45672 | J24: =K24-I24 -> 90 | K24: =MAX(K25:K31) -> 45762 | M24: =(J25*M25+J26*M26+J27*M26+J28*M28+J29*M29+J30*M30+J31*M31)/SUM(J25:J31) -> 1 | N24: =(K25*N25+K26*N26+K27*N26+K28*N28+K29*N29+K30*N30+K31*N31)/SUM(K25:K31) -> 1 | S24: =S21/5 -> 31
B25: 3.1.1 | C25: Inverters delivered | E25: =WORKDAY.INTL(G22,0,1,Data!$C$3:$C$26)-14 -> 45712 | F25: 1 | G25: =WORKDAY.INTL(E25,F25,1,Data!$C$3:$C$26) -> 45713 | I25: 45708 | J25: 1 | K25: =WORKDAY.INTL(I25,J25,1,Data!$C$3:$C$26) -> 45709 | M25: 1 | N25: 1
B26: 3.1.2 | C26: Hybrid Inverters Delivered | E26: =E25 -> 45712 | F26: 1 | G26: =WORKDAY.INTL(E26,F26,1,Data!$C$3:$C$26) -> 45713 | I26: 45729 | J26: 1 | K26: =WORKDAY.INTL(I26,J26,1,Data!$C$3:$C$26) -> 45730 | M26: 1 | N26: 1
B27: 3.1.3 | C27: Batteries Delivered | E27: 45672 | F27: 30 | G27: =WORKDAY.INTL(E27,F27,1,Data!$C$3:$C$26) -> 45714 | I27: 45672 | J27: 41 | K27: =WORKDAY.INTL(I27,J27,1,Data!$C$3:$C$26) -> 45729 | M27: 1 | N27: 1
B28: 3.2 | C28: Inverters Mounted | E28: =WORKDAY.INTL(G25,0,1,Data!$C$3:$C$26) -> 45713 | F28: 10 | G28: =WORKDAY.INTL(E28,F28,1,Data!$C$3:$C$26) -> 45727 | I28: =WORKDAY.INTL(K26,0,1,Data!$C$3:$C$26) -> 45730 | J28: 1 | K28: =WORKDAY.INTL(I28,J28,1,Data!$C$3:$C$26) -> 45733 | M28: 1 | N28: 1 | S28: =E3/S24 -> 12.903226
B29: 3.3 | C29: Solar DB Lead Time | E29: =WORKDAY.INTL(E17,0,1,Data!$C$3:$C$26) -> 45684 | F29: 30 | G29: =WORKDAY.INTL(E29,F29,1,Data!$C$3:$C$26) -> 45726 | I29: =WORKDAY.INTL(I17,0,1,Data!$C$3:$C$26) -> 45684 | J29: 40 | K29: =WORKDAY.INTL(I29,J29,1,Data!$C$3:$C$26) -> 45741 | M29: 1 | N29: 1
B30: 3.4 | C30: AC Works | E30: =WORKDAY.INTL(G28,0,1,Data!$C$3:$C$26) -> 45727 | F30: 20 | G30: =WORKDAY.INTL(E30,F30,1,Data!$C$3:$C$26) -> 45756 | I30: =WORKDAY.INTL(K28,0,1,Data!$C$3:$C$26) -> 45733 | J30: 20 | K30: =WORKDAY.INTL(I30,J30,1,Data!$C$3:$C$26) -> 45762 | M30: 1 | N30: 1
B31: 3.5 | C31: AC Tie-In | E31: =WORKDAY.INTL(G30,0,1,Data!$C$3:$C$26)-7 -> 45749 | F31: 3 | G31: =WORKDAY.INTL(E31,F31,1,Data!$C$3:$C$26) -> 45754 | I31: =WORKDAY.INTL(K30,0,1,Data!$C$3:$C$26)-7 -> 45755 | J31: 1 | K31: =WORKDAY.INTL(I31,J31,1,Data!$C$3:$C$26) -> 45756 | M31: 1 | N31: 1
B33: 4 | C33: DC Works | E33: =MIN(E34:E37) -> 45691 | F33: =G33-E33 -> 28 | G33: =MAX(G34:G37) -> 45719 | I33: =MIN(I34:I37) -> 45700 | J33: =K33-I33 -> 64 | K33: =MAX(K34:K37) -> 45764 | M33: 1 | N33: 1
B34: 4.1 | C34: Mounting Structure delivered | E34: =WORKDAY.INTL(E21,0,1,Data!$C$3:$C$26) -> 45691 | F34: 1 | G34: =WORKDAY.INTL(E34,F34,1,Data!$C$3:$C$26) -> 45692 | I34: 45700 | J34: 1 | K34: =WORKDAY.INTL(I34,J34,1,Data!$C$3:$C$26) -> 45701 | M34: 1 | N34: 1
B35: 4.2 | C35: Mounting Structure installation | E35: =WORKDAY.INTL(G34,0,1,Data!$C$3:$C$26) -> 45692 | F35: 12 | G35: =WORKDAY.INTL(E35,F35,1,Data!$C$3:$C$26) -> 45708 | I35: =WORKDAY.INTL(K34,0,1,Data!$C$3:$C$26) -> 45701 | J35: 12 | K35: =WORKDAY.INTL(I35,J35,1,Data!$C$3:$C$26) -> 45719 | M35: 1 | N35: 1
B36: 4.3 | C36: DC Cable delivered | E36: =WORKDAY.INTL(E21,0,1,Data!$C$3:$C$26) -> 45691 | F36: 1 | G36: =WORKDAY.INTL(E36,F36,1,Data!$C$3:$C$26) -> 45692 | I36: 45708 | J36: 1 | K36: =WORKDAY.INTL(I36,J36,1,Data!$C$3:$C$26) -> 45709 | M36: 1 | N36: 1
B37: 4.4 | C37: DC Stringing | E37: =WORKDAY.INTL(G36,0,1,Data!$C$3:$C$26) -> 45692 | F37: 19 | G37: =WORKDAY.INTL(E37,F37,1,Data!$C$3:$C$26) -> 45719 | I37: =WORKDAY.INTL(K41,0,1,Data!$C$3:$C$26)-10 -> 45738 | J37: 19 | K37: =WORKDAY.INTL(I37,J37,1,Data!$C$3:$C$26) -> 45764 | M37: 1 | N37: 1
B39: 5 | C39: Module installation | E39: =MIN(E40:E41) -> 45691 | F39: =G39-E39 -> 53 | G39: =MAX(G40:G41) -> 45744 | I39: =MIN(I40:I41) -> 45708 | J39: =K39-I39 -> 40 | K39: =MAX(K40:K41) -> 45748 | M39: =(J40*M40+J41*M41)/SUM(J40:J41) -> 1 | N39: =(K40*N40+K41*N41)/SUM(K40:K41) -> 1
B40: 5.1 | C40: Module delivery | E40: =E21 -> 45691 | F40: 1 | G40: =WORKDAY.INTL(E40,F40,1,Data!$C$3:$C$26) -> 45692 | I40: 45708 | J40: 1 | K40: =WORKDAY.INTL(I40,J40,1,Data!$C$3:$C$26) -> 45709 | M40: 1 | N40: 1
B41: 5.2 | C41: Module mounting | E41: =WORKDAY.INTL(G35,0,1,Data!$C$3:$C$26)-7 -> 45701 | F41: 30 | G41: =WORKDAY.INTL(E41,F41,1,Data!$C$3:$C$26) -> 45744 | I41: =WORKDAY.INTL(K35,0,1,Data!$C$3:$C$26)-7 -> 45712 | J41: 25 | K41: =WORKDAY.INTL(I41,J41,1,Data!$C$3:$C$26) -> 45748 | M41: 1 | N41: 1
B43: 6 | C43: Commissioning | E43: =MIN(E44:E45) -> 45756 | F43: =G43-E43 -> 16 | G43: =MAX(G44:G45) -> 45772 | I43: =MIN(I44:I45) -> 45764 | J43: =K43-I43 -> 20 | K43: =MAX(K44:K45) -> 45784 | M43: =(J44*M44+J45*M45)/SUM(J44:J45) -> 1 | N43: =(K44*N44+K45*N45)/SUM(K44:K45) -> 1
B44: 6.1 | C44: Commissioning | E44: =WORKDAY.INTL(MAX(G24,G33,G39),0,1,Data!$C$3:$C$26) -> 45756 | F44: 5 | G44: =WORKDAY.INTL(E44,F44,1,Data!$C$3:$C$26) -> 45763 | I44: =WORKDAY.INTL(MAX(K24,K33,K39),0,1,Data!$C$3:$C$26) -> 45764 | J44: 5 | K44: =WORKDAY.INTL(I44,J44,1,Data!$C$3:$C$26) -> 45776 | M44: 1 | N44: 1
B45: 6.2 | C45: Practical Completion | E45: =WORKDAY.INTL(G44,0,1,Data!$C$3:$C$26) -> 45763 | F45: 5 | G45: =WORKDAY.INTL(E45,F45,1,Data!$C$3:$C$26) -> 45772 | I45: =WORKDAY.INTL(K44,0,1,Data!$C$3:$C$26) -> 45776 | J45: 5 | K45: =WORKDAY.INTL(I45,J45,1,Data!$C$3:$C$26) -> 45784 | M45: 1 | N45: 1
B46: 6.3 | C46: Post-Installation Commissioning | E46: =WORKDAY.INTL(G45,0,1,Data!$C$3:$C$26) -> 45772 | F46: 10 | G46: =WORKDAY.INTL(E46,F46,1,Data!$C$3:$C$26) -> 45790 | I46: =WORKDAY.INTL(K45,0,1,Data!$C$3:$C$26) -> 45784 | J46: 15 | K46: =WORKDAY.INTL(I46,J46,1,Data!$C$3:$C$26) -> 45805 | M46: 1 | N46: 1
...

Sheet Expenditure Tracking
B2: HIGH LEVEL PROJECT EXPENDITURE TRACKING
F4: COSTED | H4: PLANNED | J4: ACTUAL | L4: Difference from costed | N4: Difference from planned
B5: EXPENDITURE | F5: =SUM(F9:F23) -> 10556110 | H5: =SUM(H9:H23) -> 10804925 | J5: =SUM(J9:J23) -> 11989843 | L5: =SUM(L9:L23) -> -1433732.3 | N5: =SUM(N9:N23) -> -1184917.5
B7: No. | D7: Item | F7: Costed Expenditure | H7: Planned Expenditure | J7: Actual Expenditure | L7: Saving / Overrun | N7: Saving / Overrun | P7: Comments on variations from planned expenditure
B9: ='Expenditure Breakdown'!B6 -> 1 | D9: ='Expenditure Breakdown'!C6 -> Panels | F9: ='Expenditure Breakdown'!J6 -> 1077596.6 | H9: 948317.8 | J9: ='Expenditure Breakdown'!X6 -> 908317.8 | L9: =F9-J9 -> 169278.76 | N9: =H9-J9 -> 40000
B10: ='Expenditure Breakdown'!B13 -> 2 | D10: ='Expenditure Breakdown'!C13 -> Inverters | F10: =+'Expenditure Breakdown'!J13 -> 210000 | H10: 252941.6 | J10: =+'Expenditure Breakdown'!X13 -> 180931.83 | L10: =F10-J10 -> 29068.17 | N10: =H10-J10 -> 72009.772
B11: ='Expenditure Breakdown'!B18 -> 3 | D11: ='Expenditure Breakdown'!C18 -> Mounting Structures | F11: =+'Expenditure Breakdown'!J18 -> 180180 | H11: 86297.652 | J11: =+'Expenditure Breakdown'!X18 -> 86550.7 | L11: =F11-J11 -> 93629.3 | N11: =H11-J11 -> -253.048
B12: ='Expenditure Breakdown'!B23 -> 4 | D12: ='Expenditure Breakdown'!C23 -> DC Equipment | F12: =+'Expenditure Breakdown'!J23 -> 344364.8 | H12: 313434 | J12: =+'Expenditure Breakdown'!X23 -> 362150 | L12: =F12-J12 -> -17785.2 | N12: =H12-J12 -> -48716
B13: ='Expenditure Breakdown'!B35 -> 5 | D13: ='Expenditure Breakdown'!C35 -> Monitoring | F13: =+'Expenditure Breakdown'!J35 -> 174000 | H13: 50640.35 | J13: =+'Expenditure Breakdown'!X35 -> 68208.04 | L13: =F13-J13 -> 105791.96 | N13: =H13-J13 -> -17567.69
B14: ='Expenditure Breakdown'!B43 -> 6 | D14: ='Expenditure Breakdown'!C43 -> AC Equipment | F14: =+'Expenditure Breakdown'!J43 -> 381282.73 | H14: 1167527.7 | J14: =+'Expenditure Breakdown'!X43 -> 1167527.7 | L14: =F14-J14 -> -786244.93 | N14: =H14-J14 -> -0.0074999998
B15: ='Expenditure Breakdown'!B53 -> 7 | D15: ='Expenditure Breakdown'!C53 -> Battery Systems | F15: =+'Expenditure Breakdown'!J53 -> 7393827 | H15: 6474594 | J15: ='Expenditure Breakdown'!X53 -> 6386529 | L15: =F15-J15 -> 1007298 | N15: =H15-J15 -> 88065
B16: ='Expenditure Breakdown'!B66 -> 8 | D16: ='Expenditure Breakdown'!C66 -> Product Add On | F16: ='Expenditure Breakdown'!J66 -> 0 | H16: 135656 | J16: ='Expenditure Breakdown'!X66 -> 313051.32 | L16: =F16-J16 -> -313051.32 | N16: =H16-J16 -> -177395.32
B17: ='Expenditure Breakdown'!M78 -> 9 | D17: ='Expenditure Breakdown'!C78 -> AC & DC Installation | F17: =+'Expenditure Breakdown'!J78 -> 342160 | H17: 676952 | J17: =+'Expenditure Breakdown'!X78 -> 676952 | L17: =F17-J17 -> -334792 | N17: =H17-J17 -> 0
B18: ='Expenditure Breakdown'!B87 -> 10 | D18: ='Expenditure Breakdown'!C87 -> Site Logistics | F18: =+'Expenditure Breakdown'!J87 -> 54108.833 | H18: 314687 | J18: =+'Expenditure Breakdown'!X87 -> 114637 | L18: =F18-J18 -> -60528.167 | N18: =H18-J18 -> 200050
B19: ='Expenditure Breakdown'!B100 -> 11 | D19: ='Expenditure Breakdown'!C100 -> Due Dilligence | F19: ='Expenditure Breakdown'!J100 -> 111020 | H19: 82026.4 | J19: ='Expenditure Breakdown'!X100 -> 38759.07 | L19: =F19-J19 -> 72260.93 | N19: =H19-J19 -> 43267.33
B20: ='Expenditure Breakdown'!B108 -> 12 | D20: ='Expenditure Breakdown'!C108 -> BDP Commission | F20: ='Expenditure Breakdown'!G107 -> 0 | H20: 0 | J20: ='Expenditure Breakdown'!X107 -> 0 | L20: =F20-J20 -> 0 | N20: =H20-J20 -> 0
B21: ='Expenditure Breakdown'!B110 -> 13 | D21: ='Expenditure Breakdown'!C110 -> Engineering | F21: =+'Expenditure Breakdown'!J110 -> 239970.35 | H21: 255808.09 | J21: =+'Expenditure Breakdown'!X110 -> 447579.71 | L21: =F21-J21 -> -207609.36 | N21: =H21-J21 -> -191771.62 | P21: RV: Matriarch defects percentage 1.25%
B22: ='Expenditure Breakdown'!B118 -> 14 | D22: ='Expenditure Breakdown'!C118 -> General Expenses | F22: =+'Expenditure Breakdown'!J118 -> 47600 | H22: 46042.527 | J22: =+'Expenditure Breakdown'!X118 -> 67232.7 | L22: =F22-J22 -> -19632.7 | N22: =H22-J22 -> -21190.173
B23: ='Expenditure Breakdown'!B129 -> 15 | D23: ='Expenditure Breakdown'!C129 -> Service Add On | F23: =+'Expenditure Breakdown'!J129 -> 0 | H23: 0 | J23: =+'Expenditure Breakdown'!X129 -> 1171415.7 | L23: =F23-J23 -> -1171415.7 | N23: =H23-J23 -> -1171415.7
D25: check: | F25: ='Expenditure Breakdown'!J2-'Expenditure Tracking'!F5 -> 0 | G25: ='Expenditure Breakdown'!#REF!-G5 -> #REF! | H25: ='Expenditure Breakdown'!X2-J5 -> 0 | I25: ='Expenditure Breakdown'!#REF!-I5 -> #REF! | J25: ='Expenditure Breakdown'!X2-J5 -> 0
A27: Copy amounts in column H and paste as values at Project review.

Sheet Data
C2: Public holidays | F2: Drop down list
C3: 45292 | D3: New Years Day | F3: Approved
C4: 45372 | D4: Human Rights day | F4: Pending
C5: 45380 | D5: Good Friday | F5: Declined
C6: 45383 | D6: Family Day | F6: Abanded
C7: 45413 | D7: Workers day
C8: 45460 | D8: Youth Day Holiday
C9: 45513 | D9: Womens Day
C10: 45559 | D10: Heritage Day
C11: 45642 | D11: Day of Reconciliation
C12: 45651 | D12: Christmas Day
C13: 45652 | D13: Day of Goodwill | H13: Manual dates
C14: 45658 | D14: New Years Day
C15: 45737 | D15: Human Rights day
C16: 45765 | D16: Good Friday
C17: 45768 | D17: Family Day
C18: 45774 | D18: Freedom Day
C19: 45775 | D19: Freedom DayObserved
C20: 45778 | D20: Workers day
C21: 45824 | D21: Youth Day Holiday
C22: 45878 | D22: Womens Day
C23: 45924 | D23: Heritage Day
C24: 46007 | D24: Day of Reconciliation
C25: 46016 | D25: Christmas Day
C26: 46017 | D26: Day of Goodwill

Sheet Cashflow
D1: [RT: Double Check the first date is always a MONDAY] | F1: 45600 | G1: =F1+7 -> 45607 | H1: =G1+7 -> 45614 | I1: =H1+7 -> 45621 | J1: =I1+7 -> 45628 | K1: =J1+7 -> 45635 | L1: =K1+7 -> 45642 | M1: =L1+7 -> 45649 | N1: =M1+7 -> 45656 | ... CP1: =CO1+7 -> 46216
A2: PLANNED | C2: CHECK | D2: CHECK
B3: Planned Revenue | C3: ='Revenue Tracking'!D4 -> 11535559 | D3: =SUM(F3:CP3) -> 11729548 | F3: =SUMIFS('Revenue Tracking'!$F$13:$F$20, 'Revenue Tracking'!$H$13:$H$20, ">="&F1,'Revenue Tracking'!$H$13:$H$20, "<"&G1) -> 0 | G3: =SUMIFS('Revenue Tracking'!$F$13:$F$20, 'Revenue Tracking'!$H$13:$H$20, ">="&G1,'Revenue Tracking'!$H$13:$H$20, "<"&H1) -> 0 | H3: =SUMIFS('Revenue Tracking'!$F$13:$F$20, 'Revenue Tracking'!$H$13:$H$20, ">="&H1,'Revenue Tracking'!$H$13:$H$20, "<"&I1) -> 0 | I3: =SUMIFS('Revenue Tracking'!$F$13:$F$20, 'Revenue Tracking'!$H$13:$H$20, ">="&I1,'Revenue Tracking'!$H$13:$H$20, "<"&J1) -> 0 | J3: =SUMIFS('Revenue Tracking'!$F$13:$F$20, 'Revenue Tracking'!$H$13:$H$20, ">="&J1,'Revenue Tracking'!$H$13:$H$20, "<"&K1) -> 0 | K3: =SUMIFS('Revenue Tracking'!$F$13:$F$20, 'Revenue Tracking'!$H$13:$H$20, ">="&K1,'Revenue Tracking'!$H$13:$H$20, "<"&L1) -> 4037445.8 | L3: =SUMIFS('Revenue Tracking'!$F$13:$F$20, 'Revenue Tracking'!$H$13:$H$20, ">="&L1,'Revenue Tracking'!$H$13:$H$20, "<"&M1) -> 0 | M3: =SUMIFS('Revenue Tracking'!$F$13:$F$20, 'Revenue Tracking'!$H$13:$H$20, ">="&M1,'Revenue Tracking'!$H$13:$H$20, "<"&N1) -> 0 | ... CP3: =SUMIFS('Revenue Tracking'!$F$13:$F$20, 'Revenue Tracking'!$H$13:$H$20, ">="&CP1,'Revenue Tracking'!$H$13:$H$20, "<"&CQ1) -> 0
B4: Planned Revenue - Cumulative | F4: =F3 -> 0 | G4: =F4+G3 -> 0 | H4: =G4+H3 -> 0 | I4: =H4+I3 -> 0 | J4: =I4+J3 -> 0 | K4: =J4+K3 -> 4037445.8 | L4: =K4+L3 -> 4037445.8 | M4: =L4+M3 -> 4037445.8 | N4: =M4+N3 -> 4037445.8 | ... CP4: =CO4+CP3 -> 11729548
B5: Planned Expenditure | C5: ='Revenue Tracking'!D5 -> 10556110 | D5: =SUM(F5:CP5) -> 10556110 | F5: =SUMIFS('Expenditure Breakdown'!$G$6:$G$150, 'Expenditure Breakdown'!$H$6:$H$150, ">="&F1,'Expenditure Breakdown'!$H$6:$H$150, "<"&G1) -> 0 | G5: =SUMIFS('Expenditure Breakdown'!$G$6:$G$150, 'Expenditure Breakdown'!$H$6:$H$150, ">="&G1,'Expenditure Breakdown'!$H$6:$H$150, "<"&H1) -> 0 | H5: =SUMIFS('Expenditure Breakdown'!$G$6:$G$150, 'Expenditure Breakdown'!$H$6:$H$150, ">="&H1,'Expenditure Breakdown'!$H$6:$H$150, "<"&I1) -> 0 | I5: =SUMIFS('Expenditure Breakdown'!$G$6:$G$150, 'Expenditure Breakdown'!$H$6:$H$150, ">="&I1,'Expenditure Breakdown'!$H$6:$H$150, "<"&J1) -> 0 | J5: =SUMIFS('Expenditure Breakdown'!$G$6:$G$150, 'Expenditure Breakdown'!$H$6:$H$150, ">="&J1,'Expenditure Breakdown'!$H$6:$H$150, "<"&K1) -> 0 | K5: =SUMIFS('Expenditure Breakdown'!$G$6:$G$150, 'Expenditure Breakdown'!$H$6:$H$150, ">="&K1,'Expenditure Breakdown'!$H$6:$H$150, "<"&L1) -> 0 | L5: =SUMIFS('Expenditure Breakdown'!$G$6:$G$150, 'Expenditure Breakdown'!$H$6:$H$150, ">="&L1,'Expenditure Breakdown'!$H$6:$H$150, "<"&M1) -> 0 | M5: =SUMIFS('Expenditure Breakdown'!$G$6:$G$150, 'Expenditure Breakdown'!$H$6:$H$150, ">="&M1,'Expenditure Breakdown'!$H$6:$H$150, "<"&N1) -> 0 | ... CP5: =SUMIFS('Expenditure Breakdown'!$G$6:$G$150, 'Expenditure Breakdown'!$H$6:$H$150, ">="&CP1,'Expenditure Breakdown'!$H$6:$H$150, "<"&CQ1) -> 0
B6: Planned Expenditure - Cumulative | F6: =F5 -> 0 | G6: =F6+G5 -> 0 | H6: =G6+H5 -> 0 | I6: =H6+I5 -> 0 | J6: =I6+J5 -> 0 | K6: =J6+K5 -> 0 | L6: =K6+L5 -> 0 | M6: =L6+M5 -> 0 | N6: =M6+N5 -> 0 | ... CP6: =CO6+CP5 -> 10556110
B7: PLANNED CashFlow | F7: =F4-F6 -> 0 | G7: =G4-G6 -> 0 | H7: =H4-H6 -> 0 | I7: =I4-I6 -> 0 | J7: =J4-J6 -> 0 | K7: =K4-K6 -> 4037445.8 | L7: =L4-L6 -> 4037445.8 | M7: =M4-M6 -> 4037445.8 | ... CP7: =CP4-CP6 -> 1173437.3
A8: ACTUAL | C8: CHECK | D8: CHECK
B9: Actual + Planned Revenue | C9: ='Revenue Tracking'!F4 -> 11729548 | D9: =SUM(F9:CP9) -> 11729548 | F9: =SUMIFS('Revenue Tracking'!$F$13:$F$20, 'Revenue Tracking'!$P$13:$P$20, ">="&F1,'Revenue Tracking'!$P$13:$P$20, "<"&G1) -> 0 | G9: =SUMIFS('Revenue Tracking'!$F$13:$F$20, 'Revenue Tracking'!$P$13:$P$20, ">="&G1,'Revenue Tracking'!$P$13:$P$20, "<"&H1) -> 0 | H9: =SUMIFS('Revenue Tracking'!$F$13:$F$20, 'Revenue Tracking'!$P$13:$P$20, ">="&H1,'Revenue Tracking'!$P$13:$P$20, "<"&I1) -> 0 | I9: =SUMIFS('Revenue Tracking'!$F$13:$F$20, 'Revenue Tracking'!$P$13:$P$20, ">="&I1,'Revenue Tracking'!$P$13:$P$20, "<"&J1) -> 0 | J9: =SUMIFS('Revenue Tracking'!$F$13:$F$20, 'Revenue Tracking'!$P$13:$P$20, ">="&J1,'Revenue Tracking'!$P$13:$P$20, "<"&K1) -> 0 | K9: =SUMIFS('Revenue Tracking'!$F$13:$F$20, 'Revenue Tracking'!$P$13:$P$20, ">="&K1,'Revenue Tracking'!$P$13:$P$20, "<"&L1) -> 73118.58 | L9: =SUMIFS('Revenue Tracking'!$F$13:$F$20, 'Revenue Tracking'!$P$13:$P$20, ">="&L1,'Revenue Tracking'!$P$13:$P$20, "<"&M1) -> 0 | M9: =SUMIFS('Revenue Tracking'!$F$13:$F$20, 'Revenue Tracking'!$P$13:$P$20, ">="&M1,'Revenue Tracking'!$P$13:$P$20, "<"&N1) -> 0 | ... CP9: =SUMIFS('Revenue Tracking'!$F$13:$F$20, 'Revenue Tracking'!$P$13:$P$20, ">="&CP1,'Revenue Tracking'!$P$13:$P$20, "<"&CQ1) -> 0
B10: Actual + Planned Revenue - Cumulative | F10: =F9 -> 0 | G10: =F10+G9 -> 0 | H10: =G10+H9 -> 0 | I10: =H10+I9 -> 0 | J10: =I10+J9 -> 0 | K10: =J10+K9 -> 73118.58 | L10: =K10+L9 -> 73118.58 | M10: =L10+M9 -> 73118.58 | N10: =M10+N9 -> 73118.58 | ... CP10: =CO10+CP9 -> 11729548
B11: Actual + Planned Expenditure | C11: ='Revenue Tracking'!F5 -> 11989843 | D11: =SUM(F11:CP11) -> 11989843 | F11: =SUMIFS('Expenditure Breakdown'!$R$6:$R$150, 'Expenditure Breakdown'!$W$6:$W$150, ">="&F1,'Expenditure Breakdown'!$W$6:$W$150, "<"&G1) -> 0 | G11: =SUMIFS('Expenditure Breakdown'!$R$6:$R$150, 'Expenditure Breakdown'!$W$6:$W$150, ">="&G1,'Expenditure Breakdown'!$W$6:$W$150, "<"&H1) -> 0 | H11: =SUMIFS('Expenditure Breakdown'!$R$6:$R$150, 'Expenditure Breakdown'!$W$6:$W$150, ">="&H1,'Expenditure Breakdown'!$W$6:$W$150, "<"&I1) -> 0 | I11: =SUMIFS('Expenditure Breakdown'!$R$6:$R$150, 'Expenditure Breakdown'!$W$6:$W$150, ">="&I1,'Expenditure Breakdown'!$W$6:$W$150, "<"&J1) -> 11026.4 | J11: =SUMIFS('Expenditure Breakdown'!$R$6:$R$150, 'Expenditure Breakdown'!$W$6:$W$150, ">="&J1,'Expenditure Breakdown'!$W$6:$W$150, "<"&K1) -> 0 | K11: =SUMIFS('Expenditure Breakdown'!$R$6:$R$150, 'Expenditure Breakdown'!$W$6:$W$150, ">="&K1,'Expenditure Breakdown'!$W$6:$W$150, "<"&L1) -> 94959.2 | L11: =SUMIFS('Expenditure Breakdown'!$R$6:$R$150, 'Expenditure Breakdown'!$W$6:$W$150, ">="&L1,'Expenditure Breakdown'!$W$6:$W$150, "<"&M1) -> 0 | M11: =SUMIFS('Expenditure Breakdown'!$R$6:$R$150, 'Expenditure Breakdown'!$W$6:$W$150, ">="&M1,'Expenditure Breakdown'!$W$6:$W$150, "<"&N1) -> 0 | ... CP11: =SUMIFS('Expenditure Breakdown'!$R$6:$R$150, 'Expenditure Breakdown'!$W$6:$W$150, ">="&CP1,'Expenditure Breakdown'!$W$6:$W$150, "<"&CQ1) -> 0
